Workbook

Sheet Formule TDB
A1: Ligne | B1: Intitulé | C1: Réalisé N | E1: Code
A2: 1 | B2: CAM040-Frais d'activation & Sim swap | C2: -701120 -701130 | D2: =VLOOKUP(B2,'Analyse Réel 01-2025'!F:H,1,FALSE) -> CAM040-Frais d'activation & Sim swap | E2: =VLOOKUP(B2,'Analyse Réel 01-2025'!F:H,2,FALSE) -> CA12
A3: 2 | B3: CAM045-Sortant voix on net | C3: -NM(706120,*,A61,*,*,*,*,*,*,*) -NM(706920,*,A58,*,*,*,*,*,*,*) | D3: =VLOOKUP(B3,'Analyse Réel 01-2025'!F:H,1,FALSE) -> CAM045-Sortant voix on net | E3: =VLOOKUP(B3,'Analyse Réel 01-2025'!F:H,2,FALSE) -> CA13
A4: 3 | B4: CAM050-Sortant voix MTN | C4: -NM(706121,*,A48,*,*,*,*,*,*,*) | D4: =VLOOKUP(B4,'Analyse Réel 01-2025'!F:H,1,FALSE) -> CAM050-Sortant voix MTN | E4: =VLOOKUP(B4,'Analyse Réel 01-2025'!F:H,2,FALSE) -> CA14
A5: 4 | B5: CAM055-Sortant voix GLO | C5: -NM(706121,*,*A49,*,*,*,*,*,*,*) | D5: =VLOOKUP(B5,'Analyse Réel 01-2025'!F:H,1,FALSE) -> CAM055-Sortant voix GLO | E5: =VLOOKUP(B5,'Analyse Réel 01-2025'!F:H,2,FALSE) -> CA15
A6: 5 | B6: CAM060-Sortant voix BBCOM | C6: -NM(706121,*,*A50,*,*,*,*,*,*,*) | D6: =VLOOKUP(B6,'Analyse Réel 01-2025'!F:H,1,FALSE) -> CAM060-Sortant voix BBCOM | E6: =VLOOKUP(B6,'Analyse Réel 01-2025'!F:H,2,FALSE) -> CA16
A7: 6 | B7: CAM065-Sortant voix LIBERCOM | C7: -NM(706121,*,*A51,*,*,*,*,*,*,*) | D7: =VLOOKUP(B7,'Analyse Réel 01-2025'!F:H,1,FALSE) -> CAM065-Sortant voix LIBERCOM | E7: =VLOOKUP(B7,'Analyse Réel 01-2025'!F:H,2,FALSE) -> CA17
A8: 7 | B8: CAM070-Sortant voix BTSA | C8: -NM(706123,*,A52,*,*,*,*,*,*,*) | D8: =VLOOKUP(B8,'Analyse Réel 01-2025'!F:H,1,FALSE) -> CAM070-Sortant voix BTSA | E8: =VLOOKUP(B8,'Analyse Réel 01-2025'!F:H,2,FALSE) -> CA18
A9: 8 | B9: CAM075-Sortant voix INTERNATIONAL | C9: -NM(706124,*,A53,*,*,*,*,*,*,*) | D9: =VLOOKUP(B9,'Analyse Réel 01-2025'!F:H,1,FALSE) -> CAM075-Sortant voix INTERNATIONAL | E9: =VLOOKUP(B9,'Analyse Réel 01-2025'!F:H,2,FALSE) -> CA19
A10: 9 | B10: CAM080-Sortant voix roaming | C10: -NM(706140,*,A54,*,*,*,*,*,*,*) | D10: =VLOOKUP(B10,'Analyse Réel 01-2025'!F:H,1,FALSE) -> CAM080-Sortant voix roaming | E10: =VLOOKUP(B10,'Analyse Réel 01-2025'!F:H,2,FALSE) -> CA20
A11: 10 | B11: CAM085-Total VOIX Sortant | C11: $CAMOBILE.#(L2:9) | D11: =VLOOKUP(B11,'Analyse Réel 01-2025'!F:H,1,FALSE) -> CAM085-Total VOIX Sortant | E11: =VLOOKUP(B11,'Analyse Réel 01-2025'!F:H,2,FALSE) -> CA21
A12: 11 | B12: CAM090-Sortant sms on net | C12: -NM(706117,*,T21,*,*,*,*,*,*,*) -NM(706920,*,A59,*,*,*,*,*,*,*) | D12: =VLOOKUP(B12,'Analyse Réel 01-2025'!F:H,1,FALSE) -> CAM090-Sortant sms on net | E12: =VLOOKUP(B12,'Analyse Réel 01-2025'!F:H,2,FALSE) -> CA23
A13: 12 | B13: CAM095-Sortant sms MTN | C13: -NM(706117,*,A48,*,*,*,*,*,*,*) | D13: =VLOOKUP(B13,'Analyse Réel 01-2025'!F:H,1,FALSE) -> CAM095-Sortant sms MTN | E13: =VLOOKUP(B13,'Analyse Réel 01-2025'!F:H,2,FALSE) -> CA24
... A22: 21 | B22: CAM140-Story Box | C22: -0*NM(706151,*,*,*,*,*,*,*,*) | D22: =VLOOKUP(B22,'Analyse Réel 01-2025'!F:H,1,FALSE) -> CAM140-Story Box | E22: =VLOOKUP(B22,'Analyse Réel 01-2025'!F:H,2,FALSE) -> CA35
A23: 22 | B23: CAM145-Phonebook STK | C23: =-"0*NM(706151)" -> #VALUE! | D23: =VLOOKUP(B23,'Analyse Réel 01-2025'!F:H,1,FALSE) -> CAM145-Phonebook STK | E23: =VLOOKUP(B23,'Analyse Réel 01-2025'!F:H,2,FALSE) -> CA36
A24: 23 | B24: CAM150-Gaming | C24: -0*NM(706151,*,*,*,*,*,*,*,*) | D24: =VLOOKUP(B24,'Analyse Réel 01-2025'!F:H,1,FALSE) -> CAM150-Gaming | E24: =VLOOKUP(B24,'Analyse Réel 01-2025'!F:H,2,FALSE) -> CA37
A25: 24 | B25: CAM155-Autres (VOICEALERT,MOOVKDO...) | C25: -0*NM(706151,*,*,*,*,*,*,*,*) | D25: =VLOOKUP(B25,'Analyse Réel 01-2025'!F:H,1,FALSE) -> CAM155-Autres (VOICEALERT,MOOVKDO...) | E25: =VLOOKUP(B25,'Analyse Réel 01-2025'!F:H,2,FALSE) -> CA38
A26: 25 | B26: CAM160-Videos | C26: -0*NM(706151,*,*,*,*,*,*,*,*) | D26: =VLOOKUP(B26,'Analyse Réel 01-2025'!F:H,1,FALSE) -> CAM160-Videos | E26: =VLOOKUP(B26,'Analyse Réel 01-2025'!F:H,2,FALSE) -> CA39
A27: 26 | B27: CAM165-Total Data | C27: $CAMOBILE.#(L19:25) | D27: =VLOOKUP(B27,'Analyse Réel 01-2025'!F:H,1,FALSE) -> CAM165-Total Data | E27: =VLOOKUP(B27,'Analyse Réel 01-2025'!F:H,2,FALSE) -> CA40
A28: 27 | B28: CAM170-Dont CA SVA ( Sce à Val Ajoutéé) | C28: 0 | D28: =VLOOKUP(B28,'Analyse Réel 01-2025'!F:H,1,FALSE) -> CAM170-Dont CA SVA ( Sce à Val Ajoutéé) | E28: =VLOOKUP(B28,'Analyse Réel 01-2025'!F:H,2,FALSE) -> CA44
A29: 28 | B29: CAM185-dont CA Internet 3G | C29: L18 | D29: =VLOOKUP(B29,'Analyse Réel 01-2025'!F:H,1,FALSE) -> CAM185-dont CA Internet 3G | E29: =VLOOKUP(B29,'Analyse Réel 01-2025'!F:H,2,FALSE) -> CA45
A30: 29 | B30: CAM035-Consumer Prepaid | C30: R(L1+L10+L17+L26) | D30: =VLOOKUP(B30,'Analyse Réel 01-2025'!F:H,1,FALSE) -> CAM035-Consumer Prepaid | E30: =VLOOKUP(B30,'Analyse Réel 01-2025'!F:H,2,FALSE) -> CA11
A31: 30 | B31: CAM036-Prépayé (Y compris commissions) | C31: L29 | D31: =VLOOKUP(B31,'Analyse Réel 01-2025'!F:H,1,FALSE) -> CAM036-Prépayé (Y compris commissions) | E31: =VLOOKUP(B31,'Analyse Réel 01-2025'!F:H,2,FALSE) -> 0
A32: 31 | B32: CAM200-Red Consumer Postpaid | C32: -706115 NM(706115,*,A27,*,*,*,*,*,*,*) NM(706115,*,A29,*,*,*,*,*,*,*) NM(706115,*,W99,*,*,*,*,*,*,*) NM(706115,*,V99,*,*,*,*,*,*,*) NM(706115,*,U99,*,*,*,*,*,*,*) NM(706115,*,T15,*,*,*,*,*,*,*) NM(706115,*,S99,*,*,*,*,*,*,*) | D32: =VLOOKUP(B32,'Analyse Réel 01-2025'!F:H,1,FALSE) -> CAM200-Red Consumer Postpaid | E32: =VLOOKUP(B32,'Analyse Réel 01-2025'!F:H,2,FALSE) -> CA48
A33: 32 | B33: CAM205-Red Business Postpaid | C33: -NM(706115,*,T15,*,*,*,*,*,*) | D33: =VLOOKUP(B33,'Analyse Réel 01-2025'!F:H,1,FALSE) -> CAM205-Red Business Postpaid | E33: =VLOOKUP(B33,'Analyse Réel 01-2025'!F:H,2,FALSE) -> CA49
A34: 33 | B34: CAM210-Red Business Prepaid | C34: -NM(706115,*,U99,*,*,*,*,*,*) | D34: =VLOOKUP(B34,'Analyse Réel 01-2025'!F:H,1,FALSE) -> CAM210-Red Business Prepaid | E34: =VLOOKUP(B34,'Analyse Réel 01-2025'!F:H,2,FALSE) -> CA50
A35: 34 | B35: CAM195-Redevance d'abonnement | C35: R(L31+L32+L33) | D35: =VLOOKUP(B35,'Analyse Réel 01-2025'!F:H,1,FALSE) -> CAM195-Redevance d'abonnement | E35: =VLOOKUP(B35,'Analyse Réel 01-2025'!F:H,2,FALSE) -> CA47
A36: 35 | B36: CAM225-Sortant voix on net | C36: -NM(706125,*,A61,*,*,*,*,*,*,*) -NM(706900,*,A58,*,*,*,*,*,*,*) -NM(706900,*,A59,*,*,*,*,*,*,*) | D36: =VLOOKUP(B36,'Analyse Réel 01-2025'!F:H,1,FALSE) -> CAM225-Sortant voix on net | E36: =VLOOKUP(B36,'Analyse Réel 01-2025'!F:H,2,FALSE) -> CA53
A37: 36 | B37: CAM230-Sortant voix MTN | C37: -NM(706126,*,A48,*,*,*,*,*,*) | D37: =VLOOKUP(B37,'Analyse Réel 01-2025'!F:H,1,FALSE) -> CAM230-Sortant voix MTN | E37: =VLOOKUP(B37,'Analyse Réel 01-2025'!F:H,2,FALSE) -> CA54
A38: 37 | B38: CAM235-Sortant voix GLO | C38: -NM(706126,*,A49,*,*,*,*,*,*) | D38: =VLOOKUP(B38,'Analyse Réel 01-2025'!F:H,1,FALSE) -> CAM235-Sortant voix GLO | E38: =VLOOKUP(B38,'Analyse Réel 01-2025'!F:H,2,FALSE) -> CA55
A39: 38 | B39: CAM240-Sortant voix BBCOM | C39: -NM(706126,*,A50,*,*,*,*,*,*) | D39: =VLOOKUP(B39,'Analyse Réel 01-2025'!F:H,1,FALSE) -> CAM240-Sortant voix BBCOM | E39: =VLOOKUP(B39,'Analyse Réel 01-2025'!F:H,2,FALSE) -> CA56
A40: 39 | B40: CAM245-Sortant voix LIBERCOM | C40: -NM(706126,*,A51,*,*,*,*,*,*) | D40: =VLOOKUP(B40,'Analyse Réel 01-2025'!F:H,1,FALSE) -> CAM245-Sortant voix LIBERCOM | E40: =VLOOKUP(B40,'Analyse Réel 01-2025'!F:H,2,FALSE) -> CA57
... A54: 53 | B54: CAM315-Banking | C54: -NM(706115,*,B99,*,*,*,*,*,*) -NM(706115,*,I99,*,*,*,*,*,*,*) | D54: =VLOOKUP(B54,'Analyse Réel 01-2025'!F:H,1,FALSE) -> CAM315-Banking | E54: =VLOOKUP(B54,'Analyse Réel 01-2025'!F:H,2,FALSE) -> CA73
A55: 54 | B55: CAM320-Autres | C55: 0 | D55: =VLOOKUP(B55,'Analyse Réel 01-2025'!F:H,1,FALSE) -> CAM320-Autres | E55: =VLOOKUP(B55,'Analyse Réel 01-2025'!F:H,2,FALSE) -> CA74
A56: 55 | B56: CAM325-Total Data | C56: $CAMOBILE.#(L52:54) | D56: =VLOOKUP(B56,'Analyse Réel 01-2025'!F:H,1,FALSE) -> CAM325-Total Data | E56: =VLOOKUP(B56,'Analyse Réel 01-2025'!F:H,2,FALSE) -> CA75
A57: 56 | B57: CAM326-Consumer Postpaid | C57: R(L43+L50+L55) | D57: =VLOOKUP(B57,'Analyse Réel 01-2025'!F:H,1,FALSE) -> CAM326-Consumer Postpaid | E57: =VLOOKUP(B57,'Analyse Réel 01-2025'!F:H,2,FALSE) -> CA52
A58: 57 | B58: CAM335-Sortant voix on net | C58: -NM(706125,*,A99,*,*,*,*,*,*) -NM(706900,*,A99,*,*,*,*,*,*) | D58: =VLOOKUP(B58,'Analyse Réel 01-2025'!F:H,1,FALSE) -> CAM335-Sortant voix on net | E58: =VLOOKUP(B58,'Analyse Réel 01-2025'!F:H,2,FALSE) -> CA78
A59: 58 | B59: CAM340-Sortant voix MTN | C59: -NM(706126,*,A43,*,*,*,*,*,*) | D59: =VLOOKUP(B59,'Analyse Réel 01-2025'!F:H,1,FALSE) -> CAM340-Sortant voix MTN | E59: =VLOOKUP(B59,'Analyse Réel 01-2025'!F:H,2,FALSE) -> CA79
A60: 59 | B60: CAM345-Sortant voix GLO | D60: =VLOOKUP(B60,'Analyse Réel 01-2025'!F:H,1,FALSE) -> CAM345-Sortant voix GLO | E60: =VLOOKUP(B60,'Analyse Réel 01-2025'!F:H,2,FALSE) -> CA80
A61: 60 | B61: CAM355-Sortant voix BBCOM | D61: =VLOOKUP(B61,'Analyse Réel 01-2025'!F:H,1,FALSE) -> CAM355-Sortant voix BBCOM | E61: =VLOOKUP(B61,'Analyse Réel 01-2025'!F:H,2,FALSE) -> CA81
...

Sheet PROD_CAMOBILE_2025M1
F1: Correspondance
A2: Intitulé | B2: Réalisé N | C2: Budget N | D2: Budget N Actualisé 3 | E2: ECART | F2: Indicateur X3 | G2: Indicateur MOOV
A3: CAM040-Frais d'activation & Sim swap | B3: -9204763 | C3: -9204763 | D3: 9204763 | E3: 0 | F3: =LEFT(A3,6) -> CAM040 | G3: =VLOOKUP(PROD_CAMOBILE_2025M1!A3,'Analyse Réel 01-2025'!F:G,2,FALSE) -> CA12
A4: CAM045-Sortant voix on net | B4: 1295717222 | C4: 1295717222 | D4: -1355614210 | E4: 0 | F4: =LEFT(A4,6) -> CAM045 | G4: =VLOOKUP(PROD_CAMOBILE_2025M1!A4,'Analyse Réel 01-2025'!F:G,2,FALSE) -> CA13
A5: CAM050-Sortant voix MTN | B5: 1123059001 | C5: 1123059001 | D5: -1123059001 | E5: 0 | F5: =LEFT(A5,6) -> CAM050 | G5: =VLOOKUP(PROD_CAMOBILE_2025M1!A5,'Analyse Réel 01-2025'!F:G,2,FALSE) -> CA14
A6: CAM055-Sortant voix GLO | B6: 0 | C6: 0 | D6: 0 | E6: 0 | F6: =LEFT(A6,6) -> CAM055 | G6: =VLOOKUP(PROD_CAMOBILE_2025M1!A6,'Analyse Réel 01-2025'!F:G,2,FALSE) -> CA15
A7: CAM060-Sortant voix BBCOM | B7: 0 | C7: 0 | D7: 0 | E7: 0 | F7: =LEFT(A7,6) -> CAM060 | G7: =VLOOKUP(PROD_CAMOBILE_2025M1!A7,'Analyse Réel 01-2025'!F:G,2,FALSE) -> CA16
A8: CAM065-Sortant voix LIBERCOM | B8: 0 | C8: 0 | D8: 0 | E8: 0 | F8: =LEFT(A8,6) -> CAM065 | G8: =VLOOKUP(PROD_CAMOBILE_2025M1!A8,'Analyse Réel 01-2025'!F:G,2,FALSE) -> CA17
A9: CAM070-Sortant voix BTSA | B9: 477346316 | C9: 477346316 | D9: 0 | E9: 0 | F9: =LEFT(A9,6) -> CAM070 | G9: =VLOOKUP(PROD_CAMOBILE_2025M1!A9,'Analyse Réel 01-2025'!F:G,2,FALSE) -> CA18
A10: CAM075-Sortant voix INTERNATIONAL | B10: 159932592 | C10: 159932592 | D10: -159932592 | E10: 0 | F10: =LEFT(A10,6) -> CAM075 | G10: =VLOOKUP(PROD_CAMOBILE_2025M1!A10,'Analyse Réel 01-2025'!F:G,2,FALSE) -> CA19
A11: CAM080-Sortant voix roaming | B11: 10567860 | C11: 10567860 | D11: -10567860 | E11: 0 | F11: =LEFT(A11,6) -> CAM080 | G11: =VLOOKUP(PROD_CAMOBILE_2025M1!A11,'Analyse Réel 01-2025'!F:G,2,FALSE) -> CA20
A12: CAM085-Total VOIX Sortant | B12: 3066622991 | C12: 3066622991 | D12: -2649173663 | E12: 0 | F12: =LEFT(A12,6) -> CAM085 | G12: =VLOOKUP(PROD_CAMOBILE_2025M1!A12,'Analyse Réel 01-2025'!F:G,2,FALSE) -> CA21
A13: CAM090-Sortant sms on net | B13: 1236479 | C13: 1236479 | D13: -1296066 | E13: 0 | F13: =LEFT(A13,6) -> CAM090 | G13: =VLOOKUP(PROD_CAMOBILE_2025M1!A13,'Analyse Réel 01-2025'!F:G,2,FALSE) -> CA23
A14: CAM095-Sortant sms MTN | B14: 1231451 | C14: 1231451 | D14: 0 | E14: 0 | F14: =LEFT(A14,6) -> CAM095 | G14: =VLOOKUP(PROD_CAMOBILE_2025M1!A14,'Analyse Réel 01-2025'!F:G,2,FALSE) -> CA24
A15: CAM0100-Sortant sms GLO | B15: 0 | C15: 0 | D15: 0 | E15: 0 | F15: =LEFT(A15,7) -> CAM0100 | G15: =VLOOKUP(PROD_CAMOBILE_2025M1!A15,'Analyse Réel 01-2025'!F:G,2,FALSE) -> CA25
A16: CAM105-Sortant sms BBCOM | B16: 1381 | C16: 1381 | D16: -1381 | E16: 0 | F16: =LEFT(A16,6) -> CAM105 | G16: =VLOOKUP(PROD_CAMOBILE_2025M1!A16,'Analyse Réel 01-2025'!F:G,2,FALSE) -> CA26
A17: CAM110-Sortant sms LIBERCOM | B17: 232047 | C17: 232047 | D17: -232047 | E17: 0 | F17: =LEFT(A17,6) -> CAM110 | G17: =VLOOKUP(PROD_CAMOBILE_2025M1!A17,'Analyse Réel 01-2025'!F:G,2,FALSE) -> CA27
A18: CAM115-Sortant sms INTERNATIONAL | B18: 2620917 | C18: -2620917 | D18: -2620917 | E18: 5241834 | F18: =LEFT(A18,6) -> CAM115 | G18: =VLOOKUP(PROD_CAMOBILE_2025M1!A18,'Analyse Réel 01-2025'!F:G,2,FALSE) -> CA28
A19: CAM120-Total SMS Sortant | B19: 5322275 | C19: 80441 | D19: -4150411 | E19: 5241834 | F19: =LEFT(A19,6) -> CAM120 | G19: =VLOOKUP(PROD_CAMOBILE_2025M1!A19,'Analyse Réel 01-2025'!F:G,2,FALSE) -> CA29
A20: CAM125-Revenu Internet 3G | B20: 3391819301 | C20: 0 | D20: 0 | E20: 3391819301 | F20: =LEFT(A20,6) -> CAM125 | G20: =VLOOKUP(PROD_CAMOBILE_2025M1!A20,'Analyse Réel 01-2025'!F:G,2,FALSE) -> CA31
A21: CAM130-CRBT | B21: 132797 | C21: -132797 | D21: -132797 | E21: 265594 | F21: =LEFT(A21,6) -> CAM130 | G21: =VLOOKUP(PROD_CAMOBILE_2025M1!A21,'Analyse Réel 01-2025'!F:G,2,FALSE) -> CA33
A22: CAM135-Crédit secours | B22: 117373380 | C22: -117373380 | D22: -117373380 | E22: 234746760 | F22: =LEFT(A22,6) -> CAM135 | G22: =VLOOKUP(PROD_CAMOBILE_2025M1!A22,'Analyse Réel 01-2025'!F:G,2,FALSE) -> CA34
A23: CAM140-Story Box | B23: 0 | C23: -129418045 | D23: -129418045 | E23: 129418045 | F23: =LEFT(A23,6) -> CAM140 | G23: =VLOOKUP(PROD_CAMOBILE_2025M1!A23,'Analyse Réel 01-2025'!F:G,2,FALSE) -> CA35
A24: CAM145-Phonebook STK | B24: 0 | C24: -129418045 | D24: -129418045 | E24: 129418045 | F24: =LEFT(A24,6) -> CAM145 | G24: =VLOOKUP(PROD_CAMOBILE_2025M1!A24,'Analyse Réel 01-2025'!F:G,2,FALSE) -> CA36
A25: CAM150-Gaming | B25: 0 | C25: -129418045 | D25: -129418045 | E25: 129418045 | F25: =LEFT(A25,6) -> CAM150 | G25: =VLOOKUP(PROD_CAMOBILE_2025M1!A25,'Analyse Réel 01-2025'!F:G,2,FALSE) -> CA37
A26: CAM155-Autres (VOICEALERT,MOOVKDO...) | B26: 0 | C26: -129418045 | D26: -129418045 | E26: 129418045 | F26: =LEFT(A26,6) -> CAM155 | G26: =VLOOKUP(PROD_CAMOBILE_2025M1!A26,'Analyse Réel 01-2025'!F:G,2,FALSE) -> CA38
A27: CAM160-Videos | B27: 0 | C27: -129418045 | D27: -129418045 | E27: 129418045 | F27: =LEFT(A27,6) -> CAM160 | G27: =VLOOKUP(PROD_CAMOBILE_2025M1!A27,'Analyse Réel 01-2025'!F:G,2,FALSE) -> CA39
... A145: CAM005-CA Global | B145: 7556427339 | C145: -208519772 | D145: -5910137752 | E145: 7764947111 | F145: =LEFT(A145,6) -> CAM005 | G145: =VLOOKUP(PROD_CAMOBILE_2025M1!A145,'Analyse Réel 01-2025'!F:G,2,FALSE) -> CA1

Sheet Données MOOV 01-2025
E1: 0
A2: CA Mobile
D4: 45658
B5: (En Millions ML) | D5: 2025 Réel | E5: 2025 Budget | F5: Ecart / Budget | G5: 2024 Réel | H5: Evol %
A8: CA Global | C8: CA1 | D8: 8324.9028 | E8: 9527.0891 | F8: -1202.1863 | G8: 9480.8077 | H8: -0.12192051
C9: CA2
B10: dont CA Etat | C10: CA3
C11: CA4
A12: CA services Mobile | C12: CA5 | D12: 8118.3484 | E12: 9340.117 | F12: -1221.7686 | G12: 9400.2691 | H12: -0.13637063
C13: CA6 | G13: 0
A14: CA récurrent | C14: CA7 | D14: 7983.1451 | E14: 9190.3209 | F14: -1207.1757 | G14: 9314.5768 | H14: -0.14294065
C15: CA8 | G15: 0
A16: CA sortant | C16: CA9 | D16: 7739.2918 | E16: 8900.1169 | F16: -1160.8251 | G16: 9000.8894 | H16: -0.14016366
B17: Prépayé (yc commissions) | C17: CA10 | D17: 3180.332 | E17: 3844.6975 | F17: -664.36549 | G17: 4134.0606 | H17: -0.23070019
A18: Consumer Prepaid | C18: CA11 | D18: 3180.332 | E18: 3844.6975 | F18: -664.36549 | G18: 4134.0606 | H18: -0.23070019
B19: Frais d'activation & Sim swap | C19: CA12 | D19: -9.204763 | E19: -22.461806 | F19: 13.257043 | G19: -34.062214 | H19: -0.72976616
B20: Sortant voix on net | C20: CA13 | D20: 1325.2425 | E20: 1532.0023 | F20: -206.7598 | G20: 1925.9137 | H20: -0.31188896
B21: Sortant voix MTN | C21: CA14 | D21: 1093.7671 | E21: 1964.2889 | F21: -870.52183 | G21: 1821.5085 | H21: -0.39952676
B22: Sortant voix GLO | C22: CA15 | D22: 0 | E22: 0 | F22: 0 | G22: 0
B23: Sortant voix BBCOM | C23: CA16 | D23: 0 | E23: 0 | G23: 0
B24: Sortant voix LIBERCOM | C24: CA17 | D24: 0 | E24: 134.85752 | F24: -134.85752 | G24: 0
B25: Sortant voix BTSA | C25: CA18 | D25: 477.33819 | E25: 0.26963616 | F25: 477.06855 | G25: 72.348988 | H25: 5.5977176
B26: Sortant voix INTERNATIONAL | C26: CA19 | D26: 159.65992 | E26: 134.97915 | F26: 24.68077 | G26: 206.80959 | H26: -0.22798589
B27: Sortant voix roaming | C27: CA20 | D27: 10.56786 | E27: 16.595851 | F27: -6.0279905 | G27: 12.72778 | H27: -0.16970124
B28: Total VOIX Sortant | C28: CA21 | D28: 3066.5755 | E28: 3782.9934 | F28: -716.41781 | G28: 4039.3085 | H28: -0.24081671
C29: CA22 | E29: 0 | G29: 0
B30: Sortant sms on net | C30: CA23 | D30: 1.236479 | E30: 1.2104351 | F30: 0.026043887 | G30: 1.899627 | H30: -0.3490938
B31: Sortant sms MTN | C31: CA24 | D31: 1.231451 | E31: 1.3495968 | F31: -0.11814585 | G31: 1.765875 | H31: -0.30263977
B32: Sortant sms GLO | C32: CA25 | D32: 0 | E32: 0 | F32: 0 | G32: 0
B33: Sortant sms BBCOM | C33: CA26 | D33: 0.001381 | E33: 0.0020104274 | F33: -0.00062942739 | G33: 0.001729
B34: Sortant sms LIBERCOM | C34: CA27 | D34: 0.232047 | E34: 0.40805876 | F34: -0.17601176 | G34: 0.444316
B35: Sortant sms INTERNATIONAL | C35: CA28 | D35: 2.620917 | E35: 1.7264834 | F35: 0.89443356 | G35: 2.610107 | H35: 0.0041415927
B36: Total SMS Sortant | C36: CA29 | D36: 5.322275 | E36: 4.6965846 | F36: 0.62569041 | G36: 6.721654 | H36: -0.20818968
C37: CA30 | G37: 0
B38: Revenu Internet 3G | C38: CA31 | D38: 3391.8193 | E38: 3972.9579 | F38: -581.13862 | G38: 3929.1116 | H38: -0.13674651
C39: CA32 | G39: 0
B40: CRBT | C40: CA33 | D40: 0.132797 | E40: 0.2890989 | F40: -0.1563019 | G40: 0.565572 | H40: -0.76519877
B41: Crédit secours | C41: CA34 | D41: 7.7828593 | E41: 6.5450633 | F41: 1.237796 | G41: 11.089769 | H41: -0.29819465
B42: Story Box | C42: CA35 | D42: 0 | E42: 0 | F42: 0 | G42: 0
B43: Phonebook STK | C43: CA36 | D43: 0 | E43: 0 | F43: 0 | G43: 0
...

Sheet Analyse Réel 01-2025
A1: Réalisé 2025 - Données MOOV | F1: Réalisé 2025 - Données X3 Base PROD | I1: Données X3 - Test | J1: Formule indicateur | K1: Formule indicateur | L1: Ecart | M1: actualisation des RG | N1: Calcul OK | O1: REMARQUES
A2: CA Global | C2: CA1 | D2: =VLOOKUP(C2,'Données MOOV 01-2025'!C:D,2,FALSE) -> 8324.9028 | E2: =D2*1000000 -> 8.3249028e+09 | F2: CAM005-CA Global | G2: CA1 | H2: =VLOOKUP(F2,PROD_CAMOBILE_2025M1!A:B,2,FALSE) -> 7556427339 | I2: 9882621663 | J2: =VLOOKUP(F2,'Formule TDB'!B:C,2,FALSE) -> R(L139+L142) | K2: R(L139+L142) | L2: =E2-H2 -> 7.6847544e+08 | N2: Calcul avec écart
A3: CA services Mobile | C3: CA5 | D3: =VLOOKUP(C3,'Données MOOV 01-2025'!C:D,2,FALSE) -> 8118.3484 | E3: =D3*1000000 -> 8.1183484e+09 | F3: CAM015-CA services Mobile | G3: CA5 | H3: =VLOOKUP(F3,PROD_CAMOBILE_2025M1!A:B,2,FALSE) -> 7349873003 | I3: 9802083009 | J3: =VLOOKUP(F3,'Formule TDB'!B:C,2,FALSE) -> R(L135+L141) | K3: R(L135+L141) | L3: =E3-H3 -> 7.6847544e+08 | N3: Aucun équivalence sur TDB X3
A4: CA récurrent | C4: CA7 | D4: =VLOOKUP(C4,'Données MOOV 01-2025'!C:D,2,FALSE) -> 7983.1451 | E4: =D4*1000000 -> 7.9831451e+09 | F4: CAM020-CA récurrent | G4: CA7 | H4: =VLOOKUP(F4,PROD_CAMOBILE_2025M1!A:B,2,FALSE) -> 7315602945 | I4: 9753598008 | J4: =VLOOKUP(F4,'Formule TDB'!B:C,2,FALSE) -> R(L134+L140) | K4: R(L134+L140) | L4: =E4-H4 -> 6.6754219e+08
A5: CA sortant | C5: CA9 | D5: =VLOOKUP(C5,'Données MOOV 01-2025'!C:D,2,FALSE) -> 7739.2918 | E5: =D5*1000000 -> 7.7392918e+09 | F5: CAM025-CA Sortant | G5: CA9 | H5: =VLOOKUP(F5,PROD_CAMOBILE_2025M1!A:B,2,FALSE) -> 7132612739 | I5: 9511898580 | J5: =VLOOKUP(F5,'Formule TDB'!B:C,2,FALSE) -> R(L30+L110+L111+L112+L113) | K5: R(L30+L110+L111+L112+L113) | L5: =E5-H5 -> 6.0667907e+08
A6: Consumer Prepaid | C6: CA11 | D6: =VLOOKUP(C6,'Données MOOV 01-2025'!C:D,2,FALSE) -> 3180.332 | E6: =D6*1000000 -> 3.180332e+09 | F6: CAM035-Consumer Prepaid | G6: CA11 | H6: =VLOOKUP(F6,PROD_CAMOBILE_2025M1!A:B,2,FALSE) -> 3180246680 | I6: 4671622639 | J6: =VLOOKUP(F6,'Formule TDB'!B:C,2,FALSE) -> R(L1+L10+L17+L26) | K6: R(L1+L10+L17+L26) | L6: =E6-H6 -> 85351 | N6: Action correctives
B7: Frais d'activation & Sim swap | C7: CA12 | D7: =VLOOKUP(C7,'Données MOOV 01-2025'!C:D,2,FALSE) -> -9.204763 | E7: =D7*1000000 -> -9204763 | F7: CAM040-Frais d'activation & Sim swap | G7: CA12 | H7: =VLOOKUP(F7,PROD_CAMOBILE_2025M1!A:B,2,FALSE) -> -9204763 | I7: -34062214 | J7: =VLOOKUP(F7,'Formule TDB'!B:C,2,FALSE) -> -701120 -701130 | K7: -701120 -701130 | L7: =E7-H7 -> 0
B8: Sortant voix on net | C8: CA13 | D8: =VLOOKUP(C8,'Données MOOV 01-2025'!C:D,2,FALSE) -> 1325.2425 | E8: =D8*1000000 -> 1.3252425e+09 | F8: CAM045-Sortant voix on net | G8: CA13 | H8: =VLOOKUP(F8,PROD_CAMOBILE_2025M1!A:B,2,FALSE) -> 1295717222 | I8: 1891504933 | J8: =VLOOKUP(F8,'Formule TDB'!B:C,2,FALSE) -> -NM(706120,*,A61,*,*,*,*,*,*,*) -NM(706920,*,A58,*,*,*,*,*,*,*) | K8: -NM(706120,*,A61,*,*,*,*,*,*,*) -NM(706920,*,A58,*,*,*,*,*,*,*) | L8: =E8-H8 -> 29525256 | M8: NM(706120,*,A61,*,*,*,*,*,*,*) -NM(706920,*,A58,*,*,*,*,*,*,*) + somme( CA consumer D29:D34) | N8: Besoin du ficher CA consumer + RG actualisées | O8: Cet écart provient des retraitements manuels effectués sur les bonus( voir feuille CA Consumer Somme L6 à11) | P8: =SUM('CA Consumer'!D6:D11) -> 29572702
B9: Sortant voix MTN | C9: CA14 | D9: =VLOOKUP(C9,'Données MOOV 01-2025'!C:D,2,FALSE) -> 1093.7671 | E9: =D9*1000000 -> 1.0937671e+09 | F9: CAM050-Sortant voix MTN | G9: CA14 | H9: =VLOOKUP(F9,PROD_CAMOBILE_2025M1!A:B,2,FALSE) -> 1123059001 | I9: 1855699449 | J9: =VLOOKUP(F9,'Formule TDB'!B:C,2,FALSE) -> -NM(706121,*,A48,*,*,*,*,*,*,*) | K9: -NM(706121,*,A48,*,*,*,*,*,*,*) | L9: =E9-H9 -> -29291907 | M9: NM(706121,*,A48,*,*,*,*,*,*,*) - CA consumer D29 | O9: Cet écart provient des retraitements manuels effectués sur les bonus( voir feuille CA Consumer L6) | P9: ='CA Consumer'!D6 -> 29291907
B10: Sortant voix GLO | C10: CA15 | D10: =VLOOKUP(C10,'Données MOOV 01-2025'!C:D,2,FALSE) -> 0 | E10: =D10*1000000 -> 0 | F10: CAM055-Sortant voix GLO | G10: CA15 | H10: =VLOOKUP(F10,PROD_CAMOBILE_2025M1!A:B,2,FALSE) -> 0 | I10: 0 | J10: =VLOOKUP(F10,'Formule TDB'!B:C,2,FALSE) -> -NM(706121,*,*A49,*,*,*,*,*,*,*) | K10: -NM(706121,*,*A49,*,*,*,*,*,*,*) | L10: =E10-H10 -> 0
B11: Sortant voix BBCOM | C11: CA16 | D11: =VLOOKUP(C11,'Données MOOV 01-2025'!C:D,2,FALSE) -> 0 | E11: =D11*1000000 -> 0 | F11: CAM060-Sortant voix BBCOM | G11: CA16 | H11: =VLOOKUP(F11,PROD_CAMOBILE_2025M1!A:B,2,FALSE) -> 0 | I11: 0 | J11: =VLOOKUP(F11,'Formule TDB'!B:C,2,FALSE) -> -NM(706121,*,*A50,*,*,*,*,*,*,*) | K11: -NM(706121,*,*A50,*,*,*,*,*,*,*) | L11: =E11-H11 -> 0
B12: Sortant voix LIBERCOM | C12: CA17 | D12: =VLOOKUP(C12,'Données MOOV 01-2025'!C:D,2,FALSE) -> 0 | E12: =D12*1000000 -> 0 | F12: CAM065-Sortant voix LIBERCOM | G12: CA17 | H12: =VLOOKUP(F12,PROD_CAMOBILE_2025M1!A:B,2,FALSE) -> 0 | I12: 0 | J12: =VLOOKUP(F12,'Formule TDB'!B:C,2,FALSE) -> -NM(706121,*,*A51,*,*,*,*,*,*,*) | K12: -NM(706121,*,*A51,*,*,*,*,*,*,*) | L12: =E12-H12 -> 0
B13: Sortant voix BTSA | C13: CA18 | D13: =VLOOKUP(C13,'Données MOOV 01-2025'!C:D,2,FALSE) -> 477.33819 | E13: =D13*1000000 -> 4.7733819e+08 | F13: CAM070-Sortant voix BTSA | G13: CA18 | H13: =VLOOKUP(F13,PROD_CAMOBILE_2025M1!A:B,2,FALSE) -> 477346316 | I13: 72356625 | J13: =VLOOKUP(F13,'Formule TDB'!B:C,2,FALSE) -> -NM(706123,*,A52,*,*,*,*,*,*,*) | K13: -NM(706123,*,A52,*,*,*,*,*,*,*) | L13: =E13-H13 -> -8124.8475 | M13: NM(706123,*,A52,*,*,*,*,*,*,*) - CA consumer D33 | O13: Cet écart provient des retraitements manuels effectués sur les bonus( voir feuille CA Consumer L10) | P13: ='CA Consumer'!D10 -> 8124.8475
B14: Sortant voix INTERNATIONAL | C14: CA19 | D14: =VLOOKUP(C14,'Données MOOV 01-2025'!C:D,2,FALSE) -> 159.65992 | E14: =D14*1000000 -> 1.5965992e+08 | F14: CAM075-Sortant voix INTERNATIONAL | G14: CA19 | H14: =VLOOKUP(F14,PROD_CAMOBILE_2025M1!A:B,2,FALSE) -> 159932592 | I14: 207019754 | J14: =VLOOKUP(F14,'Formule TDB'!B:C,2,FALSE) -> -NM(706124,*,A53,*,*,*,*,*,*,*) | K14: -NM(706124,*,A53,*,*,*,*,*,*,*) | L14: =E14-H14 -> -272670.34 | M14: NM(706124,*,A53,*,*,*,*,*,*,*) - CA consumer D34 | O14: Cet écart provient des retraitements manuels effectués sur les bonus( voir feuille CA Consumer L11) | P14: ='CA Consumer'!D11 -> 272670.34
B15: Sortant voix roaming | C15: CA20 | D15: =VLOOKUP(C15,'Données MOOV 01-2025'!C:D,2,FALSE) -> 10.56786 | E15: =D15*1000000 -> 10567860 | F15: CAM080-Sortant voix roaming | G15: CA20 | H15: =VLOOKUP(F15,PROD_CAMOBILE_2025M1!A:B,2,FALSE) -> 10567860 | I15: 12727780 | J15: =VLOOKUP(F15,'Formule TDB'!B:C,2,FALSE) -> -NM(706140,*,A54,*,*,*,*,*,*,*) | K15: -NM(706140,*,A54,*,*,*,*,*,*,*) | L15: =E15-H15 -> 0
B16: Total VOIX Sortant | C16: CA21 | D16: =VLOOKUP(C16,'Données MOOV 01-2025'!C:D,2,FALSE) -> 3066.5755 | E16: =D16*1000000 -> 3.0665755e+09 | F16: CAM085-Total VOIX Sortant | G16: CA21 | H16: =VLOOKUP(F16,PROD_CAMOBILE_2025M1!A:B,2,FALSE) -> 3066622991 | I16: 4039308541 | J16: =VLOOKUP(F16,'Formule TDB'!B:C,2,FALSE) -> $CAMOBILE.#(L2:9) | K16: $CAMOBILE.#(L2:9) | L16: =E16-H16 -> -47446 | O16: Somme des écarts L8-9-13-14
B17: Sortant sms on net | C17: CA23 | D17: =VLOOKUP(C17,'Données MOOV 01-2025'!C:D,2,FALSE) -> 1.236479 | E17: =D17*1000000 -> 1236479 | F17: CAM090-Sortant sms on net | G17: CA23 | H17: =VLOOKUP(F17,PROD_CAMOBILE_2025M1!A:B,2,FALSE) -> 1236479 | I17: 1899627 | J17: =VLOOKUP(F17,'Formule TDB'!B:C,2,FALSE) -> -NM(706117,*,T21,*,*,*,*,*,*,*) -NM(706920,*,A59,*,*,*,*,*,*,*) | K17: -NM(706117,*,T21,*,*,*,*,*,*,*) -NM(706920,*,A59,*,*,*,*,*,*,*) | L17: =E17-H17 -> 0
B18: Sortant sms MTN | C18: CA24 | D18: =VLOOKUP(C18,'Données MOOV 01-2025'!C:D,2,FALSE) -> 1.231451 | E18: =D18*1000000 -> 1231451 | F18: CAM095-Sortant sms MTN | G18: CA24 | H18: =VLOOKUP(F18,PROD_CAMOBILE_2025M1!A:B,2,FALSE) -> 1231451 | I18: 1765875 | J18: =VLOOKUP(F18,'Formule TDB'!B:C,2,FALSE) -> -NM(706117,*,A48,*,*,*,*,*,*,*) | K18: -NM(706117,*,A48,*,*,*,*,*,*,*) | L18: =E18-H18 -> 0
B19: Sortant sms GLO | C19: CA25 | D19: =VLOOKUP(C19,'Données MOOV 01-2025'!C:D,2,FALSE) -> 0 | E19: =D19*1000000 -> 0 | F19: CAM0100-Sortant sms GLO | G19: CA25 | H19: =VLOOKUP(F19,PROD_CAMOBILE_2025M1!A:B,2,FALSE) -> 0 | I19: 0 | J19: =VLOOKUP(F19,'Formule TDB'!B:C,2,FALSE) -> -NM(706117,*,A49,*,*,*,*,*,*,*) | K19: -NM(706117,*,A49,*,*,*,*,*,*,*) | L19: =E19-H19 -> 0
B20: Sortant sms BBCOM | C20: CA26 | D20: =VLOOKUP(C20,'Données MOOV 01-2025'!C:D,2,FALSE) -> 0.001381 | E20: =D20*1000000 -> 1381 | F20: CAM105-Sortant sms BBCOM | G20: CA26 | H20: =VLOOKUP(F20,PROD_CAMOBILE_2025M1!A:B,2,FALSE) -> 1381 | I20: 1729 | J20: =VLOOKUP(F20,'Formule TDB'!B:C,2,FALSE) -> -NM(706117,*,A50,*,*,*,*,*,*,*) | K20: -NM(706117,*,A50,*,*,*,*,*,*,*) | L20: =E20-H20 -> 0
B21: Sortant sms LIBERCOM | C21: CA27 | D21: =VLOOKUP(C21,'Données MOOV 01-2025'!C:D,2,FALSE) -> 0.232047 | E21: =D21*1000000 -> 232047 | F21: CAM110-Sortant sms LIBERCOM | G21: CA27 | H21: =VLOOKUP(F21,PROD_CAMOBILE_2025M1!A:B,2,FALSE) -> 232047 | I21: 444316 | J21: =VLOOKUP(F21,'Formule TDB'!B:C,2,FALSE) -> -NM(706117,*,A51,*,*,*,*,*,*,*) | K21: -NM(706117,*,A51,*,*,*,*,*,*,*) | L21: =E21-H21 -> 0
B22: Sortant sms INTERNATIONAL | C22: CA28 | D22: =VLOOKUP(C22,'Données MOOV 01-2025'!C:D,2,FALSE) -> 2.620917 | E22: =D22*1000000 -> 2620917 | F22: CAM115-Sortant sms INTERNATIONAL | G22: CA28 | H22: =VLOOKUP(F22,PROD_CAMOBILE_2025M1!A:B,2,FALSE) -> 2620917 | I22: 2610107 | J22: =VLOOKUP(F22,'Formule TDB'!B:C,2,FALSE) -> -NM(706117,*,A53,*,*,*,*,*,*,*) | K22: -NM(706117,*,A53,*,*,*,*,*,*,*) | L22: =E22-H22 -> 0
B23: Total SMS Sortant | C23: CA29 | D23: =VLOOKUP(C23,'Données MOOV 01-2025'!C:D,2,FALSE) -> 5.322275 | E23: =D23*1000000 -> 5322275 | F23: CAM120-Total SMS Sortant | G23: CA29 | H23: =VLOOKUP(F23,PROD_CAMOBILE_2025M1!A:B,2,FALSE) -> 5322275 | I23: 6721654 | J23: =VLOOKUP(F23,'Formule TDB'!B:C,2,FALSE) -> $CAMOBILE.#(L11:16) | K23: $CAMOBILE.#(L11:16) | L23: =E23-H23 -> 0
B24: Revenu Internet 3G | C24: CA31 | D24: =VLOOKUP(C24,'Données MOOV 01-2025'!C:D,2,FALSE) -> 3391.8193 | E24: =D24*1000000 -> 3391819301 | F24: CAM125-Revenu Internet 3G | G24: CA31 | H24: =VLOOKUP(F24,PROD_CAMOBILE_2025M1!A:B,2,FALSE) -> 3391819301 | I24: 3929111582 | J24: =VLOOKUP(F24,'Formule TDB'!B:C,2,FALSE) -> -NM(706153,*,A55,*,*,*,*,*,*,*) -NM(706920,*,A60,*,*,*,*,*,*,*) | K24: -NM(706153,*,A55,*,*,*,*,*,*,*) -NM(706920,*,A60,*,*,*,*,*,*,*) | L24: =E24-H24 -> 0
B25: CRBT | C25: CA33 | D25: =VLOOKUP(C25,'Données MOOV 01-2025'!C:D,2,FALSE) -> 0.132797 | E25: =D25*1000000 -> 132797 | F25: CAM130-CRBT | G25: CA33 | H25: =VLOOKUP(F25,PROD_CAMOBILE_2025M1!A:B,2,FALSE) -> 132797 | I25: 565572 | J25: =VLOOKUP(F25,'Formule TDB'!B:C,2,FALSE) -> -NM(706151,*,A57,*,*,*,*,*,*,*) | K25: -NM(706151,*,A57,*,*,*,*,*,*,*) | L25: =E25-H25 -> 0
B26: Crédit secours | C26: CA34 | D26: =VLOOKUP(C26,'Données MOOV 01-2025'!C:D,2,FALSE) -> 7.7828593 | E26: =D26*1000000 -> 7782859.3 | F26: CAM135-Crédit secours | G26: CA34 | H26: =VLOOKUP(F26,PROD_CAMOBILE_2025M1!A:B,2,FALSE) -> 117373380 | I26: 121527054 | J26: =VLOOKUP(F26,'Formule TDB'!B:C,2,FALSE) -> -NM(706151,*,A56,*,*,*,*,*,*,*) | K26: -NM(706151,*,A56,*,*,*,*,*,*,*) | L26: =E26-H26 -> -1.0959052e+08 | M26: Fichiers externe, Cellule D4 de la feuille crédits secours | N26: Besoin du fichier crédit Secour + RG actualisées | O26: Le montant des crédits secours est déterminé dans un fichier annexe
B27: Story Box | C27: CA35 | D27: =VLOOKUP(C27,'Données MOOV 01-2025'!C:D,2,FALSE) -> 0 | E27: =D27*1000000 -> 0 | F27: CAM140-Story Box | G27: CA35 | H27: =VLOOKUP(F27,PROD_CAMOBILE_2025M1!A:B,2,FALSE) -> 0 | I27: 134390508 | J27: =VLOOKUP(F27,'Formule TDB'!B:C,2,FALSE) -> -0*NM(706151,*,*,*,*,*,*,*,*) | K27: -0*NM(706151,*,*,*,*,*,*,*,*) | L27: =E27-H27 -> 0
B28: Phonebook STK | C28: CA36 | D28: =VLOOKUP(C28,'Données MOOV 01-2025'!C:D,2,FALSE) -> 0 | E28: =D28*1000000 -> 0 | F28: CAM145-Phonebook STK | G28: CA36 | H28: =VLOOKUP(F28,PROD_CAMOBILE_2025M1!A:B,2,FALSE) -> 0 | I28: 0 | J28: =VLOOKUP(F28,'Formule TDB'!B:C,2,FALSE) -> #VALUE! | K28: #VALUE! | L28: =E28-H28 -> 0
B29: Gaming | C29: CA37 | D29: =VLOOKUP(C29,'Données MOOV 01-2025'!C:D,2,FALSE) -> 0 | E29: =D29*1000000 -> 0 | F29: CAM150-Gaming | G29: CA37 | H29: =VLOOKUP(F29,PROD_CAMOBILE_2025M1!A:B,2,FALSE) -> 0 | I29: 134390508 | J29: =VLOOKUP(F29,'Formule TDB'!B:C,2,FALSE) -> -0*NM(706151,*,*,*,*,*,*,*,*) | K29: -0*NM(706151,*,*,*,*,*,*,*,*) | L29: =E29-H29 -> 0
B30: Autres dont BAC17 (VOICEALERT,MOOVKDO...) & SAV agences | C30: CA38 | D30: =VLOOKUP(C30,'Données MOOV 01-2025'!C:D,2,FALSE) -> 109.72332 | E30: =D30*1000000 -> 1.0972332e+08 | F30: CAM155-Autres (VOICEALERT,MOOVKDO...) | G30: CA38 | H30: =VLOOKUP(F30,PROD_CAMOBILE_2025M1!A:B,2,FALSE) -> 0 | I30: 134390508 | J30: =VLOOKUP(F30,'Formule TDB'!B:C,2,FALSE) -> -0*NM(706151,*,*,*,*,*,*,*,*) | K30: -0*NM(706151,*,*,*,*,*,*,*,*) | L30: =E30-H30 -> 1.0972332e+08 | M30: -NM(706151,*,A56,*,*,*,*,*,*,*) oté du montant des crédits secours, ligne 26 | O30: Cette ligne "autre" comporte le total des lignes précédentes oté du montant des crédits secours
B31: Videos | C31: CA39 | D31: =VLOOKUP(C31,'Données MOOV 01-2025'!C:D,2,FALSE) -> 0 | E31: =D31*1000000 -> 0 | F31: CAM160-Videos | G31: CA39 | H31: =VLOOKUP(F31,PROD_CAMOBILE_2025M1!A:B,2,FALSE) -> 0 | I31: 134390508 | J31: =VLOOKUP(F31,'Formule TDB'!B:C,2,FALSE) -> -0*NM(706151,*,*,*,*,*,*,*,*) | K31: -0*NM(706151,*,*,*,*,*,*,*,*) | L31: =E31-H31 -> 0
B32: Total Data | C32: CA40 | D32: =VLOOKUP(C32,'Données MOOV 01-2025'!C:D,2,FALSE) -> 117.63897 | E32: =D32*1000000 -> 1.1763897e+08 | F32: CAM165-Total Data | G32: CA40 | H32: =VLOOKUP(F32,PROD_CAMOBILE_2025M1!A:B,2,FALSE) -> 117506177 | I32: 659654658 | J32: =VLOOKUP(F32,'Formule TDB'!B:C,2,FALSE) -> $CAMOBILE.#(L19:25) | K32: $CAMOBILE.#(L19:25) | L32: =E32-H32 -> 132797 | O32: Cet ecart doit etre corrigé
B33: dont CA voix | C33: CA42 | E33: =D33*1000000 -> 0 | G33: CA42 | H33: =VLOOKUP(F33,PROD_CAMOBILE_2025M1!A:B,2,FALSE) -> #N/A | J33: =VLOOKUP(F33,'Formule TDB'!B:C,2,FALSE) -> #N/A | K33: #N/A | L33: =E33-H33 -> #N/A
B34: dont CA SMS | C34: CA43 | E34: =D34*1000000 -> 0 | G34: CA43 | H34: =VLOOKUP(F34,PROD_CAMOBILE_2025M1!A:B,2,FALSE) -> #N/A | J34: =VLOOKUP(F34,'Formule TDB'!B:C,2,FALSE) -> #N/A | K34: #N/A | L34: =E34-H34 -> #N/A
B35: dont SVA (Sce à Val. Ajoutée) | C35: CA44 | D35: =VLOOKUP(C35,'Données MOOV 01-2025'!C:D,2,FALSE) -> 0 | E35: =D35*1000000 -> 0 | F35: CAM170-Dont CA SVA ( Sce à Val Ajoutéé) | G35: CA44 | H35: =VLOOKUP(F35,PROD_CAMOBILE_2025M1!A:B,2,FALSE) -> 0 | I35: 0 | J35: =VLOOKUP(F35,'Formule TDB'!B:C,2,FALSE) -> 0 | K35: 0 | L35: =E35-H35 -> 0
B36: dont CA Internet 3G | C36: CA45 | D36: =VLOOKUP(C36,'Données MOOV 01-2025'!C:D,2,FALSE) -> 3391.8193 | E36: =D36*1000000 -> 3391819301 | F36: CAM185-dont CA Internet 3G | G36: CA45 | H36: =VLOOKUP(F36,PROD_CAMOBILE_2025M1!A:B,2,FALSE) -> 3391819301 | I36: 3929111582 | J36: =VLOOKUP(F36,'Formule TDB'!B:C,2,FALSE) -> L18 | K36: L18 | L36: =E36-H36 -> 0
B37: Postpayé | C37: CA46 | D37: =VLOOKUP(C37,'Données MOOV 01-2025'!C:D,2,FALSE) -> 283.3024 | E37: =D37*1000000 -> 283302398 | F37: CAM447-Postpayé | G37: CA46 | H37: =VLOOKUP(F37,PROD_CAMOBILE_2025M1!A:B,2,FALSE) -> 279811823 | I37: 689925758 | J37: =VLOOKUP(F37,'Formule TDB'!B:C,2,FALSE) -> R(L34+L109) | K37: R(L34+L109) | L37: =E37-H37 -> 3490575 | O37: Ligne Total
B38: Redevance d'abonnement | C38: CA47 | D38: =VLOOKUP(C38,'Données MOOV 01-2025'!C:D,2,FALSE) -> 210.72997 | E38: =D38*1000000 -> 210729966 | F38: CAM195-Redevance d'abonnement | G38: CA47 | H38: =VLOOKUP(F38,PROD_CAMOBILE_2025M1!A:B,2,FALSE) -> 210729966 | I38: 201054859 | J38: =VLOOKUP(F38,'Formule TDB'!B:C,2,FALSE) -> R(L31+L32+L33) | K38: R(L31+L32+L33) | L38: =E38-H38 -> 0
A39: Consumer Postpaid | C39: CA48 | D39: =VLOOKUP(C39,'Données MOOV 01-2025'!C:D,2,FALSE) -> 10.744112 | E39: =D39*1000000 -> 10744112 | F39: CAM200-Red Consumer Postpaid | G39: CA48 | H39: =VLOOKUP(F39,PROD_CAMOBILE_2025M1!A:B,2,FALSE) -> 10744112 | I39: -10210921 | J39: =VLOOKUP(F39,'Formule TDB'!B:C,2,FALSE) -> -706115 NM(706115,*,A27,*,*,*,*,*,*,*) NM(706115,*,A29,*,*,*,*,*,*,*) NM(706115,*,W99,*,*,*,*,*,*,*) NM(706115,*,V99,*,*,*,*,*,*,*) NM(706115,*,U99,*,*,*,*,*,*,*) NM(706115,*,T15,*,*,*,*,*,*,*) NM(706115,*,S99,*,*,*,*,*,*,*) | K39: -706115 NM(706115,*,A27,*,*,*,*,*,*,*) NM(706115,*,A29,*,*,*,*,*,*,*) NM(706115,*,W99,*,*,*,*,*,*,*) NM(706115,*,V99,*,*,*,*,*,*,*) NM(706115,*,U99,*,*,*,*,*,*,*) NM(706115,*,T15,*,*,*,*,*,*,*) NM(706115,*,S99,*,*,*,*,*,*,*) | L39: =E39-H39 -> 0
A40: Business Postpaid | C40: CA49 | D40: =VLOOKUP(C40,'Données MOOV 01-2025'!C:D,2,FALSE) -> 14.508871 | E40: =D40*1000000 -> 14508871 | F40: CAM205-Red Business Postpaid | G40: CA49 | H40: =VLOOKUP(F40,PROD_CAMOBILE_2025M1!A:B,2,FALSE) -> 14508871 | I40: 20653505 | J40: =VLOOKUP(F40,'Formule TDB'!B:C,2,FALSE) -> -NM(706115,*,T15,*,*,*,*,*,*) | K40: -NM(706115,*,T15,*,*,*,*,*,*) | L40: =E40-H40 -> 0
...

Sheet COMPTES
A1: COMPTES MOOV MONEY
A2: 706161 | B2: Revenu Moov Money Cash Out
A3: 706162 | B3: Revenu Moov Money P2P
A4: 706163 | B4: Revenu Moov Money Bank
A5: 706164 | B5: Revenu Moov Money internationa
A6: 706165 | B6: Revenu Moov Money Bill Paiemen
A10: ROAMING NATIONAL
A11: 706143 | B11: ROAMING NATIONAL VOIX
A12: 706144 | B12: ROAMING NATIONAL SMS
A13: 706145 | B13: ROAMING NATIONAL DATA
A17: ROAMING IN
A18: 706142 | B18: ROAMING VISITEURS
A19: 706143 | B19: ROAMING NATIONAL VOIX
A20: 706144 | B20: ROAMING NATIONAL SMS
A21: 706145 | B21: ROAMING NATIONAL DATA

Sheet CA Consumer
C1: CHIFFRE D'AFFAIRES CONSUMER AU 31 JANVIER 2025
C2: LIBELLE | D2: MONTANT EN HT | E2: COMPTES | F2: AXE 2
C3: Gratuités
C4: Consommation Etisalat staff Pré paid (HT) | D4: 0 | E4: 628110
C5: Bonus sur Voix on net | D5: 30324286 | E5: 701920 | F5: A17
C6: Bonus sur Voix off net national mtn | D6: 29291907
C7: Bonus sur Voix off net national glo
C8: Bonus sur Voix off net national bbcom | D8: 0
C9: Bonus sur Voix off net national libercom
C10: Bonus sur Voix off net national opt | D10: 8124.8475
C11: Bonus sur Voix off net international | D11: 272670.34
C12: Bonus sur SMS | D12: 59586.678 | E12: 701920 | F12: A22
C13: Bonus sur Data | D13: 1.491349e+09 | E13: 701920 | F13: A25
C14: Crédits donnés (Hors Cos Etisalat) | E14: 658200
C15: TOTAL CA PRE PAID (Hors Consommation Cos Etisalat et Crédits donnés...)

Sheet CA Business
C1: CHIFFRE D'AFFAIRES BUSINESS AU 31 JANVIER 2025
C2: LIBELLE | D2: MONTANT EN HT | E2: COMPTES | F2: AXE 2
C3: Gratuités
C4: Consommation Etisalat staff Pré paid (HT) | E4: 628110
C5: Bonus sur Voix on net | D5: 22818904 | E5: 701920 | F5: A17
C6: Bonus sur Voix off net national mtn | D6: 55885253
C7: Bonus sur Voix off net national glo
C8: Bonus sur Voix off net national bbcom
C9: Bonus sur Voix off net national libercom
C10: Bonus sur Voix off net national opt | D10: 97320.831
C11: Bonus sur Voix off net international | D11: 1474601.6
C12: Bonus sur SMS | D12: 215991.1 | E12: 701920 | F12: A22
C13: Bonus sur Data | D13: 63833113 | E13: 701920 | F13: A25
C14: Crédits donnés (Hors Cos Etisalat) | E14: 658200
C15: TOTAL CA PRE PAID (Hors Consommation Cos Etisalat et Crédits donnés...)
