Workbook
Name \e: #N/A
Name \M: #REF!
Name \M: #REF!
Name \M: #REF!
Name \M: #REF!
Name \M: #REF!
Name \p: '[1]Cur Q v Plan'!#REF!
Name \p: '[1]Cur Q v Plan'!#REF!
Name \p: '[1]Cur Q v Plan'!#REF!
Name \p: '[1]Cur Q v Plan'!#REF!
Name \p: '[1]Cur Q v Plan'!#REF!
Name \p: '[1]Cur Q v Plan'!#REF!
Name \p: '[1]Cur Q v Plan'!#REF!
Name \p: '[1]Cur Q v Plan'!#REF!
Name \p: '[1]Cur Q v Plan'!#REF!
Name \p: '[2]Cur Q v Plan'!#REF!
Name \p: '[1]Cur Q v Plan'!#REF!
Name \p: '[1]Cur Q v Plan'!#REF!
Name \p: '[1]Cur Q v Plan'!#REF!
Name \r: #N/A
Name \t: #N/A
Name _: #N/A
Name _???: #N/A
Name __???: #N/A
Name ___???: #N/A
Name ____???: #N/A
Name _____???: #N/A
Name ______???: #N/A
Name _______???: #N/A
Name ________???: #N/A
Name __________________________R: #REF!
Name __________________________R: #REF!
Name __________________________R: #REF!
Name __________________________R: #REF!
Name __________________________R: #REF!
Name __________________________R: #REF!
Name __________________________R: #REF!
Name __________________________R: #REF!
Name __________________________R: #REF!
Name __________________________R: #REF!
Name __________________________R: #REF!
Name __________________________R: #REF!
Name __________________________SC16: #REF!
Name __________________________SC16: #REF!
Name __________________________SC16: #REF!
Name __________________________SC16: #REF!
Name __________________________SC16: #REF!
Name __________________________SC16: #REF!
Name __________________________SC16: #REF!
Name __________________________SC16: #REF!
Name __________________________SC16: #REF!
Name __________________________SC16: #REF!
Name __________________________SC16: #REF!
Name __________________________SC16: #REF!
Name _________________________R: #REF!
Name _________________________R: #REF!
Name _________________________R: #REF!
Name _________________________R: #REF!
Name _________________________R: #REF!
Name _________________________R: #REF!

Sheet Cover
X13: Devise : | Y13: En millions de FCFA
E16: Package Stand Alone IFRS Etisalat Bénin | X16: Date d'ouverture : | Y16: 44562
E18: =+Y18 -> 44926 | X18: Date de clôture : | Y18: 44926
X20: Cellule saisissable
X21: Cellule non saisissable
X23: Produits | Y23: (+)
X24: Charges | Y24: (-)
X25: Amortissements des actifs | Y25: (-)
X26: Provisions pour dépréciation des actifs | Y26: (-)

Sheet Sommaire
B3: Sommaire
B5: Comptes sociaux - Normes OHADA | D5: Page | F5: Liens hypertextes
B6: Balance Générale | D6: 4 | F6: Balance Générale
B7: Bilan - Actif | D7: 5 | F7: Bilan - Actif
B8: Bilan - Passif | D8: 6 | F8: Bilan - Passif
B9: Compte de résultat | D9: 7 | F9: Compte de résultat
B11: Matrice de passage OHADA - Normes IFRS
B12: Passage Bilan - Actif | D12: 9 | F12: Passage Bilan - Actif
B13: Passage Bilan - Passif | D13: 10 | F13: Passage Bilan - Passif
B14: Passage Compte de résultat - par nature | D14: 11 | F14: Passage Compte de résultat - par nature
B15: Passage Compte de résultat - par fonction | D15: 12 | F15: Passage Compte de résultat - par fonction
B16: Bilan par flux | D16: 13 | F16: Bilan par flux
B18: Comptes IFRS
B19: Bilan simplifié | D19: 15 | F19: Bilan simplifié
B20: P&L - par nature | D20: 16 | F20: P&L par nature
B21: P&L - par fonction | D21: 17 | F21: P&L par fonction
B23: Notes annexes IFRS
B24: Actifs financiers non courants | D24: 19 | F24: Actifs financiers non courants
B25: Actifs financiers courants | D25: 20 | F25: Actifs financiers courants
B26: Fair value hierarchy | D26: 21 | F26: Fair value hierarchy
B27: Stocks | D27: 22 | F27: Stocks
B28: Cartes SIM | D28: 23 | F28: Cartes SIM
B29: Effectif | D29: 24 | F29: Effectif
A30: NEW | B30: Clients et comptes rattachés-Ageing | D30: 25 | F30: Clients et comptes rattachés - Ageing
A31: NEW | B31: Fournisseurs et comptes rattachés - Ageing | D31: 26 | F31: Fournisseurs et comptes rattachés - Ageing
A32: NEW | B32: Dettes sur acquisition d'immobilisations | D32: 27 | F32: Dettes sur acquisition d'immobilisations
B33: Synthèse FND | D33: 28 | F33: Synthèse FND
B34: Dettes financières à long terme | D34: 29 | F34: Dettes financières à long terme
B35: Dettes financières à court terme | D35: 30 | F35: Dettes financières à court terme
B36: Trésorerie et équivalent de trésorerie | D36: 31 | F36: Trésorerie et équivalent de trésorerie
B37: Risque de change | D37: 32 | F37: Risque de change
B38: Covenants | D38: 33 | F38: Covenants
B39: Nature des provisions-passif | D39: 34 | F39: Provision par nature
B40: Maturité des provisions-passif | D40: 35 | F40: Maturité des provisions - passif
B41: Taux effectif d'impôt | D41: 36 | F41: Taux effectif d'impôt
B42: Nature des impôts différés actifs et passifs | D42: 37 | F42: Nature des impôts différés actifs et passifs
B43: Dividendes | D43: 38 | F43: Dividendes
B44: Dettes SHL | D44: 39 | F44: Dettes SHL
... B51: PIDR | D51: 45 | F51: PIDR
B53: Contrôles de cohérence
...

Sheet <<Social>>
F16: Comptes sociaux OHADA

Sheet BG 
A1: Sommaire | F1: 1 | G1: -1 | H1: 1 | I1: -1 | J1: 1 | K1: -1
A2: Balance Générale | F2: Solde au 01/01/2021 | H2: MOUVEMENT2021 | J2: Solde au 31/06/21
A3: Nº Compte | B3: Libellé | C3: IFRS | D3: Classe | E3: A2 | F3: Débit 2021 | G3: Crédit 2021 | H3: Débit 2022 | I3: Crédit 2022 | J3: Débit 2022 | K3: Crédit 2022
A4: 101000 | B4: CAPITAL SOCIAL | C4: SN1131 | D4: =+LEFT(A4,2) -> 10 | F4: =(+IFERROR(VLOOKUP($A4,'[152]BG (2)'!$B$9:$J$570,4,FALSE),0))*1 -> 0 | G4: =(+IFERROR(VLOOKUP($A4,'[152]BG (2)'!$B$9:$J$570,5,FALSE),0))*-1 -> -10408280000 | H4: =(+IFERROR(VLOOKUP($A4,'[152]BG (2)'!$B$9:$J$570,6,FALSE),0))*1 -> 0 | I4: =(+IFERROR(VLOOKUP($A4,'[152]BG (2)'!$B$9:$J$570,7,FALSE),0))*-1 -> 0 | J4: =(+IFERROR(VLOOKUP($A4,'[152]BG (2)'!$B$9:$J$570,8,FALSE),0))*1 -> 0 | K4: =(+IFERROR(VLOOKUP($A4,'[152]BG (2)'!$B$9:$J$570,9,FALSE),0))*-1 -> -10408280000 | P4: =J4+K4 -> -10408280000 | T4: =K4+J4 -> -10408280000 | W4: =+A4-#REF! -> #REF!
A5: 101200 | B5: CAPITAL SOUSCRIT APPELE NON VE | D5: =+LEFT(A5,2) -> 10 | F5: =(+IFERROR(VLOOKUP($A5,'[152]BG (2)'!$B$9:$J$570,4,FALSE),0))*1 -> 0 | G5: =(+IFERROR(VLOOKUP($A5,'[152]BG (2)'!$B$9:$J$570,5,FALSE),0))*-1 -> 0 | H5: =(+IFERROR(VLOOKUP($A5,'[152]BG (2)'!$B$9:$J$570,6,FALSE),0))*1 -> 0 | I5: =(+IFERROR(VLOOKUP($A5,'[152]BG (2)'!$B$9:$J$570,7,FALSE),0))*-1 -> 0 | J5: =(+IFERROR(VLOOKUP($A5,'[152]BG (2)'!$B$9:$J$570,8,FALSE),0))*1 -> 0 | K5: =(+IFERROR(VLOOKUP($A5,'[152]BG (2)'!$B$9:$J$570,9,FALSE),0))*-1 -> 0 | P5: =J5+K5 -> 0 | T5: =K5+J5 -> 0 | W5: =+A5-#REF! -> #REF!
A6: 121000 | B6: REPORT A NOUVEAU CREDITEUR | C6: SN1131 | D6: =+LEFT(A6,2) -> 12 | F6: =(+IFERROR(VLOOKUP($A6,'[152]BG (2)'!$B$9:$J$570,4,FALSE),0))*1 -> 0 | G6: =(+IFERROR(VLOOKUP($A6,'[152]BG (2)'!$B$9:$J$570,5,FALSE),0))*-1 -> -11797647055 | H6: =(+IFERROR(VLOOKUP($A6,'[152]BG (2)'!$B$9:$J$570,6,FALSE),0))*1 -> 0 | I6: =(+IFERROR(VLOOKUP($A6,'[152]BG (2)'!$B$9:$J$570,7,FALSE),0))*-1 -> -4015179140 | J6: =(+IFERROR(VLOOKUP($A6,'[152]BG (2)'!$B$9:$J$570,8,FALSE),0))*1 -> 0 | K6: =(+IFERROR(VLOOKUP($A6,'[152]BG (2)'!$B$9:$J$570,9,FALSE),0))*-1 -> -15812826195 | P6: =J6+K6 -> -15812826195 | T6: =K6+J6 -> -15812826195 | W6: =+A6-#REF! -> #REF!
A7: 129000 | B7: REPORT A NOUVEAU DEBITEUR | C7: SN1131 | D7: =+LEFT(A7,2) -> 12 | F7: =(+IFERROR(VLOOKUP($A7,'[152]BG (2)'!$B$9:$J$570,4,FALSE),0))*1 -> 17260503796 | G7: =(+IFERROR(VLOOKUP($A7,'[152]BG (2)'!$B$9:$J$570,5,FALSE),0))*-1 -> 0 | H7: =(+IFERROR(VLOOKUP($A7,'[152]BG (2)'!$B$9:$J$570,6,FALSE),0))*1 -> 0 | I7: =(+IFERROR(VLOOKUP($A7,'[152]BG (2)'!$B$9:$J$570,7,FALSE),0))*-1 -> 0 | J7: =(+IFERROR(VLOOKUP($A7,'[152]BG (2)'!$B$9:$J$570,8,FALSE),0))*1 -> 17260503796 | K7: =(+IFERROR(VLOOKUP($A7,'[152]BG (2)'!$B$9:$J$570,9,FALSE),0))*-1 -> 0 | P7: =J7+K7 -> 17260503796 | T7: =K7+J7 -> 17260503796 | W7: =+A7-#REF! -> #REF!
A8: 130100 | B8: RESULTAT NET EN INSTANCE D'AFF | D8: =+LEFT(A8,2) -> 13 | F8: =(+IFERROR(VLOOKUP($A8,'[152]BG (2)'!$B$9:$J$570,4,FALSE),0))*1 -> 0 | G8: =(+IFERROR(VLOOKUP($A8,'[152]BG (2)'!$B$9:$J$570,5,FALSE),0))*-1 -> -219020909 | H8: =(+IFERROR(VLOOKUP($A8,'[152]BG (2)'!$B$9:$J$570,6,FALSE),0))*1 -> 0 | I8: =(+IFERROR(VLOOKUP($A8,'[152]BG (2)'!$B$9:$J$570,7,FALSE),0))*-1 -> 0 | J8: =(+IFERROR(VLOOKUP($A8,'[152]BG (2)'!$B$9:$J$570,8,FALSE),0))*1 -> 0 | K8: =(+IFERROR(VLOOKUP($A8,'[152]BG (2)'!$B$9:$J$570,9,FALSE),0))*-1 -> -219020909 | P8: =J8+K8 -> -219020909 | T8: =K8+J8 -> -219020909 | W8: =+A8-#REF! -> #REF!
A9: 130900 | B9: RESULTAT NET EN INSTANCE D'AFF | C9: SN1132 | D9: =+LEFT(A9,2) -> 13 | F9: =(+IFERROR(VLOOKUP($A9,'[152]BG (2)'!$B$9:$J$570,4,FALSE),0))*1 -> 0 | G9: =(+IFERROR(VLOOKUP($A9,'[152]BG (2)'!$B$9:$J$570,5,FALSE),0))*-1 -> 0 | H9: =(+IFERROR(VLOOKUP($A9,'[152]BG (2)'!$B$9:$J$570,6,FALSE),0))*1 -> 0 | I9: =(+IFERROR(VLOOKUP($A9,'[152]BG (2)'!$B$9:$J$570,7,FALSE),0))*-1 -> 0 | J9: =(+IFERROR(VLOOKUP($A9,'[152]BG (2)'!$B$9:$J$570,8,FALSE),0))*1 -> 0 | K9: =(+IFERROR(VLOOKUP($A9,'[152]BG (2)'!$B$9:$J$570,9,FALSE),0))*-1 -> 0 | P9: =J9+K9 -> 0 | T9: =K9+J9 -> 0 | W9: =+A9-#REF! -> #REF!
A10: 131000 | B10: RESULTAT NET : BENEFICE | D10: =+LEFT(A10,2) -> 13 | F10: =(+IFERROR(VLOOKUP($A10,'[152]BG (2)'!$B$9:$J$570,4,FALSE),0))*1 -> 0 | G10: =(+IFERROR(VLOOKUP($A10,'[152]BG (2)'!$B$9:$J$570,5,FALSE),0))*-1 -> -4015179140 | H10: =(+IFERROR(VLOOKUP($A10,'[152]BG (2)'!$B$9:$J$570,6,FALSE),0))*1 -> 4015179140 | I10: =(+IFERROR(VLOOKUP($A10,'[152]BG (2)'!$B$9:$J$570,7,FALSE),0))*-1 -> 0 | J10: =(+IFERROR(VLOOKUP($A10,'[152]BG (2)'!$B$9:$J$570,8,FALSE),0))*1 -> 0 | K10: =(+IFERROR(VLOOKUP($A10,'[152]BG (2)'!$B$9:$J$570,9,FALSE),0))*-1 -> 0 | P10: =J10+K10 -> 0 | T10: =K10+J10 -> 0 | W10: =+A10-#REF! -> #REF!
A11: 139000 | B11: RESULTAT NET : PERTE | D11: =+LEFT(A11,2) -> 13 | F11: =(+IFERROR(VLOOKUP($A11,'[152]BG (2)'!$B$9:$J$570,4,FALSE),0))*1 -> 0 | G11: =(+IFERROR(VLOOKUP($A11,'[152]BG (2)'!$B$9:$J$570,5,FALSE),0))*-1 -> 0 | H11: =(+IFERROR(VLOOKUP($A11,'[152]BG (2)'!$B$9:$J$570,6,FALSE),0))*1 -> 0 | I11: =(+IFERROR(VLOOKUP($A11,'[152]BG (2)'!$B$9:$J$570,7,FALSE),0))*-1 -> 0 | J11: =(+IFERROR(VLOOKUP($A11,'[152]BG (2)'!$B$9:$J$570,8,FALSE),0))*1 -> 0 | K11: =(+IFERROR(VLOOKUP($A11,'[152]BG (2)'!$B$9:$J$570,9,FALSE),0))*-1 -> 0 | P11: =J11+K11 -> 0 | T11: =K11+J11 -> 0 | W11: =+A11-#REF! -> #REF!
A12: 148000 | B12: SUBVENTION D'INVESTISSEMENT | D12: =+LEFT(A12,2) -> 14 | F12: =(+IFERROR(VLOOKUP($A12,'[152]BG (2)'!$B$9:$J$570,4,FALSE),0))*1 -> 0 | G12: =(+IFERROR(VLOOKUP($A12,'[152]BG (2)'!$B$9:$J$570,5,FALSE),0))*-1 -> 0 | H12: =(+IFERROR(VLOOKUP($A12,'[152]BG (2)'!$B$9:$J$570,6,FALSE),0))*1 -> 535112960 | I12: =(+IFERROR(VLOOKUP($A12,'[152]BG (2)'!$B$9:$J$570,7,FALSE),0))*-1 -> -1830627040 | J12: =(+IFERROR(VLOOKUP($A12,'[152]BG (2)'!$B$9:$J$570,8,FALSE),0))*1 -> 0 | K12: =(+IFERROR(VLOOKUP($A12,'[152]BG (2)'!$B$9:$J$570,9,FALSE),0))*-1 -> -1295514080 | P12: =J12+K12 -> -1295514080
A13: 161101 | B13: EMPRUNTS CAA | C13: PNC1606 | D13: =+LEFT(A13,2) -> 16 | F13: =(+IFERROR(VLOOKUP($A13,'[152]BG (2)'!$B$9:$J$570,4,FALSE),0))*1 -> 0 | G13: =(+IFERROR(VLOOKUP($A13,'[152]BG (2)'!$B$9:$J$570,5,FALSE),0))*-1 -> -564773615 | H13: =(+IFERROR(VLOOKUP($A13,'[152]BG (2)'!$B$9:$J$570,6,FALSE),0))*1 -> 188257874 | I13: =(+IFERROR(VLOOKUP($A13,'[152]BG (2)'!$B$9:$J$570,7,FALSE),0))*-1 -> 0 | J13: =(+IFERROR(VLOOKUP($A13,'[152]BG (2)'!$B$9:$J$570,8,FALSE),0))*1 -> 0 | K13: =(+IFERROR(VLOOKUP($A13,'[152]BG (2)'!$B$9:$J$570,9,FALSE),0))*-1 -> -376515741 | P13: =J13+K13 -> -376515741 | T13: =K13+J13 -> -376515741 | W13: =+A13-#REF! -> #REF!
A14: 162000 | B14: EMPRUNTS BANCAIRES | C14: PNC1602 | D14: =+LEFT(A14,2) -> 16 | F14: =(+IFERROR(VLOOKUP($A14,'[152]BG (2)'!$B$9:$J$570,4,FALSE),0))*1 -> 0 | G14: =(+IFERROR(VLOOKUP($A14,'[152]BG (2)'!$B$9:$J$570,5,FALSE),0))*-1 -> 0 | H14: =(+IFERROR(VLOOKUP($A14,'[152]BG (2)'!$B$9:$J$570,6,FALSE),0))*1 -> 0 | I14: =(+IFERROR(VLOOKUP($A14,'[152]BG (2)'!$B$9:$J$570,7,FALSE),0))*-1 -> 0 | J14: =(+IFERROR(VLOOKUP($A14,'[152]BG (2)'!$B$9:$J$570,8,FALSE),0))*1 -> 0 | K14: =(+IFERROR(VLOOKUP($A14,'[152]BG (2)'!$B$9:$J$570,9,FALSE),0))*-1 -> 0 | P14: =J14+K14 -> 0 | T14: =K14+J14 -> 0 | W14: =+A14-#REF! -> #REF!
A15: 162200 | B15: EMPRUNT GOLDEN FALCON INVESTIS | C15: PNC1603 | D15: =+LEFT(A15,2) -> 16 | F15: =(+IFERROR(VLOOKUP($A15,'[152]BG (2)'!$B$9:$J$570,4,FALSE),0))*1 -> 0 | G15: =(+IFERROR(VLOOKUP($A15,'[152]BG (2)'!$B$9:$J$570,5,FALSE),0))*-1 -> 0 | H15: =(+IFERROR(VLOOKUP($A15,'[152]BG (2)'!$B$9:$J$570,6,FALSE),0))*1 -> 0 | I15: =(+IFERROR(VLOOKUP($A15,'[152]BG (2)'!$B$9:$J$570,7,FALSE),0))*-1 -> 0 | J15: =(+IFERROR(VLOOKUP($A15,'[152]BG (2)'!$B$9:$J$570,8,FALSE),0))*1 -> 0 | K15: =(+IFERROR(VLOOKUP($A15,'[152]BG (2)'!$B$9:$J$570,9,FALSE),0))*-1 -> 0 | P15: =J15+K15 -> 0 | T15: =K15+J15 -> 0 | W15: =+A15-#REF! -> #REF!
A16: 162300 | B16: EMPRUNT CORIS BANK | C16: PNC1602 | D16: =+LEFT(A16,2) -> 16 | F16: =(+IFERROR(VLOOKUP($A16,'[152]BG (2)'!$B$9:$J$570,4,FALSE),0))*1 -> 0 | G16: =(+IFERROR(VLOOKUP($A16,'[152]BG (2)'!$B$9:$J$570,5,FALSE),0))*-1 -> -10771050910 | H16: =(+IFERROR(VLOOKUP($A16,'[152]BG (2)'!$B$9:$J$570,6,FALSE),0))*1 -> 3847116856 | I16: =(+IFERROR(VLOOKUP($A16,'[152]BG (2)'!$B$9:$J$570,7,FALSE),0))*-1 -> -921026219 | J16: =(+IFERROR(VLOOKUP($A16,'[152]BG (2)'!$B$9:$J$570,8,FALSE),0))*1 -> 0 | K16: =(+IFERROR(VLOOKUP($A16,'[152]BG (2)'!$B$9:$J$570,9,FALSE),0))*-1 -> -7844960273 | P16: =J16+K16 -> -7844960273 | U16: =K13+K15+K16 -> -8221476014 | V16: =G11+G14+G15 -> 0 | W16: =+A16-#REF! -> #REF!
A17: 162400 | B17: EMPRUNT BANK OF AFRICA (BOA) | C17: PNC1602 | D17: =+LEFT(A17,2) -> 16 | F17: =(+IFERROR(VLOOKUP($A17,'[152]BG (2)'!$B$9:$J$570,4,FALSE),0))*1 -> 0 | G17: =(+IFERROR(VLOOKUP($A17,'[152]BG (2)'!$B$9:$J$570,5,FALSE),0))*-1 -> -14830776943 | H17: =(+IFERROR(VLOOKUP($A17,'[152]BG (2)'!$B$9:$J$570,6,FALSE),0))*1 -> 2073985135 | I17: =(+IFERROR(VLOOKUP($A17,'[152]BG (2)'!$B$9:$J$570,7,FALSE),0))*-1 -> -5000000000 | J17: =(+IFERROR(VLOOKUP($A17,'[152]BG (2)'!$B$9:$J$570,8,FALSE),0))*1 -> 0 | K17: =(+IFERROR(VLOOKUP($A17,'[152]BG (2)'!$B$9:$J$570,9,FALSE),0))*-1 -> -17756791808 | P17: =J17+K17 -> -17756791808 | AC17: =4994500000/1000000 -> 4994.5
A18: 162500 | B18: EMPRUNT CBAO | C18: PNC1602 | D18: =+LEFT(A18,2) -> 16 | F18: =(+IFERROR(VLOOKUP($A18,'[152]BG (2)'!$B$9:$J$570,4,FALSE),0))*1 -> 0 | G18: =(+IFERROR(VLOOKUP($A18,'[152]BG (2)'!$B$9:$J$570,5,FALSE),0))*-1 -> -20000000000 | H18: =(+IFERROR(VLOOKUP($A18,'[152]BG (2)'!$B$9:$J$570,6,FALSE),0))*1 -> 2098417244 | I18: =(+IFERROR(VLOOKUP($A18,'[152]BG (2)'!$B$9:$J$570,7,FALSE),0))*-1 -> 0 | J18: =(+IFERROR(VLOOKUP($A18,'[152]BG (2)'!$B$9:$J$570,8,FALSE),0))*1 -> 0 | K18: =(+IFERROR(VLOOKUP($A18,'[152]BG (2)'!$B$9:$J$570,9,FALSE),0))*-1 -> -17901582756 | P18: =J18+K18 -> -17901582756
A19: 165200 | B19: AUTRES CAUTIONNEMENTS | C19: PC4736 /PNC1608 | D19: =+LEFT(A19,2) -> 16 | F19: =(+IFERROR(VLOOKUP($A19,'[152]BG (2)'!$B$9:$J$570,4,FALSE),0))*1 -> 0 | G19: =(+IFERROR(VLOOKUP($A19,'[152]BG (2)'!$B$9:$J$570,5,FALSE),0))*-1 -> -1297000 | H19: =(+IFERROR(VLOOKUP($A19,'[152]BG (2)'!$B$9:$J$570,6,FALSE),0))*1 -> 0 | I19: =(+IFERROR(VLOOKUP($A19,'[152]BG (2)'!$B$9:$J$570,7,FALSE),0))*-1 -> 0 | J19: =(+IFERROR(VLOOKUP($A19,'[152]BG (2)'!$B$9:$J$570,8,FALSE),0))*1 -> 0 | K19: =(+IFERROR(VLOOKUP($A19,'[152]BG (2)'!$B$9:$J$570,9,FALSE),0))*-1 -> -1297000 | P19: =J19+K19 -> -1297000 | T19: =K19+J19 -> -1297000 | W19: =+A19-#REF! -> #REF!
A20: 165210 | B20: CAUTIONS DISTRIBUTEURS & POSTP | C20: PC4736 /PNC1608 | D20: =+LEFT(A20,2) -> 16 | F20: =(+IFERROR(VLOOKUP($A20,'[152]BG (2)'!$B$9:$J$570,4,FALSE),0))*1 -> 0 | G20: =(+IFERROR(VLOOKUP($A20,'[152]BG (2)'!$B$9:$J$570,5,FALSE),0))*-1 -> -307748479 | H20: =(+IFERROR(VLOOKUP($A20,'[152]BG (2)'!$B$9:$J$570,6,FALSE),0))*1 -> 1260500 | I20: =(+IFERROR(VLOOKUP($A20,'[152]BG (2)'!$B$9:$J$570,7,FALSE),0))*-1 -> -20756200 | J20: =(+IFERROR(VLOOKUP($A20,'[152]BG (2)'!$B$9:$J$570,8,FALSE),0))*1 -> 0 | K20: =(+IFERROR(VLOOKUP($A20,'[152]BG (2)'!$B$9:$J$570,9,FALSE),0))*-1 -> -327244179 | P20: =J20+K20 -> -327244179 | T20: =K20+J20 -> -327244179 | U20: =K22+K21 -> -692693489 | V20: =G21+G20 -> -310493907 | W20: =+A20-#REF! -> #REF!
A21: 166101 | B21: INTERETS COURUS SUR EMPRUNTS S | C21: PC4716 | D21: =+LEFT(A21,2) -> 16 | F21: =(+IFERROR(VLOOKUP($A21,'[152]BG (2)'!$B$9:$J$570,4,FALSE),0))*1 -> 0 | G21: =(+IFERROR(VLOOKUP($A21,'[152]BG (2)'!$B$9:$J$570,5,FALSE),0))*-1 -> -2745428 | H21: =(+IFERROR(VLOOKUP($A21,'[152]BG (2)'!$B$9:$J$570,6,FALSE),0))*1 -> 0 | I21: =(+IFERROR(VLOOKUP($A21,'[152]BG (2)'!$B$9:$J$570,7,FALSE),0))*-1 -> 1961020 | J21: =(+IFERROR(VLOOKUP($A21,'[152]BG (2)'!$B$9:$J$570,8,FALSE),0))*1 -> 0 | K21: =(+IFERROR(VLOOKUP($A21,'[152]BG (2)'!$B$9:$J$570,9,FALSE),0))*-1 -> -784408 | P21: =J21+K21 -> -784408 | T21: =K21+J21 -> -784408 | W21: =+A21-#REF! -> #REF!
A22: 166200 | B22: INTERETS COURUS / EMPRUNTS BAN | C22: PC4722 | D22: =+LEFT(A22,2) -> 16 | F22: =(+IFERROR(VLOOKUP($A22,'[152]BG (2)'!$B$9:$J$570,4,FALSE),0))*1 -> 0 | G22: =(+IFERROR(VLOOKUP($A22,'[152]BG (2)'!$B$9:$J$570,5,FALSE),0))*-1 -> -907777903 | H22: =(+IFERROR(VLOOKUP($A22,'[152]BG (2)'!$B$9:$J$570,6,FALSE),0))*1 -> -265360986 | I22: =(+IFERROR(VLOOKUP($A22,'[152]BG (2)'!$B$9:$J$570,7,FALSE),0))*-1 -> 481229808 | J22: =(+IFERROR(VLOOKUP($A22,'[152]BG (2)'!$B$9:$J$570,8,FALSE),0))*1 -> 0 | K22: =(+IFERROR(VLOOKUP($A22,'[152]BG (2)'!$B$9:$J$570,9,FALSE),0))*-1 -> -691909081 | P22: =J22+K22 -> -691909081 | T22: =K22+J22 -> -691909081 | U22: -13665075378 | V22: -9204504573 | W22: =+A22-#REF! -> #REF!
A23: 166210 | B23: INTERETS COURUS EMPRUNTS AFREX | C23: PC4722 | D23: =+LEFT(A23,2) -> 16 | F23: =(+IFERROR(VLOOKUP($A23,'[152]BG (2)'!$B$9:$J$570,4,FALSE),0))*1 -> 0 | G23: =(+IFERROR(VLOOKUP($A23,'[152]BG (2)'!$B$9:$J$570,5,FALSE),0))*-1 -> -3 | H23: =(+IFERROR(VLOOKUP($A23,'[152]BG (2)'!$B$9:$J$570,6,FALSE),0))*1 -> 0 | I23: =(+IFERROR(VLOOKUP($A23,'[152]BG (2)'!$B$9:$J$570,7,FALSE),0))*-1 -> 0 | J23: =(+IFERROR(VLOOKUP($A23,'[152]BG (2)'!$B$9:$J$570,8,FALSE),0))*1 -> 0 | K23: =(+IFERROR(VLOOKUP($A23,'[152]BG (2)'!$B$9:$J$570,9,FALSE),0))*-1 -> -3 | P23: =J23+K23 -> -3 | T23: =K23+J23 -> -3 | W23: =+A23-#REF! -> #REF!
A24: 166220 | B24: INTERETS COURUS EMPRUNTS GOLDE | C24: PNC1603 | D24: =+LEFT(A24,2) -> 16 | F24: =(+IFERROR(VLOOKUP($A24,'[152]BG (2)'!$B$9:$J$570,4,FALSE),0))*1 -> 0 | G24: =(+IFERROR(VLOOKUP($A24,'[152]BG (2)'!$B$9:$J$570,5,FALSE),0))*-1 -> 0 | H24: =(+IFERROR(VLOOKUP($A24,'[152]BG (2)'!$B$9:$J$570,6,FALSE),0))*1 -> 0 | I24: =(+IFERROR(VLOOKUP($A24,'[152]BG (2)'!$B$9:$J$570,7,FALSE),0))*-1 -> 0 | J24: =(+IFERROR(VLOOKUP($A24,'[152]BG (2)'!$B$9:$J$570,8,FALSE),0))*1 -> 0 | K24: =(+IFERROR(VLOOKUP($A24,'[152]BG (2)'!$B$9:$J$570,9,FALSE),0))*-1 -> 0 | P24: =J24+K24 -> 0 | T24: =K24+J24 -> 0 | U24: =K24 -> 0 | V24: =G23 -> -3 | W24: =+A24-#REF! -> #REF!
A25: 196000 | B25: PROVISIONS POUR PENSIONS ET OB | C25: PNC1504/PC4504 | D25: =+LEFT(A25,2) -> 19 | F25: =(+IFERROR(VLOOKUP($A25,'[152]BG (2)'!$B$9:$J$570,4,FALSE),0))*1 -> 0 | G25: =(+IFERROR(VLOOKUP($A25,'[152]BG (2)'!$B$9:$J$570,5,FALSE),0))*-1 -> -75886080 | H25: =(+IFERROR(VLOOKUP($A25,'[152]BG (2)'!$B$9:$J$570,6,FALSE),0))*1 -> 0 | I25: =(+IFERROR(VLOOKUP($A25,'[152]BG (2)'!$B$9:$J$570,7,FALSE),0))*-1 -> 0 | J25: =(+IFERROR(VLOOKUP($A25,'[152]BG (2)'!$B$9:$J$570,8,FALSE),0))*1 -> 0 | K25: =(+IFERROR(VLOOKUP($A25,'[152]BG (2)'!$B$9:$J$570,9,FALSE),0))*-1 -> -75886080 | P25: =J25+K25 -> -75886080 | T25: =K25+J25 -> -75886080 | U25: =SUM(U16:U24) -> -22579244881 | W25: =+A25-#REF! -> #REF!
A26: 196100 | B26: PROVIS° PR PENSIONS ET OB | D26: =+LEFT(A26,2) -> 19 | F26: =(+IFERROR(VLOOKUP($A26,'[152]BG (2)'!$B$9:$J$570,4,FALSE),0))*1 -> 0 | G26: =(+IFERROR(VLOOKUP($A26,'[152]BG (2)'!$B$9:$J$570,5,FALSE),0))*-1 -> -560543234 | H26: =(+IFERROR(VLOOKUP($A26,'[152]BG (2)'!$B$9:$J$570,6,FALSE),0))*1 -> 69932047 | I26: =(+IFERROR(VLOOKUP($A26,'[152]BG (2)'!$B$9:$J$570,7,FALSE),0))*-1 -> -138375073 | J26: =(+IFERROR(VLOOKUP($A26,'[152]BG (2)'!$B$9:$J$570,8,FALSE),0))*1 -> 0 | K26: =(+IFERROR(VLOOKUP($A26,'[152]BG (2)'!$B$9:$J$570,9,FALSE),0))*-1 -> -628986260 | P26: =J26+K26 -> -628986260 | T26: =K26+J26 -> -628986260 | U26: =SUM(U16:U22) -> -22579244881 | W26: =+A26-#REF! -> #REF!
A27: 198000 | B27: AUTRES PROVISIONS FINANCIERES | C27: PNC1501/PC4501 | D27: =+LEFT(A27,2) -> 19 | F27: =(+IFERROR(VLOOKUP($A27,'[152]BG (2)'!$B$9:$J$570,4,FALSE),0))*1 -> 0 | G27: =(+IFERROR(VLOOKUP($A27,'[152]BG (2)'!$B$9:$J$570,5,FALSE),0))*-1 -> -315691792 | H27: =(+IFERROR(VLOOKUP($A27,'[152]BG (2)'!$B$9:$J$570,6,FALSE),0))*1 -> 60096576 | I27: =(+IFERROR(VLOOKUP($A27,'[152]BG (2)'!$B$9:$J$570,7,FALSE),0))*-1 -> -113600 | J27: =(+IFERROR(VLOOKUP($A27,'[152]BG (2)'!$B$9:$J$570,8,FALSE),0))*1 -> 0 | K27: =(+IFERROR(VLOOKUP($A27,'[152]BG (2)'!$B$9:$J$570,9,FALSE),0))*-1 -> -255708816 | P27: =J27+K27 -> -255708816 | T27: =K27+J27 -> -255708816 | W27: =+A27-#REF! -> #REF!
A28: 198800 | B28: PROVISIONS POUR RISQUES | D28: =+LEFT(A28,2) -> 19 | F28: =(+IFERROR(VLOOKUP($A28,'[152]BG (2)'!$B$9:$J$570,4,FALSE),0))*1 -> 0 | G28: =(+IFERROR(VLOOKUP($A28,'[152]BG (2)'!$B$9:$J$570,5,FALSE),0))*-1 -> -158666718 | H28: =(+IFERROR(VLOOKUP($A28,'[152]BG (2)'!$B$9:$J$570,6,FALSE),0))*1 -> 0 | I28: =(+IFERROR(VLOOKUP($A28,'[152]BG (2)'!$B$9:$J$570,7,FALSE),0))*-1 -> 0 | J28: =(+IFERROR(VLOOKUP($A28,'[152]BG (2)'!$B$9:$J$570,8,FALSE),0))*1 -> 0 | K28: =(+IFERROR(VLOOKUP($A28,'[152]BG (2)'!$B$9:$J$570,9,FALSE),0))*-1 -> -158666718 | P28: =J28+K28 -> -158666718 | T28: =K28+J28 -> -158666718 | W28: =+A28-#REF! -> #REF!
A29: 202800 | B29: CHARGES A ETALER | C29: Annuler en IFRS | D29: =+LEFT(A29,2) -> 20 | F29: =(+IFERROR(VLOOKUP($A29,'[152]BG (2)'!$B$9:$J$570,4,FALSE),0))*1 -> 0 | G29: =(+IFERROR(VLOOKUP($A29,'[152]BG (2)'!$B$9:$J$570,5,FALSE),0))*-1 -> 0 | H29: =(+IFERROR(VLOOKUP($A29,'[152]BG (2)'!$B$9:$J$570,6,FALSE),0))*1 -> 0 | I29: =(+IFERROR(VLOOKUP($A29,'[152]BG (2)'!$B$9:$J$570,7,FALSE),0))*-1 -> 0 | J29: =(+IFERROR(VLOOKUP($A29,'[152]BG (2)'!$B$9:$J$570,8,FALSE),0))*1 -> 0 | K29: =(+IFERROR(VLOOKUP($A29,'[152]BG (2)'!$B$9:$J$570,9,FALSE),0))*-1 -> 0 | P29: =J29+K29 -> 0 | T29: =K29+J29 -> 0 | W29: =+A29-#REF! -> #REF!
A30: 212100 | B30: LICENCES GSM | C30: ANC2240 | D30: =+LEFT(A30,2) -> 21 | F30: =(+IFERROR(VLOOKUP($A30,'[152]BG (2)'!$B$9:$J$570,4,FALSE),0))*1 -> 80000000000 | G30: =(+IFERROR(VLOOKUP($A30,'[152]BG (2)'!$B$9:$J$570,5,FALSE),0))*-1 -> 0 | H30: =(+IFERROR(VLOOKUP($A30,'[152]BG (2)'!$B$9:$J$570,6,FALSE),0))*1 -> 0 | I30: =(+IFERROR(VLOOKUP($A30,'[152]BG (2)'!$B$9:$J$570,7,FALSE),0))*-1 -> 0 | J30: =(+IFERROR(VLOOKUP($A30,'[152]BG (2)'!$B$9:$J$570,8,FALSE),0))*1 -> 80000000000 | K30: =(+IFERROR(VLOOKUP($A30,'[152]BG (2)'!$B$9:$J$570,9,FALSE),0))*-1 -> 0 | P30: =J30+K30 -> 80000000000 | T30: =K30+J30 -> 80000000000 | W30: =+A30-#REF! -> #REF!
A31: 212200 | B31: AUTRES LICENCES ET BREVETS | C31: ANC2221 | D31: =+LEFT(A31,2) -> 21 | F31: =(+IFERROR(VLOOKUP($A31,'[152]BG (2)'!$B$9:$J$570,4,FALSE),0))*1 -> 5886438394 | G31: =(+IFERROR(VLOOKUP($A31,'[152]BG (2)'!$B$9:$J$570,5,FALSE),0))*-1 -> 0 | H31: =(+IFERROR(VLOOKUP($A31,'[152]BG (2)'!$B$9:$J$570,6,FALSE),0))*1 -> 486590555 | I31: =(+IFERROR(VLOOKUP($A31,'[152]BG (2)'!$B$9:$J$570,7,FALSE),0))*-1 -> 0 | J31: =(+IFERROR(VLOOKUP($A31,'[152]BG (2)'!$B$9:$J$570,8,FALSE),0))*1 -> 6373028949 | K31: =(+IFERROR(VLOOKUP($A31,'[152]BG (2)'!$B$9:$J$570,9,FALSE),0))*-1 -> 0 | P31: =J31+K31 -> 6373028949 | T31: =K31+J31 -> 6373028949 | W31: =+A31-#REF! -> #REF!
A32: 213100 | B32: LOGICIELS D'EXPLOITATION TECHN | C32: ANC2222 | D32: =+LEFT(A32,2) -> 21 | F32: =(+IFERROR(VLOOKUP($A32,'[152]BG (2)'!$B$9:$J$570,4,FALSE),0))*1 -> 48010968840 | G32: =(+IFERROR(VLOOKUP($A32,'[152]BG (2)'!$B$9:$J$570,5,FALSE),0))*-1 -> 0 | H32: =(+IFERROR(VLOOKUP($A32,'[152]BG (2)'!$B$9:$J$570,6,FALSE),0))*1 -> 8357348451 | I32: =(+IFERROR(VLOOKUP($A32,'[152]BG (2)'!$B$9:$J$570,7,FALSE),0))*-1 -> 0 | J32: =(+IFERROR(VLOOKUP($A32,'[152]BG (2)'!$B$9:$J$570,8,FALSE),0))*1 -> 56368317291 | K32: =(+IFERROR(VLOOKUP($A32,'[152]BG (2)'!$B$9:$J$570,9,FALSE),0))*-1 -> 0 | P32: =J32+K32 -> 56368317291 | T32: =K32+J32 -> 56368317291 | W32: =+A32-#REF! -> #REF!
A33: 213200 | B33: LOGICIELS AUTRES APPLICATIONS | C33: ANC2222 | D33: =+LEFT(A33,2) -> 21 | F33: =(+IFERROR(VLOOKUP($A33,'[152]BG (2)'!$B$9:$J$570,4,FALSE),0))*1 -> 2155081147 | G33: =(+IFERROR(VLOOKUP($A33,'[152]BG (2)'!$B$9:$J$570,5,FALSE),0))*-1 -> 0 | H33: =(+IFERROR(VLOOKUP($A33,'[152]BG (2)'!$B$9:$J$570,6,FALSE),0))*1 -> 0 | I33: =(+IFERROR(VLOOKUP($A33,'[152]BG (2)'!$B$9:$J$570,7,FALSE),0))*-1 -> 0 | J33: =(+IFERROR(VLOOKUP($A33,'[152]BG (2)'!$B$9:$J$570,8,FALSE),0))*1 -> 2155081147 | K33: =(+IFERROR(VLOOKUP($A33,'[152]BG (2)'!$B$9:$J$570,9,FALSE),0))*-1 -> 0 | P33: =J33+K33 -> 2155081147 | T33: =K33+J33 -> 2155081147 | W33: =+A33-#REF! -> #REF!
A34: 219300 | B34: IMOB INCORP EN COURS / LOGICIE | C34: ANC2222 | D34: =+LEFT(A34,2) -> 21 | F34: =(+IFERROR(VLOOKUP($A34,'[152]BG (2)'!$B$9:$J$570,4,FALSE),0))*1 -> 5581261628 | G34: =(+IFERROR(VLOOKUP($A34,'[152]BG (2)'!$B$9:$J$570,5,FALSE),0))*-1 -> 0 | H34: =(+IFERROR(VLOOKUP($A34,'[152]BG (2)'!$B$9:$J$570,6,FALSE),0))*1 -> -476193229 | I34: =(+IFERROR(VLOOKUP($A34,'[152]BG (2)'!$B$9:$J$570,7,FALSE),0))*-1 -> -3481322210 | J34: =(+IFERROR(VLOOKUP($A34,'[152]BG (2)'!$B$9:$J$570,8,FALSE),0))*1 -> 1623746189 | K34: =(+IFERROR(VLOOKUP($A34,'[152]BG (2)'!$B$9:$J$570,9,FALSE),0))*-1 -> 0 | P34: =J34+K34 -> 1623746189 | T34: =K34+J34 -> 1623746189 | W34: =+A34-#REF! -> #REF!
A35: 223100 | B35: TERRAINS POUR SITES | C35: ANC2310 | D35: =+LEFT(A35,2) -> 22 | F35: =(+IFERROR(VLOOKUP($A35,'[152]BG (2)'!$B$9:$J$570,4,FALSE),0))*1 -> 1197014492 | G35: =(+IFERROR(VLOOKUP($A35,'[152]BG (2)'!$B$9:$J$570,5,FALSE),0))*-1 -> 0 | H35: =(+IFERROR(VLOOKUP($A35,'[152]BG (2)'!$B$9:$J$570,6,FALSE),0))*1 -> 34230581 | I35: =(+IFERROR(VLOOKUP($A35,'[152]BG (2)'!$B$9:$J$570,7,FALSE),0))*-1 -> 0 | J35: =(+IFERROR(VLOOKUP($A35,'[152]BG (2)'!$B$9:$J$570,8,FALSE),0))*1 -> 1231245073 | K35: =(+IFERROR(VLOOKUP($A35,'[152]BG (2)'!$B$9:$J$570,9,FALSE),0))*-1 -> 0 | P35: =J35+K35 -> 1231245073 | T35: =K35+J35 -> 1231245073 | W35: =+A35-#REF! -> #REF!
A36: 223800 | B36: AUTRES TERRAINS BATIS | C36: ANC2310 | D36: =+LEFT(A36,2) -> 22 | F36: =(+IFERROR(VLOOKUP($A36,'[152]BG (2)'!$B$9:$J$570,4,FALSE),0))*1 -> 70000000 | G36: =(+IFERROR(VLOOKUP($A36,'[152]BG (2)'!$B$9:$J$570,5,FALSE),0))*-1 -> 0 | H36: =(+IFERROR(VLOOKUP($A36,'[152]BG (2)'!$B$9:$J$570,6,FALSE),0))*1 -> 0 | I36: =(+IFERROR(VLOOKUP($A36,'[152]BG (2)'!$B$9:$J$570,7,FALSE),0))*-1 -> 0 | J36: =(+IFERROR(VLOOKUP($A36,'[152]BG (2)'!$B$9:$J$570,8,FALSE),0))*1 -> 70000000 | K36: =(+IFERROR(VLOOKUP($A36,'[152]BG (2)'!$B$9:$J$570,9,FALSE),0))*-1 -> 0 | P36: =J36+K36 -> 70000000 | T36: =K36+J36 -> 70000000 | W36: =+A36-#REF! -> #REF!
A37: 229700 | B37: TERRAINS EN COURS D'ACQUISITIO | C37: ANC2310 | D37: =+LEFT(A37,2) -> 22 | F37: =(+IFERROR(VLOOKUP($A37,'[152]BG (2)'!$B$9:$J$570,4,FALSE),0))*1 -> 1724788256 | G37: =(+IFERROR(VLOOKUP($A37,'[152]BG (2)'!$B$9:$J$570,5,FALSE),0))*-1 -> 0 | H37: =(+IFERROR(VLOOKUP($A37,'[152]BG (2)'!$B$9:$J$570,6,FALSE),0))*1 -> 174765000 | I37: =(+IFERROR(VLOOKUP($A37,'[152]BG (2)'!$B$9:$J$570,7,FALSE),0))*-1 -> -30706000 | J37: =(+IFERROR(VLOOKUP($A37,'[152]BG (2)'!$B$9:$J$570,8,FALSE),0))*1 -> 1868847256 | K37: =(+IFERROR(VLOOKUP($A37,'[152]BG (2)'!$B$9:$J$570,9,FALSE),0))*-1 -> 0 | P37: =J37+K37 -> 1868847256 | T37: =K37+J37 -> 1868847256 | W37: =+A37-#REF! -> #REF!
A38: 231100 | B38: BATIMENTS INDUSTRIELS | C38: ANC2320 | D38: =+LEFT(A38,2) -> 23 | F38: =(+IFERROR(VLOOKUP($A38,'[152]BG (2)'!$B$9:$J$570,4,FALSE),0))*1 -> 432753199 | G38: =(+IFERROR(VLOOKUP($A38,'[152]BG (2)'!$B$9:$J$570,5,FALSE),0))*-1 -> 0 | H38: =(+IFERROR(VLOOKUP($A38,'[152]BG (2)'!$B$9:$J$570,6,FALSE),0))*1 -> 0 | I38: =(+IFERROR(VLOOKUP($A38,'[152]BG (2)'!$B$9:$J$570,7,FALSE),0))*-1 -> 0 | J38: =(+IFERROR(VLOOKUP($A38,'[152]BG (2)'!$B$9:$J$570,8,FALSE),0))*1 -> 432753199 | K38: =(+IFERROR(VLOOKUP($A38,'[152]BG (2)'!$B$9:$J$570,9,FALSE),0))*-1 -> 0 | P38: =J38+K38 -> 432753199
A39: 234110 | B39: INFRASTRUCTURES | C39: ANC2330 | D39: =+LEFT(A39,2) -> 23 | F39: =(+IFERROR(VLOOKUP($A39,'[152]BG (2)'!$B$9:$J$570,4,FALSE),0))*1 -> 23553998802 | G39: =(+IFERROR(VLOOKUP($A39,'[152]BG (2)'!$B$9:$J$570,5,FALSE),0))*-1 -> 0 | H39: =(+IFERROR(VLOOKUP($A39,'[152]BG (2)'!$B$9:$J$570,6,FALSE),0))*1 -> 2557864678 | I39: =(+IFERROR(VLOOKUP($A39,'[152]BG (2)'!$B$9:$J$570,7,FALSE),0))*-1 -> 0 | J39: =(+IFERROR(VLOOKUP($A39,'[152]BG (2)'!$B$9:$J$570,8,FALSE),0))*1 -> 26111863480 | K39: =(+IFERROR(VLOOKUP($A39,'[152]BG (2)'!$B$9:$J$570,9,FALSE),0))*-1 -> 0 | P39: =J39+K39 -> 26111863480 | T39: =K39+J39 -> 26111863480 | W39: =+A39-#REF! -> #REF!
A40: 234120 | B40: AMENAGEMENT TECHNIQUE | C40: ANC2330 | D40: =+LEFT(A40,2) -> 23 | F40: =(+IFERROR(VLOOKUP($A40,'[152]BG (2)'!$B$9:$J$570,4,FALSE),0))*1 -> 13060093890 | G40: =(+IFERROR(VLOOKUP($A40,'[152]BG (2)'!$B$9:$J$570,5,FALSE),0))*-1 -> 0 | H40: =(+IFERROR(VLOOKUP($A40,'[152]BG (2)'!$B$9:$J$570,6,FALSE),0))*1 -> 300832814 | I40: =(+IFERROR(VLOOKUP($A40,'[152]BG (2)'!$B$9:$J$570,7,FALSE),0))*-1 -> 0 | J40: =(+IFERROR(VLOOKUP($A40,'[152]BG (2)'!$B$9:$J$570,8,FALSE),0))*1 -> 13360926704 | K40: =(+IFERROR(VLOOKUP($A40,'[152]BG (2)'!$B$9:$J$570,9,FALSE),0))*-1 -> 0 | P40: =J40+K40 -> 13360926704 | T40: =K40+J40 -> 13360926704 | W40: =+A40-#REF! -> #REF!
...

Sheet Bilan Actif
A1: Sommaire
C2: Bilan - Actif OHADA | M2: =10^6 -> 1000000
C3: En FCFA
A5: Réf. | B5: ACTIF | D5: =+Cover!Y18 -> 44926 | G5: =+Cover!Y16 -> 44562 | J5: Variation
D6: Brut | E6: Amort/Prov | F6: Net | G6: Brut | H6: Amort/Prov | I6: Net | J6: Brut | K6: Amort/Prov | L6: Net
J7: =+D7-G7 -> 0 | K7: =+E7-H7 -> 0 | L7: =+F7-I7 -> 0
A8: AA | B8: Charges immobilisées | D8: =+D9+D10 -> 0 | E8: =+E9+E10 -> 0 | F8: =D8-E8 -> 0 | G8: =+G9+G10 -> 0 | H8: =+H9+H10 -> 0 | I8: =G8-H8 -> 0 | J8: =+D8-G8 -> 0 | K8: =+E8-H8 -> 0 | L8: =+F8-I8 -> 0 | M8: =+G8-J8 -> 0
A9: AB | B9: Frais d'établissement et charges à répartir | D9: 0 | F9: =D9-E9 -> 0 | G9: 0 | I9: =G9-H9 -> 0 | J9: =+D9-G9 -> 0 | K9: =+E9-H9 -> 0 | L9: =+F9-I9 -> 0 | M9: =+G9-J9 -> 0
A10: AC | B10: Primes de remboursement des obligations | F10: =D10-E10 -> 0 | I10: =G10-H10 -> 0 | J10: =+D10-G10 -> 0 | K10: =+E10-H10 -> 0 | L10: =+F10-I10 -> 0 | M10: =+G10-J10 -> 0
A11: AD | B11: Immobilisations incorporelles | D11: =+SUM(D12:D15) -> 146520173576 | E11: =+SUM(E12:E15) -> 107413659810 | F11: =D11-E11 -> 39106513766 | G11: =+SUM(G12:G15) -> 146520173576 | H11: =+SUM(H12:H15) -> 107413659810 | I11: =G11-H11 -> 39106513766 | J11: =+D11-G11 -> 0 | K11: =+E11-H11 -> 0 | L11: =+F11-I11 -> 0 | M11: =+G11-J11 -> 146520173576
A12: AE | B12: Frais de recherche et de développement | F12: =D12-E12 -> 0 | I12: =G12-H12 -> 0 | J12: =+D12-G12 -> 0 | K12: =+E12-H12 -> 0 | L12: =+F12-I12 -> 0 | M12: =+G12-J12 -> 0
A13: AF | B13: Brevets, licences, logiciels | D13: =[152]ACTIF!$D$12 -> 146520173576 | E13: =[152]ACTIF!$E$12 -> 107413659810 | F13: =D13-E13 -> 39106513766 | G13: =[152]ACTIF!$D$12 -> 146520173576 | H13: =[152]ACTIF!$E$12 -> 107413659810 | I13: =G13-H13 -> 39106513766 | J13: =+D13-G13 -> 0 | K13: =+E13-H13 -> 0 | L13: =+F13-I13 -> 0 | M13: =+G13-J13 -> 146520173576
A14: AG | B14: Fonds commercial | F14: =D14-E14 -> 0 | I14: =G14-H14 -> 0 | J14: =+D14-G14 -> 0 | L14: =+F14-I14 -> 0 | M14: =+G14-J14 -> 0
A15: AH | B15: Autres immobilisations incorporelles | F15: =D15-E15 -> 0 | I15: =G15-H15 -> 0 | J15: =+D15-G15 -> 0 | K15: =+E15-H15 -> 0 | L15: =+F15-I15 -> 0 | M15: =+G15-J15 -> 0
A16: AI | B16: Immobilisations corporelles | D16: =SUM(D17:D22) -> 179709685658 | E16: =SUM(E17:E22) -> 113100503569 | F16: =D16-E16 -> 66609182089 | G16: =SUM(G17:G22) -> 179709685658 | H16: =SUM(H17:H22) -> 113100503569 | I16: =G16-H16 -> 66609182089 | J16: =SUM(J17:J22) -> 0 | K16: =SUM(K17:K22) -> 0 | L16: =SUM(L17:L22) -> 0 | M16: =SUM(M17:M22) -> 179709685658
A17: AJ | B17: Terrains | D17: =[152]ACTIF!$D$16 -> 3170092329 | E17: =[152]ACTIF!$E$16 -> 0 | F17: =D17-E17 -> 3170092329 | G17: =[152]ACTIF!$D$16 -> 3170092329 | H17: =[152]ACTIF!$E$16 -> 0 | I17: =G17-H17 -> 3170092329 | J17: =+D17-G17 -> 0 | K17: =+E17-H17 -> 0 | L17: =+F17-I17 -> 0 | M17: =+G17-J17 -> 3170092329
A18: AK | B18: Bâtiments | D18: =[152]ACTIF!$D$18 -> 1675459071 | E18: =[152]ACTIF!$E$18 -> 53350355 | F18: =D18-E18 -> 1622108716 | G18: =[152]ACTIF!$D$18 -> 1675459071 | H18: =[152]ACTIF!$E$18 -> 53350355 | I18: =G18-H18 -> 1622108716 | J18: =+D18-G18 -> 0 | K18: =+E18-H18 -> 0 | L18: =+F18-I18 -> 0 | M18: =+G18-J18 -> 1675459071
A19: AL | B19: Installations et agencements | D19: =[152]ACTIF!$D$20 -> 61892732272 | E19: =[152]ACTIF!$E$20 -> 41823483292 | F19: =D19-E19 -> 20069248980 | G19: =[152]ACTIF!$D$20 -> 61892732272 | H19: =[152]ACTIF!$E$20 -> 41823483292 | I19: =G19-H19 -> 20069248980 | J19: =+D19-G19 -> 0 | K19: =+E19-H19 -> 0 | L19: =+F19-I19 -> 0 | M19: =+G19-J19 -> 61892732272
A20: AM | B20: Matériel | D20: =[152]ACTIF!$D$21 -> 111780777995 | E20: =[152]ACTIF!$E$21 -> 70508337317 | F20: =D20-E20 -> 41272440678 | G20: =[152]ACTIF!$D$21 -> 111780777995 | H20: =[152]ACTIF!$E$21 -> 70508337317 | I20: =G20-H20 -> 41272440678 | J20: =+D20-G20 -> 0 | K20: =+E20-H20 -> 0 | L20: =+F20-I20 -> 0 | M20: =+G20-J20 -> 111780777995
A21: AN | B21: Matériel de transport | D21: =[152]ACTIF!$D$22 -> 715895198 | E21: =[152]ACTIF!$E$22 -> 715332605 | F21: =D21-E21 -> 562593 | G21: =[152]ACTIF!$D$22 -> 715895198 | H21: =[152]ACTIF!$E$22 -> 715332605 | I21: =G21-H21 -> 562593 | J21: =+D21-G21 -> 0 | K21: =+E21-H21 -> 0 | L21: =+F21-I21 -> 0 | M21: =+G21-J21 -> 715895198
A22: AP | B22: Avances et acomptes versés sur immobilisations | D22: =[152]ACTIF!$D$23 -> 474728793 | F22: =D22-E22 -> 474728793 | G22: =[152]ACTIF!$D$23 -> 474728793 | I22: =G22-H22 -> 474728793 | J22: =+D22-G22 -> 0 | K22: =+E22-H22 -> 0 | L22: =+F22-I22 -> 0 | M22: =+G22-J22 -> 474728793
A23: AQ | B23: Immobilisations financières | D23: =SUM(D24:D25) -> 732076630 | E23: =SUM(E24:E25) -> 0 | F23: =D23-E23 -> 732076630 | G23: =SUM(G24:G25) -> 732076630 | H23: =SUM(H24:H25) -> 0 | I23: =G23-H23 -> 732076630 | J23: =SUM(J24:J25) -> 0 | K23: =SUM(K24:K25) -> 0 | L23: =SUM(L24:L25) -> 0 | M23: =SUM(M24:M25) -> 732076630
A24: AR | B24: Titres de participation | D24: =[152]ACTIF!$D$25 -> 0 | F24: =D24-E24 -> 0 | G24: =[152]ACTIF!$D$25 -> 0 | I24: =G24-H24 -> 0 | J24: =+D24-G24 -> 0 | K24: =+E24-H24 -> 0 | L24: =+F24-I24 -> 0 | M24: =+G24-J24 -> 0
A25: AS | B25: Autres immobilisations financières | D25: =[152]ACTIF!$D$26 -> 732076630 | F25: =D25-E25 -> 732076630 | G25: =[152]ACTIF!$D$26 -> 732076630 | I25: =G25-H25 -> 732076630 | J25: =+D25-G25 -> 0 | K25: =+E25-H25 -> 0 | L25: =+F25-I25 -> 0 | M25: =+G25-J25 -> 732076630
A26: AZ | B26: TOTAL ACTIF IMMOBILISE (I) | D26: =+D23+D16+D11+D8 -> 326961935864 | E26: =+E23+E16+E11+E8 -> 220514163379 | F26: =+F23+F16+F11+F8 -> 106447772485 | G26: =+G23+G16+G11+G8 -> 326961935864 | H26: =+H23+H16+H11+H8 -> 220514163379 | I26: =+I23+I16+I11+I8 -> 106447772485 | J26: =+D26-G26 -> 0 | K26: =+E26-H26 -> 0 | L26: =+F26-I26 -> 0 | M26: =+G26-J26 -> 326961935864
B27: ACTIF CIRCULANT | J27: =+D27-G27 -> 0 | K27: =+E27-H27 -> 0 | L27: =+F27-I27 -> 0 | M27: =+G27-J27 -> 0
A28: DH | B28: Actif circulant H. A. O. | D28: =[152]ACTIF!$D$28 -> 1307827431 | F28: =D28-E28 -> 1307827431 | G28: =[152]ACTIF!$D$28 -> 1307827431 | I28: =G28-H28 -> 1307827431 | J28: =+D28-G28 -> 0 | K28: =+E28-H28 -> 0 | L28: =+F28-I28 -> 0 | M28: =+G28-J28 -> 1307827431
A29: BB | B29: Stocks | D29: =[152]ACTIF!$D$29 -> 2986894192 | E29: =[152]ACTIF!$E$29 -> 539720702 | F29: =D29-E29 -> 2447173490 | G29: =[152]ACTIF!$D$29 -> 2986894192 | H29: =[152]ACTIF!$E$29 -> 539720702 | I29: =G29-H29 -> 2447173490 | J29: =+D29-G29 -> 0 | K29: =+E29-H29 -> 0 | L29: =+F29-I29 -> 0 | M29: =+G29-J29 -> 2986894192
A30: BC | B30: Marchandises | F30: =D30-E30 -> 0 | I30: =G30-H30 -> 0 | J30: =+D30-G30 -> 0 | K30: =+E30-H30 -> 0 | L30: =+F30-I30 -> 0 | M30: =+G30-J30 -> 0
A31: BD | B31: Matières premières et autres | F31: =D31-E31 -> 0 | I31: =G31-H31 -> 0 | J31: =+D31-G31 -> 0 | K31: =+E31-H31 -> 0 | L31: =+F31-I31 -> 0 | M31: =+G31-J31 -> 0
B32: Approvisionnements | F32: =D32-E32 -> 0 | I32: =G32-H32 -> 0 | J32: =+D32-G32 -> 0 | K32: =+E32-H32 -> 0 | L32: =+F32-I32 -> 0 | M32: =+G32-J32 -> 0
A33: BE | B33: En-cours | F33: =D33-E33 -> 0 | I33: =G33-H33 -> 0 | J33: =+D33-G33 -> 0 | K33: =+E33-H33 -> 0 | L33: =+F33-I33 -> 0 | M33: =+G33-J33 -> 0
A34: BF | B34: Produits fabriqués | F34: =D34-E34 -> 0 | I34: =G34-H34 -> 0 | J34: =+D34-G34 -> 0 | K34: =+E34-H34 -> 0 | L34: =+F34-I34 -> 0 | M34: =+G34-J34 -> 0
A35: BG | B35: Créances et emplois assimilés | D35: =+SUM(D36:D38) -> 41680074289 | E35: =+SUM(E36:E38) -> 4197508048 | F35: =D35-E35 -> 37482566241 | G35: =+SUM(G36:G38) -> 41680074289 | H35: =+SUM(H36:H38) -> 4197508048 | I35: =G35-H35 -> 37482566241 | J35: =+D35-G35 -> 0 | K35: =+E35-H35 -> 0 | L35: =+F35-I35 -> 0 | M35: =+G35-J35 -> 41680074289
A36: BH | B36: Fournisseurs, avances versées | D36: =+[152]ACTIF!$D$31 -> 1657769200 | F36: =D36-E36 -> 1657769200 | G36: =+[152]ACTIF!$D$31 -> 1657769200 | I36: =G36-H36 -> 1657769200 | J36: =+D36-G36 -> 0 | K36: =+E36-H36 -> 0 | L36: =+F36-I36 -> 0 | M36: =+G36-J36 -> 1657769200
A37: BI | B37: Clients | D37: =+[152]ACTIF!$D$32 -> 24885972671 | E37: =+[152]ACTIF!$E$32 -> 4197508048 | F37: =D37-E37 -> 20688464623 | G37: =+[152]ACTIF!$D$32 -> 24885972671 | H37: =+[152]ACTIF!$E$32 -> 4197508048 | I37: =G37-H37 -> 20688464623 | J37: =+D37-G37 -> 0 | K37: =+E37-H37 -> 0 | L37: =+F37-I37 -> 0 | M37: =+G37-J37 -> 24885972671
A38: BJ | B38: Autres créances | D38: =+[152]ACTIF!$D$33 -> 15136332418 | F38: =D38-E38 -> 15136332418 | G38: =+[152]ACTIF!$D$33 -> 15136332418 | I38: =G38-H38 -> 15136332418 | J38: =+D38-G38 -> 0 | K38: =+E38-H38 -> 0 | L38: =+F38-I38 -> 0 | M38: =+G38-J38 -> 15136332418
A39: BK | B39: TOTAL ACTIF CIRCULANT (II) | D39: =+D28+D29+D35 -> 45974795912 | E39: =+E28+E29+E35 -> 4737228750 | F39: =+F28+F29+F35 -> 41237567162 | G39: =+G28+G29+G35 -> 45974795912 | H39: =+H28+H29+H35 -> 4737228750 | I39: =+I28+I29+I35 -> 41237567162 | J39: =+D39-G39 -> 0 | K39: =+E39-H39 -> 0 | L39: =+F39-I39 -> 0 | M39: =+G39-J39 -> 45974795912
B40: TRESORERIE-ACTIF
A41: BQ | B41: Titres de placement | F41: =+D41-E41 -> 0 | I41: =+G41-H41 -> 0 | J41: =+D41-G41 -> 0 | K41: =+E41-H41 -> 0 | L41: =+F41-I41 -> 0 | M41: =+G41-J41 -> 0
...

Sheet Bilan Passif 
A1: Sommaire
B3: Bilan - Passif OHADA
A6: Réf. | B6: PASSIF | C6: =+Cover!Y18 -> 44926 | D6: =+Cover!Y16 -> 44562 | E6: Variation
A9: CA | B9: Capital | C9: =+[152]PASSIF!$D$10 -> 10408280000 | D9: =+[152]PASSIF!$D$10 -> 10408280000 | E9: =C9-D9 -> 0
A10: CB | B10: Actionnaires capital non appelé - | E10: =C10-D10 -> 0
A11: CC | B11: Primes et réserves | C11: =+SUM(C12:C16) -> -1228656692 | D11: =+SUM(D12:D16) -> -1228656692 | E11: =C11-D11 -> 0
A12: CD | B12: Primes d'apport, d'émission, de fusion | E12: =C12-D12 -> 0
A13: CE | B13: Ecarts de réévaluation | E13: =C13-D13 -> 0
A14: CF | B14: Réserves indisponibles | E14: =C14-D14 -> 0
A15: CG | B15: Réserves libres | E15: =C15-D15 -> 0
A16: CH | B16: Report à nouveau + ou - | C16: =+[152]PASSIF!$D$16 -> -1228656692 | D16: =+[152]PASSIF!$D$16 -> -1228656692 | E16: =C16-D16 -> 0
A17: C I | B17: Résultat net de l'exercice (bénéfice + ou perte -) | C17: =+[152]PASSIF!$D$17 -> 4778363684 | D17: =+[152]PASSIF!$D$17 -> 4778363684 | E17: =C17-D17 -> 0
A18: CK | B18: Autres capitaux propres | C18: =+C19+C20 -> 0 | D18: =+D19+D20 -> 0 | E18: =C18-D18 -> 0
A19: CL | B19: Subventions d'investissement | E19: =C19-D19 -> 0
A20: CM | B20: Provisions réglementées et fonds assimilés | E20: =C20-D20 -> 0
A21: CP | B21: TOTAL CAPITAUX PROPRES (I) | C21: =+C18+C17+C11+C10+C9 -> 13957986992 | D21: =+D18+D17+D11+D10+D9 -> 13957986992 | E21: =+C21-D21 -> 0
B22: DETTES FINANCIERES ET RESSOURCES
B23: ASSIMILEES (1)
A24: DA | B24: Emprunts | C24: =+[152]PASSIF!$D$21 -> 46196599329 | D24: =+[152]PASSIF!$D$21 -> 46196599329 | E24: =C24-D24 -> 0
A25: DB | B25: Dettes de crédit-bail et contrats assimilés | E25: =C25-D25 -> 0
A26: DC | B26: Dettes financières diverses | E26: =C26-D26 -> 0
A27: DD | B27: Provisions financières pour risques et charges | C27: =+[152]PASSIF!$D$23 -> 1119247874 | D27: =+[152]PASSIF!$D$23 -> 1119247874 | E27: =C27-D27 -> 0
A28: DF | B28: TOTAL DETTES FINANCIERES (II) | C28: =+SUM(C24:C27) -> 47315847203 | D28: =+SUM(D24:D27) -> 47315847203 | E28: =+C28-D28 -> 0
A30: DG | B30: TOTAL RESSOURCES STABLES (I + II) | C30: =+C28+C21 -> 61273834195 | D30: =+D28+D21 -> 61273834195 | E30: =+C30-D30 -> 0
B31: PASSIF CIRCULANT
A32: DH | B32: Dettes circulantes et ressources assimilées H.A.O. | C32: =+[152]PASSIF!$D$26 -> 20173765752 | D32: =+[152]PASSIF!$D$26 -> 20173765752 | E32: =+C32-D32 -> 0
A33: DI | B33: Clients, avances reçues | C33: =+[152]PASSIF!$D$27 -> 1266250396 | D33: =+[152]PASSIF!$D$27 -> 1266250396 | E33: =+C33-D33 -> 0
A34: DJ | B34: Fournisseurs d'exploitation | C34: =+[152]PASSIF!$D$28 -> 40919405808 | D34: =+[152]PASSIF!$D$28 -> 40919405808 | E34: =+C34-D34 -> 0
A35: DK | B35: Dettes fiscales | C35: =+[152]PASSIF!$D$29 -> 6711865534 | D35: =+[152]PASSIF!$D$29 -> 6711865534 | E35: =+C35-D35 -> 0
A36: DL | B36: Dettes sociales | E36: =+C36-D36 -> 0
A37: DM | B37: Autres dettes | C37: =+[152]PASSIF!$D$30 -> 34096023296 | D37: =+[152]PASSIF!$D$30 -> 34096023296 | E37: =+C37-D37 -> 0
A38: DN | B38: Risques provisionnés | C38: =+[152]PASSIF!$D$31 -> 212954781 | D38: =+[152]PASSIF!$D$31 -> 212954781 | E38: =+C38-D38 -> 0
A39: DP | B39: TOTAL PASSIF CIRCULANT (III) | C39: =+SUM(C32:C38) -> 103380265567 | D39: =+SUM(D32:D38) -> 103380265567 | E39: =+C39-D39 -> 0
B40: TRESORERIE - PASSIF
A41: DQ | B41: Banques, crédits d'escompte | C41: =+[152]PASSIF!$D$33 -> 52277096 | D41: =+[152]PASSIF!$D$33 -> 52277096 | E41: =+C41-D41 -> 0
A42: DR | B42: Banques, crédits de trésorerie | C42: =+[152]PASSIF!$D$34 -> 16044722077 | D42: =+[152]PASSIF!$D$34 -> 16044722077 | E42: =+C42-D42 -> 0
A43: DS | B43: Banques, découverts | E43: =+C43-D43 -> 0
A44: DT | B44: TOTAL TRESORERIE-PASSIF (IV) | C44: =+SUM(C41:C43) -> 16096999173 | D44: =+SUM(D41:D43) -> 16096999173 | E44: =+C44-D44 -> 0
A45: DU | B45: Ecarts de conversion-Passif (V) | C45: =C46 -> 89314488 | D45: =D46 -> 89314488 | E45: =+C45-D45 -> 0
B46: (gain probable de change) | C46: =+[152]PASSIF!$D$36 -> 89314488 | D46: =+[152]PASSIF!$D$36 -> 89314488
...

Sheet Compte de résultat
A1: Sommaire
C2: Compte de résultat OHADA
B3: En FCFA
A4: Réf. | B4: Compte de résultat | H4: =+Cover!Y18 -> 44926
B5: ACTIVITE D'EXPLOITATION
A6: TA | B6: Ventes de marchandises | H6: =+'[152]Compte de Résultat'!$E$9 -> 1124427867
A7: TC | B7: Ventes de produits fabriqués
A8: TD | B8: Travaux, services vendus | H8: =+'[152]Compte de Résultat'!$E$14 -> 103941367167
A9: TE | B9: Production stockée ou déstockage (+ ou -)
A10: TF | B10: Production immobilisée
A11: TH | B11: Produits accessoires | H11: =+'[152]Compte de Résultat'!$E$15 -> 1193512416
A12: T I | B12: CHIFFRE D'AFFAIRES (1) (TA + TC + TD + TH) | F12: =+H6+H7+H8+H11 -> 106259307450 | H12: =+H6+H7+H8+H11 -> 106259307450
A13: TJ | B13: (1) dont à l'exportation
A14: TK | B14: Subventions d'exploitation
A15: TL | B15: Autres produits | H15: =+'[152]Compte de Résultat'!$E$20 -> 1146703428
A16: TS | B16: Reprises de provisions | H16: =+'[152]Compte de Résultat'!$E$33 -> 1588912200
A17: TT | B17: Transferts de charges | H17: =+'[152]Compte de Résultat'!$E$21 -> 202462584
A18: TW | B18: Total des produits d'exploitation | H18: =+H6+H7+H8+H9+H10+H11+H14+H15+H16+H17 -> 109197385662
A20: RA | B20: Achats de marchandises | H20: =-+'[152]Compte de Résultat'!$E$10 -> 1878495285
A21: RB | B21: - Variation de stocks | F21: (- ou +) | H21: =-+'[152]Compte de Résultat'!$E$11 -> 167058426
A22: RC | B22: Achats de matières premières et fournitures liées | H22: =-'[152]Compte de Résultat'!$E$22 -> 0
A23: RD | B23: - Variation de stocks | F23: (- ou +) | H23: =-'[152]Compte de Résultat'!$E$23 -> -20982830
A24: RE | B24: Autres achats | H24: =-+'[152]Compte de Résultat'!$E$24 -> 13535561694
A25: RH | B25: - Variation de stocks | F25: (- ou +) | H25: =-+'[152]Compte de Résultat'!$E$25 -> 70632568
A26: RI | B26: Transports | H26: =-+'[152]Compte de Résultat'!$E$26 -> 185108708
A27: RJ | B27: Services extérieurs | H27: =-+'[152]Compte de Résultat'!$E$27 -> 55972756449
A28: RK | B28: Impôts et taxes | H28: =-+'[152]Compte de Résultat'!$E$28 -> 2756966914
A29: RL | B29: Autres charges | H29: =-+'[152]Compte de Résultat'!$E$29 -> 2130824161
A30: RP | B30: Charges de personnel | H30: =-+'[152]Compte de Résultat'!$E$31 -> 4859497853
A31: RS | B31: Dotations aux amortissements et aux provisions | H31: =-+'[152]Compte de Résultat'!$E$34 -> 18531485240
A32: RW | B32: Total des charges d'exploitation | H32: =+SUM(H20:H31) -> 100067404468
A34: TX | B34: RESULTAT D'EXPLOITATION | H34: =+H18-H32 -> 9129981194
C35: Bénéfice (+) ; Perte (-)
B36: ACTIVITE FINANCIERE
A37: UA | B37: Revenus financiers | H37: ='[152]Compte de Résultat'!$E$36 -> 870907299
A38: UC | B38: Gains de change | H38: 0
A39: UD | B39: Reprises de provisions | H39: =+'[152]Compte de Résultat'!$E$37 -> 0
A40: UE | B40: Transferts de charges
A41: UF | B41: Total des produits financiers | H41: =+SUM(H37:H40) -> 870907299
A43: SA | B43: Frais financiers | H43: =-'[152]Compte de Résultat'!$E$39 -> 4155056479
...

Sheet <<Matrice OHADA-IFRS>>
E16: Matrice de passage OHADA - IFRS

Sheet Passage Actif BC 
A1: Sommaire
G2: Retraitements PPA | Q2: Reclassements | Z2: Retraitements | BC2: Ajustements conso
C3: Passage Bilan - Actif
C4: =Cover!Y13 -> En millions de FCFA | E4: Comptes sociaux OHADA | G4: Marque | I4: Base client (VB) | K4: Base client (AMENTS) | M4: Juste valeur terrain | O4: Juste valeur titres | Q4: Reclass immo. Corp | R4: Reclass immo. Incorp | S4: Reclass immo. Fin | T4: Reclass BFR | U4: Reclass Acomptes IS | V4: Autres Reclassements | W4: CCA/PCA | X4: CCA | Y4: Cash bloqué | Z4: ID social | AB4: IDA/PIDR | AD4: Cartes SIM (VB) | AG4: Cartes SIM (AMORT) | AI4: Subventions (VB) | AK4: Subventions (REPRISES) | AM4: Droit d'actif(VB) | AO4: Droit d'actif(Amort) | AQ4: Frais immobilisés | AS4: Mise en rebut (VB) | AU4: Mise en rebut (AMORT) | AW4: Stocks réseaux (VB) | AY4: Stocks réseaux (AMORT) | BA4: ECA | BC4: Ajust 1 | BD4: Ajust 2 | BE4: Ajust 3 | BF4: Ajust 4 | BH4: IFRS | BJ4: IFRS
G5: Ouverture | H5: Flux | I5: Ouverture | J5: Flux | K5: Ouverture | L5: Flux | M5: Ouverture | N5: Flux | O5: Ouverture | P5: Flux | Z5: Ouverture | AA5: Flux | AB5: Ouverture | AC5: Flux | AD5: Ouverture | AE5: Achats de cartes SIM | AF5: Sorties comptables | AG5: Ouverture | AH5: Flux | AI5: Ouverture | AJ5: Flux | AK5: Ouverture | AL5: Flux | AM5: Ouverture | AN5: Flux | AO5: Ouverture | AP5: Flux | AQ5: Ouverture | AR5: Flux | AS5: Ouverture | AT5: Flux | AU5: Ouverture | AV5: Flux | AW5: Ouverture | AX5: Flux | AY5: Ouverture | AZ5: Flux | BA5: Ouverture | BB5: Flux | BC5: Goodwill | BD5: ID | BE5: SHL & MFees | BF5: Activation charges du personnel
C7: Frais d'établissement et autres charges à répartir | E7: =+'Bilan Actif'!F9/10^6 -> 0 | AQ7: =(-530.12080712+246.787407232001+200.150696+83.075)*0 -> 0 | AR7: =-SUM('BG '!H29:I29)/10^6 -> 0 | BH7: =SUM(E7:BG7) -> 0 | BJ7: 0
C8: Autres charges immobilisées | E8: =+'Bilan Actif'!F10/10^6 -> 0 | BH8: =SUM(E8:BG8) -> 0 | BJ8: 0
B10: ANC2100 | C10: Ecarts d’acquisition | BC10: =19085+7314 -> 26399 | BH10: =SUM(E10:BG10) -> 26399 | BJ10: 26399
B11: ANC2910 | C11: Provisions pour dépréciation des écarts d’acquisition | BH11: =SUM(E11:BG11) -> 0 | BJ11: 0
B12: TANC2000 | C12: Ecarts d'acquisition | F12: =F11+F10 -> 0 | G12: =G11+G10 -> 0 | H12: =H11+H10 -> 0 | I12: =I11+I10 -> 0 | J12: =J11+J10 -> 0 | K12: =K11+K10 -> 0 | L12: =L11+L10 -> 0 | M12: =M11+M10 -> 0 | ... BF12: =BF11+BF10 -> 0 | BH12: =SUM(E12:BG12) -> 26399 | BJ12: 26399
C14: Frais de recherche et de développemt | E14: =+'Bilan Actif'!F12/10^6 -> 0 | R14: =-E14 -> 0 | BH14: =SUM(E14:BG14) -> 0 | BJ14: 0
C15: Brevets, licences, logiciels | E15: =+'Bilan Actif'!F13/10^6 -> 39106.514 | R15: =-E15 -> -39106.514 | BH15: =SUM(E15:BG15) -> 0 | BJ15: 0
C16: Fonds commercial | E16: =+'Bilan Actif'!F14/10^6 -> 0 | R16: =-E16 -> 0 | BH16: =SUM(E16:BG16) -> 0 | BJ16: 0
C17: Autres immobilisations incorporelles | E17: =+'Bilan Actif'!F15/10^6 -> 0 | R17: =-E17 -> 0 | BH17: =SUM(E17:BG17) -> 0 | BJ17: 0
B19: ANC2210 | C19: Frais de développement | R19: 0 | BH19: =SUM(E19:BG19) -> 0 | BJ19: 0
B20: ANC2821 | C20: Amortissements & dépréciation des frais de développement | BH20: =SUM(E20:BG20) -> 0 | BJ20: 0
B21: ANC2221 | C21: Brevets et marques | R21: =+('BG '!J31)/10^6 -> 6373.0289 | BH21: =SUM(E21:BG21) -> 6373.0289 | BJ21: 6254.3029
B22: ANC28221 | C22: Amortissements & dépréciation des brevets et marques | R22: =+('BG '!K73)/10^6 -> -8931.4383 | V22: =-(R22+R21) -> 2558.4094 | BH22: =SUM(E22:BG22) -> -6373.0289 | BJ22: -5372.6873
B23: ANC2222 | C23: Logiciels | R23: =+('BG '!J32+'BG '!J33+'BG '!J34)/10^6 -> 60147.145 | BH23: =SUM(E23:BG23) -> 60147.145 | BJ23: 55522.589
B24: ANC28222 | C24: Amortissements & dépréciation des logiciels | R24: =+('BG '!K74+'BG '!K75)/10^6 -> -41958.116 | V24: =SUM('BG '!R82:S83)/10^6-'[154]RECAP 1'!$K$45-V22 -> -2558.4094 | BH24: =SUM(E24:BG24) -> -44516.525 | BJ24: -40753.176
B25: ANC2240 | C25: Licences telecom | R25: =+('BG '!J30)/10^6 -> 80000 | BH25: =SUM(E25:BG25) -> 80000 | BJ25: 80000
B26: ANC2824 | C26: Amortissements & dépréciation des licences telecom | R26: =+('BG '!K72)/10^6 -> -56524.105 | V26: =SUM('BG '!S80)/10^6-'[154]RECAP 1'!$K$46 -> 0 | BH26: =SUM(E26:BG26) -> -56524.105 | BJ26: -53968.69
B27: ANC2250 | C27: Immobilisations incorporelles acquises par voie de regroupement d'entreprises | BH27: =SUM(E27:BG27) -> 0 | BJ27: 0
B28: ANC2825 | C28: Amortissements & dépréciation des immobilisations incorporelles acquises par voie de regroupement d'entreprises | BH28: =SUM(E28:BG28) -> 0 | BJ28: 0
B29: ANC2260 | C29: Cartes SIM | AD29: =1820.91778991124+330.296429+216.501643+187.185137+514.390844 -> 3069.2918 | AE29: =-AE103 -> 759.49458 | BH29: =SUM(E29:BG29) -> 3828.7864 | BJ29: 3828.7864
B30: ANC2826 | C30: Amortissements & dépréciation cartes SIM | AG30: =-1171.35990694011-346.028541147557-265.028390976732-200.907171654148-177.45912356389 -> -2160.7831 | AH30: =-'Cartes SIM'!D21/1000000 -> -229.49406 | BH30: =SUM(E30:BG30) -> -2390.2772 | BJ30: -2316.3666
B31: ANC2270 | C31: Droit d'utilisation de l'actif | AM31: =4021.665466+2117.71515+33.047333-2.01030600000104+133.291784 -> 6303.7094 | AN31: ='Impacts_IFRS.16-09'!K69 -> 434.41556 | BH31: =SUM(E31:BG31) -> 6738.125 | BJ31: 6729.8771
B32: ANC2827 | C32: Amortissements du droit d'utilisation de l'actif | AO32: =-930.344101-1133.873401-1067.353401-940.196732 -> -4071.7676 | AP32: =+'Impacts_IFRS.16-09'!L82 -> -805.85369 | BH32: =SUM(E32:BG32) -> -4877.6213 | BJ32: -4671.7804
B33: ANC2280 | C33: Autres immobilisations incorporelles | V33: =-(SUM(Activation!H25,Activation!H32:H192)/10^6) -> -2464.3598 | BF33: =SUM(Activation!H25,Activation!H32:H213)/10^6 -> 2745.5723 | BH33: =SUM(E33:BG33) -> 281.21245 | BJ33: 0
B34: ANC2828 | C34: Amortissements & dépréciation des autres immobilisations incorporelles | V34: =-(Activation!CB238/10^6+SUM(Activation!CN239)/10^6) -> 1459.7159 | BF34: =Activation!CB238/10^6+SUM(Activation!CN239)/10^6 -> -1459.7159 | BH34: =SUM(E34:BG34) -> 0 | BJ34: -215.27479
B35: ANC2298 | C35: Immobilisations incorporelles en cours | V35: =+Q56 -> 324.80203 | BH35: =SUM(E35:BG35) -> 324.80203 | BJ35: 579.13573
B36: ANC2929 | C36: Provisions pour dépréciation des immobilisations incorporelles en cours | BH36: =SUM(E36:BG36) -> 0 | BJ36: 0
B37: TANC2100 | C37: Immobilisations incorporelles | E37: =+SUM(E14:E17) -> 39106.514 | G37: =SUM(G19:G36) -> 0 | H37: =SUM(H14:H36) -> 0 | I37: =SUM(I14:I36) -> 0 | J37: =SUM(J14:J36) -> 0 | K37: =SUM(K14:K36) -> 0 | L37: =SUM(L14:L36) -> 0 | M37: =SUM(M14:M36) -> 0 | N37: =SUM(N14:N36) -> 0 | O37: =SUM(O14:O36) -> 0 | ... BF37: =SUM(BF14:BF36) -> 1285.8564 | BH37: =SUM(BH14:BH36) -> 43011.541 | BJ37: 45616.716
C39: Terrains | E39: =+'Bilan Actif'!F17/10^6 -> 3170.0923 | Q39: =-E39 -> -3170.0923 | BH39: =SUM(E39:BG39) -> 0 | BJ39: 0
C40: Bâtiments | E40: =+'Bilan Actif'!F18/10^6 -> 1622.1087 | Q40: =-E40 -> -1622.1087 | BH40: =SUM(E40:BG40) -> 0 | BJ40: 0
C41: Installations et agencements | E41: =+'Bilan Actif'!F19/10^6 -> 20069.249 | Q41: =-E41 -> -20069.249 | BH41: =SUM(E41:BG41) -> 0 | BJ41: 0
C42: Matériel, mobilier et actifs biologiques | E42: =+'Bilan Actif'!F20/10^6 -> 41272.441 | Q42: =-E42 -> -41272.441 | BH42: =SUM(E42:BG42) -> 0 | BJ42: 0
C43: Matériel de transport | E43: =+'Bilan Actif'!F21/10^6 -> 0.562593 | Q43: =-E43 -> -0.562593 | BH43: =SUM(E43:BG43) -> 0 | BJ43: 0
C44: Avances et acomptes versés sur immobilisations | E44: =+'Bilan Actif'!F22/10^6 -> 474.72879 | Q44: =-E44 -> -474.72879 | BH44: =SUM(E44:BG44) -> 0 | BJ44: 0
B46: ANC2310 | C46: Terrains | Q46: =+('BG '!J35+'BG '!J36+'BG '!J37)/10^6 -> 3170.0923 | BH46: =SUM(E46:BG46) -> 3170.0923 | BJ46: 3145.8177
...

Sheet Passage Passif BC 
A1: Sommaire
G2: Retraitements PPA | Q2: Reclassements | AK2: Retraitements | BC2: Ajustements conso
C4: Passage Bilan - Passif | E4: Comptes sociaux OHADA | G4: Marque | I4: Base client (VB) | K4: Base client (AMENTS) | M4: Juste valeur terrain | O4: Juste valeur titres | Q4: Reclass SN - Part du Groupe/Minos | R4: Reclass Dettes financières fraction à -1 an | S4: Reclass Dettes financières ICNE | T4: Reclass Dettes financières envers la mère | U4: Conventions financières exploitation (DPA) | V4: Reclass Provisions | W4: Reclass Dette d'IS | X4: Reclass BFR | Y4: Reclass Equivalents de trésorerie | Z4: Autres reclassements | AA4: Autres reclass 2 | AB4: Autres reclass 3 | AC4: Autres reclass 4 | AD4: ID social | AF4: PIDR | AH4: Cartes SIM (VB) | AK4: Cartes SIM (AMORT) | AM4: Subventions (VB) | AO4: Subventions Reprises | AQ4: Droit d'actif(VB) | AS4: Droit d'actif(Amort) | AU4: Frais immobilisés | AW4: ECA | AY4: ECA - Provision pour perte de change | BA4: ECP | BC4: Ajust 1 | BD4: Ajust 2 | BE4: Ajust 3 | BG4: IFRS | BL4: IFRS
C5: =Cover!Y13 -> En millions de FCFA | G5: Ouverture | H5: Flux | I5: Ouverture | J5: Flux | K5: Ouverture | L5: Flux | M5: Ouverture | N5: Flux | O5: Ouverture | P5: Flux | AD5: Ouverture | AE5: Flux | AF5: Ouverture | AG5: Flux | AH5: Ouverture | AI5: Achats de cartes SIM | AJ5: Sorties comptables | AK5: Ouverture | AL5: Flux | AM5: Ouverture | AN5: Flux | AO5: Ouverture | AP5: Flux | AQ5: Ouverture | AR5: Flux | AS5: Ouverture | AT5: Flux | AU5: Ouverture | AV5: Flux | AW5: Ouverture | AX5: Flux | AY5: Ouverture | AZ5: Flux | BA5: Ouverture | BB5: Flux | BC5: Goodwill | BD5: ID | BE5: Activation charges de personnel
C7: Capital | E7: =+('Bilan Passif '!C9+'Bilan Passif '!C10)/10^6 -> 10408.28 | Q7: =-E7 -> -10408.28 | BG7: =+SUM(E7:BE7) -> 0 | BL7: 0
C8: Primes d'apport, d'émission, de fusion | E8: =+'Bilan Passif '!C12/10^6 -> 0 | Q8: =-E8 -> 0 | BG8: =+SUM(E8:BE8) -> 0 | BL8: 0
C9: Ecarts de réévaluation | E9: =+'Bilan Passif '!C13/10^6 -> 0 | Q9: =-E9 -> 0 | BG9: =+SUM(E9:BE9) -> 0 | BL9: 0
C10: Réserves indisponibles | E10: =+'Bilan Passif '!C14/10^6 -> 0 | Q10: =-E10 -> 0 | BG10: =+SUM(E10:BE10) -> 0 | BL10: 0
C11: Réserves libres | E11: =+'Bilan Passif '!C15/10^6 -> 0 | Q11: =-E11 -> 0 | BG11: =+SUM(E11:BE11) -> 0 | BL11: 0
C12: Report à nouveau (+ ou - ) | E12: =+'Bilan Passif '!C16/10^6 -> -1228.6567 | Q12: =-E12 -> 1228.6567 | BG12: =+SUM(E12:BE12) -> 0 | BL12: 0
C13: Résultat net de l'exercice (bénéfice + ou perte -) | E13: =+'Bilan Passif '!C17/10^6 -> 4778.3637 | Q13: =-E13 -> -4778.3637 | BG13: =+SUM(E13:BE13) -> 0 | BL13: 0
C14: Subventions d'investissement | E14: =+'Bilan Passif '!C19/10^6 -> 0 | Q14: =-E14 -> 0 | BG14: =+SUM(E14:BE14) -> 0 | BL14: 0
C15: Provisions réglementées et fonds assimilés | E15: =+'Bilan Passif '!C20/10^6 -> 0 | Q15: =-E15 -> 0 | BG15: =+SUM(E15:BE15) -> 0 | BL15: 0
B17: SN1131 | C17: Capital & réserves - part du groupe | Q17: =-SUM('BG '!J4:K11,'BG '!J688:K688,'BG '!J687)/10^6 -> 9179.6233 | Z17: =-94.2828596846101-Z18 -> 45.27428 | AD17: =1196.5+60.0905809212002 -> 1256.5906 | AF17: 48.608513 | AH17: =275.906817837868+458.955034+527.51748+272.1091863+197.1612356+184.7497827+175.5695235+243.3039189+0.0457790733726142 -> 2335.3188 | AK17: =-52.3534514953817-297.576952826635-404.060113074649-276.452537231798-242.21997880329-185.519873683713-140.635020157903-124.221386494723 -> -1723.0393 | AS17: =-87.0857085-72.2560097-58.0208139-20.72798 -> -238.09051 | AU17: =-371.084564984+246.78740723+200.150696+58.1525 -> 134.00604 | BA17: =222.456446+46.8762550000001-210.424885+12.9370556+41.4813511+75.4173266-111.5003687+2.863455 -> 80.106636 | BC17: =19085+7314 -> 26399 | BD17: =2116.8-1.951335 -> 2114.8487 | BE17: =211.133221692526+178.572330668901+132.956685332176+101.946129422176+70.935573512176+39.925017602176+8.914461692176 -> 744.38342 | BG17: =+SUM(E17:BE17) -> 40376.63 | BL17: 40376.584
B18: SN1132 | C18: Résultat net - part du groupe | Q18: =-SUM('BG '!J448:K687)/1000000 -> 4778.3637 | Z18: ='Passage P&L-par nature'!Y191 -> -139.55714 | AJ18: ='Passage Actif BC '!AF103*70% -> 368.08803 | AL18: =(+'Passage Actif BC '!AH30)*70% -> -160.64584 | AT18: =('Impacts_IFRS.16-09'!L85*70%) -> 40.756979 | AV18: =-SUM('BG '!H29:I29)/10^6*70% -> 0 | BB18: =-SUM('BG '!H271:I272)/1000000*70% -> 0.0858508 | BE18: =(+Activation!CN240)*70%/1000000 -> 31.225326 | BG18: =+SUM(E18:BE18) -> 4918.3169 | BL18: 3337.3214
B19: SN1141 | C19: Titres d’autocontrôle | BG19: =+SUM(E19:BE19) -> 0 | BL19: 0
B20: SN1161 | C20: Ecarts de réévaluation | BG20: =+SUM(E20:BE20) -> 0 | BL20: 0
B21: SN1163 | C21: Impôts différés sur les écarts de réévaluation | BG21: =+SUM(E21:BE21) -> 0 | BL21: 0
B22: SN1171 | C22: Ecarts actuariels sur avantages du personnel | AF22: =-48.468784+153.063162027155+54.2999999999998-64.6156183425448-61.4977152467883+42.6783600365493 -> 75.459404 | AG22: =-PIDR!D13 -> 110.2 | BG22: =+SUM(E22:BE22) -> 185.6594 | BL22: 75.459404
B23: SN1172 | C23: Impôts différés sur les écarts actuariels sur avantages du personnel | AF23: =14.5406352-45.9189486081465-16.29+19.3846855027635+18.4493145740365-12.8035080109648 -> -22.637821 | AG23: =-AG22*30% -> -33.06 | BG23: =+SUM(E23:BE23) -> -55.697821 | BL23: -22.637821
B24: SN1191 | C24: Ecarts de réévaluation des instruments de capitaux propres | BG24: =+SUM(E24:BE24) -> 0 | BL24: 0
B25: SN1192 | C25: Impôts différés sur les écarts de réévaluation des instruments de capitaux propres | BG25: =+SUM(E25:BE25) -> 0 | BL25: 0
B26: TSN 1000 | C26: Situation nette - Part du groupe | E26: =+SUM(E7:E15) -> 13957.987 | G26: =+SUM(G17:G25) -> 0 | H26: =+SUM(H17:H25) -> 0 | I26: =+SUM(I17:I25) -> 0 | J26: =+SUM(J17:J25) -> 0 | K26: =+SUM(K17:K25) -> 0 | L26: =+SUM(L17:L25) -> 0 | M26: =+SUM(M17:M25) -> 0 | N26: =+SUM(N17:N25) -> 0 | ... P26: =+SUM(P17:P25) -> 0 | Q26: =+SUM(Q7:Q25) -> 0 | R26: =+SUM(R7:R25) -> 0 | S26: =+SUM(S7:S25) -> 0 | T26: =+SUM(T7:T25) -> 0 | U26: =+SUM(U7:U25) -> 0 | V26: =+SUM(V7:V25) -> 0 | W26: =+SUM(W7:W25) -> 0 | X26: =+SUM(X7:X25) -> 0 | ... BE26: =+SUM(BE7:BE25) -> 775.60875 | BG26: =+SUM(BG7:BG25) -> 45424.909 | BL26: 43766.727
B28: SN1231 | C28: Capital & réserves - part des minoritaires | BG28: =+SUM(E28:BE28) -> 0 | BL28: 0
B29: SN1232 | C29: Résultat net - part des minoritaires | BG29: =+SUM(E29:BE29) -> 0 | BL29: 0
B30: SN1261 | C30: Ecarts de réévaluation | BG30: =+SUM(E30:BE30) -> 0 | BL30: 0
B31: SN1263 | C31: Impôts différés sur les écarts de réévaluation | BG31: =+SUM(E31:BE31) -> 0 | BL31: 0
B32: SN1271 | C32: Ecarts actuariels sur avantages du personnel | BG32: =+SUM(E32:BE32) -> 0 | BL32: 0
B33: SN1272 | C33: Impôts différés sur les écarts actuariels sur avantages du personnel | BG33: =+SUM(E33:BE33) -> 0 | BL33: 0
