Workbook

Sheet RECAP 
A2: RUBRIQUES | B2: REVENU INTERCO | C2: CHARGES INTERCO
A3: INTERCO NATIONAL VOIX HT | B3: ='[1]NAT+INT DETAIL '!D14 -> 0 | C3: ='[1]NAT+INT DETAIL '!G14 -> 0
A4: INTERCO NATIONAL SMS HT | B4: ='[1]NAT+INT DETAIL '!D16 -> 0 | C4: ='[1]NAT+INT DETAIL '!G16 -> 0
A5: RN NATIONAL SBIN | B5: =+'TRAFIC&REVENU DETAILS'!G27 -> 3.4869206e+08 | C5: =+'TRAFIC&REVENU DETAILS'!D27 -> 3998053.1
A6: RN NATIONAL MTN | B6: =+'TRAFIC&REVENU DETAILS'!G32 -> 0 | C6: =+'TRAFIC&REVENU DETAILS'!D32 -> 618597.8
A7: TOTAL (1) HT | B7: =+B3+B4+B5+B6 -> 3.4869206e+08 | C7: =+C3+C4+C5+C6 -> 4616650.9
A8: INTERNATIONAL VOIX HT | B8: =+'TRAFIC&REVENU DETAILS'!D70 -> 1.1237062e+08 | C8: =+'TRAFIC&REVENU DETAILS'!G70 -> 1.5512832e+08
A9: INTERNATIONAL SMS HT | B9: =+'TRAFIC&REVENU DETAILS'!D80 -> 1.1068393e+08 | C9: =+'TRAFIC&REVENU DETAILS'!G80 -> 2451652.4
A10: TOTAL (2) HT | B10: =+B8+B9 -> 2.2305455e+08 | C10: =+C8+C9 -> 1.5757997e+08
A11: ROAMING (3) HT | B11: =+'TRAFIC&REVENU DETAILS'!D89 -> 64485749 | C11: =+'TRAFIC&REVENU DETAILS'!G89 -> 14744419
A12: Provisions DIOT (Avril.25) (6) | B12: =+'Current Month-Summary'!I37*655.957 -> -1913326.1 | D12: Provisions DIOT (Mar.25)(5) | E12: ='Current Month-Summary (2)'!I35*655.957 -> -1227602.6
A13: TOTAL 4 (1+2+3) HT | B13: =B7+B10+B11 -> 6.3623236e+08 | C13: =C7+C10+C11 -> 1.7694104e+08
A14: GRAND TOTAL (4+5+6) HT | B14: =E12+B13+B12 -> 6.3309143e+08 | C14: =C7+C10+C11 -> 1.7694104e+08
B24: =B10/1000000 -> 223.05455
B25: ='TRAFIC&REVENU DETAILS'!C70/1000000 -> 1.0351576
B26: =B24/B25 -> 215.47883

Sheet TRAFIC&REVENU DETAILS
B1: ENREGISTREMENT | F1: Référence: ENG.OPT.04
F2: Indice de révision: 00
F3: Créé le: 13/07/2012
F4: Dernière modif le:
A5: POINT DES CREANCES ET DETTES DES CARRIERS SUR LE TRAFIC | F5: Pagination: page 1 sur 1
A7: 45778
A8: NATIONAL
B9: INCOMING | E9: OUTGOING
B10: TRAFIC VOIX NATIONAL | E10: TRAFIC VOIX NATIONAL
B11: TA | C11: TRAFIC | D11: REVENU | E11: TA | F11: TRAFIC | G11: CHARGES | H11: BALANCE
A12: MTN (en minutes ) | B12: 0 | C12: =ICT!D26 -> 29853237 | D12: 0 | E12: 0 | F12: =+ICT!D126 -> 34730006 | G12: 0 | H12: =+D12-G12 -> 0
A13: SBIN MOBILE (en minutes ) | B13: 0 | C13: =ICT!D27 -> 1.0080555e+08 | D13: 0 | E13: 0 | F13: =+ICT!D127 -> 25869595 | G13: 0 | H13: =+D13-G13 -> 0
A14: SBIN FIXE (en minutes ) | B14: 0 | C14: =ICT!D8 -> 27746.433 | D14: 0 | E14: 0 | F14: =+ICT!D110 -> 46704.1 | G14: 0 | H14: =+D14-G14 -> 0
A15: SOUS TOTAL | C15: =SUM(C12:C14) -> 1.3068653e+08 | D15: =SUM(D12:D14) -> 0 | F15: =SUM(F12:F14) -> 60646305 | G15: =SUM(G12:G14) -> 0 | H15: =SUM(H12:H14) -> 0
B16: TRAFIC SMS NATIONAL | E16: TRAFIC SMS NATIONAL
B17: TA | C17: TRAFIC | D17: REVENU | E17: TA | F17: TRAFIC | G17: CHARGES
A18: MTN SMS (Unités) | B18: 0 | C18: =ICT!C48 -> 2724684 | D18: =+B18*C18 -> 0 | E18: =B18 -> 0 | F18: =+ICT!C150 -> 2676573 | G18: =+E18*F18 -> 0 | H18: =D18-G18 -> 0
A19: SBIN SMS (Unités) | B19: 0 | C19: =ICT!C49 -> 3476412 | D19: =+B19*C19 -> 0 | F19: =+ICT!C151 -> 2890730 | G19: =+E19*F19 -> 0
A20: SOUS TOTAL | C20: =+C18+C19 -> 6201096 | D20: =D18 -> 0 | F20: =+F18 -> 2676573 | G20: =G18 -> 0 | H20: =H18 -> 0
B21: TRAFIC ROAMING NATIONAL VOIX | E21: TRAFIC ROAMING NATIONAL
A22: SBIN
B23: TA | C23: TRAFIC | D23: CHARGES | E23: TA | F23: TRAFIC | G23: REVENU
A24: SBIN VOIX (en minutes ) | B24: =6/1.18 -> 5.0847458 | C24: =REVENU!C68 -> 475353.78 | D24: =+B24*C24 -> 2417053.1 | E24: =6/1.18 -> 5.0847458 | F24: =+REVENU!C34 -> 45038969 | G24: =+E24*F24 -> 2.2901171e+08 | H24: =G24-D24 -> 2.2659465e+08
A25: SBIN SMS (Unités) | B25: =0.6/1.18 -> 0.50847458 | C25: =REVENU!D68 -> 9300 | D25: =+B25*C25 -> 4728.8136 | E25: =0.6/1.18 -> 0.50847458 | F25: =+REVENU!D34 -> 374553 | G25: =+E25*F25 -> 190450.68 | H25: =G25-D25 -> 185721.86
A26: SBIN DATA (en Go) | B26: =400/1.18 -> 338.98305 | C26: =REVENU!E68 -> 4650 | D26: =+B26*C26 -> 1576271.2 | E26: =400/1.18 -> 338.98305 | F26: =+REVENU!E34 -> 352495.21 | G26: =+E26*F26 -> 1.194899e+08 | H26: =G26-D26 -> 1.1791363e+08
D27: =SUM(D24:D26) -> 3998053.1 | G27: =SUM(G24:G26) -> 3.4869206e+08 | H27: =G27-D27 -> 3.4469401e+08
A28: MTN
A29: MTN VOIX (en minutes ) | B29: =6/1.18 -> 5.0847458 | C29: =+ICT!D33 -> 53968.4 | D29: =+B29*C29 -> 274415.59 | E29: =8.5/1.18 -> 7.2033898 | G29: =+E29*F29 -> 0
A30: MTN SMS (Unités) | B30: =0.6/1.18 -> 0.50847458 | C30: =+ICT!C36 -> 10225 | D30: =+B30*C30 -> 5199.1525 | E30: =1/1.18 -> 0.84745763 | G30: =+E30*F30 -> 0
A31: MTN DATA (en Go) | B31: =400/1.18 -> 338.98305 | C31: 1000 | D31: =+B31*C31 -> 338983.05 | E31: =500/1.18 -> 423.72881 | G31: =+E31*F31 -> 0
D32: =+D29+D30+D31 -> 618597.8 | G32: =SUM(G29:G31) -> 0
A38: INTERNATIONAL VOIX
B39: INCOMING | E39: OUTGOING | K39: TRAFIC FREE ROAMING
B40: TA | C40: TRAFIC | D40: REVENU | E40: TA | F40: TRAFIC | G40: CHARGES | H40: BALANCE | K40: ENTRANT | L40: SORTANT
A41: ORANGE BF (en minutes ) | B41: 180 | C41: 0 | D41: =C41*B41 -> 0 | E41: =0.2995*655.957 -> 196.45912 | H41: =+D41-G41 -> 0 | N41: =B41*C41 -> 0 | O41: =N41/1000000 -> 0 | AF41: =C42+C44+C50 -> 353834.03
A42: BELGA VOIX(en minutes ) | B42: =0.3*655.957 -> 196.7871 | C42: =+ICT!D10-C68 -> 55460.75 | D42: =(C42*B42)+(B65*C65)+(1600*655.957) -> 11963491 | F42: =+ICT!D114+ICT!D91 -> 226828.8 | G42: =(ICT!B156+ICT!B114+ICT!B91)*655.957 -> 28500835 | H42: =+D42-G42 -> -16537343 | N42: =B42*C42 -> 10913960 | O42: =N42/1000000 -> 10.91396 | AF42: =AF41/C70 -> 0.34181658
A43: BTI(en minutes ) | B43: =0.3*655.957 -> 196.7871 | C43: =0 -> 0 | D43: =(C43*B43)+(B66*C66) -> 0 | H43: =+D43-G43 -> 0 | N43: =B43*C43 -> 0 | O43: =N43/1000000 -> 0 | T43: =C43/'[2]NAT+INT'!$C$25-1 -> -1
A44: ORANGE (en minutes ) | B44: =0.3*655.957 -> 196.7871 | C44: =+ICT!D12 -> 29838.8 | D44: =C44*B44 -> 5871890.9 | H44: =+D44-G44 -> 5871890.9 | N44: =B44*C44 -> 5871890.9 | O44: =N44/1000000 -> 5.8718909
A45: PCCW(en minutes ) | B45: =0.3*655.957 -> 196.7871 | C45: 0 | D45: =C45*B45 -> 0 | H45: =+D45-G45 -> 0 | N45: =B45*C45 -> 0 | O45: =N45/1000000 -> 0
A46: ORANGE CI | B46: 125 | C46: 0 | D46: =C46*B46 -> 0 | E46: 125 | H46: =+D46-G46 -> 0
...

Sheet RECAP
B1: ENREGISTREMENT | F1: Référence: ENG.OPT.04
F2: Indice de révision: 00
F3: Créé le: 13/07/2012
F4: Dernière modif le:
A5: POINT DES CREANCES ET DETTES DES CARRIERS SUR LE TRAFIC | F5: Pagination: page 1 sur 1
A7: 45778
A8: NATIONAL
B9: INCOMING | E9: OUTGOING
B10: TRAFIC VOIX NATIONAL | E10: TRAFIC VOIX NATIONAL
B11: TA | C11: TRAFIC | D11: REVENU | E11: TA | F11: TRAFIC | G11: CHARGES | H11: BALANCE
A12: MTN (en minutes ) | B12: 0 | C12: =ICT!D26 -> 29853237 | D12: 0 | E12: 0 | F12: =+ICT!D126 -> 34730006 | G12: 0 | H12: =+D12-G12 -> 0
A13: SBIN MOBILE (en minutes ) | B13: 0 | C13: =ICT!D27 -> 1.0080555e+08 | D13: 0 | E13: 0 | F13: =+ICT!D127 -> 25869595 | G13: 0 | H13: =+D13-G13 -> 0
A14: SBIN FIXE (en minutes ) | B14: 0 | C14: =ICT!D8 -> 27746.433 | D14: 0 | E14: 0 | F14: =+ICT!D110 -> 46704.1 | G14: 0 | H14: =+D14-G14 -> 0
A15: SOUS TOTAL | C15: =SUM(C12:C14) -> 1.3068653e+08 | D15: =SUM(D12:D14) -> 0 | F15: =SUM(F12:F14) -> 60646305 | G15: =SUM(G12:G14) -> 0 | H15: =SUM(H12:H14) -> 0
B16: TRAFIC SMS NATIONAL | E16: TRAFIC SMS NATIONAL
B17: TA | C17: TRAFIC | D17: REVENU | E17: TA | F17: TRAFIC | G17: CHARGES
A18: MTN SMS (Unités) | B18: 0 | C18: =ICT!C48 -> 2724684 | D18: =+B18*C18 -> 0 | E18: =B18 -> 0 | F18: =+ICT!C150 -> 2676573 | G18: =+E18*F18 -> 0 | H18: =D18-G18 -> 0
A19: SBIN SMS (Unités) | B19: 0 | C19: =ICT!C49 -> 3476412 | D19: =+B19*C19 -> 0 | F19: =+ICT!C151 -> 2890730 | G19: =+E19*F19 -> 0
A20: SOUS TOTAL | C20: =+C18+C19 -> 6201096 | D20: =D18 -> 0 | F20: =+F18 -> 2676573 | G20: =G18 -> 0 | H20: =H18 -> 0
B21: TRAFIC ROAMING NATIONAL VOIX | E21: TRAFIC ROAMING NATIONAL
A22: SBIN
B23: TA | C23: TRAFIC | D23: CHARGES | E23: TA | F23: TRAFIC | G23: REVENU
A24: SBIN VOIX (en minutes ) | B24: =6/1.18 -> 5.0847458 | C24: =REVENU!C68 -> 475353.78 | D24: =+B24*C24 -> 2417053.1 | E24: =6/1.18 -> 5.0847458 | F24: =+REVENU!C34 -> 45038969 | G24: =+E24*F24 -> 2.2901171e+08 | H24: =G24-D24 -> 2.2659465e+08
A25: SBIN SMS (Unités) | B25: =0.6/1.18 -> 0.50847458 | C25: =REVENU!D68 -> 9300 | D25: =+B25*C25 -> 4728.8136 | E25: =0.6/1.18 -> 0.50847458 | F25: =+REVENU!D34 -> 374553 | G25: =+E25*F25 -> 190450.68 | H25: =G25-D25 -> 185721.86
A26: SBIN DATA (en Go) | B26: =400/1.18 -> 338.98305 | C26: =REVENU!E68 -> 4650 | D26: =+B26*C26 -> 1576271.2 | E26: =400/1.18 -> 338.98305 | F26: =+REVENU!E34 -> 352495.21 | G26: =+E26*F26 -> 1.194899e+08 | H26: =G26-D26 -> 1.1791363e+08
D27: =SUM(D24:D26) -> 3998053.1 | G27: =SUM(G24:G26) -> 3.4869206e+08 | H27: =G27-D27 -> 3.4469401e+08
A28: MTN
A29: MTN VOIX (en minutes ) | B29: =6/1.18 -> 5.0847458 | C29: =+ICT!D33 -> 53968.4 | D29: =+B29*C29 -> 274415.59 | E29: =8.5/1.18 -> 7.2033898 | G29: =+E29*F29 -> 0
A30: MTN SMS (Unités) | B30: =0.6/1.18 -> 0.50847458 | C30: =+ICT!C36 -> 10225 | D30: =+B30*C30 -> 5199.1525 | E30: =1/1.18 -> 0.84745763 | G30: =+E30*F30 -> 0
A31: MTN DATA (en Go) | B31: =400/1.18 -> 338.98305 | C31: 1000 | D31: =+B31*C31 -> 338983.05 | E31: =500/1.18 -> 423.72881 | G31: =+E31*F31 -> 0
D32: =+D29+D30+D31 -> 618597.8 | G32: =SUM(G29:G31) -> 0
A38: INTERNATIONAL VOIX
B39: INCOMING | E39: OUTGOING | K39: TRAFIC FREE ROAMING
B40: TA | C40: TRAFIC | D40: REVENU | E40: TA | F40: TRAFIC | G40: CHARGES | H40: BALANCE | K40: ENTRANT | L40: SORTANT
A41: ORANGE BF (en minutes ) | B41: 180 | C41: 0 | D41: =C41*B41 -> 0 | E41: =0.2995*655.957 -> 196.45912 | H41: =+D41-G41 -> 0 | N41: =B41*C41 -> 0 | O41: =N41/1000000 -> 0 | AF41: =C42+C44+C50 -> 353834.03
A42: BELGA VOIX(en minutes ) | B42: =0.3*655.957 -> 196.7871 | C42: =+ICT!D10-C68 -> 55460.75 | D42: =(C42*B42)+(B65*C65)+(1600*655.957) -> 11963491 | F42: =+ICT!D114+ICT!D91 -> 226828.8 | G42: =(ICT!B156+ICT!B114+ICT!B91)*655.957 -> 28500835 | H42: =+D42-G42 -> -16537343 | N42: =B42*C42 -> 10913960 | O42: =N42/1000000 -> 10.91396 | AF42: =AF41/C70 -> 0.34181658
A43: BTI(en minutes ) | B43: =0.3*655.957 -> 196.7871 | C43: =0 -> 0 | D43: =(C43*B43)+(B66*C66) -> 0 | H43: =+D43-G43 -> 0 | N43: =B43*C43 -> 0 | O43: =N43/1000000 -> 0 | T43: =C43/'[2]NAT+INT'!$C$25-1 -> -1
A44: ORANGE (en minutes ) | B44: =0.3*655.957 -> 196.7871 | C44: =+ICT!D12 -> 29838.8 | D44: =C44*B44 -> 5871890.9 | H44: =+D44-G44 -> 5871890.9 | N44: =B44*C44 -> 5871890.9 | O44: =N44/1000000 -> 5.8718909
A45: PCCW(en minutes ) | B45: =0.3*655.957 -> 196.7871 | C45: 0 | D45: =C45*B45 -> 0 | H45: =+D45-G45 -> 0 | N45: =B45*C45 -> 0 | O45: =N45/1000000 -> 0
A46: ORANGE CI | B46: 125 | C46: 0 | D46: =C46*B46 -> 0 | E46: 125 | H46: =+D46-G46 -> 0
...

Sheet ICT
A1: Aggregated Data | B1: 1.102099e+08 | C1: 17220504359
A3: Rating Scenario:EN-RTRAN | B3: 0 | C3: 117257 | D3: =+C3/60 -> 1954.2833
A4: Billing Operator:MT-BEN | B4: 0 | C4: 117257 | D4: =+C4/60 -> 1954.2833
A5: Rating Scenario:ENT-COUR | B5: 174975 | C5: 132069 | D5: =+C5/60 -> 2201.15
D6: =+C6/60 -> 0
A7: Rating Scenario:ENT-FIX | B7: 0 | C7: 1664786 | D7: =+C7/60 -> 27746.433
A8: Billing Operator:SBIN | B8: 0 | C8: 1664786 | D8: =+C8/60 -> 27746.433
A9: Rating Scenario:ENT-INT | B9: 55089592 | C9: 87794132 | D9: =+C9/60 -> 1463235.5
A10: Billing Operator:BELGA | B10: 19510.045 | C10: 3921645 | D10: =+C10/60 -> 65360.75
A11: Billing Operator:FRSN | B11: 58439.167 | C11: 70127 | D11: =+C11/60 -> 1168.7833
A12: Billing Operator:FT | B12: 8893.21 | C12: 1790328 | D12: =+C12/60 -> 29838.8
A13: Billing Operator:GA-TEL | B13: 1552536.5 | C13: 717057 | D13: =+C13/60 -> 11950.95
A14: Billing Operator:MATEL | B14: 76598.885 | C14: 15386533 | D14: =+C14/60 -> 256442.22
A15: Billing Operator:MV-NE | B15: 2408.1653 | C15: 3184 | D15: =+C15/60 -> 53.066667
A16: Billing Operator:MV-RCI | B16: 4351404.7 | C16: 5148423 | D16: =+C16/60 -> 85807.05
A17: Billing Operator:MV-TOG | B17: 33195942 | C17: 43846225 | D17: =+C17/60 -> 730770.42
A18: Billing Operator:ONATEL | B18: 5580758.3 | C18: 3782583 | D18: =+C18/60 -> 63043.05
... A23: Billing Operator:SBIN | B23: 0 | C23: 26856650 | D23: =+C23/60 -> 447610.83
D24: =+C24/60 -> 0
A25: Rating Scenario:ENT-NAT | B25: 0 | C25: 7839526958 | D25: =+C25/60 -> 1.3065878e+08
A26: Billing Operator:MT-BEN | B26: 0 | C26: 1791194193 | D26: =+C26/60 -> 29853237
A27: Billing Operator:SBIN | B27: 0 | C27: 6048332765 | D27: =+C27/60 -> 1.0080555e+08
A28: Rating Scenario:ENT-RFIX | B28: 0 | C28: 1037 | D28: =+C28/60 -> 17.283333
A29: Billing Operator:SBIN | B29: 0 | C29: 1037 | D29: =+C29/60 -> 17.283333
A30: Rating Scenario:ENT-RNAT | B30: 0 | C30: 161788610 | D30: =+C30/60 -> 2696476.8
A31: Billing Operator:SBIN | B31: 0 | C31: 161788610 | D31: =+C31/60 -> 2696476.8
A32: Rating Scenario:ENT-RNMT | B32: 0 | C32: 3238104 | D32: =+C32/60 -> 53968.4
A33: Billing Operator:MT-BEN | B33: 0 | C33: 3238104 | D33: =+C33/60 -> 53968.4
A35: Rating Scenario:ENT-RSMS | B35: 0 | C35: 8518336
A36: Billing Operator:MT-BEN | B36: 0 | C36: 10225
A37: Billing Operator:SBIN | B37: 0 | C37: 8508111
A38: Rating Scenario:ENT-SA2P | B38: 28596.89 | C38: 408527
A39: Billing Operator:BELGA | B39: 28596.89 | C39: 408527
A40: Rating Scenario:ENT-SMSI | B40: 5488.3528 | C40: 1866623
A41: Billing Operator:BELGA | B41: 23.04 | C41: 329
A42: Billing Operator:MV-NE | B42: 0 | C42: 565952
A43: Billing Operator:MV-TOG | B43: 274.56 | C43: 1220644
A44: Billing Operator:SBIN | B44: 0 | C44: 1
A45: Billing Operator:SYB | B45: 5190.7528 | C45: 79697
A47: Rating Scenario:ENT-SMSN | B47: 0 | C47: 6201096
...

Sheet ROAMING IN 
D2: CALL ANALYSIS REPORT
D4: Client: BEN02
D6: Roaming Parnters: ALL
D7: Direction: TAP OUT
D8: Record Type: ALL
D10: Currency: XOF
D11: Report Type: Monthly
D12: Month and Year From: May-2025
D13: Month and Year To: May-2025
I18: GPRS | AL18: MOC | BN18: MTC
I19: MMS | X19: Others | AL19: SMS | AZ19: Voice | BN19: SMS | CB19: Voice
A20: Client | B20: RP Code | E20: Roaming Partner Name | F20: Direction | G20: Year | H20: Month | I20: Total Calls | K20: Duration in min. | L20: Ceil Duration in Min. | M20: Duration in Sec. | N20: Chargeable Units | O20: Charged Units | P20: Data Volume Incoming (KB) | Q20: Data Volume Outgoing (KB) | R20: Charges (SDR) | S20: Tax (SDR) | T20: Charges (XOF) | U20: Tax (XOF) | V20: Total Amount(XOF) | W20: Total Amount(SDR) | X20: Total Calls | Y20: Duration in min. | Z20: Ceil Duration in Min. | AA20: Duration in Sec. | AB20: Chargeable Units | AC20: Charged Units | AD20: Data Volume Incoming (KB) | AE20: Data Volume Outgoing (KB) | AF20: Charges (SDR) | AG20: Tax (SDR) | AH20: Charges (XOF) | AI20: Tax (XOF) | AJ20: Total Amount(XOF) | AK20: Total Amount(SDR) | AL20: Total Calls | AM20: Duration in min. | AN20: Ceil Duration in Min. | AO20: Duration in Sec. | AP20: Chargeable Units | AQ20: Charged Units | AR20: Data Volume Incoming (KB) | AS20: Data Volume Outgoing (KB) | AT20: Charges (SDR) | AU20: Tax (SDR) | AV20: Charges (XOF) | AW20: Tax (XOF) | AX20: Total Amount(XOF) | AY20: Total Amount(SDR) | AZ20: Total Calls | BA20: Duration in min. | BB20: Ceil Duration in Min. | BC20: Duration in Sec. | BD20: Chargeable Units | BE20: Charged Units | BF20: Data Volume Incoming (KB) | BG20: Data Volume Outgoing (KB) | BH20: Charges (SDR) | BI20: Tax (SDR) | BJ20: Charges (XOF) | BK20: Tax (XOF) | BL20: Total Amount(XOF) | BM20: Total Amount(SDR) | BN20: Total Calls | BO20: Duration in min. | BP20: Ceil Duration in Min. | BQ20: Duration in Sec. | BR20: Chargeable Units | BS20: Charged Units | BT20: Data Volume Incoming (KB) | BU20: Data Volume Outgoing (KB) | BV20: Charges (SDR) | BW20: Tax (SDR) | BX20: Charges (XOF) | BY20: Tax (XOF) | BZ20: Total Amount(XOF) | CA20: Total Amount(SDR) | CB20: Total Calls | CC20: Duration in min. | CD20: Ceil Duration in Min. | CE20: Duration in Sec. | CF20: Chargeable Units | CG20: Charged Units | CH20: Data Volume Incoming (KB) | CI20: Data Volume Outgoing (KB) | CJ20: Charges (SDR) | CK20: Tax (SDR) | CL20: Charges (XOF) | CM20: Tax (XOF) | CN20: Total Amount(XOF) | CO20: Total Amount(SDR)
A21: BEN02 | B21: AAZOR | E21: Orange France (M2m Traffic) | F21: INBOUND | G21: 2025 | H21: May | AL21: 1 | AM21: 0 | AN21: 0 | AO21: 0 | AP21: 0 | AQ21: 0 | AR21: 0 | AS21: 0 | AT21: 0.006 | AU21: 0.001 | AV21: 4.448 | AW21: 0.8 | AX21: 5.248 | AY21: 0.007 | BN21: 1 | BO21: 0 | BP21: 0 | BQ21: 0 | BR21: 0 | BS21: 0 | BT21: 0 | BU21: 0 | BV21: 0 | BW21: 0 | BX21: 0 | BY21: 0 | BZ21: 0 | CA21: 0 | CB21: 1 | CC21: 1 | CD21: 1 | CE21: 60 | CF21: 60 | CG21: 60 | CH21: 0 | CI21: 0 | CJ21: 0 | CK21: 0 | CL21: 0 | CM21: 0 | CN21: 0 | CO21: 0
B22: AAZTD | E22: Telekom Deutschland Gmbh | F22: INBOUND | G22: 2025 | H22: May | AL22: 70 | AM22: 0 | AN22: 0 | AO22: 0 | AP22: 0 | AQ22: 0 | AR22: 0 | AS22: 0 | AT22: 1.177 | AU22: 0.212 | AV22: 918.363 | AW22: 165.327 | AX22: 1083.69 | AY22: 1.389 | BN22: 68 | BO22: 0 | BP22: 0 | BQ22: 0 | BR22: 0 | BS22: 0 | BT22: 0 | BU22: 0 | BV22: 0 | BW22: 0 | BX22: 0 | BY22: 0 | BZ22: 0 | CA22: 0
B23: AAZVF | E23: Vodafone Malta | F23: INBOUND | G23: 2025 | H23: May | X23: 2681 | Y23: 94962.283 | Z23: 0 | AA23: 5697737 | AB23: 38343 | AC23: 39085 | AD23: 9807 | AE23: 28536 | AF23: 0.257 | AG23: 0.046 | AH23: 200.385 | AI23: 36.044 | AJ23: 236.429 | AK23: 0.303
B24: ALBVF | E24: Vodafone Albani | F24: INBOUND | G24: 2025 | H24: May | X24: 6 | Y24: 112.833 | Z24: 0 | AA24: 6770 | AB24: 0 | AC24: 0 | AD24: 0 | AE24: 0 | AF24: 0 | AG24: 0 | AH24: 0 | AI24: 0 | AJ24: 0 | AK24: 0
B25: ARETC | E25: Etisalat, Uae | F25: INBOUND | G25: 2025 | H25: May | X25: 18442 | Y25: 354468.02 | Z25: 0 | AA25: 21268081 | AB25: 21364519 | AC25: 23156736 | AD25: 14907897 | AE25: 6456622 | AF25: 6446.763 | AG25: 1160.417 | AH25: 5028423.9 | AI25: 905116.19 | AJ25: 5933540.1 | AK25: 7607.181 | AL25: 7 | AM25: 0 | AN25: 0 | AO25: 0 | AP25: 0 | AQ25: 0 | AR25: 0 | AS25: 0 | AT25: 0.609 | AU25: 0.11 | AV25: 474.737 | AW25: 85.454 | AX25: 560.19 | AY25: 0.718 | AZ25: 8 | BA25: 12.567 | BB25: 17 | BC25: 754 | BD25: 754 | BE25: 801 | BF25: 0 | BG25: 0 | BH25: 4.186 | BI25: 0.753 | BJ25: 3264.745 | BK25: 587.654 | BL25: 3852.399 | BM25: 4.939 | BN25: 18745 | BO25: 0 | BP25: 0 | BQ25: 0 | BR25: 0 | BS25: 0 | BT25: 0 | BU25: 0 | BV25: 0 | BW25: 0 | BX25: 0 | BY25: 0 | BZ25: 0 | CA25: 0 | CB25: 57 | CC25: 52.35 | CD25: 85 | CE25: 3141 | CF25: 3141 | CG25: 5100 | CH25: 0 | CI25: 0 | CJ25: 0 | CK25: 0 | CL25: 0 | CM25: 0 | CN25: 0 | CO25: 0
B26: BELKO | E26: Telnet Group Bvba/Sprl | F26: INBOUND | G26: 2025 | H26: May | X26: 328 | Y26: 7550.033 | Z26: 0 | AA26: 453002 | AB26: 2701 | AC26: 2803 | AD26: 260 | AE26: 2441 | AF26: 0.012 | AG26: 0.002 | AH26: 8.971 | AI26: 1.624 | AJ26: 10.595 | AK26: 0.014 | AL26: 3 | AM26: 0 | AN26: 0 | AO26: 0 | AP26: 0 | AQ26: 0 | AR26: 0 | AS26: 0 | AT26: 0.025 | AU26: 0.005 | AV26: 19.679 | AW26: 3.543 | AX26: 23.222 | AY26: 0.03 | BN26: 148 | BO26: 0 | BP26: 0 | BQ26: 0 | BR26: 0 | BS26: 0 | BT26: 0 | BU26: 0 | BV26: 0 | BW26: 0 | BX26: 0 | BY26: 0 | BZ26: 0 | CA26: 0
B27: BELMO | E27: Mobistar Gsm | F27: INBOUND | G27: 2025 | H27: May | I27: 1 | K27: 1.733 | L27: 0 | M27: 104 | N27: 46 | O27: 46 | P27: 37 | Q27: 9 | R27: 0 | S27: 0 | T27: 0.2 | U27: 0.036 | V27: 0.236 | W27: 0 | X27: 366326 | Y27: 12151146 | Z27: 0 | AA27: 729068764 | AB27: 4094781 | AC27: 4170016 | AD27: 1916178 | AE27: 2178603 | AF27: 23.241 | AG27: 4.176 | AH27: 18128.118 | AI27: 3257.527 | AJ27: 21385.644 | AK27: 27.418 | AL27: 249 | AM27: 0 | AN27: 0 | AO27: 0 | AP27: 0 | AQ27: 0 | AR27: 0 | AS27: 0 | AT27: 1.42 | AU27: 0.255 | AV27: 1107.431 | AW27: 199.268 | AX27: 1306.699 | AY27: 1.675 | AZ27: 48 | BA27: 74.2 | BB27: 104 | BC27: 4452 | BD27: 4452 | BE27: 4425 | BF27: 0 | BG27: 0 | BH27: 9.595 | BI27: 1.727 | BJ27: 7483.894 | BK27: 1347.102 | BL27: 8830.996 | BM27: 11.322 | BN27: 2862 | BO27: 0 | BP27: 0 | BQ27: 0 | BR27: 0 | BS27: 0 | BT27: 0 | BU27: 0 | BV27: 0 | BW27: 0 | BX27: 0 | BY27: 0 | BZ27: 0 | CA27: 0 | CB27: 52 | CC27: 60.8 | CD27: 94 | CE27: 3648 | CF27: 3648 | CG27: 3648 | CH27: 0 | CI27: 0 | CJ27: 0 | CK27: 0 | CL27: 0 | CM27: 0 | CN27: 0 | CO27: 0
B28: BELTB | E28: Belgacom(Nv/Sa) | F28: INBOUND | G28: 2025 | H28: May | X28: 73618 | Y28: 1593542 | Z28: 0 | AA28: 95612518 | AB28: 7799242 | AC28: 7802392 | AD28: 4954033 | AE28: 2845210 | AF28: 54.304 | AG28: 9.775 | AH28: 42357.016 | AI28: 7624.452 | AJ28: 49981.469 | AK28: 64.079 | AL28: 44 | AM28: 0 | AN28: 0 | AO28: 0 | AP28: 0 | AQ28: 0 | AR28: 0 | AS28: 0 | AT28: 0.627 | AU28: 0.113 | AV28: 489.227 | AW28: 88.064 | AX28: 577.291 | AY28: 0.74 | AZ28: 17 | BA28: 31.883 | BB28: 44 | BC28: 1913 | BD28: 1913 | BE28: 1913 | BF28: 0 | BG28: 0 | BH28: 6.86 | BI28: 1.235 | BJ28: 5350.555 | BK28: 963.099 | BL28: 6313.654 | BM28: 8.095 | BN28: 2861 | BO28: 0 | BP28: 0 | BQ28: 0 | BR28: 0 | BS28: 0 | BT28: 0 | BU28: 0 | BV28: 0 | BW28: 0 | BX28: 0 | BY28: 0 | BZ28: 0 | CA28: 0 | CB28: 16 | CC28: 14.2 | CD28: 24 | CE28: 852 | CF28: 852 | CG28: 852 | CH28: 0 | CI28: 0 | CJ28: 0 | CK28: 0 | CL28: 0 | CM28: 0 | CN28: 0 | CO28: 0
B29: BELTN | E29: Telnet Group Bvba/Sprl | F29: INBOUND | G29: 2025 | H29: May | X29: 2 | Y29: 0.05 | Z29: 0 | AA29: 3 | AB29: 0 | AC29: 1 | AD29: 0 | AE29: 0 | AF29: 0 | AG29: 0 | AH29: 0.003 | AI29: 0.001 | AJ29: 0.004 | AK29: 0 | BN29: 2 | BO29: 0 | BP29: 0 | BQ29: 0 | BR29: 0 | BS29: 0 | BT29: 0 | BU29: 0 | BV29: 0 | BW29: 0 | BX29: 0 | BY29: 0 | BZ29: 0 | CA29: 0
B30: BFACT | E30: Orange (Airtel) - Bfaso | F30: INBOUND | G30: 2025 | H30: May | X30: 588682 | Y30: 1213892 | Z30: 0 | AA30: 72833520 | AB30: 66888 | AC30: 70244 | AD30: 20561 | AE30: 46328 | AF30: 0.576 | AG30: 0.102 | AH30: 449.191 | AI30: 79.404 | AJ30: 528.595 | AK30: 0.678 | BN30: 3 | BO30: 0 | BP30: 0 | BQ30: 0 | BR30: 0 | BS30: 0 | BT30: 0 | BU30: 0 | BV30: 0 | BW30: 0 | BX30: 0 | BY30: 0 | BZ30: 0 | CA30: 0
B31: BFAON | E31: Telmob | F31: INBOUND | G31: 2025 | H31: May | X31: 921130 | Y31: 15580195 | Z31: 0 | AA31: 934811680 | AB31: 10425585 | AC31: 10450223 | AD31: 6857304 | AE31: 3568282 | AF31: 51.5 | AG31: 9.271 | AH31: 40169.202 | AI31: 7231.335 | AJ31: 47400.537 | AK31: 60.771 | AL31: 744 | AM31: 0 | AN31: 0 | AO31: 0 | AP31: 0 | AQ31: 0 | AR31: 0 | AS31: 0 | AT31: 5.631 | AU31: 1.013 | AV31: 4392.397 | AW31: 790.388 | AX31: 5182.785 | AY31: 6.645 | AZ31: 287 | BA31: 269.733 | BB31: 445 | BC31: 16184 | BD31: 16184 | BE31: 16184 | BF31: 0 | BG31: 0 | BH31: 30.565 | BI31: 5.502 | BJ31: 23840.537 | BK31: 4291.301 | BL31: 28131.837 | BM31: 36.067 | BN31: 208281 | BO31: 0 | BP31: 0 | BQ31: 0 | BR31: 0 | BS31: 0 | BT31: 0 | BU31: 0 | BV31: 0 | BW31: 0 | BX31: 0 | BY31: 0 | BZ31: 0 | CA31: 0 | CB31: 503 | CC31: 436.65 | CD31: 728 | CE31: 26199 | CF31: 26199 | CG31: 26199 | CH31: 0 | CI31: 0 | CJ31: 0 | CK31: 0 | CL31: 0 | CM31: 0 | CN31: 0 | CO31: 0
B32: BFATL | E32: Telecel - Bfaso | F32: INBOUND | G32: 2025 | H32: May | AZ32: 1 | BA32: 0.25 | BB32: 1 | BC32: 15 | BD32: 15 | BE32: 60 | BF32: 0 | BG32: 0 | BH32: 0.239 | BI32: 0.043 | BJ32: 186.292 | BK32: 33.533 | BL32: 219.824 | BM32: 0.282 | BN32: 73585 | BO32: 0 | BP32: 0 | BQ32: 0 | BR32: 0 | BS32: 0 | BT32: 0 | BU32: 0 | BV32: 0 | BW32: 0 | BX32: 0 | BY32: 0 | BZ32: 0 | CA32: 0 | CB32: 534 | CC32: 552.25 | CD32: 853 | CE32: 33135 | CF32: 33135 | CG32: 41100 | CH32: 0 | CI32: 0 | CJ32: 0 | CK32: 0 | CL32: 0 | CM32: 0 | CN32: 0 | CO32: 0
B33: BRARN | E33: Tim - Brarn | F33: INBOUND | G33: 2025 | H33: May | BN33: 61 | BO33: 0 | BP33: 0 | BQ33: 0 | BR33: 0 | BS33: 0 | BT33: 0 | BU33: 0 | BV33: 0 | BW33: 0 | BX33: 0 | BY33: 0 | BZ33: 0 | CA33: 0
B34: BRASP | E34: Tim - Brasp | F34: INBOUND | G34: 2025 | H34: May | AL34: 7 | AM34: 0 | AN34: 0 | AO34: 0 | AP34: 0 | AQ34: 0 | AR34: 0 | AS34: 0 | AT34: 0.758 | AU34: 0.136 | AV34: 591.459 | AW34: 106.463 | AX34: 697.923 | AY34: 0.895 | AZ34: 7 | BA34: 6.983 | BB34: 11 | BC34: 419 | BD34: 419 | BE34: 660 | BF34: 0 | BG34: 0 | BH34: 12.12 | BI34: 2.182 | BJ34: 9453.654 | BK34: 1701.659 | BL34: 11155.312 | BM34: 14.302 | BN34: 30 | BO34: 0 | BP34: 0 | BQ34: 0 | BR34: 0 | BS34: 0 | BT34: 0 | BU34: 0 | BV34: 0 | BW34: 0 | BX34: 0 | BY34: 0 | BZ34: 0 | CA34: 0
B35: CAFAT | E35: Acell-Rca | F35: INBOUND | G35: 2025 | H35: May | AL35: 38 | AM35: 0 | AN35: 0 | AO35: 0 | AP35: 0 | AQ35: 0 | AR35: 0 | AS35: 0 | AT35: 0.288 | AU35: 0.052 | AV35: 224.343 | AW35: 40.369 | AX35: 264.712 | AY35: 0.339 | BN35: 1580 | BO35: 0 | BP35: 0 | BQ35: 0 | BR35: 0 | BS35: 0 | BT35: 0 | BU35: 0 | BV35: 0 | BW35: 0 | BX35: 0 | BY35: 0 | BZ35: 0 | CA35: 0 | CB35: 3 | CC35: 2.667 | CD35: 4 | CE35: 160 | CF35: 160 | CG35: 160 | CH35: 0 | CI35: 0 | CJ35: 0 | CK35: 0 | CL35: 0 | CM35: 0 | CN35: 0 | CO35: 0
B36: CANBM | E36: Bell Mobility | F36: INBOUND | G36: 2025 | H36: May | X36: 5484 | Y36: 103865.17 | Z36: 0 | AA36: 6231910 | AB36: 608455 | AC36: 609280 | AD36: 305182 | AE36: 303273 | AF36: 7.506 | AG36: 1.351 | AH36: 5854.412 | AI36: 1053.756 | AJ36: 6908.168 | AK36: 8.857 | AL36: 43 | AM36: 0 | AN36: 0 | AO36: 0 | AP36: 0 | AQ36: 0 | AR36: 0 | AS36: 0 | AT36: 0.181 | AU36: 0.033 | AV36: 141.034 | AW36: 25.39 | AX36: 166.424 | AY36: 0.213 | AZ36: 21 | BA36: 20.35 | BB36: 32 | BC36: 1221 | BD36: 1221 | BE36: 1221 | BF36: 0 | BG36: 0 | BH36: 1.392 | BI36: 0.251 | BJ36: 1085.609 | BK36: 195.411 | BL36: 1281.021 | BM36: 1.642 | BN36: 523 | BO36: 0 | BP36: 0 | BQ36: 0 | BR36: 0 | BS36: 0 | BT36: 0 | BU36: 0 | BV36: 0 | BW36: 0 | BX36: 0 | BY36: 0 | BZ36: 0 | CA36: 0 | CB36: 16 | CC36: 27.767 | CD36: 38 | CE36: 1666 | CF36: 1666 | CG36: 1666 | CH36: 0 | CI36: 0 | CJ36: 0 | CK36: 0 | CL36: 0 | CM36: 0 | CN36: 0 | CO36: 0
B37: CANMC | E37: Fido-Canada | F37: INBOUND | G37: 2025 | H37: May | X37: 38 | Y37: 55.033 | Z37: 0 | AA37: 3302 | AB37: 14648 | AC37: 14970 | AD37: 10859 | AE37: 3789 | AF37: 111.144 | AG37: 20.006 | AH37: 86691.241 | AI37: 15604.427 | AJ37: 102295.67 | AK37: 131.15 | AL37: 2 | AM37: 0 | AN37: 0 | AO37: 0 | AP37: 0 | AQ37: 0 | AR37: 0 | AS37: 0 | AT37: 0.217 | AU37: 0.039 | AV37: 168.988 | AW37: 30.418 | AX37: 199.407 | AY37: 0.256 | AZ37: 4 | BA37: 3.333 | BB37: 6 | BC37: 200 | BD37: 200 | BE37: 360 | BF37: 0 | BG37: 0 | BH37: 1.433 | BI37: 0.258 | BJ37: 1117.75 | BK37: 201.196 | BL37: 1318.946 | BM37: 1.691 | BN37: 35 | BO37: 0 | BP37: 0 | BQ37: 0 | BR37: 0 | BS37: 0 | BT37: 0 | BU37: 0 | BV37: 0 | BW37: 0 | BX37: 0 | BY37: 0 | BZ37: 0 | CA37: 0
B38: CANOB | E38: Sasktel Canada (Bics) | F38: INBOUND | G38: 2025 | H38: May | X38: 1 | Y38: 0.417 | Z38: 0 | AA38: 25 | AB38: 684 | AC38: 690 | AD38: 664 | AE38: 21 | AF38: 5.161 | AG38: 0.929 | AH38: 4025.887 | AI38: 724.659 | AJ38: 4750.546 | AK38: 6.091
B39: CANRW | E39: Rogers - Canada | F39: INBOUND | G39: 2025 | H39: May | X39: 12 | Y39: 17.017 | Z39: 0 | AA39: 1021 | AB39: 5891 | AC39: 5895 | AD39: 3820 | AE39: 2071 | AF39: 0.042 | AG39: 0.007 | AH39: 32.47 | AI39: 5.845 | AJ39: 38.316 | AK39: 0.049 | BN39: 9 | BO39: 0 | BP39: 0 | BQ39: 0 | BR39: 0 | BS39: 0 | BT39: 0 | BU39: 0 | BV39: 0 | BW39: 0 | BX39: 0 | BY39: 0 | BZ39: 0 | CA39: 0
B40: CANTS | E40: Telus | F40: INBOUND | G40: 2025 | H40: May | X40: 76331 | Y40: 453750.58 | Z40: 0 | AA40: 27225035 | AB40: 44606893 | AC40: 44613600 | AD40: 30967722 | AE40: 13639171 | AF40: 549.596 | AG40: 98.927 | AH40: 428680.81 | AI40: 77162.389 | AJ40: 505843.2 | AK40: 648.524 | AL40: 694 | AM40: 0 | AN40: 0 | AO40: 0 | AP40: 0 | AQ40: 0 | AR40: 0 | AS40: 0 | AT40: 2.918 | AU40: 0.525 | AV40: 2276.227 | AW40: 409.775 | AX40: 2686.002 | AY40: 3.444 | AZ40: 118 | BA40: 479.467 | BB40: 552 | BC40: 28768 | BD40: 28768 | BE40: 28768 | BF40: 0 | BG40: 0 | BH40: 29.279 | BI40: 5.27 | BJ40: 22837.147 | BK40: 4110.687 | BL40: 26947.834 | BM40: 34.549 | BN40: 4562 | BO40: 0 | BP40: 0 | BQ40: 0 | BR40: 0 | BS40: 0 | BT40: 0 | BU40: 0 | BV40: 0 | BW40: 0 | BX40: 0 | BY40: 0 | BZ40: 0 | CA40: 0 | CB40: 36 | CC40: 174.133 | CD40: 197 | CE40: 10448 | CF40: 10448 | CG40: 10448 | CH40: 0 | CI40: 0 | CJ40: 0 | CK40: 0 | CL40: 0 | CM40: 0 | CN40: 0 | CO40: 0
B41: CANVT | E41: Videotron | F41: INBOUND | G41: 2025 | H41: May | X41: 14128 | Y41: 241620.72 | Z41: 0 | AA41: 14497243 | AB41: 5050911 | AC41: 5051490 | AD41: 3224103 | AE41: 1826808 | AF41: 41.486 | AG41: 7.467 | AH41: 32358.989 | AI41: 5824.559 | AJ41: 38183.548 | AK41: 48.954 | AL41: 14 | AM41: 0 | AN41: 0 | AO41: 0 | AP41: 0 | AQ41: 0 | AR41: 0 | AS41: 0 | AT41: 0.118 | AU41: 0.021 | AV41: 91.836 | AW41: 16.533 | AX41: 108.369 | AY41: 0.139 | AZ41: 16 | BA41: 41.767 | BB41: 54 | BC41: 2506 | BD41: 2506 | BE41: 2506 | BF41: 0 | BG41: 0 | BH41: 2.981 | BI41: 0.537 | BJ41: 2325.368 | BK41: 418.565 | BL41: 2743.933 | BM41: 3.518 | BN41: 593 | BO41: 0 | BP41: 0 | BQ41: 0 | BR41: 0 | BS41: 0 | BT41: 0 | BU41: 0 | BV41: 0 | BW41: 0 | BX41: 0 | BY41: 0 | BZ41: 0 | CA41: 0 | CB41: 5 | CC41: 5.867 | CD41: 9 | CE41: 352 | CF41: 352 | CG41: 352 | CH41: 0 | CI41: 0 | CJ41: 0 | CK41: 0 | CL41: 0 | CM41: 0 | CN41: 0 | CO41: 0
B42: CHEC1 | E42: Swisscom(Switzerland)Ltd | F42: INBOUND | G42: 2025 | H42: May | X42: 365 | Y42: 13228.283 | Z42: 0 | AA42: 793697 | AB42: 23887 | AC42: 24030 | AD42: 15357 | AE42: 8530 | AF42: 0.178 | AG42: 0.032 | AH42: 138.549 | AI42: 24.952 | AJ42: 163.501 | AK42: 0.21 | AL42: 37 | AM42: 0 | AN42: 0 | AO42: 0 | AP42: 0 | AQ42: 0 | AR42: 0 | AS42: 0 | AT42: 0.311 | AU42: 0.056 | AV42: 242.71 | AW42: 43.694 | AX42: 286.404 | AY42: 0.367 | BN42: 484 | BO42: 0 | BP42: 0 | BQ42: 0 | BR42: 0 | BS42: 0 | BT42: 0 | BU42: 0 | BV42: 0 | BW42: 0 | BX42: 0 | BY42: 0 | BZ42: 0 | CA42: 0 | CB42: 5 | CC42: 13.833 | CD42: 17 | CE42: 830 | CF42: 830 | CG42: 830 | CH42: 0 | CI42: 0 | CJ42: 0 | CK42: 0 | CL42: 0 | CM42: 0 | CN42: 0 | CO42: 0
B43: CHEDX | E43: Sunrise Communications Ag | F43: INBOUND | G43: 2025 | H43: May | X43: 61862 | Y43: 1208470.9 | Z43: 0 | AA43: 72508254 | AB43: 17216991 | AC43: 17218752 | AD43: 13074736 | AE43: 4142255 | AF43: 70.706 | AG43: 12.727 | AH43: 55150.096 | AI43: 9927.051 | AJ43: 65077.147 | AK43: 83.433 | AL43: 421 | AM43: 0 | AN43: 0 | AO43: 0 | AP43: 0 | AQ43: 0 | AR43: 0 | AS43: 0 | AT43: 3.541 | AU43: 0.637 | AV43: 2761.647 | AW43: 497.162 | AX43: 3258.81 | AY43: 4.178 | AZ43: 46 | BA43: 138.933 | BB43: 164 | BC43: 8336 | BD43: 8336 | BE43: 8336 | BF43: 0 | BG43: 0 | BH43: 35.052 | BI43: 6.309 | BJ43: 27340.29 | BK43: 4921.253 | BL43: 32261.542 | BM43: 41.361 | BN43: 2958 | BO43: 0 | BP43: 0 | BQ43: 0 | BR43: 0 | BS43: 0 | BT43: 0 | BU43: 0 | BV43: 0 | BW43: 0 | BX43: 0 | BY43: 0 | BZ43: 0 | CA43: 0 | CB43: 16 | CC43: 16.967 | CD43: 27 | CE43: 1018 | CF43: 1018 | CG43: 1018 | CH43: 0 | CI43: 0 | CJ43: 0 | CK43: 0 | CL43: 0 | CM43: 0 | CN43: 0 | CO43: 0
B44: CHNCU | E44: China Unicom | F44: INBOUND | G44: 2025 | H44: May | AL44: 185 | AM44: 0 | AN44: 0 | AO44: 0 | AP44: 0 | AQ44: 0 | AR44: 0 | AS44: 0 | AT44: 7.779 | AU44: 1.4 | AV44: 6067.608 | AW44: 1092.195 | AX44: 7159.804 | AY44: 9.179 | AZ44: 65 | BA44: 74.3 | BB44: 110 | BC44: 4458 | BD44: 4458 | BE44: 6600 | BF44: 0 | BG44: 0 | BH44: 15.222 | BI44: 2.74 | BJ44: 11872.831 | BK44: 2137.115 | BL44: 14009.946 | BM44: 17.962 | BN44: 8903 | BO44: 0 | BP44: 0 | BQ44: 0 | BR44: 0 | BS44: 0 | BT44: 0 | BU44: 0 | BV44: 0 | BW44: 0 | BX44: 0 | BY44: 0 | BZ44: 0 | CA44: 0 | CB44: 41 | CC44: 30.733 | CD44: 59 | CE44: 1844 | CF44: 1844 | CG44: 3540 | CH44: 0 | CI44: 0 | CJ44: 0.05 | CK44: 0.009 | CL44: 38.702 | CM44: 6.958 | CN44: 45.66 | CO44: 0.059
B45: CHNDX | E45: China Telecom | F45: INBOUND | G45: 2025 | H45: May | X45: 107898 | Y45: 1996668.6 | Z45: 0 | AA45: 119800116 | AB45: 29113714 | AC45: 29114765 | AD45: 25511863 | AE45: 3601851 | AF45: 358.666 | AG45: 64.56 | AH45: 279756.43 | AI45: 50356.136 | AJ45: 330112.57 | AK45: 423.226 | AL45: 198 | AM45: 0 | AN45: 0 | AO45: 0 | AP45: 0 | AQ45: 0 | AR45: 0 | AS45: 0 | AT45: 3.33 | AU45: 0.6 | AV45: 2597.654 | AW45: 467.64 | AX45: 3065.294 | AY45: 3.93 | AZ45: 25 | BA45: 9.817 | BB45: 26 | BC45: 589 | BD45: 589 | BE45: 1560 | BF45: 0 | BG45: 0 | BH45: 1.598 | BI45: 0.288 | BJ45: 1246.32 | BK45: 224.341 | BL45: 1470.66 | BM45: 1.885 | BN45: 91 | BO45: 0 | BP45: 0 | BQ45: 0 | BR45: 0 | BS45: 0 | BT45: 0 | BU45: 0 | BV45: 0 | BW45: 0 | BX45: 0 | BY45: 0 | BZ45: 0 | CA45: 0
B46: CIV02 | E46: Moov(A-Cell) | F46: INBOUND | G46: 2025 | H46: May | X46: 989092 | Y46: 17109900 | Z46: 0 | AA46: 1026594002 | AB46: 9238158 | AC46: 9321945 | AD46: 3139222 | AE46: 6098937 | AF46: 45.944 | AG46: 8.281 | AH46: 35836.275 | AI46: 6459.153 | AJ46: 42295.427 | AK46: 54.225 | AL46: 32 | AM46: 0 | AN46: 0 | AO46: 0 | AP46: 0 | AQ46: 0 | AR46: 0 | AS46: 0 | AT46: 0.242 | AU46: 0.044 | AV46: 188.92 | AW46: 33.995 | AX46: 222.915 | AY46: 0.286 | AZ46: 1123 | BA46: 1466.8 | BB46: 2016 | BC46: 88008 | BD46: 88008 | BE46: 88008 | BF46: 0 | BG46: 0 | BH46: 128.871 | BI46: 23.197 | BJ46: 100518.14 | BK46: 18093.253 | BL46: 118611.4 | BM46: 152.067 | BN46: 709857 | BO46: 0 | BP46: 0 | BQ46: 0 | BR46: 0 | BS46: 0 | BT46: 0 | BU46: 0 | BV46: 0 | BW46: 0 | BX46: 0 | BY46: 0 | BZ46: 0 | CA46: 0 | CB46: 1308 | CC46: 2017.583 | CD46: 2723 | CE46: 121055 | CF46: 121055 | CG46: 121055 | CH46: 0 | CI46: 0 | CJ46: 0 | CK46: 0 | CL46: 0 | CM46: 0 | CN46: 0 | CO46: 0
B47: CIV03 | E47: Orange-Ivory C | F47: INBOUND | G47: 2025 | H47: May | X47: 2687750 | Y47: 41866942 | Z47: 0 | AA47: 2512016527 | AB47: 231158076 | AC47: 231472949 | AD47: 175918731 | AE47: 55239346 | AF47: 1900.938 | AG47: 342.023 | AH47: 1482716.4 | AI47: 266775.02 | AJ47: 1749491.5 | AK47: 2242.961 | AL47: 3158 | AM47: 0 | AN47: 0 | AO47: 0 | AP47: 0 | AQ47: 0 | AR47: 0 | AS47: 0 | AT47: 26.559 | AU47: 4.781 | AV47: 20715.636 | AW47: 3729.307 | AX47: 24444.943 | AY47: 31.34 | AZ47: 4287 | BA47: 5798.1 | BB47: 8116 | BC47: 347886 | BD47: 347886 | BE47: 347886 | BF47: 0 | BG47: 0 | BH47: 1601.693 | BI47: 288.305 | BJ47: 1249308 | BK47: 224875.51 | BL47: 1474183.5 | BM47: 1889.998 | BN47: 321123 | BO47: 0 | BP47: 0 | BQ47: 0 | BR47: 0 | BS47: 0 | BT47: 0 | BU47: 0 | BV47: 0 | BW47: 0 | BX47: 0 | BY47: 0 | BZ47: 0 | CA47: 0 | CB47: 12724 | CC47: 25353.233 | CD47: 31997 | CE47: 1521194 | CF47: 1521194 | CG47: 1521194 | CH47: 0 | CI47: 0 | CJ47: 0 | CK47: 0 | CL47: 0 | CM47: 0 | CN47: 0 | CO47: 0
B48: CMR02 | E48: Orange Cameroun | F48: INBOUND | G48: 2025 | H48: May | X48: 249109 | Y48: 4880654 | Z48: 0 | AA48: 292839239 | AB48: 6323 | AC48: 6765 | AD48: 4524 | AE48: 1799 | AF48: 0.055 | AG48: 0.01 | AH48: 43.239 | AI48: 7.617 | AJ48: 50.855 | AK48: 0.065 | AL48: 87 | AM48: 0 | AN48: 0 | AO48: 0 | AP48: 0 | AQ48: 0 | AR48: 0 | AS48: 0 | AT48: 0.732 | AU48: 0.132 | AV48: 570.697 | AW48: 102.739 | AX48: 673.436 | AY48: 0.863 | AZ48: 127 | BA48: 176.483 | BB48: 255 | BC48: 10589 | BD48: 10589 | BE48: 10589 | BF48: 0 | BG48: 0 | BH48: 60.729 | BI48: 10.931 | BJ48: 47368.298 | BK48: 8526.294 | BL48: 55894.592 | BM48: 71.66 | BN48: 95767 | BO48: 0 | BP48: 0 | BQ48: 0 | BR48: 0 | BS48: 0 | BT48: 0 | BU48: 0 | BV48: 0 | BW48: 0 | BX48: 0 | BY48: 0 | BZ48: 0 | CA48: 0 | CB48: 169 | CC48: 155 | CD48: 258 | CE48: 9300 | CF48: 9300 | CG48: 9300 | CH48: 0 | CI48: 0 | CJ48: 0 | CK48: 0 | CL48: 0 | CM48: 0 | CN48: 0 | CO48: 0
...

Sheet ROAMING OUT
D2: CALL ANALYSIS REPORT
D4: Client: BEN02
D6: Roaming Parnters: ALL
D7: Direction: TAP IN
D8: Record Type: ALL
D10: Currency: XOF
D11: Report Type: Monthly
D12: Month and Year From: May-2025
D13: Month and Year To: May-2025
I18: GPRS | X18: MOC | AZ18: MTC
I19: Others | X19: SMS | AL19: Voice | AZ19: SMS | BN19: Voice
A20: Client | B20: RP Code | E20: Roaming Partner Name | F20: Direction | G20: Year | H20: Month | I20: Total Calls | K20: Duration in min. | L20: Ceil Duration in Min. | M20: Duration in Sec. | N20: Chargeable Units | O20: Charged Units | P20: Data Volume Incoming (KB) | Q20: Data Volume Outgoing (KB) | R20: Charges (SDR) | S20: Tax (SDR) | T20: Charges (XOF) | U20: Tax (XOF) | V20: Total Amount(XOF) | W20: Total Amount(SDR) | X20: Total Calls | Y20: Duration in min. | Z20: Ceil Duration in Min. | AA20: Duration in Sec. | AB20: Chargeable Units | AC20: Charged Units | AD20: Data Volume Incoming (KB) | AE20: Data Volume Outgoing (KB) | AF20: Charges (SDR) | AG20: Tax (SDR) | AH20: Charges (XOF) | AI20: Tax (XOF) | AJ20: Total Amount(XOF) | AK20: Total Amount(SDR) | AL20: Total Calls | AM20: Duration in min. | AN20: Ceil Duration in Min. | AO20: Duration in Sec. | AP20: Chargeable Units | AQ20: Charged Units | AR20: Data Volume Incoming (KB) | AS20: Data Volume Outgoing (KB) | AT20: Charges (SDR) | AU20: Tax (SDR) | AV20: Charges (XOF) | AW20: Tax (XOF) | AX20: Total Amount(XOF) | AY20: Total Amount(SDR) | AZ20: Total Calls | BA20: Duration in min. | BB20: Ceil Duration in Min. | BC20: Duration in Sec. | BD20: Chargeable Units | BE20: Charged Units | BF20: Data Volume Incoming (KB) | BG20: Data Volume Outgoing (KB) | BH20: Charges (SDR) | BI20: Tax (SDR) | BJ20: Charges (XOF) | BK20: Tax (XOF) | BL20: Total Amount(XOF) | BM20: Total Amount(SDR) | BN20: Total Calls | BO20: Duration in min. | BP20: Ceil Duration in Min. | BQ20: Duration in Sec. | BR20: Chargeable Units | BS20: Charged Units | BT20: Data Volume Incoming (KB) | BU20: Data Volume Outgoing (KB) | BV20: Charges (SDR) | BW20: Tax (SDR) | BX20: Charges (XOF) | BY20: Tax (XOF) | BZ20: Total Amount(XOF) | CA20: Total Amount(SDR)
A21: BEN02 | B21: ALBVF | E21: Vodafone Albani | F21: OUTBOUND | G21: 2025 | H21: May | I21: 442 | K21: 1067.9 | L21: 0 | M21: 64074 | N21: 0 | O21: 1 | P21: 0 | Q21: 0 | R21: 0 | S21: 0 | T21: 0 | U21: 0 | V21: 0 | W21: 0
B22: ARETC | E22: Etisalat, Uae | F22: OUTBOUND | G22: 2025 | H22: May | I22: 52548 | K22: 1434520.4 | L22: 0 | M22: 86071223 | N22: 626173 | O22: 1893376 | P22: 368378 | Q22: 257795 | R22: 741.826 | S22: 0 | T22: 578618.58 | U22: 0 | V22: 578618.58 | W22: 741.826 | X22: 400 | Y22: 0 | Z22: 0 | AA22: 0 | AB22: 0 | AC22: 0 | AD22: 0 | AE22: 0 | AF22: 50.56 | AG22: 0 | AH22: 39436.396 | AI22: 0 | AJ22: 39436.396 | AK22: 50.56 | AL22: 17 | AM22: 40.75 | AN22: 49 | AO22: 2445 | AP22: 2445 | AQ22: 3043 | AR22: 0 | AS22: 0 | AT22: 78.878 | AU22: 0 | AV22: 61523.819 | AW22: 0 | AX22: 61523.819 | AY22: 78.878 | AZ22: 5213 | BA22: 0 | BB22: 0 | BC22: 0 | BD22: 0 | BE22: 0 | BF22: 0 | BG22: 0 | BH22: 0 | BI22: 0 | BJ22: 0 | BK22: 0 | BL22: 0 | BM22: 0 | BN22: 59 | BO22: 65.267 | BP22: 101 | BQ22: 3916 | BR22: 3916 | BS22: 6001 | BT22: 0 | BU22: 0 | BV22: 0 | BW22: 0 | BX22: 0 | BY22: 0 | BZ22: 0 | CA22: 0
B23: BELKO | E23: Telnet Group Bvba/Sprl | F23: OUTBOUND | G23: 2025 | H23: May | I23: 565 | K23: 11338.933 | L23: 0 | M23: 680336 | N23: 40214 | O23: 40543 | P23: 19348 | Q23: 20867 | R23: 0.166 | S23: 0 | T23: 129.245 | U23: 0 | V23: 129.245 | W23: 0.166 | BN23: 2 | BO23: 1.55 | BP23: 2 | BQ23: 93 | BR23: 93 | BS23: 120 | BT23: 0 | BU23: 0 | BV23: 0 | BW23: 0 | BX23: 0 | BY23: 0 | BZ23: 0 | CA23: 0
B24: BELMO | E24: Mobistar Gsm | F24: OUTBOUND | G24: 2025 | H24: May | I24: 313 | K24: 3236.217 | L24: 0 | M24: 194173 | N24: 11815 | O24: 11991 | P24: 5885 | Q24: 5930 | R24: 0.079 | S24: 0 | T24: 61.627 | U24: 0 | V24: 61.627 | W24: 0.079 | AZ24: 3 | BA24: 0 | BB24: 0 | BC24: 0 | BD24: 0 | BE24: 0 | BF24: 0 | BG24: 0 | BH24: 0 | BI24: 0 | BJ24: 0 | BK24: 0 | BL24: 0 | BM24: 0 | BN24: 1 | BO24: 0.467 | BP24: 1 | BQ24: 28 | BR24: 28 | BS24: 28 | BT24: 0 | BU24: 0 | BV24: 0 | BW24: 0 | BX24: 0 | BY24: 0 | BZ24: 0 | CA24: 0
B25: BFACT | E25: Orange (Airtel) - Bfaso | F25: OUTBOUND | G25: 2025 | H25: May | I25: 191576 | K25: 6090891.8 | L25: 0 | M25: 365453510 | N25: 172833 | O25: 174058 | P25: 107747 | Q25: 65086 | R25: 1.445 | S25: 0.258 | T25: 1126.917 | U25: 200.981 | V25: 1327.897 | W25: 1.702 | AL25: 35 | AM25: 25.333 | AN25: 52 | AO25: 1520 | AP25: 1520 | AQ25: 3120 | AR25: 0 | AS25: 0 | AT25: 0 | AU25: 0 | AV25: 0 | AW25: 0 | AX25: 0 | AY25: 0 | AZ25: 9 | BA25: 0 | BB25: 0 | BC25: 0 | BD25: 0 | BE25: 0 | BF25: 0 | BG25: 0 | BH25: 0 | BI25: 0 | BJ25: 0 | BK25: 0 | BL25: 0 | BM25: 0
B26: BFAON | E26: Telmob | F26: OUTBOUND | G26: 2025 | H26: May | AL26: 397 | AM26: 300.083 | AN26: 557 | AO26: 18005 | AP26: 18005 | AQ26: 14946 | AR26: 0 | AS26: 0 | AT26: 39.437 | AU26: 7.098 | AV26: 30760.545 | AW26: 5536.383 | AX26: 36296.928 | AY26: 46.535 | AZ26: 324 | BA26: 0 | BB26: 0 | BC26: 0 | BD26: 0 | BE26: 0 | BF26: 0 | BG26: 0 | BH26: 0 | BI26: 0 | BJ26: 0 | BK26: 0 | BL26: 0 | BM26: 0 | BN26: 5134 | BO26: 8279.567 | BP26: 11083 | BQ26: 496774 | BR26: 496774 | BS26: 0 | BT26: 0 | BU26: 0 | BV26: 0 | BW26: 0 | BX26: 0 | BY26: 0 | BZ26: 0 | CA26: 0
B27: BFATL | E27: Telecel - Bfaso | F27: OUTBOUND | G27: 2025 | H27: May | AL27: 24 | AM27: 6.4 | AN27: 26 | AO27: 384 | AP27: 384 | AQ27: 186 | AR27: 0 | AS27: 0 | AT27: 1.04 | AU27: 0.188 | AV27: 811.192 | AW27: 146.638 | AX27: 957.83 | AY27: 1.228 | AZ27: 435 | BA27: 0 | BB27: 0 | BC27: 0 | BD27: 0 | BE27: 0 | BF27: 0 | BG27: 0 | BH27: 0 | BI27: 0 | BJ27: 0 | BK27: 0 | BL27: 0 | BM27: 0 | BN27: 1 | BO27: 0.333 | BP27: 1 | BQ27: 20 | BR27: 20 | BS27: 0 | BT27: 0 | BU27: 0 | BV27: 0 | BW27: 0 | BX27: 0 | BY27: 0 | BZ27: 0 | CA27: 0
B28: CAFAT | E28: Acell-Rca | F28: OUTBOUND | G28: 2025 | H28: May | AL28: 2 | AM28: 2.683 | AN28: 4 | AO28: 161 | AP28: 161 | AQ28: 161 | AR28: 0 | AS28: 0 | AT28: 0.79 | AU28: 0.15 | AV28: 616.067 | AW28: 117.053 | AX28: 733.119 | AY28: 0.94 | AZ28: 688 | BA28: 0 | BB28: 0 | BC28: 0 | BD28: 0 | BE28: 0 | BF28: 0 | BG28: 0 | BH28: 0 | BI28: 0 | BJ28: 0 | BK28: 0 | BL28: 0 | BM28: 0 | BN28: 1 | BO28: 0.2 | BP28: 1 | BQ28: 12 | BR28: 12 | BS28: 12 | BT28: 0 | BU28: 0 | BV28: 0 | BW28: 0 | BX28: 0 | BY28: 0 | BZ28: 0 | CA28: 0
B29: CAFFT | E29: Orange-Hub | F29: OUTBOUND | G29: 2025 | H29: May | AL29: 19 | AM29: 21.2 | AN29: 32 | AO29: 1272 | AP29: 1272 | AQ29: 1272 | AR29: 0 | AS29: 0 | AT29: 5.349 | AU29: 1.016 | AV29: 4171.889 | AW29: 792.667 | AX29: 4964.555 | AY29: 6.365 | AZ29: 798 | BA29: 0 | BB29: 0 | BC29: 0 | BD29: 0 | BE29: 0 | BF29: 0 | BG29: 0 | BH29: 0 | BI29: 0 | BJ29: 0 | BK29: 0 | BL29: 0 | BM29: 0 | BN29: 13 | BO29: 7.817 | BP29: 16 | BQ29: 469 | BR29: 469 | BS29: 469 | BT29: 0 | BU29: 0 | BV29: 0 | BW29: 0 | BX29: 0 | BY29: 0 | BZ29: 0 | CA29: 0
B30: CANBM | E30: Bell Mobility | F30: OUTBOUND | G30: 2025 | H30: May | I30: 2858 | K30: 95445.067 | L30: 0 | M30: 5726704 | N30: 117589 | O30: 118985 | P30: 24187 | Q30: 93403 | R30: 1.456 | S30: 0 | T30: 1135.519 | U30: 0 | V30: 1135.519 | W30: 1.456 | AL30: 71 | AM30: 115.95 | AN30: 149 | AO30: 6957 | AP30: 6957 | AQ30: 6957 | AR30: 0 | AS30: 0 | AT30: 9.747 | AU30: 1.459 | AV30: 7602.548 | AW30: 1138.247 | AX30: 8740.795 | AY30: 11.206 | BN30: 23 | BO30: 29.117 | BP30: 40 | BQ30: 1747 | BR30: 1747 | BS30: 1747 | BT30: 0 | BU30: 0 | BV30: 0 | BW30: 0 | BX30: 0 | BY30: 0 | BZ30: 0 | CA30: 0
B31: CANRW | E31: Rogers - Canada | F31: OUTBOUND | G31: 2025 | H31: May | I31: 1943 | K31: 185859.1 | L31: 0 | M31: 11151546 | N31: 181551 | O31: 182592 | P31: 19675 | Q31: 161876 | R31: 1.316 | S31: 0 | T31: 1026.415 | U31: 0 | V31: 1026.415 | W31: 1.316 | AL31: 93 | AM31: 219.717 | AN31: 267 | AO31: 13183 | AP31: 13183 | AQ31: 16020 | AR31: 0 | AS31: 0 | AT31: 62.696 | AU31: 0.114 | AV31: 48902.534 | AW31: 88.732 | AX31: 48991.266 | AY31: 62.81 | AZ31: 7539 | BA31: 0 | BB31: 0 | BC31: 0 | BD31: 0 | BE31: 0 | BF31: 0 | BG31: 0 | BH31: 0 | BI31: 0 | BJ31: 0 | BK31: 0 | BL31: 0 | BM31: 0 | BN31: 31 | BO31: 49.467 | BP31: 65 | BQ31: 2968 | BR31: 2968 | BS31: 3900 | BT31: 0 | BU31: 0 | BV31: 0.144 | BW31: 0 | BX31: 112.046 | BY31: 0 | BZ31: 112.046 | CA31: 0.144
B32: CANTS | E32: Telus | F32: OUTBOUND | G32: 2025 | H32: May | I32: 2084 | K32: 6088.25 | L32: 0 | M32: 365295 | N32: 19094 | O32: 20176 | P32: 5838 | Q32: 13256 | R32: 0.226 | S32: 0 | T32: 176.185 | U32: 0 | V32: 176.185 | W32: 0.226
B33: CHEDX | E33: Sunrise Communications Ag | F33: OUTBOUND | G33: 2025 | H33: May | I33: 12575 | K33: 742123.42 | L33: 0 | M33: 44527405 | N33: 41431 | O33: 41708 | P33: 8480 | Q33: 32950 | R33: 0.179 | S33: 0 | T33: 139.307 | U33: 0 | V33: 139.307 | W33: 0.179 | AL33: 53 | AM33: 84.533 | AN33: 113 | AO33: 5072 | AP33: 5072 | AQ33: 5072 | AR33: 0 | AS33: 0 | AT33: 22.637 | AU33: 0 | AV33: 17656.913 | AW33: 0 | AX33: 17656.913 | AY33: 22.637 | BN33: 22 | BO33: 23.467 | BP33: 35 | BQ33: 1408 | BR33: 1408 | BS33: 1408 | BT33: 0 | BU33: 0 | BV33: 0 | BW33: 0 | BX33: 0 | BY33: 0 | BZ33: 0 | CA33: 0
B34: CHNCU | E34: China Unicom | F34: OUTBOUND | G34: 2025 | H34: May | AL34: 34 | AM34: 57.367 | AN34: 77 | AO34: 3442 | AP34: 3442 | AQ34: 0 | AR34: 0 | AS34: 0 | AT34: 11.254 | AU34: 0 | AV34: 8777.875 | AW34: 0 | AX34: 8777.875 | AY34: 11.254 | BN34: 59 | BO34: 80.483 | BP34: 115 | BQ34: 4829 | BR34: 4829 | BS34: 0 | BT34: 0 | BU34: 0 | BV34: 0.088 | BW34: 0 | BX34: 68.682 | BY34: 0 | BZ34: 68.682 | CA34: 0.088
B35: CIV02 | E35: Moov(A-Cell) | F35: OUTBOUND | G35: 2025 | H35: May | I35: 856482 | K35: 24354752 | L35: 0 | M35: 1461285099 | N35: 13721464 | O35: 13747162 | P35: 11108396 | Q35: 2613068 | R35: 67.816 | S35: 0 | T35: 52896.286 | U35: 0 | V35: 52896.286 | W35: 67.816 | AL35: 1304 | AM35: 1490.567 | AN35: 2195 | AO35: 89434 | AP35: 89434 | AQ35: 89489 | AR35: 0 | AS35: 0 | AT35: 206.17 | AU35: 0 | AV35: 160810.62 | AW35: 0 | AX35: 160810.62 | AY35: 206.17 | AZ35: 102178 | BA35: 0 | BB35: 0 | BC35: 0 | BD35: 0 | BE35: 0 | BF35: 0 | BG35: 0 | BH35: 0 | BI35: 0 | BJ35: 0 | BK35: 0 | BL35: 0 | BM35: 0 | BN35: 14811 | BO35: 27184.867 | BP35: 35169 | BQ35: 1631092 | BR35: 1631092 | BS35: 1631092 | BT35: 0 | BU35: 0 | BV35: 0 | BW35: 0 | BX35: 0 | BY35: 0 | BZ35: 0 | CA35: 0
B36: CIV03 | E36: Orange-Ivory C | F36: OUTBOUND | G36: 2025 | H36: May | I36: 21618 | K36: 526098.17 | L36: 0 | M36: 31565890 | N36: 180400 | O36: 180988 | P36: 112801 | Q36: 67599 | R36: 1.5 | S36: 0.271 | T36: 1170.136 | U36: 211.035 | V36: 1381.171 | W36: 1.771 | AL36: 18 | AM36: 1.8 | AN36: 19 | AO36: 108 | AP36: 108 | AQ36: 1111 | AR36: 0 | AS36: 0 | AT36: 0.386 | AU36: 0.07 | AV36: 301.256 | AW36: 54.225 | AX36: 355.481 | AY36: 0.456 | AZ36: 339 | BA36: 0 | BB36: 0 | BC36: 0 | BD36: 0 | BE36: 0 | BF36: 0 | BG36: 0 | BH36: 0 | BI36: 0 | BJ36: 0 | BK36: 0 | BL36: 0 | BM36: 0 | BN36: 49 | BO36: 113.217 | BP36: 140 | BQ36: 6793 | BR36: 6793 | BS36: 6793 | BT36: 0 | BU36: 0 | BV36: 0 | BW36: 0 | BX36: 0 | BY36: 0 | BZ36: 0 | CA36: 0
B37: CIVTL | E37: Loteny Telecom | F37: OUTBOUND | G37: 2025 | H37: May | I37: 33823 | K37: 493113.18 | L37: 0 | M37: 29586791 | N37: 9080720 | O37: 9097276 | P37: 4284509 | Q37: 4796211 | R37: 37.354 | S37: 0 | T37: 29135.586 | U37: 0 | V37: 29135.586 | W37: 37.354 | AL37: 1627 | AM37: 1762.75 | AN37: 2675 | AO37: 105765 | AP37: 105765 | AQ37: 105940 | AR37: 0 | AS37: 0 | AT37: 480.957 | AU37: 0 | AV37: 375142.25 | AW37: 0 | AX37: 375142.25 | AY37: 480.957 | BN37: 16824 | BO37: 29017 | BP37: 38235 | BQ37: 1741020 | BR37: 1741020 | BS37: 2294100 | BT37: 0 | BU37: 0 | BV37: 0 | BW37: 0 | BX37: 0 | BY37: 0 | BZ37: 0 | CA37: 0
B38: CMR02 | E38: Orange Cameroun | F38: OUTBOUND | G38: 2025 | H38: May | I38: 70000 | K38: 2287541.8 | L38: 0 | M38: 137252510 | N38: 142638 | O38: 145792 | P38: 25379 | Q38: 117259 | R38: 1.201 | S38: 0 | T38: 937.067 | U38: 0 | V38: 937.067 | W38: 1.201 | X38: 11 | Y38: 0 | Z38: 0 | AA38: 0 | AB38: 0 | AC38: 0 | AD38: 0 | AE38: 0 | AF38: 0.093 | AG38: 0 | AH38: 72.157 | AI38: 0 | AJ38: 72.157 | AK38: 0.093 | AL38: 52 | AM38: 48.383 | AN38: 80 | AO38: 2903 | AP38: 2903 | AQ38: 2903 | AR38: 0 | AS38: 0 | AT38: 15.613 | AU38: 0 | AV38: 12177.836 | AW38: 0 | AX38: 12177.836 | AY38: 15.613 | AZ38: 5680 | BA38: 0 | BB38: 0 | BC38: 0 | BD38: 0 | BE38: 0 | BF38: 0 | BG38: 0 | BH38: 0 | BI38: 0 | BJ38: 0 | BK38: 0 | BL38: 0 | BM38: 0 | BN38: 65 | BO38: 43.917 | BP38: 84 | BQ38: 2635 | BR38: 2635 | BS38: 2635 | BT38: 0 | BU38: 0 | BV38: 0 | BW38: 0 | BX38: 0 | BY38: 0 | BZ38: 0 | CA38: 0
B39: CMRMT | E39: Mtn - Cameroon | F39: OUTBOUND | G39: 2025 | H39: May | I39: 1575 | K39: 40781.567 | L39: 0 | M39: 2446894 | N39: 256408 | O39: 256830 | P39: 11041 | Q39: 245368 | R39: 1.055 | S39: 0 | T39: 822.596 | U39: 0 | V39: 822.596 | W39: 1.055 | AL39: 32 | AM39: 32.2 | AN39: 49 | AO39: 1932 | AP39: 1932 | AQ39: 1995 | AR39: 0 | AS39: 0 | AT39: 8.312 | AU39: 0 | AV39: 6483.602 | AW39: 0 | AX39: 6483.602 | AY39: 8.312 | BN39: 47 | BO39: 38.05 | BP39: 70 | BQ39: 2283 | BR39: 2283 | BS39: 4200 | BT39: 0 | BU39: 0 | BV39: 0 | BW39: 0 | BX39: 0 | BY39: 0 | BZ39: 0 | CA39: 0
B40: CODAC | E40: Africell Rdc Sa. | F40: OUTBOUND | G40: 2025 | H40: May | AZ40: 6 | BA40: 0 | BB40: 0 | BC40: 0 | BD40: 0 | BE40: 0 | BF40: 0 | BG40: 0 | BH40: 0 | BI40: 0 | BJ40: 0 | BK40: 0 | BL40: 0 | BM40: 0
B41: CODFT | E41: Congo China | F41: OUTBOUND | G41: 2025 | H41: May | I41: 14071 | K41: 132921.55 | L41: 0 | M41: 7975293 | N41: 4317 | O41: 4393 | P41: 2563 | Q41: 1754 | R41: 0.032 | S41: 0.008 | T41: 24.773 | U41: 6.248 | V41: 31.02 | W41: 0.04 | AL41: 6 | AM41: 9.867 | AN41: 12 | AO41: 592 | AP41: 592 | AQ41: 592 | AR41: 0 | AS41: 0 | AT41: 2.594 | AU41: 0.674 | AV41: 2023.237 | AW41: 526.042 | AX41: 2549.279 | AY41: 3.268 | AZ41: 4 | BA41: 0 | BB41: 0 | BC41: 0 | BD41: 0 | BE41: 0 | BF41: 0 | BG41: 0 | BH41: 0 | BI41: 0 | BJ41: 0 | BK41: 0 | BL41: 0 | BM41: 0 | BN41: 5 | BO41: 3.583 | BP41: 7 | BQ41: 215 | BR41: 215 | BS41: 215 | BT41: 0 | BU41: 0 | BV41: 0 | BW41: 0 | BX41: 0 | BY41: 0 | BZ41: 0 | CA41: 0
B42: CODVC | E42: Vodacom - Congo | F42: OUTBOUND | G42: 2025 | H42: May | I42: 61693 | K42: 890943.52 | L42: 0 | M42: 53456611 | N42: 65711 | O42: 67162 | P42: 28874 | Q42: 36838 | R42: 0.411 | S42: 0.107 | T42: 320.239 | U42: 83.489 | V42: 403.728 | W42: 0.518
B43: COGCT | E43: Airtel - Congo | F43: OUTBOUND | G43: 2025 | H43: May | I43: 2893 | K43: 120465.45 | L43: 0 | M43: 7227927 | N43: 565248 | O43: 567397 | P43: 277770 | Q43: 287479 | R43: 6.27 | S43: 0 | T43: 4890.719 | U43: 0 | V43: 4890.719 | W43: 6.27 | AL43: 43 | AM43: 42.55 | AN43: 66 | AO43: 2553 | AP43: 2553 | AQ43: 2553 | AR43: 0 | AS43: 0 | AT43: 7.133 | AU43: 0 | AV43: 5563.548 | AW43: 0 | AX43: 5563.548 | AY43: 7.133 | BN43: 51 | BO43: 38.133 | BP43: 72 | BQ43: 2288 | BR43: 2288 | BS43: 2288 | BT43: 0 | BU43: 0 | BV43: 0 | BW43: 0 | BX43: 0 | BY43: 0 | BZ43: 0 | CA43: 0
B44: CPVTM | E44: T Telecomunic | F44: OUTBOUND | G44: 2025 | H44: May | AZ44: 31 | BA44: 0 | BB44: 0 | BC44: 0 | BD44: 0 | BE44: 0 | BF44: 0 | BG44: 0 | BH44: 0 | BI44: 0 | BJ44: 0 | BK44: 0 | BL44: 0 | BM44: 0
B45: CZECM | E45: Vodafone , Czech Republic | F45: OUTBOUND | G45: 2025 | H45: May | AZ45: 2 | BA45: 0 | BB45: 0 | BC45: 0 | BD45: 0 | BE45: 0 | BF45: 0 | BG45: 0 | BH45: 0 | BI45: 0 | BJ45: 0 | BK45: 0 | BL45: 0 | BM45: 0
B46: DEUD1 | E46: T-Mobile,German | F46: OUTBOUND | G46: 2025 | H46: May | I46: 13 | K46: 978.817 | L46: 0 | M46: 58729 | N46: 365 | O46: 371 | P46: 271 | Q46: 94 | R46: 0.002 | S46: 0 | T46: 1.895 | U46: 0 | V46: 1.895 | W46: 0.002 | AL46: 1 | AM46: 0.083 | AN46: 1 | AO46: 5 | AP46: 5 | AQ46: 5 | AR46: 0 | AS46: 0 | AT46: 0.035 | AU46: 0 | AV46: 27.331 | AW46: 0 | AX46: 27.331 | AY46: 0.035 | BN46: 1 | BO46: 1.15 | BP46: 2 | BQ46: 69 | BR46: 69 | BS46: 69 | BT46: 0 | BU46: 0 | BV46: 0 | BW46: 0 | BX46: 0 | BY46: 0 | BZ46: 0 | CA46: 0
B47: DEUD2 | E47: Vodafone German | F47: OUTBOUND | G47: 2025 | H47: May | I47: 287 | K47: 39390.9 | L47: 0 | M47: 2363454 | N47: 21932 | O47: 22101 | P47: 4958 | Q47: 16975 | R47: 0.145 | S47: 0 | T47: 113.304 | U47: 0 | V47: 113.304 | W47: 0.145 | AL47: 13 | AM47: 10.1 | AN47: 17 | AO47: 606 | AP47: 606 | AQ47: 606 | AR47: 0 | AS47: 0 | AT47: 2.489 | AU47: 0 | AV47: 1941.635 | AW47: 0 | AX47: 1941.635 | AY47: 2.489 | BN47: 30 | BO47: 29.917 | BP47: 47 | BQ47: 1795 | BR47: 1795 | BS47: 1795 | BT47: 0 | BU47: 0 | BV47: 0 | BW47: 0 | BX47: 0 | BY47: 0 | BZ47: 0 | CA47: 0
B48: DEUE2 | E48: O2 (Germany) Gm | F48: OUTBOUND | G48: 2025 | H48: May | AL48: 5 | AM48: 9.4 | AN48: 12 | AO48: 564 | AP48: 564 | AQ48: 720 | AR48: 0 | AS48: 0 | AT48: 19.242 | AU48: 0 | AV48: 15008.298 | AW48: 0 | AX48: 15008.298 | AY48: 19.242 | BN48: 4 | BO48: 0.4 | BP48: 4 | BQ48: 24 | BR48: 24 | BS48: 240 | BT48: 0 | BU48: 0 | BV48: 0 | BW48: 0 | BX48: 0 | BY48: 0 | BZ48: 0 | CA48: 0
...

Sheet MTC
D2: CALL ANALYSIS REPORT
D4: Client: BEN02
D6: Roaming Parnters: BFAON;CIV02;TGOTC;TGOTL;MLI01;SENSG
D7: Direction: Both
D8: Record Type: Voice
D10: Currency: XOF
D11: Report Type: Monthly
D12: Month and Year From: May-2025
D13: Month and Year To: May-2025
I18: MOC | X18: MTC
I19: Voice | X19: Voice
A20: Client | B20: RP Code | E20: Roaming Partner Name | F20: Direction | G20: Year | H20: Month | I20: Total Calls | K20: Duration in min. | L20: Ceil Duration in Min. | M20: Duration in Sec. | N20: Chargeable Units | O20: Charged Units | P20: Data Volume Incoming (KB) | Q20: Data Volume Outgoing (KB) | R20: Charges (SDR) | S20: Tax (SDR) | T20: Charges (XOF) | U20: Tax (XOF) | V20: Total Amount(XOF) | W20: Total Amount(SDR) | X20: Total Calls | Y20: Duration in min. | Z20: Ceil Duration in Min. | AA20: Duration in Sec. | AB20: Chargeable Units | AC20: Charged Units | AD20: Data Volume Incoming (KB) | AE20: Data Volume Outgoing (KB) | AF20: Charges (SDR) | AG20: Tax (SDR) | AH20: Charges (XOF) | AI20: Tax (XOF) | AJ20: Total Amount(XOF) | AK20: Total Amount(SDR)
A21: BEN02 | B21: BFAON | E21: Telmob | F21: INBOUND | G21: 2025 | H21: May | I21: 287 | K21: 269.733 | L21: 445 | M21: 16184 | N21: 16184 | O21: 16184 | P21: 0 | Q21: 0 | R21: 30.565 | S21: 5.502 | T21: 23840.537 | U21: 4291.301 | V21: 28131.837 | W21: 36.067 | X21: 503 | Y21: 436.65 | Z21: 728 | AA21: 26199 | AB21: 26199 | AC21: 26199 | AD21: 0 | AE21: 0 | AF21: 0 | AG21: 0 | AH21: 0 | AI21: 0 | AJ21: 0 | AK21: 0
F22: OUTBOUND | G22: 2025 | H22: May | I22: 397 | K22: 300.083 | L22: 557 | M22: 18005 | N22: 18005 | O22: 14946 | P22: 0 | Q22: 0 | R22: 39.437 | S22: 7.098 | T22: 30760.545 | U22: 5536.383 | V22: 36296.928 | W22: 46.535 | X22: 5134 | Y22: 8279.567 | Z22: 11083 | AA22: 496774 | AB22: 496774 | AC22: 0 | AD22: 0 | AE22: 0 | AF22: 0 | AG22: 0 | AH22: 0 | AI22: 0 | AJ22: 0 | AK22: 0
E23: Telmob Total | I23: 684 | K23: 569.816 | L23: 1002 | M23: 34189 | N23: 34189 | O23: 31130 | P23: 0 | Q23: 0 | R23: 70.002 | S23: 12.6 | T23: 54601.082 | U23: 9827.684 | V23: 64428.765 | W23: 82.602 | X23: 5637 | Y23: 8716.217 | Z23: 11811 | AA23: 522973 | AB23: 522973 | AC23: 26199 | AD23: 0 | AE23: 0 | AF23: 0 | AG23: 0 | AH23: 0 | AI23: 0 | AJ23: 0 | AK23: 0
B24: CIV02 | E24: Moov(A-Cell) | F24: INBOUND | G24: 2025 | H24: May | I24: 1123 | K24: 1466.8 | L24: 2016 | M24: 88008 | N24: 88008 | O24: 88008 | P24: 0 | Q24: 0 | R24: 128.871 | S24: 23.197 | T24: 100518.14 | U24: 18093.253 | V24: 118611.4 | W24: 152.067 | X24: 1308 | Y24: 2017.583 | Z24: 2723 | AA24: 121055 | AB24: 121055 | AC24: 121055 | AD24: 0 | AE24: 0 | AF24: 0 | AG24: 0 | AH24: 0 | AI24: 0 | AJ24: 0 | AK24: 0
F25: OUTBOUND | G25: 2025 | H25: May | I25: 1304 | K25: 1490.567 | L25: 2195 | M25: 89434 | N25: 89434 | O25: 89489 | P25: 0 | Q25: 0 | R25: 206.17 | S25: 0 | T25: 160810.62 | U25: 0 | V25: 160810.62 | W25: 206.17 | X25: 14811 | Y25: 27184.867 | Z25: 35169 | AA25: 1631092 | AB25: 1631092 | AC25: 1631092 | AD25: 0 | AE25: 0 | AF25: 0 | AG25: 0 | AH25: 0 | AI25: 0 | AJ25: 0 | AK25: 0
E26: Moov(A-Cell) Total | I26: 2427 | K26: 2957.367 | L26: 4211 | M26: 177442 | N26: 177442 | O26: 177497 | P26: 0 | Q26: 0 | R26: 335.041 | S26: 23.197 | T26: 261328.77 | U26: 18093.253 | V26: 279422.02 | W26: 358.237 | X26: 16119 | Y26: 29202.45 | Z26: 37892 | AA26: 1752147 | AB26: 1752147 | AC26: 1752147 | AD26: 0 | AE26: 0 | AF26: 0 | AG26: 0 | AH26: 0 | AI26: 0 | AJ26: 0 | AK26: 0
B27: MLI01 | E27: Malitel Gsm-900 | F27: INBOUND | G27: 2025 | H27: May | I27: 936 | K27: 654.133 | L27: 1333 | M27: 39248 | N27: 39248 | O27: 39248 | P27: 0 | Q27: 0 | R27: 57.306 | S27: 10.315 | T27: 44698.271 | U27: 8045.7 | V27: 52743.971 | W27: 67.621 | X27: 660 | Y27: 631.55 | Z27: 1041 | AA27: 37893 | AB27: 37893 | AC27: 37893 | AD27: 0 | AE27: 0 | AF27: 0 | AG27: 0 | AH27: 0 | AI27: 0 | AJ27: 0 | AK27: 0
F28: OUTBOUND | G28: 2025 | H28: May | I28: 1242 | K28: 735.717 | L28: 1566 | M28: 44143 | N28: 44143 | O28: 44143 | P28: 0 | Q28: 0 | R28: 0.143 | S28: 0.026 | T28: 111.749 | U28: 20.109 | V28: 131.858 | W28: 0.169 | X28: 6260 | Y28: 11039.333 | Z28: 14454 | AA28: 662360 | AB28: 662360 | AC28: 797680 | AD28: 0 | AE28: 0 | AF28: 0 | AG28: 0 | AH28: 0 | AI28: 0 | AJ28: 0 | AK28: 0
E29: Malitel Gsm-900 Total | I29: 2178 | K29: 1389.85 | L29: 2899 | M29: 83391 | N29: 83391 | O29: 83391 | P29: 0 | Q29: 0 | R29: 57.449 | S29: 10.341 | T29: 44810.02 | U29: 8065.809 | V29: 52875.829 | W29: 67.79 | X29: 6920 | Y29: 11670.883 | Z29: 15495 | AA29: 700253 | AB29: 700253 | AC29: 835573 | AD29: 0 | AE29: 0 | AF29: 0 | AG29: 0 | AH29: 0 | AI29: 0 | AJ29: 0 | AK29: 0
B30: SENSG | E30: Yas Senegal | F30: INBOUND | G30: 2025 | H30: May | I30: 34 | K30: 72.3 | L30: 89 | M30: 4338 | N30: 4338 | O30: 4338 | P30: 0 | Q30: 0 | R30: 9.356 | S30: 1.684 | T30: 7297.983 | U30: 1313.639 | V30: 8611.623 | W30: 11.041 | X30: 28 | Y30: 33.683 | Z30: 48 | AA30: 2021 | AB30: 2021 | AC30: 2021 | AD30: 0 | AE30: 0 | AF30: 0 | AG30: 0 | AH30: 0 | AI30: 0 | AJ30: 0 | AK30: 0
F31: OUTBOUND | G31: 2025 | H31: May | I31: 137 | K31: 209.7 | L31: 283 | M31: 12582 | N31: 12582 | O31: 12582 | P31: 0 | Q31: 0 | R31: 52.381 | S31: 0 | T31: 40856.597 | U31: 0 | V31: 40856.597 | W31: 52.381 | X31: 579 | Y31: 1065.433 | Z31: 1376 | AA31: 63926 | AB31: 63926 | AC31: 82560 | AD31: 0 | AE31: 0 | AF31: 0 | AG31: 0 | AH31: 0 | AI31: 0 | AJ31: 0 | AK31: 0
E32: Yas Senegal Total | I32: 171 | K32: 282 | L32: 372 | M32: 16920 | N32: 16920 | O32: 16920 | P32: 0 | Q32: 0 | R32: 61.737 | S32: 1.684 | T32: 48154.58 | U32: 1313.639 | V32: 49468.22 | W32: 63.422 | X32: 607 | Y32: 1099.116 | Z32: 1424 | AA32: 65947 | AB32: 65947 | AC32: 84581 | AD32: 0 | AE32: 0 | AF32: 0 | AG32: 0 | AH32: 0 | AI32: 0 | AJ32: 0 | AK32: 0
B33: TGOTC | E33: Togo Cellulaire | F33: INBOUND | G33: 2025 | H33: May | I33: 671 | K33: 740.217 | L33: 1054 | M33: 44413 | N33: 44413 | O33: 44413 | P33: 0 | Q33: 0 | R33: 46.843 | S33: 8.432 | T33: 36537.497 | U33: 6576.737 | V33: 43114.233 | W33: 55.275 | X33: 14607 | Y33: 28076.083 | Z33: 35346 | AA33: 1684565 | AB33: 1684565 | AC33: 1684565 | AD33: 0 | AE33: 0 | AF33: 0 | AG33: 0 | AH33: 0 | AI33: 0 | AJ33: 0 | AK33: 0
F34: OUTBOUND | G34: 2025 | H34: May | I34: 19136 | K34: 16608.217 | L34: 28091 | M34: 996493 | N34: 996493 | O34: 996493 | P34: 0 | Q34: 0 | R34: 995.286 | S34: 179.152 | T34: 776315.46 | U34: 139737.25 | V34: 916052.71 | W34: 1174.439 | X34: 17338 | Y34: 28564.4 | Z34: 37756 | AA34: 1713864 | AB34: 1713864 | AC34: 1713864 | AD34: 0 | AE34: 0 | AF34: 0 | AG34: 0 | AH34: 0 | AI34: 0 | AJ34: 0 | AK34: 0
E35: Togo Cellulaire Total | I35: 19807 | K35: 17348.434 | L35: 29145 | M35: 1040906 | N35: 1040906 | O35: 1040906 | P35: 0 | Q35: 0 | R35: 1042.129 | S35: 187.584 | T35: 812852.96 | U35: 146313.99 | V35: 959166.94 | W35: 1229.714 | X35: 31945 | Y35: 56640.483 | Z35: 73102 | AA35: 3398429 | AB35: 3398429 | AC35: 3398429 | AD35: 0 | AE35: 0 | AF35: 0 | AG35: 0 | AH35: 0 | AI35: 0 | AJ35: 0 | AK35: 0
B36: TGOTL | E36: Moov Africa Togo | F36: INBOUND | G36: 2025 | H36: May | I36: 15118 | K36: 15519.283 | L36: 23031 | M36: 931157 | N36: 931157 | O36: 931157 | P36: 0 | Q36: 0 | R36: 1010.132 | S36: 181.824 | T36: 787895.23 | U36: 141821.36 | V36: 929716.58 | W36: 1191.957 | X36: 201518 | Y36: 494636 | Z36: 591157 | AA36: 29678160 | AB36: 29678160 | AC36: 29678160 | AD36: 0 | AE36: 0 | AF36: 0 | AG36: 0 | AH36: 0 | AI36: 0 | AJ36: 0 | AK36: 0
F37: OUTBOUND | G37: 2025 | H37: May | I37: 30846 | K37: 28229.3 | L37: 46610 | M37: 1693758 | N37: 1693758 | O37: 1693758 | P37: 0 | Q37: 0 | R37: 1670.7 | S37: 300.727 | T37: 1303132.5 | U37: 234564.57 | V37: 1537697.1 | W37: 1971.427 | X37: 257034 | Y37: 424215.27 | Z37: 559617 | AA37: 25452916 | AB37: 25452916 | AC37: 25452916 | AD37: 0 | AE37: 0 | AF37: 0 | AG37: 0 | AH37: 0 | AI37: 0 | AJ37: 0 | AK37: 0
