Workbook

Sheet 632200 01 25
A1: Date | B1: NumÃ©ro de piÃ¨ce | C1: Site | D1: Type | E1: Journal | F1: LibellÃ© ligne | G1: DÃ©bit rÃ©fÃ©rentiel | H1: CrÃ©dit rÃ©fÃ©rentiel | I1: SOLDE | J1: MAP | K1: RÃ©fÃ©rence | L1: Contrepartie | M1: Taxe | N1: Coll | O1: Transaction | P1: Module | Q1: CatÃ©gorie | R1: Etat | S1: NumÃ©ro chrono | T1: Marquage
A2: 45658 | B2: SIEGE1901EXTOU000131 | C2: SIEGE | D2: EXT | E2: EXT | F2: PROV RSIT ANNUEL D_COM DEC 24 | G2: -16315807 | H2: 0 | I2: -16315807 | J2: AUTRES | K2: EXT12046 | L2: ="408106" -> 408106 | M2: ="001" -> 001 | O2: STDCO | P2: 2 | Q2: 1 | R2: 1
A3: 45658 | B3: SIEGE1901EXTOU000131 | C3: SIEGE | D3: EXT | E3: EXT | F3: PROV RSIT ANNUEL SOMAC DEC 24 | G3: -51413053 | H3: 0 | I3: -51413053 | J3: AUTRES | K3: EXT12046 | L3: ="408106" -> 408106 | M3: ="001" -> 001 | O3: STDCO | P3: 2 | Q3: 1 | R3: 1
A4: 45658 | B4: SIEGE1901EXTOU000131 | C4: SIEGE | D4: EXT | E4: EXT | F4: PROV RSIT ANNUEL EASYCOM DEC 24 | G4: -56972031 | H4: 0 | I4: -56972031 | J4: AUTRES | K4: EXT12046 | L4: ="408106" -> 408106 | M4: ="001" -> 001 | O4: STDCO | P4: 2 | Q4: 1 | R4: 1
A5: 45658 | B5: SIEGE1901EXTOU000131 | C5: SIEGE | D5: EXT | E5: EXT | F5: PROV RSIT ANNUEL LINARCEL DEC 24 | G5: -124565840 | H5: 0 | I5: -124565840 | J5: AUTRES | K5: EXT12046 | L5: ="408106" -> 408106 | M5: ="001" -> 001 | O5: STDCO | P5: 2 | Q5: 1 | R5: 1
A6: 45658 | B6: SIEGE1901EXTOU000131 | C6: SIEGE | D6: EXT | E6: EXT | F6: PROV RSIT ANNUEL PRODICOM DEC 24 | G6: -101782088 | H6: 0 | I6: -101782088 | J6: AUTRES | K6: EXT12046 | L6: ="408106" -> 408106 | M6: ="001" -> 001 | O6: STDCO | P6: 2 | Q6: 1 | R6: 1
A7: 45658 | B7: SIEGE1901EXTOU000131 | C7: SIEGE | D7: EXT | E7: EXT | F7: PROV RSIT ANNUEL AFTELT DEC 24 | G7: -1421096 | H7: 0 | I7: -1421096 | J7: AUTRES | K7: EXT12046 | L7: ="408106" -> 408106 | M7: ="001" -> 001 | O7: STDCO | P7: 2 | Q7: 1 | R7: 1
A8: 45658 | B8: SIEGE1901EXTOU000131 | C8: SIEGE | D8: EXT | E8: EXT | F8: PROV RIST TRIMESTR EASY COM DEC 24 | G8: -4254264 | H8: 0 | I8: -4254264 | J8: AUTRES | K8: EXT12046 | L8: ="408106" -> 408106 | M8: ="001" -> 001 | O8: STDCO | P8: 2 | Q8: 1 | R8: 1
A9: 45658 | B9: SIEGE1901EXTOU000131 | C9: SIEGE | D9: EXT | E9: EXT | F9: PROV RIST TRIMESTR LINARCEL DEC 24 | G9: -7787501 | H9: 0 | I9: -7787501 | J9: AUTRES | K9: EXT12046 | L9: ="408106" -> 408106 | M9: ="001" -> 001 | O9: STDCO | P9: 2 | Q9: 1 | R9: 1
A10: 45658 | B10: SIEGE1901EXTOU000131 | C10: SIEGE | D10: EXT | E10: EXT | F10: PROV RIST TRIMESTR PRODICOM DEC 24 | G10: -7906005 | H10: 0 | I10: -7906005 | J10: AUTRES | K10: EXT12046 | L10: ="408106" -> 408106 | M10: ="001" -> 001 | O10: STDCO | P10: 2 | Q10: 1 | R10: 1
A11: 45658 | B11: SIEGE1901EXTOU000131 | C11: SIEGE | D11: EXT | E11: EXT | F11: PROV RIST TRIMESTR SOMAC DEC 24 | G11: -3398061 | H11: 0 | I11: -3398061 | J11: AUTRES | K11: EXT12046 | L11: ="408106" -> 408106 | M11: ="001" -> 001 | O11: STDCO | P11: 2 | Q11: 1 | R11: 1
A12: 45658 | B12: SIEGE1901EXTOU000131 | C12: SIEGE | D12: EXT | E12: EXT | F12: PROV RIST TRIM AFTEL DEC 24 | G12: -331971 | H12: 0 | I12: -331971 | J12: AUTRES | K12: EXT12046 | L12: ="408106" -> 408106 | M12: ="001" -> 001 | O12: STDCO | P12: 2 | Q12: 1 | R12: 1
A13: 45658 | B13: SIEGE1901EXTOU000131 | C13: SIEGE | D13: EXT | E13: EXT | F13: PROV RIST/MENS MMONEY EASY COM DEC 24 | G13: -2127132 | H13: 0 | I13: -2127132 | J13: AUTRES | K13: EXT12046 | L13: ="408106" -> 408106 | M13: ="001" -> 001 | O13: STDCO | P13: 2 | Q13: 1 | R13: 1
... A70: 45658 | B70: SIEGE1901EXTOU000135 | C70: SIEGE | D70: EXT | E70: EXT | F70: EXT PROV RIST TRIMESTR D_COM OCT 24 | G70: -1849452 | H70: 0 | I70: -1849452 | J70: AUTRES | K70: EXT12046 | L70: ="408106" -> 408106 | M70: ="001" -> 001 | O70: STDCO | P70: 2 | Q70: 1 | R70: 1
A71: 45659 | B71: FAFSIEGE25010323 | C71: SIEGE | D71: FAFOU | E71: FA | F71: AGONMAKPOSSI F4 COMMISSION | G71: -46950 | H71: 0 | I71: -46950 | J71: AUTRES | K71: FA0349 | L71: ="401699" -> 401699 | M71: ="001" -> 001 | O71: STDCO | P71: 2 | Q71: 1 | R71: 1
A72: 45659 | B72: FAFSIEGE25010324 | C72: SIEGE | D72: FAFOU | E72: FA | F72: AGONMAKPOSSI F4 COMMISSION | G72: 46950 | H72: 0 | I72: 46950 | J72: AUTRES | K72: FA0350 | L72: ="401699" -> 401699 | M72: ="001" -> 001 | O72: STDCO | P72: 2 | Q72: 1 | R72: 1
A73: 45659 | B73: SIEGE1901EXTOU000044 | C73: SIEGE | D73: EXT | E73: EXT | F73: EXT PROV PRIMES ACTIVATÂ°/MOOVSHOPS | G73: -356100 | H73: 0 | I73: -356100 | J73: AUTRES | K73: EXT12029 | L73: ="408101" -> 408101 | M73: ="001" -> 001 | O73: STDCO | P73: 2 | Q73: 1 | R73: 1
A74: 45659 | B74: SIEGE1901EXTOU000044 | C74: SIEGE | D74: EXT | E74: EXT | F74: EXT PROV PROMOTEURS PRIME JRNL | G74: -27617700 | H74: 0 | I74: -27617700 | J74: AUTRES | K74: EXT12029 | L74: ="408101" -> 408101 | M74: ="001" -> 001 | O74: STDCO | P74: 2 | Q74: 1 | R74: 1
A75: 45660 | B75: FAFSIEGE25010094 | C75: SIEGE | D75: FAFOU | E75: FA | F75: ANNUL DJOKLE C. F18 NOV24 APPORTEUR D'AFFAIRE | G75: -266925 | H75: 0 | I75: -266925 | J75: AUTRES | K75: FA0143 | L75: ="401699" -> 401699 | M75: ="001" -> 001 | O75: STDCO | P75: 2 | Q75: 1 | R75: 1
A76: 45660 | B76: FAFSIEGE25010095 | C76: SIEGE | D76: FAFOU | E76: FA | F76: ANNUL DJOKLE C. F18 NOV24 APPORTEUR D'AFFAIRE | G76: 266925 | H76: 0 | I76: 266925 | J76: AUTRES | K76: FA0144 | L76: ="401699" -> 401699 | M76: ="001" -> 001 | O76: STDCO | P76: 2 | Q76: 1 | R76: 1
A77: 45663 | B77: FAFSIEGE25010001 | C77: SIEGE | D77: FAFOU | E77: FA | F77: EASYCOM F16155 DEC-24 COM PDV | G77: 2163201 | H77: 0 | I77: 2163201 | J77: AUTRES | K77: FA0051 | L77: ="401924" -> 401924 | M77: ="001" -> 001 | O77: STDCO | P77: 2 | Q77: 1 | R77: 1
A78: 45663 | B78: FAFSIEGE25010002 | C78: SIEGE | D78: FAFOU | E78: FA | F78: EASYCOM F16155 DEC-24 DIRECTE MASTER | G78: 811200 | H78: 0 | I78: 811200 | J78: AUTRES | K78: FA0051 | L78: ="401924" -> 401924 | M78: ="001" -> 001 | O78: STDCO | P78: 2 | Q78: 1 | R78: 1
A79: 45663 | B79: FAFSIEGE25010002 | C79: SIEGE | D79: FAFOU | E79: FA | F79: EASYCOM F16155 DEC-24 COM EVD | G79: 270400 | H79: 0 | I79: 270400 | J79: AUTRES | K79: FA0051 | L79: ="401924" -> 401924 | M79: ="001" -> 001 | O79: STDCO | P79: 2 | Q79: 1 | R79: 1
A80: 45663 | B80: FAFSIEGE25010002 | C80: SIEGE | D80: FAFOU | E80: FA | F80: EASYCOM F16155 DEC-24 MENSUEL MM | G80: 2141531 | H80: 0 | I80: 2141531 | J80: AUTRES | K80: FA0051 | L80: ="401924" -> 401924 | M80: ="001" -> 001 | O80: STDCO | P80: 2 | Q80: 1 | R80: 1
A81: 45663 | B81: FAFSIEGE25010002 | C81: SIEGE | D81: FAFOU | E81: FA | F81: EASYCOM F16155 DEC-24 RECHARG MM | G81: 10707655 | H81: 0 | I81: 10707655 | J81: AUTRES | K81: FA0051 | L81: ="401924" -> 401924 | M81: ="001" -> 001 | O81: STDCO | P81: 2 | Q81: 1 | R81: 1
A82: 45663 | B82: FAFSIEGE25010002 | C82: SIEGE | D82: FAFOU | E82: FA | F82: EASYCOM F16155 DEC-24 SPECIAL NORD | G82: 847458 | H82: 0 | I82: 847458 | J82: AUTRES | K82: FA0051 | L82: ="401924" -> 401924 | M82: ="001" -> 001 | O82: STDCO | P82: 2 | Q82: 1 | R82: 1
A83: 45663 | B83: FAFSIEGE25010002 | C83: SIEGE | D83: FAFOU | E83: FA | F83: EASYCOM F15623 T4-2024 TRIME4 | G83: 11825819 | H83: 0 | I83: 11825819 | J83: AUTRES | K83: FA0051 | L83: ="401924" -> 401924 | M83: ="001" -> 001 | O83: STDCO | P83: 2 | Q83: 1 | R83: 1
A84: 45663 | B84: FAFSIEGE25010003 | C84: SIEGE | D84: FAFOU | E84: FA | F84: AVOIR F1033 LINARCEL F1032 NOV24 COM REALISATÂ° MM DEPOT RETRAIT | G84: -721146 | H84: 0 | I84: -721146 | J84: AUTRES | K84: FA0052 | L84: ="401916" -> 401916 | M84: ="001" -> 001 | O84: STDCO | P84: 2 | Q84: 1 | R84: 1
A85: 45663 | B85: FAFSIEGE25010010 | C85: SIEGE | D85: FAFOU | E85: FA | F85: EASYCOM F16176 ANNUELLE 2024 COMMISSION | G85: 56972031 | H85: 0 | I85: 56972031 | J85: AUTRES | K85: FA0059 | L85: ="401924" -> 401924 | M85: ="001" -> 001 | O85: STDCO | P85: 2 | Q85: 1 | R85: 1
A86: 45664 | B86: FAFSIEGE25010134 | C86: SIEGE | D86: FAFOU | E86: FA | F86: SOMAC F154 DEC-24 COM | G86: 12616421 | H86: 0 | I86: 12616421 | J86: AUTRES | K86: FA0005 | L86: ="401918" -> 401918 | M86: ="001" -> 001 | O86: STDCO | P86: 2 | Q86: 1 | R86: 1
A87: 45664 | B87: FAFSIEGE25010135 | C87: SIEGE | D87: FAFOU | E87: FA | F87: SOMAC F155 COM T4 2024 | G87: 9749660 | H87: 0 | I87: 9749660 | J87: AUTRES | K87: FA0006 | L87: ="401918" -> 401918 | M87: ="001" -> 001 | O87: STDCO | P87: 2 | Q87: 1 | R87: 1
A88: 45664 | B88: FAFSIEGE25010136 | C88: SIEGE | D88: FAFOU | E88: FA | F88: SOMAC F156 DEC-24 4% COM | G88: 1188537 | H88: 0 | I88: 1188537 | J88: AUTRES | K88: FA0007 | L88: ="401918" -> 401918 | M88: ="001" -> 001 | O88: STDCO | P88: 2 | Q88: 1 | R88: 1
A89: 45664 | B89: FAFSIEGE25010137 | C89: SIEGE | D89: FAFOU | E89: FA | F89: AFTEL F20 1,5% DEC-24 COM DIRECT | G89: 26210 | H89: 0 | I89: 26210 | J89: AUTRES | K89: FA0008 | L89: ="4018051" -> 4018051 | M89: ="001" -> 001 | O89: STDCO | P89: 2 | Q89: 1 | R89: 1
A90: 45664 | B90: FAFSIEGE25010137 | C90: SIEGE | D90: FAFOU | E90: FA | F90: AFTEL F20 4% DEC-24 COM DIRECT | G90: 69893 | H90: 0 | I90: 69893 | J90: AUTRES | K90: FA0008 | L90: ="4018051" -> 4018051 | M90: ="001" -> 001 | O90: STDCO | P90: 2 | Q90: 1 | R90: 1
A91: 45664 | B91: FAFSIEGE25010137 | C91: SIEGE | D91: FAFOU | E91: FA | F91: AFTEL F20 COMMI T4 2024 | G91: 1075745 | H91: 0 | I91: 1075745 | J91: AUTRES | K91: FA0008 | L91: ="4018051" -> 4018051 | M91: ="001" -> 001 | O91: STDCO | P91: 2 | Q91: 1 | R91: 1
A92: 45664 | B92: FAFSIEGE25010138 | C92: SIEGE | D92: FAFOU | E92: FA | F92: AFTEL F22 DEC-24 COM RECHARGE | G92: 834901 | H92: 0 | I92: 834901 | J92: AUTRES | K92: FA0009 | L92: ="4018051" -> 4018051 | M92: ="001" -> 001 | O92: STDCO | P92: 2 | Q92: 1 | R92: 1
A93: 45664 | B93: FAFSIEGE25010150 | C93: SIEGE | D93: FAFOU | E93: FA | F93: SOMAC F157 SOLD COM ANNU-24 | G93: 51413053 | H93: 0 | I93: 51413053 | J93: AUTRES | K93: FA0021 | L93: ="401918" -> 401918 | M93: ="001" -> 001 | O93: STDCO | P93: 2 | Q93: 1 | R93: 1
A94: 45664 | B94: FAFSIEGE25010151 | C94: SIEGE | D94: FAFOU | E94: FA | F94: D COMMERCIAL F388 ANNUEL-24 | G94: 16315807 | H94: 0 | I94: 16315807 | J94: AUTRES | K94: FA0022 | L94: ="401915" -> 401915 | M94: ="001" -> 001 | O94: STDCO | P94: 2 | Q94: 1 | R94: 1
A95: 45664 | B95: FAFSIEGE25010152 | C95: SIEGE | D95: FAFOU | E95: FA | F95: D COMMERCIAL F389 1,5% DEC-24 COM DIRECT | G95: 587733 | H95: 0 | I95: 587733 | J95: AUTRES | K95: FA0023 | L95: ="401915" -> 401915 | M95: ="001" -> 001 | O95: STDCO | P95: 2 | Q95: 1 | R95: 1
A96: 45664 | B96: FAFSIEGE25010152 | C96: SIEGE | D96: FAFOU | E96: FA | F96: D COMMERCIAL F389 4% DEC-24 COM DIRECT | G96: 1567289 | H96: 0 | I96: 1567289 | J96: AUTRES | K96: FA0023 | L96: ="401915" -> 401915 | M96: ="001" -> 001 | O96: STDCO | P96: 2 | Q96: 1 | R96: 1
...

Sheet 605731 01 25
A1: Date | B1: NumÃ©ro de piÃ¨ce | C1: Site | D1: Type | E1: Journal | F1: LibellÃ© ligne | G1: DÃ©bit rÃ©fÃ©rentiel | H1: CrÃ©dit rÃ©fÃ©rentiel | I1: SOLDE | J1: MAP | K1: RÃ©fÃ©rence | L1: Contrepartie | M1: Taxe | N1: Coll | O1: Transaction | P1: Module | Q1: CatÃ©gorie | R1: Etat | S1: NumÃ©ro chrono | T1: Marquage
A2: 45659 | B2: SIEGE1901EXTOU000033 | C2: SIEGE | D2: EXT | E2: EXT | F2: EXT PROV RVNU UNIPAY DEC 24 | G2: -4458480 | H2: 0 | I2: -4458480 | J2: AUTRES | K2: EXT12011-1 | L2: ="408101" -> 408101 | M2: ="001" -> 001 | O2: STDCO | P2: 2 | Q2: 1 | R2: 1
A3: 45659 | B3: SIEGE1901EXTOU000034 | C3: SIEGE | D3: EXT | E3: EXT | F3: EXT PROV RVNU SHARE CHANNEL VAS HOLDINGS Oct, DEC 24 | G3: -1241976 | H3: 0 | I3: -1241976 | J3: AUTRES | K3: EXT12011-2 | L3: ="408101" -> 408101 | M3: ="001" -> 001 | O3: STDCO | P3: 2 | Q3: 1 | R3: 1
A4: 45659 | B4: SIEGE1901EXTOU000035 | C4: SIEGE | D4: EXT | E4: EXT | F4: EXT PROV MOBILEUM INC DEC 24 | G4: 0 | H4: 0 | I4: 0 | J4: AUTRES | K4: EXT12011-3 | L4: ="408101" -> 408101 | M4: ="001" -> 001 | O4: STDCO | P4: 2 | Q4: 1 | R4: 1
A5: 45659 | B5: SIEGE1901EXTOU000080 | C5: SIEGE | D5: EXT | E5: EXT | F5: BLACK GREEN RELIGIOUS SVCES OCT 24 | G5: -28163591 | H5: 0 | I5: -28163591 | J5: AUTRES | K5: EXT12078 | L5: ="408101" -> 408101 | M5: ="001" -> 001 | O5: STDCO | P5: 2 | Q5: 1 | R5: 1
A6: 45659 | B6: SIEGE1901EXTOU000080 | C6: SIEGE | D6: EXT | E6: EXT | F6: EXT PROV PEACEBOXCOM SMS OCT 24 | G6: -1405980 | H6: 0 | I6: -1405980 | J6: AUTRES | K6: EXT12078 | L6: ="408101" -> 408101 | M6: ="001" -> 001 | O6: STDCO | P6: 2 | Q6: 1 | R6: 1
A7: 45659 | B7: SIEGE1901EXTOU000080 | C7: SIEGE | D7: EXT | E7: EXT | F7: KIRUSA MOOV CELEBRITES OCT 24 | G7: -246750 | H7: 0 | I7: -246750 | J7: AUTRES | K7: EXT12078 | L7: ="408101" -> 408101 | M7: ="001" -> 001 | O7: STDCO | P7: 2 | Q7: 1 | R7: 1
A8: 45659 | B8: SIEGE1901EXTOU000106 | C8: SIEGE | D8: EXT | E8: EXT | F8: EXT PROV COMVIVA Mars- avr 23&24 MAI JUIN DEC 24 | G8: -701862 | H8: 0 | I8: -701862 | J8: AUTRES | K8: EXT012010 | L8: ="408101" -> 408101 | M8: ="001" -> 001 | O8: STDCO | P8: 2 | Q8: 1 | R8: 1
A9: 45663 | B9: FAFSIEGE25010004 | C9: SIEGE | D9: FAFOU | E9: FA | F9: UNIPAY F06-24 JUIN-24 IVR DATING | G9: 635027 | H9: 0 | I9: 635027 | J9: AUTRES | K9: FA0053 | L9: ="401699" -> 401699 | M9: ="001" -> 001 | O9: STDCO | P9: 2 | Q9: 1 | R9: 1
A10: 45663 | B10: FAFSIEGE25010005 | C10: SIEGE | D10: FAFOU | E10: FA | F10: UNIPAY F07-24 JLT-24 IVR DATING | G10: 480112 | H10: 0 | I10: 480112 | J10: AUTRES | K10: FA0054 | L10: ="401699" -> 401699 | M10: ="001" -> 001 | O10: STDCO | P10: 2 | Q10: 1 | R10: 1
A11: 45663 | B11: FAFSIEGE25010006 | C11: SIEGE | D11: FAFOU | E11: FA | F11: UNIPAY F08-24 AOUT-24 IVR DATING | G11: 453421 | H11: 0 | I11: 453421 | J11: AUTRES | K11: FA0055 | L11: ="401699" -> 401699 | M11: ="001" -> 001 | O11: STDCO | P11: 2 | Q11: 1 | R11: 1
A12: 45663 | B12: FAFSIEGE25010007 | C12: SIEGE | D12: FAFOU | E12: FA | F12: UNIPAY F09-24 SEPT-24 IVR DATING | G12: 382313 | H12: 0 | I12: 382313 | J12: AUTRES | K12: FA0056 | L12: ="401699" -> 401699 | M12: ="001" -> 001 | O12: STDCO | P12: 2 | Q12: 1 | R12: 1
A13: 45663 | B13: FAFSIEGE25010008 | C13: SIEGE | D13: FAFOU | E13: FA | F13: UNIPAY F10-24 OCT-24 IVR DATING | G13: 377544 | H13: 0 | I13: 377544 | J13: AUTRES | K13: FA0057 | L13: ="401699" -> 401699 | M13: ="001" -> 001 | O13: STDCO | P13: 2 | Q13: 1 | R13: 1
A14: 45663 | B14: FAFSIEGE25010009 | C14: SIEGE | D14: FAFOU | E14: FA | F14: UNIPAY F11-24 NOV-24 IVR DATING | G14: 360211 | H14: 0 | I14: 360211 | J14: AUTRES | K14: FA0058 | L14: ="401699" -> 401699 | M14: ="001" -> 001 | O14: STDCO | P14: 2 | Q14: 1 | R14: 1
A15: 45663 | B15: FAFSIEGE25010011 | C15: SIEGE | D15: FAFOU | E15: FA | F15: SUMMVIEW F89 DEC24 MOOV TV | G15: 1006389 | H15: 0 | I15: 1006389 | J15: AUTRES | K15: FA0060 | L15: ="401729" -> 401729 | M15: ="001" -> 001 | O15: STDCO | P15: 2 | Q15: 1 | R15: 1
A16: 45663 | B16: FAFSIEGE25010025 | C16: SIEGE | D16: FAFOU | E16: FA | F16: CHANNEL VAS F215-315 DEC-24 FEE R | G16: 1034674 | H16: 0 | I16: 1034674 | J16: AUTRES | K16: FA0074 | L16: ="401999" -> 401999 | M16: ="001" -> 001 | O16: STDCO | P16: 2 | Q16: 1 | R16: 1
A17: 45663 | B17: FAFSIEGE25010035 | C17: SIEGE | D17: FAFOU | E17: FA | F17: AFRIC CONSULTING F02 DEC-24 QUIZZ GENIE HERBE | G17: 305983 | H17: 0 | I17: 305983 | J17: AUTRES | K17: FA0084 | L17: ="401699" -> 401699 | M17: ="001" -> 001 | O17: STDCO | P17: 2 | Q17: 1 | R17: 1
A18: 45663 | B18: FAFSIEGE25010039 | C18: SIEGE | D18: FAFOU | E18: FA | F18: UNIPAY F05-24 MAI-24 IVR DATING | G18: 609078 | H18: 0 | I18: 609078 | J18: AUTRES | K18: FA0088 | L18: ="401699" -> 401699 | M18: ="001" -> 001 | O18: STDCO | P18: 2 | Q18: 1 | R18: 1
A19: 45665 | B19: FAFSIEGE25010101 | C19: SIEGE | D19: FAFOU | E19: FA | F19: KIRUSA F6866 DEC-24 CELEBR REV | G19: 74724 | H19: 0 | I19: 74724 | J19: AUTRES | K19: FA0150 | L19: ="401699" -> 401699 | M19: ="001" -> 001 | O19: STDCO | P19: 2 | Q19: 1 | R19: 1
A20: 45665 | B20: FAFSIEGE25010102 | C20: SIEGE | D20: FAFOU | E20: FA | F20: BLACKNGREEN F570 DEC-24 PORT RELIG | G20: 19710458 | H20: 0 | I20: 19710458 | J20: AUTRES | K20: FA0200 | L20: ="401699" -> 401699 | M20: ="001" -> 001 | O20: STDCO | P20: 2 | Q20: 1 | R20: 1
A21: 45670 | B21: FAFSIEGE25010108 | C21: SIEGE | D21: FAFOU | E21: FA | F21: DIGITAL VIRGO F159 MAI-DEC24 SERVICE A VALEUR AJOUTE | G21: 1039225 | H21: 0 | I21: 1039225 | J21: AUTRES | K21: FA0206 | L21: ="401699" -> 401699 | M21: ="001" -> 001 | O21: STDCO | P21: 2 | Q21: 1 | R21: 1
A22: 45670 | B22: FAFSIEGE25010109 | C22: SIEGE | D22: FAFOU | E22: FA | F22: COMVIVA F11576 MAI-JUIN24 RVNU SHARE | G22: 45195 | H22: 0 | I22: 45195 | J22: AUTRES | K22: FA0207 | L22: ="401529" -> 401529 | M22: ="001" -> 001 | O22: STDCO | P22: 2 | Q22: 1 | R22: 1
A23: 45670 | B23: FAFSIEGE25010127 | C23: SIEGE | D23: FAFOU | E23: FA | F23: SINCH:SAP FRANCE F10310044I DEC-24 Rdvces | G23: 601427 | H23: 0 | I23: 601427 | J23: AUTRES | K23: FA0226 | L23: ="401170" -> 401170 | M23: ="001" -> 001 | O23: STDCO | P23: 2 | Q23: 1 | R23: 1
A24: 45670 | B24: SIEGE1901EXTOU000137 | C24: SIEGE | D24: EXT | E24: EXT | F24: EXT PROV SMS SAPFRANCE DEC24 | G24: -1498624 | H24: 0 | I24: -1498624 | J24: AUTRES | K24: EXT12057-1 | L24: ="408870" -> 408870 | M24: ="001" -> 001 | O24: STDCO | P24: 2 | Q24: 1 | R24: 1
A25: 45677 | B25: FAFSIEGE25010260 | C25: SIEGE | D25: FAFOU | E25: FA | F25: PANZ CONSULTANTS F01-12 DEC-24 GAMEOFYY | G25: 3242098 | H25: 0 | I25: 3242098 | J25: AUTRES | K25: FA0280 | L25: ="401699" -> 401699 | M25: ="001" -> 001 | O25: STDCO | P25: 2 | Q25: 1 | R25: 1
A26: 45688 | B26: SIEGE1901REGUL000021 | C26: SIEGE | D26: REG | E26: REG | F26: PROV RVNU UNIPAY DEC24 & JANV25 | G26: 1114620 | H26: 0 | I26: 1114620 | J26: AUTRES | K26: REG01011-1 | L26: ="408101" -> 408101 | M26: ="001" -> 001 | O26: STDCO | P26: 2 | Q26: 1 | R26: 1
A27: 45688 | B27: SIEGE1901REGUL000022 | C27: SIEGE | D27: REG | E27: REG | F27: PROV RVNU SHARE CHANNEL VAS HOLDINGS JANV 25 | G27: 1034674 | H27: 0 | I27: 1034674 | J27: AUTRES | K27: REG01011-2 | L27: ="408101" -> 408101 | M27: ="001" -> 001 | O27: STDCO | P27: 2 | Q27: 1 | R27: 1
A28: 45688 | B28: SIEGE1901REGUL000023 | C28: SIEGE | D28: REG | E28: REG | F28: PROV MOBILEUM INC JANV 25 | G28: 5739624 | H28: 0 | I28: 5739624 | J28: AUTRES | K28: REG01011-3 | L28: ="408101" -> 408101 | M28: ="001" -> 001 | O28: STDCO | P28: 2 | Q28: 1 | R28: 1
A29: 45688 | B29: SIEGE1901REGUL000068 | C29: SIEGE | D29: REG | E29: REG | F29: PROV BLACK GREEN RELIGIOUS SVCES JANV25 | G29: 28163591 | H29: 0 | I29: 28163591 | J29: AUTRES | K29: REG01078 | L29: ="408101" -> 408101 | M29: ="001" -> 001 | O29: STDCO | P29: 2 | Q29: 1 | R29: 1
A30: 45688 | B30: SIEGE1901REGUL000068 | C30: SIEGE | D30: REG | E30: REG | F30: PROV PEACEBOXCOM SMS | G30: 1484090 | H30: 0 | I30: 1484090 | J30: SMS | K30: REG01078 | L30: ="408101" -> 408101 | M30: ="001" -> 001 | O30: STDCO | P30: 2 | Q30: 1 | R30: 1
A31: 45688 | B31: SIEGE1901REGUL000068 | C31: SIEGE | D31: REG | E31: REG | F31: KIRUSA MOOV CELEBRITES JANV25 | G31: 246750 | H31: 0 | I31: 246750 | J31: AUTRES | K31: REG01078 | L31: ="408101" -> 408101 | M31: ="001" -> 001 | O31: STDCO | P31: 2 | Q31: 1 | R31: 1
A32: 45688 | B32: SIEGE1901REGUL000103 | C32: SIEGE | D32: REG | E32: REG | F32: PROV SMS BELGACOM JANV25 | G32: 1497392 | H32: 0 | I32: 1497392 | J32: SMS | K32: REG01057 | L32: ="408950" -> 408950 | M32: ="001" -> 001 | O32: STDCO | P32: 2 | Q32: 1 | R32: 1
A33: 45688 | B33: SIEGE1901REGUL000104 | C33: SIEGE | D33: REG | E33: REG | F33: PROV SMS SAPFRANCE JANV25 | G33: 1907575 | H33: 0 | I33: 1907575 | J33: SMS | K33: REG01057-1 | L33: ="408870" -> 408870 | M33: ="001" -> 001 | O33: STDCO | P33: 2 | Q33: 1 | R33: 1
A34: 45688 | B34: SIEGE1901REGUL000107 | C34: SIEGE | D34: REG | E34: REG | F34: PROV RVNU SHARING CRED SECOURS JANV25 | G34: 2755132 | H34: 0 | I34: 2755132 | J34: AUTRES | K34: REG01054 | L34: ="408101" -> 408101 | M34: ="001" -> 001 | O34: STDCO | P34: 2 | Q34: 1 | R34: 1

Sheet 632200 02 25
A1: Date | B1: NumÃ©ro de piÃ¨ce | C1: Site | D1: Type | E1: Journal | F1: LibellÃ© ligne | G1: DR | H1: CR | I1: SOLDE | J1: MAP | K1: RÃ©fÃ©rence | L1: Contrepartie | M1: Taxe | N1: Coll | O1: Transaction | P1: Module | Q1: CatÃ©gorie | R1: Etat | S1: NumÃ©ro chrono | T1: Marquage
A2: 45689 | B2: SIEGE1902EXTOU000029 | C2: SIEGE | D2: EXT | E2: EXT | F2: EXT PROV PRIMES ACTIVATÂ°/MOOVSHOPS | G2: -382900 | H2: 0 | I2: -382900 | J2: AUTRES | K2: EXT01029 | L2: ="408101" -> 408101 | M2: ="001" -> 001 | O2: STDCO | P2: 2 | Q2: 1 | R2: 1
A3: 45689 | B3: SIEGE1902EXTOU000029 | C3: SIEGE | D3: EXT | E3: EXT | F3: EXT PROV PROMOTEURS PRIME JRNL | G3: -9217277 | H3: 0 | I3: -9217277 | J3: AUTRES | K3: EXT01029 | L3: ="408101" -> 408101 | M3: ="001" -> 001 | O3: STDCO | P3: 2 | Q3: 1 | R3: 1
A4: 45689 | B4: SIEGE1902EXTOU000163 | C4: SIEGE | D4: EXT | E4: EXT | F4: EXT PROV PRIM ACTIV PRODICOM DEC 24 | G4: -3244831 | H4: 0 | I4: -3244831 | J4: AUTRES | K4: EXT01046 | L4: ="408106" -> 408106 | M4: ="001" -> 001 | O4: STDCO | P4: 2 | Q4: 1 | R4: 1
A5: 45689 | B5: SIEGE1902EXTOU000163 | C5: SIEGE | D5: EXT | E5: EXT | F5: EXT PROV PRIM ACTIV SOMAC DEC 24 | G5: -986186 | H5: 0 | I5: -986186 | J5: AUTRES | K5: EXT01046 | L5: ="408106" -> 408106 | M5: ="001" -> 001 | O5: STDCO | P5: 2 | Q5: 1 | R5: 1
A6: 45689 | B6: SIEGE1902EXTOU000163 | C6: SIEGE | D6: EXT | E6: EXT | F6: EXT PROV RIST/MENS MMONEY AFTEL JANV 25 | G6: -314849 | H6: 0 | I6: -314849 | J6: AUTRES | K6: EXT01046 | L6: ="408106" -> 408106 | M6: ="001" -> 001 | O6: STDCO | P6: 2 | Q6: 1 | R6: 1
A7: 45689 | B7: SIEGE1902EXTOU000163 | C7: SIEGE | D7: EXT | E7: EXT | F7: EXT PROV COM M-MONEY AFTEL JANV 25 | G7: -787124 | H7: 0 | I7: -787124 | J7: AUTRES | K7: EXT01046 | L7: ="408106" -> 408106 | M7: ="001" -> 001 | O7: STDCO | P7: 2 | Q7: 1 | R7: 1
A8: 45689 | B8: SIEGE1902EXTOU000163 | C8: SIEGE | D8: EXT | E8: EXT | F8: ANNUL EXT PARTIEL/RSIT ANNUEL SOMAC | G8: 15120214 | H8: 0 | I8: 15120214 | J8: AUTRES | K8: EXT01046 | L8: ="408106" -> 408106 | M8: ="001" -> 001 | O8: STDCO | P8: 2 | Q8: 1 | R8: 1
A9: 45691 | B9: FAFSIEGE25020067 | C9: SIEGE | D9: FAFOU | E9: FA | F9: AFTEL F30 PRIME ACCOMPAGNEMENT & RELANCE | G9: 3169322 | H9: 0 | I9: 3169322 | J9: AUTRES | K9: FA0317 | L9: ="4018051" -> 4018051 | M9: ="001" -> 001 | O9: STDCO | P9: 2 | Q9: 1 | R9: 1
A10: 45691 | B10: FAFSIEGE25020068 | C10: SIEGE | D10: FAFOU | E10: FA | F10: LINARCEL F1086 PRIME RELANCE & PRIME D'ACCOMPAGNEMENT TEAM BULDING | G10: 16556433 | H10: 0 | I10: 16556433 | J10: AUTRES | K10: FA0318 | L10: ="401916" -> 401916 | M10: ="001" -> 001 | O10: STDCO | P10: 2 | Q10: 1 | R10: 1
A11: 45691 | B11: FAFSIEGE25020071 | C11: SIEGE | D11: FAFOU | E11: FA | F11: D.COM F394 PRIME RELANCE & PRIME ACCOMPAGNEMENT TEAM BULDING | G11: 9333898 | H11: 0 | I11: 9333898 | J11: AUTRES | K11: FA0319 | L11: ="401915" -> 401915 | M11: ="001" -> 001 | O11: STDCO | P11: 2 | Q11: 1 | R11: 1
A12: 45691 | B12: FAFSIEGE25020072 | C12: SIEGE | D12: FAFOU | E12: FA | F12: EASYCOM F16348 PRIME ACCOMPAGNEMENT TEAM BULDING ET PRIME RELANCE | G12: 9060059 | H12: 0 | I12: 9060059 | J12: AUTRES | K12: FA0320 | L12: ="401924" -> 401924 | M12: ="001" -> 001 | O12: STDCO | P12: 2 | Q12: 1 | R12: 1
A13: 45691 | B13: FAFSIEGE25020073 | C13: SIEGE | D13: FAFOU | E13: FA | F13: PRODICOM F177 PRIME ACCOMPAGNEMENT TEAM BULDING ET PRIME RELANCE | G13: 21755469 | H13: 0 | I13: 21755469 | J13: AUTRES | K13: FA0321 | L13: ="401917" -> 401917 | M13: ="001" -> 001 | O13: STDCO | P13: 2 | Q13: 1 | R13: 1
A14: 45691 | B14: FAFSIEGE25020074 | C14: SIEGE | D14: FAFOU | E14: FA | F14: SOMAC F008 PRIME RELANCE | G14: 8047328 | H14: 0 | I14: 8047328 | J14: AUTRES | K14: FA0322 | L14: ="401918" -> 401918 | M14: ="001" -> 001 | O14: STDCO | P14: 2 | Q14: 1 | R14: 1
A15: 45691 | B15: FAFSIEGE25020075 | C15: SIEGE | D15: FAFOU | E15: FA | F15: SOMAC F009 PRIME ACCOMPAGNEMENT TEAM BULDING | G15: 2377034 | H15: 0 | I15: 2377034 | J15: AUTRES | K15: FA0323 | L15: ="401918" -> 401918 | M15: ="001" -> 001 | O15: STDCO | P15: 2 | Q15: 1 | R15: 1
A16: 45693 | B16: FAFSIEGE25020098 | C16: SIEGE | D16: FAFOU | E16: FA | F16: MANU'S F8 DEC-24 APPORTEUR AFFAIRE | G16: 88425 | H16: 0 | I16: 88425 | J16: AUTRES | K16: FA0523 | L16: ="401699" -> 401699 | M16: ="001" -> 001 | O16: STDCO | P16: 2 | Q16: 1 | R16: 1
A17: 45693 | B17: FAFSIEGE25020099 | C17: SIEGE | D17: FAFOU | E17: FA | F17: MANU'S F9 JAN-25 APPORTEUR AFFAIRE | G17: 84000 | H17: 0 | I17: 84000 | J17: AUTRES | K17: FA0524 | L17: ="401699" -> 401699 | M17: ="001" -> 001 | O17: STDCO | P17: 2 | Q17: 1 | R17: 1
A18: 45693 | B18: FAFSIEGE25020100 | C18: SIEGE | D18: FAFOU | E18: FA | F18: SOMAC F158 DEC-24 COMMISSION ACTIVATION KIT | G18: 1099492 | H18: 0 | I18: 1099492 | J18: AUTRES | K18: FA0525 | L18: ="401918" -> 401918 | M18: ="001" -> 001 | O18: STDCO | P18: 2 | Q18: 1 | R18: 1
A19: 45695 | B19: FAFSIEGE25020134 | C19: SIEGE | D19: FAFOU | E19: FA | F19: ASSOGBA GBENONCLO ELIE F1 APPORTEUR D'AFFAIRE | G19: 52275 | H19: 0 | I19: 52275 | J19: AUTRES | K19: FA0564 | L19: ="401699" -> 401699 | M19: ="001" -> 001 | O19: STDCO | P19: 2 | Q19: 1 | R19: 1
A20: 45695 | B20: FAFSIEGE25020135 | C20: SIEGE | D20: FAFOU | E20: FA | F20: OMO AKALA SERVICES F38 APPORTEUR D'AFFAIRE | G20: 12075 | H20: 0 | I20: 12075 | J20: AUTRES | K20: FA0565 | L20: ="401699" -> 401699 | M20: ="001" -> 001 | O20: STDCO | P20: 2 | Q20: 1 | R20: 1
A21: 45695 | B21: FAFSIEGE25020136 | C21: SIEGE | D21: FAFOU | E21: FA | F21: MEKASSOMAWOU SERVICE F8 APPORTEUR D'AFFAIRE | G21: 55950 | H21: 0 | I21: 55950 | J21: AUTRES | K21: FA0566 | L21: ="401699" -> 401699 | M21: ="001" -> 001 | O21: STDCO | P21: 2 | Q21: 1 | R21: 1
A22: 45698 | B22: FAFSIEGE25020223 | C22: SIEGE | D22: FAFOU | E22: FA | F22: PRODICOM F169 DEC-24 COM ACTIVATÂ° | G22: 3068898 | H22: 0 | I22: 3068898 | J22: AUTRES | K22: FA0411 | L22: ="401917" -> 401917 | M22: ="001" -> 001 | O22: STDCO | P22: 2 | Q22: 1 | R22: 1
A23: 45698 | B23: FAFSIEGE25020234 | C23: SIEGE | D23: FAFOU | E23: FA | F23: OMO AKALA SERVICES F39 JAN-25 COMMISSION | G23: 16650 | H23: 0 | I23: 16650 | J23: AUTRES | K23: FA0422 | L23: ="401699" -> 401699 | M23: ="001" -> 001 | O23: STDCO | P23: 2 | Q23: 1 | R23: 1
A24: 45698 | B24: FAFSIEGE25020235 | C24: SIEGE | D24: FAFOU | E24: FA | F24: MEKASSOMAWOU SERVICES F9 JAN-25 COMMISSION | G24: 39600 | H24: 0 | I24: 39600 | J24: AUTRES | K24: FA0423 | L24: ="401699" -> 401699 | M24: ="001" -> 001 | O24: STDCO | P24: 2 | Q24: 1 | R24: 1
A25: 45699 | B25: FAFSIEGE25020236 | C25: SIEGE | D25: FAFOU | E25: FA | F25: SIMENOU MITONDJI MARIUS F2 DEC-24 COMMISSION | G25: 11700 | H25: 0 | I25: 11700 | J25: AUTRES | K25: FA0424 | L25: ="401699" -> 401699 | M25: ="001" -> 001 | O25: STDCO | P25: 2 | Q25: 1 | R25: 1
A26: 45699 | B26: FAFSIEGE25020237 | C26: SIEGE | D26: FAFOU | E26: FA | F26: SIMENOU MITONDJI MARIUS F1 JAN-25 COMMISSION | G26: 99375 | H26: 0 | I26: 99375 | J26: AUTRES | K26: FA0425 | L26: ="401699" -> 401699 | M26: ="001" -> 001 | O26: STDCO | P26: 2 | Q26: 1 | R26: 1
A27: 45701 | B27: FAFSIEGE25020278 | C27: SIEGE | D27: FAFOU | E27: FA | F27: KOUKPOLIYI J. F7 JAN-25 COMMISSION | G27: 19875 | H27: 0 | I27: 19875 | J27: AUTRES | K27: FA0467 | L27: ="401699" -> 401699 | M27: ="001" -> 001 | O27: STDCO | P27: 2 | Q27: 1 | R27: 1
A28: 45705 | B28: FAFSIEGE25020350 | C28: SIEGE | D28: FAFOU | E28: FA | F28: AFTEL F33 JAN-25 COM RECHARGEMENT MOOV MONEY | G28: 789892 | H28: 0 | I28: 789892 | J28: AUTRES | K28: FA0671 | L28: ="4018051" -> 4018051 | M28: ="001" -> 001 | O28: STDCO | P28: 2 | Q28: 1 | R28: 1
A29: 45705 | B29: FAFSIEGE25020351 | C29: SIEGE | D29: FAFOU | E29: FA | F29: AFTEL F35 JAN-25 COM MENSUELLE MOOV MONEY | G29: 315957 | H29: 0 | I29: 315957 | J29: AUTRES | K29: FA0672 | L29: ="4018051" -> 4018051 | M29: ="001" -> 001 | O29: STDCO | P29: 2 | Q29: 1 | R29: 1
A30: 45708 | B30: FAFSIEGE25020313 | C30: SIEGE | D30: FAFOU | E30: FA | F30: DJOKLE C. S. F24 COMMISSION | G30: 169425 | H30: 0 | I30: 169425 | J30: AUTRES | K30: FA0678 | L30: ="401699" -> 401699 | M30: ="001" -> 001 | O30: STDCO | P30: 2 | Q30: 1 | R30: 1
A31: 45708 | B31: FAFSIEGE25020314 | C31: SIEGE | D31: FAFOU | E31: FA | F31: DJOKLE C. S. F23 COMMISSION | G31: 280350 | H31: 0 | I31: 280350 | J31: AUTRES | K31: FA0679 | L31: ="401699" -> 401699 | M31: ="001" -> 001 | O31: STDCO | P31: 2 | Q31: 1 | R31: 1
A32: 45708 | B32: SIEGE1902ENCAI025842 | C32: SIEGE | D32: ENCAI | E32: FLOOZ | F32: PRIMES ACTIVATÂ° JAN 24 | G32: 388200 | H32: 0 | I32: 388200 | J32: AUTRES | K32: FLOOZ0105 | M32: ="001" -> 001 | O32: STDCO | P32: 2 | Q32: 1 | R32: 1
A33: 45716 | B33: SIEGE1902REGUL000017 | C33: SIEGE | D33: REG | E33: REG | F33: PROV PRIMES ACTIVATÂ°/MOOVSHOPS | G33: 388200 | H33: 0 | I33: 388200 | J33: AUTRES | K33: REG02029 | L33: ="408101" -> 408101 | M33: ="001" -> 001 | O33: STDCO | P33: 2 | Q33: 1 | R33: 1
A34: 45716 | B34: SIEGE1902REGUL000017 | C34: SIEGE | D34: REG | E34: REG | F34: PROV PROMOTEURS PRIME JRNL | G34: 58000000 | H34: 0 | I34: 58000000 | J34: AUTRES | K34: REG02029 | L34: ="408101" -> 408101 | M34: ="001" -> 001 | O34: STDCO | P34: 2 | Q34: 1 | R34: 1
A35: 45716 | B35: SIEGE1902REGUL000188 | C35: SIEGE | D35: REG | E35: REG | F35: BONUS/ACTIV FORF V_D&EVD FEV25 | G35: 199650062 | H35: 0 | I35: 199650062 | J35: AUTRES | K35: REG02100 | L35: ="408101" -> 408101 | M35: ="001" -> 001 | O35: STDCO | P35: 2 | Q35: 1 | R35: 1
A36: 45716 | B36: SIEGE1902REGUL000230 | C36: SIEGE | D36: REG | E36: REG | F36: PROV RSIT ANNUEL D_COM FEV 25 | G36: 3753615 | H36: 0 | I36: 3753615 | J36: AUTRES | K36: REG02046 | L36: ="408106" -> 408106 | M36: ="001" -> 001 | O36: STDCO | P36: 2 | Q36: 1 | R36: 1
A37: 45716 | B37: SIEGE1902REGUL000230 | C37: SIEGE | D37: REG | E37: REG | F37: PROV RSIT ANNUEL SOMAC FEV 25 | G37: 5588196 | H37: 0 | I37: 5588196 | J37: AUTRES | K37: REG02046 | L37: ="408106" -> 408106 | M37: ="001" -> 001 | O37: STDCO | P37: 2 | Q37: 1 | R37: 1
A38: 45716 | B38: SIEGE1902REGUL000230 | C38: SIEGE | D38: REG | E38: REG | F38: PROV RSIT ANNUEL EASYCOM FEV 25 | G38: 7791669 | H38: 0 | I38: 7791669 | J38: AUTRES | K38: REG02046 | L38: ="408106" -> 408106 | M38: ="001" -> 001 | O38: STDCO | P38: 2 | Q38: 1 | R38: 1
A39: 45716 | B39: SIEGE1902REGUL000230 | C39: SIEGE | D39: REG | E39: REG | F39: PROV RSIT ANNUEL LINARCEL FEV 25 | G39: 13132280 | H39: 0 | I39: 13132280 | J39: AUTRES | K39: REG02046 | L39: ="408106" -> 408106 | M39: ="001" -> 001 | O39: STDCO | P39: 2 | Q39: 1 | R39: 1
A40: 45716 | B40: SIEGE1902REGUL000230 | C40: SIEGE | D40: REG | E40: REG | F40: PROV RSIT ANNUEL PRODICOM FEV 25 | G40: 13579675 | H40: 0 | I40: 13579675 | J40: AUTRES | K40: REG02046 | L40: ="408106" -> 408106 | M40: ="001" -> 001 | O40: STDCO | P40: 2 | Q40: 1 | R40: 1
...

Sheet 605731 02 25
A1: Date | B1: NumÃ©ro de piÃ¨ce | C1: Site | D1: Type | E1: Journal | F1: LibellÃ© ligne | G1: DR | H1: CR | I1: SOLDE | J1: MAP | K1: RÃ©fÃ©rence | L1: Contrepartie | M1: Taxe | N1: Coll | O1: Transaction | P1: Module | Q1: CatÃ©gorie | R1: Etat | S1: NumÃ©ro chrono | T1: Marquage
A2: 45689 | B2: FAFSIEGE25020194 | C2: SIEGE | D2: FAFOU | E2: FA | F2: ComzAfrica F1755 JAN-24 ACS SERVICE | G2: 1963369 | H2: 0 | I2: 1963369 | J2: AUTRES | K2: FA0383 | L2: ="401499" -> 401499 | M2: ="001" -> 001 | O2: STDCO | P2: 2 | Q2: 1 | R2: 1
A3: 45689 | B3: FAFSIEGE25020195 | C3: SIEGE | D3: FAFOU | E3: FA | F3: ComzAfrica F1756 FEV-24 ACS SERVICE | G3: 1681359 | H3: 0 | I3: 1681359 | J3: AUTRES | K3: FA0384 | L3: ="401499" -> 401499 | M3: ="001" -> 001 | O3: STDCO | P3: 2 | Q3: 1 | R3: 1
A4: 45689 | B4: FAFSIEGE25020196 | C4: SIEGE | D4: FAFOU | E4: FA | F4: ComzAfrica F1757 MARS-24 ACS SERVICE | G4: 1219019 | H4: 0 | I4: 1219019 | J4: AUTRES | K4: FA0385 | L4: ="401499" -> 401499 | M4: ="001" -> 001 | O4: STDCO | P4: 2 | Q4: 1 | R4: 1
A5: 45689 | B5: FAFSIEGE25020197 | C5: SIEGE | D5: FAFOU | E5: FA | F5: ComzAfrica F1758 AVRIL-24 ACS SERVICE | G5: 1535116 | H5: 0 | I5: 1535116 | J5: AUTRES | K5: FA0386 | L5: ="401499" -> 401499 | M5: ="001" -> 001 | O5: STDCO | P5: 2 | Q5: 1 | R5: 1
A6: 45689 | B6: FAFSIEGE25020198 | C6: SIEGE | D6: FAFOU | E6: FA | F6: ComzAfrica F1759 MAI-24 ACS SERVICE | G6: 1402810 | H6: 0 | I6: 1402810 | J6: AUTRES | K6: FA0387 | L6: ="401499" -> 401499 | M6: ="001" -> 001 | O6: STDCO | P6: 2 | Q6: 1 | R6: 1
A7: 45689 | B7: FAFSIEGE25020199 | C7: SIEGE | D7: FAFOU | E7: FA | F7: ComzAfrica F1760 JUIN-24 ACS SERVICE | G7: 842029 | H7: 0 | I7: 842029 | J7: AUTRES | K7: FA0388 | L7: ="401499" -> 401499 | M7: ="001" -> 001 | O7: STDCO | P7: 2 | Q7: 1 | R7: 1
A8: 45689 | B8: FAFSIEGE25020200 | C8: SIEGE | D8: FAFOU | E8: FA | F8: ComzAfrica F1761 JUIL-24 ACS SERVICE | G8: 886965 | H8: 0 | I8: 886965 | J8: AUTRES | K8: FA0389 | L8: ="401499" -> 401499 | M8: ="001" -> 001 | O8: STDCO | P8: 2 | Q8: 1 | R8: 1
A9: 45689 | B9: FAFSIEGE25020201 | C9: SIEGE | D9: FAFOU | E9: FA | F9: ComzAfrica F1762 AOUT-24 ACS SERVICE | G9: 1066996 | H9: 0 | I9: 1066996 | J9: AUTRES | K9: FA0390 | L9: ="401499" -> 401499 | M9: ="001" -> 001 | O9: STDCO | P9: 2 | Q9: 1 | R9: 1
A10: 45689 | B10: FAFSIEGE25020202 | C10: SIEGE | D10: FAFOU | E10: FA | F10: ComzAfrica F1763 SEPT-24 ACS SERVICE | G10: 777020 | H10: 0 | I10: 777020 | J10: AUTRES | K10: FA0391 | L10: ="401499" -> 401499 | M10: ="001" -> 001 | O10: STDCO | P10: 2 | Q10: 1 | R10: 1
A11: 45689 | B11: FAFSIEGE25020203 | C11: SIEGE | D11: FAFOU | E11: FA | F11: ComzAfrica F1764 OCT-24 ACS SERVICE | G11: 813927 | H11: 0 | I11: 813927 | J11: AUTRES | K11: FA0392 | L11: ="401499" -> 401499 | M11: ="001" -> 001 | O11: STDCO | P11: 2 | Q11: 1 | R11: 1
A12: 45689 | B12: FAFSIEGE25020204 | C12: SIEGE | D12: FAFOU | E12: FA | F12: ComzAfrica F1765 NOV-24 ACS SERVICE | G12: 1212502 | H12: 0 | I12: 1212502 | J12: AUTRES | K12: FA0393 | L12: ="401499" -> 401499 | M12: ="001" -> 001 | O12: STDCO | P12: 2 | Q12: 1 | R12: 1
A13: 45689 | B13: FAFSIEGE25020205 | C13: SIEGE | D13: FAFOU | E13: FA | F13: ComzAfrica F1766 DEC-24 ACS SERVICE | G13: 1259610 | H13: 0 | I13: 1259610 | J13: AUTRES | K13: FA0394 | L13: ="401499" -> 401499 | M13: ="001" -> 001 | O13: STDCO | P13: 2 | Q13: 1 | R13: 1
A14: 45689 | B14: FAFSIEGE25020214 | C14: SIEGE | D14: FAFOU | E14: FA | F14: UNIPAY F12-24IVR DATIN DEC-24 | G14: 100061 | H14: 0 | I14: 100061 | J14: AUTRES | K14: FA0403 | L14: ="401699" -> 401699 | M14: ="001" -> 001 | O14: STDCO | P14: 2 | Q14: 1 | R14: 1
A15: 45689 | B15: SIEGE1902EXTOU000002 | C15: SIEGE | D15: EXT | E15: EXT | F15: EXT PROV COMVIVA Mars- avr 23&24 MAI JUIN DEC JAN 25 | G15: -584649 | H15: 0 | I15: -584649 | J15: AUTRES | K15: EXT001010 | L15: ="408101" -> 408101 | M15: ="001" -> 001 | O15: STDCO | P15: 2 | Q15: 1 | R15: 1
A16: 45689 | B16: SIEGE1902EXTOU000018 | C16: SIEGE | D16: EXT | E16: EXT | F16: EXT PROV RVNU UNIPAY DEC24 & JANV25 | G16: -1114620 | H16: 0 | I16: -1114620 | J16: AUTRES | K16: EXT01011-1 | L16: ="408101" -> 408101 | M16: ="001" -> 001 | O16: STDCO | P16: 2 | Q16: 1 | R16: 1
A17: 45689 | B17: SIEGE1902EXTOU000019 | C17: SIEGE | D17: EXT | E17: EXT | F17: EXT PROV RVNU SHARE CHANNEL VAS HOLDINGS JANV 25 | G17: -1034674 | H17: 0 | I17: -1034674 | J17: AUTRES | K17: EXT01011-2 | L17: ="408101" -> 408101 | M17: ="001" -> 001 | O17: STDCO | P17: 2 | Q17: 1 | R17: 1
A18: 45689 | B18: SIEGE1902EXTOU000020 | C18: SIEGE | D18: EXT | E18: EXT | F18: EXT PROV MOBILEUM INC JANV 25 | G18: -5739624 | H18: 0 | I18: -5739624 | J18: AUTRES | K18: EXT01011-3 | L18: ="408101" -> 408101 | M18: ="001" -> 001 | O18: STDCO | P18: 2 | Q18: 1 | R18: 1
A19: 45689 | B19: SIEGE1902EXTOU000065 | C19: SIEGE | D19: EXT | E19: EXT | F19: EXT PROV BLACK GREEN RELIGIOUS SVCES JANV25 | G19: -28163591 | H19: 0 | I19: -28163591 | J19: AUTRES | K19: EXT01078 | L19: ="408101" -> 408101 | M19: ="001" -> 001 | O19: STDCO | P19: 2 | Q19: 1 | R19: 1
A20: 45689 | B20: SIEGE1902EXTOU000065 | C20: SIEGE | D20: EXT | E20: EXT | F20: EXT PROV PEACEBOXCOM SMS | G20: -1484090 | H20: 0 | I20: -1484090 | J20: AUTRES | K20: EXT01078 | L20: ="408101" -> 408101 | M20: ="001" -> 001 | O20: STDCO | P20: 2 | Q20: 1 | R20: 1
A21: 45689 | B21: SIEGE1902EXTOU000065 | C21: SIEGE | D21: EXT | E21: EXT | F21: KIRUSA MOOV CELEBRITES JANV25 | G21: -246750 | H21: 0 | I21: -246750 | J21: AUTRES | K21: EXT01078 | L21: ="408101" -> 408101 | M21: ="001" -> 001 | O21: STDCO | P21: 2 | Q21: 1 | R21: 1
A22: 45689 | B22: SIEGE1902EXTOU000159 | C22: SIEGE | D22: EXT | E22: EXT | F22: EXT PROV RVNU SHAR CRED SEC JANV-DEC24 | G22: -27353809 | H22: 0 | I22: -27353809 | J22: AUTRES | K22: EXT12054 | L22: ="408101" -> 408101 | M22: ="001" -> 001 | O22: STDCO | P22: 2 | Q22: 1 | R22: 1
A23: 45689 | B23: SIEGE1902EXTOU000162 | C23: SIEGE | D23: EXT | E23: EXT | F23: EXT PROV SMS SAPFRANCE JANV25 | G23: -1907575 | H23: 0 | I23: -1907575 | J23: AUTRES | K23: EXT01057-1 | L23: ="408870" -> 408870 | M23: ="001" -> 001 | O23: STDCO | P23: 2 | Q23: 1 | R23: 1
A24: 45691 | B24: FAFSIEGE25020161 | C24: SIEGE | D24: FAFOU | E24: FA | F24: SUMMVIEW F10 JAN-25 MOOV TV | G24: 1005425 | H24: 0 | I24: 1005425 | J24: AUTRES | K24: FA0551 | L24: ="401729" -> 401729 | M24: ="001" -> 001 | O24: STDCO | P24: 2 | Q24: 1 | R24: 1
A25: 45693 | B25: FAFSIEGE25020162 | C25: SIEGE | D25: FAFOU | E25: FA | F25: CHANNEL VAS F215-347 JAN-25 FEE REPAYMENTS | G25: 1170994 | H25: 0 | I25: 1170994 | J25: AUTRES | K25: FA0552 | L25: ="401999" -> 401999 | M25: ="001" -> 001 | O25: STDCO | P25: 2 | Q25: 1 | R25: 1
A26: 45695 | B26: FAFSIEGE25020138 | C26: SIEGE | D26: FAFOU | E26: FA | F26: SINCH:SAP FRANCE F310377I JAN-25 Rdvces | G26: 568610 | H26: 0 | I26: 568610 | J26: AUTRES | K26: FA0568 | L26: ="401170" -> 401170 | M26: ="001" -> 001 | O26: STDCO | P26: 2 | Q26: 1 | R26: 1
A27: 45698 | B27: FAFSIEGE25020230 | C27: SIEGE | D27: FAFOU | E27: FA | F27: KIRUSA F6892 JAN-25 CELEBR REVENUE | G27: 74589 | H27: 0 | I27: 74589 | J27: AUTRES | K27: FA0418 | L27: ="401699" -> 401699 | M27: ="001" -> 001 | O27: STDCO | P27: 2 | Q27: 1 | R27: 1
A28: 45698 | B28: FAFSIEGE25020231 | C28: SIEGE | D28: FAFOU | E28: FA | F28: PANZ CONSULTANTS F02-08 JAN-25 GAMEOFYY | G28: 3148220 | H28: 0 | I28: 3148220 | J28: AUTRES | K28: FA0419 | L28: ="401699" -> 401699 | M28: ="001" -> 001 | O28: STDCO | P28: 2 | Q28: 1 | R28: 1
A29: 45707 | B29: FAFSIEGE25020330 | C29: SIEGE | D29: FAFOU | E29: FA | F29: UNIPAY F01-25 JAN-25 IVR DATING | G29: 328617 | H29: 0 | I29: 328617 | J29: AUTRES | K29: FA0651 | L29: ="401699" -> 401699 | M29: ="001" -> 001 | O29: STDCO | P29: 2 | Q29: 1 | R29: 1
A30: 45707 | B30: FAFSIEGE25020333 | C30: SIEGE | D30: FAFOU | E30: FA | F30: BLACKNGREEN F660 JAN-25 PORT RELIG | G30: 22208536 | H30: 0 | I30: 22208536 | J30: AUTRES | K30: FA0654 | L30: ="401699" -> 401699 | M30: ="001" -> 001 | O30: STDCO | P30: 2 | Q30: 1 | R30: 1
A31: 45716 | B31: SIEGE1902REGUL000006 | C31: SIEGE | D31: REG | E31: REG | F31: PROV RVNU UNIPAY FEV25 | G31: 557310 | H31: 0 | I31: 557310 | J31: AUTRES | K31: REG02011-1 | L31: ="408101" -> 408101 | M31: ="001" -> 001 | O31: STDCO | P31: 2 | Q31: 1 | R31: 1
A32: 45716 | B32: SIEGE1902REGUL000007 | C32: SIEGE | D32: REG | E32: REG | F32: PROV RVNU SHARE CHANNEL VAS FEV 25 | G32: 0 | H32: 0 | I32: 0 | J32: AUTRES | K32: REG02011-2 | L32: ="408101" -> 408101 | M32: ="001" -> 001 | O32: STDCO | P32: 2 | Q32: 1 | R32: 1
A33: 45716 | B33: SIEGE1902REGUL000008 | C33: SIEGE | D33: REG | E33: REG | F33: PROV MOBILEUM INC JANV-FEV25 | G33: 11479248 | H33: 0 | I33: 11479248 | J33: AUTRES | K33: REG02011-3 | L33: ="408101" -> 408101 | M33: ="001" -> 001 | O33: STDCO | P33: 2 | Q33: 1 | R33: 1
A34: 45716 | B34: SIEGE1902REGUL000053 | C34: SIEGE | D34: REG | E34: REG | F34: PROV BLACK GREEN RELIGIOUS SVCES FEV25 | G34: 28163591 | H34: 0 | I34: 28163591 | J34: AUTRES | K34: REG02078 | L34: ="408101" -> 408101 | M34: ="001" -> 001 | O34: STDCO | P34: 2 | Q34: 1 | R34: 1
A35: 45716 | B35: SIEGE1902REGUL000053 | C35: SIEGE | D35: REG | E35: REG | F35: PROV PEACEBOXCOM SMS | G35: 1562200 | H35: 0 | I35: 1562200 | J35: SMS | K35: REG02078 | L35: ="408101" -> 408101 | M35: ="001" -> 001 | O35: STDCO | P35: 2 | Q35: 1 | R35: 1
A36: 45716 | B36: SIEGE1902REGUL000053 | C36: SIEGE | D36: REG | E36: REG | F36: KIRUSA MOOV CELEBRITES FEV25 | G36: 246750 | H36: 0 | I36: 246750 | J36: AUTRES | K36: REG02078 | L36: ="408101" -> 408101 | M36: ="001" -> 001 | O36: STDCO | P36: 2 | Q36: 1 | R36: 1
A37: 45716 | B37: SIEGE1902REGUL000184 | C37: SIEGE | D37: REG | E37: REG | F37: PROV SMS BELGACOM FEV25 | G37: 1960104 | H37: 0 | I37: 1960104 | J37: SMS | K37: REG02057 | L37: ="408950" -> 408950 | M37: ="001" -> 001 | O37: STDCO | P37: 2 | Q37: 1 | R37: 1
A38: 45716 | B38: SIEGE1902REGUL000185 | C38: SIEGE | D38: REG | E38: REG | F38: PROV SMS SAPFRANCE FEV25 | G38: 2350792 | H38: 0 | I38: 2350792 | J38: SMS | K38: REG02057-1 | L38: ="408870" -> 408870 | M38: ="001" -> 001 | O38: STDCO | P38: 2 | Q38: 1 | R38: 1
A39: 45716 | B39: SIEGE1902REGUL000189 | C39: SIEGE | D39: REG | E39: REG | F39: PROV RVNU SHARING CRED SECOURS FEV25 | G39: 2180986 | H39: 0 | I39: 2180986 | J39: AUTRES | K39: REG02054 | L39: ="408101" -> 408101 | M39: ="001" -> 001 | O39: STDCO | P39: 2 | Q39: 1 | R39: 1
A40: 45716 | B40: SIEGE1902REGUL000214 | C40: SIEGE | D40: REG | E40: REG | F40: PROV COMVIVA Mars- avr 23&24 MAI JUIN DEC JAN FEV 25 | G40: 819075 | H40: 0 | I40: 819075 | J40: AUTRES | K40: REG002010 | L40: ="408101" -> 408101 | M40: ="001" -> 001 | O40: STDCO | P40: 2 | Q40: 1 | R40: 1

Sheet RECAP
A1: 632200 | B1: 1 | C1: 2 | D1: 3 | E1: 4 | F1: 5 | G1: 6 | H1: 7 | I1: 8 | J1: 9 | K1: 10 | L1: 11 | M1: 12
A2: IMM | B2: =SUMIFS('632200 01 25'!$I:$I,'632200 01 25'!$J:$J,$A2) -> 22956492 | C2: =SUMIFS('632200 02 25'!$I:$I,'632200 02 25'!$J:$J,$A2) -> 8813560
A3: MM | B3: =SUMIFS('632200 01 25'!$I:$I,'632200 01 25'!$J:$J,$A3) -> 0 | C3: =SUMIFS('632200 02 25'!$I:$I,'632200 02 25'!$J:$J,$A3) -> 0
A4: AUTRES | B4: =SUMIFS('632200 01 25'!$I:$I,'632200 01 25'!$J:$J,$A4) -> 472252242 | C4: =SUMIFS('632200 02 25'!$I:$I,'632200 02 25'!$J:$J,$A4) -> 473016966
A5: MAJ | B5: =SUMIFS('632200 01 25'!$I:$I,'632200 01 25'!$J:$J,$A5) -> 0 | C5: =SUMIFS('632200 02 25'!$I:$I,'632200 02 25'!$J:$J,$A5) -> 0
A11: 605731 | B11: 1 | C11: 2 | D11: 3 | E11: 4 | F11: 5 | G11: 6 | H11: 7 | I11: 8 | J11: 9 | K11: 10 | L11: 11 | M11: 12
A12: MM | B12: =SUMIFS('605731 01 25'!$I:$I,'605731 01 25'!$J:$J,$A12) -> 0 | C12: =SUMIFS('605731 02 25'!$I:$I,'605731 02 25'!$J:$J,$A12) -> 0
A13: SMS | B13: =SUMIFS('605731 01 25'!$I:$I,'605731 01 25'!$J:$J,$A13) -> 4889057 | C13: =SUMIFS('605731 02 25'!$I:$I,'605731 02 25'!$J:$J,$A13) -> 5873096
A14: AUTRES | B14: =SUMIFS('605731 01 25'!$I:$I,'605731 01 25'!$J:$J,$A14) -> 31695007 | C14: =SUMIFS('605731 02 25'!$I:$I,'605731 02 25'!$J:$J,$A14) -> 19083352
