Workbook

Sheet Feuil2
A1: ITEM | B1: INTER | C1: MOOV | D1: MTN | E1: SBIN | F1: NON DETERMINE | G1: OPT | H1: Total général
A2: TABLEAU 2 | B2: 1285426.3 | C2: 44153132 | D2: 35569488 | E2: 20345380 | F2: 77090.259 | G2: 25592.098 | H2: =SUM(B2:G2) -> 1.0145611e+08
A3: TABLEAU 1 | B3: 1308461.8 | C3: 50395205 | D3: 37508278 | E3: 20939953 | F3: 78916.975 | G3: 29196.731 | H3: =SUM(B3:G3) -> 1.1026001e+08
A5: Trafic sortant prépayé (Consumer)
A6: vers le fixe | C6: =+G2/10^6 -> 0.025592098
A7: vers l'international | C7: =+B2/10^6 -> 1.2854263
A8: vers Mobile (on net) | C8: =+C2/10^6 -> 44.153132
A9: vers MTN | C9: =(D2+F2)/10^6 -> 35.646578
A10: vers SBIN | C10: =+E2/10^6 -> 20.34538
A11: vers BBCOM, LIBERCOM
A12: Outbound roaming
A15: Business Prepaid
A16: vers le fixe | C16: =G3/10^6-C6 -> 0.0036046327
A17: vers l'international | C17: =B3/10^6-C7 -> 0.023035497
A18: vers Mobile (on net) | C18: =C3/10^6-C8 -> 6.2420734
A19: vers MTN | C19: =(D3+F3)/10^6-C9 -> 1.9406167
A20: vers SBIN | C20: =E3/10^6-C10 -> 0.59457358
A21: vers BBCOM, LIBERCOM
A22: Outbound roaming | C22: =[1]BTI!$C$10 -> 0
A25: Trafic entrant prépayé (Consumer)
A26: du fixe | B26: =[1]BTI!$N$41 -> 116192.24 | C26: =+B26/1000000 -> 0.11619224
A27: de l'international | B27: =[2]Somme!$B$53+[1]BTI!$B$42 -> 1053760.4 | C27: =+B27/1000000 -> 1.0537604 | D27: 88074.413
A28: de MTN | B28: =[1]BTI!$B$38 -> 32166054 | C28: =+B28/1000000 -> 32.166054
A29: de SBIN | B29: =[1]BTI!$B$41-B26 -> 90908268 | C29: =+B29/1000000 -> 90.908268
A30: de BBCOM, LIBERCOM | C30: =+B30/1000000 -> 0
A31: Consumer Postpaid | C31: =+B31/1000000 -> 0
A32: du fixe | B32: =[1]BTI!$N$21 -> 143.73177 | C32: =+B32/1000000 -> 0.00014373177
A33: de l'international | B33: =[2]Somme!$F$53+[1]BTI!$B$22 -> 211.7966 | C33: =+B33/1000000 -> 0.0002117966 | D33: 22.731483
A34: de MTN | B34: =[1]BTI!$B$18 -> 7122.3767 | C34: =+B34/1000000 -> 0.0071223767
A35: de SBIN | B35: =[1]BTI!$B$21-B32 -> 112455.07 | C35: =+B35/1000000 -> 0.11245507
A36: de BBCOM, LIBERCOM | C36: =+B36/1000000 -> 0
A37: Business Postpaid | C37: =+B37/1000000 -> 0
A38: du fixe | B38: =[1]BTI!$N$11 -> 776.51613 | C38: =+B38/1000000 -> 0.00077651613
A39: de l'international | B39: =[2]Somme!$F$34+[1]BTI!$B$12 -> 3271.7261 | C39: =+B39/1000000 -> 0.0032717261 | D39: 443.73611
A40: de MTN | B40: =[1]BTI!$B$8 -> 63595.35 | C40: =+B40/1000000 -> 0.06359535
A41: de SBIN | B41: =[1]BTI!$B$11-B38 -> 607542.62 | C41: =+B41/1000000 -> 0.60754262
A42: de BBCOM, LIBERCOM | C42: =+B42/1000000 -> 0
A43: Business Prepaid | C43: =+B43/1000000 -> 0
A44: du fixe | B44: =[1]BTI!$N$31 -> 9808.6136 | C44: =+B44/1000000 -> 0.0098086136
A45: de l'international | B45: =[2]Somme!$B$34+[1]BTI!$B$32 -> 16320.485 | C45: =+B45/1000000 -> 0.016320485 | D45: 1950.6858
...

Sheet Feuil1
A1: Consumer Postpaid | C1: Stats trafic | D1: poids | E1: trend TBG | H1: SENS | I1: INTER | J1: MOOV | K1: MTN | L1: NON DETERMINE | M1: OPT | N1: SBIN | O1: Total général
A2: vers le fixe | B2: =+C2*D2 -> 1.360382e-06 | C2: =+M2/1000000 -> 5.35e-06 | D2: =+B19/E2 -> 0.25427701 | E2: =SUM(B19,B26) -> 0.00079051722 | F2: =+$G$2*B2 -> 1.4057281e-06 | G2: 1.0333333 | H2: SORTANT | I2: =+I7 -> 7631.7333 | J2: =+J7 -> 105691.33 | K2: =+K7 -> 94064.566 | L2: =+L7 -> 14050.967 | M2: =+M7 -> 5.35 | N2: =+N7 -> 7498.0167 | O2: =SUM(I2:N2) -> 228941.97
A3: vers l'international | B3: =+C3*D3 -> 0.0010616951 | C3: =+I2/1000000 -> 0.0076317333 | D3: =+B20/E3 -> 0.13911585 | E3: =SUM(B20,B27) -> 0.019278573 | F3: =+$G$2*B3 -> 0.0010970849
A4: vers Mobile (on net) | B4: =+C4*D4 -> 0.010367178 | C4: =SUM(J2,L2)/1000000 -> 0.1197423 | D4: =+B21/E4 -> 0.086579077 | E4: =SUM(B21,B28) -> 0.18019305 | F4: =+$G$2*B4 -> 0.01071275
A5: vers MTN | B5: =+C5*D5 -> 0.01188748 | C5: =+K2/1000000 -> 0.094064566 | D5: =+B22/E5 -> 0.12637575 | E5: =SUM(B22,B29) -> 0.16507595 | F5: =+$G$2*B5 -> 0.012283729 | H5: SENS | I5: INTER | J5: MOOV | K5: MTN | L5: NON DETERMINE | M5: OPT | N5: SBIN | O5: Total général
A6: vers SBIN | B6: =+C6*D4 -> 0.00064917136 | C6: =+N2/1000000 -> 0.0074980167 | D6: =+B23/E6 -> #DIV/0! | E6: =SUM(B23,B30) -> 0 | F6: =+$G$2*B6 -> 0.00067081041 | H6: ENTRANT | I6: 2164.3833 | J6: 61819.233 | K6: 27479.467 | L6: 10793.45 | M6: 181.81667 | N6: 6363.1333 | O6: 108957.37
A7: vers BBCOM, LIBERCOM | B7: =+C7*D7 -> #DIV/0! | C7: 0 | D7: =+B24/E7 -> #DIV/0! | E7: =SUM(B24,B31) -> 0 | F7: =+$G$2*B7 -> #DIV/0! | H7: SORTANT | I7: 7631.7333 | J7: 105691.33 | K7: 94064.566 | L7: 14050.967 | M7: 5.35 | N7: 7498.0167 | O7: 228941.97
A8: Business Postpaid | C8: =SUM(C2:C7) -> 0.22894197 | F8: =+$G$2*B8 -> 0 | H8: Total général | I8: 9796.1167 | J8: 167510.57 | K8: 121544.03 | L8: 24844.417 | M8: 187.16667 | N8: 13861.15 | O8: 337899.33
A9: vers le fixe | B9: =C2-B2 -> 3.989618e-06 | F9: =+$G$2*B9 -> 4.1226052e-06
A10: vers l'international | B10: =C3-B3 -> 0.0065700382 | F10: =+$G$2*B10 -> 0.0067890395
A11: vers Mobile (on net) | B11: =C4-B4 -> 0.10937512 | F11: =+$G$2*B11 -> 0.11302096 | I11: SENS | J11: MOOV | K11: MTN | L11: NASUBA | M11: NON DETERMINE | N11: Total général
A12: vers MTN | B12: =C5-B5 -> 0.082177086 | F12: =+$G$2*B12 -> 0.084916323 | H12: =+B4/30*31 -> 0.01071275 | I12: ENTRANT | J12: 112635.08 | K12: 2537.35 | L12: 76.85 | M12: 1009.7333 | N12: 116259.02
A13: vers SBIN | B13: =C6-B6 -> 0.0068488453 | F13: =+$G$2*B13 -> 0.0070771401 | H13: =+B5/30*31 -> 0.012283729 | I13: SORTANT | J13: 51587.517 | K13: 1035.1667 | L13: 30.616667 | M13: 540.43333 | N13: 53193.733
A14: vers BBCOM, LIBERCOM | B14: =C7-B7 -> #DIV/0! | F14: =+$G$2*B14 -> #DIV/0! | H14: =+B6/30*31 -> 0.00067081041 | I14: Total général | J14: 164222.6 | K14: 3572.5167 | L14: 107.46667 | M14: 1550.1667 | N14: 169452.75
H15: =+B7/30*31 -> #DIV/0!
H16: =+B8/30*31 -> 0
H17: =+B9/30*31 -> 4.1226052e-06
A18: Consumer Postpaid | H18: =+B10/30*31 -> 0.0067890395
A19: vers le fixe | B19: 0.00020101036 | H19: =+B11/30*31 -> 0.11302096
A20: vers l'international | B20: 0.0026819551 | H20: =+B12/30*31 -> 0.084916323
A21: vers Mobile (on net) | B21: 0.015600948
A22: vers MTN | B22: 0.020861597
A23: vers SBIN | B23: 0
A24: vers BBCOM, LIBERCOM | B24: 0
A25: Business Postpaid
A26: vers le fixe | B26: 0.00058950686
A27: vers l'international | B27: 0.016596618
A28: vers Mobile (on net) | B28: 0.1645921
A29: vers MTN | B29: 0.14421435
A30: vers SBIN | B30: 0
A31: vers BBCOM, LIBERCOM | B31: 0

Sheet TRAFIC
A1: ITEM | B1: TRAFIC | C1: M*10¨6 | D1: CHECK
A2: Total Trafic sortant | B2: =+B4+B13 -> 155.92179 | C2: =B2*10^6 -> 1.5592179e+08 | D2: =+D4+D13 -> 110.48895
C3: =B3*10^6 -> 0
A4: Trafic sortant prépayé (Consumer) | B4: =SUM(B5:B11) -> 145.00684 | C4: =B4*10^6 -> 1.4500684e+08 | D4: =SUM(D5:D11) -> 101.45611
A5: vers le fixe | B5: 0.031407182 | C5: =B5*10^6 -> 31407.182 | D5: =Feuil2!C6 -> 0.025592098
A6: vers l'international | B6: 1.6410865 | C6: =B6*10^6 -> 1641086.5 | D6: =Feuil2!C7 -> 1.2854263
A7: vers Mobile (on net) | B7: 71.9012 | C7: =B7*10^6 -> 71901200 | D7: =Feuil2!C8 -> 44.153132
A8: vers MTN | B8: 67.215837 | C8: =B8*10^6 -> 67215837 | D8: =Feuil2!C9 -> 35.646578
A9: vers SBIN | B9: 4.2173096 | C9: =B9*10^6 -> 4217309.6 | D9: =Feuil2!C10 -> 20.34538
A10: vers BBCOM, LIBERCOM | C10: =B10*10^6 -> 0
A11: Outbound roaming | C11: =B11*10^6 -> 0
C12: =B12*10^6 -> 0
A13: Trafic sortant postpayé | B13: =+B22+B31+B40 -> 10.914954 | C13: =B13*10^6 -> 10914954 | D13: =+D22+D31+D40 -> 9.0328458
A14: vers le fixe | B14: =+B23+B32+B41 -> 0.004382266 | C14: =B14*10^6 -> 4382.266 | D14: =+D23+D32+D41 -> 0.0036099827
A15: vers l'international | B15: =+B24+B33+B42 -> 0.039062813 | C15: =B15*10^6 -> 39062.813 | D15: =+D24+D33+D42 -> 0.03066723
A16: vers Mobile (on net) | B16: =+B25+B34+B43 -> 8.08459 | C16: =B16*10^6 -> 8084590 | D16: =+D25+D34+D43 -> 6.3618157
A17: vers MTN | B17: =+B26+B35+B44 -> 2.6658573 | C17: =B17*10^6 -> 2665857.3 | D17: =+D26+D35+D44 -> 2.0346813
A18: vers SBIN | B18: =+B27+B36+B45 -> 0.12106122 | C18: =B18*10^6 -> 121061.22 | D18: =+D27+D36+D45 -> 0.6020716
A19: vers BBCOM, LIBERCOM | B19: =+B28+B37+B46 -> 0 | C19: =B19*10^6 -> 0 | D19: =+D28+D37+D46 -> 0
A20: Outbound roaming | B20: =+B29+B38+B47 -> 0 | C20: =B20*10^6 -> 0 | D20: =+D29+D38+D47 -> 0
C21: =B21*10^6 -> 0
A22: Consumer Postpaid | B22: =SUM(B23:B29) -> 0.02735875 | C22: =B22*10^6 -> 27358.75 | D22: =SUM(D23:D29) -> 0.023966885
A23: vers le fixe | B23: 0.00017114538 | C23: =B23*10^6 -> 171.14538 | D23: =Feuil1!B2 -> 1.360382e-06
A24: vers l'international | B24: 0.0015170514 | C24: =B24*10^6 -> 1517.0514 | D24: =Feuil1!B3 -> 0.0010616951
A25: vers Mobile (on net) | B25: 0.010889815 | C25: =B25*10^6 -> 10889.815 | D25: =Feuil1!B4 -> 0.010367178
A26: vers MTN | B26: 0.014433598 | C26: =B26*10^6 -> 14433.598 | D26: =Feuil1!B5 -> 0.01188748
A27: vers SBIN | B27: 0.00034714025 | C27: =B27*10^6 -> 347.14025 | D27: =Feuil1!B6 -> 0.00064917136
A28: vers BBCOM, LIBERCOM | C28: =B28*10^6 -> 0
A29: Outbound roaming | C29: =B29*10^6 -> 0
C30: =B30*10^6 -> 0
A31: Business Postpaid | B31: =SUM(B32:B38) -> 0.22821938 | C31: =B31*10^6 -> 228219.38 | D31: =SUM(D32:D38) -> 0.20497508
A32: vers le fixe | B32: 0.00050192128 | C32: =B32*10^6 -> 501.92128 | D32: =Feuil1!B9 -> 3.989618e-06
A33: vers l'international | B33: 0.0093878986 | C33: =B33*10^6 -> 9387.8986 | D33: =Feuil1!B10 -> 0.0065700382
A34: vers Mobile (on net) | B34: 0.11488902 | C34: =B34*10^6 -> 114889.02 | D34: =Feuil1!B11 -> 0.10937512
A35: vers MTN | B35: 0.099778169 | C35: =B35*10^6 -> 99778.169 | D35: =Feuil1!B12 -> 0.082177086
A36: vers SBIN | B36: 0.0036623764 | C36: =B36*10^6 -> 3662.3764 | D36: =Feuil1!B13 -> 0.0068488453
A37: vers BBCOM, LIBERCOM | C37: =B37*10^6 -> 0
A38: Outbound roaming | C38: =B38*10^6 -> 0
C39: =B39*10^6 -> 0
A40: Business Prepaid | B40: =SUM(B41:B47) -> 10.659375 | C40: =B40*10^6 -> 10659375 | D40: =SUM(D41:D47) -> 8.8039039
...
