Workbook
Name _: #REF!
Name _: #REF!
Name _: #REF!
Name _: #REF!
Name __: #REF!
Name __: #REF!
Name __: #REF!
Name ___________B1: #N/A
Name ___________eng2: #N/A
Name ___________eng3: 'Data Mobile'!___________eng3
Name ___________eng3: #N/A
Name ___________eng3: 'Data Mobile'!___________eng3
Name ___________eng4: #N/A
Name __________B1: #N/A
Name __________eng2: #N/A
Name __________eng3: 'Data Mobile'!__________eng3
Name __________eng3: #N/A
Name __________eng3: 'Data Mobile'!__________eng3
Name __________eng4: #N/A
Name _________eng3: 'Data Mobile'!_________eng3
Name _________eng3: #N/A
Name _________eng3: 'Data Mobile'!_________eng3
Name ________eng3: 'Data Mobile'!________eng3
Name ________eng3: #N/A
Name ________eng3: 'Data Mobile'!________eng3
Name _______eng3: 'Data Mobile'!_______eng3
Name _______eng3: #N/A
Name _______eng3: 'Data Mobile'!_______eng3
Name ______eng3: 'Data Mobile'!______eng3
Name ______eng3: #N/A
Name ______eng3: 'Data Mobile'!______eng3
Name ______FRF4: '[2]FX Rates'!$G$10
Name ______GBP4: '[2]FX Rates'!$G$9
Name _____0: #REF!
Name _____0: #REF!
Name _____0: #REF!
Name _____0: #REF!
Name _____12: #REF!
Name _____12: #REF!
Name _____12: #REF!
Name _____12: #REF!
Name _____14: #REF!
Name _____14: #REF!
Name _____14: #REF!
Name _____14: #REF!
Name _____16: #REF!
Name _____16: #REF!
Name _____16: #REF!
Name _____2: #REF!
Name _____2: #REF!
Name _____2: #REF!
Name _____25: #REF!
Name _____25: #REF!
Name _____25: #REF!
Name _____26: #REF!
Name _____26: #REF!
Name _____26: #REF!
Name _____27: #REF!
Name _____27: #REF!
Name _____27: #REF!

Sheet Cover
E15: MOOV AFRICA BENIN TBG
E17: 45809
A5603: 41743
A5604: 41743
A5605: 41744
A5606: 41744
A5607: 41744
A5608: 41744
A5609: 41744
A5610: 41744
A5611: 41744
A5612: 41744
A5613: 41744
A5614: 41744
A5615: 41744

Sheet P&L conso
A1: P&L consolidé | V1: =+V25+'Opex Consolidés'!V7 | AD1: =+AD25+'Opex Consolidés'!AD7 | AL1: =+AL25+'Opex Consolidés'!AL7 | AU1: #REF! | BC1: 577.07409 | BK1: =+BK25+'Opex Consolidés'!BD7 | BT1: -68804439 | BW1: =BV4 | CB1: =+CB25+'Opex Consolidés'!BU7 | CJ1: =+CJ25+'Opex Consolidés'!CC7 | CR1: =+CR25+'Opex Consolidés'!CR7 | CS1: 17000.499 | CT1: =CT25+'Opex Consolidés'!CT7 | CW1: 16458.089 | CZ1: 26225.79 | DC1: 8378.9625
E3: 0 | G3: 0 | AD3: 0 | CZ3: 0 | DD3: 0
D4: 45658 | J4: 45689 | P4: 45717 | V4: 45748 | AD4: 45778 | AL4: 45809 | AU4: 45839 | BC4: 45870 | BK4: 45901 | BT4: 45931 | CB4: 45962 | CJ4: 45992 | CR4: CUMUL | CZ4: ANNUEL
A5: (En Millions ML) | D5: 2025 Réel | E5: 2025 Budget | F5: Ecart / Budget | G5: 2024 Réel | H5: Evol % | J5: 2025 Réel | K5: 2025 Budget | L5: Ecart / Budget | M5: 2024 Réel | N5: Evol % | P5: 2025 Réel | Q5: 2025 Budget | R5: Ecart / Budget | S5: 2024 Réel | T5: Evol % | V5: 2025 Réel | W5: 2025 Budget | X5: 2025 Actu1 | Y5: Ecart / Budget | Z5: Ecart / Actu1 | AA5: 2024 Réel | AB5: Evol % | AD5: 2025 Réel | AE5: 2025 Budget | AF5: 2025 Actu1 | AG5: Ecart / Budget | AH5: Ecart / Actu1 | AI5: 2024 Réel | AJ5: Evol % | AL5: 2025 Réel | AM5: 2025 Budget | AN5: 2025 Actu1 | AO5: 2025 Actu2 | AP5: Ecart / Budget | AQ5: Ecart / Actu1 | AR5: 2024 Réel | AS5: Evol % | AU5: 2025 Réel | AV5: 2025 Budget | AW5: 2025 Actu2 | AX5: Ecart / Budget | AY5: Ecart / Actu2 | AZ5: 2024 Réel | BA5: Evol % | BC5: 2025 Réel | BD5: 2025 Budget | BE5: 2025 Actu2 | BF5: Ecart / Budget | BG5: Ecart / Actu2 | BH5: 2024 Réel | BI5: Evol % | BK5: 2025 Réel | BL5: 2025 Budget | BM5: 2025 Actu2 | BN5: 2025 Actu3 | BO5: Ecart / Budget | BP5: Ecart / Actu2 | BQ5: 2024 Réel | BR5: Evol % | BT5: 2025 Réel | BU5: 2025 Budget | BV5: 2025 Actu3 | BW5: Ecart / Budget | BX5: Ecart / Actu3 | BY5: 2024 Réel | BZ5: Evol % | CB5: 2025 Réel | CC5: 2025 Budget | CD5: 2025 Actu3 | CE5: Ecart / Budget | CF5: Ecart / Actu3 | CG5: 2024 Réel | CH5: Evol % | CJ5: 2025 Réel | CK5: 2025 Budget | CL5: 2025 Actu3 | CM5: Ecart / Budget | CN5: Ecart / Actu3 | CO5: 2024 Réel | CP5: Evol % | CR5: 2025 Réel | CS5: 2025 Budget | CT5: 2025 Actu3 | CU5: Ecart / Budget | CV5: Ecart / Actu3 | CW5: 2024 Réel | CX5: Evol % | CZ5: 2025 Budget | DA5: 2025 Actu1 | DB5: 2025 Actu2 | DC5: 2025 Actu3 | DD5: 2024 Réel | DE5: Bud / 2024 (%) | DF5: Actu 1 / 2024 (%) | DG5: Actu 2 / 2024 (%) | DH5: Actu3 / 2024 (%)
A7: Chiffre d'affaires | C7: PL1 | D7: 8324.9028 | E7: 9527.0891 | F7: -1202.1863 | G7: 9480.8077 | H7: -0.12192051 | J7: 7599.911 | K7: 8782.1227 | L7: -1182.2117 | M7: 9059.8608 | N7: -0.16114484 | P7: 7943.4924 | Q7: 9473.1389 | R7: -1529.6465 | S7: 9959.7273 | T7: -0.20243877 | V7: 8080.2292 | W7: 9362.5379 | X7: 7876.1248 | Y7: -1282.3087 | Z7: 204.10442 | AA7: 9279.8977 | AB7: -0.12927605 | AD7: 7954.7423 | AE7: 9772.4636 | AF7: 8199.6147 | AG7: -1817.7213 | AH7: -244.87237 | AI7: 9134.1999 | AJ7: -0.12912544 | AL7: 6462.0625 | AM7: 9466.6859 | AN7: 0 | AO7: 0 | AP7: -3004.6234 | AQ7: 6462.0625 | AR7: 8946.7558 | AS7: -0.27772004 | CR7: =+SUMIF($D$5:$CQ$5,CR$5,$D7:$CQ7) | CS7: =+SUMIF($D$5:$CQ$5,CS$5,$D7:$CQ7) | CT7: ='CA Mobile'!CT8 | CU7: =+CR7-CS7 | CV7: =+CR7-CT7 | CW7: =+SUMIF($D$5:$CQ$5,CW$5,$D7:$CQ7) | CX7: =IFERROR(CR7/CW7-1, "-") | CZ7: 114333.76 | DD7: 106192.13 | DE7: =CZ7/DD7-1 | DF7: =DA7/DD7-1 | DG7: =DB7/DD7-1 | DH7: =DC7/DD7-1
A8: Fixe & Internet | C8: PL2 | CR8: =+SUMIF($D$5:$CQ$5,CR$5,$D8:$CQ8) | CS8: =+SUMIF($D$5:$CQ$5,CS$5,$D8:$CQ8) | CU8: =+CR8-CS8 | CV8: =+CR8-CT8 | CW8: =+SUMIF($D$5:$CQ$5,CW$5,$D8:$CQ8) | CX8: =IFERROR(CR8/CW8-1, "-")
A9: Mobile | C9: PL3 | D9: 8324.9028 | E9: 9527.0891 | F9: -1202.1863 | G9: 9480.8077 | H9: -0.12192051 | J9: 7599.911 | K9: 8782.1227 | L9: -1182.2117 | M9: 9059.8608 | N9: -0.16114484 | P9: 7943.4924 | Q9: 9473.1389 | R9: -1529.6465 | S9: 9959.7273 | T9: -0.20243877 | V9: 8080.2292 | W9: 9362.5379 | X9: 7876.1248 | Y9: -1282.3087 | Z9: 204.10442 | AA9: 9279.8977 | AB9: -0.12927605 | AD9: 7954.7423 | AE9: 9772.4636 | AF9: 8199.6147 | AG9: -1817.7213 | AH9: -244.87237 | AI9: 9134.1999 | AJ9: -0.12912544 | AL9: 6462.0625 | AM9: 9466.6859 | AN9: 8095.1472 | AO9: 0 | AP9: -3004.6234 | AQ9: -1633.0847 | AR9: 8946.7558 | AS9: -0.27772004 | CR9: =+SUMIF($D$5:$CQ$5,CR$5,$D9:$CQ9) | CS9: =+SUMIF($D$5:$CQ$5,CS$5,$D9:$CQ9) | CT9: =CT10 | CU9: =+CR9-CS9 | CV9: =+CR9-CT9 | CW9: =+SUMIF($D$5:$CQ$5,CW$5,$D9:$CQ9) | CX9: =IFERROR(CR9/CW9-1, "-") | CZ9: 114333.76 | DA9: 100883.84 | DD9: 106192.13 | DE9: =CZ9/DD9-1 | DG9: =DB9/DD9-1 | DH9: =DC9/DD9-1
A10: Intercompagnie Mobile | C10: PL4 | D10: 8324.9028 | E10: 9527.0891 | F10: -1202.1863 | G10: 9480.8077 | H10: -0.12192051 | J10: 7599.911 | K10: 8782.1227 | L10: -1182.2117 | M10: 9059.8608 | N10: -0.16114484 | P10: 7943.4924 | Q10: 9473.1389 | R10: -1529.6465 | S10: 9959.7273 | T10: -0.20243877 | V10: 8080.2292 | W10: 9362.5379 | X10: 7876.1248 | Y10: -1282.3087 | Z10: 204.10442 | AA10: 9279.8977 | AB10: -0.12927605 | AD10: 7954.7423 | AE10: 9772.4636 | AF10: 8199.6147 | AG10: -1817.7213 | AH10: -244.87237 | AI10: 9134.1999 | AJ10: -0.12912544 | AL10: 6462.0625 | AM10: 9466.6859 | AN10: 8095.1472 | AO10: 0 | AP10: -3004.6234 | AQ10: -1633.0847 | AR10: 8946.7558 | AS10: -0.27772004 | CR10: =+SUMIF($D$5:$CQ$5,CR$5,$D10:$CQ10) | CS10: =+SUMIF($D$5:$CQ$5,CS$5,$D10:$CQ10) | CT10: ='CA Mobile'!CT8 | CU10: =+CR10-CS10 | CV10: =+CR10-CT10 | CW10: =+SUMIF($D$5:$CQ$5,CW$5,$D10:$CQ10) | CX10: =IFERROR(CR10/CW10-1, "-") | CZ10: 114333.76 | DA10: 100883.84 | DD10: 106192.13 | DE10: =CZ10/DD10-1 | DF10: =DA10/DD10-1 | DG10: =DB10/DD10-1 | DH10: =DC10/DD10-1
C11: PL5 | CR11: =+SUMIF($D$5:$CQ$5,CR$5,$D11:$CQ11) | CS11: =+SUMIF($D$5:$CQ$5,CS$5,$D11:$CQ11) | CT11: =+SUMIF($D$5:$CP$5,CT$5,$D11:$CP11)+SUMIF($D$5:$BI$5,CR$5,$D11:$BI11) | CU11: =+CR11-CS11 | CV11: =+CR11-CT11 | CW11: =+SUMIF($D$5:$CQ$5,CW$5,$D11:$CQ11) | CX11: =IFERROR(CR11/CW11-1, "-")
A12: Intercompagnie | C12: PL6 | CR12: =+SUMIF($D$5:$CQ$5,CR$5,$D12:$CQ12) | CS12: =+SUMIF($D$5:$CQ$5,CS$5,$D12:$CQ12) | CT12: =+SUMIF($D$5:$CP$5,CT$5,$D12:$CP12)+SUMIF($D$5:$BI$5,CR$5,$D12:$BI12) | CU12: =+CR12-CS12 | CV12: =+CR12-CT12 | CW12: =+SUMIF($D$5:$CQ$5,CW$5,$D12:$CQ12) | CX12: =IFERROR(CR12/CW12-1, "-") | DE12: =CZ12/DD12-1
A13: dont Intercompagnie hors trafic | C13: PL7 | CR13: =+SUMIF($D$5:$CQ$5,CR$5,$D13:$CQ13) | CS13: =+SUMIF($D$5:$CQ$5,CS$5,$D13:$CQ13) | CT13: =+SUMIF($D$5:$CP$5,CT$5,$D13:$CP13)+SUMIF($D$5:$BI$5,CR$5,$D13:$BI13) | CU13: =+CR13-CS13 | CV13: =+CR13-CT13 | CW13: =+SUMIF($D$5:$CQ$5,CW$5,$D13:$CQ13) | CX13: =IFERROR(CR13/CW13-1, "-") | DE13: =CZ13/DD13-1
C14: PL8 | CR14: =+SUMIF($D$5:$CQ$5,CR$5,$D14:$CQ14) | CS14: =+SUMIF($D$5:$CQ$5,CS$5,$D14:$CQ14) | CT14: =+SUMIF($D$5:$CP$5,CT$5,$D14:$CP14)+SUMIF($D$5:$BI$5,CR$5,$D14:$BI14) | CU14: =+CR14-CS14 | CV14: =+CR14-CT14 | CW14: =+SUMIF($D$5:$CQ$5,CW$5,$D14:$CQ14) | CX14: =IFERROR(CR14/CW14-1, "-") | DE14: =CZ14/DD14-1
A15: Coût des ventes | C15: PL9 | D15: -1407.8713 | E15: -1517.7256 | F15: 109.85439 | G15: -1387.0909 | H15: 0.014981231 | J15: -1367.514 | K15: -1459.5803 | L15: 92.066302 | M15: -1472.3759 | N15: -0.071219506 | P15: -1517.8719 | Q15: -1580.7997 | R15: 62.927761 | S15: -1642.8287 | T15: -0.076061964 | V15: -1545.0213 | W15: -1545.981 | X15: -1371.157 | Y15: 0.95971407 | Z15: -173.86429 | AA15: -1449.7183 | AB15: 0.065738969 | AD15: -1332.1608 | AE15: -1578.2509 | AF15: -1420.3445 | AG15: 246.09008 | AH15: 88.18369 | AI15: -1621.855 | AJ15: -0.17861903 | AL15: -1275.3912 | AM15: -1551.4919 | AN15: -1413.2652 | AO15: 0 | AP15: 276.10074 | AQ15: 137.87398 | AR15: -1587.1442 | AS15: -0.19642385 | CR15: =+SUMIF($D$5:$CQ$5,CR$5,$D15:$CQ15) | CS15: =+SUMIF($D$5:$CQ$5,CS$5,$D15:$CQ15) | CT15: =+CT16+CT17 | CU15: =+CR15-CS15 | CV15: =+CR15-CT15 | CW15: =+SUMIF($D$5:$CQ$5,CW$5,$D15:$CQ15) | CX15: =IFERROR(CR15/CW15-1, "-") | CZ15: -18651.46 | DA15: -17158.455 | DD15: -17784.539 | DE15: =(CZ15/DD15-1) | DF15: =DA15/DD15-1 | DG15: =DB15/DD15-1 | DH15: =DC15/DD15-1
A16: Fixe & Internet | C16: PL10 | CR16: =+SUMIF($D$5:$CQ$5,CR$5,$D16:$CQ16) | CS16: =+SUMIF($D$5:$CQ$5,CS$5,$D16:$CQ16) | CT16: =+SUMIF($D$5:$CP$5,CT$5,$D16:$CP16)+SUMIF($D$5:$BI$5,CR$5,$D16:$BI16) | CU16: =+CR16-CS16 | CV16: =+CR16-CT16 | CW16: =+SUMIF($D$5:$CQ$5,CW$5,$D16:$CQ16) | CX16: =IFERROR(CR16/CW16-1, "-") | DE16: =CZ16/DD16-1
A17: Mobile | C17: PL11 | D17: -1407.8713 | E17: -1517.7256 | F17: 109.85439 | G17: -1387.0909 | H17: 0.014981231 | J17: -1367.514 | K17: -1459.5803 | L17: 92.066302 | M17: -1472.3759 | N17: -0.071219506 | P17: -1517.8719 | Q17: -1580.7997 | R17: 62.927761 | S17: -1642.8287 | T17: -0.076061964 | V17: -1545.0213 | W17: -1545.981 | X17: -1371.157 | Y17: 0.95971407 | Z17: -173.86429 | AA17: -1449.7183 | AB17: 0.065738969 | AD17: -1332.1608 | AE17: -1578.2509 | AF17: -1420.3445 | AG17: 246.09008 | AH17: 88.18369 | AI17: -1621.855 | AJ17: -0.17861903 | AL17: -1275.3912 | AM17: -1551.4919 | AN17: -1413.2652 | AO17: 0 | AP17: 276.10074 | AQ17: 137.87398 | AR17: -1587.1442 | AS17: -0.19642385 | CR17: =+SUMIF($D$5:$CQ$5,CR$5,$D17:$CQ17) | CS17: =+SUMIF($D$5:$CQ$5,CS$5,$D17:$CQ17) | CT17: =+CT18 | CU17: =+CR17-CS17 | CV17: =+CR17-CT17 | CW17: =+SUMIF($D$5:$CQ$5,CW$5,$D17:$CQ17) | CX17: =IFERROR(CR17/CW17-1, "-") | CZ17: -18651.46 | DA17: -17158.455 | DD17: -17784.539 | DE17: =(CZ17/DD17-1) | DF17: =DA17/DD17-1 | DG17: =DB17/DD17-1 | DH17: =DC17/DD17-1
A18: Intercompagnie Mobile | C18: PL12 | D18: -1407.8713 | E18: -1517.7256 | F18: 109.85439 | G18: -1387.0909 | H18: 0.014981231 | J18: -1367.514 | K18: -1459.5803 | L18: 92.066302 | M18: -1472.3759 | N18: -0.071219506 | P18: -1517.8719 | Q18: -1580.7997 | R18: 62.927761 | S18: -1642.8287 | T18: -0.076061964 | V18: -1545.0213 | W18: -1545.981 | X18: -1371.157 | Y18: 0.95971407 | Z18: -173.86429 | AA18: -1449.7183 | AB18: 0.065738969 | AD18: -1332.1608 | AE18: -1578.2509 | AF18: -1420.3445 | AG18: 246.09008 | AH18: 88.18369 | AI18: -1621.855 | AJ18: -0.17861903 | AL18: -1275.3912 | AM18: -1551.4919 | AN18: -1413.2652 | AO18: 0 | AP18: 276.10074 | AQ18: 137.87398 | AR18: -1587.1442 | AS18: -0.19642385 | CR18: =+SUMIF($D$5:$CQ$5,CR$5,$D18:$CQ18) | CS18: =+SUMIF($D$5:$CQ$5,CS$5,$D18:$CQ18) | CT18: ='Marge Mobile'!CT58 | CU18: =+CR18-CS18 | CV18: =+CR18-CT18 | CW18: =+SUMIF($D$5:$CQ$5,CW$5,$D18:$CQ18) | CX18: =IFERROR(CR18/CW18-1, "-") | CZ18: -18651.46 | DA18: -17158.455 | DD18: -17784.539 | DE18: =(CZ18/DD18-1) | DF18: =DA18/DD18-1 | DG18: =DB18/DD18-1 | DH18: =DC18/DD18-1
C19: PL13 | CS19: =+SUMIF($D$5:$CQ$5,CS$5,$D19:$CQ19) | CT19: =+SUMIF($D$5:$CP$5,CT$5,$D19:$CX19)+SUMIF($D$5:$AJ$5,CR$5,$D19:$AJ19) | CU19: =+CR19-CS19 | CV19: =+CR19-CT19 | CW19: =+SUMIF($D$5:$CQ$5,CW$5,$D19:$CQ19) | CX19: =IFERROR(CR19/CW19-1, "-")
A20: Marge Brute | C20: PL14 | D20: 6917.0315 | E20: 8009.3634 | F20: -1092.3319 | G20: 8093.7168 | H20: -0.14538256 | J20: 6232.397 | K20: 7322.5424 | L20: -1090.1454 | M20: 7587.485 | N20: -0.17859514 | P20: 6425.6205 | Q20: 7892.3393 | R20: -1466.7188 | S20: 8316.8986 | T20: -0.22740185 | V20: 6535.2079 | W20: 7816.5569 | X20: 6504.9678 | Y20: -1281.349 | Z20: 30.240132 | AA20: 7830.1794 | AB20: -0.1653821 | AD20: 6622.5815 | AE20: 8194.2127 | AF20: 6779.2702 | AG20: -1571.6312 | AH20: -156.68868 | AI20: 7512.345 | AJ20: -0.11844018 | AL20: 5186.6713 | AM20: 7915.194 | AN20: 6681.882 | AO20: 0 | AP20: -2728.5227 | AQ20: -1495.2107 | AR20: 7359.6117 | AS20: -0.29525204 | CR20: =+SUMIF($D$5:$CQ$5,CR$5,$D20:$CQ20) | CS20: =+SUMIF($D$5:$CQ$5,CS$5,$D20:$CQ20) | CT20: =+CT7+CT15 | CU20: =+CR20-CS20 | CV20: =+CR20-CT20 | CW20: =+SUMIF($D$5:$CQ$5,CW$5,$D20:$CQ20) | CX20: =IFERROR(CR20/CW20-1, "-") | CZ20: 95682.303 | DA20: 83725.385 | DD20: 88407.592 | DE20: =CZ20/DD20-1 | DF20: =DA20/DD20-1 | DG20: =DB20/DD20-1 | DH20: =DC20/DD20-1
A21: % CA | C21: PL15 | D21: 0.83088436 | E21: 0.84069366 | F21: -0.0098093041 | G21: 0.85369486 | H21: -0.00026719731 | J21: 0.82006184 | K21: 0.83380097 | L21: -0.013739126 | M21: 0.83748361 | N21: -0.00020802519 | P21: 0.8089163 | Q21: 0.83312821 | R21: -0.024211907 | S21: 0.83505285 | T21: -0.00031299269 | V21: 0.80878992 | W21: 0.83487586 | X21: 0.82590969 | Y21: -0.026085944 | Z21: -0.017119772 | AA21: 0.84377863 | AB21: -0.00041466701 | AD21: 0.8325325 | AE21: 0.8385002 | AF21: 0.82677911 | AG21: -0.0059677032 | AH21: 0.0057533832 | AI21: 0.82244148 | AJ21: 0.00012269582 | AL21: 0.80263404 | AM21: 0.83611034 | AN21: 0.0082541822 | AO21: 0 | AP21: -0.033476304 | AQ21: 0.79437985 | AR21: 0.82260115 | AS21: -0.00024273147 | CR21: =+CR20/CR7 | CS21: =+CS20/CS7 | CT21: =+CT20/CT7 | CU21: =+(CR21-CS21) | CV21: =+(CR21-CT21) | CW21: =+CW20/CW7 | CX21: =IFERROR(CR21/CW21-1, "-") | CZ21: 0.83686831 | DA21: 0.008299187 | DD21: 9.9825998 | DE21: =+(CZ21-DD21) | DF21: =DA21/DD21-1 | DG21: =DB21/DD21-1 | DH21: =DC21/DD21-1
A22: Fixe & Internet | C22: PL16 | CR22: =+CJ22 | CS22: =+#REF! | CT22: =IF(CS$4<=Cover!$E$17,INDEX(#REF!,MATCH($C22,#REF!,0),7),0) | CU22: =+CR22-CS22 | CV22: =+CR22-CT22 | CW22: =+#REF! | CX22: =IFERROR(CR22/CW22-1, "-") | DE22: =CZ22/DD22-1
A23: Mobile | C23: PL17 | D23: 6917.0315 | E23: 8009.3634 | F23: -1092.3319 | G23: 8093.7168 | H23: -0.14538256 | J23: 6232.397 | K23: 7322.5424 | L23: -1090.1454 | M23: 7587.485 | N23: -0.17859514 | P23: 6425.6205 | Q23: 7892.3393 | R23: -1466.7188 | S23: 8316.8986 | T23: -0.22740185 | V23: 6535.2079 | W23: 7816.5569 | X23: 6504.9678 | Y23: -1281.349 | Z23: 30.240132 | AA23: 7830.1794 | AB23: -0.1653821 | AD23: 6622.5815 | AE23: 8194.2127 | AF23: 6779.2702 | AG23: -1571.6312 | AH23: -156.68868 | AI23: 7512.345 | AJ23: -0.11844018 | AL23: 5186.6713 | AM23: 7915.194 | AN23: 6681.882 | AO23: 0 | AP23: -2728.5227 | AQ23: -1495.2107 | AR23: 7359.6117 | AS23: -0.29525204 | CR23: =+SUMIF($D$5:$CQ$5,CR$5,$D23:$CQ23) | CS23: =+SUMIF($D$5:$CQ$5,CS$5,$D23:$CQ23) | CT23: =+CT9+CT17 | CU23: =+CR23-CS23 | CV23: =+CR23-CT23 | CW23: =+SUMIF($D$5:$CQ$5,CW$5,$D23:$CQ23) | CX23: =IFERROR(CR23/CW23-1, "-") | CZ23: 95682.303 | DA23: 83725.385 | DD23: 88407.592 | DE23: =(CZ23/DD23-1) | DF23: =DA23/DD23-1 | DG23: =DB23/DD23-1 | DH23: =DC23/DD23-1
C24: PL18 | CR24: =+SUMIF($D$5:$CQ$5,CR$5,$D24:$CQ24) | CS24: =+SUMIF($D$5:$CQ$5,CS$5,$D24:$CQ24) | CT24: =+SUMIF($D$5:$CP$5,CT$5,$D24:$CX24)+SUMIF($D$5:$AJ$5,CR$5,$D24:$AJ24) | CU24: =+CR24-CS24 | CV24: =+CR24-CT24 | CW24: =+SUMIF($D$5:$CQ$5,CW$5,$D24:$CQ24) | CX24: =IFERROR(CR24/CW24-1, "-")
A25: Coûts opérationnels | C25: PL19 | D25: -5023.3945 | E25: -5752.8634 | F25: 729.46896 | G25: -5774.0655 | H25: -0.13000736 | J25: -5233.5165 | K25: -5412.0079 | L25: 178.49134 | M25: -5467.9109 | N25: -0.042867268 | P25: -5306.2354 | Q25: -5658.8042 | R25: 352.56882 | S25: -5318.9236 | T25: -0.0023854885 | V25: -5421.9008 | W25: -5772.0206 | X25: -5383.448 | Y25: 350.11983 | Z25: -38.452731 | AA25: -5458.7716 | AB25: -0.0067544161 | AD25: -5302.1763 | AE25: -5682.373 | AF25: -5325.1097 | AG25: 380.19665 | AH25: 22.93341 | AI25: -5565.8537 | AJ25: -0.047374108 | AL25: -5739.4271 | AM25: -5580.6859 | AN25: -5222.0484 | AO25: 0 | AP25: -158.74112 | AQ25: -517.37863 | AR25: -5075.041 | AS25: 0.13091246 | CR25: =+SUMIF($D$5:$CQ$5,CR$5,$D25:$CQ25) | CS25: =+SUMIF($D$5:$CQ$5,CS$5,$D25:$CQ25) | CT25: =+SUMIF($D$5:$CP$5,CT$5,$D25:$CP25)+SUMIF($D$5:$BI$5,CR$5,$D25:$BI25) | CU25: =+CR25-CS25 | CV25: =+CR25-CT25 | CW25: =+SUMIF($D$5:$CQ$5,CW$5,$D25:$CQ25) | CX25: =IFERROR(CR25/CW25-1, "-") | CZ25: -67535.531 | DA25: -63800.274 | DD25: -66696.264 | DE25: =CZ25/DD25-1 | DF25: =DA25/DD25-1 | DG25: =DB25/DD25-1 | DH25: =DC25/DD25-1
A26: Fixe & Internet | C26: PL20 | CR26: =+SUMIF($D$5:$CQ$5,CR$5,$D26:$CQ26) | CS26: =+SUMIF($D$5:$CQ$5,CS$5,$D26:$CQ26) | CT26: =+SUMIF($D$5:$CP$5,CT$5,$D26:$CP26)+SUMIF($D$5:$BI$5,CR$5,$D26:$BI26) | CU26: =+CR26-CS26 | CV26: =+CR26-CT26 | CW26: =+SUMIF($D$5:$CQ$5,CW$5,$D26:$CQ26) | CX26: =IFERROR(CR26/CW26-1, "-") | DE26: =CZ26/DD26-1
A27: Intercompagnie Fixe & Internet | C27: PL21 | CR27: =+SUMIF($D$5:$CQ$5,CR$5,$D27:$CQ27) | CS27: =+SUMIF($D$5:$CQ$5,CS$5,$D27:$CQ27) | CT27: =+SUMIF($D$5:$CP$5,CT$5,$D27:$CP27)+SUMIF($D$5:$BI$5,CR$5,$D27:$BI27) | CU27: =+CR27-CS27 | CV27: =+CR27-CT27 | CW27: =+SUMIF($D$5:$CQ$5,CW$5,$D27:$CQ27) | CX27: =IFERROR(CR27/CW27-1, "-") | DE27: =CZ27/DD27-1
A28: Mobile | C28: PL22 | D28: -5023.3945 | E28: -5752.8634 | F28: 729.46896 | G28: -5774.0655 | H28: -0.13000736 | J28: -5233.5165 | K28: -5412.0079 | L28: 178.49134 | M28: -5467.9109 | N28: -0.042867268 | P28: -5306.2354 | Q28: -5658.8042 | R28: 352.56882 | S28: -5318.9236 | T28: -0.0023854885 | V28: -5421.9008 | W28: -5772.0206 | X28: -5383.448 | Y28: 350.11983 | Z28: -38.452731 | AA28: -5458.7716 | AB28: -0.0067544161 | AD28: -5302.1763 | AE28: -5682.373 | AF28: -5325.1097 | AG28: 380.19665 | AH28: 22.93341 | AI28: -5565.8537 | AJ28: -0.047374108 | AL28: -5739.4271 | AM28: -5580.6859 | AN28: -5222.0484 | AO28: 0 | AP28: -158.74112 | AQ28: -517.37863 | AR28: -5075.041 | AS28: 0.13091246 | CR28: =+SUMIF($D$5:$CQ$5,CR$5,$D28:$CQ28) | CS28: =+SUMIF($D$5:$CQ$5,CS$5,$D28:$CQ28) | CT28: =+CT29 | CU28: =+CR28-CS28 | CV28: =+CR28-CT28 | CW28: =+SUMIF($D$5:$CQ$5,CW$5,$D28:$CQ28) | CX28: =IFERROR(CR28/CW28-1, "-") | CZ28: -67535.531 | DA28: -63800.274 | DD28: -66696.264 | DE28: =CZ28/DD28-1 | DF28: =DA28/DD28-1 | DG28: =DB28/DD28-1 | DH28: =DC28/DD28-1
A29: Intercompagnie Mobile | C29: PL23 | D29: -5023.3945 | E29: -5752.8634 | F29: 729.46896 | G29: -5774.0655 | H29: -0.13000736 | J29: -5233.5165 | K29: -5412.0079 | L29: 178.49134 | M29: -5467.9109 | N29: -0.042867268 | P29: -5306.2354 | Q29: -5658.8042 | R29: 352.56882 | S29: -5318.9236 | T29: -0.0023854885 | V29: -5421.9008 | W29: -5772.0206 | X29: -5383.448 | Y29: 350.11983 | Z29: -38.452731 | AA29: -5458.7716 | AB29: -0.0067544161 | AD29: -5302.1763 | AE29: -5682.373 | AF29: -5325.1097 | AG29: 380.19665 | AH29: 22.93341 | AI29: -5565.8537 | AJ29: -0.047374108 | AL29: -5739.4271 | AM29: -5580.6859 | AN29: -5222.0484 | AO29: 0 | AP29: -158.74112 | AQ29: -517.37863 | AR29: -5075.041 | AS29: 0.13091246 | CR29: =+SUMIF($D$5:$CQ$5,CR$5,$D29:$CQ29) | CS29: =+SUMIF($D$5:$CQ$5,CS$5,$D29:$CQ29) | CT29: =-'Opex Consolidés'!CT7 | CU29: =+CR29-CS29 | CV29: =+CR29-CT29 | CW29: =+SUMIF($D$5:$CQ$5,CW$5,$D29:$CQ29) | CX29: =IFERROR(CR29/CW29-1, "-") | CZ29: -67535.531 | DA29: -63800.274 | DD29: -66696.264 | DE29: =CZ29/DD29-1 | DF29: =DA29/DD29-1 | DH29: =DC29/DD29-1
C30: PL24 | CX30: =IFERROR(CR30/CW30-1, "-")
A31: EBITDA | C31: PL25 | D31: 1893.637 | E31: 2256.5 | F31: -362.86294 | G31: 2319.6513 | H31: -0.18365444 | J31: 998.88051 | K31: 1910.5345 | L31: -911.65403 | M31: 2119.574 | N31: -0.52873526 | P31: 1119.3851 | Q31: 2233.5351 | R31: -1114.15 | S31: 2997.975 | T31: -0.62661959 | V31: 1113.3071 | W31: 2044.5363 | X31: 1121.5197 | Y31: -931.22918 | Z31: -8.2125987 | AA31: 2371.4079 | AB31: -0.53052903 | AD31: 1320.4052 | AE31: 2511.8397 | AF31: 1454.1604 | AG31: -1191.4346 | AH31: -133.75527 | AI31: 1946.4913 | AJ31: -0.32164856 | AL31: -552.75577 | AM31: 2334.508 | AN31: 1459.8336 | AO31: 0 | AP31: -2887.2638 | AQ31: -2012.5894 | AR31: 2284.5707 | AS31: -1.2419517 | CR31: =+SUMIF($D$5:$CQ$5,CR$5,$D31:$CQ31) | CS31: =+SUMIF($D$5:$CQ$5,CS$5,$D31:$CQ31) | CT31: =+CT20+CT25 | CU31: =+CR31-CS31 | CV31: =+CR31-CT31 | CW31: =+SUMIF($D$5:$CQ$5,CW$5,$D31:$CQ31) | CX31: =IFERROR(CR31/CW31-1, "-") | CZ31: 28146.773 | DA31: 19925.11 | DD31: 21711.328 | DE31: =CZ31/DD31-1 | DF31: =DA31/DD31-1 | DG31: =DB31/DD31-1 | DH31: =DC31/DD31-1
A32: % CA | C32: PL26 | D32: 0.22746656 | E32: 0.23685094 | F32: -0.0093843725 | G32: 0.24466811 | H32: -0.00070305628 | J32: 0.13143318 | K32: 0.21754815 | L32: -0.086114965 | M32: 0.23395216 | N32: -0.0043820488 | P32: 0.14091851 | Q32: 0.23577561 | R32: -0.094857097 | S32: 0.30100975 | T32: -0.0053184735 | V32: 0.13778163 | W32: 0.21837416 | X32: 0.14239487 | Y32: -0.080592528 | Z32: -0.004613238 | AA32: 0.25554246 | AB32: -0.0046082685 | AD32: 0.16598968 | AE32: 0.25703239 | AF32: 0.17734497 | AG32: -0.091042711 | AH32: -0.011355288 | AI32: 0.21309926 | AJ32: -0.0022106871 | AL32: -0.085538598 | AM32: 0.24660246 | AN32: 0.0018033441 | AO32: 0 | AP32: -0.33214106 | AQ32: -0.087341943 | AR32: 0.25535186 | AS32: -0.013349833 | CR32: =+CR31/CR7 | CS32: =+CS31/CS7 | CT32: =+CT31/CT7 | CU32: =+(CR32-CS32) | CV32: =+(CR32-CT32) | CW32: =+CW31/CW7 | CX32: =IFERROR(CR32/CW32-1, "-") | CZ32: 0.24618076 | DA32: 0.0019750547 | DD32: 2.4332127 | DE32: =(CZ32-DD32) | DF32: =DA32/DD32-1 | DG32: =DB32/DD32-1 | DH32: =DC32/DD32-1
A33: Fixe & Internet | C33: PL27 | CR33: =+CJ33 | CS33: =+#REF! | CU33: =+CR33-CS33 | CV33: =+CR33-CT33 | CW33: =+#REF! | CX33: =IFERROR(CR33/CW33-1, "-") | DE33: =CZ33/DD33-1
A34: Mobile | C34: PL28 | D34: 1893.637 | E34: 2256.5 | F34: -362.86294 | G34: 2319.6513 | H34: -0.18365444 | J34: 998.88051 | K34: 1910.5345 | L34: -911.65403 | M34: 2119.574 | N34: -0.52873526 | P34: 1119.3851 | Q34: 2233.5351 | R34: -1114.15 | S34: 2997.975 | T34: -0.62661959 | V34: 1113.3071 | W34: 2044.5363 | X34: 1121.5197 | Y34: -931.22918 | Z34: -8.2125987 | AA34: 2371.4079 | AB34: -0.53052903 | AD34: 1320.4052 | AE34: 2511.8397 | AF34: 1454.1604 | AG34: -1191.4346 | AH34: -133.75527 | AI34: 1946.4913 | AJ34: -0.32164856 | AL34: -552.75577 | AM34: 2334.508 | AN34: 1459.8336 | AO34: 0 | AP34: -2887.2638 | AQ34: -2012.5894 | AR34: 2284.5707 | AS34: -1.2419517 | CR34: =+SUMIF($D$5:$CQ$5,CR$5,$D34:$CQ34) | CS34: =+SUMIF($D$5:$CQ$5,CS$5,$D34:$CQ34) | CT34: =+CT23+CT28 | CU34: =+CR34-CS34 | CV34: =+CR34-CT34 | CW34: =+SUMIF($D$5:$CQ$5,CW$5,$D34:$CQ34) | CX34: =IFERROR(CR34/CW34-1, "-") | CZ34: 28146.773 | DA34: 19925.11 | DD34: 21711.328 | DE34: =CZ34/DD34-1 | DF34: =DA34/DD34-1 | DG34: =DB34/DD34-1 | DH34: =DC34/DD34-1
C35: PL29 | CR35: =+SUMIF($D$5:$CQ$5,CR$5,$D35:$CQ35) | CS35: =+SUMIF($D$5:$CQ$5,CS$5,$D35:$CQ35) | CT35: =+SUMIF($D$5:$CP$5,CT$5,$D35:$CX35)+SUMIF($D$5:$AJ$5,CR$5,$D35:$AJ35) | CU35: =+CR35-CS35 | CV35: =+CR35-CT35 | CW35: =+SUMIF($D$5:$CQ$5,CW$5,$D35:$CQ35) | CX35: =IFERROR(CR35/CW35-1, "-")
A36: Amortissements et déprec. Courant | C36: PL30 | D36: -1741.8583 | E36: -1755 | F36: 13.141733 | G36: -1626.288 | H36: 0.071063857 | J36: -1754.9732 | K36: -1774.631 | L36: 19.657768 | M36: -1623.0309 | N36: 0.081293773 | P36: -1779.8004 | Q36: -1774.631 | R36: -5.1694124 | S36: -1961.7764 | T36: -0.092760822 | V36: -1775.0229 | W36: -1732.131 | X36: -1732.131 | Y36: -42.891929 | Z36: -42.891929 | AA36: -1803.3618 | AB36: -0.015714472 | AD36: -1806.0059 | AE36: -1754.9927 | AF36: -1754.9927 | AG36: -51.013161 | AH36: -51.013161 | AI36: -1809.4697 | AJ36: -0.0019142878 | AL36: -1817.6639 | AM36: -1752.6683 | AN36: -1752.6683 | AO36: 0 | AP36: -64.995655 | AQ36: -64.995655 | AR36: -1801.8079 | AS36: 0.0088000375 | CR36: =+SUMIF($D$5:$CQ$5,CR$5,$D36:$CQ36) | CS36: =+SUMIF($D$5:$CQ$5,CS$5,$D36:$CQ36) | CT36: =+SUMIF($D$5:$CP$5,CT$5,$D36:$CP36)+SUMIF($D$5:$BI$5,CR$5,$D36:$BI36) | CU36: =+CR36-CS36 | CV36: =+CR36-CT36 | CW36: =+SUMIF($D$5:$CQ$5,CW$5,$D36:$CQ36) | CX36: =IFERROR(CR36/CW36-1, "-") | CZ36: -21086.659 | DA36: -21305.834 | DD36: -20598.107 | DE36: =CZ36/DD36-1 | DF36: =DA36/DD36-1 | DG36: =DB36/DD36-1 | DH36: =DC36/DD36-1
A37: Dotations (Amo. et Pv NC) | C37: PL31 | CR37: =+SUMIF($D$5:$CQ$5,CR$5,$D37:$CQ37) | CS37: =+SUMIF($D$5:$CQ$5,CS$5,$D37:$CQ37) | CT37: =+SUMIF($D$5:$CP$5,CT$5,$D37:$CP37)+SUMIF($D$5:$BI$5,CR$5,$D37:$BI37) | CU37: =+CR37-CS37 | CV37: =+CR37-CT37 | CW37: =+SUMIF($D$5:$CQ$5,CW$5,$D37:$CQ37) | CX37: =IFERROR(CR37/CW37-1, "-")
A38: Autres non courant | C38: PL32 | CR38: =+SUMIF($D$5:$CQ$5,CR$5,$D38:$CQ38) | CS38: =+SUMIF($D$5:$CQ$5,CS$5,$D38:$CQ38) | CT38: =+SUMIF($D$5:$CP$5,CT$5,$D38:$CP38)+SUMIF($D$5:$BI$5,CR$5,$D38:$BI38) | CU38: =+CR38-CS38 | CV38: =+CR38-CT38 | CW38: =+SUMIF($D$5:$CQ$5,CW$5,$D38:$CQ38) | CX38: =IFERROR(CR38/CW38-1, "-")
A39: +/- value de cession d'immob. | C39: PL33 | CR39: =+SUMIF($D$5:$CQ$5,CR$5,$D39:$CQ39) | CS39: =+SUMIF($D$5:$CQ$5,CS$5,$D39:$CQ39) | CT39: =+SUMIF($D$5:$CP$5,CT$5,$D39:$CP39)+SUMIF($D$5:$BI$5,CR$5,$D39:$BI39) | CU39: =+CR39-CS39 | CV39: =+CR39-CT39 | CW39: =+SUMIF($D$5:$CQ$5,CW$5,$D39:$CQ39) | CX39: =IFERROR(CR39/CW39-1, "-")
C40: PL34 | CR40: =+SUMIF($D$5:$CQ$5,CR$5,$D40:$CQ40) | CS40: =+SUMIF($D$5:$CQ$5,CS$5,$D40:$CQ40) | CT40: =+SUMIF($D$5:$CP$5,CT$5,$D40:$CP40)+SUMIF($D$5:$BI$5,CR$5,$D40:$BI40) | CU40: =+CR40-CS40 | CV40: =+CR40-CT40 | CW40: =+SUMIF($D$5:$CQ$5,CW$5,$D40:$CQ40) | CX40: =IFERROR(CR40/CW40-1, "-")
A41: EBITA | C41: PL35 | D41: 151.77877 | E41: 501.49997 | F41: -349.72121 | G41: 693.36333 | H41: -0.78109779 | J41: -756.09269 | K41: 135.90357 | L41: -891.99626 | M41: 496.54315 | N41: -2.522713 | P41: -660.41525 | Q41: 458.90413 | R41: -1119.3194 | S41: 1036.1987 | T41: -1.6373442 | V41: -661.71575 | W41: 312.40536 | X41: -610.61122 | Y41: -974.12111 | Z41: -51.104527 | AA41: 568.04608 | AB41: -2.164898 | AD41: -485.6007 | AE41: 756.84703 | AF41: -300.83227 | AG41: -1242.4477 | AH41: -184.76843 | AI41: 137.02157 | AJ41: -4.5439727 | AL41: -2370.4197 | AM41: 581.83976 | AN41: -292.83466 | AO41: 0 | AP41: -2952.2595 | AQ41: -2077.585 | AR41: 482.76276 | AS41: -5.9101129 | CR41: =+SUMIF($D$5:$CQ$5,CR$5,$D41:$CQ41) | CS41: =+SUMIF($D$5:$CQ$5,CS$5,$D41:$CQ41) | CT41: =+CT31+CT36+CT37+CT38+CT39 | CU41: =+CR41-CS41 | CV41: =+CR41-CT41 | CW41: =+SUMIF($D$5:$CQ$5,CW$5,$D41:$CQ41) | CX41: =IFERROR(CR41/CW41-1, "-") | CZ41: 7060.1132 | DA41: -1380.7232 | DD41: 1113.2213 | DE41: =CZ41/DD41-1 | DF41: =DA41/DD41-1 | DG41: =DB41/DD41-1 | DH41: =DC41/DD41-1
A42: % CA | C42: PL36 | D42: 0.018231897 | E42: 0.052639371 | F42: -0.034407474 | G42: 0.07313336 | H42: -0.0075070342 | J42: -0.099487046 | K42: 0.015475025 | L42: -0.11496207 | M42: 0.054806929 | N42: -0.028152275 | P42: -0.083139156 | Q42: 0.048442669 | R42: -0.13158182 | S42: 0.10403886 | T42: -0.017991164 | V42: -0.081893191 | W42: 0.033367594 | X42: -0.067623512 | Y42: -0.11526078 | Z42: -0.014269678 | AA42: 0.061212537 | AB42: -0.0233785 | AD42: -0.061045434 | AE42: 0.077446901 | AF42: -0.036688586 | AG42: -0.13849234 | AH42: -0.024356849 | AI42: 0.015000938 | AJ42: -0.050694411 | AL42: -0.36682092 | AM42: 0.061461822 | AN42: -0.00036174099 | AO42: 0 | AP42: -0.42828274 | AQ42: -0.36645918 | AR42: 0.053959533 | AS42: -0.077980744 | CR42: =+CR41/CR7 | CS42: =+CS41/CS7 | CT42: =+CT41/CT7 | CU42: =+(CR42-CS42)*100 | CV42: =+(CR42-CT42)*100 | CW42: =+CW41/CW7 | CX42: =IFERROR(CR42/CW42-1, "-") | CZ42: 0.061750029 | DA42: -0.00013686267 | DD42: 0.10165576 | DE42: =+(CZ42-DD42)*100 | DF42: =DA42/DD42-1 | DG42: =DB42/DD42-1 | DH42: =DC42/DD42-1
...

Sheet Opex Consolidés
J1: 6444110418 | Y1: =Y7/W7 | Z1: =Z7/X7 | AU1: -20648636 | AW1: 12.127701 | CR1: =65151.9-CR7 | DP1: 0
A2: Opex Consolidés | J2: 419560633 | K2: 0 | P2: 21468044 | W2: 839.68735 | X2: 0 | AD2: 0 | AE2: 0 | AF2: 2024 Réel | AO2: 0 | AU2: 0 | BN2: 0 | BP2: 0 | CR2: =CS7+'P&L conso'!CS25 | CT2: =CT7+'P&L conso'!CT25 | DP2: 10167534 | DQ2: 0 | DR2: 0 | DU2: 0
E3: 0 | G3: 0 | CZ3: 0 | DQ3: 295188041
D4: 45658 | J4: 45689 | P4: 45717 | V4: 45748 | AD4: 45778 | AL4: 45809 | AU4: 45839 | BC4: 45870 | BK4: 45901 | BT4: 45931 | CB4: 45962 | CJ4: 45992 | CR4: CUMUL | CZ4: ANNUEL
B5: (En Millions ML) | D5: 2025 Réel | E5: 2025 Budget | F5: Ecart / Budget | G5: 2024 Réel | H5: Evol % | J5: 2025 Réel | K5: 2025 Budget | L5: Ecart / Budget | M5: 2024 Réel | N5: Evol % | P5: 2025 Réel | Q5: 2025 Budget | R5: Ecart / Budget | S5: 2024 Réel | T5: Evol % | V5: 2025 Réel | W5: 2025 Budget | X5: 2025 Actu1 | Y5: Ecart / Budget | Z5: Ecart / Actu1 | AA5: 2024 Réel | AB5: Evol % | AD5: 2025 Réel | AE5: 2025 Budget | AF5: 2025 Actu1 | AG5: Ecart / Budget | AH5: Ecart / Actu1 | AI5: 2024 Réel | AJ5: Evol % | AL5: 2025 Réel | AM5: 2025 Budget | AN5: 2025 Actu1 | AO5: 2025 Actu2 | AP5: Ecart / Budget | AQ5: Ecart / Actu1 | AR5: 2024 Réel | AS5: Evol % | AU5: 2025 Réel | AV5: 2025 Budget | AW5: 2025 Actu2 | AX5: Ecart / Budget | AY5: Ecart / Actu2 | AZ5: 2024 Réel | BA5: Evol % | BC5: 2025 Réel | BD5: 2025 Budget | BE5: 2025 Actu2 | BF5: Ecart / Budget | BG5: Ecart / Actu2 | BH5: 2024 Réel | BI5: Evol % | BK5: 2025 Réel | BL5: 2025 Budget | BM5: 2025 Actu2 | BN5: 2025 Actu3 | BO5: Ecart / Budget | BP5: Ecart / Actu2 | BQ5: 2024 Réel | BR5: Evol % | BT5: 2025 Réel | BU5: 2025 Budget | BV5: 2025 Actu3 | BW5: Ecart / Budget | BX5: Ecart / Actu3 | BY5: 2024 Réel | BZ5: Evol % | CB5: 2025 Réel | CC5: 2025 Budget | CD5: 2025 Actu3 | CE5: Ecart / Budget | CF5: Ecart / Actu3 | CG5: 2024 Réel | CH5: Evol % | CJ5: 2025 Réel | CK5: 2025 Budget | CL5: 2025 Actu3 | CM5: Ecart / Budget | CN5: Ecart / Actu3 | CO5: 2024 Réel | CP5: Evol % | CR5: 2025 Réel | CS5: 2025 Budget | CT5: 2025 Actu3 | CU5: Ecart / Budget | CV5: Ecart / Actu3 | CW5: 2024 Réel | CX5: Evol % | CZ5: 2025 Budget | DA5: 2025 Actu1 | DB5: 2025 Actu2 | DC5: 2025 Actu3 | DD5: 2024 Réel | DE5: Bud / 2024 (%) | DF5: Actu 1 / 2024 (%) | DG5: Actu 2 / 2024 (%) | DH5: Actu3 / 2024 (%) | DJ5: 2025 Réel | DK5: 2025 Budget | DL5: 2024 Réel | DM5: Actu | DP5: 2025 Réel
DJ6: =SUM(D6,J6,P6,V6,AD6,AL6,AU6,BC6,BK6,BT6,CB6,CJ6)-CR6 | DK6: =SUM(E6,K6,Q6,W6,AE6,AM6,AV6,BD6,BL6,BU6,CC6,CK6)-CS6 | DL6: =SUM(G6,M6,S6,AA6,AI6,AR6,AZ6,BH6,BQ6,BY6,CG6,CO6)-CW6 | DM6: =SUM(D6,J6,P6,V6,AD6,AL6,AU6,BC6,,BN6,BV6,CD6,CL6)-CT6
B7: Total Opex | C7: Opex1 | D7: 5023.3945 | E7: 5752.8634 | F7: -729.46896 | G7: 5774.0655 | H7: -0.13000736 | J7: 5233.5165 | K7: 5412.0079 | L7: -178.49134 | M7: 5467.9109 | N7: -0.042867268 | P7: 5306.2354 | Q7: 5658.8042 | R7: -352.56882 | S7: 5318.9236 | T7: -0.0023854885 | V7: 5421.9008 | W7: 5772.0206 | X7: 5383.448 | Y7: -350.11983 | Z7: 38.452731 | AA7: 5458.7716 | AB7: -0.0067544161 | AD7: 5302.1763 | AE7: 5682.373 | AF7: 5325.1097 | AG7: -380.19665 | AH7: -22.93341 | AI7: 5565.8537 | AJ7: -0.047374108 | AL7: 5739.4271 | AM7: 5580.6859 | AN7: 0 | AO7: 0 | AP7: 158.74112 | AQ7: 5739.4271 | AR7: 5075.041 | AS7: 0.13091246 | CR7: =SUMIF($D$5:$CQ$5,CR$5,$D7:$CQ7) | CS7: =SUMIF($D$5:$CQ$5,CS$5,$D7:$CQ7) | CT7: =SUMIF($D$5:$CQ$5,CT$5,$D7:$CQ7)+SUMIF($D$5:$BI$5,CR$5,$D7:$BI7) | CU7: =+CR7-CS7 | CV7: =+CR7-CT7 | CW7: =SUMIF($D$5:$CQ$5,CW$5,$D7:$CQ7) | CX7: =IFERROR(CR7/CW7-1, "-") | CZ7: 67535.531 | DD7: 66696.264 | DE7: =+CZ7/DD7-1 | DF7: =+DA7/DD7-1 | DG7: =+DB7/DD7-1 | DH7: =+DC7/DD7-1 | DJ7: =SUM(D7,J7,P7,V7,AD7,AL7,AU7,BC7,BK7,BT7,CB7,CJ7)-CR7 | DK7: =SUM(E7,K7,Q7,W7,AE7,AM7,AV7,BD7,BL7,BU7,CC7,CK7)-CS7 | DL7: =SUM(G7,M7,S7,AA7,AI7,AR7,AZ7,BH7,BQ7,BY7,CG7,CO7)-CW7 | DM7: =SUM(D7,J7,P7,V7,AD7,AL7,AU7,BC7,,BN7,BV7,CD7,CL7)-CT7 | DP7: =SUM(DP9,DP40,DP57,DP113,DP167,DP184,DP201) | DQ7: =-CR7+DP7/10^6 | DR7: =SUM(E7,K7,Q7,W7,AE7,AM7,AV7,BD7,BL7,BU7,CC7,CK7)-CS7 | DS7: =SUM(D7,J7,P7,V7,AD7,AL7,AU7,BC7,,BN7,BV7,CD7,CL7)-CT7 | DU7: 6509.7557 | DV7: =DU7-CJ7
C8: Opex2 | CT8: =SUMIF($D$5:$CQ$5,CT$5,$D8:$CQ8)+SUMIF($D$5:$BI$5,CR$5,$D8:$BI8) | CX8: =IFERROR(CR8/CW8-1, "-") | DJ8: =SUM(D8,J8,P8,V8,AD8,AL8,AU8,BC8,BK8,BT8,CB8,CJ8)-CR8 | DK8: =SUM(E8,K8,Q8,W8,AE8,AM8,AV8,BD8,BL8,BU8,CC8,CK8)-CS8 | DL8: =SUM(G8,M8,S8,AA8,AI8,AR8,AZ8,BH8,BQ8,BY8,CG8,CO8)-CW8 | DM8: =SUM(D8,J8,P8,V8,AD8,AL8,AU8,BC8,,BN8,BV8,CD8,CL8)-CT8 | DQ8: =-CR8+DP8/10^6 | DR8: =SUM(E8,K8,Q8,W8,AE8,AM8,AV8,BD8,BL8,BU8,CC8,CK8)-CS8 | DS8: =SUM(D8,J8,P8,V8,AD8,AL8,AU8,BC8,,BN8,BV8,CD8,CL8)-CT8 | DV8: =DU8-CJ8 | DX8: =CS8-CZ8 | DY8: =CT8-DC8 | DZ8: =CW8-DD8
B9: Personnel | C9: Opex3 | D9: 418.50116 | E9: 437.22587 | F9: -18.724713 | G9: 463.14343 | H9: -0.096389728 | J9: 427.18334 | K9: 437.22587 | L9: -10.04253 | M9: 414.54924 | N9: 0.03047673 | P9: 451.70827 | Q9: 437.22587 | R9: 14.482397 | S9: 412.27444 | T9: 0.095649461 | V9: 425.00465 | W9: 452.22587 | X9: 452.22587 | Y9: -27.221217 | Z9: -27.221217 | AA9: 409.95078 | AB9: 0.036721172 | AD9: 403.8914 | AE9: 437.22587 | AF9: 437.22587 | AG9: -33.33447 | AH9: -33.33447 | AI9: 422.14686 | AJ9: -0.043244332 | AL9: 559.2972 | AM9: 437.22587 | AN9: 0 | AO9: 0 | AP9: 122.07133 | AQ9: 559.2972 | AR9: 439.56219 | AS9: 0.27239605 | CR9: =SUMIF($D$5:$CQ$5,CR$5,$D9:$CQ9) | CS9: =SUMIF($D$5:$CQ$5,CS$5,$D9:$CQ9) | CT9: =SUMIF($D$5:$CQ$5,CT$5,$D9:$CQ9)+SUMIF($D$5:$BI$5,CR$5,$D9:$BI9) | CU9: =+CR9-CS9 | CV9: =+CR9-CT9 | CW9: =SUMIF($D$5:$CQ$5,CW$5,$D9:$CQ9) | CX9: =IFERROR(CR9/CW9-1, "-") | CZ9: 5306.5205 | DD9: 5023.8916 | DE9: =+CZ9/DD9-1 | DF9: =+DA9/DD9-1 | DG9: =+DB9/DD9-1 | DH9: =+DC9/DD9-1 | DJ9: =SUM(D9,J9,P9,V9,AD9,AL9,AU9,BC9,BK9,BT9,CB9,CJ9)-CR9 | DK9: =SUM(E9,K9,Q9,W9,AE9,AM9,AV9,BD9,BL9,BU9,CC9,CK9)-CS9 | DL9: =SUM(G9,M9,S9,AA9,AI9,AR9,AZ9,BH9,BQ9,BY9,CG9,CO9)-CW9 | DM9: =SUM(D9,J9,P9,V9,AD9,AL9,AU9,BC9,,BN9,BV9,CD9,CL9)-CT9 | DP9: =SUM(DP10:DP38) | DQ9: =-CR9+DP9/10^6 | DR9: =SUM(E9,K9,Q9,W9,AE9,AM9,AV9,BD9,BL9,BU9,CC9,CK9)-CS9 | DS9: =SUM(D9,J9,P9,V9,AD9,AL9,AU9,BC9,,BN9,BV9,CD9,CL9)-CT9 | DU9: 438.17153 | DV9: =DU9-CJ9 | DX9: =(CS9-CZ9)*10^6 | DY9: =(CT9-DC9)*10^6 | DZ9: =(CW9-DD9)*10^6
B10: TAXES SUR APPOINTEMENTS ET SAL | C10: Opex4 | G10: 0 | M10: 0 | S10: 0 | AA10: 0 | AI10: 0 | CR10: =SUMIF($D$5:$CQ$5,CR$5,$D10:$CQ10) | CS10: =SUMIF($D$5:$CQ$5,CS$5,$D10:$CQ10) | CT10: =SUMIF($D$5:$CQ$5,CT$5,$D10:$CQ10)+SUMIF($D$5:$BI$5,CR$5,$D10:$BI10) | CU10: =+CR10-CS10 | CV10: =+CR10-CT10 | CW10: =SUMIF($D$5:$CQ$5,CW$5,$D10:$CQ10) | CX10: =IFERROR(CR10/CW10-1, "-") | CZ10: 0 | DA10: 0 | DD10: 0 | DJ10: =SUM(D10,J10,P10,V10,AD10,AL10,AU10,BC10,BK10,BT10,CB10,CJ10)-CR10 | DK10: =SUM(E10,K10,Q10,W10,AE10,AM10,AV10,BD10,BL10,BU10,CC10,CK10)-CS10 | DL10: =SUM(G10,M10,S10,AA10,AI10,AR10,AZ10,BH10,BQ10,BY10,CG10,CO10)-CW10 | DM10: =SUM(D10,J10,P10,V10,AD10,AL10,AU10,BC10,,BN10,BV10,CD10,CL10)-CT10 | DQ10: =-CR10+DP10/10^6 | DR10: =SUM(E10,K10,Q10,W10,AE10,AM10,AV10,BD10,BL10,BU10,CC10,CK10)-CS10 | DS10: =SUM(D10,J10,P10,V10,AD10,AL10,AU10,BC10,,BN10,BV10,CD10,CL10)-CT10 | DV10: =DU10-CJ10 | DX10: =(CS10-CZ10)*10^6 | DY10: =(CT10-DC10)*10^6 | DZ10: =(CW10-DD10)*10^6
B11: APPOINTEMENTS, SALAIRES PERSON | C11: Opex5 | D11: 226.87083 | E11: 271.843 | G11: 243.82677 | J11: 276.09957 | K11: 271.843 | M11: 250.52701 | P11: 256.55706 | Q11: 271.843 | S11: 251.32896 | V11: 254.56437 | W11: 271.843 | X11: 271.843 | AA11: 255.07508 | AD11: 256.07346 | AE11: 271.843 | AF11: 271.843 | AI11: 254.42255 | AL11: 230.9815 | AM11: 271.843 | CR11: =SUMIF($D$5:$CQ$5,CR$5,$D11:$CQ11) | CS11: =SUMIF($D$5:$CQ$5,CS$5,$D11:$CQ11) | CT11: =SUMIF($D$5:$CQ$5,CT$5,$D11:$CQ11)+SUMIF($D$5:$BI$5,CR$5,$D11:$BI11) | CU11: =+CR11-CS11 | CV11: =+CR11-CT11 | CW11: =SUMIF($D$5:$CQ$5,CW$5,$D11:$CQ11) | CX11: =IFERROR(CR11/CW11-1, "-") | CZ11: 3262.1161 | DA11: 3206.1145 | DD11: 3047.1451 | DE11: =+CZ11/DD11-1 | DF11: =+DA11/DD11-1 | DG11: =+DB11/DD11-1 | DH11: =+DC11/DD11-1 | DJ11: =SUM(D11,J11,P11,V11,AD11,AL11,AU11,BC11,BK11,BT11,CB11,CJ11)-CR11 | DK11: =SUM(E11,K11,Q11,W11,AE11,AM11,AV11,BD11,BL11,BU11,CC11,CK11)-CS11 | DL11: =SUM(G11,M11,S11,AA11,AI11,AR11,AZ11,BH11,BQ11,BY11,CG11,CO11)-CW11 | DM11: =SUM(D11,J11,P11,V11,AD11,AL11,AU11,BC11,,BN11,BV11,CD11,CL11)-CT11 | DP11: #VALUE! | DQ11: =-CR11+DP11/10^6 | DR11: =SUM(E11,K11,Q11,W11,AE11,AM11,AV11,BD11,BL11,BU11,CC11,CK11)-CS11 | DS11: =SUM(D11,J11,P11,V11,AD11,AL11,AU11,BC11,,BN11,BV11,CD11,CL11)-CT11 | DT11: =DQ11/11 | DU11: 262.72376 | DV11: =DU11-CJ11 | DX11: =(CS11-CZ11)*10^6 | DY11: =(CT11-DC11)*10^6 | DZ11: =(CW11-DD11)*10^6
B12: CONGES PAYES PERSONNEL NATIONA | C12: Opex6 | D12: 49.304441 | G12: 52.490243 | J12: 13.921259 | M12: 19.639126 | P12: 6.139638 | S12: 27.372416 | V12: 17.04329 | AA12: 12.074878 | AD12: 14.646434 | AI12: 16.600311 | AL12: 13.385284 | CR12: =SUMIF($D$5:$CQ$5,CR$5,$D12:$CQ12) | CS12: =SUMIF($D$5:$CQ$5,CS$5,$D12:$CQ12) | CT12: =SUMIF($D$5:$CQ$5,CT$5,$D12:$CQ12)+SUMIF($D$5:$BI$5,CR$5,$D12:$BI12) | CU12: =+CR12-CS12 | CV12: =+CR12-CT12 | CW12: =SUMIF($D$5:$CQ$5,CW$5,$D12:$CQ12) | CX12: =IFERROR(CR12/CW12-1, "-") | CZ12: 0 | DA12: 69.365338 | DD12: 110.74184 | DE12: =+CZ12/DD12-1 | DF12: =+DA12/DD12-1 | DG12: =+DB12/DD12-1 | DH12: =+DC12/DD12-1 | DJ12: =SUM(D12,J12,P12,V12,AD12,AL12,AU12,BC12,BK12,BT12,CB12,CJ12)-CR12 | DK12: =SUM(E12,K12,Q12,W12,AE12,AM12,AV12,BD12,BL12,BU12,CC12,CK12)-CS12 | DL12: =SUM(G12,M12,S12,AA12,AI12,AR12,AZ12,BH12,BQ12,BY12,CG12,CO12)-CW12 | DM12: =SUM(D12,J12,P12,V12,AD12,AL12,AU12,BC12,,BN12,BV12,CD12,CL12)-CT12 | DP12: #VALUE! | DQ12: =-CR12+DP12/10^6 | DR12: =SUM(E12,K12,Q12,W12,AE12,AM12,AV12,BD12,BL12,BU12,CC12,CK12)-CS12 | DS12: =SUM(D12,J12,P12,V12,AD12,AL12,AU12,BC12,,BN12,BV12,CD12,CL12)-CT12 | DU12: -31.251393 | DV12: =DU12-CJ12 | DX12: =(CS12-CZ12)*10^6 | DY12: =(CT12-DC12)*10^6 | DZ12: =(CW12-DD12)*10^6
B13: CHARGES SOCIALES S/ REMUNERATI | C13: Opex7 | D13: 67.453394 | E13: 70.154336 | G13: 76.944862 | J13: 70.409587 | K13: 70.154336 | M13: 70.194999 | P13: 68.244258 | Q13: 70.154336 | S13: 62.751017 | V13: 66.503683 | W13: 70.154336 | X13: 70.154336 | AA13: 63.971797 | AD13: 67.135866 | AE13: 70.154336 | AF13: 70.154336 | AI13: 67.709261 | AL13: 66.425273 | AM13: 70.154336 | CR13: =SUMIF($D$5:$CQ$5,CR$5,$D13:$CQ13) | CS13: =SUMIF($D$5:$CQ$5,CS$5,$D13:$CQ13) | CT13: =SUMIF($D$5:$CQ$5,CT$5,$D13:$CQ13)+SUMIF($D$5:$BI$5,CR$5,$D13:$BI13) | CU13: =+CR13-CS13 | CV13: =+CR13-CT13 | CW13: =SUMIF($D$5:$CQ$5,CW$5,$D13:$CQ13) | CX13: =IFERROR(CR13/CW13-1, "-") | CZ13: 841.85203 | DA13: 837.49626 | DD13: 797.67097 | DE13: =+CZ13/DD13-1 | DF13: =+DA13/DD13-1 | DG13: =+DB13/DD13-1 | DH13: =+DC13/DD13-1 | DJ13: =SUM(D13,J13,P13,V13,AD13,AL13,AU13,BC13,BK13,BT13,CB13,CJ13)-CR13 | DK13: =SUM(E13,K13,Q13,W13,AE13,AM13,AV13,BD13,BL13,BU13,CC13,CK13)-CS13 | DL13: =SUM(G13,M13,S13,AA13,AI13,AR13,AZ13,BH13,BQ13,BY13,CG13,CO13)-CW13 | DM13: =SUM(D13,J13,P13,V13,AD13,AL13,AU13,BC13,,BN13,BV13,CD13,CL13)-CT13 | DP13: #VALUE! | DQ13: =-CR13+DP13/10^6 | DR13: =SUM(E13,K13,Q13,W13,AE13,AM13,AV13,BD13,BL13,BU13,CC13,CK13)-CS13 | DS13: =SUM(D13,J13,P13,V13,AD13,AL13,AU13,BC13,,BN13,BV13,CD13,CL13)-CT13 | DU13: 68.494617 | DV13: =DU13-CJ13 | DX13: =(CS13-CZ13)*10^6 | DY13: =(CT13-DC13)*10^6 | DZ13: =(CW13-DD13)*10^6
B14: AUTRES CHARGES SOCIALES | C14: Opex8 | D14: 16.100452 | E14: 23.470584 | G14: 17.821406 | J14: 20.932853 | K14: 23.470584 | M14: 18.223743 | P14: 18.214341 | Q14: 23.470584 | S14: 18.138523 | V14: 18.372789 | W14: 23.470584 | X14: 23.470584 | AA14: 20.539258 | AD14: 18.097547 | AE14: 23.470584 | AF14: 23.470584 | AI14: 18.286525 | AL14: 16.915452 | AM14: 23.470584 | CR14: =SUMIF($D$5:$CQ$5,CR$5,$D14:$CQ14) | CS14: =SUMIF($D$5:$CQ$5,CS$5,$D14:$CQ14) | CT14: =SUMIF($D$5:$CQ$5,CT$5,$D14:$CQ14)+SUMIF($D$5:$BI$5,CR$5,$D14:$BI14) | CU14: =+CR14-CS14 | CV14: =+CR14-CT14 | CW14: =SUMIF($D$5:$CQ$5,CW$5,$D14:$CQ14) | CX14: =IFERROR(CR14/CW14-1, "-") | CZ14: 281.64701 | DA14: 266.48291 | DD14: 216.52125 | DE14: =+CZ14/DD14-1 | DF14: =+DA14/DD14-1 | DG14: =+DB14/DD14-1 | DH14: =+DC14/DD14-1 | DJ14: =SUM(D14,J14,P14,V14,AD14,AL14,AU14,BC14,BK14,BT14,CB14,CJ14)-CR14 | DK14: =SUM(E14,K14,Q14,W14,AE14,AM14,AV14,BD14,BL14,BU14,CC14,CK14)-CS14 | DL14: =SUM(G14,M14,S14,AA14,AI14,AR14,AZ14,BH14,BQ14,BY14,CG14,CO14)-CW14 | DM14: =SUM(D14,J14,P14,V14,AD14,AL14,AU14,BC14,,BN14,BV14,CD14,CL14)-CT14 | DP14: #VALUE! | DQ14: =-CR14+DP14/10^6 | DR14: =SUM(E14,K14,Q14,W14,AE14,AM14,AV14,BD14,BL14,BU14,CC14,CK14)-CS14 | DS14: =SUM(D14,J14,P14,V14,AD14,AL14,AU14,BC14,,BN14,BV14,CD14,CL14)-CT14 | DU14: 14.369378 | DV14: =DU14-CJ14 | DX14: =(CS14-CZ14)*10^6 | DY14: =(CT14-DC14)*10^6 | DZ14: =(CW14-DD14)*10^6
B15: PERSONNEL INTERIMAIRE & STAGIA | C15: Opex9 | E15: 0 | G15: 0 | K15: 0 | M15: 0 | Q15: 0 | S15: 0 | W15: 0 | X15: 0 | AA15: 0 | AE15: 0 | AF15: 0 | AI15: 0 | AL15: 0 | AM15: 0 | CT15: =SUMIF($D$5:$CQ$5,CT$5,$D15:$CQ15)+SUMIF($D$5:$BI$5,CR$5,$D15:$BI15) | CX15: =IFERROR(CR15/CW15-1, "-") | CZ15: 0 | DA15: 0 | DD15: 0 | DG15: =+DB15/DD15-1 | DH15: =+DC15/DD15-1 | DJ15: =SUM(D15,J15,P15,V15,AD15,AL15,AU15,BC15,BK15,BT15,CB15,CJ15)-CR15 | DK15: =SUM(E15,K15,Q15,W15,AE15,AM15,AV15,BD15,BL15,BU15,CC15,CK15)-CS15 | DL15: =SUM(G15,M15,S15,AA15,AI15,AR15,AZ15,BH15,BQ15,BY15,CG15,CO15)-CW15 | DM15: =SUM(D15,J15,P15,V15,AD15,AL15,AU15,BC15,,BN15,BV15,CD15,CL15)-CT15 | DQ15: =-CR15+DP15/10^6 | DR15: =SUM(E15,K15,Q15,W15,AE15,AM15,AV15,BD15,BL15,BU15,CC15,CK15)-CS15 | DS15: =SUM(D15,J15,P15,V15,AD15,AL15,AU15,BC15,,BN15,BV15,CD15,CL15)-CT15 | DV15: =DU15-CJ15 | DX15: =(CS15-CZ15)*10^6 | DY15: =(CT15-DC15)*10^6 | DZ15: =(CW15-DD15)*10^6
B16: PRIMES ET GRATIFICATIONS PERSO | C16: Opex10 | D16: 33.39541 | E16: 38.379319 | G16: 26.709627 | J16: 4.563872 | K16: 38.379319 | M16: 15.861169 | P16: 87.867673 | Q16: 38.379319 | S16: 28.380923 | V16: 37.495894 | W16: 38.379319 | X16: 38.379319 | AA16: 26.218939 | AD16: 19.917355 | AE16: 38.379319 | AF16: 38.379319 | AI16: 36.479091 | AL16: 39.543724 | AM16: 38.379319 | CR16: =SUMIF($D$5:$CQ$5,CR$5,$D16:$CQ16) | CS16: =SUMIF($D$5:$CQ$5,CS$5,$D16:$CQ16) | CT16: =SUMIF($D$5:$CQ$5,CT$5,$D16:$CQ16)+SUMIF($D$5:$BI$5,CR$5,$D16:$BI16) | CU16: =+CR16-CS16 | CV16: =+CR16-CT16 | CW16: =SUMIF($D$5:$CQ$5,CW$5,$D16:$CQ16) | CX16: =IFERROR(CR16/CW16-1, "-") | CZ16: 460.55183 | DA16: 471.24082 | DD16: 459.16007 | DE16: =+CZ16/DD16-1 | DF16: =+DA16/DD16-1 | DG16: =+DB16/DD16-1 | DH16: =+DC16/DD16-1 | DJ16: =SUM(D16,J16,P16,V16,AD16,AL16,AU16,BC16,BK16,BT16,CB16,CJ16)-CR16 | DK16: =SUM(E16,K16,Q16,W16,AE16,AM16,AV16,BD16,BL16,BU16,CC16,CK16)-CS16 | DL16: =SUM(G16,M16,S16,AA16,AI16,AR16,AZ16,BH16,BQ16,BY16,CG16,CO16)-CW16 | DM16: =SUM(D16,J16,P16,V16,AD16,AL16,AU16,BC16,,BN16,BV16,CD16,CL16)-CT16 | DP16: #VALUE! | DQ16: =-CR16+DP16/10^6 | DR16: =SUM(E16,K16,Q16,W16,AE16,AM16,AV16,BD16,BL16,BU16,CC16,CK16)-CS16 | DS16: =SUM(D16,J16,P16,V16,AD16,AL16,AU16,BC16,,BN16,BV16,CD16,CL16)-CT16 | DT16: 22.791149 | DU16: 89.601339 | DV16: =DU16-CJ16 | DX16: =(CS16-CZ16)*10^6 | DY16: =(CT16-DC16)*10^6 | DZ16: =(CW16-DD16)*10^6
B17: INDEMNITES DE LICENCIEMENT PER | C17: Opex11 | G17: 0 | J17: 12.842046 | M17: 0 | P17: -12.842046 | S17: 0 | V17: 0 | AA17: 0 | AD17: 0 | AI17: 0 | AL17: 0 | CR17: =SUMIF($D$5:$CQ$5,CR$5,$D17:$CQ17) | CS17: =SUMIF($D$5:$CQ$5,CS$5,$D17:$CQ17) | CT17: =SUMIF($D$5:$CQ$5,CT$5,$D17:$CQ17)+SUMIF($D$5:$BI$5,CR$5,$D17:$BI17) | CU17: =+CR17-CS17 | CV17: =+CR17-CT17 | CW17: =SUMIF($D$5:$CQ$5,CW$5,$D17:$CQ17) | CX17: =IFERROR(CR17/CW17-1, "-") | CZ17: 0 | DA17: 0 | DD17: 0 | DJ17: =SUM(D17,J17,P17,V17,AD17,AL17,AU17,BC17,BK17,BT17,CB17,CJ17)-CR17 | DK17: =SUM(E17,K17,Q17,W17,AE17,AM17,AV17,BD17,BL17,BU17,CC17,CK17)-CS17 | DL17: =SUM(G17,M17,S17,AA17,AI17,AR17,AZ17,BH17,BQ17,BY17,CG17,CO17)-CW17 | DM17: =SUM(D17,J17,P17,V17,AD17,AL17,AU17,BC17,,BN17,BV17,CD17,CL17)-CT17 | DQ17: =-CR17+DP17/10^6 | DR17: =SUM(E17,K17,Q17,W17,AE17,AM17,AV17,BD17,BL17,BU17,CC17,CK17)-CS17 | DS17: =SUM(D17,J17,P17,V17,AD17,AL17,AU17,BC17,,BN17,BV17,CD17,CL17)-CT17 | DV17: =DU17-CJ17 | DX17: =(CS17-CZ17)*10^6 | DY17: =(CT17-DC17)*10^6 | DZ17: =(CW17-DD17)*10^6
B18: EAU RESIDENCES | C18: Opex12 | G18: 0 | M18: 0 | S18: 0 | AA18: 0 | AI18: 0 | CR18: =SUMIF($D$5:$CQ$5,CR$5,$D18:$CQ18) | CS18: =SUMIF($D$5:$CQ$5,CS$5,$D18:$CQ18) | CT18: =SUMIF($D$5:$CQ$5,CT$5,$D18:$CQ18)+SUMIF($D$5:$BI$5,CR$5,$D18:$BI18) | CU18: =+CR18-CS18 | CV18: =+CR18-CT18 | CW18: =SUMIF($D$5:$CQ$5,CW$5,$D18:$CQ18) | CX18: =IFERROR(CR18/CW18-1, "-") | CZ18: 0 | DA18: 0 | DD18: 0 | DJ18: =SUM(D18,J18,P18,V18,AD18,AL18,AU18,BC18,BK18,BT18,CB18,CJ18)-CR18 | DK18: =SUM(E18,K18,Q18,W18,AE18,AM18,AV18,BD18,BL18,BU18,CC18,CK18)-CS18 | DL18: =SUM(G18,M18,S18,AA18,AI18,AR18,AZ18,BH18,BQ18,BY18,CG18,CO18)-CW18 | DM18: =SUM(D18,J18,P18,V18,AD18,AL18,AU18,BC18,,BN18,BV18,CD18,CL18)-CT18 | DQ18: =-CR18+DP18/10^6 | DR18: =SUM(E18,K18,Q18,W18,AE18,AM18,AV18,BD18,BL18,BU18,CC18,CK18)-CS18 | DS18: =SUM(D18,J18,P18,V18,AD18,AL18,AU18,BC18,,BN18,BV18,CD18,CL18)-CT18 | DV18: =DU18-CJ18 | DX18: =(CS18-CZ18)*10^6 | DY18: =(CT18-DC18)*10^6 | DZ18: =(CW18-DD18)*10^6
B19: ELECTRICITE RESIDENCES | C19: Opex13 | G19: 0 | M19: 0 | S19: 0 | AA19: 0 | AI19: 0 | CR19: =SUMIF($D$5:$CQ$5,CR$5,$D19:$CQ19) | CS19: =SUMIF($D$5:$CQ$5,CS$5,$D19:$CQ19) | CT19: =SUMIF($D$5:$CQ$5,CT$5,$D19:$CQ19)+SUMIF($D$5:$BI$5,CR$5,$D19:$BI19) | CU19: =+CR19-CS19 | CV19: =+CR19-CT19 | CW19: =SUMIF($D$5:$CQ$5,CW$5,$D19:$CQ19) | CX19: =IFERROR(CR19/CW19-1, "-") | CZ19: 0 | DA19: 0 | DD19: 0 | DJ19: =SUM(D19,J19,P19,V19,AD19,AL19,AU19,BC19,BK19,BT19,CB19,CJ19)-CR19 | DK19: =SUM(E19,K19,Q19,W19,AE19,AM19,AV19,BD19,BL19,BU19,CC19,CK19)-CS19 | DL19: =SUM(G19,M19,S19,AA19,AI19,AR19,AZ19,BH19,BQ19,BY19,CG19,CO19)-CW19 | DM19: =SUM(D19,J19,P19,V19,AD19,AL19,AU19,BC19,,BN19,BV19,CD19,CL19)-CT19 | DQ19: =-CR19+DP19/10^6 | DR19: =SUM(E19,K19,Q19,W19,AE19,AM19,AV19,BD19,BL19,BU19,CC19,CK19)-CS19 | DS19: =SUM(D19,J19,P19,V19,AD19,AL19,AU19,BC19,,BN19,BV19,CD19,CL19)-CT19 | DV19: =DU19-CJ19 | DX19: =(CS19-CZ19)*10^6 | DY19: =(CT19-DC19)*10^6 | DZ19: =(CW19-DD19)*10^6
B20: LOYERS RESIDENCES | C20: Opex14 | G20: 0 | M20: 0 | S20: 0 | AA20: 0 | AI20: 0 | CR20: =SUMIF($D$5:$CQ$5,CR$5,$D20:$CQ20) | CS20: =SUMIF($D$5:$CQ$5,CS$5,$D20:$CQ20) | CT20: =SUMIF($D$5:$CQ$5,CT$5,$D20:$CQ20)+SUMIF($D$5:$BI$5,CR$5,$D20:$BI20) | CU20: =+CR20-CS20 | CV20: =+CR20-CT20 | CW20: =SUMIF($D$5:$CQ$5,CW$5,$D20:$CQ20) | CX20: =IFERROR(CR20/CW20-1, "-") | CZ20: 0 | DA20: 0 | DD20: 0 | DJ20: =SUM(D20,J20,P20,V20,AD20,AL20,AU20,BC20,BK20,BT20,CB20,CJ20)-CR20 | DK20: =SUM(E20,K20,Q20,W20,AE20,AM20,AV20,BD20,BL20,BU20,CC20,CK20)-CS20 | DL20: =SUM(G20,M20,S20,AA20,AI20,AR20,AZ20,BH20,BQ20,BY20,CG20,CO20)-CW20 | DM20: =SUM(D20,J20,P20,V20,AD20,AL20,AU20,BC20,,BN20,BV20,CD20,CL20)-CT20 | DQ20: =-CR20+DP20/10^6 | DR20: =SUM(E20,K20,Q20,W20,AE20,AM20,AV20,BD20,BL20,BU20,CC20,CK20)-CS20 | DS20: =SUM(D20,J20,P20,V20,AD20,AL20,AU20,BC20,,BN20,BV20,CD20,CL20)-CT20 | DV20: =DU20-CJ20 | DX20: =(CS20-CZ20)*10^6 | DY20: =(CT20-DC20)*10^6 | DZ20: =(CW20-DD20)*10^6
B21: ENTRETIEN ET REPARATIONS RESID | C21: Opex15 | G21: 0 | M21: 0 | S21: 0 | AA21: 0 | AI21: 0 | CR21: =SUMIF($D$5:$CQ$5,CR$5,$D21:$CQ21) | CS21: =SUMIF($D$5:$CQ$5,CS$5,$D21:$CQ21) | CT21: =SUMIF($D$5:$CQ$5,CT$5,$D21:$CQ21)+SUMIF($D$5:$BI$5,CR$5,$D21:$BI21) | CU21: =+CR21-CS21 | CV21: =+CR21-CT21 | CW21: =SUMIF($D$5:$CQ$5,CW$5,$D21:$CQ21) | CX21: =IFERROR(CR21/CW21-1, "-") | CZ21: 0 | DA21: 0 | DD21: 0 | DJ21: =SUM(D21,J21,P21,V21,AD21,AL21,AU21,BC21,BK21,BT21,CB21,CJ21)-CR21 | DK21: =SUM(E21,K21,Q21,W21,AE21,AM21,AV21,BD21,BL21,BU21,CC21,CK21)-CS21 | DL21: =SUM(G21,M21,S21,AA21,AI21,AR21,AZ21,BH21,BQ21,BY21,CG21,CO21)-CW21 | DM21: =SUM(D21,J21,P21,V21,AD21,AL21,AU21,BC21,,BN21,BV21,CD21,CL21)-CT21 | DQ21: =-CR21+DP21/10^6 | DR21: =SUM(E21,K21,Q21,W21,AE21,AM21,AV21,BD21,BL21,BU21,CC21,CK21)-CS21 | DS21: =SUM(D21,J21,P21,V21,AD21,AL21,AU21,BC21,,BN21,BV21,CD21,CL21)-CT21 | DV21: =DU21-CJ21 | DX21: =(CS21-CZ21)*10^6 | DY21: =(CT21-DC21)*10^6 | DZ21: =(CW21-DD21)*10^6
B22: FRAIS MEDICAUX PERSONNEL NATIO | C22: Opex16 | G22: 0 | M22: 0 | S22: 0 | AA22: 0 | AI22: 0 | AL22: 0 | CR22: =SUMIF($D$5:$CQ$5,CR$5,$D22:$CQ22) | CS22: =SUMIF($D$5:$CQ$5,CS$5,$D22:$CQ22) | CT22: =SUMIF($D$5:$CQ$5,CT$5,$D22:$CQ22)+SUMIF($D$5:$BI$5,CR$5,$D22:$BI22) | CU22: =+CR22-CS22 | CV22: =+CR22-CT22 | CW22: =SUMIF($D$5:$CQ$5,CW$5,$D22:$CQ22) | CX22: =IFERROR(CR22/CW22-1, "-") | CZ22: 0 | DA22: 0 | DD22: 0 | DJ22: =SUM(D22,J22,P22,V22,AD22,AL22,AU22,BC22,BK22,BT22,CB22,CJ22)-CR22 | DK22: =SUM(E22,K22,Q22,W22,AE22,AM22,AV22,BD22,BL22,BU22,CC22,CK22)-CS22 | DL22: =SUM(G22,M22,S22,AA22,AI22,AR22,AZ22,BH22,BQ22,BY22,CG22,CO22)-CW22 | DM22: =SUM(D22,J22,P22,V22,AD22,AL22,AU22,BC22,,BN22,BV22,CD22,CL22)-CT22 | DQ22: =-CR22+DP22/10^6 | DR22: =SUM(E22,K22,Q22,W22,AE22,AM22,AV22,BD22,BL22,BU22,CC22,CK22)-CS22 | DS22: =SUM(D22,J22,P22,V22,AD22,AL22,AU22,BC22,,BN22,BV22,CD22,CL22)-CT22 | DV22: =DU22-CJ22 | DX22: =(CS22-CZ22)*10^6 | DY22: =(CT22-DC22)*10^6 | DZ22: =(CW22-DD22)*10^6
B23: AVANTAGES EN NATURE PERSONNEL | C23: Opex17 | D23: 14.098579 | E23: 15.315587 | G23: 32.254248 | J23: 13.386099 | K23: 15.315587 | M23: 27.960439 | P23: 12.477019 | Q23: 15.315587 | S23: 11.743268 | V23: 16.032823 | W23: 30.315587 | X23: 30.315587 | AA23: 19.511494 | AD23: 12.985269 | AE23: 15.315587 | AF23: 15.315587 | AI23: 15.867698 | AL23: 7.47608 | AM23: 15.315587 | CR23: =SUMIF($D$5:$CQ$5,CR$5,$D23:$CQ23) | CS23: =SUMIF($D$5:$CQ$5,CS$5,$D23:$CQ23) | CT23: =SUMIF($D$5:$CQ$5,CT$5,$D23:$CQ23)+SUMIF($D$5:$BI$5,CR$5,$D23:$BI23) | CU23: =+CR23-CS23 | CV23: =+CR23-CT23 | CW23: =SUMIF($D$5:$CQ$5,CW$5,$D23:$CQ23) | CX23: =IFERROR(CR23/CW23-1, "-") | CZ23: 243.59705 | DA23: 237.61198 | DD23: 195.41184 | DE23: =+CZ23/DD23-1 | DF23: =+DA23/DD23-1 | DG23: =+DB23/DD23-1 | DH23: =+DC23/DD23-1 | DJ23: =SUM(D23,J23,P23,V23,AD23,AL23,AU23,BC23,BK23,BT23,CB23,CJ23)-CR23 | DK23: =SUM(E23,K23,Q23,W23,AE23,AM23,AV23,BD23,BL23,BU23,CC23,CK23)-CS23 | DL23: =SUM(G23,M23,S23,AA23,AI23,AR23,AZ23,BH23,BQ23,BY23,CG23,CO23)-CW23 | DM23: =SUM(D23,J23,P23,V23,AD23,AL23,AU23,BC23,,BN23,BV23,CD23,CL23)-CT23 | DP23: #VALUE! | DQ23: =-CR23+DP23/10^6 | DR23: =SUM(E23,K23,Q23,W23,AE23,AM23,AV23,BD23,BL23,BU23,CC23,CK23)-CS23 | DS23: =SUM(D23,J23,P23,V23,AD23,AL23,AU23,BC23,,BN23,BV23,CD23,CL23)-CT23 | DU23: 13.826821 | DV23: =DU23-CJ23 | DX23: =(CS23-CZ23)*10^6 | DY23: =(CT23-DC23)*10^6 | DZ23: =(CW23-DD23)*10^6
B24: TRANSFERT DE CHARGES D'EXPLOITATION | C24: Opex18 | G24: 0 | M24: 0 | S24: 0 | AA24: 0 | AI24: 0 | CR24: =SUMIF($D$5:$CQ$5,CR$5,$D24:$CQ24) | CS24: =SUMIF($D$5:$CQ$5,CS$5,$D24:$CQ24) | CT24: =SUMIF($D$5:$CQ$5,CT$5,$D24:$CQ24)+SUMIF($D$5:$BI$5,CR$5,$D24:$BI24) | CU24: =+CR24-CS24 | CV24: =+CR24-CT24 | CW24: =SUMIF($D$5:$CQ$5,CW$5,$D24:$CQ24) | CX24: =IFERROR(CR24/CW24-1, "-") | CZ24: 0 | DA24: 0 | DD24: 0 | DJ24: =SUM(D24,J24,P24,V24,AD24,AL24,AU24,BC24,BK24,BT24,CB24,CJ24)-CR24 | DK24: =SUM(E24,K24,Q24,W24,AE24,AM24,AV24,BD24,BL24,BU24,CC24,CK24)-CS24 | DL24: =SUM(G24,M24,S24,AA24,AI24,AR24,AZ24,BH24,BQ24,BY24,CG24,CO24)-CW24 | DM24: =SUM(D24,J24,P24,V24,AD24,AL24,AU24,BC24,,BN24,BV24,CD24,CL24)-CT24 | DQ24: =-CR24+DP24/10^6 | DR24: =SUM(E24,K24,Q24,W24,AE24,AM24,AV24,BD24,BL24,BU24,CC24,CK24)-CS24 | DS24: =SUM(D24,J24,P24,V24,AD24,AL24,AU24,BC24,,BN24,BV24,CD24,CL24)-CT24 | DV24: =DU24-CJ24 | DX24: =(CS24-CZ24)*10^6 | DY24: =(CT24-DC24)*10^6 | DZ24: =(CW24-DD24)*10^6
B25: EAU RESIDENCES | C25: Opex19 | G25: 0 | M25: 0 | S25: 0 | AA25: 0 | AI25: 0 | CR25: =SUMIF($D$5:$CQ$5,CR$5,$D25:$CQ25) | CS25: =SUMIF($D$5:$CQ$5,CS$5,$D25:$CQ25) | CT25: =SUMIF($D$5:$CQ$5,CT$5,$D25:$CQ25)+SUMIF($D$5:$BI$5,CR$5,$D25:$BI25) | CU25: =+CR25-CS25 | CV25: =+CR25-CT25 | CW25: =SUMIF($D$5:$CQ$5,CW$5,$D25:$CQ25) | CX25: =IFERROR(CR25/CW25-1, "-") | CZ25: 0 | DA25: 0 | DD25: 0 | DJ25: =SUM(D25,J25,P25,V25,AD25,AL25,AU25,BC25,BK25,BT25,CB25,CJ25)-CR25 | DK25: =SUM(E25,K25,Q25,W25,AE25,AM25,AV25,BD25,BL25,BU25,CC25,CK25)-CS25 | DL25: =SUM(G25,M25,S25,AA25,AI25,AR25,AZ25,BH25,BQ25,BY25,CG25,CO25)-CW25 | DM25: =SUM(D25,J25,P25,V25,AD25,AL25,AU25,BC25,,BN25,BV25,CD25,CL25)-CT25 | DQ25: =-CR25+DP25/10^6 | DR25: =SUM(E25,K25,Q25,W25,AE25,AM25,AV25,BD25,BL25,BU25,CC25,CK25)-CS25 | DS25: =SUM(D25,J25,P25,V25,AD25,AL25,AU25,BC25,,BN25,BV25,CD25,CL25)-CT25 | DV25: =DU25-CJ25 | DX25: =(CS25-CZ25)*10^6 | DY25: =(CT25-DC25)*10^6 | DZ25: =(CW25-DD25)*10^6
B26: ELECTRICITE RESIDENCES | C26: Opex20 | G26: 0 | M26: 0 | S26: 0 | AA26: 0 | AI26: 0 | CR26: =SUMIF($D$5:$CQ$5,CR$5,$D26:$CQ26) | CS26: =SUMIF($D$5:$CQ$5,CS$5,$D26:$CQ26) | CT26: =SUMIF($D$5:$CQ$5,CT$5,$D26:$CQ26)+SUMIF($D$5:$BI$5,CR$5,$D26:$BI26) | CU26: =+CR26-CS26 | CV26: =+CR26-CT26 | CW26: =SUMIF($D$5:$CQ$5,CW$5,$D26:$CQ26) | CX26: =IFERROR(CR26/CW26-1, "-") | CZ26: 0 | DA26: 0 | DD26: 0 | DJ26: =SUM(D26,J26,P26,V26,AD26,AL26,AU26,BC26,BK26,BT26,CB26,CJ26)-CR26 | DK26: =SUM(E26,K26,Q26,W26,AE26,AM26,AV26,BD26,BL26,BU26,CC26,CK26)-CS26 | DL26: =SUM(G26,M26,S26,AA26,AI26,AR26,AZ26,BH26,BQ26,BY26,CG26,CO26)-CW26 | DM26: =SUM(D26,J26,P26,V26,AD26,AL26,AU26,BC26,,BN26,BV26,CD26,CL26)-CT26 | DQ26: =-CR26+DP26/10^6 | DR26: =SUM(E26,K26,Q26,W26,AE26,AM26,AV26,BD26,BL26,BU26,CC26,CK26)-CS26 | DS26: =SUM(D26,J26,P26,V26,AD26,AL26,AU26,BC26,,BN26,BV26,CD26,CL26)-CT26 | DV26: =DU26-CJ26 | DX26: =(CS26-CZ26)*10^6 | DY26: =(CT26-DC26)*10^6 | DZ26: =(CW26-DD26)*10^6
B27: LOYERS RESIDENCES | C27: Opex21 | G27: 0 | M27: 0 | S27: 0 | AA27: 0 | AI27: 0 | CR27: =SUMIF($D$5:$CQ$5,CR$5,$D27:$CQ27) | CS27: =SUMIF($D$5:$CQ$5,CS$5,$D27:$CQ27) | CT27: =SUMIF($D$5:$CQ$5,CT$5,$D27:$CQ27)+SUMIF($D$5:$BI$5,CR$5,$D27:$BI27) | CU27: =+CR27-CS27 | CV27: =+CR27-CT27 | CW27: =SUMIF($D$5:$CQ$5,CW$5,$D27:$CQ27) | CX27: =IFERROR(CR27/CW27-1, "-") | CZ27: 0 | DA27: 0 | DD27: 0 | DJ27: =SUM(D27,J27,P27,V27,AD27,AL27,AU27,BC27,BK27,BT27,CB27,CJ27)-CR27 | DK27: =SUM(E27,K27,Q27,W27,AE27,AM27,AV27,BD27,BL27,BU27,CC27,CK27)-CS27 | DL27: =SUM(G27,M27,S27,AA27,AI27,AR27,AZ27,BH27,BQ27,BY27,CG27,CO27)-CW27 | DM27: =SUM(D27,J27,P27,V27,AD27,AL27,AU27,BC27,,BN27,BV27,CD27,CL27)-CT27 | DQ27: =-CR27+DP27/10^6 | DR27: =SUM(E27,K27,Q27,W27,AE27,AM27,AV27,BD27,BL27,BU27,CC27,CK27)-CS27 | DS27: =SUM(D27,J27,P27,V27,AD27,AL27,AU27,BC27,,BN27,BV27,CD27,CL27)-CT27 | DV27: =DU27-CJ27 | DX27: =(CS27-CZ27)*10^6 | DY27: =(CT27-DC27)*10^6 | DZ27: =(CW27-DD27)*10^6
B28: ENTRETIEN ET REPARATIONS RESID | C28: Opex22 | G28: 0 | M28: 0 | S28: 0 | AA28: 0 | AI28: 0 | CR28: =SUMIF($D$5:$CQ$5,CR$5,$D28:$CQ28) | CS28: =SUMIF($D$5:$CQ$5,CS$5,$D28:$CQ28) | CT28: =SUMIF($D$5:$CQ$5,CT$5,$D28:$CQ28)+SUMIF($D$5:$BI$5,CR$5,$D28:$BI28) | CU28: =+CR28-CS28 | CV28: =+CR28-CT28 | CW28: =SUMIF($D$5:$CQ$5,CW$5,$D28:$CQ28) | CX28: =IFERROR(CR28/CW28-1, "-") | CZ28: 0 | DA28: 0 | DD28: 0 | DJ28: =SUM(D28,J28,P28,V28,AD28,AL28,AU28,BC28,BK28,BT28,CB28,CJ28)-CR28 | DK28: =SUM(E28,K28,Q28,W28,AE28,AM28,AV28,BD28,BL28,BU28,CC28,CK28)-CS28 | DL28: =SUM(G28,M28,S28,AA28,AI28,AR28,AZ28,BH28,BQ28,BY28,CG28,CO28)-CW28 | DM28: =SUM(D28,J28,P28,V28,AD28,AL28,AU28,BC28,,BN28,BV28,CD28,CL28)-CT28 | DQ28: =-CR28+DP28/10^6 | DR28: =SUM(E28,K28,Q28,W28,AE28,AM28,AV28,BD28,BL28,BU28,CC28,CK28)-CS28 | DS28: =SUM(D28,J28,P28,V28,AD28,AL28,AU28,BC28,,BN28,BV28,CD28,CL28)-CT28 | DV28: =DU28-CJ28 | DX28: =(CS28-CZ28)*10^6 | DY28: =(CT28-DC28)*10^6 | DZ28: =(CW28-DD28)*10^6
B29: FRAIS DE TELEPHONE RESIDENCES | C29: Opex23 | G29: 0 | M29: 0 | S29: 0 | AA29: 0 | AI29: 0 | CR29: =SUMIF($D$5:$CQ$5,CR$5,$D29:$CQ29) | CS29: =SUMIF($D$5:$CQ$5,CS$5,$D29:$CQ29) | CT29: =SUMIF($D$5:$CQ$5,CT$5,$D29:$CQ29)+SUMIF($D$5:$BI$5,CR$5,$D29:$BI29) | CU29: =+CR29-CS29 | CV29: =+CR29-CT29 | CW29: =SUMIF($D$5:$CQ$5,CW$5,$D29:$CQ29) | CX29: =IFERROR(CR29/CW29-1, "-") | CZ29: 0 | DA29: 0 | DD29: 0 | DJ29: =SUM(D29,J29,P29,V29,AD29,AL29,AU29,BC29,BK29,BT29,CB29,CJ29)-CR29 | DK29: =SUM(E29,K29,Q29,W29,AE29,AM29,AV29,BD29,BL29,BU29,CC29,CK29)-CS29 | DL29: =SUM(G29,M29,S29,AA29,AI29,AR29,AZ29,BH29,BQ29,BY29,CG29,CO29)-CW29 | DM29: =SUM(D29,J29,P29,V29,AD29,AL29,AU29,BC29,,BN29,BV29,CD29,CL29)-CT29 | DQ29: =-CR29+DP29/10^6 | DR29: =SUM(E29,K29,Q29,W29,AE29,AM29,AV29,BD29,BL29,BU29,CC29,CK29)-CS29 | DS29: =SUM(D29,J29,P29,V29,AD29,AL29,AU29,BC29,,BN29,BV29,CD29,CL29)-CT29 | DV29: =DU29-CJ29 | DX29: =(CS29-CZ29)*10^6 | DY29: =(CT29-DC29)*10^6 | DZ29: =(CW29-DD29)*10^6
B30: PRIMES ET GRATIFICATIONS PERSO | C30: Opex24 | G30: 0 | M30: 0 | S30: 0 | AA30: 0 | AI30: 0 | CR30: =SUMIF($D$5:$CQ$5,CR$5,$D30:$CQ30) | CS30: =SUMIF($D$5:$CQ$5,CS$5,$D30:$CQ30) | CT30: =SUMIF($D$5:$CQ$5,CT$5,$D30:$CQ30)+SUMIF($D$5:$BI$5,CR$5,$D30:$BI30) | CU30: =+CR30-CS30 | CV30: =+CR30-CT30 | CW30: =SUMIF($D$5:$CQ$5,CW$5,$D30:$CQ30) | CX30: =IFERROR(CR30/CW30-1, "-") | CZ30: 0 | DA30: 0 | DD30: 0 | DJ30: =SUM(D30,J30,P30,V30,AD30,AL30,AU30,BC30,BK30,BT30,CB30,CJ30)-CR30 | DK30: =SUM(E30,K30,Q30,W30,AE30,AM30,AV30,BD30,BL30,BU30,CC30,CK30)-CS30 | DL30: =SUM(G30,M30,S30,AA30,AI30,AR30,AZ30,BH30,BQ30,BY30,CG30,CO30)-CW30 | DM30: =SUM(D30,J30,P30,V30,AD30,AL30,AU30,BC30,,BN30,BV30,CD30,CL30)-CT30 | DP30: 0 | DQ30: =-CR30+DP30/10^6 | DR30: =SUM(E30,K30,Q30,W30,AE30,AM30,AV30,BD30,BL30,BU30,CC30,CK30)-CS30 | DS30: =SUM(D30,J30,P30,V30,AD30,AL30,AU30,BC30,,BN30,BV30,CD30,CL30)-CT30 | DV30: =DU30-CJ30 | DX30: =(CS30-CZ30)*10^6 | DY30: =(CT30-DC30)*10^6 | DZ30: =(CW30-DD30)*10^6
B31: INDEMNITES DE LICENCIEMENT PER | C31: Opex25 | G31: 0 | M31: 0 | S31: 0 | AA31: 0 | AI31: 0 | CR31: =SUMIF($D$5:$CQ$5,CR$5,$D31:$CQ31) | CS31: =SUMIF($D$5:$CQ$5,CS$5,$D31:$CQ31) | CT31: =SUMIF($D$5:$CQ$5,CT$5,$D31:$CQ31)+SUMIF($D$5:$BI$5,CR$5,$D31:$BI31) | CU31: =+CR31-CS31 | CV31: =+CR31-CT31 | CW31: =SUMIF($D$5:$CQ$5,CW$5,$D31:$CQ31) | CX31: =IFERROR(CR31/CW31-1, "-") | CZ31: 0 | DA31: 0 | DD31: 0 | DJ31: =SUM(D31,J31,P31,V31,AD31,AL31,AU31,BC31,BK31,BT31,CB31,CJ31)-CR31 | DK31: =SUM(E31,K31,Q31,W31,AE31,AM31,AV31,BD31,BL31,BU31,CC31,CK31)-CS31 | DL31: =SUM(G31,M31,S31,AA31,AI31,AR31,AZ31,BH31,BQ31,BY31,CG31,CO31)-CW31 | DM31: =SUM(D31,J31,P31,V31,AD31,AL31,AU31,BC31,,BN31,BV31,CD31,CL31)-CT31 | DQ31: =-CR31+DP31/10^6 | DR31: =SUM(E31,K31,Q31,W31,AE31,AM31,AV31,BD31,BL31,BU31,CC31,CK31)-CS31 | DS31: =SUM(D31,J31,P31,V31,AD31,AL31,AU31,BC31,,BN31,BV31,CD31,CL31)-CT31 | DV31: =DU31-CJ31 | DX31: =(CS31-CZ31)*10^6 | DY31: =(CT31-DC31)*10^6 | DZ31: =(CW31-DD31)*10^6
B32: AVANTAGES EN NATURE PERSONNEL | C32: Opex26 | G32: 0 | M32: 0 | S32: 0 | AA32: 0 | AI32: 0 | CR32: =SUMIF($D$5:$CQ$5,CR$5,$D32:$CQ32) | CS32: =SUMIF($D$5:$CQ$5,CS$5,$D32:$CQ32) | CT32: =SUMIF($D$5:$CQ$5,CT$5,$D32:$CQ32)+SUMIF($D$5:$BI$5,CR$5,$D32:$BI32) | CU32: =+CR32-CS32 | CV32: =+CR32-CT32 | CW32: =SUMIF($D$5:$CQ$5,CW$5,$D32:$CQ32) | CX32: =IFERROR(CR32/CW32-1, "-") | CZ32: 0 | DA32: 0 | DD32: 0 | DJ32: =SUM(D32,J32,P32,V32,AD32,AL32,AU32,BC32,BK32,BT32,CB32,CJ32)-CR32 | DK32: =SUM(E32,K32,Q32,W32,AE32,AM32,AV32,BD32,BL32,BU32,CC32,CK32)-CS32 | DL32: =SUM(G32,M32,S32,AA32,AI32,AR32,AZ32,BH32,BQ32,BY32,CG32,CO32)-CW32 | DM32: =SUM(D32,J32,P32,V32,AD32,AL32,AU32,BC32,,BN32,BV32,CD32,CL32)-CT32 | DQ32: =-CR32+DP32/10^6 | DR32: =SUM(E32,K32,Q32,W32,AE32,AM32,AV32,BD32,BL32,BU32,CC32,CK32)-CS32 | DS32: =SUM(D32,J32,P32,V32,AD32,AL32,AU32,BC32,,BN32,BV32,CD32,CL32)-CT32 | DV32: =DU32-CJ32 | DX32: =(CS32-CZ32)*10^6 | DY32: =(CT32-DC32)*10^6 | DZ32: =(CW32-DD32)*10^6
