Workbook
Name \e: #N/A
Name \M: #REF!
Name \M: #REF!
Name \M: #REF!
Name \M: #REF!
Name \p: '[1]cur q v plan'!#REF!
Name \p: '[1]cur q v plan'!#REF!
Name \p: '[1]cur q v plan'!#REF!
Name \p: '[1]cur q v plan'!#REF!
Name \r: #N/A
Name \t: #N/A
Name _: #REF!
Name _: #REF!
Name _: #REF!
Name _: #REF!
Name __: #REF!
Name __: #REF!
Name __: {"subs",#N/A,FALSE,"database ";"proportional",#N/A,FALSE,"database "}
Name __: #REF!
Name ___________B1: #N/A
Name ___________eng2: #N/A
Name ___________eng3: [0]!___________eng3
Name ___________eng3: #N/A
Name ___________eng3: [0]!___________eng3
Name ___________eng4: #N/A
Name __________B1: #N/A
Name __________eng2: #N/A
Name __________eng3: [0]!__________eng3
Name __________eng3: #N/A
Name __________eng3: [0]!__________eng3
Name __________eng4: #N/A
Name _________eng3: [0]!_________eng3
Name _________eng3: #N/A
Name _________eng3: [0]!_________eng3
Name ________eng3: [0]!________eng3
Name ________eng3: #N/A
Name ________eng3: [0]!________eng3
Name _______eng3: [0]!_______eng3
Name _______eng3: #N/A
Name _______eng3: [0]!_______eng3
Name ______eng3: [0]!______eng3
Name ______eng3: #N/A
Name ______eng3: [0]!______eng3
Name ______FRF4: '[6]FX Rates'!$G$10
Name ______GBP4: '[6]FX Rates'!$G$9
Name _____0: #REF!
Name _____0: #REF!
Name _____0: #REF!
Name _____0: #REF!
Name _____12: #REF!
Name _____12: #REF!
Name _____12: #REF!
Name _____12: #REF!
Name _____14: #REF!
Name _____14: #REF!
Name _____14: #REF!
Name _____14: #REF!
Name _____16: #REF!
Name _____16: #REF!
Name _____16: #REF!

Sheet Cover
E15: MOOV AFRICA BENIN TBG
E17: 45627
A5603: 41743
A5604: 41743
A5605: 41744
A5606: 41744
A5607: 41744
A5608: 41744
A5609: 41744
A5610: 41744
A5611: 41744
A5612: 41744
A5613: 41744
A5614: 41744
A5615: 41744

Sheet P&L conso
A1: P&L consolidé | V1: =+V25+'Opex Consolidés'!V7 -> 0 | AD1: =+AD25+'Opex Consolidés'!AD7 -> 0 | AL1: =+AL25+'Opex Consolidés'!AL7 -> 0 | AU1: =#REF! -> #REF! | BC1: 577.07409 | BK1: =+BK25+'Opex Consolidés'!BD7 -> 0 | BT1: -68804439 | BW1: =BV4 -> 0 | CB1: =+CB25+'Opex Consolidés'!BU7 -> 0 | CJ1: =+CJ25+'Opex Consolidés'!CC7 -> 0 | CR1: =+CR25+'Opex Consolidés'!CR7 -> 0 | CS1: 17000.499 | CT1: =CT25+'Opex Consolidés'!CT7 -> 0 | CW1: 16458.089 | CZ1: 26225.79 | DC1: 8378.9625
E3: 0 | G3: 0 | AD3: 0 | CZ3: 0 | DD3: 0
D4: 45292 | J4: 45323 | P4: 45352 | V4: 45383 | AD4: 45413 | AL4: 45444 | AU4: 45474 | BC4: 45505 | BK4: 45536 | BT4: 45566 | CB4: 45597 | CJ4: 45627 | CR4: CUMUL | CZ4: ANNUEL
A5: (En Millions ML) | D5: 2024 Réel | E5: 2024 Budget | F5: Ecart / Budget | G5: 2023 Réel | H5: Evol % | J5: 2024 Réel | K5: 2024 Budget | L5: Ecart / Budget | M5: 2023 Réel | N5: Evol % | P5: 2024 Réel | Q5: 2024 Budget | R5: Ecart / Budget | S5: 2023 Réel | T5: Evol % | V5: 2024 Réel | W5: 2024 Budget | X5: 2024 Actu1 | Y5: Ecart / Budget | Z5: Ecart / Actu1 | AA5: 2023 Réel | AB5: Evol % | AD5: 2024 Réel | AE5: 2024 Budget | AF5: 2024 Actu1 | AG5: Ecart / Budget | AH5: Ecart / Actu1 | AI5: 2023 Réel | AJ5: Evol % | AL5: 2024 Réel | AM5: 2024 Budget | AN5: 2024 Actu1 | AO5: 2024 Actu2 | AP5: Ecart / Budget | AQ5: Ecart / Actu1 | AR5: 2023 Réel | AS5: Evol % | AU5: 2024 Réel | AV5: 2024 Budget | AW5: 2024 Actu2 | AX5: Ecart / Budget | AY5: Ecart / Actu2 | AZ5: 2023 Réel | BA5: Evol % | BC5: 2024 Réel | BD5: 2024 Budget | BE5: 2024 Actu2 | BF5: Ecart / Budget | BG5: Ecart / Actu2 | BH5: 2023 Réel | BI5: Evol % | BK5: 2024 Réel | BL5: 2024 Budget | BM5: 2024 Actu2 | BN5: 2024 Actu3 | BO5: Ecart / Budget | BP5: Ecart / Actu2 | BQ5: 2023 Réel | BR5: Evol % | BT5: 2024 Réel | BU5: 2024 Budget | BV5: 2024 Actu3 | BW5: Ecart / Budget | BX5: Ecart / Actu3 | BY5: 2023 Réel | BZ5: Evol % | CB5: 2024 Réel | CC5: 2024 Budget | CD5: 2024 Actu3 | CE5: Ecart / Budget | CF5: Ecart / Actu3 | CG5: 2023 Réel | CH5: Evol % | CJ5: 2024 Réel | CK5: 2024 Budget | CL5: 2024 Actu3 | CM5: Ecart / Budget | CN5: Ecart / Actu3 | CO5: 2023 Réel | CP5: Evol % | CR5: 2024 Réel | CS5: 2024 Budget | CT5: 2024 Actu3 | CU5: Ecart / Budget | CV5: Ecart / Actu3 | CW5: 2023 Réel | CX5: Evol % | CZ5: 2024 Budget | DA5: 2024 Actu1 | DB5: 2024 Actu2 | DC5: 2024 Actu3 | DD5: 2023 Réel | DE5: Bud / 2023 (%) | DF5: Actu 1 / 2023 (%) | DG5: Actu 2 / 2023 (%) | DH5: Actu3 / 2023 (%)
A7: Chiffre d'affaires | C7: PL1 | CU7: =+CR7-CS7 -> 0 | CV7: =+CR7-CT7 -> 0 | CX7: =IFERROR(CR7/CW7-1, "-") -> - | DE7: =CZ7/DD7-1 -> #DIV/0! | DF7: =DA7/DD7-1 -> #DIV/0! | DG7: =DB7/DD7-1 -> #DIV/0! | DH7: =DC7/DD7-1 -> #DIV/0!
A8: Fixe & Internet | C8: PL2 | CU8: =+CR8-CS8 -> 0 | CV8: =+CR8-CT8 -> 0 | CX8: =IFERROR(CR8/CW8-1, "-") -> -
A9: Mobile | C9: PL3 | CU9: =+CR9-CS9 -> 0 | CV9: =+CR9-CT9 -> 0 | CX9: =IFERROR(CR9/CW9-1, "-") -> - | DE9: =CZ9/DD9-1 -> #DIV/0! | DG9: =DB9/DD9-1 -> #DIV/0! | DH9: =DC9/DD9-1 -> #DIV/0!
A10: Intercompagnie Mobile | C10: PL4 | CU10: =+CR10-CS10 -> 0 | CV10: =+CR10-CT10 -> 0 | CX10: =IFERROR(CR10/CW10-1, "-") -> - | DE10: =CZ10/DD10-1 -> #DIV/0! | DF10: =DA10/DD10-1 -> #DIV/0! | DG10: =DB10/DD10-1 -> #DIV/0! | DH10: =DC10/DD10-1 -> #DIV/0!
C11: PL5 | CU11: =+CR11-CS11 -> 0 | CV11: =+CR11-CT11 -> 0 | CX11: =IFERROR(CR11/CW11-1, "-") -> -
A12: Intercompagnie | C12: PL6 | CU12: =+CR12-CS12 -> 0 | CV12: =+CR12-CT12 -> 0 | CX12: =IFERROR(CR12/CW12-1, "-") -> - | DE12: =CZ12/DD12-1 -> #DIV/0!
A13: dont Intercompagnie hors trafic | C13: PL7 | CU13: =+CR13-CS13 -> 0 | CV13: =+CR13-CT13 -> 0 | CX13: =IFERROR(CR13/CW13-1, "-") -> - | DE13: =CZ13/DD13-1 -> #DIV/0!
C14: PL8 | CU14: =+CR14-CS14 -> 0 | CV14: =+CR14-CT14 -> 0 | CX14: =IFERROR(CR14/CW14-1, "-") -> - | DE14: =CZ14/DD14-1 -> #DIV/0!
A15: Coût des ventes | C15: PL9 | CU15: =+CR15-CS15 -> 0 | CV15: =+CR15-CT15 -> 0 | CX15: =IFERROR(CR15/CW15-1, "-") -> - | DE15: =(CZ15/DD15-1) -> #DIV/0! | DF15: =DA15/DD15-1 -> #DIV/0! | DG15: =DB15/DD15-1 -> #DIV/0! | DH15: =DC15/DD15-1 -> #DIV/0!
A16: Fixe & Internet | C16: PL10 | CU16: =+CR16-CS16 -> 0 | CV16: =+CR16-CT16 -> 0 | CX16: =IFERROR(CR16/CW16-1, "-") -> - | DE16: =CZ16/DD16-1 -> #DIV/0!
A17: Mobile | C17: PL11 | CU17: =+CR17-CS17 -> 0 | CV17: =+CR17-CT17 -> 0 | CX17: =IFERROR(CR17/CW17-1, "-") -> - | DE17: =(CZ17/DD17-1) -> #DIV/0! | DF17: =DA17/DD17-1 -> #DIV/0! | DG17: =DB17/DD17-1 -> #DIV/0! | DH17: =DC17/DD17-1 -> #DIV/0!
A18: Intercompagnie Mobile | C18: PL12 | CU18: =+CR18-CS18 -> 0 | CV18: =+CR18-CT18 -> 0 | CX18: =IFERROR(CR18/CW18-1, "-") -> - | DE18: =(CZ18/DD18-1) -> #DIV/0! | DF18: =DA18/DD18-1 -> #DIV/0! | DG18: =DB18/DD18-1 -> #DIV/0! | DH18: =DC18/DD18-1 -> #DIV/0!
C19: PL13 | CU19: =+CR19-CS19 -> 0 | CV19: =+CR19-CT19 -> 0 | CX19: =IFERROR(CR19/CW19-1, "-") -> -
A20: Marge Brute | C20: PL14 | CU20: =+CR20-CS20 -> 0 | CV20: =+CR20-CT20 -> 0 | CX20: =IFERROR(CR20/CW20-1, "-") -> - | DE20: =CZ20/DD20-1 -> #DIV/0! | DF20: =DA20/DD20-1 -> #DIV/0! | DG20: =DB20/DD20-1 -> #DIV/0! | DH20: =DC20/DD20-1 -> #DIV/0!
A21: % CA | C21: PL15 | CU21: =+(CR21-CS21) -> 0 | CV21: =+(CR21-CT21) -> 0 | CX21: =IFERROR(CR21/CW21-1, "-") -> - | DE21: =+(CZ21-DD21) -> 0 | DF21: =DA21/DD21-1 -> #DIV/0! | DG21: =DB21/DD21-1 -> #DIV/0! | DH21: =DC21/DD21-1 -> #DIV/0!
A22: Fixe & Internet | C22: PL16 | CU22: =+CR22-CS22 -> 0 | CV22: =+CR22-CT22 -> 0 | CX22: =IFERROR(CR22/CW22-1, "-") -> - | DE22: =CZ22/DD22-1 -> #DIV/0!
A23: Mobile | C23: PL17 | CU23: =+CR23-CS23 -> 0 | CV23: =+CR23-CT23 -> 0 | CX23: =IFERROR(CR23/CW23-1, "-") -> - | DE23: =(CZ23/DD23-1) -> #DIV/0! | DF23: =DA23/DD23-1 -> #DIV/0! | DG23: =DB23/DD23-1 -> #DIV/0! | DH23: =DC23/DD23-1 -> #DIV/0!
C24: PL18 | CU24: =+CR24-CS24 -> 0 | CV24: =+CR24-CT24 -> 0 | CX24: =IFERROR(CR24/CW24-1, "-") -> -
A25: Coûts opérationnels | C25: PL19 | CU25: =+CR25-CS25 -> 0 | CV25: =+CR25-CT25 -> 0 | CX25: =IFERROR(CR25/CW25-1, "-") -> - | DE25: =CZ25/DD25-1 -> #DIV/0! | DF25: =DA25/DD25-1 -> #DIV/0! | DG25: =DB25/DD25-1 -> #DIV/0! | DH25: =DC25/DD25-1 -> #DIV/0!
A26: Fixe & Internet | C26: PL20 | CU26: =+CR26-CS26 -> 0 | CV26: =+CR26-CT26 -> 0 | CX26: =IFERROR(CR26/CW26-1, "-") -> - | DE26: =CZ26/DD26-1 -> #DIV/0!
A27: Intercompagnie Fixe & Internet | C27: PL21 | CU27: =+CR27-CS27 -> 0 | CV27: =+CR27-CT27 -> 0 | CX27: =IFERROR(CR27/CW27-1, "-") -> - | DE27: =CZ27/DD27-1 -> #DIV/0!
A28: Mobile | C28: PL22 | CU28: =+CR28-CS28 -> 0 | CV28: =+CR28-CT28 -> 0 | CX28: =IFERROR(CR28/CW28-1, "-") -> - | DE28: =CZ28/DD28-1 -> #DIV/0! | DF28: =DA28/DD28-1 -> #DIV/0! | DG28: =DB28/DD28-1 -> #DIV/0! | DH28: =DC28/DD28-1 -> #DIV/0!
A29: Intercompagnie Mobile | C29: PL23 | CU29: =+CR29-CS29 -> 0 | CV29: =+CR29-CT29 -> 0 | CX29: =IFERROR(CR29/CW29-1, "-") -> - | DE29: =CZ29/DD29-1 -> #DIV/0! | DF29: =DA29/DD29-1 -> #DIV/0! | DH29: =DC29/DD29-1 -> #DIV/0!
C30: PL24 | CX30: =IFERROR(CR30/CW30-1, "-") -> -
A31: EBITDA | C31: PL25 | CU31: =+CR31-CS31 -> 0 | CV31: =+CR31-CT31 -> 0 | CX31: =IFERROR(CR31/CW31-1, "-") -> - | DE31: =CZ31/DD31-1 -> #DIV/0! | DF31: =DA31/DD31-1 -> #DIV/0! | DG31: =DB31/DD31-1 -> #DIV/0! | DH31: =DC31/DD31-1 -> #DIV/0!
A32: % CA | C32: PL26 | CU32: =+(CR32-CS32) -> 0 | CV32: =+(CR32-CT32) -> 0 | CX32: =IFERROR(CR32/CW32-1, "-") -> - | DE32: =(CZ32-DD32) -> 0 | DF32: =DA32/DD32-1 -> #DIV/0! | DG32: =DB32/DD32-1 -> #DIV/0! | DH32: =DC32/DD32-1 -> #DIV/0!
A33: Fixe & Internet | C33: PL27 | CU33: =+CR33-CS33 -> 0 | CV33: =+CR33-CT33 -> 0 | CX33: =IFERROR(CR33/CW33-1, "-") -> - | DE33: =CZ33/DD33-1 -> #DIV/0!
A34: Mobile | C34: PL28 | CU34: =+CR34-CS34 -> 0 | CV34: =+CR34-CT34 -> 0 | CX34: =IFERROR(CR34/CW34-1, "-") -> - | DE34: =CZ34/DD34-1 -> #DIV/0! | DF34: =DA34/DD34-1 -> #DIV/0! | DG34: =DB34/DD34-1 -> #DIV/0! | DH34: =DC34/DD34-1 -> #DIV/0!
C35: PL29 | CU35: =+CR35-CS35 -> 0 | CV35: =+CR35-CT35 -> 0 | CX35: =IFERROR(CR35/CW35-1, "-") -> -
A36: Amortissements et déprec. Courant | C36: PL30 | CU36: =+CR36-CS36 -> 0 | CV36: =+CR36-CT36 -> 0 | CX36: =IFERROR(CR36/CW36-1, "-") -> - | DE36: =CZ36/DD36-1 -> #DIV/0! | DF36: =DA36/DD36-1 -> #DIV/0! | DG36: =DB36/DD36-1 -> #DIV/0! | DH36: =DC36/DD36-1 -> #DIV/0!
A37: Dotations (Amo. et Pv NC) | C37: PL31 | CU37: =+CR37-CS37 -> 0 | CV37: =+CR37-CT37 -> 0 | CX37: =IFERROR(CR37/CW37-1, "-") -> -
A38: Autres non courant | C38: PL32 | CU38: =+CR38-CS38 -> 0 | CV38: =+CR38-CT38 -> 0 | CX38: =IFERROR(CR38/CW38-1, "-") -> -
A39: +/- value de cession d'immob. | C39: PL33 | CU39: =+CR39-CS39 -> 0 | CV39: =+CR39-CT39 -> 0 | CX39: =IFERROR(CR39/CW39-1, "-") -> -
C40: PL34 | CU40: =+CR40-CS40 -> 0 | CV40: =+CR40-CT40 -> 0 | CX40: =IFERROR(CR40/CW40-1, "-") -> -
A41: EBITA | C41: PL35 | CU41: =+CR41-CS41 -> 0 | CV41: =+CR41-CT41 -> 0 | CX41: =IFERROR(CR41/CW41-1, "-") -> - | DE41: =CZ41/DD41-1 -> #DIV/0! | DF41: =DA41/DD41-1 -> #DIV/0! | DG41: =DB41/DD41-1 -> #DIV/0! | DH41: =DC41/DD41-1 -> #DIV/0!
A42: % CA | C42: PL36 | CU42: =+(CR42-CS42)*100 -> 0 | CV42: =+(CR42-CT42)*100 -> 0 | CX42: =IFERROR(CR42/CW42-1, "-") -> - | DE42: =+(CZ42-DD42)*100 -> 0 | DF42: =DA42/DD42-1 -> #DIV/0! | DG42: =DB42/DD42-1 -> #DIV/0! | DH42: =DC42/DD42-1 -> #DIV/0!
...

Sheet Opex Consolidés
J1: 6444110418 | Y1: =Y7/W7 -> #DIV/0! | Z1: =Z7/X7 -> #DIV/0! | AU1: -20648636 | AW1: 12.127701 | CR1: =65151.9-CR7 -> 65151.9 | DP1: 0
A2: Opex Consolidés | J2: 419560633 | K2: 0 | P2: 21468044 | W2: 839.68735 | X2: 0 | AD2: 0 | AE2: 0 | AF2: 2024 Réel | AO2: 0 | AU2: 0 | BN2: 0 | BP2: 0 | CR2: =CS7+'P&L conso'!CS25 -> 0 | CT2: =CT7+'P&L conso'!CT25 -> 0 | DP2: 10167534 | DQ2: 0 | DR2: 0 | DU2: 0
E3: 0 | G3: 0 | CZ3: 0 | DQ3: 295188041
D4: 45292 | J4: 45323 | P4: 45352 | V4: 45383 | AD4: 45413 | AL4: 45444 | AU4: 45474 | BC4: 45505 | BK4: 45536 | BT4: 45566 | CB4: 45597 | CJ4: 45627 | CR4: CUMUL | CZ4: ANNUEL
B5: (En Millions ML) | D5: 2024 Réel | E5: 2024 Budget | F5: Ecart / Budget | G5: 2023 Réel | H5: Evol % | J5: 2024 Réel | K5: 2024 Budget | L5: Ecart / Budget | M5: 2023 Réel | N5: Evol % | P5: 2024 Réel | Q5: 2024 Budget | R5: Ecart / Budget | S5: 2023 Réel | T5: Evol % | V5: 2024 Réel | W5: 2024 Budget | X5: 2024 Actu1 | Y5: Ecart / Budget | Z5: Ecart / Actu1 | AA5: 2023 Réel | AB5: Evol % | AD5: 2024 Réel | AE5: 2024 Budget | AF5: 2024 Actu1 | AG5: Ecart / Budget | AH5: Ecart / Actu1 | AI5: 2023 Réel | AJ5: Evol % | AL5: 2024 Réel | AM5: 2024 Budget | AN5: 2024 Actu1 | AO5: 2024 Actu2 | AP5: Ecart / Budget | AQ5: Ecart / Actu1 | AR5: 2023 Réel | AS5: Evol % | AU5: 2024 Réel | AV5: 2024 Budget | AW5: 2024 Actu2 | AX5: Ecart / Budget | AY5: Ecart / Actu2 | AZ5: 2023 Réel | BA5: Evol % | BC5: 2024 Réel | BD5: 2024 Budget | BE5: 2024 Actu2 | BF5: Ecart / Budget | BG5: Ecart / Actu2 | BH5: 2023 Réel | BI5: Evol % | BK5: 2024 Réel | BL5: 2024 Budget | BM5: 2024 Actu2 | BN5: 2024 Actu3 | BO5: Ecart / Budget | BP5: Ecart / Actu2 | BQ5: 2023 Réel | BR5: Evol % | BT5: 2024 Réel | BU5: 2024 Budget | BV5: 2024 Actu3 | BW5: Ecart / Budget | BX5: Ecart / Actu3 | BY5: 2023 Réel | BZ5: Evol % | CB5: 2024 Réel | CC5: 2024 Budget | CD5: 2024 Actu3 | CE5: Ecart / Budget | CF5: Ecart / Actu3 | CG5: 2023 Réel | CH5: Evol % | CJ5: 2024 Réel | CK5: 2024 Budget | CL5: 2024 Actu3 | CM5: Ecart / Budget | CN5: Ecart / Actu3 | CO5: 2023 Réel | CP5: Evol % | CR5: 2024 Réel | CS5: 2024 Budget | CT5: 2024 Actu3 | CU5: Ecart / Budget | CV5: Ecart / Actu3 | CW5: 2023 Réel | CX5: Evol % | CZ5: 2024 Budget | DA5: 2024 Actu1 | DB5: 2024 Actu2 | DC5: 2024 Actu3 | DD5: 2023 Réel | DE5: Bud / 2023 (%) | DF5: Actu 1 / 2023 (%) | DG5: Actu 2 / 2023 (%) | DH5: Actu3 / 2023 (%) | DJ5: 2024 Réel | DK5: 2024 Budget | DL5: 2023 Réel | DM5: Actu | DP5: 2024 Réel
DJ6: =SUM(D6,J6,P6,V6,AD6,AL6,AU6,BC6,BK6,BT6,CB6,CJ6)-CR6 -> 0 | DK6: =SUM(E6,K6,Q6,W6,AE6,AM6,AV6,BD6,BL6,BU6,CC6,CK6)-CS6 -> 0 | DL6: =SUM(G6,M6,S6,AA6,AI6,AR6,AZ6,BH6,BQ6,BY6,CG6,CO6)-CW6 -> 0 | DM6: =SUM(D6,J6,P6,V6,AD6,AL6,AU6,BC6,,BN6,BV6,CD6,CL6)-CT6 -> 0
B7: Total Opex | C7: Opex1 | CU7: =+CR7-CS7 -> 0 | CV7: =+CR7-CT7 -> 0 | CX7: =IFERROR(CR7/CW7-1, "-") -> - | DE7: =+CZ7/DD7-1 -> #DIV/0! | DF7: =+DA7/DD7-1 -> #DIV/0! | DG7: =+DB7/DD7-1 -> #DIV/0! | DH7: =+DC7/DD7-1 -> #DIV/0! | DJ7: =SUM(D7,J7,P7,V7,AD7,AL7,AU7,BC7,BK7,BT7,CB7,CJ7)-CR7 -> 0 | DK7: =SUM(E7,K7,Q7,W7,AE7,AM7,AV7,BD7,BL7,BU7,CC7,CK7)-CS7 -> 0 | DL7: =SUM(G7,M7,S7,AA7,AI7,AR7,AZ7,BH7,BQ7,BY7,CG7,CO7)-CW7 -> 0 | DM7: =SUM(D7,J7,P7,V7,AD7,AL7,AU7,BC7,,BN7,BV7,CD7,CL7)-CT7 -> 0 | DP7: =SUM(DP9,DP40,DP57,DP113,DP167,DP184,DP201) -> #VALUE! | DQ7: =-CR7+DP7/10^6 -> #VALUE! | DR7: =SUM(E7,K7,Q7,W7,AE7,AM7,AV7,BD7,BL7,BU7,CC7,CK7)-CS7 -> 0 | DS7: =SUM(D7,J7,P7,V7,AD7,AL7,AU7,BC7,,BN7,BV7,CD7,CL7)-CT7 -> 0 | DU7: 6509.7557 | DV7: =DU7-CJ7 -> 6509.7557
C8: Opex2 | CX8: =IFERROR(CR8/CW8-1, "-") -> - | DJ8: =SUM(D8,J8,P8,V8,AD8,AL8,AU8,BC8,BK8,BT8,CB8,CJ8)-CR8 -> 0 | DK8: =SUM(E8,K8,Q8,W8,AE8,AM8,AV8,BD8,BL8,BU8,CC8,CK8)-CS8 -> 0 | DL8: =SUM(G8,M8,S8,AA8,AI8,AR8,AZ8,BH8,BQ8,BY8,CG8,CO8)-CW8 -> 0 | DM8: =SUM(D8,J8,P8,V8,AD8,AL8,AU8,BC8,,BN8,BV8,CD8,CL8)-CT8 -> 0 | DQ8: =-CR8+DP8/10^6 -> 0 | DR8: =SUM(E8,K8,Q8,W8,AE8,AM8,AV8,BD8,BL8,BU8,CC8,CK8)-CS8 -> 0 | DS8: =SUM(D8,J8,P8,V8,AD8,AL8,AU8,BC8,,BN8,BV8,CD8,CL8)-CT8 -> 0 | DV8: =DU8-CJ8 -> 0 | DX8: =CS8-CZ8 -> 0 | DY8: =CT8-DC8 -> 0 | DZ8: =CW8-DD8 -> 0
B9: Personnel | C9: Opex3 | CU9: =+CR9-CS9 -> 0 | CV9: =+CR9-CT9 -> 0 | CX9: =IFERROR(CR9/CW9-1, "-") -> - | DE9: =+CZ9/DD9-1 -> #DIV/0! | DF9: =+DA9/DD9-1 -> #DIV/0! | DG9: =+DB9/DD9-1 -> #DIV/0! | DH9: =+DC9/DD9-1 -> #DIV/0! | DJ9: =SUM(D9,J9,P9,V9,AD9,AL9,AU9,BC9,BK9,BT9,CB9,CJ9)-CR9 -> 0 | DK9: =SUM(E9,K9,Q9,W9,AE9,AM9,AV9,BD9,BL9,BU9,CC9,CK9)-CS9 -> 0 | DL9: =SUM(G9,M9,S9,AA9,AI9,AR9,AZ9,BH9,BQ9,BY9,CG9,CO9)-CW9 -> 0 | DM9: =SUM(D9,J9,P9,V9,AD9,AL9,AU9,BC9,,BN9,BV9,CD9,CL9)-CT9 -> 0 | DP9: =SUM(DP10:DP38) -> #VALUE! | DQ9: =-CR9+DP9/10^6 -> #VALUE! | DR9: =SUM(E9,K9,Q9,W9,AE9,AM9,AV9,BD9,BL9,BU9,CC9,CK9)-CS9 -> 0 | DS9: =SUM(D9,J9,P9,V9,AD9,AL9,AU9,BC9,,BN9,BV9,CD9,CL9)-CT9 -> 0 | DU9: 438.17153 | DV9: =DU9-CJ9 -> 438.17153 | DX9: =(CS9-CZ9)*10^6 -> 0 | DY9: =(CT9-DC9)*10^6 -> 0 | DZ9: =(CW9-DD9)*10^6 -> 0
B10: TAXES SUR APPOINTEMENTS ET SAL | C10: Opex4 | CU10: =+CR10-CS10 -> 0 | CV10: =+CR10-CT10 -> 0 | CX10: =IFERROR(CR10/CW10-1, "-") -> - | DJ10: =SUM(D10,J10,P10,V10,AD10,AL10,AU10,BC10,BK10,BT10,CB10,CJ10)-CR10 -> 0 | DK10: =SUM(E10,K10,Q10,W10,AE10,AM10,AV10,BD10,BL10,BU10,CC10,CK10)-CS10 -> 0 | DL10: =SUM(G10,M10,S10,AA10,AI10,AR10,AZ10,BH10,BQ10,BY10,CG10,CO10)-CW10 -> 0 | DM10: =SUM(D10,J10,P10,V10,AD10,AL10,AU10,BC10,,BN10,BV10,CD10,CL10)-CT10 -> 0 | DQ10: =-CR10+DP10/10^6 -> 0 | DR10: =SUM(E10,K10,Q10,W10,AE10,AM10,AV10,BD10,BL10,BU10,CC10,CK10)-CS10 -> 0 | DS10: =SUM(D10,J10,P10,V10,AD10,AL10,AU10,BC10,,BN10,BV10,CD10,CL10)-CT10 -> 0 | DV10: =DU10-CJ10 -> 0 | DX10: =(CS10-CZ10)*10^6 -> 0 | DY10: =(CT10-DC10)*10^6 -> 0 | DZ10: =(CW10-DD10)*10^6 -> 0
B11: APPOINTEMENTS, SALAIRES PERSON | C11: Opex5 | CU11: =+CR11-CS11 -> 0 | CV11: =+CR11-CT11 -> 0 | CX11: =IFERROR(CR11/CW11-1, "-") -> - | DE11: =+CZ11/DD11-1 -> #DIV/0! | DF11: =+DA11/DD11-1 -> #DIV/0! | DG11: =+DB11/DD11-1 -> #DIV/0! | DH11: =+DC11/DD11-1 -> #DIV/0! | DJ11: =SUM(D11,J11,P11,V11,AD11,AL11,AU11,BC11,BK11,BT11,CB11,CJ11)-CR11 -> 0 | DK11: =SUM(E11,K11,Q11,W11,AE11,AM11,AV11,BD11,BL11,BU11,CC11,CK11)-CS11 -> 0 | DL11: =SUM(G11,M11,S11,AA11,AI11,AR11,AZ11,BH11,BQ11,BY11,CG11,CO11)-CW11 -> 0 | DM11: =SUM(D11,J11,P11,V11,AD11,AL11,AU11,BC11,,BN11,BV11,CD11,CL11)-CT11 -> 0 | DP11: =#VALUE! -> #VALUE! | DQ11: =-CR11+DP11/10^6 -> #VALUE! | DR11: =SUM(E11,K11,Q11,W11,AE11,AM11,AV11,BD11,BL11,BU11,CC11,CK11)-CS11 -> 0 | DS11: =SUM(D11,J11,P11,V11,AD11,AL11,AU11,BC11,,BN11,BV11,CD11,CL11)-CT11 -> 0 | DT11: =DQ11/11 -> #VALUE! | DU11: 262.72376 | DV11: =DU11-CJ11 -> 262.72376 | DX11: =(CS11-CZ11)*10^6 -> 0 | DY11: =(CT11-DC11)*10^6 -> 0 | DZ11: =(CW11-DD11)*10^6 -> 0
B12: CONGES PAYES PERSONNEL NATIONA | C12: Opex6 | CU12: =+CR12-CS12 -> 0 | CV12: =+CR12-CT12 -> 0 | CX12: =IFERROR(CR12/CW12-1, "-") -> - | DE12: =+CZ12/DD12-1 -> #DIV/0! | DF12: =+DA12/DD12-1 -> #DIV/0! | DG12: =+DB12/DD12-1 -> #DIV/0! | DH12: =+DC12/DD12-1 -> #DIV/0! | DJ12: =SUM(D12,J12,P12,V12,AD12,AL12,AU12,BC12,BK12,BT12,CB12,CJ12)-CR12 -> 0 | DK12: =SUM(E12,K12,Q12,W12,AE12,AM12,AV12,BD12,BL12,BU12,CC12,CK12)-CS12 -> 0 | DL12: =SUM(G12,M12,S12,AA12,AI12,AR12,AZ12,BH12,BQ12,BY12,CG12,CO12)-CW12 -> 0 | DM12: =SUM(D12,J12,P12,V12,AD12,AL12,AU12,BC12,,BN12,BV12,CD12,CL12)-CT12 -> 0 | DP12: =#VALUE! -> #VALUE! | DQ12: =-CR12+DP12/10^6 -> #VALUE! | DR12: =SUM(E12,K12,Q12,W12,AE12,AM12,AV12,BD12,BL12,BU12,CC12,CK12)-CS12 -> 0 | DS12: =SUM(D12,J12,P12,V12,AD12,AL12,AU12,BC12,,BN12,BV12,CD12,CL12)-CT12 -> 0 | DU12: -31.251393 | DV12: =DU12-CJ12 -> -31.251393 | DX12: =(CS12-CZ12)*10^6 -> 0 | DY12: =(CT12-DC12)*10^6 -> 0 | DZ12: =(CW12-DD12)*10^6 -> 0
B13: CHARGES SOCIALES S/ REMUNERATI | C13: Opex7 | CU13: =+CR13-CS13 -> 0 | CV13: =+CR13-CT13 -> 0 | CX13: =IFERROR(CR13/CW13-1, "-") -> - | DE13: =+CZ13/DD13-1 -> #DIV/0! | DF13: =+DA13/DD13-1 -> #DIV/0! | DG13: =+DB13/DD13-1 -> #DIV/0! | DH13: =+DC13/DD13-1 -> #DIV/0! | DJ13: =SUM(D13,J13,P13,V13,AD13,AL13,AU13,BC13,BK13,BT13,CB13,CJ13)-CR13 -> 0 | DK13: =SUM(E13,K13,Q13,W13,AE13,AM13,AV13,BD13,BL13,BU13,CC13,CK13)-CS13 -> 0 | DL13: =SUM(G13,M13,S13,AA13,AI13,AR13,AZ13,BH13,BQ13,BY13,CG13,CO13)-CW13 -> 0 | DM13: =SUM(D13,J13,P13,V13,AD13,AL13,AU13,BC13,,BN13,BV13,CD13,CL13)-CT13 -> 0 | DP13: =#VALUE! -> #VALUE! | DQ13: =-CR13+DP13/10^6 -> #VALUE! | DR13: =SUM(E13,K13,Q13,W13,AE13,AM13,AV13,BD13,BL13,BU13,CC13,CK13)-CS13 -> 0 | DS13: =SUM(D13,J13,P13,V13,AD13,AL13,AU13,BC13,,BN13,BV13,CD13,CL13)-CT13 -> 0 | DU13: 68.494617 | DV13: =DU13-CJ13 -> 68.494617 | DX13: =(CS13-CZ13)*10^6 -> 0 | DY13: =(CT13-DC13)*10^6 -> 0 | DZ13: =(CW13-DD13)*10^6 -> 0
B14: AUTRES CHARGES SOCIALES | C14: Opex8 | CU14: =+CR14-CS14 -> 0 | CV14: =+CR14-CT14 -> 0 | CX14: =IFERROR(CR14/CW14-1, "-") -> - | DE14: =+CZ14/DD14-1 -> #DIV/0! | DF14: =+DA14/DD14-1 -> #DIV/0! | DG14: =+DB14/DD14-1 -> #DIV/0! | DH14: =+DC14/DD14-1 -> #DIV/0! | DJ14: =SUM(D14,J14,P14,V14,AD14,AL14,AU14,BC14,BK14,BT14,CB14,CJ14)-CR14 -> 0 | DK14: =SUM(E14,K14,Q14,W14,AE14,AM14,AV14,BD14,BL14,BU14,CC14,CK14)-CS14 -> 0 | DL14: =SUM(G14,M14,S14,AA14,AI14,AR14,AZ14,BH14,BQ14,BY14,CG14,CO14)-CW14 -> 0 | DM14: =SUM(D14,J14,P14,V14,AD14,AL14,AU14,BC14,,BN14,BV14,CD14,CL14)-CT14 -> 0 | DP14: =#VALUE! -> #VALUE! | DQ14: =-CR14+DP14/10^6 -> #VALUE! | DR14: =SUM(E14,K14,Q14,W14,AE14,AM14,AV14,BD14,BL14,BU14,CC14,CK14)-CS14 -> 0 | DS14: =SUM(D14,J14,P14,V14,AD14,AL14,AU14,BC14,,BN14,BV14,CD14,CL14)-CT14 -> 0 | DU14: 14.369378 | DV14: =DU14-CJ14 -> 14.369378 | DX14: =(CS14-CZ14)*10^6 -> 0 | DY14: =(CT14-DC14)*10^6 -> 0 | DZ14: =(CW14-DD14)*10^6 -> 0
B15: PERSONNEL INTERIMAIRE & STAGIA | C15: Opex9 | CX15: =IFERROR(CR15/CW15-1, "-") -> - | DG15: =+DB15/DD15-1 -> #DIV/0! | DH15: =+DC15/DD15-1 -> #DIV/0! | DJ15: =SUM(D15,J15,P15,V15,AD15,AL15,AU15,BC15,BK15,BT15,CB15,CJ15)-CR15 -> 0 | DK15: =SUM(E15,K15,Q15,W15,AE15,AM15,AV15,BD15,BL15,BU15,CC15,CK15)-CS15 -> 0 | DL15: =SUM(G15,M15,S15,AA15,AI15,AR15,AZ15,BH15,BQ15,BY15,CG15,CO15)-CW15 -> 0 | DM15: =SUM(D15,J15,P15,V15,AD15,AL15,AU15,BC15,,BN15,BV15,CD15,CL15)-CT15 -> 0 | DQ15: =-CR15+DP15/10^6 -> 0 | DR15: =SUM(E15,K15,Q15,W15,AE15,AM15,AV15,BD15,BL15,BU15,CC15,CK15)-CS15 -> 0 | DS15: =SUM(D15,J15,P15,V15,AD15,AL15,AU15,BC15,,BN15,BV15,CD15,CL15)-CT15 -> 0 | DV15: =DU15-CJ15 -> 0 | DX15: =(CS15-CZ15)*10^6 -> 0 | DY15: =(CT15-DC15)*10^6 -> 0 | DZ15: =(CW15-DD15)*10^6 -> 0
B16: PRIMES ET GRATIFICATIONS PERSO | C16: Opex10 | CU16: =+CR16-CS16 -> 0 | CV16: =+CR16-CT16 -> 0 | CX16: =IFERROR(CR16/CW16-1, "-") -> - | DE16: =+CZ16/DD16-1 -> #DIV/0! | DF16: =+DA16/DD16-1 -> #DIV/0! | DG16: =+DB16/DD16-1 -> #DIV/0! | DH16: =+DC16/DD16-1 -> #DIV/0! | DJ16: =SUM(D16,J16,P16,V16,AD16,AL16,AU16,BC16,BK16,BT16,CB16,CJ16)-CR16 -> 0 | DK16: =SUM(E16,K16,Q16,W16,AE16,AM16,AV16,BD16,BL16,BU16,CC16,CK16)-CS16 -> 0 | DL16: =SUM(G16,M16,S16,AA16,AI16,AR16,AZ16,BH16,BQ16,BY16,CG16,CO16)-CW16 -> 0 | DM16: =SUM(D16,J16,P16,V16,AD16,AL16,AU16,BC16,,BN16,BV16,CD16,CL16)-CT16 -> 0 | DP16: =#VALUE! -> #VALUE! | DQ16: =-CR16+DP16/10^6 -> #VALUE! | DR16: =SUM(E16,K16,Q16,W16,AE16,AM16,AV16,BD16,BL16,BU16,CC16,CK16)-CS16 -> 0 | DS16: =SUM(D16,J16,P16,V16,AD16,AL16,AU16,BC16,,BN16,BV16,CD16,CL16)-CT16 -> 0 | DT16: 22.791149 | DU16: 89.601339 | DV16: =DU16-CJ16 -> 89.601339 | DX16: =(CS16-CZ16)*10^6 -> 0 | DY16: =(CT16-DC16)*10^6 -> 0 | DZ16: =(CW16-DD16)*10^6 -> 0
B17: INDEMNITES DE LICENCIEMENT PER | C17: Opex11 | CU17: =+CR17-CS17 -> 0 | CV17: =+CR17-CT17 -> 0 | CX17: =IFERROR(CR17/CW17-1, "-") -> - | DJ17: =SUM(D17,J17,P17,V17,AD17,AL17,AU17,BC17,BK17,BT17,CB17,CJ17)-CR17 -> 0 | DK17: =SUM(E17,K17,Q17,W17,AE17,AM17,AV17,BD17,BL17,BU17,CC17,CK17)-CS17 -> 0 | DL17: =SUM(G17,M17,S17,AA17,AI17,AR17,AZ17,BH17,BQ17,BY17,CG17,CO17)-CW17 -> 0 | DM17: =SUM(D17,J17,P17,V17,AD17,AL17,AU17,BC17,,BN17,BV17,CD17,CL17)-CT17 -> 0 | DQ17: =-CR17+DP17/10^6 -> 0 | DR17: =SUM(E17,K17,Q17,W17,AE17,AM17,AV17,BD17,BL17,BU17,CC17,CK17)-CS17 -> 0 | DS17: =SUM(D17,J17,P17,V17,AD17,AL17,AU17,BC17,,BN17,BV17,CD17,CL17)-CT17 -> 0 | DV17: =DU17-CJ17 -> 0 | DX17: =(CS17-CZ17)*10^6 -> 0 | DY17: =(CT17-DC17)*10^6 -> 0 | DZ17: =(CW17-DD17)*10^6 -> 0
B18: EAU RESIDENCES | C18: Opex12 | CU18: =+CR18-CS18 -> 0 | CV18: =+CR18-CT18 -> 0 | CX18: =IFERROR(CR18/CW18-1, "-") -> - | DJ18: =SUM(D18,J18,P18,V18,AD18,AL18,AU18,BC18,BK18,BT18,CB18,CJ18)-CR18 -> 0 | DK18: =SUM(E18,K18,Q18,W18,AE18,AM18,AV18,BD18,BL18,BU18,CC18,CK18)-CS18 -> 0 | DL18: =SUM(G18,M18,S18,AA18,AI18,AR18,AZ18,BH18,BQ18,BY18,CG18,CO18)-CW18 -> 0 | DM18: =SUM(D18,J18,P18,V18,AD18,AL18,AU18,BC18,,BN18,BV18,CD18,CL18)-CT18 -> 0 | DQ18: =-CR18+DP18/10^6 -> 0 | DR18: =SUM(E18,K18,Q18,W18,AE18,AM18,AV18,BD18,BL18,BU18,CC18,CK18)-CS18 -> 0 | DS18: =SUM(D18,J18,P18,V18,AD18,AL18,AU18,BC18,,BN18,BV18,CD18,CL18)-CT18 -> 0 | DV18: =DU18-CJ18 -> 0 | DX18: =(CS18-CZ18)*10^6 -> 0 | DY18: =(CT18-DC18)*10^6 -> 0 | DZ18: =(CW18-DD18)*10^6 -> 0
B19: ELECTRICITE RESIDENCES | C19: Opex13 | CU19: =+CR19-CS19 -> 0 | CV19: =+CR19-CT19 -> 0 | CX19: =IFERROR(CR19/CW19-1, "-") -> - | DJ19: =SUM(D19,J19,P19,V19,AD19,AL19,AU19,BC19,BK19,BT19,CB19,CJ19)-CR19 -> 0 | DK19: =SUM(E19,K19,Q19,W19,AE19,AM19,AV19,BD19,BL19,BU19,CC19,CK19)-CS19 -> 0 | DL19: =SUM(G19,M19,S19,AA19,AI19,AR19,AZ19,BH19,BQ19,BY19,CG19,CO19)-CW19 -> 0 | DM19: =SUM(D19,J19,P19,V19,AD19,AL19,AU19,BC19,,BN19,BV19,CD19,CL19)-CT19 -> 0 | DQ19: =-CR19+DP19/10^6 -> 0 | DR19: =SUM(E19,K19,Q19,W19,AE19,AM19,AV19,BD19,BL19,BU19,CC19,CK19)-CS19 -> 0 | DS19: =SUM(D19,J19,P19,V19,AD19,AL19,AU19,BC19,,BN19,BV19,CD19,CL19)-CT19 -> 0 | DV19: =DU19-CJ19 -> 0 | DX19: =(CS19-CZ19)*10^6 -> 0 | DY19: =(CT19-DC19)*10^6 -> 0 | DZ19: =(CW19-DD19)*10^6 -> 0
B20: LOYERS RESIDENCES | C20: Opex14 | CU20: =+CR20-CS20 -> 0 | CV20: =+CR20-CT20 -> 0 | CX20: =IFERROR(CR20/CW20-1, "-") -> - | DJ20: =SUM(D20,J20,P20,V20,AD20,AL20,AU20,BC20,BK20,BT20,CB20,CJ20)-CR20 -> 0 | DK20: =SUM(E20,K20,Q20,W20,AE20,AM20,AV20,BD20,BL20,BU20,CC20,CK20)-CS20 -> 0 | DL20: =SUM(G20,M20,S20,AA20,AI20,AR20,AZ20,BH20,BQ20,BY20,CG20,CO20)-CW20 -> 0 | DM20: =SUM(D20,J20,P20,V20,AD20,AL20,AU20,BC20,,BN20,BV20,CD20,CL20)-CT20 -> 0 | DQ20: =-CR20+DP20/10^6 -> 0 | DR20: =SUM(E20,K20,Q20,W20,AE20,AM20,AV20,BD20,BL20,BU20,CC20,CK20)-CS20 -> 0 | DS20: =SUM(D20,J20,P20,V20,AD20,AL20,AU20,BC20,,BN20,BV20,CD20,CL20)-CT20 -> 0 | DV20: =DU20-CJ20 -> 0 | DX20: =(CS20-CZ20)*10^6 -> 0 | DY20: =(CT20-DC20)*10^6 -> 0 | DZ20: =(CW20-DD20)*10^6 -> 0
B21: ENTRETIEN ET REPARATIONS RESID | C21: Opex15 | CU21: =+CR21-CS21 -> 0 | CV21: =+CR21-CT21 -> 0 | CX21: =IFERROR(CR21/CW21-1, "-") -> - | DJ21: =SUM(D21,J21,P21,V21,AD21,AL21,AU21,BC21,BK21,BT21,CB21,CJ21)-CR21 -> 0 | DK21: =SUM(E21,K21,Q21,W21,AE21,AM21,AV21,BD21,BL21,BU21,CC21,CK21)-CS21 -> 0 | DL21: =SUM(G21,M21,S21,AA21,AI21,AR21,AZ21,BH21,BQ21,BY21,CG21,CO21)-CW21 -> 0 | DM21: =SUM(D21,J21,P21,V21,AD21,AL21,AU21,BC21,,BN21,BV21,CD21,CL21)-CT21 -> 0 | DQ21: =-CR21+DP21/10^6 -> 0 | DR21: =SUM(E21,K21,Q21,W21,AE21,AM21,AV21,BD21,BL21,BU21,CC21,CK21)-CS21 -> 0 | DS21: =SUM(D21,J21,P21,V21,AD21,AL21,AU21,BC21,,BN21,BV21,CD21,CL21)-CT21 -> 0 | DV21: =DU21-CJ21 -> 0 | DX21: =(CS21-CZ21)*10^6 -> 0 | DY21: =(CT21-DC21)*10^6 -> 0 | DZ21: =(CW21-DD21)*10^6 -> 0
B22: FRAIS MEDICAUX PERSONNEL NATIO | C22: Opex16 | CU22: =+CR22-CS22 -> 0 | CV22: =+CR22-CT22 -> 0 | CX22: =IFERROR(CR22/CW22-1, "-") -> - | DJ22: =SUM(D22,J22,P22,V22,AD22,AL22,AU22,BC22,BK22,BT22,CB22,CJ22)-CR22 -> 0 | DK22: =SUM(E22,K22,Q22,W22,AE22,AM22,AV22,BD22,BL22,BU22,CC22,CK22)-CS22 -> 0 | DL22: =SUM(G22,M22,S22,AA22,AI22,AR22,AZ22,BH22,BQ22,BY22,CG22,CO22)-CW22 -> 0 | DM22: =SUM(D22,J22,P22,V22,AD22,AL22,AU22,BC22,,BN22,BV22,CD22,CL22)-CT22 -> 0 | DQ22: =-CR22+DP22/10^6 -> 0 | DR22: =SUM(E22,K22,Q22,W22,AE22,AM22,AV22,BD22,BL22,BU22,CC22,CK22)-CS22 -> 0 | DS22: =SUM(D22,J22,P22,V22,AD22,AL22,AU22,BC22,,BN22,BV22,CD22,CL22)-CT22 -> 0 | DV22: =DU22-CJ22 -> 0 | DX22: =(CS22-CZ22)*10^6 -> 0 | DY22: =(CT22-DC22)*10^6 -> 0 | DZ22: =(CW22-DD22)*10^6 -> 0
B23: AVANTAGES EN NATURE PERSONNEL | C23: Opex17 | CU23: =+CR23-CS23 -> 0 | CV23: =+CR23-CT23 -> 0 | CX23: =IFERROR(CR23/CW23-1, "-") -> - | DE23: =+CZ23/DD23-1 -> #DIV/0! | DF23: =+DA23/DD23-1 -> #DIV/0! | DG23: =+DB23/DD23-1 -> #DIV/0! | DH23: =+DC23/DD23-1 -> #DIV/0! | DJ23: =SUM(D23,J23,P23,V23,AD23,AL23,AU23,BC23,BK23,BT23,CB23,CJ23)-CR23 -> 0 | DK23: =SUM(E23,K23,Q23,W23,AE23,AM23,AV23,BD23,BL23,BU23,CC23,CK23)-CS23 -> 0 | DL23: =SUM(G23,M23,S23,AA23,AI23,AR23,AZ23,BH23,BQ23,BY23,CG23,CO23)-CW23 -> 0 | DM23: =SUM(D23,J23,P23,V23,AD23,AL23,AU23,BC23,,BN23,BV23,CD23,CL23)-CT23 -> 0 | DP23: =#VALUE! -> #VALUE! | DQ23: =-CR23+DP23/10^6 -> #VALUE! | DR23: =SUM(E23,K23,Q23,W23,AE23,AM23,AV23,BD23,BL23,BU23,CC23,CK23)-CS23 -> 0 | DS23: =SUM(D23,J23,P23,V23,AD23,AL23,AU23,BC23,,BN23,BV23,CD23,CL23)-CT23 -> 0 | DU23: 13.826821 | DV23: =DU23-CJ23 -> 13.826821 | DX23: =(CS23-CZ23)*10^6 -> 0 | DY23: =(CT23-DC23)*10^6 -> 0 | DZ23: =(CW23-DD23)*10^6 -> 0
B24: TRANSFERT DE CHARGES D'EXPLOITATION | C24: Opex18 | CU24: =+CR24-CS24 -> 0 | CV24: =+CR24-CT24 -> 0 | CX24: =IFERROR(CR24/CW24-1, "-") -> - | DJ24: =SUM(D24,J24,P24,V24,AD24,AL24,AU24,BC24,BK24,BT24,CB24,CJ24)-CR24 -> 0 | DK24: =SUM(E24,K24,Q24,W24,AE24,AM24,AV24,BD24,BL24,BU24,CC24,CK24)-CS24 -> 0 | DL24: =SUM(G24,M24,S24,AA24,AI24,AR24,AZ24,BH24,BQ24,BY24,CG24,CO24)-CW24 -> 0 | DM24: =SUM(D24,J24,P24,V24,AD24,AL24,AU24,BC24,,BN24,BV24,CD24,CL24)-CT24 -> 0 | DQ24: =-CR24+DP24/10^6 -> 0 | DR24: =SUM(E24,K24,Q24,W24,AE24,AM24,AV24,BD24,BL24,BU24,CC24,CK24)-CS24 -> 0 | DS24: =SUM(D24,J24,P24,V24,AD24,AL24,AU24,BC24,,BN24,BV24,CD24,CL24)-CT24 -> 0 | DV24: =DU24-CJ24 -> 0 | DX24: =(CS24-CZ24)*10^6 -> 0 | DY24: =(CT24-DC24)*10^6 -> 0 | DZ24: =(CW24-DD24)*10^6 -> 0
B25: EAU RESIDENCES | C25: Opex19 | CU25: =+CR25-CS25 -> 0 | CV25: =+CR25-CT25 -> 0 | CX25: =IFERROR(CR25/CW25-1, "-") -> - | DJ25: =SUM(D25,J25,P25,V25,AD25,AL25,AU25,BC25,BK25,BT25,CB25,CJ25)-CR25 -> 0 | DK25: =SUM(E25,K25,Q25,W25,AE25,AM25,AV25,BD25,BL25,BU25,CC25,CK25)-CS25 -> 0 | DL25: =SUM(G25,M25,S25,AA25,AI25,AR25,AZ25,BH25,BQ25,BY25,CG25,CO25)-CW25 -> 0 | DM25: =SUM(D25,J25,P25,V25,AD25,AL25,AU25,BC25,,BN25,BV25,CD25,CL25)-CT25 -> 0 | DQ25: =-CR25+DP25/10^6 -> 0 | DR25: =SUM(E25,K25,Q25,W25,AE25,AM25,AV25,BD25,BL25,BU25,CC25,CK25)-CS25 -> 0 | DS25: =SUM(D25,J25,P25,V25,AD25,AL25,AU25,BC25,,BN25,BV25,CD25,CL25)-CT25 -> 0 | DV25: =DU25-CJ25 -> 0 | DX25: =(CS25-CZ25)*10^6 -> 0 | DY25: =(CT25-DC25)*10^6 -> 0 | DZ25: =(CW25-DD25)*10^6 -> 0
B26: ELECTRICITE RESIDENCES | C26: Opex20 | CU26: =+CR26-CS26 -> 0 | CV26: =+CR26-CT26 -> 0 | CX26: =IFERROR(CR26/CW26-1, "-") -> - | DJ26: =SUM(D26,J26,P26,V26,AD26,AL26,AU26,BC26,BK26,BT26,CB26,CJ26)-CR26 -> 0 | DK26: =SUM(E26,K26,Q26,W26,AE26,AM26,AV26,BD26,BL26,BU26,CC26,CK26)-CS26 -> 0 | DL26: =SUM(G26,M26,S26,AA26,AI26,AR26,AZ26,BH26,BQ26,BY26,CG26,CO26)-CW26 -> 0 | DM26: =SUM(D26,J26,P26,V26,AD26,AL26,AU26,BC26,,BN26,BV26,CD26,CL26)-CT26 -> 0 | DQ26: =-CR26+DP26/10^6 -> 0 | DR26: =SUM(E26,K26,Q26,W26,AE26,AM26,AV26,BD26,BL26,BU26,CC26,CK26)-CS26 -> 0 | DS26: =SUM(D26,J26,P26,V26,AD26,AL26,AU26,BC26,,BN26,BV26,CD26,CL26)-CT26 -> 0 | DV26: =DU26-CJ26 -> 0 | DX26: =(CS26-CZ26)*10^6 -> 0 | DY26: =(CT26-DC26)*10^6 -> 0 | DZ26: =(CW26-DD26)*10^6 -> 0
B27: LOYERS RESIDENCES | C27: Opex21 | CU27: =+CR27-CS27 -> 0 | CV27: =+CR27-CT27 -> 0 | CX27: =IFERROR(CR27/CW27-1, "-") -> - | DJ27: =SUM(D27,J27,P27,V27,AD27,AL27,AU27,BC27,BK27,BT27,CB27,CJ27)-CR27 -> 0 | DK27: =SUM(E27,K27,Q27,W27,AE27,AM27,AV27,BD27,BL27,BU27,CC27,CK27)-CS27 -> 0 | DL27: =SUM(G27,M27,S27,AA27,AI27,AR27,AZ27,BH27,BQ27,BY27,CG27,CO27)-CW27 -> 0 | DM27: =SUM(D27,J27,P27,V27,AD27,AL27,AU27,BC27,,BN27,BV27,CD27,CL27)-CT27 -> 0 | DQ27: =-CR27+DP27/10^6 -> 0 | DR27: =SUM(E27,K27,Q27,W27,AE27,AM27,AV27,BD27,BL27,BU27,CC27,CK27)-CS27 -> 0 | DS27: =SUM(D27,J27,P27,V27,AD27,AL27,AU27,BC27,,BN27,BV27,CD27,CL27)-CT27 -> 0 | DV27: =DU27-CJ27 -> 0 | DX27: =(CS27-CZ27)*10^6 -> 0 | DY27: =(CT27-DC27)*10^6 -> 0 | DZ27: =(CW27-DD27)*10^6 -> 0
B28: ENTRETIEN ET REPARATIONS RESID | C28: Opex22 | CU28: =+CR28-CS28 -> 0 | CV28: =+CR28-CT28 -> 0 | CX28: =IFERROR(CR28/CW28-1, "-") -> - | DJ28: =SUM(D28,J28,P28,V28,AD28,AL28,AU28,BC28,BK28,BT28,CB28,CJ28)-CR28 -> 0 | DK28: =SUM(E28,K28,Q28,W28,AE28,AM28,AV28,BD28,BL28,BU28,CC28,CK28)-CS28 -> 0 | DL28: =SUM(G28,M28,S28,AA28,AI28,AR28,AZ28,BH28,BQ28,BY28,CG28,CO28)-CW28 -> 0 | DM28: =SUM(D28,J28,P28,V28,AD28,AL28,AU28,BC28,,BN28,BV28,CD28,CL28)-CT28 -> 0 | DQ28: =-CR28+DP28/10^6 -> 0 | DR28: =SUM(E28,K28,Q28,W28,AE28,AM28,AV28,BD28,BL28,BU28,CC28,CK28)-CS28 -> 0 | DS28: =SUM(D28,J28,P28,V28,AD28,AL28,AU28,BC28,,BN28,BV28,CD28,CL28)-CT28 -> 0 | DV28: =DU28-CJ28 -> 0 | DX28: =(CS28-CZ28)*10^6 -> 0 | DY28: =(CT28-DC28)*10^6 -> 0 | DZ28: =(CW28-DD28)*10^6 -> 0
B29: FRAIS DE TELEPHONE RESIDENCES | C29: Opex23 | CU29: =+CR29-CS29 -> 0 | CV29: =+CR29-CT29 -> 0 | CX29: =IFERROR(CR29/CW29-1, "-") -> - | DJ29: =SUM(D29,J29,P29,V29,AD29,AL29,AU29,BC29,BK29,BT29,CB29,CJ29)-CR29 -> 0 | DK29: =SUM(E29,K29,Q29,W29,AE29,AM29,AV29,BD29,BL29,BU29,CC29,CK29)-CS29 -> 0 | DL29: =SUM(G29,M29,S29,AA29,AI29,AR29,AZ29,BH29,BQ29,BY29,CG29,CO29)-CW29 -> 0 | DM29: =SUM(D29,J29,P29,V29,AD29,AL29,AU29,BC29,,BN29,BV29,CD29,CL29)-CT29 -> 0 | DQ29: =-CR29+DP29/10^6 -> 0 | DR29: =SUM(E29,K29,Q29,W29,AE29,AM29,AV29,BD29,BL29,BU29,CC29,CK29)-CS29 -> 0 | DS29: =SUM(D29,J29,P29,V29,AD29,AL29,AU29,BC29,,BN29,BV29,CD29,CL29)-CT29 -> 0 | DV29: =DU29-CJ29 -> 0 | DX29: =(CS29-CZ29)*10^6 -> 0 | DY29: =(CT29-DC29)*10^6 -> 0 | DZ29: =(CW29-DD29)*10^6 -> 0
B30: PRIMES ET GRATIFICATIONS PERSO | C30: Opex24 | CU30: =+CR30-CS30 -> 0 | CV30: =+CR30-CT30 -> 0 | CX30: =IFERROR(CR30/CW30-1, "-") -> - | DJ30: =SUM(D30,J30,P30,V30,AD30,AL30,AU30,BC30,BK30,BT30,CB30,CJ30)-CR30 -> 0 | DK30: =SUM(E30,K30,Q30,W30,AE30,AM30,AV30,BD30,BL30,BU30,CC30,CK30)-CS30 -> 0 | DL30: =SUM(G30,M30,S30,AA30,AI30,AR30,AZ30,BH30,BQ30,BY30,CG30,CO30)-CW30 -> 0 | DM30: =SUM(D30,J30,P30,V30,AD30,AL30,AU30,BC30,,BN30,BV30,CD30,CL30)-CT30 -> 0 | DP30: 0 | DQ30: =-CR30+DP30/10^6 -> 0 | DR30: =SUM(E30,K30,Q30,W30,AE30,AM30,AV30,BD30,BL30,BU30,CC30,CK30)-CS30 -> 0 | DS30: =SUM(D30,J30,P30,V30,AD30,AL30,AU30,BC30,,BN30,BV30,CD30,CL30)-CT30 -> 0 | DV30: =DU30-CJ30 -> 0 | DX30: =(CS30-CZ30)*10^6 -> 0 | DY30: =(CT30-DC30)*10^6 -> 0 | DZ30: =(CW30-DD30)*10^6 -> 0
B31: INDEMNITES DE LICENCIEMENT PER | C31: Opex25 | CU31: =+CR31-CS31 -> 0 | CV31: =+CR31-CT31 -> 0 | CX31: =IFERROR(CR31/CW31-1, "-") -> - | DJ31: =SUM(D31,J31,P31,V31,AD31,AL31,AU31,BC31,BK31,BT31,CB31,CJ31)-CR31 -> 0 | DK31: =SUM(E31,K31,Q31,W31,AE31,AM31,AV31,BD31,BL31,BU31,CC31,CK31)-CS31 -> 0 | DL31: =SUM(G31,M31,S31,AA31,AI31,AR31,AZ31,BH31,BQ31,BY31,CG31,CO31)-CW31 -> 0 | DM31: =SUM(D31,J31,P31,V31,AD31,AL31,AU31,BC31,,BN31,BV31,CD31,CL31)-CT31 -> 0 | DQ31: =-CR31+DP31/10^6 -> 0 | DR31: =SUM(E31,K31,Q31,W31,AE31,AM31,AV31,BD31,BL31,BU31,CC31,CK31)-CS31 -> 0 | DS31: =SUM(D31,J31,P31,V31,AD31,AL31,AU31,BC31,,BN31,BV31,CD31,CL31)-CT31 -> 0 | DV31: =DU31-CJ31 -> 0 | DX31: =(CS31-CZ31)*10^6 -> 0 | DY31: =(CT31-DC31)*10^6 -> 0 | DZ31: =(CW31-DD31)*10^6 -> 0
B32: AVANTAGES EN NATURE PERSONNEL | C32: Opex26 | CU32: =+CR32-CS32 -> 0 | CV32: =+CR32-CT32 -> 0 | CX32: =IFERROR(CR32/CW32-1, "-") -> - | DJ32: =SUM(D32,J32,P32,V32,AD32,AL32,AU32,BC32,BK32,BT32,CB32,CJ32)-CR32 -> 0 | DK32: =SUM(E32,K32,Q32,W32,AE32,AM32,AV32,BD32,BL32,BU32,CC32,CK32)-CS32 -> 0 | DL32: =SUM(G32,M32,S32,AA32,AI32,AR32,AZ32,BH32,BQ32,BY32,CG32,CO32)-CW32 -> 0 | DM32: =SUM(D32,J32,P32,V32,AD32,AL32,AU32,BC32,,BN32,BV32,CD32,CL32)-CT32 -> 0 | DQ32: =-CR32+DP32/10^6 -> 0 | DR32: =SUM(E32,K32,Q32,W32,AE32,AM32,AV32,BD32,BL32,BU32,CC32,CK32)-CS32 -> 0 | DS32: =SUM(D32,J32,P32,V32,AD32,AL32,AU32,BC32,,BN32,BV32,CD32,CL32)-CT32 -> 0 | DV32: =DU32-CJ32 -> 0 | DX32: =(CS32-CZ32)*10^6 -> 0 | DY32: =(CT32-DC32)*10^6 -> 0 | DZ32: =(CW32-DD32)*10^6 -> 0
B33: AUTRES INDEMNITES ET AVANTAGES | C33: Opex27 | CU33: =+CR33-CS33 -> 0 | CV33: =+CR33-CT33 -> 0 | CX33: =IFERROR(CR33/CW33-1, "-") -> - | DJ33: =SUM(D33,J33,P33,V33,AD33,AL33,AU33,BC33,BK33,BT33,CB33,CJ33)-CR33 -> 0 | DK33: =SUM(E33,K33,Q33,W33,AE33,AM33,AV33,BD33,BL33,BU33,CC33,CK33)-CS33 -> 0 | DL33: =SUM(G33,M33,S33,AA33,AI33,AR33,AZ33,BH33,BQ33,BY33,CG33,CO33)-CW33 -> 0 | DM33: =SUM(D33,J33,P33,V33,AD33,AL33,AU33,BC33,,BN33,BV33,CD33,CL33)-CT33 -> 0 | DQ33: =-CR33+DP33/10^6 -> 0 | DR33: =SUM(E33,K33,Q33,W33,AE33,AM33,AV33,BD33,BL33,BU33,CC33,CK33)-CS33 -> 0 | DS33: =SUM(D33,J33,P33,V33,AD33,AL33,AU33,BC33,,BN33,BV33,CD33,CL33)-CT33 -> 0 | DV33: =DU33-CJ33 -> 0 | DX33: =(CS33-CZ33)*10^6 -> 0 | DY33: =(CT33-DC33)*10^6 -> 0 | DZ33: =(CW33-DD33)*10^6 -> 0
B34: FRAIS DE FORMATION DU PERSONNE | C34: Opex28 | CU34: =+CR34-CS34 -> 0 | CV34: =+CR34-CT34 -> 0 | CX34: =IFERROR(CR34/CW34-1, "-") -> - | DJ34: =SUM(D34,J34,P34,V34,AD34,AL34,AU34,BC34,BK34,BT34,CB34,CJ34)-CR34 -> 0 | DK34: =SUM(E34,K34,Q34,W34,AE34,AM34,AV34,BD34,BL34,BU34,CC34,CK34)-CS34 -> 0 | DL34: =SUM(G34,M34,S34,AA34,AI34,AR34,AZ34,BH34,BQ34,BY34,CG34,CO34)-CW34 -> 0 | DM34: =SUM(D34,J34,P34,V34,AD34,AL34,AU34,BC34,,BN34,BV34,CD34,CL34)-CT34 -> 0 | DQ34: =-CR34+DP34/10^6 -> 0 | DR34: =SUM(E34,K34,Q34,W34,AE34,AM34,AV34,BD34,BL34,BU34,CC34,CK34)-CS34 -> 0 | DS34: =SUM(D34,J34,P34,V34,AD34,AL34,AU34,BC34,,BN34,BV34,CD34,CL34)-CT34 -> 0 | DV34: =DU34-CJ34 -> 0 | DX34: =(CS34-CZ34)*10^6 -> 0 | DY34: =(CT34-DC34)*10^6 -> 0 | DZ34: =(CW34-DD34)*10^6 -> 0
B35: TRANSPORT PERSONNEL | C35: Opex29 | CU35: =+CR35-CS35 -> 0 | CV35: =+CR35-CT35 -> 0 | CX35: =IFERROR(CR35/CW35-1, "-") -> - | DJ35: =SUM(D35,J35,P35,V35,AD35,AL35,AU35,BC35,BK35,BT35,CB35,CJ35)-CR35 -> 0 | DK35: =SUM(E35,K35,Q35,W35,AE35,AM35,AV35,BD35,BL35,BU35,CC35,CK35)-CS35 -> 0 | DL35: =SUM(G35,M35,S35,AA35,AI35,AR35,AZ35,BH35,BQ35,BY35,CG35,CO35)-CW35 -> 0 | DM35: =SUM(D35,J35,P35,V35,AD35,AL35,AU35,BC35,,BN35,BV35,CD35,CL35)-CT35 -> 0 | DQ35: =-CR35+DP35/10^6 -> 0 | DR35: =SUM(E35,K35,Q35,W35,AE35,AM35,AV35,BD35,BL35,BU35,CC35,CK35)-CS35 -> 0 | DS35: =SUM(D35,J35,P35,V35,AD35,AL35,AU35,BC35,,BN35,BV35,CD35,CL35)-CT35 -> 0 | DV35: =DU35-CJ35 -> 0 | DX35: =(CS35-CZ35)*10^6 -> 0 | DY35: =(CT35-DC35)*10^6 -> 0 | DZ35: =(CW35-DD35)*10^6 -> 0
B36: RECEPTIONS PERSONNEL | C36: Opex30 | CU36: =+CR36-CS36 -> 0 | CV36: =+CR36-CT36 -> 0 | CX36: =IFERROR(CR36/CW36-1, "-") -> - | DJ36: =SUM(D36,J36,P36,V36,AD36,AL36,AU36,BC36,BK36,BT36,CB36,CJ36)-CR36 -> 0 | DK36: =SUM(E36,K36,Q36,W36,AE36,AM36,AV36,BD36,BL36,BU36,CC36,CK36)-CS36 -> 0 | DL36: =SUM(G36,M36,S36,AA36,AI36,AR36,AZ36,BH36,BQ36,BY36,CG36,CO36)-CW36 -> 0 | DM36: =SUM(D36,J36,P36,V36,AD36,AL36,AU36,BC36,,BN36,BV36,CD36,CL36)-CT36 -> 0 | DQ36: =-CR36+DP36/10^6 -> 0 | DR36: =SUM(E36,K36,Q36,W36,AE36,AM36,AV36,BD36,BL36,BU36,CC36,CK36)-CS36 -> 0 | DS36: =SUM(D36,J36,P36,V36,AD36,AL36,AU36,BC36,,BN36,BV36,CD36,CL36)-CT36 -> 0 | DV36: =DU36-CJ36 -> 0 | DX36: =(CS36-CZ36)*10^6 -> 0 | DY36: =(CT36-DC36)*10^6 -> 0 | DZ36: =(CW36-DD36)*10^6 -> 0
B37: ASSURANCE DU PERSONNEL | C37: Opex31 | CU37: =+CR37-CS37 -> 0 | CV37: =+CR37-CT37 -> 0 | CX37: =IFERROR(CR37/CW37-1, "-") -> - | DE37: =+CZ37/DD37-1 -> #DIV/0! | DF37: =+DA37/DD37-1 -> #DIV/0! | DG37: =+DB37/DD37-1 -> #DIV/0! | DH37: =+DC37/DD37-1 -> #DIV/0! | DJ37: =SUM(D37,J37,P37,V37,AD37,AL37,AU37,BC37,BK37,BT37,CB37,CJ37)-CR37 -> 0 | DK37: =SUM(E37,K37,Q37,W37,AE37,AM37,AV37,BD37,BL37,BU37,CC37,CK37)-CS37 -> 0 | DL37: =SUM(G37,M37,S37,AA37,AI37,AR37,AZ37,BH37,BQ37,BY37,CG37,CO37)-CW37 -> 0 | DM37: =SUM(D37,J37,P37,V37,AD37,AL37,AU37,BC37,,BN37,BV37,CD37,CL37)-CT37 -> 0 | DP37: =#VALUE! -> #VALUE! | DQ37: =-CR37+DP37/10^6 -> #VALUE! | DR37: =SUM(E37,K37,Q37,W37,AE37,AM37,AV37,BD37,BL37,BU37,CC37,CK37)-CS37 -> 0 | DS37: =SUM(D37,J37,P37,V37,AD37,AL37,AU37,BC37,,BN37,BV37,CD37,CL37)-CT37 -> 0 | DU37: 20.407007 | DV37: =DU37-CJ37 -> 20.407007 | DX37: =(CS37-CZ37)*10^6 -> 0 | DY37: =(CT37-DC37)*10^6 -> 0 | DZ37: =(CW37-DD37)*10^6 -> 0
B38: Réduction budget | C38: Opex32 | CU38: =+CR38-CS38 -> 0 | CV38: =+CR38-CT38 -> 0 | CX38: =IFERROR(CR38/CW38-1, "-") -> - | DJ38: =SUM(D38,J38,P38,V38,AD38,AL38,AU38,BC38,BK38,BT38,CB38,CJ38)-CR38 -> 0 | DK38: =SUM(E38,K38,Q38,W38,AE38,AM38,AV38,BD38,BL38,BU38,CC38,CK38)-CS38 -> 0 | DL38: =SUM(G38,M38,S38,AA38,AI38,AR38,AZ38,BH38,BQ38,BY38,CG38,CO38)-CW38 -> 0 | DM38: =SUM(D38,J38,P38,V38,AD38,AL38,AU38,BC38,,BN38,BV38,CD38,CL38)-CT38 -> 0 | DQ38: =-CR38+DP38/10^6 -> 0 | DR38: =SUM(E38,K38,Q38,W38,AE38,AM38,AV38,BD38,BL38,BU38,CC38,CK38)-CS38 -> 0 | DS38: =SUM(D38,J38,P38,V38,AD38,AL38,AU38,BC38,,BN38,BV38,CD38,CL38)-CT38 -> 0 | DV38: =DU38-CJ38 -> 0 | DX38: =(CS38-CZ38)*10^6 -> 0 | DY38: =(CT38-DC38)*10^6 -> 0 | DZ38: =(CW38-DD38)*10^6 -> 0
C39: Opex33 | CX39: =IFERROR(CR39/CW39-1, "-") -> - | DJ39: =SUM(D39,J39,P39,V39,AD39,AL39,AU39,BC39,BK39,BT39,CB39,CJ39)-CR39 -> 0 | DK39: =SUM(E39,K39,Q39,W39,AE39,AM39,AV39,BD39,BL39,BU39,CC39,CK39)-CS39 -> 0 | DL39: =SUM(G39,M39,S39,AA39,AI39,AR39,AZ39,BH39,BQ39,BY39,CG39,CO39)-CW39 -> 0 | DM39: =SUM(D39,J39,P39,V39,AD39,AL39,AU39,BC39,,BN39,BV39,CD39,CL39)-CT39 -> 0 | DQ39: =-CR39+DP39/10^6 -> 0 | DR39: =SUM(E39,K39,Q39,W39,AE39,AM39,AV39,BD39,BL39,BU39,CC39,CK39)-CS39 -> 0 | DS39: =SUM(D39,J39,P39,V39,AD39,AL39,AU39,BC39,,BN39,BV39,CD39,CL39)-CT39 -> 0 | DV39: =DU39-CJ39 -> 0 | DX39: =(CS39-CZ39)*10^6 -> 0 | DY39: =(CT39-DC39)*10^6 -> 0 | DZ39: =(CW39-DD39)*10^6 -> 0
B40: Communication | C40: Opex34 | CU40: =+CR40-CS40 -> 0 | CV40: =+CR40-CT40 -> 0 | CX40: =IFERROR(CR40/CW40-1, "-") -> - | DE40: =+CZ40/DD40-1 -> #DIV/0! | DF40: =+DA40/DD40-1 -> #DIV/0! | DG40: =+DB40/DD40-1 -> #DIV/0! | DH40: =+DC40/DD40-1 -> #DIV/0! | DJ40: =SUM(D40,J40,P40,V40,AD40,AL40,AU40,BC40,BK40,BT40,CB40,CJ40)-CR40 -> 0 | DK40: =SUM(E40,K40,Q40,W40,AE40,AM40,AV40,BD40,BL40,BU40,CC40,CK40)-CS40 -> 0 | DL40: =SUM(G40,M40,S40,AA40,AI40,AR40,AZ40,BH40,BQ40,BY40,CG40,CO40)-CW40 -> 0 | DM40: =SUM(D40,J40,P40,V40,AD40,AL40,AU40,BC40,,BN40,BV40,CD40,CL40)-CT40 -> 0 | DP40: =SUM(DP41:DP55) -> #VALUE! | DQ40: =-CR40+DP40/10^6 -> #VALUE! | DR40: =SUM(E40,K40,Q40,W40,AE40,AM40,AV40,BD40,BL40,BU40,CC40,CK40)-CS40 -> 0 | DS40: =SUM(D40,J40,P40,V40,AD40,AL40,AU40,BC40,,BN40,BV40,CD40,CL40)-CT40 -> 0 | DU40: 338.23657 | DV40: =DU40-CJ40 -> 338.23657 | DX40: =(CS40-CZ40)*10^6 -> 0 | DY40: =(CT40-DC40)*10^6 -> 0 | DZ40: =(CW40-DD40)*10^6 -> 0
...

Sheet CA Mobile
P1: =#REF! -> #REF! | Y1: =Y8/W8 -> #DIV/0! | Z1: =Z8/X8 -> #DIV/0! | AU1: 0 | AV1: 0 | DJ1: 0
A2: CA Mobile | J2: 0 | P2: 8366.7791 | Q2: =P2+P179+P177+P171+P149+P144+P143+P53-P118-P126 -> 8366.7791 | R2: =+P8-Q2 -> -8366.7791 | W2: 0 | AD2: 0 | AG2: =AD8/AF8-1 -> #DIV/0! | BC2: 0 | CK2: 0 | DC2: 0
E3: 0 | CZ3: 0 | DD3: 0
D4: 45292 | J4: 45323 | P4: 45352 | V4: 45383 | AD4: 45413 | AL4: 45444 | AU4: 45474 | BC4: 45505 | BK4: 45536 | BT4: 45566 | CB4: 45597 | CJ4: 45627 | CR4: CUMUL | DB4: ANNUEL
B5: (En Millions ML) | D5: 2024 Réel | E5: 2024 Budget | F5: Ecart / Budget | G5: 2023 Réel | H5: Evol % | J5: 2024 Réel | K5: 2024 Budget | L5: Ecart / Budget | M5: 2023 Réel | N5: Evol % | P5: 2024 Réel | Q5: 2024 Budget | R5: Ecart / Budget | S5: 2023 Réel | T5: Evol % | V5: 2024 Réel | W5: 2024 Budget | X5: 2024 Actu1 | Y5: Ecart / Budget | Z5: Ecart / Actu1 | AA5: 2023 Réel | AB5: Evol % | AD5: 2024 Réel | AE5: 2024 Budget | AF5: 2024 Actu1 | AG5: Ecart / Budget | AH5: Ecart / Actu1 | AI5: 2023 Réel | AJ5: Evol % | AL5: 2024 Réel | AM5: 2024 Budget | AN5: 2024 Actu1 | AO5: 2024 Actu2 | AP5: Ecart / Budget | AQ5: Ecart / Actu1 | AR5: 2023 Réel | AS5: Evol % | AU5: 2024 Réel | AV5: 2024 Budget | AW5: 2024 Actu2 | AX5: Ecart / Budget | AY5: Ecart / Actu2 | AZ5: 2023 Réel | BA5: Evol % | BC5: 2024 Réel | BD5: 2024 Budget | BE5: 2024 Actu2 | BF5: Ecart / Budget | BG5: Ecart / Actu2 | BH5: 2023 Réel | BI5: Evol % | BK5: 2024 Réel | BL5: 2024 Budget | BM5: 2024 Actu2 | BN5: 2024 Actu3 | BO5: Ecart / Budget | BP5: Ecart / Actu2 | BQ5: 2023 Réel | BR5: Evol % | BT5: 2024 Réel | BU5: 2024 Budget | BV5: 2024 Actu3 | BW5: Ecart / Budget | BX5: Ecart / Actu3 | BY5: 2023 Réel | BZ5: Evol % | CB5: 2024 Réel | CC5: 2024 Budget | CD5: 2024 Actu3 | CE5: Ecart / Budget | CF5: Ecart / Actu3 | CG5: 2023 Réel | CH5: Evol % | CJ5: 2024 Réel | CK5: 2024 Budget | CL5: 2024 Actu3 | CM5: Ecart / Budget | CN5: Ecart / Actu3 | CO5: 2023 Réel | CP5: Evol % | CR5: 2024 Réel | CS5: 2024 Budget | CT5: 2024 Actu3 | CU5: Ecart / Budget | CV5: Ecart / Actu3 | CW5: 2023 Réel | CX5: Evol % | CZ5: 2024 Budget | DA5: 2024 Actu1 | DB5: 2024 Actu2 | DC5: 2024 Actu3 | DD5: 2023 Réel | DE5: Bud / 2023 (%) | DF5: Actu 1 / 2023 (%) | DG5: Actu 2 / 2023 (%) | DH5: Actu3 / 2023 (%)
A8: CA Global | C8: CA1 | CU8: =+CR8-CS8 -> 0 | CV8: =+CR8-CT8 -> 0 | CX8: =IFERROR(CR8/CW8-1, "-") -> - | DE8: =(CZ8-DD8)/DD8 -> #DIV/0! | DF8: =(DA8-DD8)/DD8 -> #DIV/0! | DG8: =(DB8-DD8)/DD8 -> #DIV/0! | DH8: =(DC8-DD8)/DD8 -> #DIV/0! | DM8: =CS8-CZ8 -> 0 | DN8: =CT8-DC8 -> 0 | DO8: =CW8-DD8 -> 0
C9: CA2 | CV9: =+CR9-CT9 -> 0 | CX9: =IFERROR(CR9/CW9-1, "-") -> - | DM9: =(CS9-CZ9)*10^6 -> 0 | DN9: =(CT9-DC9)*10^6 -> 0 | DO9: =(CW9-DD9)*10^6 -> 0
B10: dont CA Etat | C10: CA3 | CV10: =+CR10-CT10 -> 0 | CX10: =IFERROR(CR10/CW10-1, "-") -> - | DM10: =(CS10-CZ10)*10^6 -> 0 | DN10: =(CT10-DC10)*10^6 -> 0 | DO10: =(CW10-DD10)*10^6 -> 0
C11: CA4 | CV11: =+CR11-CT11 -> 0 | CX11: =IFERROR(CR11/CW11-1, "-") -> - | DM11: =(CS11-CZ11)*10^6 -> 0 | DN11: =(CT11-DC11)*10^6 -> 0 | DO11: =(CW11-DD11)*10^6 -> 0
A12: CA services Mobile | C12: CA5 | CU12: =+CR12-CS12 -> 0 | CV12: =+CR12-CT12 -> 0 | CX12: =IFERROR(CR12/CW12-1, "-") -> - | DE12: =(CZ12-DD12)/DD12 -> #DIV/0! | DF12: =(DA12-DD12)/DD12 -> #DIV/0! | DG12: =(DB12-DD12)/DD12 -> #DIV/0! | DH12: =(DC12-DD12)/DD12 -> #DIV/0! | DM12: =(CS12-CZ12)*10^6 -> 0 | DN12: =(CT12-DC12)*10^6 -> 0 | DO12: =(CW12-DD12)*10^6 -> 0
C13: CA6 | CV13: =+CR13-CT13 -> 0 | CX13: =IFERROR(CR13/CW13-1, "-") -> - | DM13: =(CS13-CZ13)*10^6 -> 0 | DN13: =(CT13-DC13)*10^6 -> 0 | DO13: =(CW13-DD13)*10^6 -> 0
A14: CA récurrent | C14: CA7 | CU14: =+CR14-CS14 -> 0 | CV14: =+CR14-CT14 -> 0 | CX14: =IFERROR(CR14/CW14-1, "-") -> - | DE14: =(CZ14-DD14)/DD14 -> #DIV/0! | DF14: =(DA14-DD14)/DD14 -> #DIV/0! | DG14: =(DB14-DD14)/DD14 -> #DIV/0! | DH14: =(DC14-DD14)/DD14 -> #DIV/0! | DM14: =(CS14-CZ14)*10^6 -> 0 | DN14: =(CT14-DC14)*10^6 -> 0 | DO14: =(CW14-DD14)*10^6 -> 0
C15: CA8 | CV15: =+CR15-CT15 -> 0 | CX15: =IFERROR(CR15/CW15-1, "-") -> - | DM15: =(CS15-CZ15)*10^6 -> 0 | DN15: =(CT15-DC15)*10^6 -> 0 | DO15: =(CW15-DD15)*10^6 -> 0
A16: CA sortant | C16: CA9 | CU16: =+CR16-CS16 -> 0 | CV16: =+CR16-CT16 -> 0 | CX16: =IFERROR(CR16/CW16-1, "-") -> - | DE16: =(CZ16-DD16)/DD16 -> #DIV/0! | DF16: =(DA16-DD16)/DD16 -> #DIV/0! | DG16: =(DB16-DD16)/DD16 -> #DIV/0! | DH16: =(DC16-DD16)/DD16 -> #DIV/0! | DM16: =(CS16-CZ16)*10^6 -> 0 | DN16: =(CT16-DC16)*10^6 -> 0 | DO16: =(CW16-DD16)*10^6 -> 0
B17: Prépayé (yc commissions) | C17: CA10 | CU17: =+CR17-CS17 -> 0 | CV17: =+CR17-CT17 -> 0 | CX17: =IFERROR(CR17/CW17-1, "-") -> - | DE17: =(CZ17-DD17)/DD17 -> #DIV/0! | DF17: =(DA17-DD17)/DD17 -> #DIV/0! | DG17: =(DB17-DD17)/DD17 -> #DIV/0! | DH17: =(DC17-DD17)/DD17 -> #DIV/0! | DM17: =(CS17-CZ17)*10^6 -> 0 | DN17: =(CT17-DC17)*10^6 -> 0 | DO17: =(CW17-DD17)*10^6 -> 0
A18: Consumer Prepaid | C18: CA11 | CU18: =+CR18-CS18 -> 0 | CV18: =+CR18-CT18 -> 0 | CX18: =+CR18/CW18-1 -> #DIV/0! | DE18: =(CZ18-DD18)/DD18 -> #DIV/0! | DF18: =(DA18-DD18)/DD18 -> #DIV/0! | DG18: =(DB18-DD18)/DD18 -> #DIV/0! | DH18: =(DC18-DD18)/DD18 -> #DIV/0! | DM18: =(CS18-CZ18)*10^6 -> 0 | DN18: =(CT18-DC18)*10^6 -> 0 | DO18: =(CW18-DD18)*10^6 -> 0
B19: Frais d'activation & Sim swap | C19: CA12 | CU19: =+CR19-CS19 -> 0 | CV19: =+CR19-CT19 -> 0 | CX19: =+CR19/CW19-1 -> #DIV/0! | DE19: =(CZ19-DD19)/DD19 -> #DIV/0! | DF19: =(DA19-DD19)/DD19 -> #DIV/0! | DG19: =(DB19-DD19)/DD19 -> #DIV/0! | DH19: =(DC19-DD19)/DD19 -> #DIV/0! | DM19: =(CS19-CZ19)*10^6 -> 0 | DN19: =(CT19-DC19)*10^6 -> 0 | DO19: =(CW19-DD19)*10^6 -> 0
B20: Sortant voix on net | C20: CA13 | CU20: =+CR20-CS20 -> 0 | CV20: =+CR20-CT20 -> 0 | CX20: =+CR20/CW20-1 -> #DIV/0! | DE20: =(CZ20-DD20)/DD20 -> #DIV/0! | DF20: =(DA20-DD20)/DD20 -> #DIV/0! | DG20: =(DB20-DD20)/DD20 -> #DIV/0! | DH20: =(DC20-DD20)/DD20 -> #DIV/0! | DM20: =(CS20-CZ20)*10^6 -> 0 | DN20: =(CT20-DC20)*10^6 -> 0 | DO20: =(CW20-DD20)*10^6 -> 0
B21: Sortant voix MTN | C21: CA14 | CU21: =+CR21-CS21 -> 0 | CV21: =+CR21-CT21 -> 0 | CX21: =+CR21/CW21-1 -> #DIV/0! | DE21: =(CZ21-DD21)/DD21 -> #DIV/0! | DF21: =(DA21-DD21)/DD21 -> #DIV/0! | DG21: =(DB21-DD21)/DD21 -> #DIV/0! | DH21: =(DC21-DD21)/DD21 -> #DIV/0! | DM21: =(CS21-CZ21)*10^6 -> 0 | DN21: =(CT21-DC21)*10^6 -> 0 | DO21: =(CW21-DD21)*10^6 -> 0
B22: Sortant voix GLO | C22: CA15 | CU22: =+CR22-CS22 -> 0 | CV22: =+CR22-CT22 -> 0 | DM22: =(CS22-CZ22)*10^6 -> 0 | DN22: =(CT22-DC22)*10^6 -> 0 | DO22: =(CW22-DD22)*10^6 -> 0
B23: Sortant voix BBCOM | C23: CA16 | CU23: =+CR23-CS23 -> 0 | CV23: =+CR23-CT23 -> 0 | DM23: =(CS23-CZ23)*10^6 -> 0 | DN23: =(CT23-DC23)*10^6 -> 0 | DO23: =(CW23-DD23)*10^6 -> 0
B24: Sortant voix LIBERCOM | C24: CA17 | CU24: =+CR24-CS24 -> 0 | CV24: =+CR24-CT24 -> 0 | DM24: =(CS24-CZ24)*10^6 -> 0 | DN24: =(CT24-DC24)*10^6 -> 0 | DO24: =(CW24-DD24)*10^6 -> 0
B25: Sortant voix BTSA | C25: CA18 | CU25: =+CR25-CS25 -> 0 | CV25: =+CR25-CT25 -> 0 | CX25: =+CR25/CW25-1 -> #DIV/0! | DE25: =(CZ25-DD25)/DD25 -> #DIV/0! | DF25: =(DA25-DD25)/DD25 -> #DIV/0! | DG25: =(DB25-DD25)/DD25 -> #DIV/0! | DH25: =(DC25-DD25)/DD25 -> #DIV/0! | DM25: =(CS25-CZ25)*10^6 -> 0 | DN25: =(CT25-DC25)*10^6 -> 0 | DO25: =(CW25-DD25)*10^6 -> 0
B26: Sortant voix INTERNATIONAL | C26: CA19 | CU26: =+CR26-CS26 -> 0 | CV26: =+CR26-CT26 -> 0 | CX26: =+CR26/CW26-1 -> #DIV/0! | DE26: =(CZ26-DD26)/DD26 -> #DIV/0! | DF26: =(DA26-DD26)/DD26 -> #DIV/0! | DG26: =(DB26-DD26)/DD26 -> #DIV/0! | DH26: =(DC26-DD26)/DD26 -> #DIV/0! | DM26: =(CS26-CZ26)*10^6 -> 0 | DN26: =(CT26-DC26)*10^6 -> 0 | DO26: =(CW26-DD26)*10^6 -> 0
B27: Sortant voix roaming | C27: CA20 | CU27: =+CR27-CS27 -> 0 | CV27: =+CR27-CT27 -> 0 | CX27: =+CR27/CW27-1 -> #DIV/0! | DE27: =(CZ27-DD27)/DD27 -> #DIV/0! | DF27: =(DA27-DD27)/DD27 -> #DIV/0! | DG27: =(DB27-DD27)/DD27 -> #DIV/0! | DH27: =(DC27-DD27)/DD27 -> #DIV/0! | DM27: =(CS27-CZ27)*10^6 -> 0 | DN27: =(CT27-DC27)*10^6 -> 0 | DO27: =(CW27-DD27)*10^6 -> 0
B28: Total VOIX Sortant | C28: CA21 | CU28: =+CR28-CS28 -> 0 | CV28: =+CR28-CT28 -> 0 | CX28: =+CR28/CW28-1 -> #DIV/0! | DE28: =(CZ28-DD28)/DD28 -> #DIV/0! | DF28: =(DA28-DD28)/DD28 -> #DIV/0! | DG28: =(DB28-DD28)/DD28 -> #DIV/0! | DH28: =(DC28-DD28)/DD28 -> #DIV/0! | DM28: =(CS28-CZ28)*10^6 -> 0 | DN28: =(CT28-DC28)*10^6 -> 0 | DO28: =(CW28-DD28)*10^6 -> 0
C29: CA22 | CU29: =+CR29-CS29 -> 0 | CV29: =+CR29-CT29 -> 0 | DM29: =(CS29-CZ29)*10^6 -> 0 | DN29: =(CT29-DC29)*10^6 -> 0 | DO29: =(CW29-DD29)*10^6 -> 0
B30: Sortant sms on net | C30: CA23 | CU30: =+CR30-CS30 -> 0 | CV30: =+CR30-CT30 -> 0 | CX30: =+CR30/CW30-1 -> #DIV/0! | DE30: =(CZ30-DD30)/DD30 -> #DIV/0! | DF30: =(DA30-DD30)/DD30 -> #DIV/0! | DG30: =(DB30-DD30)/DD30 -> #DIV/0! | DH30: =(DC30-DD30)/DD30 -> #DIV/0! | DM30: =(CS30-CZ30)*10^6 -> 0 | DN30: =(CT30-DC30)*10^6 -> 0 | DO30: =(CW30-DD30)*10^6 -> 0
B31: Sortant sms MTN | C31: CA24 | CU31: =+CR31-CS31 -> 0 | CV31: =+CR31-CT31 -> 0 | CX31: =+CR31/CW31-1 -> #DIV/0! | DE31: =(CZ31-DD31)/DD31 -> #DIV/0! | DF31: =(DA31-DD31)/DD31 -> #DIV/0! | DG31: =(DB31-DD31)/DD31 -> #DIV/0! | DH31: =(DC31-DD31)/DD31 -> #DIV/0! | DM31: =(CS31-CZ31)*10^6 -> 0 | DN31: =(CT31-DC31)*10^6 -> 0 | DO31: =(CW31-DD31)*10^6 -> 0
B32: Sortant sms GLO | C32: CA25 | CU32: =+CR32-CS32 -> 0 | CV32: =+CR32-CT32 -> 0 | DM32: =(CS32-CZ32)*10^6 -> 0 | DN32: =(CT32-DC32)*10^6 -> 0 | DO32: =(CW32-DD32)*10^6 -> 0
B33: Sortant sms BBCOM | C33: CA26 | CU33: =+CR33-CS33 -> 0 | CV33: =+CR33-CT33 -> 0 | CX33: =+CR33/CW33-1 -> #DIV/0! | DE33: =(CZ33-DD33)/DD33 -> #DIV/0! | DF33: =(DA33-DD33)/DD33 -> #DIV/0! | DG33: =(DB33-DD33)/DD33 -> #DIV/0! | DH33: =(DC33-DD33)/DD33 -> #DIV/0! | DM33: =(CS33-CZ33)*10^6 -> 0 | DN33: =(CT33-DC33)*10^6 -> 0 | DO33: =(CW33-DD33)*10^6 -> 0
B34: Sortant sms LIBERCOM | C34: CA27 | CU34: =+CR34-CS34 -> 0 | CV34: =+CR34-CT34 -> 0 | CX34: =+CR34/CW34-1 -> #DIV/0! | DE34: =(CZ34-DD34)/DD34 -> #DIV/0! | DF34: =(DA34-DD34)/DD34 -> #DIV/0! | DG34: =(DB34-DD34)/DD34 -> #DIV/0! | DH34: =(DC34-DD34)/DD34 -> #DIV/0! | DM34: =(CS34-CZ34)*10^6 -> 0 | DN34: =(CT34-DC34)*10^6 -> 0 | DO34: =(CW34-DD34)*10^6 -> 0
B35: Sortant sms INTERNATIONAL | C35: CA28 | CU35: =+CR35-CS35 -> 0 | CV35: =+CR35-CT35 -> 0 | CX35: =+CR35/CW35-1 -> #DIV/0! | DE35: =(CZ35-DD35)/DD35 -> #DIV/0! | DF35: =(DA35-DD35)/DD35 -> #DIV/0! | DG35: =(DB35-DD35)/DD35 -> #DIV/0! | DH35: =(DC35-DD35)/DD35 -> #DIV/0! | DM35: =(CS35-CZ35)*10^6 -> 0 | DN35: =(CT35-DC35)*10^6 -> 0 | DO35: =(CW35-DD35)*10^6 -> 0
B36: Total SMS Sortant | C36: CA29 | CU36: =+CR36-CS36 -> 0 | CV36: =+CR36-CT36 -> 0 | CX36: =+CR36/CW36-1 -> #DIV/0! | DE36: =(CZ36-DD36)/DD36 -> #DIV/0! | DF36: =(DA36-DD36)/DD36 -> #DIV/0! | DG36: =(DB36-DD36)/DD36 -> #DIV/0! | DH36: =(DC36-DD36)/DD36 -> #DIV/0! | DM36: =(CS36-CZ36)*10^6 -> 0 | DN36: =(CT36-DC36)*10^6 -> 0 | DO36: =(CW36-DD36)*10^6 -> 0
C37: CA30 | CU37: =+CR37-CS37 -> 0 | CV37: =+CR37-CT37 -> 0 | DM37: =(CS37-CZ37)*10^6 -> 0 | DN37: =(CT37-DC37)*10^6 -> 0 | DO37: =(CW37-DD37)*10^6 -> 0
B38: Revenu Internet 3G | C38: CA31 | CU38: =+CR38-CS38 -> 0 | CV38: =+CR38-CT38 -> 0 | CX38: =+CR38/CW38-1 -> #DIV/0! | DE38: =(CZ38-DD38)/DD38 -> #DIV/0! | DF38: =(DA38-DD38)/DD38 -> #DIV/0! | DG38: =(DB38-DD38)/DD38 -> #DIV/0! | DH38: =(DC38-DD38)/DD38 -> #DIV/0! | DM38: =(CS38-CZ38)*10^6 -> 0 | DN38: =(CT38-DC38)*10^6 -> 0 | DO38: =(CW38-DD38)*10^6 -> 0
C39: CA32 | CU39: =+CR39-CS39 -> 0 | CV39: =+CR39-CT39 -> 0 | DM39: =(CS39-CZ39)*10^6 -> 0 | DN39: =(CT39-DC39)*10^6 -> 0 | DO39: =(CW39-DD39)*10^6 -> 0
B40: CRBT | C40: CA33 | CU40: =+CR40-CS40 -> 0 | CV40: =+CR40-CT40 -> 0 | CX40: =+CR40/CW40-1 -> #DIV/0! | DE40: =(CZ40-DD40)/DD40 -> #DIV/0! | DF40: =(DA40-DD40)/DD40 -> #DIV/0! | DG40: =(DB40-DD40)/DD40 -> #DIV/0! | DH40: =(DC40-DD40)/DD40 -> #DIV/0! | DM40: =(CS40-CZ40)*10^6 -> 0 | DN40: =(CT40-DC40)*10^6 -> 0 | DO40: =(CW40-DD40)*10^6 -> 0
B41: Crédit secours | C41: CA34 | CU41: =+CR41-CS41 -> 0 | CV41: =+CR41-CT41 -> 0 | CX41: =+CR41/CW41-1 -> #DIV/0! | DE41: =(CZ41-DD41)/DD41 -> #DIV/0! | DF41: =(DA41-DD41)/DD41 -> #DIV/0! | DG41: =(DB41-DD41)/DD41 -> #DIV/0! | DH41: =(DC41-DD41)/DD41 -> #DIV/0! | DM41: =(CS41-CZ41)*10^6 -> 0 | DN41: =(CT41-DC41)*10^6 -> 0 | DO41: =(CW41-DD41)*10^6 -> 0
B42: Story Box | C42: CA35 | CU42: =+CR42-CS42 -> 0 | CV42: =+CR42-CT42 -> 0 | DM42: =(CS42-CZ42)*10^6 -> 0 | DN42: =(CT42-DC42)*10^6 -> 0 | DO42: =(CW42-DD42)*10^6 -> 0
...

Sheet Marge Mobile
A2: Marge brute Mobile | CS2: 25912.891 | CT2: 25481.374 | CW2: 56170.705
E3: 0 | G3: 0 | CZ3: 0 | DD3: 0
D4: 45292 | J4: 45323 | P4: 45352 | V4: 45383 | AD4: 45413 | AL4: 45444 | AU4: 45474 | BC4: 45505 | BK4: 45536 | BT4: 45566 | CB4: 45597 | CJ4: 45627 | CR4: CUMUL | CZ4: ANNUEL
B5: (En Millions ML) | D5: 2024 Réel | E5: 2024 Budget | F5: Ecart / Budget | G5: 2023 Réel | H5: Evol % | J5: 2024 Réel | K5: 2024 Budget | L5: Ecart / Budget | M5: 2023 Réel | N5: Evol % | P5: 2024 Réel | Q5: 2024 Budget | R5: Ecart / Budget | S5: 2023 Réel | T5: Evol % | V5: 2024 Réel | W5: 2024 Budget | X5: 2024 Actu1 | Y5: Ecart / Budget | Z5: Ecart / Actu1 | AA5: 2023 Réel | AB5: Evol % | AD5: 2024 Réel | AE5: 2024 Budget | AF5: 2024 Actu1 | AG5: Ecart / Budget | AH5: Ecart / Actu1 | AI5: 2023 Réel | AJ5: Evol % | AL5: 2024 Réel | AM5: 2024 Budget | AN5: 2024 Actu1 | AO5: 2024 Actu2 | AP5: Ecart / Budget | AQ5: Ecart / Actu1 | AR5: 2023 Réel | AS5: Evol % | AU5: 2024 Réel | AV5: 2024 Budget | AW5: 2024 Actu2 | AX5: Ecart / Budget | AY5: Ecart / Actu2 | AZ5: 2023 Réel | BA5: Evol % | BC5: 2024 Réel | BD5: 2024 Budget | BE5: 2024 Actu2 | BF5: Ecart / Budget | BG5: Ecart / Actu2 | BH5: 2023 Réel | BI5: Evol % | BK5: 2024 Réel | BL5: 2024 Budget | BM5: 2024 Actu2 | BN5: 2024 Actu3 | BO5: Ecart / Budget | BP5: Ecart / Actu2 | BQ5: 2023 Réel | BR5: Evol % | BT5: 2024 Réel | BU5: 2024 Budget | BV5: 2024 Actu3 | BW5: Ecart / Budget | BX5: Ecart / Actu3 | BY5: 2023 Réel | BZ5: Evol % | CB5: 2024 Réel | CC5: 2024 Budget | CD5: 2024 Actu3 | CE5: Ecart / Budget | CF5: Ecart / Actu3 | CG5: 2023 Réel | CH5: Evol % | CJ5: 2024 Réel | CK5: 2024 Budget | CL5: 2024 Actu3 | CM5: Ecart / Budget | CN5: Ecart / Actu3 | CO5: 2023 Réel | CP5: Evol % | CR5: 2024 Réel | CS5: 2024 Budget | CT5: 2024 Actu3 | CU5: Ecart / Budget | CV5: Ecart / Actu3 | CW5: 2023 Réel | CX5: Evol % | CZ5: 2024 Budget | DA5: 2024 Actu1 | DB5: 2024 Actu2 | DC5: 2024 Actu3 | DD5: 2023 Réel | DE5: Bud / 2023 (%) | DF5: Actu 1 / 2023 (%) | DG5: Actu 2 / 2023 (%) | DH5: Actu3 / 2023 (%) | DJ5: 2024 Réel | DK5: 2024 Budget | DL5: 2023 Réel | DM5: Actu
DJ6: =SUM(D6,J6,P6,V6,AD6,AL6,AU6,BC6,BK6,BT6,CB6,CJ6)-CR6 -> 0 | DK6: =SUM(E6,K6,Q6,W6,AE6,AM6,AV6,BD6,BL6,BU6,CC6,CK6)-CS6 -> 0 | DL6: =SUM(G6,M6,S6,AA6,AI6,AR6,AZ6,BH6,BQ6,BY6,CG6,CO6)-CW6 -> 0 | DM6: =SUM(D6,J6,P6,V6,AD6,AL6,AU6,BC6,,BN6,BV6,CD6,CL6)-CT6 -> 0
A7: Total Revenu | C7: MB1 | CU7: =+CR7-CS7 -> 0 | CV7: =+CR7-CT7 -> 0 | CX7: =IFERROR(CR7/CW7-1, "-") -> - | DE7: =CZ7/DD7-1 -> #DIV/0! | DF7: =DA7/DD7-1 -> #DIV/0! | DG7: =DB7/DD7-1 -> #DIV/0! | DH7: =DC7/DD7-1 -> #DIV/0! | DJ7: =SUM(D7,J7,P7,V7,AD7,AL7,AU7,BC7,BK7,BT7,CB7,CJ7)-CR7 -> 0 | DK7: =SUM(E7,K7,Q7,W7,AE7,AM7,AV7,BD7,BL7,BU7,CC7,CK7)-CS7 -> 0 | DL7: =SUM(G7,M7,S7,AA7,AI7,AR7,AZ7,BH7,BQ7,BY7,CG7,CO7)-CW7 -> 0 | DM7: =SUM(D7,J7,P7,V7,AD7,AL7,AU7,BC7,,BN7,BV7,CD7,CL7)-CT7 -> 0
B8: Trafic (mn) | C8: MB2 | CU8: =+CR8-CS8 -> 0 | CV8: =+CR8-CT8 -> 0 | CX8: =IFERROR(CR8/CW8-1, "-") -> - | DE8: =CZ8/DD8-1 -> #DIV/0! | DF8: =DA8/DD8-1 -> #DIV/0! | DG8: =DB8/DD8-1 -> #DIV/0! | DH8: =DC8/DD8-1 -> #DIV/0! | DJ8: =SUM(D8,J8,P8,V8,AD8,AL8,AU8,BC8,BK8,BT8,CB8,CJ8)-CR8 -> 0 | DK8: =SUM(E8,K8,Q8,W8,AE8,AM8,AV8,BD8,BL8,BU8,CC8,CK8)-CS8 -> 0 | DL8: =SUM(G8,M8,S8,AA8,AI8,AR8,AZ8,BH8,BQ8,BY8,CG8,CO8)-CW8 -> 0 | DM8: =SUM(D8,J8,P8,V8,AD8,AL8,AU8,BC8,,BN8,BV8,CD8,CL8)-CT8 -> 0 | DX8: =CS8-CZ8 -> 0 | DY8: =CT8-DC8 -> 0 | DZ8: =CW8-DD8 -> 0
B9: Coût unitaire | C9: MB3 | CU9: =+CR9-CS9 -> 0 | CV9: =+CR9-CT9 -> 0 | CX9: =IFERROR(CR9/CW9-1, "-") -> - | DE9: =CZ9/DD9-1 -> #DIV/0! | DF9: =DA9/DD9-1 -> #DIV/0! | DG9: =DB9/DD9-1 -> #DIV/0! | DH9: =DC9/DD9-1 -> #DIV/0! | DJ9: =SUM(D9,J9,P9,V9,AD9,AL9,AU9,BC9,BK9,BT9,CB9,CJ9)-CR9 -> 0 | DK9: =SUM(E9,K9,Q9,W9,AE9,AM9,AV9,BD9,BL9,BU9,CC9,CK9)-CS9 -> 0 | DL9: =SUM(G9,M9,S9,AA9,AI9,AR9,AZ9,BH9,BQ9,BY9,CG9,CO9)-CW9 -> 0 | DM9: =SUM(D9,J9,P9,V9,AD9,AL9,AU9,BC9,,BN9,BV9,CD9,CL9)-CT9 -> 0 | DX9: =(CS9-CZ9)*10^6 -> 0 | DY9: =(CT9-DC9)*10^6 -> 0 | DZ9: =(CW9-DD9)*10^6 -> 0
B10: International | C10: MB4 | CU10: =+CR10-CS10 -> 0 | CV10: =+CR10-CT10 -> 0 | CX10: =IFERROR(CR10/CW10-1, "-") -> - | DE10: =CZ10/DD10-1 -> #DIV/0! | DF10: =DA10/DD10-1 -> #DIV/0! | DG10: =DB10/DD10-1 -> #DIV/0! | DH10: =DC10/DD10-1 -> #DIV/0! | DJ10: =SUM(D10,J10,P10,V10,AD10,AL10,AU10,BC10,BK10,BT10,CB10,CJ10)-CR10 -> 0 | DK10: =SUM(E10,K10,Q10,W10,AE10,AM10,AV10,BD10,BL10,BU10,CC10,CK10)-CS10 -> 0 | DL10: =SUM(G10,M10,S10,AA10,AI10,AR10,AZ10,BH10,BQ10,BY10,CG10,CO10)-CW10 -> 0 | DM10: =SUM(D10,J10,P10,V10,AD10,AL10,AU10,BC10,,BN10,BV10,CD10,CL10)-CT10 -> 0 | DX10: =(CS10-CZ10)*10^6 -> 0 | DY10: =(CT10-DC10)*10^6 -> 0 | DZ10: =(CW10-DD10)*10^6 -> 0
B11: Trafic (mn) | C11: MB5 | CU11: =+CR11-CS11 -> 0 | CV11: =+CR11-CT11 -> 0 | CX11: =IFERROR(CR11/CW11-1, "-") -> - | DJ11: =SUM(D11,J11,P11,V11,AD11,AL11,AU11,BC11,BK11,BT11,CB11,CJ11)-CR11 -> 0 | DK11: =SUM(E11,K11,Q11,W11,AE11,AM11,AV11,BD11,BL11,BU11,CC11,CK11)-CS11 -> 0 | DL11: =SUM(G11,M11,S11,AA11,AI11,AR11,AZ11,BH11,BQ11,BY11,CG11,CO11)-CW11 -> 0 | DM11: =SUM(D11,J11,P11,V11,AD11,AL11,AU11,BC11,,BN11,BV11,CD11,CL11)-CT11 -> 0 | DX11: =(CS11-CZ11)*10^6 -> 0 | DY11: =(CT11-DC11)*10^6 -> 0 | DZ11: =(CW11-DD11)*10^6 -> 0
B12: Coût unitaire | C12: MB6 | CU12: =+CR12-CS12 -> 0 | CV12: =+CR12-CT12 -> 0 | CX12: =IFERROR(CR12/CW12-1, "-") -> - | DJ12: =SUM(D12,J12,P12,V12,AD12,AL12,AU12,BC12,BK12,BT12,CB12,CJ12)-CR12 -> 0 | DK12: =SUM(E12,K12,Q12,W12,AE12,AM12,AV12,BD12,BL12,BU12,CC12,CK12)-CS12 -> 0 | DL12: =SUM(G12,M12,S12,AA12,AI12,AR12,AZ12,BH12,BQ12,BY12,CG12,CO12)-CW12 -> 0 | DM12: =SUM(D12,J12,P12,V12,AD12,AL12,AU12,BC12,,BN12,BV12,CD12,CL12)-CT12 -> 0 | DX12: =(CS12-CZ12)*10^6 -> 0 | DY12: =(CT12-DC12)*10^6 -> 0 | DZ12: =(CW12-DD12)*10^6 -> 0
B13: Transit Sortant International depuis les concurents | C13: MB7 | CU13: =+CR13-CS13 -> 0 | CV13: =+CR13-CT13 -> 0 | CX13: =IFERROR(CR13/CW13-1, "-") -> - | DJ13: =SUM(D13,J13,P13,V13,AD13,AL13,AU13,BC13,BK13,BT13,CB13,CJ13)-CR13 -> 0 | DK13: =SUM(E13,K13,Q13,W13,AE13,AM13,AV13,BD13,BL13,BU13,CC13,CK13)-CS13 -> 0 | DL13: =SUM(G13,M13,S13,AA13,AI13,AR13,AZ13,BH13,BQ13,BY13,CG13,CO13)-CW13 -> 0 | DM13: =SUM(D13,J13,P13,V13,AD13,AL13,AU13,BC13,,BN13,BV13,CD13,CL13)-CT13 -> 0 | DX13: =(CS13-CZ13)*10^6 -> 0 | DY13: =(CT13-DC13)*10^6 -> 0 | DZ13: =(CW13-DD13)*10^6 -> 0
