Workbook
Name \e: #N/A
Name \M: #REF!
Name \M: #REF!
Name \M: #REF!
Name \M: #REF!
Name \M: #REF!
Name \M: #REF!
Name \p: '[1]Cur Q v Plan'!#REF!
Name \p: '[1]Cur Q v Plan'!#REF!
Name \p: '[1]Cur Q v Plan'!#REF!
Name \p: '[1]Cur Q v Plan'!#REF!
Name \p: '[1]Cur Q v Plan'!#REF!
Name \p: '[1]Cur Q v Plan'!#REF!
Name \r: #N/A
Name \t: #N/A
Name _: #REF!
Name _: #REF!
Name _: #REF!
Name _: #REF!
Name _: #REF!
Name _: #REF!
Name __: #REF!
Name __: #REF!
Name __: #REF!
Name __: #REF!
Name ___________B1: #N/A
Name ___________eng2: #N/A
Name ___________eng3: 'Data Mobile '!___________eng3
Name ___________eng3: 'Mobile Money'!___________eng3
Name ___________eng3: 'Data Mobile '!___________eng3
Name ___________eng4: #N/A
Name __________B1: #N/A
Name __________eng2: #N/A
Name __________eng3: 'Data Mobile '!__________eng3
Name __________eng3: 'Mobile Money'!__________eng3
Name __________eng3: 'Data Mobile '!__________eng3
Name __________eng4: #N/A
Name _________eng3: 'Data Mobile '!_________eng3
Name _________eng3: 'Mobile Money'!_________eng3
Name _________eng3: 'Data Mobile '!_________eng3
Name ________eng3: 'Data Mobile '!________eng3
Name ________eng3: 'Mobile Money'!________eng3
Name ________eng3: 'Data Mobile '!________eng3
Name _______eng3: 'Data Mobile '!_______eng3
Name _______eng3: 'Mobile Money'!_______eng3
Name _______eng3: 'Data Mobile '!_______eng3
Name ______eng3: 'Data Mobile '!______eng3
Name ______eng3: 'Mobile Money'!______eng3
Name ______eng3: 'Data Mobile '!______eng3
Name ______FRF4: '[2]FX Rates'!$G$10
Name ______FRF4: '[2]FX Rates'!$G$10
Name ______GBP4: '[2]FX Rates'!$G$9
Name ______GBP4: '[2]FX Rates'!$G$9
Name _____0: #REF!
Name _____0: #REF!
Name _____0: #REF!
Name _____0: #REF!
Name _____0: #REF!
Name _____12: #REF!
Name _____12: #REF!

Sheet ANALYSE
D4: ELEMENTS | E4: Actu2 | F4: Budget 24 | G4: Variation | J4: ELEMENTS | K4: ACTU2 | L4: Budget 24 | M4: Variation
D5: SORTANT PREPAID (VOIX, SMS, SVA) | E5: =+'CA Mobile'!O14 -> 41713.594 | F5: 42546.216 | G5: =+E5-F5 -> -832.62157 | K5: Coût | L5: Coût
D6: DATA | E6: =+'CA Mobile'!O136 -> 52607.642 | F6: 55738.929 | G6: =+E6-F6 -> -3131.2878 | J6: Commissions Distributeurs | K6: =+'Marge Mobile '!O36+'Marge Mobile '!O37 -> -7604.8287 | L6: -7649.091 | M6: =+K6-L6 -> 44.262322
D7: VENTE DE TERMINAUX | E7: =+'CA Mobile'!O170 -> 2246.6647 | F7: 1788 | G7: =+E7-F7 -> 458.66474 | J7: SVA | K7: =+'Marge Mobile '!O25 -> -374.89955 | L7: -442.21631 | M7: =+K7-L7 -> 67.316763
E8: =SUM(E5:E7) -> 96567.9 | F8: =SUM(F5:F7) -> 100073.14 | G8: =+E8-F8 -> -3505.2447 | J8: Achat de terminaux | K8: =+'Marge Mobile '!O31 -> -2021.9983 | L8: -1609.2 | M8: =+K8-L8 -> -412.79827
D9: SVA | E9: =+'CA Mobile'!O44+'CA Mobile'!O76+'CA Mobile'!O101+SUM('CA Mobile'!O123:O130) -> 1342.5418 | F9: 739.36062 | G9: =+E9-F9 -> 603.18117
D10: POSTPAID | E10: =+'CA Mobile'!O47 -> 3522.7874 | F10: 3720.9151 | G10: =+E10-F10 -> -198.12771
D11: ROAMING | E11: =+'CA Mobile'!O168 -> 1946.1155 | F11: 564.8223 | G11: =+E11-F11 -> 1381.2932 | J11: International sortant | K11: =+'Marge Mobile '!O11 -> -1987.96 | L11: -1651.9842 | M11: =+K11-L11 -> -335.97582
D12: LS ET VENTE DE CAPACITE | E12: =+'CA Mobile'!O135 -> 1762.1956 | F12: 840 | G12: =+E12-F12 -> 922.19558 | J12: Roaming out et interconnexion SMS | K12: =+'Marge Mobile '!O29+'Marge Mobile '!O28 -> -837.76983 | L12: -544.24674 | M12: =+K12-L12 -> -293.52308
D13: COLOCATION | E13: =+'CA Mobile'!O162 -> 864.16902 | F13: 1565.8803 | G13: =+E13-F13 -> -701.71126 | J13: Achat de capacité | K13: =+'Marge Mobile '!O20 -> -590.3613 | L13: 0 | M13: =+K13-L13 -> -590.3613
D14: ENTRANT INTERNATIONAL | E14: =+'CA Mobile'!O156 -> 2352.548 | F14: 2696.9631 | G14: =+E14-F14 -> -344.41501
E15: =SUM(E10:E14) -> 10447.816 | F15: =SUM(F10:F14) -> 9388.5808 | G15: =+E15-F15 -> 1059.2348 | J15: Commissions MM | K15: =+'Marge Mobile '!O38 -> -5233.6426 | L15: -4873.0681 | M15: =+K15-L15 -> -360.57449
D17: MOOV MONEY | E17: =+'CA Mobile'!O134 -> 7318.0478 | F17: 6437.8944 | G17: =+E17-F17 -> 880.15338 | J17: TOTAL | K17: =SUM(K6:K15) -> -18651.46 | L17: =SUM(L6:L15) -> -16769.806 | M17: =+K17-L17 -> -1881.6539
D19: TOTAL | E19: =+E8+E15+E17 -> 114333.76 | F19: =+F8+F15+F17 -> 115899.62 | G19: =+E19-F19 -> -1565.8564
J20: IMPACT MARGE | L20: SVA | M20: =+G9+M7 -> 670.49793
L21: DATA ET VOIX | M21: =+G5+G6+M6 -> -3919.6471
L22: INTERNATIONAL | M22: =+G14+M11 -> -680.39083
L23: CAPACITE | M23: =+G12+M13 -> 331.83428
M24: =SUM(M20:M23) -> -3597.7057

Sheet Cover
E15: MOOV BENIN BUDGET 2025
F5602: U | G5602: 1000 | H5602: U | I5602: XOF | J5602: 847 | K5602: 763 | L5602: 762712 | M5602: ONATEL
A5603: 41743 | B5603: FC DRC1150-014779 | C5603: BL DRC1150-002137 | D5603: DRC11500 | E5603: 1 | F5603: U | G5603: 1 | H5603: U | I5603: XOF | J5603: 848 | K5603: 848 | L5603: 848 | M5603: ONATEL
A5604: 41743 | B5604: FC DRC1150-014784 | C5604: BL DRC1150-002142 | D5604: DRC11500 | E5604: 42 | F5604: U | G5604: 42 | H5604: U | I5604: XOF | J5604: 847 | K5604: 847 | L5604: 35593 | M5604: ONATEL
A5605: 41744 | B5605: FC DRN5010-004909 | C5605: CC DRN5010-004906 | D5605: DI5010004 | E5605: 500 | F5605: U | G5605: 500 | H5605: U | I5605: XOF | J5605: 847 | K5605: 763 | L5605: 381356 | M5605: ONATEL
A5606: 41744 | B5606: FC DRC1130-008172 | C5606: CC DRC1130-008119 | D5606: DRC11300 | E5606: 1 | F5606: U | G5606: 1 | H5606: U | I5606: XOF | J5606: 848 | K5606: 848 | L5606: 848 | M5606: ONATEL
A5607: 41744 | B5607: FC DRC1080-004286 | C5607: CC DRC1080-004381 | D5607: DRC10800 | E5607: 3 | F5607: U | G5607: 3 | H5607: U | I5607: XOF | J5607: 847 | K5607: 847 | L5607: 2542 | M5607: ONATEL
A5608: 41744 | B5608: FC DRC1130-008174 | C5608: CC DRC1130-008121 | D5608: DRC11300 | E5608: 13 | F5608: U | G5608: 13 | H5608: U | I5608: XOF | J5608: 847 | K5608: 847 | L5608: 11016 | M5608: ONATEL
A5609: 41744 | B5609: FC DRC1150-014797 | C5609: CC DRC1150-015116 | D5609: DRC11500 | E5609: 1 | F5609: U | G5609: 1 | H5609: U | I5609: XOF | J5609: 848 | K5609: 848 | L5609: 848 | M5609: ONATEL
A5610: 41744 | B5610: FC DRC1110-004324 | C5610: CC DRC1110-004283 | D5610: DRC11100 | E5610: 1 | F5610: U | G5610: 1 | H5610: U | I5610: XOF | J5610: 848 | K5610: 848 | L5610: 848 | M5610: ONATEL
A5611: 41744 | B5611: FC DRO6070-000412 | C5611: CC DRO6070-000407 | D5611: DRO60700 | E5611: 1 | F5611: U | G5611: 1 | H5611: U | I5611: XOF | J5611: 848 | K5611: 848 | L5611: 848 | M5611: ONATEL
A5612: 41744 | B5612: FC DRC1150-014790 | C5612: CC DRC1150-015109 | D5612: DRC11500 | E5612: 8 | F5612: U | G5612: 8 | H5612: U | I5612: XOF | J5612: 848 | K5612: 848 | L5612: 6780 | M5612: ONATEL
A5613: 41744 | B5613: FC DRC1120-012603 | C5613: CC DRC1120-012589 | D5613: DI1120055 | E5613: 2000 | F5613: U | G5613: 2000 | H5613: U | I5613: XOF | J5613: 847 | K5613: 763 | L5613: 1525424 | M5613: ONATEL
A5614: 41744 | B5614: FC DRC1140-009616 | C5614: CC DRC1140-010229 | D5614: DRC11400 | E5614: 1 | F5614: U | G5614: 1 | H5614: U | I5614: XOF | J5614: 848 | K5614: 848 | L5614: 848 | M5614: ONATEL
A5615: 41744 | B5615: FC DRC1140-009619 | C5615: CC DRC1140-010232 | D5615: DRC11400 | E5615: 3 | F5615: U | G5615: 3 | H5615: U | I5615: XOF | J5615: 847

Sheet P&L conso
B1: P&L consolidé
C2: JANV | D2: FEV | E2: Mars | F2: AVR | G2: MAI | H2: JUIN | I2: JUIL | J2: AOUT | K2: SEPT | L2: OCT | M2: NOV | N2: DEC | O2: ANNUEL | S2: VARIATIONS
B3: (En Millions ML) | C3: 2025 Budget | D3: 2025 Budget | E3: 2025 Budget | F3: 2025 Budget | G3: 2025 Budget | H3: 2025 Budget | I3: 2025 Budget | J3: 2025 Budget | K3: 2025 Budget | L3: 2025 Budget | M3: 2025 Budget | N3: 2025 Budget | O3: 2025 Budget | P3: 2024 Actu3 | Q3: 2023 Réel | R3: Budget initial | S3: Var Budget 25 vs Actu 3. % | T3: Var Actu 3 2024 vs Réel 2023. % | U3: Var Budget 2025 vs Budget 2024. % | AG3: Annuel
AC4: (En Millions Dh) | AG4: 2023 Réel | AH4: 2024 Actu3 | AI4: Budget 2025 | AJ4: A3 / 2023 (%) | AK4: B25 / A3 (%)
B5: Chiffre d'affaires | C5: =C7 -> 9527.0891 | D5: =D7 -> 8782.1227 | E5: =E7 -> 9473.1389 | F5: =F7 -> 9362.5379 | G5: =G7 -> 9772.4636 | H5: =H7 -> 9466.6859 | I5: =I7 -> 9614.0551 | J5: =J7 -> 9618.2497 | ... N5: =N7 -> 10293.443 | O5: =SUM(C5,D5,E5,F5,G5,H5,I5,J5,K5,L5,M5,N5) -> 114333.76 | P5: 108391.85 | Q5: 105542.99 | R5: 115899.62 | S5: =O5/P5-1 -> 0.054818851 | T5: =P5/Q5-1 -> 0.026992374 | U5: =O5/R5-1 -> -0.013510454 | V5: 108887.36 | W5: =P5-V5 -> -495.5082 | AG5: =+AG8-Q5 -> 0 | AH5: =AH8-P5 -> 495.5082 | AI5: =AI8-O5 -> 0.00026070813
B6: Fixe & Internet | C6: 0 | D6: 0 | E6: 0 | F6: 0 | G6: 0 | H6: 0 | I6: 0 | J6: 0 | K6: 0 | L6: 0 | M6: 0 | N6: 0 | Q6: 0 | T6: =P6/Q6-1 -> #DIV/0! | W6: =P6-V6 -> 0 | AC6: Chiffre d'affaires | AG6: 105542.99 | AH6: 108887.36 | AI6: 114333.76 | AJ6: 0.031687221 | AK6: 0.050018743
B7: Mobile | C7: =C8 -> 9527.0891 | D7: =D8 -> 8782.1227 | E7: =E8 -> 9473.1389 | F7: =F8 -> 9362.5379 | G7: =G8 -> 9772.4636 | H7: =H8 -> 9466.6859 | I7: =I8 -> 9614.0551 | J7: =J8 -> 9618.2497 | ... O7: =O8 -> 114333.76 | P7: 108391.85 | Q7: =Q8 -> 105542.99 | R7: 115899.62 | S7: =O7/P7-1 -> 0.054818851 | T7: =P7/Q7-1 -> 0.026992374 | U7: =O7/R7-1 -> -0.013510454 | V7: 108887.36 | W7: =P7-V7 -> -495.5082 | AD7: Fixe & Internet | AJ7: #DIV/0! | AK7: #DIV/0!
B8: Intercompagnie Mobile | C8: ='CA Mobile'!C7 -> 9527.0891 | D8: ='CA Mobile'!D7 -> 8782.1227 | E8: ='CA Mobile'!E7 -> 9473.1389 | F8: ='CA Mobile'!F7 -> 9362.5379 | G8: ='CA Mobile'!G7 -> 9772.4636 | H8: ='CA Mobile'!H7 -> 9466.6859 | I8: ='CA Mobile'!I7 -> 9614.0551 | J8: ='CA Mobile'!J7 -> 9618.2497 | ... O8: ='CA Mobile'!O7 -> 114333.76 | P8: 108391.85 | Q8: =+Q5 -> 105542.99 | R8: 115899.62 | S8: =O8/P8-1 -> 0.054818851 | T8: =P8/Q8-1 -> 0.026992374 | U8: =O8/R8-1 -> -0.013510454 | V8: 108887.36 | W8: =P8-V8 -> -495.5082 | AD8: Mobile | AG8: 105542.99 | AH8: 108887.36 | AI8: 114333.76 | AJ8: 0.031687221 | AK8: 0.050018743
C9: 0 | D9: 0 | E9: 0 | F9: 0 | G9: 0 | H9: 0 | I9: 0 | J9: 0 | K9: 0 | L9: 0 | M9: 0 | N9: 0 | Q9: 0 | S9: =O9-Q9 -> 0 | T9: =P9/Q9-1 -> #DIV/0! | U9: =O9/R9-1 -> #DIV/0! | W9: =P9-V9 -> 0
B10: Intercompagnie | C10: 0 | D10: 0 | E10: 0 | F10: 0 | G10: 0 | H10: 0 | I10: 0 | J10: 0 | K10: 0 | L10: 0 | M10: 0 | N10: 0 | Q10: 0 | S10: =O10-Q10 -> 0 | T10: =P10/Q10-1 -> #DIV/0! | U10: =O10/R10-1 -> #DIV/0! | W10: =P10-V10 -> 0 | AD10: Intercompagnie | AJ10: #DIV/0! | AK10: #DIV/0!
B11: dont Intercompagnie hors trafic | C11: 0 | D11: 0 | E11: 0 | F11: 0 | G11: 0 | H11: 0 | I11: 0 | J11: 0 | K11: 0 | L11: 0 | M11: 0 | N11: 0 | Q11: 0 | S11: =O11-Q11 -> 0 | T11: =P11/Q11-1 -> #DIV/0! | U11: =O11/R11-1 -> #DIV/0! | W11: =P11-V11 -> 0 | AD11: dont intercompagnie hors trafic
C12: 0 | D12: 0 | E12: 0 | F12: 0 | G12: 0 | H12: 0 | I12: 0 | J12: 0 | K12: 0 | L12: 0 | M12: 0 | N12: 0 | P12: -7.2000003e-05 | Q12: 0 | S12: =O12-Q12 -> 0 | V12: 0 | W12: =P12-V12 -> -7.2000003e-05 | AG12: =AG13+Q13 -> 0 | AH12: =+AH13+P13 -> 49.564045 | AI12: =+AI13+O13 -> 0
B13: Coût des ventes | C13: =C15 -> -1517.7256 | D13: =D15 -> -1459.5803 | E13: =E15 -> -1580.7997 | F13: =F15 -> -1545.981 | G13: =G15 -> -1578.2509 | H13: =H15 -> -1551.4919 | I13: =I15 -> -1581.9014 | J13: =J15 -> -1573.4276 | ... N13: =N15 -> -1637.9559 | O13: =SUM(C13,D13,E13,F13,G13,H13,I13,J13,K13,L13,M13,N13) -> -18651.46 | P13: -17895.733 | Q13: -15895.604 | R13: -16769.806 | S13: =O13/P13-1 -> 0.042229479 | T13: =P13/Q13-1 -> 0.12582906 | U13: =O13/R13-1 -> 0.11220487 | V13: -17945.297 | W13: =P13-V13 -> 49.564045 | AD13: Coût des ventes | AG13: 15895.604 | AH13: 17945.297 | AI13: 18651.46 | AJ13: 0.12894716 | AK13: 0.039350891
B14: Fixe & Internet | Q14: 0 | S14: =O14-Q14 -> 0 | T14: =P14/Q14-1 -> #DIV/0! | W14: =P14-V14 -> 0 | AD14: Fixe & Internet | AJ14: #DIV/0! | AK14: #DIV/0!
B15: Mobile | C15: =C16 -> -1517.7256 | D15: =D16 -> -1459.5803 | E15: =E16 -> -1580.7997 | F15: =F16 -> -1545.981 | G15: =G16 -> -1578.2509 | H15: =H16 -> -1551.4919 | I15: =I16 -> -1581.9014 | J15: =J16 -> -1573.4276 | ... N15: =N16 -> -1637.9559 | O15: =O13 -> -18651.46 | P15: -17895.733 | Q15: -15895.604 | R15: -16769.806 | S15: =O15/P15-1 -> 0.042229479 | T15: =P15/Q15-1 -> 0.12582906 | U15: =O15/R15-1 -> 0.11220487 | V15: -17945.297 | W15: =P15-V15 -> 49.564045 | AD15: Mobile | AG15: 15895.604 | AH15: 17945.297 | AI15: 18651.46 | AJ15: 0.12894716 | AK15: 0.039350891
B16: Intercompagnie Mobile | C16: ='Marge Mobile '!C39 -> -1517.7256 | D16: ='Marge Mobile '!D39 -> -1459.5803 | E16: ='Marge Mobile '!E39 -> -1580.7997 | F16: ='Marge Mobile '!F39 -> -1545.981 | G16: ='Marge Mobile '!G39 -> -1578.2509 | H16: ='Marge Mobile '!H39 -> -1551.4919 | I16: ='Marge Mobile '!I39 -> -1581.9014 | J16: ='Marge Mobile '!J39 -> -1573.4276 | ... N16: ='Marge Mobile '!N39 -> -1637.9559 | O16: =O13 -> -18651.46 | P16: -17895.733 | Q16: -15895.604 | R16: -16769.806 | S16: =O16/P16-1 -> 0.042229479 | T16: =P16/Q16-1 -> 0.12582906 | U16: =O16/R16-1 -> 0.11220487 | V16: -17945.297 | W16: =P16-V16 -> 49.564045 | AG16: =+Q18-AG17 -> 0 | AH16: =AH17-P18 -> 445.94416 | AI16: =AI17-O18 -> 0.00026070813
C17: 0 | D17: 0 | E17: 0 | F17: 0 | G17: 0 | H17: 0 | I17: 0 | J17: 0 | K17: 0 | L17: 0 | M17: 0 | N17: 0 | P17: 0.092828847 | Q17: 0 | S17: =O17-Q17 -> 0 | V17: 0 | W17: =P17-V17 -> 0.092828847 | AC17: Marge Brute | AG17: 89647.387 | AH17: 90942.059 | AI17: 95682.304 | AJ17: 0.014441817 | AK17: 0.052123795
B18: Marge Brute | C18: =C5+C13 -> 8009.3634 | D18: =D5+D13 -> 7322.5424 | E18: =E5+E13 -> 7892.3393 | F18: =F5+F13 -> 7816.5569 | G18: =G5+G13 -> 8194.2127 | H18: =H5+H13 -> 7915.194 | I18: =I5+I13 -> 8032.1538 | J18: =J5+J13 -> 8044.8221 | ... N18: =N5+N13 -> 8655.4868 | O18: =+O5+O13 -> 95682.303 | P18: 90496.114 | Q18: 89647.387 | R18: 99129.814 | S18: =O18/P18-1 -> 0.057308417 | T18: =P18/Q18-1 -> 0.0094673922 | U18: =O18/R18-1 -> -0.034777734 | V18: 90942.059 | W18: =P18-V18 -> -445.94416 | AD18: % | AG18: 0.84939214 | AH18: 0.83519393 | AI18: 0.83686831 | AJ18: -1.4198209 | AK18: 0.16743764
B19: % CA | C19: =C18/C5 -> 0.84069366 | D19: =D18/D5 -> 0.83380097 | E19: =E18/E5 -> 0.83312821 | F19: =F18/F5 -> 0.83487586 | G19: =G18/G5 -> 0.8385002 | H19: =H18/H5 -> 0.83611034 | I19: 0.73060125 | J19: =J18/J5 -> 0.83641227 | K19: =K18/K5 -> 0.83585444 | L19: =L18/L5 -> 0.83786985 | M19: =M18/M5 -> 0.83816198 | N19: =N18/N5 -> 0.84087385 | O19: =+O18/O5 -> 0.83686831 | P19: 0.8348978 | Q19: 0.84939214 | R19: 0.8553075 | S19: =O19/P19-1 -> 0.0023601834 | T19: =P19/Q19-1 -> -0.017064374 | U19: =O19/R19-1 -> -0.021558546 | V19: 0.83519393 | W19: =P19-V19 -> -0.00029613586 | AD19: Fixe & Internet | AJ19: #DIV/0! | AK19: #DIV/0!
B20: Fixe & Internet | S20: =O20-Q20 -> 0 | T20: =P20/Q20-1 -> #DIV/0! | W20: =P20-V20 -> 0 | AD20: % | AG20: #DIV/0! | AH20: #DIV/0! | AI20: #DIV/0! | AJ20: #DIV/0! | AK20: #DIV/0!
B21: Mobile | C21: =C18 -> 8009.3634 | D21: =D18 -> 7322.5424 | E21: =E18 -> 7892.3393 | F21: =F18 -> 7816.5569 | G21: =G18 -> 8194.2127 | H21: =H18 -> 7915.194 | I21: =I18 -> 8032.1538 | J21: =J18 -> 8044.8221 | ... N21: =N18 -> 8655.4868 | O21: =+O7+O15 -> 95682.303 | P21: 90496.114 | Q21: 89647.387 | R21: 99129.814 | S21: =O21/P21-1 -> 0.057308417 | T21: =P21/Q21-1 -> 0.0094673922 | U21: =O21/R21-1 -> -0.034777734 | V21: 90942.059 | W21: =P21-V21 -> -445.94416 | AD21: Mobile | AJ21: #DIV/0! | AK21: #DIV/0!
C22: 0 | D22: 0 | E22: 0 | F22: 0 | G22: 0 | H22: 0 | I22: 0 | J22: 0 | K22: 0 | L22: 0 | M22: 0 | N22: 0 | Q22: 0 | S22: =O22-Q22 -> 0 | W22: =P22-V22 -> 0 | AD22: % | AG22: 0 | AH22: 0 | AI22: 0 | AJ22: 0 | AK22: 0
B23: Coûts opérationnels | C23: =C26 -> -5752.8634 | D23: =D26 -> -5412.0079 | E23: =E26 -> -5658.8042 | F23: =F26 -> -5772.0206 | G23: =G26 -> -5682.373 | H23: =H26 -> -5580.6859 | I23: =I26 -> -5830.1077 | J23: =J26 -> -5690.6091 | ... N23: =N26 -> -5706.9963 | O23: =SUM(C23,D23,E23,F23,G23,H23,I23,J23,K23,L23,M23,N23) -> -67535.531 | P23: -64651.048 | Q23: -61867.1 | R23: -69069.6 | S23: =O23/P23-1 -> 0.044616185 | T23: =P23/Q23-1 -> 0.044998838 | U23: =O23/R23-1 -> -0.022210486 | V23: -64817.051 | W23: =P23-V23 -> 166.00342 | AG23: =+Q29-AG26 -> 0 | AH23: =AH26-P29 -> 279.75958 | AI23: =AI26-O29 -> 0.010710858
B24: Fixe & Internet | C24: 0 | D24: 0 | E24: 0 | F24: 0 | G24: 0 | H24: 0 | I24: 0 | J24: 0 | K24: 0 | L24: 0 | M24: 0 | N24: 0 | Q24: 0 | S24: =O24-Q24 -> 0 | W24: =P24-V24 -> 0 | AD24: Coûts opérationnels | AG24: 61867.1 | AH24: 64817.232 | AI24: 67535.52 | AJ24: 0.047684992 | AK24: 0.041937738
B25: Intercompagnie Fixe & Internet | C25: 0 | D25: 0 | E25: 0 | F25: 0 | G25: 0 | H25: 0 | I25: 0 | J25: 0 | K25: 0 | L25: 0 | M25: 0 | N25: 0 | Q25: 0 | S25: =O25-Q25 -> 0 | W25: =P25-V25 -> 0
B26: Mobile | C26: =C27 -> -5752.8634 | D26: =D27 -> -5412.0079 | E26: =E27 -> -5658.8042 | F26: =F27 -> -5772.0206 | G26: =G27 -> -5682.373 | H26: =H27 -> -5580.6859 | I26: =I27 -> -5830.1077 | J26: =J27 -> -5690.6091 | ... N26: =N27 -> -5706.9963 | O26: =+O27 -> -67535.531 | P26: -64651.048 | Q26: -61867.1 | R26: -69069.6 | S26: =O26/P26-1 -> 0.044616185 | T26: =P26/Q26-1 -> 0.044998838 | U26: =O26/R26-1 -> -0.022210486 | V26: -64817.232 | W26: =P26-V26 -> 166.18458 | AC26: EBITDA | AG26: 27780.287 | AH26: 26124.826 | AI26: 28146.783 | AJ26: -0.059591214 | AK26: 0.077396001
B27: Intercompagnie Mobile | C27: =-'Opex Consolidés'!C7 -> -5752.8634 | D27: =-'Opex Consolidés'!D7 -> -5412.0079 | E27: =-'Opex Consolidés'!E7 -> -5658.8042 | F27: =-'Opex Consolidés'!F7 -> -5772.0206 | G27: =-'Opex Consolidés'!G7 -> -5682.373 | H27: =-'Opex Consolidés'!H7 -> -5580.6859 | I27: =-'Opex Consolidés'!I7 -> -5830.1077 | J27: =-'Opex Consolidés'!J7 -> -5690.6091 | ... N27: =-'Opex Consolidés'!N7 -> -5706.9963 | O27: =SUM(C27,D27,E27,F27,G27,H27,I27,J27,K27,L27,M27,N27) -> -67535.531 | P27: -64651.048 | Q27: -61867.1 | R27: -69069.6 | S27: =O27/P27-1 -> 0.044616185 | T27: =P27/Q27-1 -> 0.044998838 | U27: =O27/R27-1 -> -0.022210486 | V27: -64817.232 | W27: =P27-V27 -> 166.18458 | AD27: % | AG27: 0.263213 | AH27: 0.23992525 | AI27: 0.24618085 | AJ27: -2.3287747 | AK27: 0.62555985
C28: 0 | D28: 0 | E28: 0 | F28: 0 | G28: 0 | H28: 0 | I28: 0 | J28: 0 | K28: 0 | L28: 0 | M28: 0 | N28: 0 | S28: =O28-Q28 -> 0 | W28: =P28-V28 -> 0
B29: EBITDA | C29: =C18+C23 -> 2256.5 | D29: =D18+D23 -> 1910.5345 | E29: =E18+E23 -> 2233.5351 | F29: =F18+F23 -> 2044.5363 | G29: =G18+G23 -> 2511.8397 | H29: =H18+H23 -> 2334.508 | I29: =I18+I23 -> 2202.0461 | J29: =J18+J23 -> 2354.213 | ... N29: =N18+N23 -> 2948.4905 | O29: =SUM(C29:N29) -> 28146.773 | P29: 25845.067 | Q29: 27780.287 | R29: 30060.214 | S29: =O29/P29-1 -> 0.089057845 | T29: =P29/Q29-1 -> -0.069661649 | U29: =O29/R29-1 -> -0.063653603 | V29: 26125.008 | W29: =P29-V29 -> -279.94074 | AD29: Amortissements et déprec. des immob | AG29: 18266.7 | AH29: 20724.23 | AI29: 21341.659 | AJ29: 0.13453607 | AK29: 0.02979264
B30: % CA | C30: =C29/C5 -> 0.23685094 | D30: =D29/D5 -> 0.21754815 | E30: =E29/E5 -> 0.23577561 | F30: =F29/F5 -> 0.21837416 | G30: =G29/G5 -> 0.25703239 | H30: =H29/H5 -> 0.24660246 | I30: =I29/I5 -> 0.22904446 | J30: =J29/J5 -> 0.24476522 | ... O30: =O29/O5 -> 0.24618076 | P30: 0.23844106 | Q30: 0.263213 | R30: 0.25936421 | S30: =O30/P30-1 -> 0.032459596 | T30: =P30/Q30-1 -> -0.094113671 | U30: =O30/R30-1 -> -0.050829884 | V30: 0.23992692 | W30: =P30-V30 -> -0.0014858588 | AD30: Autres non courant | AJ30: #DIV/0! | AK30: #DIV/0!
B31: Fixe & Internet | C31: 0 | D31: 0 | E31: 0 | F31: 0 | G31: 0 | H31: 0 | I31: 0 | J31: 0 | K31: 0 | L31: 0 | M31: 0 | N31: 0 | Q31: 0 | S31: =O31-Q31 -> 0 | T31: =P31/Q31-1 -> #DIV/0! | W31: =P31-V31 -> 0 | AD31: Restructuration | AJ31: #DIV/0! | AK31: #DIV/0!
B32: Mobile | C32: =C18+C23 -> 2256.5 | D32: =D18+D23 -> 1910.5345 | E32: =E18+E23 -> 2233.5351 | F32: =F18+F23 -> 2044.5363 | G32: =G18+G23 -> 2511.8397 | H32: =H18+H23 -> 2334.508 | I32: =I18+I23 -> 2202.0461 | J32: =J18+J23 -> 2354.213 | ... N32: =N18+N23 -> 2948.4905 | O32: =+O21+O26 -> 28146.773 | P32: 25845.067 | Q32: 27780.287 | R32: 30060.214 | S32: =O32/P32-1 -> 0.089057845 | T32: =P32/Q32-1 -> -0.069661649 | U32: =O32/R32-1 -> -0.063653603 | V32: 26125.1 | W32: =P32-V32 -> -280.03364
C33: 0 | D33: 0 | E33: 0 | F33: 0 | G33: 0 | H33: 0 | I33: 0 | J33: 0 | K33: 0 | L33: 0 | M33: 0 | N33: 0 | Q33: 0 | S33: =O33-Q33 -> 0 | W33: =P33-V33 -> 0
B34: Amortissements et déprec. Courant | C34: -1755 | D34: -1774.631 | E34: -1774.631 | F34: -1732.131 | G34: -1754.9927 | H34: -1752.6683 | I34: -1746.2313 | J34: -1723.2073 | K34: -1735.4531 | L34: -1773.4636 | M34: -1778.2972 | N34: -1785.9531 | O34: =SUM(C34,D34,E34,F34,G34,H34,I34,J34,K34,L34,M34,N34) -> -21086.659 | P34: -20724.23 | Q34: -18266.7 | R34: -20248.648 | S34: =O34/P34-1 -> 0.017488202 | T34: =P34/Q34-1 -> 0.13453607 | U34: =O34/R34-1 -> 0.041386067 | V34: -20724.23 | W34: =P34-V34 -> 0 | AC34: EBITA | AG34: 9513.5874 | AH34: 5400.5964 | AI34: 6805.1239 | AJ34: -0.43232809 | AK34: 0.26006897
B35: Dotations (Amo. et Pv NC) | C35: 0 | D35: 0 | E35: 0 | F35: 0 | G35: 0 | H35: 0 | I35: 0 | J35: 0 | K35: 0 | L35: 0 | M35: 0 | N35: 0 | O35: =SUM(C35,D35,E35,F35,G35,H35,I35,J35,K35,L35,M35,N35) -> 0 | P35: 0 | Q35: 0 | R35: 0 | S35: =O35-Q35 -> 0 | V35: 0 | W35: =P35-V35 -> 0 | AD35: % | AG35: 0.090139452 | AH35: 0.049598012 | AI35: 0.05951981 | AJ35: -4.054144 | AK35: 0.99217981
B36: Autres non courant | C36: 0 | D36: 0 | E36: 0 | F36: 0 | G36: 0 | H36: 0 | I36: 0 | J36: 0 | K36: 0 | L36: 0 | M36: 0 | N36: 0 | O36: =SUM(C36,D36,E36,F36,G36,H36,I36,J36,K36,L36,M36,N36) -> 0 | P36: 0 | Q36: 0 | R36: 0 | S36: =O36-Q36 -> 0 | V36: 0 | W36: =P36-V36 -> 0
B37: +/- value de cession d'immob. | C37: -1.8e-05 | D37: 0.31512 | E37: 0 | F37: 0 | G37: 0 | H37: 0 | I37: 0 | J37: 0 | K37: 0 | L37: 0 | M37: 0 | N37: 0 | O37: 0 | P37: 0 | Q37: 0 | R37: 0 | S37: =O37-Q37 -> 0 | V37: 0 | W37: =P37-V37 -> 0 | AD37: Résultat financier | AG37: -3438.403 | AH37: -3866.1186 | AI37: -3986 | AJ37: 0.12439368 | AK37: 0.031008207
C38: 0 | D38: 0 | E38: 0 | F38: 0 | G38: 0 | H38: 0 | I38: 0 | J38: 0 | K38: 0 | L38: 0 | M38: 0 | N38: 0 | S38: =O38-Q38 -> 0 | W38: =P38-V38 -> 0
B39: EBITA | C39: =C29+C34 -> 501.49997 | D39: =D29+D34 -> 135.90357 | E39: =E29+E34 -> 458.90413 | F39: =F29+F34 -> 312.40536 | G39: =G29+G34 -> 756.84703 | H39: =H29+H34 -> 581.83976 | I39: =I29+I34 -> 455.81478 | J39: =J29+J34 -> 631.00572 | ... N39: =N29+N34 -> 1162.5374 | O39: =+O29+O34+O35+O36+O37 -> 7060.1132 | P39: 5120.8368 | Q39: 9513.5874 | R39: 9811.566 | S39: =O39/P39-1 -> 0.37870303 | T39: =P39/Q39-1 -> -0.4617344 | U39: =O39/R39-1 -> -0.28042952 | V39: 5400.7775 | W39: =P39-V39 -> -279.94074 | AD39: Contribution Covid | AJ39: #DIV/0! | AK39: #DIV/0!
B40: % CA | C40: =C39/C5 -> 0.052639371 | D40: =D39/D5 -> 0.015475025 | E40: =E39/E5 -> 0.048442669 | F40: =F39/F5 -> 0.033367594 | G40: =G39/G5 -> 0.077446901 | H40: =H39/H5 -> 0.061461822 | I40: =I39/I5 -> 0.047411293 | J40: =J39/J5 -> 0.065605047 | ... N40: =N39/N5 -> 0.11293961 | O40: =+O39/O5 -> 0.061750029 | P40: 0.047243745 | Q40: 0.090139452 | R40: 0.084655722 | S40: =O40/P40-1 -> 0.30705195 | T40: =P40/Q40-1 -> -0.4758816 | U40: =O40/R40-1 -> -0.27057466 | V40: 0.049599676 | W40: =P40-V40 -> -0.0023559308
...

Sheet Opex Consolidés
K1: 18
A2: Opex Consolidés
C4: JANVIER | D4: FEVRIER | E4: MARS | F4: AVRIL | G4: MAI | H4: JUIN | I4: JUILLET | J4: AOUT | K4: SEPT | L4: OCT | M4: NOV | N4: DEC | O4: ANNUEL | S4: VARIATIONS
B5: (En Millions ML) | C5: 2025 Budget | D5: 2025 Budget | E5: 2025 Budget | F5: 2025 Budget | G5: 2025 Budget | H5: 2025 Budget | I5: 2025 Budget | J5: 2025 Budget | K5: 2025 Budget | L5: 2025 Budget | M5: 2025 Budget | N5: 2025 Budget | O5: 2025 Budget | P5: 2024 Actu 3 | Q5: 2023 Réel | R5: Budget initial | S5: Var Budget Actu 3. % | T5: Var Actu 3 vs Réel 23. % | U5: Var Budget 2025 vs Budget 2024. %
B7: Total Opex | C7: =SUM(C9,C11,C13,C22,C30,C36,C42) -> 5752.8634 | D7: =SUM(D9,D11,D13,D22,D30,D36,D42) -> 5412.0079 | E7: =SUM(E9,E11,E13,E22,E30,E36,E42) -> 5658.8042 | F7: =SUM(F9,F11,F13,F22,F30,F36,F42) -> 5772.0206 | G7: =SUM(G9,G11,G13,G22,G30,G36,G42) -> 5682.373 | H7: =SUM(H9,H11,H13,H22,H30,H36,H42) -> 5580.6859 | I7: =SUM(I9,I11,I13,I22,I30,I36,I42) -> 5830.1077 | J7: =SUM(J9,J11,J13,J22,J30,J36,J42) -> 5690.6091 | ... N7: =SUM(N9,N11,N13,N22,N30,N36,N42) -> 5706.9963 | O7: =SUM(C7,D7,E7,F7,G7,H7,I7,J7,K7,L7,M7,N7) -> 67535.531 | P7: 64651.048 | Q7: 61867.1 | R7: 69069.6 | S7: =O7/P7-1 -> 0.044616185 | T7: =P7/Q7-1 -> 0.044998838 | U7: =O7/R7-1 -> -0.022210486 | W7: 64817.122 | X7: =P7-W7 -> -166.07461
C8: 0 | D8: 0 | E8: 0 | F8: 0 | G8: 0 | H8: 0 | I8: 0 | J8: 0 | K8: 0 | L8: 0 | M8: 0 | N8: 0 | X8: =P8-W8 -> 0
B9: Personnel | C9: 437.22587 | D9: 437.22587 | E9: 437.22587 | F9: 452.22587 | G9: 437.22587 | H9: 437.22587 | I9: 452.22587 | J9: 437.22587 | K9: 437.22587 | L9: 452.22587 | M9: 437.22587 | N9: 452.03587 | O9: =SUM(C9,D9,E9,F9,G9,H9,I9,J9,K9,L9,M9,N9) -> 5306.5205 | P9: 5064.8381 | Q9: 4761.3279 | R9: 5078.2318 | S9: =O9/P9-1 -> 0.04771769 | T9: =P9/Q9-1 -> 0.063744858 | U9: =O9/R9-1 -> 0.044954359 | W9: 5064.8381 | X9: =P9-W9 -> 0
Q10: 0 | X10: =P10-W10 -> 0
B11: Communication | C11: 284.29255 | D11: 281.99255 | E11: 281.99255 | F11: 289.29255 | G11: 281.99255 | H11: 281.99255 | I11: 300.99255 | J11: 281.99255 | K11: 281.99255 | L11: 289.29255 | M11: 281.99255 | N11: 307.29255 | O11: =SUM(C11,D11,E11,F11,G11,H11,I11,J11,K11,L11,M11,N11) -> 3445.1106 | P11: 3438.8998 | Q11: 3337.1979 | R11: 3439.3611 | S11: =O11/P11-1 -> 0.0018060305 | T11: =P11/Q11-1 -> 0.030475238 | U11: =O11/R11-1 -> 0.0016716723 | W11: 3438.8998 | X11: =P11-W11 -> 0
X12: =P12-W12 -> 0
B13: Exploitation & maintenance | C13: =C14+C15+C16+C18+C19 -> 1768.4753 | D13: =D14+D15+D16+D18+D19 -> 1737.3645 | E13: =E14+E15+E16+E18+E19 -> 1726.6695 | F13: =F14+F15+F16+F18+F19 -> 1714.1927 | G13: =G14+G15+G16+G18+G19 -> 1713.7202 | H13: =H14+H15+H16+H18+H19 -> 1732.334 | I13: =I14+I15+I16+I18+I19 -> 1769.6852 | J13: =J14+J15+J16+J18+J19 -> 1769.9477 | ... N13: =N14+N15+N16+N18+N19 -> 1589.2547 | O13: =SUM(C13,D13,E13,F13,G13,H13,I13,J13,K13,L13,M13,N13) -> 20292.074 | P13: 19379.8 | Q13: 17558.215 | R13: 20385.578 | S13: =O13/P13-1 -> 0.047073405 | T13: =P13/Q13-1 -> 0.10374551 | U13: =O13/R13-1 -> -0.0045867789 | W13: 19379.6 | X13: =P13-W13 -> 0.20016
B14: Achat d'énergie - Bâtiment - Gardiennage | C14: 864.64316 | D14: 833.26986 | E14: 821.96986 | F14: 806.11361 | G14: 804.61361 | H14: 821.85736 | I14: 841.34486 | J14: 841.34486 | K14: 709.95989 | L14: 711.65364 | M14: 703.34739 | N14: 706.88193 | O14: =SUM(C14,D14,E14,F14,G14,H14,I14,J14,K14,L14,M14,N14) -> 9467 | P14: 8822.3339 | Q14: 7999.3604 | R14: 9117.9995 | S14: =O14/P14-1 -> 0.073072055 | T14: =P14/Q14-1 -> 0.10287992 | U14: =O14/R14-1 -> 0.038275995 | W14: 8822.3339 | X14: =P14-W14 -> 0
B15: Lignes et réseaux (entretien & achats) | C15: 591.38042 | D15: 591.64292 | E15: 592.24792 | F15: 595.62742 | G15: 596.65492 | H15: 598.02492 | I15: 604.2248 | J15: 604.4873 | K15: 557.44492 | L15: 557.70742 | M15: 557.96992 | N15: 558.31992 | O15: =SUM(C15,D15,E15,F15,G15,H15,I15,J15,K15,L15,M15,N15) -> 7005.7328 | P15: 6471.8001 | Q15: 5895.2442 | R15: 6344.0146 | S15: =O15/P15-1 -> 0.082501411 | T15: =P15/Q15-1 -> 0.097800184 | U15: =O15/R15-1 -> 0.10430591 | W15: 6471.6 | X15: =P15-W15 -> 0.20016
B16: Fees du contrat GMNS | C16: 129.42982 | D16: 129.42982 | E16: 129.42982 | F16: 129.42982 | G16: 129.42982 | H16: 129.42982 | I16: 141.09371 | J16: 141.09371 | K16: 141.09371 | L16: 141.09371 | M16: 141.09371 | N16: 141.09371 | O16: =SUM(C16,D16,E16,F16,G16,H16,I16,J16,K16,L16,M16,N16) -> 1623.1412 | P16: 2203.8709 | Q16: 2329.7488 | R16: 2744.8641 | S16: =O16/P16-1 -> -0.2635044 | T16: =P16/Q16-1 -> -0.054030682 | U16: =O16/R16-1 -> -0.40866245 | W16: 2203.8709 | X16: =P16-W16 -> 0
B17: Fees du contrat IHS (spécifique à CDI) | O17: =SUM(C17,D17,E17,F17,G17,H17,I17,J17,K17,L17,M17,N17) -> 0 | P17: 0 | R17: 0 | S17: =O17-P17 -> 0 | W17: 0 | X17: =P17-W17 -> 0
B18: Matériel de transport (Entretien et locat°) | C18: 9.0052297 | D18: 9.0052297 | E18: 9.0052297 | F18: 9.0052297 | G18: 9.0052297 | H18: 9.0052297 | I18: 9.0052297 | J18: 9.0052297 | K18: 9.0052297 | L18: 9.0052297 | M18: 9.0052297 | N18: 8.9424737 | O18: =SUM(C18,D18,E18,F18,G18,H18,I18,J18,K18,L18,M18,N18) -> 108 | P18: 82.546802 | Q18: 84.490408 | R18: 97.5 | S18: =O18/P18-1 -> 0.30834869 | T18: =P18/Q18-1 -> -0.023003869 | U18: =O18/R18-1 -> 0.10769231 | W18: 82.546802 | X18: =P18-W18 -> 0
B19: Maintenance informatique | C19: 174.01664 | D19: 174.01664 | E19: 174.01664 | F19: 174.01664 | G19: 174.01664 | H19: 174.01664 | I19: 174.01664 | J19: 174.01664 | K19: 174.01664 | L19: 174.01664 | M19: 174.01664 | N19: 174.01664 | O19: =SUM(C19,D19,E19,F19,G19,H19,I19,J19,K19,L19,M19,N19) -> 2088.1997 | P19: 1799.2487 | Q19: 1249.3708 | R19: 2081.1997 | S19: =O19/P19-1 -> 0.16059535 | T19: =P19/Q19-1 -> 0.44012386 | U19: =O19/R19-1 -> 0.0033634446 | W19: 1799.2487 | X19: =P19-W19 -> 0
X20: =P20-W20 -> 0
X21: =P21-W21 -> 0
B22: Frais généraux | C22: =C23+C24+C25+C26+C27 -> 399.65218 | D22: =D23+D24+D25+D26+D27 -> 312.04262 | E22: =E23+E24+E25+E26+E27 -> 338.62234 | F22: =F23+F24+F25+F26+F27 -> 500.54786 | G22: =G23+G24+G25+G26+G27 -> 334.79848 | H22: =H23+H24+H25+H26+H27 -> 301.84274 | I22: =I23+I24+I25+I26+I27 -> 452.52356 | J22: =J23+J24+J25+J26+J27 -> 338.04521 | ... N22: =N23+N24+N25+N26+N27 -> 353.06783 | O22: =SUM(C22,D22,E22,F22,G22,H22,I22,J22,K22,L22,M22,N22) -> 4414.8809 | P22: 3942.5188 | Q22: 3069.902 | R22: 4532.7765 | S22: =O22/P22-1 -> 0.11981225 | T22: =P22/Q22-1 -> 0.28424911 | U22: =O22/R22-1 -> -0.026009585 | W22: 4241.9469 | X22: =P22-W22 -> -299.42804
B23: Frais d'achats d'études, honoraires | C23: 274.14083 | D23: 193.14083 | E23: 200.14083 | F23: 332.89083 | G23: 206.95083 | H23: 176.64083 | I23: 282.89083 | J23: 197.14083 | K23: 187.14083 | L23: 174.89083 | M23: 294.14083 | N23: 175.89083 | O23: =SUM(C23,D23,E23,F23,G23,H23,I23,J23,K23,L23,M23,N23) -> 2696 | P23: 2462.1368 | Q23: 2249.0254 | R23: 2701.3903 | S23: =O23/P23-1 -> 0.094983827 | T23: =P23/Q23-1 -> 0.094757242 | U23: =O23/R23-1 -> -0.001995368 | W23: 2735.1368 | X23: =P23-W23 -> -273
B24: Management fees | C24: 85.055817 | D24: 78.446262 | E24: 85.714381 | F24: 86.189905 | G24: 87.392121 | H24: 84.746383 | I24: 88.165605 | J24: 88.273161 | K24: 87.847669 | L24: 86.825801 | M24: 90.513926 | N24: 95.709873 | O24: =SUM(C24,D24,E24,F24,G24,H24,I24,J24,K24,L24,M24,N24) -> 1044.8809 | P24: 672.11907 | Q24: 244.33975 | R24: 1043.0966 | S24: =O24/P24-1 -> 0.55460683 | T24: =P24/Q24-1 -> 1.7507562 | U24: =O24/R24-1 -> 0.0017106022 | W24: 698.54711 | X24: =P24-W24 -> -26.428037
B25: Transport, déplacement, mission | C25: 14.166667 | D25: 14.166667 | E25: 14.166667 | F25: 14.166667 | G25: 14.166667 | H25: 14.166667 | I25: 14.166667 | J25: 14.166667 | K25: 14.166667 | L25: 14.166667 | M25: 14.166667 | N25: 14.166667 | O25: =SUM(C25,D25,E25,F25,G25,H25,I25,J25,K25,L25,M25,N25) -> 170 | P25: 173.84879 | Q25: 257.91308 | R25: 252.802 | S25: =O25/P25-1 -> -0.022138733 | T25: =P25/Q25-1 -> -0.32594039 | U25: =O25/R25-1 -> -0.32753697 | W25: 173.84879 | X25: =P25-W25 -> 0
B26: Frais postaux, bancaires et assurances | C26: 6.2888588 | D26: 6.2888588 | E26: 18.600459 | F26: 47.300459 | G26: 6.2888588 | H26: 6.2888588 | I26: 47.300459 | J26: 18.464553 | K26: 6.2888588 | L26: 47.300459 | M26: 6.2888588 | N26: 47.300459 | O26: =SUM(C26,D26,E26,F26,G26,H26,I26,J26,K26,L26,M26,N26) -> 264 | P26: 387.91185 | Q26: 271.45921 | R26: 479.08769 | S26: =O26/P26-1 -> -0.31943302 | T26: =P26/Q26-1 -> 0.42898763 | U26: =O26/R26-1 -> -0.44895266 | W26: 387.91185 | X26: =P26-W26 -> 0
B27: Achats de mat. et fournitures consom. | C27: 20 | D27: 20 | E27: 20 | F27: 20 | G27: 20 | H27: 20 | I27: 20 | J27: 20 | K27: 20 | L27: 20 | M27: 20 | N27: 20 | O27: =SUM(C27,D27,E27,F27,G27,H27,I27,J27,K27,L27,M27,N27) -> 240 | P27: 246.5023 | Q27: 47.164529 | R27: 56.4 | S27: =O27/P27-1 -> -0.026378241 | T27: =P27/Q27-1 -> 4.226434 | U27: =O27/R27-1 -> 3.2553191 | W27: 246.5023 | X27: =P27-W27 -> 0
X28: =P28-W28 -> 0
X29: =P29-W29 -> 0
B30: Impôts, taxes et redevances | C30: =+C31+C33 -> 2838.468 | D30: =+D31+D33 -> 2618.6328 | E30: =+E31+E33 -> 2849.5444 | F30: =+F31+F33 -> 2791.012 | G30: =+G31+G33 -> 2889.8863 | H30: =+H31+H33 -> 2802.5413 | I30: =+I31+I33 -> 2829.9309 | J30: =+J31+J33 -> 2838.6482 | ... N30: =+N31+N33 -> 2980.5958 | O30: =SUM(C30,D30,E30,F30,G30,H30,I30,J30,K30,L30,M30,N30) -> 33779.951 | P30: 32432.759 | Q30: 32006.456 | R30: 35342.359 | S30: =O30/P30-1 -> 0.041537992 | T30: =P30/Q30-1 -> 0.013319294 | U30: =O30/R30-1 -> -0.044207825 | W30: 32299.606 | X30: =P30-W30 -> 133.15326
B31: Redevances régulateur | C31: 2676.5734 | D31: 2454.2935 | E31: 2685.3963 | F31: 2624.4416 | G31: 2724.2273 | H31: 2637.5465 | I31: 2665.8633 | J31: 2674.2719 | K31: 2569.6951 | L31: 2687.2893 | M31: 2590.7904 | N31: 2815.8981 | O31: =SUM(C31,D31,E31,F31,G31,H31,I31,J31,K31,L31,M31,N31) -> 31806.287 | P31: 30475.692 | Q31: 30140.154 | R31: 33258.638 | S31: =O31/P31-1 -> 0.043660842 | T31: =P31/Q31-1 -> 0.011132614 | U31: =O31/R31-1 -> -0.043668386 | W31: 30342.539 | X31: =P31-W31 -> 133.15326
B32: Droits sur le trafic International Entrant | O32: =SUM(C32,D32,E32,F32,G32,H32,I32,J32,K32,L32,M32,N32) -> 0 | R32: 0 | X32: =P32-W32 -> 0
B33: Autres impôts et taxes | C33: 161.89465 | D33: 164.33932 | E33: 164.14816 | F33: 166.57042 | G33: 165.65905 | H33: 164.99472 | I33: 164.06759 | J33: 164.37632 | K33: 164.14621 | L33: 164.5967 | M33: 164.17308 | N33: 164.69773 | O33: =SUM(C33,D33,E33,F33,G33,H33,I33,J33,K33,L33,M33,N33) -> 1973.6639 | P33: 1957.0666 | Q33: 1866.3019 | R33: 2083.7218 | S33: =O33/P33-1 -> 0.0084806977 | T33: =P33/Q33-1 -> 0.048633447 | U33: =O33/R33-1 -> -0.052817907 | W33: 1957.0666 | X33: =P33-W33 -> 0
X34: =P34-W34 -> 0
X35: =P35-W35 -> 0
B36: Provision clients, R&C & NC | C36: =C37+C38+C39 -> 24.749544 | D36: =D37+D38+D39 -> 24.749544 | E36: =E37+E38+E39 -> 24.749544 | F36: =F37+F38+F39 -> 24.749544 | G36: =G37+G38+G39 -> 24.749544 | H36: =H37+H38+H39 -> 24.749544 | I36: =I37+I38+I39 -> 24.749544 | J36: =J37+J38+J39 -> 24.749544 | ... N36: =N37+N38+N39 -> 24.749544 | O36: =SUM(C36,D36,E36,F36,G36,H36,I36,J36,K36,L36,M36,N36) -> 296.99453 | P36: 390.82502 | Q36: 1126.97 | R36: 291.29348 | S36: =O36/P36-1 -> -0.24008312 | T36: =P36/Q36-1 -> -0.65320724 | U36: =O36/R36-1 -> 0.019571504 | W36: 390.82502 | X36: =P36-W36 -> 3e-06
B37: Prov. Créances clients | C37: 13.218288 | D37: 13.218288 | E37: 13.218288 | F37: 13.218288 | G37: 13.218288 | H37: 13.218288 | I37: 13.218288 | J37: 13.218288 | K37: 13.218288 | L37: 13.218288 | M37: 13.218288 | N37: 13.218288 | O37: =SUM(C37,D37,E37,F37,G37,H37,I37,J37,K37,L37,M37,N37) -> 158.61946 | P37: 273.5043 | Q37: -717.22245 | R37: 192 | S37: =O37/P37-1 -> -0.42004765 | T37: =P37/Q37-1 -> -1.3813382 | U37: =O37/R37-1 -> -0.17385698 | W37: 262.1169 | X37: =P37-W37 -> 11.387403
B38: Prov. R&C | C38: 0 | D38: 0 | E38: 0 | F38: 0 | G38: 0 | H38: 0 | I38: 0 | J38: 0 | K38: 0 | L38: 0 | M38: 0 | N38: 0 | O38: =SUM(C38,D38,E38,F38,G38,H38,I38,J38,K38,L38,M38,N38) -> 0 | P38: 0 | Q38: 0 | R38: 0 | W38: 11.3874 | X38: =P38-W38 -> -11.3874
B39: PIDR | C39: 11.531256 | D39: 11.531256 | E39: 11.531256 | F39: 11.531256 | G39: 11.531256 | H39: 11.531256 | I39: 11.531256 | J39: 11.531256 | K39: 11.531256 | L39: 11.531256 | M39: 11.531256 | N39: 11.531256 | O39: =SUM(C39,D39,E39,F39,G39,H39,I39,J39,K39,L39,M39,N39) -> 138.37507 | P39: 117.32072 | Q39: 8.34645 | R39: 99.29348 | S39: =O39/P39-1 -> 0.17945977 | T39: =P39/Q39-1 -> 13.056362 | U39: =O39/R39-1 -> 0.39359676 | W39: 117.32072 | X39: =P39-W39 -> 0
B40: Autres provisions | O40: =SUM(C40,D40,E40,F40,G40,H40,I40,J40,K40,L40,M40,N40) -> 0 | Q40: 1835.846 | R40: 0 | T40: =P40/Q40-1 -> -1 | X40: =P40-W40 -> 0
X41: =P41-W41 -> 0
B42: Ecart de change sur exploitation | C42: 0 | D42: 0 | E42: 0 | F42: 0 | G42: 0 | H42: 0 | I42: 0 | J42: 0 | K42: 0 | L42: 0 | M42: 0 | N42: 0 | O42: =SUM(C42,D42,E42,F42,G42,H42,I42,J42,K42,L42,M42,N42) -> 0 | P42: 1.406461 | Q42: 7 | R42: 0 | W42: 1.406461 | X42: =P42-W42 -> 0

Sheet Feuil2
B1: AT CDI
B2: Activité Internationale Mobile
D4: Janvier | F4: AOUT | R4: SEPTEMBRE | AD4: OCTOBRE | AP4: NOVEMBRE | BB4: DECEMBRE | BM4: Fevrier | BO4: Mars | BQ4: AOUT | CC4: SEPTEMBRE | CO4: OCTOBRE | DA4: NOVEMBRE | DM4: DECEMBRE | DX4: Avril | DZ4: Mai | EB4: Juin | ED4: Juil | EF4: Août | EH4: Sept | EJ4: Oct | EL4: Nov | EN4: Déc
D5: 2017 Budget | F5: 2016 Réel | G5: 2016 Budget | H5: 2016 Actu 1 | I5: 2016 Actu 2 | J5: 2016 Actu 3 | K5: Ecart / Budget | L5: Ecart / Actu 1 | M5: Ecart / Actu 2 | N5: Ecart / Actu 3 | O5: 2015 Réel | P5: Evol % | R5: 2016 Réel | S5: 2016 Budget | T5: 2016 Actu 1 | U5: 2016 Actu 2 | V5: 2016 Actu 3 | W5: Ecart / Budget | X5: Ecart / Actu 1 | Y5: Ecart / Actu 2 | Z5: Ecart / Actu 3 | AA5: 2015 Réel | AB5: Evol % | AD5: 2016 Réel | AE5: 2016 Budget | AF5: 2016 Actu 1 | AG5: 2016 Actu 2 | AH5: 2016 Actu 3 | AI5: Ecart / Budget | AJ5: Ecart / Actu 1 | AK5: Ecart / Actu 2 | AL5: Ecart / Actu 3 | AM5: 2015 Réel | AN5: Evol % | AP5: 2016 Réel | AQ5: 2016 Budget | AR5: 2016 Actu 1 | AS5: 2016 Actu 2 | AT5: 2016 Actu 3 | AU5: Ecart / Budget | AV5: Ecart / Actu 1 | AW5: Ecart / Actu 2 | AX5: Ecart / Actu 3 | AY5: 2015 Réel | AZ5: Evol % | BB5: 2016 Réel | BC5: 2016 Budget | BD5: 2016 Actu 1 | BE5: 2016 Actu 2 | BF5: 2016 Actu 3 | BG5: Ecart / Budget | BH5: Ecart / Actu 1 | BI5: Ecart / Actu 2 | BJ5: Ecart / Actu 3 | BK5: 2015 Réel | BL5: Evol % | BM5: 2017 Budget | BO5: 2017 Budget | BQ5: 2016 Réel | BR5: 2016 Budget | BS5: 2016 Actu 1 | BT5: 2016 Actu 2 | BU5: 2016 Actu 3 | BV5: Ecart / Budget | BW5: Ecart / Actu 1 | BX5: Ecart / Actu 2 | BY5: Ecart / Actu 3 | BZ5: 2015 Réel | CA5: Evol % | CC5: 2016 Réel | CD5: 2016 Budget | CE5: 2016 Actu 1 | CF5: 2016 Actu 2 | CG5: 2016 Actu 3 | CH5: Ecart / Budget | CI5: Ecart / Actu 1 | CJ5: Ecart / Actu 2 | CK5: Ecart / Actu 3 | CL5: 2015 Réel | CM5: Evol % | CO5: 2016 Réel | CP5: 2016 Budget | CQ5: 2016 Actu 1 | CR5: 2016 Actu 2 | CS5: 2016 Actu 3 | CT5: Ecart / Budget | CU5: Ecart / Actu 1 | CV5: Ecart / Actu 2 | CW5: Ecart / Actu 3 | CX5: 2015 Réel | CY5: Evol % | DA5: 2016 Réel | DB5: 2016 Budget | DC5: 2016 Actu 1 | DD5: 2016 Actu 2 | DE5: 2016 Actu 3 | DF5: Ecart / Budget | DG5: Ecart / Actu 1 | DH5: Ecart / Actu 2 | DI5: Ecart / Actu 3 | DJ5: 2015 Réel | DK5: Evol % | DM5: 2016 Réel | DN5: 2016 Budget | DO5: 2016 Actu 1 | DP5: 2016 Actu 2 | DQ5: 2016 Actu 3 | DR5: Ecart / Budget | DS5: Ecart / Actu 1 | DT5: Ecart / Actu 2 | DU5: Ecart / Actu 3 | DV5: 2015 Réel | DW5: Evol % | DX5: 2017 Budget | DZ5: 2017 Budget | EB5: 2017 Budget | ED5: 2017 Budget | EF5: 2017 Budget | EH5: 2017 Budget | EJ5: 2017 Budget | EL5: 2017 Budget | EN5: 2017 Budget | EP5: 2017 Budget | EQ5: 2018 Budget | ER5: 2019 Budget | ES5: 2020 Budget | ET5: 2016 Actu 3 | EU5: Ecart / Actu 1 | EV5: Ecart / Actu 2 | EW5: Ecart / Actu 3 | EX5: Var Budget 2017 vs Actu 3 2016 . Val | EY5: Evol %
B6: Chiffre d'affaires (Millions de FCFA)
B7: Entrant International
B8: Voix
B9: dont direct
B10: dont transit
B11: vers concurents
B12: via concurents
B13: SMS
B15: Trafic (Millions de Minutes)
B16: Entrant International
B17: Voix
B18: dont direct
... B31: SMS

Sheet CA Mobile
C1: =SUM(C25,C33,C35,C44,C112,C122,C131) -> 7990.5954 | D1: =SUM(D25,D33,D35,D44,D112,D122,D131) -> 7269.5786 | E1: =SUM(E25,E33,E35,E44,E112,E122,E131) -> 7905.7983 | F1: =SUM(F25,F33,F35,F44,F112,F122,F131) -> 7759.0643 | G1: =SUM(G25,G33,G35,G44,G112,G122,G131) -> 8155.7259 | H1: =SUM(H25,H33,H35,H44,H112,H122,H131) -> 7840.9826 | I1: =SUM(I25,I33,I35,I44,I112,I122,I131) -> 7914.5657 | J1: =SUM(J25,J33,J35,J44,J112,J122,J131) -> 7934.2943 | ... N1: =SUM(N25,N33,N35,N44,N112,N122,N131) -> 8487.0194
A2: CA Mobile | C2: =SUM(C25,C33,C35,C44,C112,C120,C122,C131) -> 7990.9509 | D2: =SUM(D25,D33,D35,D44,D112,D120,D122,D131) -> 7269.8936 | E2: =SUM(E25,E33,E35,E44,E112,E120,E122,E131) -> 7906.1736 | F2: =SUM(F25,F33,F35,F44,F112,F120,F122,F131) -> 7765.7843 | G2: =SUM(G25,G33,G35,G44,G112,G120,G122,G131) -> 8156.0415 | H2: =SUM(H25,H33,H35,H44,H112,H120,H122,H131) -> 7841.2614 | I2: =SUM(I25,I33,I35,I44,I112,I120,I122,I131) -> 7914.8924 | J2: =SUM(J25,J33,J35,J44,J112,J120,J122,J131) -> 7934.5844 | ... N2: =SUM(N25,N33,N35,N44,N112,N120,N122,N131) -> 8487.3309 | O2: =+O7-99188 -> 15145.764 | Q2: =O7-P7 -> 5942.0094
C4: JANVIER | D4: FEVRIER | E4: MARS | F4: AVRIL | G4: MAI | H4: JUIN | I4: JUILLET | J4: AOUT | K4: SEPT | L4: OCT | M4: NOV | N4: DEC | O4: ANNUEL | S4: VARIATIONS
B5: (En Millions ML) | C5: 2025 Budget | D5: 2025 Budget | E5: 2025 Budget | F5: 2025 Budget | G5: 2025 Budget | H5: 2025 Budget | I5: 2025 Budget | J5: 2025 Budget | K5: 2025 Budget | L5: 2025 Budget | M5: 2025 Budget | N5: 2025 Budget | O5: 2025 Budget | P5: 2024 Actu 3 | Q5: 2023 Réel | R5: Budget 2024 | S5: Budget vs Actu 3. % | T5: Var Actu 3 vs réel 23. % | U5: Var Budget 2025 vs Budget 2024. %
C6: 9528.3391 | D6: 8783.3727 | E6: 9474.3889 | F6: 9363.7879 | G6: 9773.7136 | H6: 9467.9359 | I6: 9615.3051 | J6: 9619.4997 | K6: 9286.4369 | L6: 9721.6942 | M6: 9419.597 | N6: 10279.693
A7: CA Global | C7: =C9+C170 -> 9527.0891 | D7: =D9+D170 -> 8782.1227 | E7: =E9+E170 -> 9473.1389 | F7: =F9+F170 -> 9362.5379 | G7: =G9+G170 -> 9772.4636 | H7: =H9+H170 -> 9466.6859 | I7: =I9+I170 -> 9614.0551 | J7: =J9+J170 -> 9618.2497 | ... N7: =N9+N170 -> 10293.443 | O7: =SUM(C7,D7,E7,F7,G7,H7,I7,J7,K7,L7,M7,N7) -> 114333.76 | P7: 108391.75 | Q7: 105542.99 | R7: 115899.62 | S7: =O7/P7-1 -> 0.054819755 | T7: =P7/Q7-1 -> 0.026991494 | U7: =O7/R7-1 -> -0.013510454 | W7: 108887.36 | X7: =+P7-W7 -> -495.6011
X8: =+P8-W8 -> 0
A9: CA services Mobile | C9: =C11+C168 -> 9340.117 | D9: =D11+D168 -> 8595.1506 | E9: =E11+E168 -> 9286.1669 | F9: =F11+F168 -> 9175.5659 | G9: =G11+G168 -> 9585.4915 | H9: =H11+H168 -> 9278.7138 | I9: =I11+I168 -> 9427.0831 | J9: =J11+J168 -> 9430.2776 | ... N9: =N11+N168 -> 10105.471 | O9: =SUM(C9,D9,E9,F9,G9,H9,I9,J9,K9,L9,M9,N9) -> 112087.1 | P9: 106222.97 | Q9: 104258.6 | R9: 114111.62 | S9: =O9/P9-1 -> 0.055205842 | T9: =P9/Q9-1 -> 0.018841361 | U9: =O9/R9-1 -> -0.017741587 | W9: 106727.25 | X9: =+P9-W9 -> -504.2845
S10: =IFERROR(O10/#REF!-1,"") | X10: =+P10-W10 -> 0
A11: CA récurrent | C11: =SUM(C13,C140,C162) -> 9190.3209 | D11: =SUM(D13,D140,D162) -> 8457.9278 | E11: =SUM(E13,E140,E162) -> 9131.6851 | F11: =SUM(F13,F140,F162) -> 9023.3403 | G11: =SUM(G13,G140,G162) -> 9425.3998 | H11: =SUM(H13,H140,H162) -> 9120.928 | I11: =SUM(I13,I140,I162) -> 9261.1067 | J11: =SUM(J13,J140,J162) -> 9261.2516 | ... N11: =SUM(N13,N140,N162) -> 9920.8601 | O11: =SUM(C11,D11,E11,F11,G11,H11,I11,J11,K11,L11,M11,N11) -> 110140.98 | P11: 104772.04 | Q11: 103530.79 | R11: 113546.8 | S11: =O11/P11-1 -> 0.051244084 | T11: =P11/Q11-1 -> 0.011989195 | U11: =O11/R11-1 -> -0.029994808 | W11: 105257.38 | X11: =+P11-W11 -> -485.34531
S12: =IFERROR(O12/#REF!-1,"") | X12: =+P12-W12 -> 0
A13: CA sortant | C13: =C14+C47+C136+C134+C135 -> 8900.1169 | D13: =D14+D47+D136+D134+D135 -> 8185.5921 | E13: =E14+E47+E136+E134+E135 -> 8857.764 | F13: =F14+F47+F136+F134+F135 -> 8752.973 | G13: =G14+G47+G136+G134+G135 -> 9168.8618 | H13: =H14+H47+H136+H134+H135 -> 8852.6956 | I13: =I14+I47+I136+I134+I135 -> 8990.6143 | J13: =J14+J47+J136+J134+J135 -> 9002.7823 | ... N13: =N14+N47+N136+N134+N135 -> 9641.7925 | O13: =SUM(C13,D13,E13,F13,G13,H13,I13,J13,K13,L13,M13,N13) -> 106924.27 | P13: 101290.24 | Q13: 99912.622 | R13: 109283.95 | S13: =O13/P13-1 -> 0.055622578 | T13: =P13/Q13-1 -> 0.013788251 | U13: =O13/R13-1 -> -0.021592265 | W13: 101717.67 | X13: =+P13-W13 -> -427.42809
B14: Prépayé (yc commissions) | C14: =SUM(C16,C25,C33,C44) -> 3844.6975 | D14: =SUM(D16,D25,D33,D44) -> 3485.7674 | E14: =SUM(E16,E25,E33,E44) -> 3661.4635 | F14: =SUM(F16,F25,F33,F44) -> 3589.6058 | G14: =SUM(G16,G25,G33,G44) -> 3709.6789 | H14: =SUM(H16,H25,H33,H44) -> 3487.2954 | I14: =SUM(I16,I25,I33,I44) -> 3393.2811 | J14: =SUM(J16,J25,J33,J44) -> 3277.7306 | ... N14: =SUM(N16,N25,N33,N44) -> 3644.2647 | O14: =SUM(C14,D14,E14,F14,G14,H14,I14,J14,K14,L14,M14,N14) -> 41713.594 | P14: 42221.113 | Q14: 45973.654 | R14: 42546.216 | S14: =O14/P14-1 -> -0.012020505 | T14: =P14/Q14-1 -> -0.081623725 | U14: =O14/R14-1 -> -0.019569815 | W14: 42645.924 | X14: =+P14-W14 -> -424.81051
A15: Consumer Prepaid | Q15: 45973.654 | T15: =P15/Q15-1 -> -1 | X15: =+P15-W15 -> 0
B16: Frais d'activation & Sim swap | C16: -22.461806 | D16: -22.461806 | E16: -22.461806 | F16: -22.461806 | G16: -22.461806 | H16: -22.461806 | I16: -22.461806 | J16: -22.461806 | K16: -22.461806 | L16: -22.461806 | M16: -22.461806 | N16: -22.461806 | O16: =SUM(C16,D16,E16,F16,G16,H16,I16,J16,K16,L16,M16,N16) -> -269.54168 | P16: -122.23531 | Q16: -159.9668 | R16: -110.81714 | S16: =O16/P16-1 -> 1.2051049 | T16: =P16/Q16-1 -> -0.23587076 | U16: =O16/R16-1 -> 1.4323104 | W16: -144.60831 | X16: =+P16-W16 -> 22.372999
B17: Sortant voix on net | C17: 1532.0023 | D17: 1445.4383 | E17: 1509.9634 | F17: 1477.3446 | G17: 1510.8206 | H17: 1404.6592 | I17: 1326.96 | J17: 1220.0911 | K17: 1154.8218 | L17: 1226.802 | M17: 1204.8924 | N17: 1400.6297 | O17: =SUM(C17,D17,E17,F17,G17,H17,I17,J17,K17,L17,M17,N17) -> 16414.425 | P17: 18794.826 | Q17: 21114.269 | R17: 20085.705 | S17: =O17/P17-1 -> -0.12665194 | T17: =P17/Q17-1 -> -0.10985192 | U17: =O17/R17-1 -> -0.18278074 | W17: 19085.647 | X17: =+P17-W17 -> -290.82094
B18: Sortant voix MTN | C18: 1964.2889 | D18: 1734.4496 | E18: 1811.1466 | F18: 1795.8073 | G18: 1879.0664 | H18: 1773.9869 | I18: 1763.7703 | J18: 1753.6863 | K18: 1671.8586 | L18: 1739.7501 | M18: 1706.2775 | N18: 1904.056 | O18: =SUM(C18,D18,E18,F18,G18,H18,I18,J18,K18,L18,M18,N18) -> 21498.145 | P18: 19090.156 | Q18: 21426.061 | R18: 18464.202 | S18: =O18/P18-1 -> 0.12613771 | T18: =P18/Q18-1 -> -0.10902168 | U18: =O18/R18-1 -> 0.16431483 | W18: 19203.304 | X18: =+P18-W18 -> -113.14805
B19: Sortant voix GLO | O19: =SUM(C19,D19,E19,F19,G19,H19,I19,J19,K19,L19,M19,N19) -> 0 | P19: 0 | Q19: 0 | R19: 0 | S19: =IFERROR(O19/#REF!-1,"") | W19: 0 | X19: =+P19-W19 -> 0
B20: Sortant voix BBCOM | O20: =SUM(C20,D20,E20,F20,G20,H20,I20,J20,K20,L20,M20,N20) -> 0 | P20: 0 | Q20: 0 | R20: 0 | S20: =IFERROR(O20/#REF!-1,"") | W20: 0 | X20: =+P20-W20 -> 0
B21: Sortant voix LIBERCOM | C21: 134.85752 | D21: 119.07238 | E21: 124.38783 | F21: 123.28637 | G21: 129.00452 | H21: 121.83573 | I21: 121.13407 | J21: 120.44151 | K21: 114.82166 | L21: 119.48439 | M21: 117.18552 | N21: 130.76876 | O21: =SUM(C21,D21,E21,F21,G21,H21,I21,J21,K21,L21,M21,N21) -> 1476.2803 | P21: 458.77224 | Q21: 0 | R21: 918.64691 | S21: =IFERROR(O21/#REF!-1,"") | U21: =O21/R21-1 -> 0.60701597 | W21: 466.54314 | X21: =+P21-W21 -> -7.7709009
B22: Sortant voix BTSA | C22: 0.26963616 | D22: 0.23807511 | E22: 0.2487029 | F22: 0.24650062 | G22: 0.25793359 | H22: 0.2436002 | I22: 0.24219728 | J22: 0.24081258 | K22: 0.22957616 | L22: 0.23889888 | M22: 0.23430249 | N22: 0.26146102 | O22: =SUM(C22,D22,E22,F22,G22,H22,I22,J22,K22,L22,M22,N22) -> 2.951697 | P22: 753.12036 | Q22: 504.61094 | R22: 503.73856 | S22: =O22/P22-1 -> -0.99608071 | T22: =P22/Q22-1 -> 0.49247728 | U22: =O22/R22-1 -> -0.99414042 | W22: 753.13589 | X22: =+P22-W22 -> -0.015537256
B23: Sortant voix INTERNATIONAL | C23: 134.97915 | D23: 111.99366 | E23: 130.13844 | F23: 106.77848 | G23: 97.116671 | H23: 92.696709 | I23: 79.670356 | J23: 77.686936 | K23: 76.301697 | L23: 79.82422 | M23: 74.539823 | N23: 86.418551 | O23: =SUM(C23,D23,E23,F23,G23,H23,I23,J23,K23,L23,M23,N23) -> 1148.1447 | P23: 1860.7982 | Q23: 2277.915 | R23: 1832.1303 | S23: =O23/P23-1 -> -0.3829827 | T23: =P23/Q23-1 -> -0.18311341 | U23: =O23/R23-1 -> -0.37332803 | W23: 1895.663 | X23: =+P23-W23 -> -34.86479
B24: Sortant voix roaming | C24: 16.595851 | D24: 14.877293 | E24: 16.190098 | F24: 15.999767 | G24: 16.570214 | H24: 16.040831 | I24: 16.621053 | J24: 16.742199 | K24: 16.286464 | L24: 16.926658 | M24: 16.496737 | N24: 17.186085 | O24: =SUM(C24,D24,E24,F24,G24,H24,I24,J24,K24,L24,M24,N24) -> 196.53325 | P24: 156.91299 | Q24: 191.22686 | R24: 208.56604 | S24: =O24/P24-1 -> 0.25249826 | T24: =P24/Q24-1 -> -0.17944063 | U24: =O24/R24-1 -> -0.057692948 | W24: 157.61975 | X24: =+P24-W24 -> -0.70675359
B25: Total VOIX Sortant | C25: =SUM(C17:C24) -> 3782.9934 | D25: =SUM(D17:D24) -> 3426.0693 | E25: =SUM(E17:E24) -> 3592.075 | F25: =SUM(F17:F24) -> 3519.4631 | G25: =SUM(G17:G24) -> 3632.8363 | H25: =SUM(H17:H24) -> 3409.4629 | I25: =SUM(I17:I24) -> 3308.398 | J25: =SUM(J17:J24) -> 3188.8889 | ... N25: =SUM(N17:N24) -> 3539.3205 | O25: =SUM(C25,D25,E25,F25,G25,H25,I25,J25,K25,L25,M25,N25) -> 40736.48 | P25: 41114.586 | Q25: 45514.083 | R25: 42012.989 | S25: =O25/P25-1 -> -0.0091964084 | T25: =P25/Q25-1 -> -0.096662326 | U25: =O25/R25-1 -> -0.030383689 | W25: 41561.913 | X25: =+P25-W25 -> -447.32698
S26: =IFERROR(O26/#REF!-1,"") | X26: =+P26-W26 -> 0
B27: Sortant sms on net | C27: 1.2104351 | D27: 1.0398187 | E27: 1.1670257 | F27: 1.0669521 | G27: 1.0504499 | H27: 1.0113768 | I27: 1.0086457 | J27: 0.95447968 | K27: 0.85628454 | L27: 0.87258911 | M27: 0.80033178 | N27: 0.81720716 | O27: =SUM(C27,D27,E27,F27,G27,H27,I27,J27,K27,L27,M27,N27) -> 11.855596 | P27: 21.744486 | Q27: 25.897273 | R27: 16.214351 | S27: =O27/P27-1 -> -0.4547769 | T27: =P27/Q27-1 -> -0.16035614 | U27: =O27/R27-1 -> -0.26882078 | W27: 21.537112 | X27: =+P27-W27 -> 0.20737405
B28: Sortant sms MTN | C28: 1.3495968 | D28: 1.1374519 | E28: 1.3023064 | F28: 1.1885618 | G28: 1.1962148 | H28: 1.2040726 | I28: 1.2282198 | J28: 1.1609352 | K28: 1.034408 | L28: 1.0342915 | M28: 0.94422095 | N28: 0.95968363 | O28: =SUM(C28,D28,E28,F28,G28,H28,I28,J28,K28,L28,M28,N28) -> 13.739963 | P28: 19.068547 | Q28: 22.816118 | R28: 16.660504 | S28: =O28/P28-1 -> -0.27944361 | T28: =P28/Q28-1 -> -0.16425104 | U28: =O28/R28-1 -> -0.17529727 | W28: 18.786359 | X28: =+P28-W28 -> 0.282188
B29: Sortant sms GLO | O29: =SUM(C29,D29,E29,F29,G29,H29,I29,J29,K29,L29,M29,N29) -> 0 | P29: 0 | Q29: 0 | R29: 0 | S29: =IFERROR(O29/#REF!-1,"") | W29: 0 | X29: =+P29-W29 -> 0
B30: Sortant sms BBCOM | C30: 0.0020104274 | D30: 0.0016762382 | E30: 0.0019295857 | F30: 0.0017563069 | G30: 0.0017700046 | H30: 0.0017804293 | I30: 0.0018167483 | J30: 0.001716933 | K30: 0.0015299382 | L30: 0.0015297013 | M30: 0.0013965179 | N30: 0.0014193724 | O30: =SUM(C30,D30,E30,F30,G30,H30,I30,J30,K30,L30,M30,N30) -> 0.020332203 | P30: 0.020845527 | Q30: 0.036873 | R30: 0 | S30: =O30/P30-1 -> -0.024625116 | T30: =P30/Q30-1 -> -0.43466692 | W30: 0.020435599 | X30: =+P30-W30 -> 0.00040992729
B31: Sortant sms LIBERCOM | C31: 0.40805876 | D31: 0.34140512 | E31: 0.39232378 | F31: 0.35740193 | G31: 0.36003331 | H31: 0.36223221 | I31: 0.36958136 | J31: 0.34929483 | K31: 0.31124397 | L31: 0.31119999 | M31: 0.28410344 | N31: 0.28875388 | O31: =SUM(C31,D31,E31,F31,G31,H31,I31,J31,K31,L31,M31,N31) -> 4.1356326 | P31: 4.9110022 | Q31: 4.265927 | R31: 5.2290122 | S31: =O31/P31-1 -> -0.1578842 | T31: =P31/Q31-1 -> 0.15121572 | U31: =O31/R31-1 -> -0.20909869 | W31: 4.8271228 | X31: =+P31-W31 -> 0.083879474
B32: Sortant sms INTERNATIONAL | C32: 1.7264834 | D32: 1.4070221 | E32: 1.6645672 | F32: 1.4475044 | G32: 1.4659039 | H32: 1.440472 | I32: 1.4342532 | J32: 1.4858452 | K32: 1.262133 | L32: 1.2737513 | M32: 1.1651426 | N32: 1.1646236 | O32: =SUM(C32,D32,E32,F32,G32,H32,I32,J32,K32,L32,M32,N32) -> 16.937702 | P32: 27.091205 | Q32: 34.620099 | R32: 23.294845 | S32: =O32/P32-1 -> -0.37478964 | T32: =P32/Q32-1 -> -0.21747176 | U32: =O32/R32-1 -> -0.27289912 | W32: 28.198017 | X32: =+P32-W32 -> -1.1068121
B33: Total SMS Sortant | C33: =SUM(C27:C32) -> 4.6965846 | D33: =SUM(D27:D32) -> 3.9273741 | E33: =SUM(E27:E32) -> 4.5281527 | F33: =SUM(F27:F32) -> 4.0621766 | G33: =SUM(G27:G32) -> 4.0743719 | H33: =SUM(H27:H32) -> 4.0199341 | I33: =SUM(I27:I32) -> 4.0425168 | J33: =SUM(J27:J32) -> 3.9522718 | ... N33: =SUM(N27:N32) -> 3.2316877 | O33: =SUM(C33,D33,E33,F33,G33,H33,I33,J33,K33,L33,M33,N33) -> 46.689227 | P33: 72.836086 | Q33: 87.63629 | R33: 61.398712 | S33: =O33/P33-1 -> -0.35898222 | T33: =P33/Q33-1 -> -0.16888214 | U33: =O33/R33-1 -> -0.23957319 | W33: 73.369047 | X33: =+P33-W33 -> -0.53296069
S34: =IFERROR(O34/#REF!-1,"") | X34: =+P34-W34 -> 0
B35: Revenu Internet 3G | C35: 3972.9579 | D35: 3623.2346 | E35: 4066.6491 | F35: 3997.4935 | G35: 4278.6044 | H35: 4176.7512 | I35: 4341.7594 | J35: 4475.3446 | K35: 4328.3511 | L35: 4542.2054 | M35: 4352.5713 | N35: 4660.8506 | O35: =SUM(C35,D35,E35,F35,G35,H35,I35,J35,K35,L35,M35,N35) -> 50816.773 | P35: 45701.5 | Q35: 43055.339 | R35: 53656.802 | S35: =O35/P35-1 -> 0.11192791 | T35: =P35/Q35-1 -> 0.061459526 | U35: =O35/R35-1 -> -0.052929523 | W35: 45759.382 | X35: =+P35-W35 -> -57.881779
B36: M-Commerce | C36: 500.40913 | D36: 512.69496 | E36: 544.48982 | F36: 579.99647 | G36: 601.84185 | H36: 600.27115 | I36: 662.46305 | J36: 652.57413 | K36: 628.76187 | L36: 673.95144 | M36: 631.00712 | N36: 729.58683 | Q36: 5130.0771 | T36: =P36/Q36-1 -> -1 | X36: =+P36-W36 -> 0
B37: CRBT | C37: 0.2890989 | D37: 0.2624272 | E37: 0.29199712 | F37: 0.28399075 | G37: 0.29492439 | H37: 0.28683776 | I37: 0.29788101 | J37: 0.29937041 | K37: 0.29116187 | L37: 0.3023716 | M37: 0.29408077 | N37: 0.30540288 | O37: =SUM(C37,D37,E37,F37,G37,H37,I37,J37,K37,L37,M37,N37) -> 3.4995447 | P37: 82.94541 | Q37: 12.158026 | R37: 8.04767 | S37: =O37/P37-1 -> -0.95780906 | T37: =P37/Q37-1 -> 5.8222759 | U37: =O37/R37-1 -> -0.56514809 | W37: 82.80285 | X37: =+P37-W37 -> 0.14255914
B38: Crédit secours | C38: 6.5450633 | D38: 6.0299035 | E38: 6.8094839 | F38: 6.7216195 | G38: 7.084587 | H38: 6.993173 | I38: 7.3708043 | J38: 7.5182204 | K38: 7.4212111 | L38: 7.8219565 | M38: 7.721028 | N38: 8.1379635 | O38: =SUM(C38,D38,E38,F38,G38,H38,I38,J38,K38,L38,M38,N38) -> 86.175014 | P38: 86.55635 | Q38: 320.6121 | R38: 129.19411 | S38: =O38/P38-1 -> -0.0044056388 | T38: =P38/Q38-1 -> -0.73002781 | U38: =O38/R38-1 -> -0.33298032 | W38: 86.022483 | X38: =+P38-W38 -> 0.53386717
B39: Story Box | O39: =SUM(C39,D39,E39,F39,G39,H39,I39,J39,K39,L39,M39,N39) -> 0 | P39: 0 | Q39: 0 | R39: 0 | S39: =IFERROR(O39/#REF!-1,"") | W39: 0 | X39: =+P39-W39 -> 0
B40: Phonebook STK | O40: =SUM(C40,D40,E40,F40,G40,H40,I40,J40,K40,L40,M40,N40) -> 0 | P40: 0 | Q40: 0 | R40: 0 | S40: =IFERROR(O40/#REF!-1,"") | W40: 0 | X40: =+P40-W40 -> 0
B41: Gaming | C41: 0 | D41: 0 | E41: 0 | F41: 0 | G41: 0 | H41: 0 | I41: 0 | J41: 0 | K41: 0 | L41: 0 | M41: 0 | N41: 0 | O41: =SUM(C41,D41,E41,F41,G41,H41,I41,J41,K41,L41,M41,N41) -> 0 | P41: 0 | Q41: 0 | R41: 0 | S41: =IFERROR(O41/#REF!-1,"") | W41: 0 | X41: =+P41-W41 -> 0
...

Sheet Marge Mobile 
A2: Marge brute Mobile | M2: =N8/M8-1 -> 0.092913939 | N2: =N38/M38-1 -> 0.15740584
C5: JANVIER | D5: FEV | E5: MARS | F5: AVR | G5: MAI | H5: JUIN | I5: JUIL | J5: AOUT | K5: SEPT | L5: OCT | M5: NOV | N5: DEC | O5: ANNUEL | S5: VARIATIONS
B6: (En Millions ML) | C6: 2025 Budget | D6: 2025 Budget | E6: 2025 Budget | F6: 2025 Budget | G6: 2025 Budget | H6: 2025 Budget | I6: 2025 Budget | J6: 2025 Budget | K6: 2025 Budget | L6: 2025 Budget | M6: 2025 Budget | N6: 2025 Budget | O6: 2025 Budget | P6: 2024 Actu3 | Q6: 2023 Réel | R6: Budget 2024 | S6: Var Budget vs Actu 3 . | T6: Var Actu 3 vs Réel 23. % | U6: Var Budget vs Budget 2024. %
A8: Total Revenu | C8: =+'CA Mobile'!C7 -> 9527.0891 | D8: =+'CA Mobile'!D7 -> 8782.1227 | E8: =+'CA Mobile'!E7 -> 9473.1389 | F8: =+'CA Mobile'!F7 -> 9362.5379 | G8: =+'CA Mobile'!G7 -> 9772.4636 | H8: =+'CA Mobile'!H7 -> 9466.6859 | I8: =+'CA Mobile'!I7 -> 9614.0551 | J8: =+'CA Mobile'!J7 -> 9618.2497 | ... N8: =+'CA Mobile'!N7 -> 10293.443 | O8: =SUM(C8:N8) -> 114333.76 | P8: 108391.75 | Q8: 105542.99 | R8: 115899.62 | S8: =O8/P8-1 -> 0.054819755 | T8: =P8/Q8-1 -> 0.026991494 | U8: =O8/R8-1 -> -0.013510454 | V8: 108887.36 | X8: =V8-P8 -> 495.6011
B9: Trafic (mn) | C9: 1.3868277 | D9: 1.1541336 | E9: 1.3412454 | F9: 1.1021665 | G9: 1.0043925 | H9: 0.95955033 | I9: 0.82649798 | J9: 0.80746278 | K9: 0.79655808 | L9: 0.83071262 | M9: 0.7756846 | N9: 0.88962797 | O9: =SUM(C9:N9) -> 11.87486 | P9: 18.015451 | Q9: 19.767327 | R9: 15.136436 | S9: =O9/P9-1 -> -0.34085137 | T9: =P9/Q9-1 -> -0.088624816 | U9: =O9/R9-1 -> -0.21547844 | V9: 18.015451 | X9: =V9-P9 -> 0
B10: Coût unitaire | C10: =-C11/C9 -> 115.60917 | D10: =-D11/D9 -> 137.18516 | E10: =-E11/E9 -> 121.0293 | F10: 133.84932 | G10: =-G11/G9 -> 164.60697 | H10: =-H11/H9 -> 173.34161 | I10: =-I11/I9 -> 200.03679 | J10: =-J11/J9 -> 207.22937 | K10: =-K11/K9 -> 212.57709 | L10: =-L11/L9 -> 201.42947 | M10: =-M11/M9 -> 218.29749 | N10: =-N11/N9 -> 192.58612 | O10: =O11/O9 -> -167.40913 | P10: -127.79684 | Q10: -115.602 | R10: -109.13958 | S10: =O10/P10-1 -> 0.30996302 | T10: =P10/Q10-1 -> 0.10548987 | V10: -127.79684 | X10: =V10-P10 -> 0
B11: International | C11: -160.33 | D11: -158.33 | E11: -162.33 | F11: -165.33 | G11: -165.33 | H11: -166.33 | I11: -165.33 | J11: -167.33 | K11: -169.33 | L11: -167.33 | M11: -169.33 | N11: -171.33 | O11: =SUM(C11:N11) -> -1987.96 | P11: -2302.3177 | Q11: -2285.1425 | R11: -1651.9842 | S11: =O11/P11-1 -> -0.13653967 | T11: =P11/Q11-1 -> 0.0075160315 | U11: =O11/R11-1 -> 0.20337714 | V11: -2302.3177 | X11: =V11-P11 -> 0
B12: Trafic (mn) | C12: 75.833719 | D12: 67.040992 | E12: 72.330875 | F12: 66.395866 | G12: 71.830327 | H12: 66.823089 | I12: 66.823089 | J12: 70.355701 | K12: 68.689589 | L12: 70.298771 | M12: 68.905137 | N12: 78.87431 | O12: =SUM(C12:N12) -> 844.20147 | P12: 846.86758 | Q12: 0 | R12: 847.28519 | S12: =O12/Q12-1 -> #DIV/0! | T12: =O12/#REF!-1 -> #REF! | U12: =O12/R12-1 -> -0.0036395295 | V12: 846.86758 | X12: =V12-P12 -> 0
B13: Coût unitaire | C13: -10 | D13: -10 | E13: -10 | F13: 0 | G13: 0 | H13: 0 | I13: 0 | J13: 0 | K13: 0 | L13: 0 | M13: 0 | N13: 0 | O13: =O14/O12 -> 0 | P13: 0 | Q13: 0 | R13: 0 | V13: 0 | X13: =V13-P13 -> 0
B14: Opérateur national 1 (mtn) | C14: 0 | D14: 0 | E14: 0 | F14: 0 | G14: 0 | H14: 0 | I14: 0 | J14: 0 | K14: 0 | L14: 0 | M14: 0 | N14: 0 | O14: =SUM(C14:N14) -> 0 | P14: 0 | Q14: 0 | R14: 0 | V14: 0 | X14: =V14-P14 -> 0
B15: Trafic (mn) | C15: 0 | D15: 0 | E15: 0 | F15: 0 | G15: 0 | H15: 0 | I15: 0 | J15: 0 | K15: 0 | L15: 0 | M15: 0 | N15: 0 | O15: =SUM(C15:N15) -> 0 | P15: 0 | R15: 0 | V15: 0 | X15: =V15-P15 -> 0
B16: Coût unitaire | C16: 0 | D16: 0 | E16: 0 | F16: -10 | G16: -10 | H16: -10 | I16: -10 | J16: -10 | K16: -10 | L16: -10 | M16: -10 | N16: -10 | O16: - | P16: - | Q16: - | R16: - | V16: - | X16: =V16-P16 -> #VALUE!
B17: Opérateur national 2 (glo) | C17: 0 | D17: 0 | E17: 0 | F17: 0 | G17: 0 | H17: 0 | I17: 0 | J17: 0 | K17: 0 | L17: 0 | M17: 0 | N17: 0 | O17: =SUM(C17:N17) -> 0 | P17: 0 | Q17: 0 | R17: 0 | V17: 0 | X17: =V17-P17 -> 0
C18: 0 | D18: 0 | E18: 0 | F18: 0.026719928 | G18: 0.026719928 | H18: 0.026719928 | I18: 0.026719928 | J18: 0.026077273 | K18: 0.02545973 | L18: 0.026056172 | M18: 0.025539623 | N18: 0.029234687 | X18: =V18-P18 -> 0
C19: 0 | D19: 0 | E19: 0 | F19: 0 | G19: 0 | H19: 0 | I19: 0 | J19: -1886.5767 | K19: -1932.3369 | L19: -1888.1045 | M19: -1926.2922 | N19: -1682.822 | X19: =V19-P19 -> 0
B20: Achat de capacité | C20: -49.196775 | D20: -49.196775 | E20: -49.196775 | F20: -49.196775 | G20: -49.196775 | H20: -49.196775 | I20: -49.196775 | J20: -49.196775 | K20: -49.196775 | L20: -49.196775 | M20: -49.196775 | N20: -49.196775 | O20: =SUM(C20:N20) -> -590.3613 | P20: -815.33103 | Q20: -223.12875 | R20: 0 | V20: -815.33103 | X20: =V20-P20 -> 0
C21: 0 | D21: 0 | E21: 0 | F21: 0 | G21: 0 | H21: 0 | I21: 0 | J21: 0 | K21: 0 | L21: 0 | M21: 0 | N21: 0 | X21: =V21-P21 -> 0
C22: 0 | D22: 0 | E22: 0 | F22: 0 | G22: 0 | H22: 0 | I22: 0 | J22: 0 | K22: 0 | L22: 0 | M22: 0 | N22: 0 | X22: =V22-P22 -> 0
C23: 0 | D23: 0 | E23: 0 | F23: 0 | G23: 0 | H23: 0 | I23: 0 | J23: 0 | K23: 0 | L23: 0 | M23: 0 | N23: 0 | X23: =V23-P23 -> 0
