Workbook
Name \A: #REF!
Name \A: #REF!
Name \A: #REF!
Name \A: #REF!
Name \e: #N/A
Name \i: #REF!
Name \i: #REF!
Name \p: '[1]Cur Q v Plan'!#REF!
Name \p: '[2]Cur Q v Plan'!#REF!
Name \p: #REF!
Name \p: '[1]Cur Q v Plan'!#REF!
Name \p: '[1]Cur Q v Plan'!#REF!
Name \r: #N/A
Name \t: #N/A
Name _: #REF!
Name _: #REF!
Name _: #N/A
Name _: #REF!
Name _: #REF!
Name _???: #N/A
Name __: #REF!
Name __: #REF!
Name __: #N/A
Name __: #REF!
Name __: #REF!
Name __???: #N/A
Name ___???: #N/A
Name ____???: #N/A
Name _____???: #N/A
Name ______???: #N/A
Name _______???: #N/A
Name ________???: #N/A
Name _________________aaa1: #REF!
Name _________________aaa1: #REF!
Name _________________aaa2: #REF!
Name _________________aaa2: #REF!
Name _________________aaa3: #REF!
Name _________________aaa3: #REF!
Name _________________aaa4: #REF!
Name _________________aaa4: #REF!
Name _________________aaa5: #REF!
Name _________________aaa5: #REF!
Name _________________aaa6: #REF!
Name _________________aaa6: #REF!
Name _________________aaa7: #REF!
Name _________________aaa7: #REF!
Name _________________aaa8: #REF!
Name _________________aaa8: #REF!
Name _________________ess1: #REF!
Name _________________ess1: #REF!
Name _________________FRF4: '[3]FX Rates'!$G$10
Name _________________FRU2003: #REF!
Name _________________FRU2003: #REF!
Name _________________GBP4: '[3]FX Rates'!$G$9
Name _________________pg1: #REF!
Name _________________pg1: #REF!
Name _________________pg2: #REF!
Name _________________pg2: #REF!
Name _________________SC16: #REF!
Name _________________SC16: #REF!

Sheet Canevas au 31 Décembre 2023
F2: TBG Filiales (Réels)
C6: Pour info: - Saisir toutes les périodes à charger, une par colonne - Une période doit s'écrire : mmm/aaaa
B7: N° Indicat | C7: Nom Technique | D7: Axe | E7: Sous axe | F7: Description Indicateur | G7: Filiale | H7: 001.2023 | I7: 002.2023 | J7: 003.2023 | K7: 004.2023 | L7: 005.2023 | M7: 006.2023 | N7: 007.2023 | O7: 008.2023 | P7: 009.2023 | Q7: 010.2023 | R7: 011.2023 | S7: 012.2023 | T7: 11.2023
B8: 34 | C8: ZFIL_A01 | D8: Taux de change | E8: Taux de change | F8: Taux de change P&L | G8: Centrafrique | H8: ='[375]Canevas au 31 Janvier 2023'!T8 -> 0 | I8: ='[376]Canevas au 29 Février 2023'!T8 -> 0 | J8: ='[377]Canevas au 31 Mars 2023'!T8 -> 0 | K8: ='[378]Canevas au 30 Avril 2023'!T8 -> 0 | L8: ='[379]Canevas au 31 Mai 2023'!T8 -> 0 | M8: ='[380]Canevas au 30 Juin 2023'!T8 -> 0 | N8: ='[381]Canevas au 31 Juillet 2023'!T8 -> 0 | O8: ='[382]Canevas au 31 Août 2023'!T8 -> 0 | P8: ='[383]Canevas au 30 Septembre 2023'!T8 -> 0 | Q8: ='[384]Canevas au 31 Octobre 2023'!T8 -> 0
B9: 35 | C9: ZFIL_A02 | D9: Taux de change | E9: Taux de change | F9: Taux de change Bilan | G9: Centrafrique | H9: ='[375]Canevas au 31 Janvier 2023'!T9 -> 0 | I9: ='[376]Canevas au 29 Février 2023'!T9 -> 0 | J9: ='[377]Canevas au 31 Mars 2023'!T9 -> 0 | K9: ='[378]Canevas au 30 Avril 2023'!T9 -> 0 | L9: ='[379]Canevas au 31 Mai 2023'!T9 -> 0 | M9: ='[380]Canevas au 30 Juin 2023'!T9 -> 0 | N9: ='[381]Canevas au 31 Juillet 2023'!T9 -> 0 | O9: ='[382]Canevas au 31 Août 2023'!T9 -> 0 | P9: ='[383]Canevas au 30 Septembre 2023'!T9 -> 0 | Q9: ='[384]Canevas au 31 Octobre 2023'!T9 -> 0
B10: 211 | C10: ZFIL_M03 | D10: Parc Mobile actif | E10: Mobile | F10: Parc Mobile actif (PrP) | G10: Centrafrique | H10: ='[375]Canevas au 31 Janvier 2023'!T10 -> 213951 | I10: ='[376]Canevas au 29 Février 2023'!T10 -> 214351 | J10: ='[377]Canevas au 31 Mars 2023'!T10 -> 214604 | K10: ='[378]Canevas au 30 Avril 2023'!T10 -> 214861 | L10: ='[379]Canevas au 31 Mai 2023'!T10 -> 189213 | M10: ='[380]Canevas au 30 Juin 2023'!T10 -> 194034 | N10: ='[381]Canevas au 31 Juillet 2023'!T10 -> 209553 | O10: ='[382]Canevas au 31 Août 2023'!T10 -> 220447 | P10: ='[383]Canevas au 30 Septembre 2023'!T10 -> 225403 | Q10: ='[384]Canevas au 31 Octobre 2023'!T10 -> 232931 | T10: =+'Indicateurs Parc Mobile '!AA9 -> 248517
B11: 212 | C11: ZFIL_M04 | D11: Parc Mobile actif | E11: Mobile | F11: Parc Mobile actif (PoP) | G11: Centrafrique | H11: ='[375]Canevas au 31 Janvier 2023'!T11 -> 4145 | I11: ='[376]Canevas au 29 Février 2023'!T11 -> 4194 | J11: ='[377]Canevas au 31 Mars 2023'!T11 -> 4246 | K11: ='[378]Canevas au 30 Avril 2023'!T11 -> 4291 | L11: ='[379]Canevas au 31 Mai 2023'!T11 -> 4306 | M11: ='[380]Canevas au 30 Juin 2023'!T11 -> 4320 | N11: ='[381]Canevas au 31 Juillet 2023'!T11 -> 4329 | O11: ='[382]Canevas au 31 Août 2023'!T11 -> 4341 | P11: ='[383]Canevas au 30 Septembre 2023'!T11 -> 4355 | Q11: ='[384]Canevas au 31 Octobre 2023'!T11 -> 4371 | T11: =+'Indicateurs Parc Mobile '!AA13 -> 4397
B12: 357 | C12: ZFIL_M82 | D12: Parc Mobile localisé | E12: Mobile | F12: Parc Mobile localisé | G12: Centrafrique | H12: ='[375]Canevas au 31 Janvier 2023'!T12 -> 130333 | I12: ='[376]Canevas au 29 Février 2023'!T12 -> 132912.33 | J12: ='[377]Canevas au 31 Mars 2023'!T12 -> 131644 | K12: ='[378]Canevas au 30 Avril 2023'!T12 -> 137663.67 | L12: ='[379]Canevas au 31 Mai 2023'!T12 -> 154227 | M12: ='[380]Canevas au 30 Juin 2023'!T12 -> 160284.33 | N12: ='[381]Canevas au 31 Juillet 2023'!T12 -> 175803.33 | O12: ='[382]Canevas au 31 Août 2023'!T12 -> 185482.33 | P12: ='[383]Canevas au 30 Septembre 2023'!T12 -> 186210.67 | Q12: ='[384]Canevas au 31 Octobre 2023'!T12 -> 193837.67 | T12: =+'Indicateurs Parc Mobile '!AA16 -> 205130.33
B13: 213 | C13: ZFIL_M05 | D13: Parc Mobile actif | E13: Mobile | F13: Parc Internet Mobile | G13: Centrafrique | H13: ='[375]Canevas au 31 Janvier 2023'!T13 -> 0 | I13: ='[376]Canevas au 29 Février 2023'!T13 -> 0 | J13: ='[377]Canevas au 31 Mars 2023'!T13 -> 0 | K13: ='[378]Canevas au 30 Avril 2023'!T13 -> 0 | L13: ='[379]Canevas au 31 Mai 2023'!T13 -> 0 | M13: ='[380]Canevas au 30 Juin 2023'!T13 -> 0 | N13: ='[381]Canevas au 31 Juillet 2023'!T13 -> 0 | O13: ='[382]Canevas au 31 Août 2023'!T13 -> 0 | P13: ='[383]Canevas au 30 Septembre 2023'!T13 -> 0 | Q13: ='[384]Canevas au 31 Octobre 2023'!T13 -> 0
B14: 214 | C14: ZFIL_M06 | D14: Parc Mobile Money | E14: Mobile | F14: Parc Mobile Money | G14: Centrafrique | H14: ='[375]Canevas au 31 Janvier 2023'!T14 -> 0 | I14: ='[376]Canevas au 29 Février 2023'!T14 -> 0 | J14: ='[377]Canevas au 31 Mars 2023'!T14 -> 0 | K14: ='[378]Canevas au 30 Avril 2023'!T14 -> 0 | L14: ='[379]Canevas au 31 Mai 2023'!T14 -> 0 | M14: ='[380]Canevas au 30 Juin 2023'!T14 -> 0 | N14: ='[381]Canevas au 31 Juillet 2023'!T14 -> 0 | O14: ='[382]Canevas au 31 Août 2023'!T14 -> 0 | P14: ='[383]Canevas au 30 Septembre 2023'!T14 -> 0 | Q14: ='[384]Canevas au 31 Octobre 2023'!T14 -> 0
B15: 227 | C15: ZFIL_M11 | D15: Ventes brutes Mobile | E15: Mobile | F15: Mobile (PrP) | G15: Centrafrique | H15: ='[375]Canevas au 31 Janvier 2023'!T15 -> 11228 | I15: ='[376]Canevas au 29 Février 2023'!T15 -> 11204 | J15: ='[377]Canevas au 31 Mars 2023'!T15 -> 11284 | K15: ='[378]Canevas au 30 Avril 2023'!T15 -> 14010 | L15: ='[379]Canevas au 31 Mai 2023'!T15 -> 14510 | M15: ='[380]Canevas au 30 Juin 2023'!T15 -> 27308 | N15: ='[381]Canevas au 31 Juillet 2023'!T15 -> 30781 | O15: ='[382]Canevas au 31 Août 2023'!T15 -> 31042 | P15: ='[383]Canevas au 30 Septembre 2023'!T15 -> 26419.75 | Q15: ='[384]Canevas au 31 Octobre 2023'!T15 -> 37423 | T15: =+'Indicateurs Parc Mobile '!O20 -> 31553
B16: 228 | C16: ZFIL_M12 | D16: Ventes brutes Mobile | E16: Mobile | F16: Mobile (PoP) | G16: Centrafrique | H16: ='[375]Canevas au 31 Janvier 2023'!T16 -> 82 | I16: ='[376]Canevas au 29 Février 2023'!T16 -> 80 | J16: ='[377]Canevas au 31 Mars 2023'!T16 -> 92 | K16: ='[378]Canevas au 30 Avril 2023'!T16 -> 94 | L16: ='[379]Canevas au 31 Mai 2023'!T16 -> 134 | M16: ='[380]Canevas au 30 Juin 2023'!T16 -> 137 | N16: ='[381]Canevas au 31 Juillet 2023'!T16 -> 127 | O16: ='[382]Canevas au 31 Août 2023'!T16 -> 124 | P16: ='[383]Canevas au 30 Septembre 2023'!T16 -> 124 | Q16: ='[384]Canevas au 31 Octobre 2023'!T16 -> 132 | T16: =+'Indicateurs Parc Mobile '!O21 -> 125
B17: 230 | C17: ZFIL_M13 | D17: Résiliations Mobile yc flux d'inactivité | E17: Mobile | F17: Mobile (PrP) | G17: Centrafrique | H17: ='[375]Canevas au 31 Janvier 2023'!T17 -> 10808 | I17: ='[376]Canevas au 29 Février 2023'!T17 -> 10813 | J17: ='[377]Canevas au 31 Mars 2023'!T17 -> 11031 | K17: ='[378]Canevas au 30 Avril 2023'!T17 -> 13756 | L17: ='[379]Canevas au 31 Mai 2023'!T17 -> 40158 | M17: ='[380]Canevas au 30 Juin 2023'!T17 -> 22487 | N17: ='[381]Canevas au 31 Juillet 2023'!T17 -> 15262 | O17: ='[382]Canevas au 31 Août 2023'!T17 -> 20148 | P17: ='[383]Canevas au 30 Septembre 2023'!T17 -> 21463.75 | Q17: ='[384]Canevas au 31 Octobre 2023'!T17 -> 29895 | T17: =+'Indicateurs Parc Mobile '!O25 -> 21389
B18: 231 | C18: ZFIL_M14 | D18: Résiliations Mobile yc flux d'inactivité | E18: Mobile | F18: Mobile (PoP) | G18: Centrafrique | H18: ='[375]Canevas au 31 Janvier 2023'!T18 -> 22 | I18: ='[376]Canevas au 29 Février 2023'!T18 -> 22 | J18: ='[377]Canevas au 31 Mars 2023'!T18 -> 40 | K18: ='[378]Canevas au 30 Avril 2023'!T18 -> 46 | L18: ='[379]Canevas au 31 Mai 2023'!T18 -> 119 | M18: ='[380]Canevas au 30 Juin 2023'!T18 -> 123 | N18: ='[381]Canevas au 31 Juillet 2023'!T18 -> 118 | O18: ='[382]Canevas au 31 Août 2023'!T18 -> 112 | P18: ='[383]Canevas au 30 Septembre 2023'!T18 -> 110 | Q18: ='[384]Canevas au 31 Octobre 2023'!T18 -> 116 | T18: =+'Indicateurs Parc Mobile '!O26 -> 112
B19: 275 | C19: ZFIL_M16 | D19: Trafic Mobile sortant PrP | E19: Mobile | F19: Trafic sortant PrP vers le fixe | G19: Centrafrique | H19: ='[375]Canevas au 31 Janvier 2023'!T19 -> 1848 | I19: ='[376]Canevas au 29 Février 2023'!T19 -> 216 | J19: ='[377]Canevas au 31 Mars 2023'!T19 -> 407.42857 | K19: ='[378]Canevas au 30 Avril 2023'!T19 -> 407.42857 | L19: ='[379]Canevas au 31 Mai 2023'!T19 -> 511 | M19: ='[380]Canevas au 30 Juin 2023'!T19 -> 1284 | N19: ='[381]Canevas au 31 Juillet 2023'!T19 -> 2448 | O19: ='[382]Canevas au 31 Août 2023'!T19 -> 168 | P19: ='[383]Canevas au 30 Septembre 2023'!T19 -> 100732 | Q19: ='[384]Canevas au 31 Octobre 2023'!T19 -> 100732 | T19: =+'Marge Mobile'!O24*10^6 -> -200000
B20: 276 | C20: ZFIL_M17 | D20: Trafic Mobile sortant PrP | E20: Mobile | F20: Trafic sortant PrP vers l'international | G20: Centrafrique | H20: ='[375]Canevas au 31 Janvier 2023'!T20 -> 159767 | I20: ='[376]Canevas au 29 Février 2023'!T20 -> 146998 | J20: ='[377]Canevas au 31 Mars 2023'!T20 -> 129397.35 | K20: ='[378]Canevas au 30 Avril 2023'!T20 -> 160369 | L20: ='[379]Canevas au 31 Mai 2023'!T20 -> 178535 | M20: ='[380]Canevas au 30 Juin 2023'!T20 -> 163107 | N20: ='[381]Canevas au 31 Juillet 2023'!T20 -> 161155 | O20: ='[382]Canevas au 31 Août 2023'!T20 -> 155166 | P20: ='[383]Canevas au 30 Septembre 2023'!T20 -> 158546 | Q20: ='[384]Canevas au 31 Octobre 2023'!T20 -> 129610 | T20: =+'Trafic '!O16*10^6 -> 773974.82
B21: 277 | C21: ZFIL_M18 | D21: Trafic Mobile sortant PrP | E21: Mobile | F21: Trafic sortant PrP On net | G21: Centrafrique | H21: ='[375]Canevas au 31 Janvier 2023'!T21 -> 2912000 | I21: ='[376]Canevas au 29 Février 2023'!T21 -> 2892000 | J21: ='[377]Canevas au 31 Mars 2023'!T21 -> 2817000 | K21: ='[378]Canevas au 30 Avril 2023'!T21 -> 2891000 | L21: ='[379]Canevas au 31 Mai 2023'!T21 -> 2982000 | M21: ='[380]Canevas au 30 Juin 2023'!T21 -> 3000000 | N21: ='[381]Canevas au 31 Juillet 2023'!T21 -> 3100000 | O21: ='[382]Canevas au 31 Août 2023'!T21 -> 3369700 | P21: ='[383]Canevas au 30 Septembre 2023'!T21 -> 3538185 | Q21: ='[384]Canevas au 31 Octobre 2023'!T21 -> 3608948.7 | T21: =+'Trafic '!O14*10^6 -> 3645038.2
B22: 278 | C22: ZFIL_M19 | D22: Trafic Mobile sortant PrP | E22: Mobile | F22: Trafic sortant PrP vers Telecel | G22: Centrafrique | H22: ='[375]Canevas au 31 Janvier 2023'!T22 -> 113837 | I22: ='[376]Canevas au 29 Février 2023'!T22 -> 133961 | J22: ='[377]Canevas au 31 Mars 2023'!T22 -> 179795.1 | K22: ='[378]Canevas au 30 Avril 2023'!T22 -> 175306.25 | L22: ='[379]Canevas au 31 Mai 2023'!T22 -> 177261.7 | M22: ='[380]Canevas au 30 Juin 2023'!T22 -> 315123 | N22: ='[381]Canevas au 31 Juillet 2023'!T22 -> 337902 | O22: ='[382]Canevas au 31 Août 2023'!T22 -> 392785 | P22: ='[383]Canevas au 30 Septembre 2023'!T22 -> 414337 | Q22: ='[384]Canevas au 31 Octobre 2023'!T22 -> 1581109 | T22: =+'Marge Mobile'!O13*10^6 -> 769969
B23: 279 | C23: ZFIL_M20 | D23: Trafic Mobile sortant PrP | E23: Mobile | F23: Trafic sortant PrP vers Orange | G23: Centrafrique | H23: ='[375]Canevas au 31 Janvier 2023'!T23 -> 135189 | I23: ='[376]Canevas au 29 Février 2023'!T23 -> 184954 | J23: ='[377]Canevas au 31 Mars 2023'!T23 -> 256845.33 | K23: ='[378]Canevas au 30 Avril 2023'!T23 -> 275660 | L23: ='[379]Canevas au 31 Mai 2023'!T23 -> 266252.7 | M23: ='[380]Canevas au 30 Juin 2023'!T23 -> 311753 | N23: ='[381]Canevas au 31 Juillet 2023'!T23 -> 366011 | O23: ='[382]Canevas au 31 Août 2023'!T23 -> 406753 | P23: ='[383]Canevas au 30 Septembre 2023'!T23 -> 438290 | Q23: ='[384]Canevas au 31 Octobre 2023'!T23 -> 1913951 | T23: =+'Marge Mobile'!O16*10^6 -> 1539982
B24: 280 | C24: ZFIL_M21 | D24: Trafic Mobile sortant PrP | E24: Mobile | F24: Trafic sortant PrP vers AZUR | G24: Centrafrique | H24: ='[375]Canevas au 31 Janvier 2023'!T24 -> 0 | I24: ='[376]Canevas au 29 Février 2023'!T24 -> 0 | J24: ='[377]Canevas au 31 Mars 2023'!T24 -> 0 | K24: ='[378]Canevas au 30 Avril 2023'!T24 -> 0 | L24: ='[379]Canevas au 31 Mai 2023'!T24 -> 0 | M24: ='[380]Canevas au 30 Juin 2023'!T24 -> 0 | N24: ='[381]Canevas au 31 Juillet 2023'!T24 -> 0 | O24: ='[382]Canevas au 31 Août 2023'!T24 -> 0 | P24: ='[383]Canevas au 30 Septembre 2023'!T24 -> 0 | Q24: ='[384]Canevas au 31 Octobre 2023'!T24 -> 0 | T24: =+'Marge Mobile'!O19*10^6 -> 0
B25: 292 | C25: ZFIL_M32 | D25: Trafic Mobile sortant PoP | E25: Mobile | F25: Trafic sortant PoP vers le fixe | G25: Centrafrique | H25: ='[375]Canevas au 31 Janvier 2023'!T25 -> 0 | I25: ='[376]Canevas au 29 Février 2023'!T25 -> 0 | J25: ='[377]Canevas au 31 Mars 2023'!T25 -> 0 | K25: ='[378]Canevas au 30 Avril 2023'!T25 -> 0 | L25: ='[379]Canevas au 31 Mai 2023'!T25 -> 0 | M25: ='[380]Canevas au 30 Juin 2023'!T25 -> 0 | N25: ='[381]Canevas au 31 Juillet 2023'!T25 -> 0 | O25: ='[382]Canevas au 31 Août 2023'!T25 -> 0 | P25: ='[383]Canevas au 30 Septembre 2023'!T25 -> 0 | Q25: ='[384]Canevas au 31 Octobre 2023'!T25 -> 0
B26: 293 | C26: ZFIL_M33 | D26: Trafic Mobile sortant PoP | E26: Mobile | F26: Trafic sortant PoP vers l'international | G26: Centrafrique | H26: ='[375]Canevas au 31 Janvier 2023'!T26 -> 0 | I26: ='[376]Canevas au 29 Février 2023'!T26 -> 0 | J26: ='[377]Canevas au 31 Mars 2023'!T26 -> 0 | K26: ='[378]Canevas au 30 Avril 2023'!T26 -> 0 | L26: ='[379]Canevas au 31 Mai 2023'!T26 -> 0 | M26: ='[380]Canevas au 30 Juin 2023'!T26 -> 0 | N26: ='[381]Canevas au 31 Juillet 2023'!T26 -> 0 | O26: ='[382]Canevas au 31 Août 2023'!T26 -> 0 | P26: ='[383]Canevas au 30 Septembre 2023'!T26 -> 0 | Q26: ='[384]Canevas au 31 Octobre 2023'!T26 -> 0
B27: 294 | C27: ZFIL_M34 | D27: Trafic Mobile sortant PoP | E27: Mobile | F27: Trafic sortant PoP On net | G27: Centrafrique | H27: ='[375]Canevas au 31 Janvier 2023'!T27 -> 0 | I27: ='[376]Canevas au 29 Février 2023'!T27 -> 0 | J27: ='[377]Canevas au 31 Mars 2023'!T27 -> 0 | K27: ='[378]Canevas au 30 Avril 2023'!T27 -> 0 | L27: ='[379]Canevas au 31 Mai 2023'!T27 -> 0 | M27: ='[380]Canevas au 30 Juin 2023'!T27 -> 0 | N27: ='[381]Canevas au 31 Juillet 2023'!T27 -> 0 | O27: ='[382]Canevas au 31 Août 2023'!T27 -> 0 | P27: ='[383]Canevas au 30 Septembre 2023'!T27 -> 0 | Q27: ='[384]Canevas au 31 Octobre 2023'!T27 -> 0
B28: 295 | C28: ZFIL_M35 | D28: Trafic Mobile sortant PoP | E28: Mobile | F28: Trafic sortant PoP vers Telecel | G28: Centrafrique | H28: ='[375]Canevas au 31 Janvier 2023'!T28 -> 0 | I28: ='[376]Canevas au 29 Février 2023'!T28 -> 0 | J28: ='[377]Canevas au 31 Mars 2023'!T28 -> 0 | K28: ='[378]Canevas au 30 Avril 2023'!T28 -> 0 | L28: ='[379]Canevas au 31 Mai 2023'!T28 -> 0 | M28: ='[380]Canevas au 30 Juin 2023'!T28 -> 0 | N28: ='[381]Canevas au 31 Juillet 2023'!T28 -> 0 | O28: ='[382]Canevas au 31 Août 2023'!T28 -> 0 | P28: ='[383]Canevas au 30 Septembre 2023'!T28 -> 0 | Q28: ='[384]Canevas au 31 Octobre 2023'!T28 -> 0
B29: 296 | C29: ZFIL_M36 | D29: Trafic Mobile sortant PoP | E29: Mobile | F29: Trafic sortant PoP vers Orange | G29: Centrafrique | H29: ='[375]Canevas au 31 Janvier 2023'!T29 -> 0 | I29: ='[376]Canevas au 29 Février 2023'!T29 -> 0 | J29: ='[377]Canevas au 31 Mars 2023'!T29 -> 0 | K29: ='[378]Canevas au 30 Avril 2023'!T29 -> 0 | L29: ='[379]Canevas au 31 Mai 2023'!T29 -> 0 | M29: ='[380]Canevas au 30 Juin 2023'!T29 -> 0 | N29: ='[381]Canevas au 31 Juillet 2023'!T29 -> 0 | O29: ='[382]Canevas au 31 Août 2023'!T29 -> 0 | P29: ='[383]Canevas au 30 Septembre 2023'!T29 -> 0 | Q29: ='[384]Canevas au 31 Octobre 2023'!T29 -> 0
B30: 297 | C30: ZFIL_M37 | D30: Trafic Mobile sortant PoP | E30: Mobile | F30: Trafic sortant PoP vers AZUR | G30: Centrafrique | H30: ='[375]Canevas au 31 Janvier 2023'!T30 -> 0 | I30: ='[376]Canevas au 29 Février 2023'!T30 -> 0 | J30: ='[377]Canevas au 31 Mars 2023'!T30 -> 0 | K30: ='[378]Canevas au 30 Avril 2023'!T30 -> 0 | L30: ='[379]Canevas au 31 Mai 2023'!T30 -> 0 | M30: ='[380]Canevas au 30 Juin 2023'!T30 -> 0 | N30: ='[381]Canevas au 31 Juillet 2023'!T30 -> 0 | O30: ='[382]Canevas au 31 Août 2023'!T30 -> 0 | P30: ='[383]Canevas au 30 Septembre 2023'!T30 -> 0 | Q30: ='[384]Canevas au 31 Octobre 2023'!T30 -> 0
B31: 311 | C31: ZFIL_M48 | D31: Trafic Mobile entrant PrP | E31: Mobile | F31: Trafic entrant PrP depuis le fixe | G31: Centrafrique | H31: ='[375]Canevas au 31 Janvier 2023'!T31 -> 483 | I31: ='[376]Canevas au 29 Février 2023'!T31 -> 448 | J31: ='[377]Canevas au 31 Mars 2023'!T31 -> 456.14286 | K31: ='[378]Canevas au 30 Avril 2023'!T31 -> 456.14286 | L31: ='[379]Canevas au 31 Mai 2023'!T31 -> 442 | M31: ='[380]Canevas au 30 Juin 2023'!T31 -> 254 | N31: ='[381]Canevas au 31 Juillet 2023'!T31 -> 123 | O31: ='[382]Canevas au 31 Août 2023'!T31 -> 68 | P31: ='[383]Canevas au 30 Septembre 2023'!T31 -> 81 | Q31: ='[384]Canevas au 31 Octobre 2023'!T31 -> 29 | T31: =+'Trafic '!O27*10^6 -> 0
B32: 312 | C32: ZFIL_M49 | D32: Trafic Mobile entrant PrP | E32: Mobile | F32: Trafic entrant PrP depuis l'international | G32: Centrafrique | H32: ='[375]Canevas au 31 Janvier 2023'!T32 -> 31616 | I32: ='[376]Canevas au 29 Février 2023'!T32 -> 30975 | J32: ='[377]Canevas au 31 Mars 2023'!T32 -> 29897.667 | K32: ='[378]Canevas au 30 Avril 2023'!T32 -> 33518 | L32: ='[379]Canevas au 31 Mai 2023'!T32 -> 41531.3 | M32: ='[380]Canevas au 30 Juin 2023'!T32 -> 33861 | N32: ='[381]Canevas au 31 Juillet 2023'!T32 -> 34523 | O32: ='[382]Canevas au 31 Août 2023'!T32 -> 35027 | P32: ='[383]Canevas au 30 Septembre 2023'!T32 -> 35189 | Q32: ='[384]Canevas au 31 Octobre 2023'!T32 -> 60217 | T32: =+'Trafic '!O28*10^6 -> 35968
B33: 313 | C33: ZFIL_M50 | D33: Trafic Mobile entrant PrP | E33: Mobile | F33: Trafic entrant PrP depuis Telecel | G33: Centrafrique | H33: ='[375]Canevas au 31 Janvier 2023'!T33 -> 31616 | I33: ='[376]Canevas au 29 Février 2023'!T33 -> 30502 | J33: ='[377]Canevas au 31 Mars 2023'!T33 -> 31086.667 | K33: ='[378]Canevas au 30 Avril 2023'!T33 -> 39846.25 | L33: ='[379]Canevas au 31 Mai 2023'!T33 -> 38936 | M33: ='[380]Canevas au 30 Juin 2023'!T33 -> 50265 | N33: ='[381]Canevas au 31 Juillet 2023'!T33 -> 55786 | O33: ='[382]Canevas au 31 Août 2023'!T33 -> 62157 | P33: ='[383]Canevas au 30 Septembre 2023'!T33 -> 63098 | Q33: ='[384]Canevas au 31 Octobre 2023'!T33 -> 50060 | T33: =+'Trafic '!O24*10^6 -> 195398
B34: 314 | C34: ZFIL_M51 | D34: Trafic Mobile entrant PrP | E34: Mobile | F34: Trafic entrant PrP depuis Orange | G34: Centrafrique | H34: ='[375]Canevas au 31 Janvier 2023'!T34 -> 45095 | I34: ='[376]Canevas au 29 Février 2023'!T34 -> 49776 | J34: ='[377]Canevas au 31 Mars 2023'!T34 -> 59850.667 | K34: ='[378]Canevas au 30 Avril 2023'!T34 -> 60093.75 | L34: ='[379]Canevas au 31 Mai 2023'!T34 -> 59972 | M34: ='[380]Canevas au 30 Juin 2023'!T34 -> 65011 | N34: ='[381]Canevas au 31 Juillet 2023'!T34 -> 69045 | O34: ='[382]Canevas au 31 Août 2023'!T34 -> 74321 | P34: ='[383]Canevas au 30 Septembre 2023'!T34 -> 76612 | Q34: ='[384]Canevas au 31 Octobre 2023'!T34 -> 628047 | T34: =+'Trafic '!O25*10^6 -> 156385
B35: 315 | C35: ZFIL_M52 | D35: Trafic Mobile entrant PrP | E35: Mobile | F35: Trafic entrant PrP depuis AZUR | G35: Centrafrique | H35: ='[375]Canevas au 31 Janvier 2023'!T35 -> 0 | I35: ='[376]Canevas au 29 Février 2023'!T35 -> 0 | J35: ='[377]Canevas au 31 Mars 2023'!T35 -> 0 | K35: ='[378]Canevas au 30 Avril 2023'!T35 -> 0 | L35: ='[379]Canevas au 31 Mai 2023'!T35 -> 0 | M35: ='[380]Canevas au 30 Juin 2023'!T35 -> 0 | N35: ='[381]Canevas au 31 Juillet 2023'!T35 -> 0 | O35: ='[382]Canevas au 31 Août 2023'!T35 -> 0 | P35: ='[383]Canevas au 30 Septembre 2023'!T35 -> 0 | Q35: ='[384]Canevas au 31 Octobre 2023'!T35 -> 0 | T35: =+'Trafic '!O26*10^6 -> 0
B36: 316 | C36: ZFIL_M53 | D36: Trafic Mobile entrant PrP | E36: Mobile | F36: Transit Entrant PrP International via les concurrents | G36: Centrafrique | H36: ='[375]Canevas au 31 Janvier 2023'!T36 -> 0 | I36: ='[376]Canevas au 29 Février 2023'!T36 -> 0 | J36: ='[377]Canevas au 31 Mars 2023'!T36 -> 0 | K36: ='[378]Canevas au 30 Avril 2023'!T36 -> 0 | L36: ='[379]Canevas au 31 Mai 2023'!T36 -> 0 | M36: ='[380]Canevas au 30 Juin 2023'!T36 -> 0 | N36: ='[381]Canevas au 31 Juillet 2023'!T36 -> 0 | O36: ='[382]Canevas au 31 Août 2023'!T36 -> 0 | P36: ='[383]Canevas au 30 Septembre 2023'!T36 -> 0 | Q36: ='[384]Canevas au 31 Octobre 2023'!T36 -> 0
B37: 317 | C37: ZFIL_M54 | D37: Trafic Mobile entrant PrP | E37: Mobile | F37: Transit Entrant PrP International vers les concurrents | G37: Centrafrique | H37: ='[375]Canevas au 31 Janvier 2023'!T37 -> 0 | I37: ='[376]Canevas au 29 Février 2023'!T37 -> 0 | J37: ='[377]Canevas au 31 Mars 2023'!T37 -> 0 | K37: ='[378]Canevas au 30 Avril 2023'!T37 -> 0 | L37: ='[379]Canevas au 31 Mai 2023'!T37 -> 0 | M37: ='[380]Canevas au 30 Juin 2023'!T37 -> 0 | N37: ='[381]Canevas au 31 Juillet 2023'!T37 -> 0 | O37: ='[382]Canevas au 31 Août 2023'!T37 -> 0 | P37: ='[383]Canevas au 30 Septembre 2023'!T37 -> 0 | Q37: ='[384]Canevas au 31 Octobre 2023'!T37 -> 0
B38: 327 | C38: ZFIL_M62 | D38: Trafic Mobile entrant PoP | E38: Mobile | F38: Trafic entrant PoP depuis le fixe | G38: Centrafrique | H38: ='[375]Canevas au 31 Janvier 2023'!T38 -> 0 | I38: ='[376]Canevas au 29 Février 2023'!T38 -> 0 | J38: ='[377]Canevas au 31 Mars 2023'!T38 -> 0 | K38: ='[378]Canevas au 30 Avril 2023'!T38 -> 0 | L38: ='[379]Canevas au 31 Mai 2023'!T38 -> 0 | M38: ='[380]Canevas au 30 Juin 2023'!T38 -> 0 | N38: ='[381]Canevas au 31 Juillet 2023'!T38 -> 0 | O38: ='[382]Canevas au 31 Août 2023'!T38 -> 0 | P38: ='[383]Canevas au 30 Septembre 2023'!T38 -> 0 | Q38: ='[384]Canevas au 31 Octobre 2023'!T38 -> 0
B39: 328 | C39: ZFIL_M63 | D39: Trafic Mobile entrant PoP | E39: Mobile | F39: Trafic entrant PoP depuis l'international | G39: Centrafrique | H39: ='[375]Canevas au 31 Janvier 2023'!T39 -> 0 | I39: ='[376]Canevas au 29 Février 2023'!T39 -> 0 | J39: ='[377]Canevas au 31 Mars 2023'!T39 -> 0 | K39: ='[378]Canevas au 30 Avril 2023'!T39 -> 0 | L39: ='[379]Canevas au 31 Mai 2023'!T39 -> 0 | M39: ='[380]Canevas au 30 Juin 2023'!T39 -> 0 | N39: ='[381]Canevas au 31 Juillet 2023'!T39 -> 0 | O39: ='[382]Canevas au 31 Août 2023'!T39 -> 0 | P39: ='[383]Canevas au 30 Septembre 2023'!T39 -> 0 | Q39: ='[384]Canevas au 31 Octobre 2023'!T39 -> 0
B40: 329 | C40: ZFIL_M64 | D40: Trafic Mobile entrant PoP | E40: Mobile | F40: Trafic entrant PoP depuis Telecel | G40: Centrafrique | H40: ='[375]Canevas au 31 Janvier 2023'!T40 -> 0 | I40: ='[376]Canevas au 29 Février 2023'!T40 -> 0 | J40: ='[377]Canevas au 31 Mars 2023'!T40 -> 0 | K40: ='[378]Canevas au 30 Avril 2023'!T40 -> 0 | L40: ='[379]Canevas au 31 Mai 2023'!T40 -> 0 | M40: ='[380]Canevas au 30 Juin 2023'!T40 -> 0 | N40: ='[381]Canevas au 31 Juillet 2023'!T40 -> 0 | O40: ='[382]Canevas au 31 Août 2023'!T40 -> 0 | P40: ='[383]Canevas au 30 Septembre 2023'!T40 -> 0 | Q40: ='[384]Canevas au 31 Octobre 2023'!T40 -> 0
B41: 330 | C41: ZFIL_M65 | D41: Trafic Mobile entrant PoP | E41: Mobile | F41: Trafic entrant PoP depuis Orange | G41: Centrafrique | H41: ='[375]Canevas au 31 Janvier 2023'!T41 -> 0 | I41: ='[376]Canevas au 29 Février 2023'!T41 -> 0 | J41: ='[377]Canevas au 31 Mars 2023'!T41 -> 0 | K41: ='[378]Canevas au 30 Avril 2023'!T41 -> 0 | L41: ='[379]Canevas au 31 Mai 2023'!T41 -> 0 | M41: ='[380]Canevas au 30 Juin 2023'!T41 -> 0 | N41: ='[381]Canevas au 31 Juillet 2023'!T41 -> 0 | O41: ='[382]Canevas au 31 Août 2023'!T41 -> 0 | P41: ='[383]Canevas au 30 Septembre 2023'!T41 -> 0 | Q41: ='[384]Canevas au 31 Octobre 2023'!T41 -> 0
B42: 331 | C42: ZFIL_M66 | D42: Trafic Mobile entrant PoP | E42: Mobile | F42: Trafic entrant PoP depuis AZUR | G42: Centrafrique | H42: ='[375]Canevas au 31 Janvier 2023'!T42 -> 0 | I42: ='[376]Canevas au 29 Février 2023'!T42 -> 0 | J42: ='[377]Canevas au 31 Mars 2023'!T42 -> 0 | K42: ='[378]Canevas au 30 Avril 2023'!T42 -> 0 | L42: ='[379]Canevas au 31 Mai 2023'!T42 -> 0 | M42: ='[380]Canevas au 30 Juin 2023'!T42 -> 0 | N42: ='[381]Canevas au 31 Juillet 2023'!T42 -> 0 | O42: ='[382]Canevas au 31 Août 2023'!T42 -> 0 | P42: ='[383]Canevas au 30 Septembre 2023'!T42 -> 0 | Q42: ='[384]Canevas au 31 Octobre 2023'!T42 -> 0
B43: 332 | C43: ZFIL_M67 | D43: Trafic Mobile entrant PoP | E43: Mobile | F43: Transit Entrant PoP International via les concurrents | G43: Centrafrique | H43: ='[375]Canevas au 31 Janvier 2023'!T43 -> 0 | I43: ='[376]Canevas au 29 Février 2023'!T43 -> 0 | J43: ='[377]Canevas au 31 Mars 2023'!T43 -> 0 | K43: ='[378]Canevas au 30 Avril 2023'!T43 -> 0 | L43: ='[379]Canevas au 31 Mai 2023'!T43 -> 0 | M43: ='[380]Canevas au 30 Juin 2023'!T43 -> 0 | N43: ='[381]Canevas au 31 Juillet 2023'!T43 -> 0 | O43: ='[382]Canevas au 31 Août 2023'!T43 -> 0 | P43: ='[383]Canevas au 30 Septembre 2023'!T43 -> 0 | Q43: ='[384]Canevas au 31 Octobre 2023'!T43 -> 0
B44: 333 | C44: ZFIL_M68 | D44: Trafic Mobile entrant PoP | E44: Mobile | F44: Transit Entrant PoP International vers les concurrents | G44: Centrafrique | H44: ='[375]Canevas au 31 Janvier 2023'!T44 -> 0 | I44: ='[376]Canevas au 29 Février 2023'!T44 -> 0 | J44: ='[377]Canevas au 31 Mars 2023'!T44 -> 0 | K44: ='[378]Canevas au 30 Avril 2023'!T44 -> 0 | L44: ='[379]Canevas au 31 Mai 2023'!T44 -> 0 | M44: ='[380]Canevas au 30 Juin 2023'!T44 -> 0 | N44: ='[381]Canevas au 31 Juillet 2023'!T44 -> 0 | O44: ='[382]Canevas au 31 Août 2023'!T44 -> 0 | P44: ='[383]Canevas au 30 Septembre 2023'!T44 -> 0 | Q44: ='[384]Canevas au 31 Octobre 2023'!T44 -> 0
...

Sheet Page de garde
F16: Tableau de bord
H19: Décembre 2023
D23: Filiale Moov - Republique Centraficaine
D34: CONFIDENTIEL

Sheet Sommaire
B3: Table des matières
B6: I . Synthèse Moov RCA | L6: P. 2
B8: 1 . Commentaires | L8: P. 2
B10: 1. Tableau de Cash | L10: P. 3
B12: 2. P&L | L12: P. 4
B14: 3. Opex | L14: P. 5
B15: 4 . Indicateurs Parc | L15: P. 7
B17: 5 . ARPU & Usage | L17: P. 8
B19: 6 . Chiffre d'affaires | L19: P. 9
B21: 7 . Marge brute | L21: P. 10
B23: 8. Mobile Money | L23: P. 11
B25: 9. Trafic | L25: P. 12

Sheet Cash 
A2: Moov RCA : Flux Financier consolidé | N2: -4.174705 | P2: 142.22 | Z2: 146.3947
Z4: 0 | AA4: 8.621609
N5: Mensuel | T5: CUMUL M-1 | Z5: CUMUL | AH5: Annuel
C6: Janvier | D6: Février | E6: Mars | F6: Avril | G6: Mai | H6: Juin | I6: Juillet | J6: Août | K6: Septembre | L6: Octobre | M6: Novembre | N6: 2023 | O6: 2023 Budget | P6: Ecart / Budget | Q6: 2022 Réel | R6: Evol % | T6: 2023 | U6: 2023 Budget | V6: Ecart / Budget | W6: 2021 Réel | X6: Evol % | Z6: 2023 | AA6: 2023 Budget | AB6: Ecart / Budget | AC6: 2022 Réel | AD6: Evol % | AF6: 2023 Actu 1 | AG6: 2023 Actu 2 | AH6: 2023 Actu3 | AI6: 2023 Budget | AJ6: 2020 Actu3 | AK6: 2022 Réel | AL6: Ecart / Budget | AM6: Var Actu1/ Budget (%) | AN6: Var Actu1/ 2018 (%) | AO6: B23/ 2022 (%) | AP6: Var Actu3/ 2019 (%)
A8: EBITDA | C8: -35.396924 | D8: -2.0441189 | E8: -50.161313 | F8: -52.420881 | G8: -52.344836 | H8: -46.847419 | I8: -0.54119978 | J8: 11.749142 | K8: 10.20646 | L8: 210.00689 | M8: 26.632439 | N8: 24.782787 | O8: 188.746 | P8: -163.96322 | Q8: -49.495703 | R8: ns | T8: 18.838241 | U8: 596.02418 | V8: -577.18593 | W8: -113.53462 | X8: ns | Z8: 43.621029 | AA8: 784.77018 | AB8: -741.14915 | AC8: -163.03033 | AD8: ns | AF8: 894.0842 | AI8: 784.77018 | AK8: -163.03033 | AL8: -784.77018 | AM8: ns | AN8: ns | AO8: ns | AP8: ns
A10: Autres résultat non courant ( -) | C10: 0 | D10: 0 | E10: 0 | F10: 0 | G10: 0 | H10: 0 | I10: 0 | J10: 0 | K10: 0 | L10: 0 | M10: 0 | N10: -15.688708 | P10: -15.688708 | Q10: 0 | R10: ns | T10: 0 | U10: 0 | V10: 0 | W10: -61.1 | X10: ns | Z10: -15.688708 | AA10: 0 | AB10: -15.688708 | AC10: -61.1 | AD10: 0.743229 | AF10: 0 | AI10: 0 | AK10: -61.1
A12: Neutralisation de la variation de provisions incluses dans l'Ebitda (-) | C12: 2 | D12: 2 | E12: -50.423 | F12: 3 | G12: 3 | H12: 5.88 | I12: 2 | J12: 2 | K12: 0.21534 | L12: 3.177 | M12: -38.2 | N12: 43.11066 | O12: 1.8 | P12: 41.31066 | Q12: -25.380195 | R12: ns | T12: -65.35066 | U12: 17.155484 | V12: -82.506144 | W12: 17.575098 | X12: ns | Z12: -22.24 | AA12: 18.955484 | AB12: -41.195484 | AC12: -7.8050977 | AD12: -1.8494198 | AF12: -30.4998 | AI12: 18.955484 | AK12: -7.8050977 | AL12: -18.955484 | AM12: ns | AN12: ns | AO12: ns | AP12: ns
AN13: ns
A14: Variation de BFR opérationnel (+/-) | C14: -1031.6071 | D14: 1077.7852 | E14: 513.28175 | F14: 74.897301 | G14: 133.11722 | H14: 284.03278 | I14: 153.89029 | J14: -59.950994 | K14: 378.22519 | L14: -152.42723 | M14: 40.379556 | N14: 1244.2013 | O14: 57.731459 | P14: 1186.4698 | Q14: 220.16609 | R14: 4.651194 | S14: 0 | T14: 1411.5239 | U14: 755.39224 | V14: 656.13167 | W14: 669.52263 | X14: 1.1082542 | Z14: 2655.7252 | AA14: 813.1237 | AB14: 1842.6015 | AC14: 889.68872 | AD14: 1.9850049 | AF14: 741.59604 | AI14: 813.1237 | AK14: 889.68872 | AL14: -813.1237 | AM14: ns | AN14: ns | AO14: -0.086058211 | AP14: ns
C15: 0 | D15: 0 | E15: 0 | F15: 0 | G15: 0 | H15: 0 | I15: 0 | J15: 0 | K15: 0 | L15: 0 | M15: 0 | N15: 0 | O15: #REF! | P15: #REF! | Q15: 0 | R15: ns | T15: 0 | V15: 0 | W15: 0 | X15: ns | Z15: 0 | AB15: 0 | AC15: 0 | AD15: ns | AK15: 0 | AL15: 0 | AM15: ns | AN15: ns
A16: Flux net de cash flow provenant des activités opérationnelles avant impôt | C16: #REF! | D16: #REF! | E16: #REF! | F16: #REF! | G16: #REF! | H16: #REF! | I16: #REF! | J16: #REF! | K16: #REF! | L16: #REF! | M16: #REF! | N16: #REF! | O16: #REF! | P16: #REF! | Q16: #REF! | R16: #REF! | T16: #REF! | V16: #REF! | W16: #REF! | X16: #REF! | Z16: #REF! | AB16: #REF! | AC16: #REF! | AD16: #REF! | AK16: #REF! | AL16: 0 | AM16: ns | AN16: #REF!
C17: #REF! | D17: #REF! | E17: #REF! | F17: #REF! | G17: #REF! | H17: #REF! | I17: #REF! | J17: #REF! | K17: #REF! | L17: #REF! | M17: #REF! | N17: #REF! | O17: #REF! | P17: #REF! | Q17: #REF! | R17: #REF! | T17: #REF! | V17: #REF! | W17: #REF! | X17: #REF! | Z17: #REF! | AB17: #REF! | AC17: #REF! | AD17: #REF! | AK17: #REF! | AL17: 0 | AM17: ns | AN17: #REF!
A18: Dividendes reçus de sociétés mises en équivalence (+) | C18: #REF! | D18: #REF! | E18: #REF! | F18: #REF! | G18: #REF! | H18: #REF! | I18: #REF! | J18: #REF! | K18: #REF! | L18: #REF! | M18: #REF! | N18: #REF! | O18: #REF! | P18: #REF! | Q18: #REF! | R18: #REF! | T18: #REF! | V18: #REF! | W18: #REF! | X18: #REF! | Z18: #REF! | AB18: #REF! | AC18: #REF! | AD18: #REF! | AK18: #REF! | AL18: 0 | AM18: ns | AN18: #REF!
A19: Dividendes reçus des participations non consolidées (+) | C19: #REF! | D19: #REF! | E19: #REF! | F19: #REF! | G19: #REF! | H19: #REF! | I19: #REF! | J19: #REF! | K19: #REF! | L19: #REF! | M19: #REF! | N19: #REF! | O19: #REF! | P19: #REF! | Q19: #REF! | R19: #REF! | T19: #REF! | V19: #REF! | W19: #REF! | X19: #REF! | Z19: #REF! | AB19: #REF! | AC19: #REF! | AD19: #REF! | AK19: #REF! | AL19: 0 | AM19: ns | AN19: #REF!
C20: #REF! | D20: #REF! | E20: #REF! | F20: #REF! | G20: #REF! | H20: #REF! | I20: #REF! | J20: #REF! | K20: #REF! | L20: #REF! | M20: #REF! | N20: #REF! | O20: #REF! | P20: #REF! | Q20: #REF! | R20: #REF! | T20: #REF! | V20: #REF! | W20: #REF! | X20: #REF! | Z20: #REF! | AB20: #REF! | AC20: #REF! | AD20: #REF! | AK20: #REF! | AL20: 0 | AM20: ns | AN20: #REF!
A21: CFFO avant capex | C21: 0 | D21: 0 | E21: 0 | F21: 0 | G21: 0 | H21: 0 | I21: 0 | J21: 0 | K21: 0 | L21: 0 | M21: 0 | N21: 0 | O21: #REF! | P21: #REF! | Q21: 0 | R21: ns | T21: 0 | V21: 0 | W21: 0 | X21: ns | Z21: 0 | AB21: 0 | AC21: 0 | AD21: ns | AK21: 0 | AL21: 0 | AM21: ns | AN21: ns | AO21: #DIV/0!
A22: Investissements en SIMs | O22: 0 | P22: 0 | R22: ns | AL22: 0 | AM22: ns | AN22: ns | AO22: ns
A23: Investissements nets (Capex brutes - cession d'immo.) (-) | C23: -4.417442 | D23: -6.207719 | E23: -40.9 | F23: -8.8751244 | G23: -9.0265526 | H23: -10.940375 | I23: -10.857476 | J23: -39.247704 | K23: -3.839499 | L23: -19.762526 | M23: -2.874499 | N23: -1469.7964 | O23: -74.600871 | P23: -1395.1955 | Q23: -10.863914 | R23: -134.2916 | T23: -156.84894 | U23: -3665.3992 | V23: 3508.5503 | W23: -102.55571 | X23: -0.52940221 | Z23: -1626.6453 | AA23: -3740.0001 | AB23: 2113.3548 | AC23: -113.41963 | AD23: -13.341832 | AF23: -3739.9804 | AI23: -3740.0001 | AK23: -113.41963 | AL23: 3740.0001 | AM23: ns | AN23: ns | AO23: 31.974892 | AP23: ns
A24: Neutralisation element non cash
O25: 0
A26: Produits de cession d'immobilisations | O26: 0
A27: CFFO | C27: -1069.4215 | D27: 1071.5333 | E27: 371.79743 | F27: 16.601295 | G27: 74.745834 | H27: 232.12499 | I27: 144.49161 | J27: -85.449557 | K27: 384.8075 | L27: 40.994134 | M27: 25.937496 | N27: -173.39033 | O27: 173.67659 | P27: -347.06692 | Q27: 134.42628 | R27: ns | T27: 1208.1626 | U27: -2296.8273 | V27: 3504.9898 | W27: 409.90739 | X27: 1.9474037 | Z27: 1034.7722 | AA27: -2123.1507 | AB27: 3157.9229 | AC27: 544.33367 | AD27: 0.90098883 | AF27: -2134.7999 | AI27: -2123.1507 | AK27: 544.33367 | AL27: 2123.1507 | AM27: ns | AN27: ns | AO27: ns | AP27: ns
A29: Résultat financier hors dividendes des sociétés non consolidées (+/-) | C29: -15 | D29: 0 | E29: -36.1 | F29: -12.04875 | G29: -7.108665 | H29: 9.624156 | I29: -28.38998 | J29: -18 | K29: -22.3326 | L29: -18.705842 | M29: -57.75 | N29: -53.488319 | O29: -41.676592 | P29: -11.811727 | Q29: -14.08724 | R29: -2.7969339 | T29: -205.81168 | U29: -479.04269 | V29: 273.23101 | W29: -499.84343 | X29: 0.5882477 | Z29: -259.3 | AA29: -520.71928 | AB29: 261.41928 | AC29: -513.93066 | AD29: 0.49545723 | AF29: -237.10007 | AI29: -520.71928 | AK29: -513.93066 | AL29: 520.71928 | AM29: ns | AN29: ns | AO29: -0.013209206 | AP29: ns
A31: Impôts payés (-) | C31: 0 | D31: 0 | E31: 0 | F31: 0 | G31: 0 | H31: 0 | I31: 0 | J31: 0 | K31: 0 | L31: 0 | M31: 0 | N31: 0 | P31: 0 | Q31: 0 | R31: ns | U31: -62.130023 | V31: 62.130023 | X31: ns | AA31: -62.130023 | AB31: 62.130023 | AD31: ns | AI31: -62.130023 | AL31: 62.130023 | AM31: ns | AN31: ns | AO31: ns
A33: Intérêts financiers payés + produits financiers encaissés | C33: 0 | D33: 0 | E33: 0 | F33: 0 | G33: 0 | H33: 0 | I33: 0 | J33: 0 | K33: 0 | L33: 0 | M33: 0 | N33: 0 | Q33: 0 | CS33: Intérêts financiers payés + produits financiers encaissés | CT33: Intérêts financiers payés + produits financiers encaissés | CU33: Intérêts financiers payés + produits financiers encaissés | CV33: Intérêts financiers payés + produits financiers encaissés | CW33: Intérêts financiers payés + produits financiers encaissés | CX33: Intérêts financiers payés + produits financiers encaissés | CY33: Intérêts financiers payés + produits financiers encaissés | CZ33: Intérêts financiers payés + produits financiers encaissés | DA33: Intérêts financiers payés + produits financiers encaissés | DB33: Intérêts financiers payés + produits financiers encaissés | DC33: Intérêts financiers payés + produits financiers encaissés | DD33: Intérêts financiers payés + produits financiers encaissés | DE33: Intérêts financiers payés + produits financiers encaissés | DF33: Intérêts financiers payés + produits financiers encaissés | DG33: Intérêts financiers payés + produits financiers encaissés | DH33: Intérêts financiers payés + produits financiers encaissés | DI33: Intérêts financiers payés + produits financiers encaissés | DJ33: Intérêts financiers payés + produits financiers encaissés | DK33: Intérêts financiers payés + produits financiers encaissés | DL33: Intérêts financiers payés + produits financiers encaissés | DM33: Intérêts financiers payés + produits financiers encaissés | DN33: Intérêts financiers payés + produits financiers encaissés | DO33: Intérêts financiers payés + produits financiers encaissés | DP33: Intérêts financiers payés + produits financiers encaissés | DQ33: Intérêts financiers payés + produits financiers encaissés | DR33: Intérêts financiers payés + produits financiers encaissés | DS33: Intérêts financiers payés + produits financiers encaissés | DT33: Intérêts financiers payés + produits financiers encaissés | DU33: Intérêts financiers payés + produits financiers encaissés | DV33: Intérêts financiers payés + produits financiers encaissés | DW33: Intérêts financiers payés + produits financiers encaissés | DX33: Intérêts financiers payés + produits financiers encaissés | DY33: Intérêts financiers payés + produits financiers encaissés | DZ33: Intérêts financiers payés + produits financiers encaissés | EA33: Intérêts financiers payés + produits financiers encaissés | EB33: Intérêts financiers payés + produits financiers encaissés | EC33: Intérêts financiers payés + produits financiers encaissés | ED33: Intérêts financiers payés + produits financiers encaissés | EE33: Intérêts financiers payés + produits financiers encaissés | EF33: Intérêts financiers payés + produits financiers encaissés | EG33: Intérêts financiers payés + produits financiers encaissés | EH33: Intérêts financiers payés + produits financiers encaissés | EI33: Intérêts financiers payés + produits financiers encaissés | EJ33: Intérêts financiers payés + produits financiers encaissés | EK33: Intérêts financiers payés + produits financiers encaissés | EL33: Intérêts financiers payés + produits financiers encaissés | EM33: Intérêts financiers payés + produits financiers encaissés | EN33: Intérêts financiers payés + produits financiers encaissés | EO33: Intérêts financiers payés + produits financiers encaissés | EP33: Intérêts financiers payés + produits financiers encaissés | EQ33: Intérêts financiers payés + produits financiers encaissés | ER33: Intérêts financiers payés + produits financiers encaissés | ES33: Intérêts financiers payés + produits financiers encaissés | ET33: Intérêts financiers payés + produits financiers encaissés | EU33: Intérêts financiers payés + produits financiers encaissés | EV33: Intérêts financiers payés + produits financiers encaissés | EW33: Intérêts financiers payés + produits financiers encaissés | EX33: Intérêts financiers payés + produits financiers encaissés | EY33: Intérêts financiers payés + produits financiers encaissés | EZ33: Intérêts financiers payés + produits financiers encaissés | FA33: Intérêts financiers payés + produits financiers encaissés | FB33: Intérêts financiers payés + produits financiers encaissés | FC33: Intérêts financiers payés + produits financiers encaissés | FD33: Intérêts financiers payés + produits financiers encaissés | FE33: Intérêts financiers payés + produits financiers encaissés | FF33: Intérêts financiers payés + produits financiers encaissés | FG33: Intérêts financiers payés + produits financiers encaissés | FH33: Intérêts financiers payés + produits financiers encaissés | FI33: Intérêts financiers payés + produits financiers encaissés | FJ33: Intérêts financiers payés + produits financiers encaissés | FK33: Intérêts financiers payés + produits financiers encaissés | FL33: Intérêts financiers payés + produits financiers encaissés | FM33: Intérêts financiers payés + produits financiers encaissés | FN33: Intérêts financiers payés + produits financiers encaissés | FO33: Intérêts financiers payés + produits financiers encaissés | FP33: Intérêts financiers payés + produits financiers encaissés | FQ33: Intérêts financiers payés + produits financiers encaissés | FR33: Intérêts financiers payés + produits financiers encaissés | FS33: Intérêts financiers payés + produits financiers encaissés | FT33: Intérêts financiers payés + produits financiers encaissés | FU33: Intérêts financiers payés + produits financiers encaissés | FV33: Intérêts financiers payés + produits financiers encaissés | FW33: Intérêts financiers payés + produits financiers encaissés | FX33: Intérêts financiers payés + produits financiers encaissés | FY33: Intérêts financiers payés + produits financiers encaissés | FZ33: Intérêts financiers payés + produits financiers encaissés | GA33: Intérêts financiers payés + produits financiers encaissés | GB33: Intérêts financiers payés + produits financiers encaissés | GC33: Intérêts financiers payés + produits financiers encaissés | GD33: Intérêts financiers payés + produits financiers encaissés | GE33: Intérêts financiers payés + produits financiers encaissés | GF33: Intérêts financiers payés + produits financiers encaissés | GG33: Intérêts financiers payés + produits financiers encaissés | GH33: Intérêts financiers payés + produits financiers encaissés | GI33: Intérêts financiers payés + produits financiers encaissés | GJ33: Intérêts financiers payés + produits financiers encaissés | GK33: Intérêts financiers payés + produits financiers encaissés | GL33: Intérêts financiers payés + produits financiers encaissés | GM33: Intérêts financiers payés + produits financiers encaissés | GN33: Intérêts financiers payés + produits financiers encaissés | GO33: Intérêts financiers payés + produits financiers encaissés | GP33: Intérêts financiers payés + produits financiers encaissés | GQ33: Intérêts financiers payés + produits financiers encaissés | GR33: Intérêts financiers payés + produits financiers encaissés | GS33: Intérêts financiers payés + produits financiers encaissés | GT33: Intérêts financiers payés + produits financiers encaissés | GU33: Intérêts financiers payés + produits financiers encaissés | GV33: Intérêts financiers payés + produits financiers encaissés | GW33: Intérêts financiers payés + produits financiers encaissés | GX33: Intérêts financiers payés + produits financiers encaissés | GY33: Intérêts financiers payés + produits financiers encaissés | GZ33: Intérêts financiers payés + produits financiers encaissés | HA33: Intérêts financiers payés + produits financiers encaissés | HB33: Intérêts financiers payés + produits financiers encaissés | HC33: Intérêts financiers payés + produits financiers encaissés | HD33: Intérêts financiers payés + produits financiers encaissés | HE33: Intérêts financiers payés + produits financiers encaissés | HF33: Intérêts financiers payés + produits financiers encaissés | HG33: Intérêts financiers payés + produits financiers encaissés | HH33: Intérêts financiers payés + produits financiers encaissés | HI33: Intérêts financiers payés + produits financiers encaissés | HJ33: Intérêts financiers payés + produits financiers encaissés | HK33: Intérêts financiers payés + produits financiers encaissés | HL33: Intérêts financiers payés + produits financiers encaissés | HM33: Intérêts financiers payés + produits financiers encaissés | HN33: Intérêts financiers payés + produits financiers encaissés | HO33: Intérêts financiers payés + produits financiers encaissés | HP33: Intérêts financiers payés + produits financiers encaissés | HQ33: Intérêts financiers payés + produits financiers encaissés | HR33: Intérêts financiers payés + produits financiers encaissés | HS33: Intérêts financiers payés + produits financiers encaissés | HT33: Intérêts financiers payés + produits financiers encaissés | HU33: Intérêts financiers payés + produits financiers encaissés | HV33: Intérêts financiers payés + produits financiers encaissés | HW33: Intérêts financiers payés + produits financiers encaissés | HX33: Intérêts financiers payés + produits financiers encaissés | HY33: Intérêts financiers payés + produits financiers encaissés | HZ33: Intérêts financiers payés + produits financiers encaissés | IA33: Intérêts financiers payés + produits financiers encaissés | IB33: Intérêts financiers payés + produits financiers encaissés | IC33: Intérêts financiers payés + produits financiers encaissés | ID33: Intérêts financiers payés + produits financiers encaissés | IE33: Intérêts financiers payés + produits financiers encaissés | IF33: Intérêts financiers payés + produits financiers encaissés | IG33: Intérêts financiers payés + produits financiers encaissés | IH33: Intérêts financiers payés + produits financiers encaissés | II33: Intérêts financiers payés + produits financiers encaissés | IJ33: Intérêts financiers payés + produits financiers encaissés | IK33: Intérêts financiers payés + produits financiers encaissés | IL33: Intérêts financiers payés + produits financiers encaissés | IM33: Intérêts financiers payés + produits financiers encaissés | IN33: Intérêts financiers payés + produits financiers encaissés | IO33: Intérêts financiers payés + produits financiers encaissés | IP33: Intérêts financiers payés + produits financiers encaissés | IQ33: Intérêts financiers payés + produits financiers encaissés | IR33: Intérêts financiers payés + produits financiers encaissés | IS33: Intérêts financiers payés + produits financiers encaissés | IT33: Intérêts financiers payés + produits financiers encaissés | IU33: Intérêts financiers payés + produits financiers encaissés | IV33: Intérêts financiers payés + produits financiers encaissés | IW33: Intérêts financiers payés + produits financiers encaissés | IX33: Intérêts financiers payés + produits financiers encaissés | IY33: Intérêts financiers payés + produits financiers encaissés | IZ33: Intérêts financiers payés + produits financiers encaissés | JA33: Intérêts financiers payés + produits financiers encaissés | JB33: Intérêts financiers payés + produits financiers encaissés | JC33: Intérêts financiers payés + produits financiers encaissés | JD33: Intérêts financiers payés + produits financiers encaissés | JE33: Intérêts financiers payés + produits financiers encaissés | JF33: Intérêts financiers payés + produits financiers encaissés | JG33: Intérêts financiers payés + produits financiers encaissés | JH33: Intérêts financiers payés + produits financiers encaissés
A34: Dividendes payés (-) | C34: 0 | D34: 0 | E34: 0 | F34: 0 | G34: 0 | H34: 0 | I34: 0 | J34: 0 | K34: 0 | L34: 0 | M34: 0 | N34: 0 | Q34: 0
A35: Cash flow used for financing and taxes | C35: -15 | D35: 0 | E35: -36.1 | F35: -12.04875 | G35: -7.108665 | H35: 9.624156 | I35: -28.38998 | J35: -18 | K35: -22.3326 | L35: -18.705842 | M35: -57.75 | N35: -53.488319 | Q35: -14.08724
A36: Decaissements solde antériorité (-)
C38: -15 | D38: 0 | E38: -36.1 | F38: -12.04875 | G38: -7.108665 | H38: 9.624156 | I38: -28.38998 | J38: -18 | K38: -22.3326 | L38: -18.705842 | M38: -57.75 | N38: -53.488319 | O38: -41.676592 | P38: -11.811727 | Q38: -14.08724 | R38: -2.7969339 | S38: 0 | T38: -205.81168 | U38: -541.17271 | V38: 335.36103 | W38: -499.84343 | X38: 0.5882477 | Z38: -259.3 | AA38: -582.8493 | AB38: 323.5493 | AC38: -513.93066 | AD38: 0.49545723 | AF38: -237.10007 | AI38: -582.8493 | AK38: -513.93066 | AL38: 582.8493 | AM38: ns | AN38: ns | AO38: -0.13410104
A40: Cash flow used for investment (+/-) | C40: 0 | D40: 0 | E40: 0 | F40: 0 | G40: 0 | H40: 0 | I40: 0 | J40: 0 | K40: 0 | L40: 0 | M40: 745.33 | N40: 0.3 | P40: 0.3 | Q40: 0 | R40: ns | T40: 745.33 | U40: 0 | V40: 745.33 | W40: 6.1 | X40: 121.18525 | Z40: 745.63 | AA40: 0 | AB40: 745.63 | AC40: 6.1 | AD40: 121.23443 | AF40: 0 | AI40: 0 | AK40: 6.1 | AL40: 0 | AM40: ns | AN40: ns | AO40: ns | AP40: ns
AM41: ns
A42: Elements non cash | C42: -102.27137 | D42: -119 | E42: -126.2 | F42: -101.32034 | G42: -128.08311 | H42: -131.12416 | I42: -98.471234 | J42: -73.233975 | K42: 11308.893 | L42: -31.234158 | M42: 8.31 | N42: 12.518319 | O42: 0 | Q42: -126.29796 | R42: ns | T42: 10406.264 | U42: 0 | W42: -1017.8493 | X42: ns | Z42: 10418.783 | AA42: 0 | AC42: -1144.1473 | AD42: ns | AF42: 10412.836 | AI42: 0 | AK42: -1144.1473 | AL42: 0 | AM42: ns | AN42: ns | AO42: ns | AP42: ns
A44: Net cash flow | C44: -1186.6929 | D44: 952.53331 | E44: 209.49743 | F44: -96.767792 | G44: -60.445944 | H44: 110.62499 | I44: 17.6304 | J44: -176.68353 | K44: 11671.367 | L44: -8.945866 | M44: 721.8275 | N44: -214.06033 | O44: 132 | P44: -346.06033 | Q44: -5.958921 | R44: -34.922667 | T44: 12153.945 | U44: -2838 | V44: 14991.945 | W44: -1101.6853 | X44: ns | Z44: 11939.885 | AA44: -2706 | AB44: 14645.885 | AC44: -1107.6443 | AD44: ns | AF44: 8040.9359 | AI44: -2706 | AK44: -1107.6443 | AL44: 2706 | AM44: ns | AN44: ns | AO44: -1.4430226 | AP44: ns
A46: Dettes brutes | C46: -18486.424 | D46: -18605.835 | E46: -18455.984 | F46: -18562.984 | G46: -18634.176 | H46: -18476.309 | I46: -18603.17 | J46: -18694.004 | K46: -6969.1424 | L46: -7018.5824 | M46: -7068.0224 | N46: -6846.3357 | O46: -10127.25 | P46: 3280.914 | Q46: -18384.835 | R46: -0.62760962 | T46: -7068.0224 | U46: -10259.25 | V46: 3191.2273 | W46: -18396.771 | X46: -0.61580093 | Z46: -6846.3357 | AA46: -10127.25 | AB46: 3280.914 | AC46: -18384.835 | AD46: -0.62760962 | AF46: -10324.764 | AI46: -10127.25 | AK46: -18384.835 | AL46: 10127.25 | AM46: ns | AN46: #REF! | AO46: 0.449152 | AP46: #REF!
A48: Trésorerie brute (+) | C48: 41.645075 | D48: 5.945667 | E48: 65.621958 | F48: 75.854166 | G48: 86.6 | H48: 39.357943 | I48: 183.84956 | J48: 98 | K48: 44.505866 | L48: 85 | M48: 856.2675 | N48: 420.52048 | O48: 0 | P48: 420.52048 | Q48: 19.10522 | R48: 21.010764 | T48: 856.2675 | V48: 856.2675 | W48: 37 | X48: 22.142365 | Z48: 420.52048 | AB48: 420.52048 | AC48: 19.10522 | AD48: 21.010764 | AF48: 0 | AI48: 0 | AK48: 19.10522 | AL48: 0 | AM48: ns | AN48: ns | AO48: ns | AP48: ns
A50: Trésorerie nette fin de période | C50: -18444.779 | D50: -18599.889 | E50: -18390.362 | F50: -18487.13 | G50: -18547.576 | H50: -18436.951 | I50: -18419.32 | J50: -18596.004 | K50: -6924.6365 | L50: -6933.5824 | M50: -6211.7549 | N50: -6425.8152 | O50: -10127.25 | P50: 3701.4345 | Q50: -18365.73 | R50: 0.65011926 | T50: -6211.7549 | U50: -10259.25 | V50: 4047.4948 | W50: -18359.771 | X50: 0.6616649 | Z50: -6425.8152 | AA50: -10127.25 | AB50: 3701.4345 | AC50: -18365.73 | AD50: 0.65011926 | AF50: -10324.764 | AI50: -10127.25 | AK50: -18365.73 | AL50: 10127.25 | AM50: ns | AN50: ns | AO50: -0.44857897 | AP50: ns
A52: Trésorerie nette début de période | T52: -18365.7 | W52: -17258.086 | Z52: -18365.7 | AC52: -17258.086 | AK52: -17258.086 | AM52: ns
AA54: -6425.8152

Sheet P&L 
B2: Moov - RCA : P&L | AA2: -0.79344379
O4: MENSUEL | U4: CUMUL (m-1) | AA4: CUMUL | AK4: ANNUEL
D5: Janvier | E5: Février | F5: Mars | G5: Avril | H5: Mai | I5: Juin | J5: Juillet | K5: Août | L5: Septembre | M5: Octobre | N5: Novembre | O5: 2023 | P5: 2023 Budget | Q5: Ecart / Budget | R5: 2022 Réel | S5: Evol % | U5: 2023 | V5: 2023 Budget | W5: Ecart / Budget | X5: 2021 Réel | Y5: Evol % | AA5: 2023 | AB5: 2023 Budget | AC5: Ecart / Budget | AD5: 2022 Réel | AE5: Evol % | AG5: 2017 Actu 1 | AH5: 2017 Actu 2 | AI5: 2023 Actu 1 | AJ5: 2023 Actu 2 | AK5: 2023 Actu3 | AL5: 2023 Budget | AM5: 2019 Actu3 | AN5: 2022 Réel | AO5: Ecart / Budget | AP5: Var Actu1/ Budget (%) | AQ5: Var Actu1/ 2018 (%) | AR5: B23/ 2022 (%) | AS5: Var Actu3/ 2019 (%) | AT5: Var Actu1/ 2017 (%)
B7: Chiffre d'affaires | D7: 308.61504 | E7: 300.96135 | F7: 317.29534 | G7: 317.9 | H7: 345.63525 | I7: 328.565 | J7: 354.14007 | K7: 373.72891 | L7: 365.64251 | M7: 394.72369 | N7: 368.20351 | O7: 374.89057 | P7: 575.53449 | Q7: -200.64392 | R7: 315.53342 | S7: 0.18811686 | U7: 3775.4107 | V7: 4580.7294 | W7: -805.31869 | X7: 3545.3164 | Y7: 0.064900928 | AA7: 4150.3013 | AB7: 5156.2639 | AC7: -1005.9626 | AD7: 3860.8498 | AE7: 0.074970925 | AG7: 4718.995 | AH7: 4718.6895 | AI7: 5156.1148 | AL7: 5156.2639 | AN7: 3860.8498 | AO7: 1295.4141 | AP7: -2.8906658e-05 | AQ7: 0.33548703 | AR7: 0.33552564 | AS7: ns | AT7: 3860.2941
B8: Services | D8: 302.51504 | E8: 296.06135 | F8: 312.39534 | G8: 314.12819 | H8: 336.75726 | I8: 320.67887 | J8: 346.22285 | K8: 365.92891 | L8: 358.24251 | M8: 389.92369 | N8: 363.20351 | O8: 366.38213 | P8: 562.35455 | Q8: -195.97243 | R8: 309.5856 | S8: 0.18345987 | U8: 3706.0575 | V8: 4483.4152 | W8: -777.35771 | X8: 3492.7382 | Y8: 0.061075108 | AA8: 4072.4397 | AB8: 5045.7698 | AC8: -973.33014 | AD8: 3802.3238 | AE8: 0.071039689 | AG8: 4619.8687 | AH8: 4643.7486 | AI8: 5080.443 | AL8: 5045.7698 | AN8: 3802.3238 | AO8: 1243.446 | AP8: 0.0068717386 | AQ8: 0.33614161 | AR8: 0.32702266 | AS8: ns
B9: Equipements | D9: 6.1 | E9: 4.9 | F9: 4.9 | G9: 3.7718106 | H9: 8.8779833 | I9: 7.886132 | J9: 7.917225 | K9: 7.8 | L9: 7.4 | M9: 4.8 | N9: 5 | O9: 8.508442 | P9: 13.179939 | Q9: -4.6714974 | R9: 5.947819 | S9: 0.43051461 | U9: 69.353151 | V9: 97.314132 | W9: -27.960982 | X9: 52.578192 | Y9: 0.31904785 | AA9: 77.861593 | AB9: 110.49407 | AC9: -32.632479 | AD9: 58.526011 | AE9: 0.33037587 | AG9: 99.126234 | AH9: 74.940828 | AI9: 75.671811 | AL9: 110.49407 | AN9: 58.526011 | AO9: 51.968061 | AP9: -0.31515049 | AQ9: 0.29296033 | AR9: 0.88794811 | AS9: ns
AI10: 0 | AL10: 0
B11: Coût des ventes | D11: -56.293099 | E11: -54.923423 | F11: -55.856001 | G11: -58.488376 | H11: -62.998653 | I11: -64.257158 | J11: -68.224515 | K11: -70.58647 | L11: -71.46869 | M11: -82.125007 | N11: -86.50999 | O11: -81.918077 | P11: -96.750103 | Q11: -14.832026 | R11: -71.378209 | S11: 0.14766226 | U11: -731.73138 | V11: -790.36485 | W11: -58.633464 | X11: -697.97246 | Y11: 0.048367122 | AA11: -813.64946 | AB11: -887.11495 | AC11: -73.46549 | AD11: -769.35067 | AE11: 0.057579449 | AG11: -1285.1415 | AH11: -1314.6028 | AI11: -922.94242 | AL11: -887.11495 | AN11: -769.35067 | AO11: -117.76428 | AP11: -0.040386498 | AQ11: 0.19963815 | AR11: -0.1530697 | AS11: ns
B13: Marge Brute | D13: 252.32194 | E13: 246.03792 | F13: 261.43934 | G13: 259.41162 | H13: 282.63659 | I13: 264.30784 | J13: 285.91556 | K13: 303.14244 | L13: 294.17382 | M13: 312.59869 | N13: 281.69352 | O13: 292.97249 | P13: 478.78439 | Q13: -185.8119 | R13: 244.15521 | S13: 0.19994367 | U13: 3043.6793 | V13: 3790.3645 | W13: -746.68523 | X13: 2847.3439 | Y13: 0.068953877 | AA13: 3336.6518 | AB13: 4269.1489 | AC13: -932.49712 | AD13: 3091.4991 | AE13: 0.079298969 | AG13: 3433.8535 | AH13: 3404.0867 | AI13: 4233.1724 | AL13: 4269.1489 | AN13: 3091.4991 | AO13: 1177.6498 | AP13: -0.0084270934 | AQ13: 0.3692944 | AR13: 0.38093164 | AS13: ns
B14: Taux de marge brute (%) | D14: 0.81759444 | E14: 0.81750672 | F14: 0.82396212 | G14: 0.81601643 | H14: 0.81773082 | I14: 0.80443091 | J14: 0.80735161 | K14: 0.81112922 | L14: 0.80453944 | M14: 0.79194305 | N14: 0.76504844 | O14: 0.78148803 | P14: 0.83189521 | Q14: -5.0407184 | R14: 0.77378558 | S14: 0.77024524 | U14: 0.80618496 | V14: 0.82745873 | W14: -2.1273776 | X14: 0.8031283 | Y14: 0.30566585 | AA14: 0.80395412 | AB14: 0.82795393 | AC14: -2.3999807 | AD14: 0.80073022 | AE14: 0.3223897 | AG14: 0.72766628 | AH14: 0.72140511 | AI14: 0.82100041 | AL14: 0.82795393 | AN14: 0.80073022 | AO14: 2.7223704 | AP14: -0.69535127 | AQ14: 2.0270191 | AR14: 2.7223704 | AS14: -80.073022
B15: Coûts opérationnels | D15: -287.71886 | E15: -248.08204 | F15: -311.60066 | G15: -311.83251 | H15: -334.98143 | I15: -311.15526 | J15: -286.45676 | K15: -291.3933 | L15: -283.96736 | M15: -102.59179 | N15: -255.06108 | O15: -268.18971 | P15: -290.03839 | Q15: -21.848679 | R15: -293.65091 | S15: -0.086705682 | U15: -3024.8411 | V15: -3194.3403 | W15: -169.49929 | X15: -2960.8785 | Y15: 0.021602554 | AA15: -3293.0308 | AB15: -3484.3787 | AC15: -191.34797 | AD15: -3254.5294 | AE15: 0.011830078 | AG15: -3384.769 | AH15: -3358.6879 | AI15: -3339.0882 | AL15: -3484.3787 | AN15: -3254.5294 | AO15: -229.84931 | AP15: 0.041697687 | AQ15: 0.025981874 | AR15: -0.070624437 | AS15: ns
B17: EBITDA | D17: -35.396924 | E17: -2.0441189 | F17: -50.161313 | G17: -52.420881 | H17: -52.344836 | I17: -46.847419 | J17: -0.54119978 | K17: 11.749142 | L17: 10.20646 | M17: 210.00689 | N17: 26.632439 | O17: 24.782787 | P17: 188.746 | Q17: -163.96322 | R17: -49.495703 | S17: ns | U17: 18.838241 | V17: 596.02418 | W17: -577.18593 | X17: -113.53462 | Y17: ns | AA17: 43.621029 | AB17: 784.77018 | AC17: -741.14915 | AD17: -163.03033 | AE17: ns | AG17: 49.084496 | AH17: 45.39884 | AI17: 894.0842 | AL17: 784.77018 | AN17: -163.03033 | AO17: 947.80051 | AP17: 0.13929431 | AQ17: ns | AR17: ns | AS17: ns
B18: Marge d'Ebitda (%) | D18: -0.11469604 | E18: -0.0033533433 | F18: -0.054118937 | G18: -0.042112847 | H18: -0.032912856 | I18: -0.024412769 | J18: -0.0002380876 | K18: 0.00443893 | L18: 0.0033880551 | M18: 0.06163608 | N18: 0.0070541832 | O18: 0.0059713225 | P18: 0.32794907 | Q18: -32.197775 | R18: -0.012819899 | U18: 0.0049897198 | V18: 0.13011556 | W18: -12.512584 | X18: -0.032023834 | Y18: 3.7013554 | AA18: 0.010510328 | AB18: 0.15219744 | AC18: -14.168712 | AD18: -0.04222654 | AE18: 5.2736868 | AG18: 0.010401472 | AH18: 0.0096210696 | AI18: 0.17340269 | AL18: 0.15219744 | AN18: -0.04222654 | AO18: 19.442398 | AP18: 2.120525 | AQ18: 21.562923 | AR18: 19.442398 | AS18: 4.222654
B19: Amortissements et déprec. Courant | D19: -186 | E19: -190.20877 | F19: -190.25877 | G19: 16.602385 | H19: -138.8621 | I19: -140.47944 | J19: -139.10884 | K19: -139.36394 | L19: -140.70207 | M19: -139.74902 | N19: -139.74902 | O19: -142.79902 | P19: -206.89399 | Q19: -64.094973 | R19: -166.20717 | S19: -0.14083719 | U19: -1527.8796 | V19: -2195.9768 | W19: -668.09719 | X19: -2088.4551 | Y19: -0.26841637 | AA19: -1670.6786 | AB19: -2402.8707 | AC19: -732.19216 | AD19: -2254.6623 | AE19: -0.2590116 | AG19: -744.46314 | AH19: -739.62521 | AI19: -2011.0651 | AL19: -2402.8707 | AN19: -2254.6623 | AO19: -148.20849 | AP19: 0.16305729 | AQ19: -0.10804151 | AR19: -0.065734231 | AS19: ns
B20: Dotations (amo. et provisions non courants) | Q20: 0 | S20: ns | U20: 0 | W20: 0 | X20: 0 | Y20: ns | AA20: 0 | AC20: 0 | AD20: 0 | AE20: ns | AN20: 0 | AO20: 0 | AP20: ns | AQ20: ns | AR20: ns | AS20: ns
B21: Autres non courant | D21: 0 | E21: 0 | F21: 0 | G21: 0 | H21: 0 | I21: 0 | J21: 0 | K21: 0 | L21: 0 | M21: 0 | N21: 0 | O21: -15.688708 | Q21: 15.688708 | S21: ns | U21: 0 | W21: 0 | X21: -61.1 | Y21: ns | AA21: -15.688708 | AC21: 15.688708 | AD21: -61.1 | AE21: 0.743229 | AI21: 0 | AL21: 0 | AN21: -61.1 | AO21: 61.1 | AP21: ns | AQ21: ns | AR21: ns | AS21: ns
B22: +/- value de cession d'immobilisations | Q22: 0 | S22: ns | U22: 0 | W22: 0 | X22: 0 | Y22: ns | AA22: 0 | AC22: 0 | AD22: 0 | AE22: ns | AN22: 0 | AO22: 0 | AR22: ns | AS22: ns
B23: PIDR | D23: 0 | E23: 0 | F23: -0.208 | G23: -0.208 | H23: -0.208 | I23: 0.23 | J23: 0.23 | K23: 0.23 | L23: -0.69 | M23: 0.23 | N23: -0.366 | O23: 16.86 | P23: -0.1 | Q23: -16.96 | R23: 3.4 | S23: 3.9588235 | U23: -0.76 | V23: 0 | W23: 0.76 | X23: -0.38 | Y23: 1 | AA23: 16.1 | AB23: 0 | AC23: -16.1 | AD23: 3.02 | AE23: 4.3311258 | AI23: -0.97066667 | AL23: -0.4 | AN23: 3.02 | AO23: -3.42 | AR23: ns | AS23: ns
B25: EBITA | D25: -221.39692 | E25: -192.25288 | F25: -240.62808 | G25: -36.026496 | H25: -191.41493 | I25: -187.09686 | J25: -139.42004 | K25: -127.3848 | L25: -131.18561 | M25: 70.487875 | N25: -113.48258 | O25: -116.84494 | P25: -18.247985 | Q25: -98.596952 | R25: -212.30287 | S25: 0.44963091 | U25: -1509.8013 | V25: -1600.2526 | W25: 90.451257 | X25: -2263.4697 | Y25: 0.33297039 | AA25: -1626.6463 | AB25: -1618.5006 | AC25: -8.1456951 | AD25: -2475.7726 | AE25: 0.34297428 | AG25: -695.37864 | AH25: -694.22637 | AI25: -1117.9516 | AL25: -1618.5006 | AN25: -2475.7726 | AO25: 857.27202 | AP25: 0.30926708 | AQ25: -0.54844333 | AR25: 0.34626444 | AS25: ns
