Workbook

Sheet Cover
E13: Tableau de Bord de Gestion
E15: Octobre 2025

Sheet RH QS
A2: Effectif et Sites BTS | D2: RH & QS
D4: 45658 | E4: 45689 | F4: 45717 | G4: 45748 | H4: 45778 | I4: 45809 | J4: 45839 | K4: 45870 | L4: 45901 | M4: 45931 | N4: 45962 | O4: 45992
B6: Effectif fin de période | D6: =+SUM(D7:D8) -> 116 | E6: =+SUM(E7:E8) -> 118 | F6: =+SUM(F7:F8) -> 118 | G6: =+SUM(G7:G8) -> 118 | H6: =+SUM(H7:H8) -> 118 | I6: =+SUM(I7:I8) -> 118 | J6: =+SUM(J7:J8) -> 118 | K6: =+SUM(K7:K8) -> 118 | ... O6: =+SUM(O7:O8) -> 118
B7: Variation (+/-) | D7: 1 | E7: 2 | F7: 0 | G7: 0 | H7: 0 | I7: 0 | J7: 0 | K7: 0 | L7: 0 | M7: 0 | N7: 0 | O7: 0
B8: Effectif début de période | D8: 115 | E8: =+D6 -> 116 | F8: =+E6 -> 118 | G8: =+F6 -> 118 | H8: =+G6 -> 118 | I8: =+H6 -> 118 | J8: =+I6 -> 118 | K8: =+J6 -> 118 | L8: =+K6 -> 118 | ... O8: =+N6 -> 118
B10: Nombre de BTS Total | D10: =+SUM(D11,D14) -> 1062 | E10: =+SUM(E11,E14) -> 1068 | F10: =+SUM(F11,F14) -> 1089 | G10: =+SUM(G11,G14) -> 1119 | H10: =+SUM(H11,H14) -> 1139 | I10: =+SUM(I11,I14) -> 1139 | J10: =+SUM(J11,J14) -> 1139 | K10: =+SUM(K11,K14) -> 1139 | ... O10: =+SUM(O11,O14) -> 1139
B11: Nbre fin de période 2G | D11: =+SUM(D12:D13) -> 678 | E11: =+SUM(E12:E13) -> 679 | F11: =+SUM(F12:F13) -> 690 | G11: =+SUM(G12:G13) -> 705 | H11: =+SUM(H12:H13) -> 715 | I11: =+SUM(I12:I13) -> 715 | J11: =+SUM(J12:J13) -> 715 | K11: =+SUM(K12:K13) -> 715 | ... O11: =+SUM(O12:O13) -> 715
B12: Variation (+/-) | D12: 2 | E12: 1 | F12: 11 | G12: 15 | H12: 10 | I12: 0 | J12: 0 | K12: 0 | L12: 0 | M12: 0 | N12: 0 | O12: 0
B13: Nbre début de période 2G | D13: 676 | E13: =+D11 -> 678 | F13: =+E11 -> 679 | G13: =+F11 -> 690 | H13: =+G11 -> 705 | I13: =+H11 -> 715 | J13: =+I11 -> 715 | K13: =+J11 -> 715 | L13: =+K11 -> 715 | ... O13: =+N11 -> 715
B14: Nbre fin de période 3G/4G | D14: =+SUM(D15:D16) -> 384 | E14: =+SUM(E15:E16) -> 389 | F14: =+SUM(F15:F16) -> 399 | G14: =+SUM(G15:G16) -> 414 | H14: =+SUM(H15:H16) -> 424 | I14: =+SUM(I15:I16) -> 424 | J14: =+SUM(J15:J16) -> 424 | K14: =+SUM(K15:K16) -> 424 | ... O14: =+SUM(O15:O16) -> 424
B15: Variation (+/-) | D15: 6 | E15: 5 | F15: 10 | G15: 15 | H15: 10 | I15: 0 | J15: 0 | K15: 0 | L15: 0 | M15: 0 | N15: 0 | O15: 0
B16: Nbre début de période 3G/4G | D16: 378 | E16: =+D14 -> 384 | F16: =+E14 -> 389 | G16: =+F14 -> 399 | H16: =+G14 -> 414 | I16: =+H14 -> 424 | J16: =+I14 -> 424 | K16: =+J14 -> 424 | L16: =+K14 -> 424 | ... O16: =+N14 -> 424
B18: Nombre de sites Total
B19: Nbre fin de période 2G/3G/4G | D19: =+SUM(D20:D21) -> 504 | E19: =+SUM(E20:E21) -> 506 | F19: =+SUM(F20:F21) -> 512 | G19: =+SUM(G20:G21) -> 527 | H19: =+SUM(H20:H21) -> 537 | I19: =+SUM(I20:I21) -> 537 | J19: =+SUM(J20:J21) -> 537 | K19: =+SUM(K20:K21) -> 537 | ... O19: =+SUM(O20:O21) -> 537
B20: Variation (+/-) | D20: 1 | E20: 2 | F20: 6 | G20: 15 | H20: 10 | I20: 0 | J20: 0 | K20: 0 | L20: 0 | M20: 0 | N20: 0 | O20: 0
B21: Nbre début de période 2G/3G/4G | D21: 503 | E21: =+D19 -> 504 | F21: =+E19 -> 506 | G21: =+F19 -> 512 | H21: =+G19 -> 527 | I21: =+H19 -> 537 | J21: =+I19 -> 537 | K21: =+J19 -> 537 | L21: =+K19 -> 537 | ... O21: =+N19 -> 537

Sheet Parc 
D2: 0.61715886 | J2: 0.61586377 | P2: 0.5927915 | V2: 0.59067085 | BJ2: 0.55666499
B4: Parc d'abonnés | D4: JANVIER | J4: FEVRIER | P4: MARS | V4: AVRIL | AD4: MAI | AL4: JUIN | AT4: JUILLET | BB4: AOUT | BJ4: SEPTEMBRE | BR4: OCTOBRE | BZ4: NOVEMBRE | CH4: DECEMBRE | CP4: CUMUL | CX4: ANNUEL
D5: 2025 Réel | E5: 2025 Budget | F5: Ecart / Budget | G5: 2024 Réel | H5: Evol % | J5: 2025 Réel | K5: 2025 Budget | L5: Ecart / Budget | M5: 2024 Réel | N5: Evol % | P5: 2025 Réel | Q5: 2025 Budget | R5: Ecart / Budget | S5: 2024 Réel | T5: Evol % | V5: 2025 Réel | W5: 2025 Budget | X5: 2025 Actu 1 | Y5: Ecart / Budget | Z5: Ecart / Actu 1 | AA5: 2024 Réel | AB5: Evol % | AD5: 2025 Réel | AE5: 2025 Budget | AF5: 2025 Actu 1 | AG5: Ecart / Budget | AH5: Ecart / Actu 1 | AI5: 2024 Réel | AJ5: Evol % | AL5: 2025 Réel | AM5: 2025 Budget | AN5: 2025 Actu 1 | AO5: Ecart / Budget | AP5: Ecart / Actu 1 | AQ5: 2024 Réel | AR5: Evol % | AT5: 2025 Réel | AU5: 2025 Budget | AV5: 2025 Actu 2 | AW5: Ecart / Budget | AX5: Ecart / Actu 2 | AY5: 2024 Réel | AZ5: Evol % | BB5: 2025 Réel | BC5: 2025 Budget | BD5: 2025 Actu3 | BE5: Ecart / Budget | BF5: Ecart / Actu 3 | BG5: 2024 Réel | BH5: Evol % | BJ5: 2025 Réel | BK5: 2025 Budget | BL5: 2025 Actu3 | BM5: Ecart / Budget | BN5: Ecart / Actu 3 | BO5: 2024 Réel | BP5: Evol % | BR5: 2025 Réel | BS5: 2025 Budget | BT5: 2025 Actu 3 | BU5: Ecart / Budget | BV5: Ecart / Actu 3 | BW5: 2024 Réel | BX5: Evol % | BZ5: 2025 Réel | CA5: 2025 Budget | CB5: 2025 Actu 3 | CC5: Ecart / Budget | CD5: Ecart / Actu 3 | CE5: 2024 Réel | CF5: Evol % | CH5: 2025 Réel | CI5: 2025 Budget | CJ5: 2025 Actu 3 | CK5: Ecart / Budget | CL5: Ecart / Actu 3 | CM5: 2024 Réel | CN5: Evol % | CP5: 2025 Réel | CQ5: 2025 Budget | CR5: 2025 Actu 3 | CS5: Ecart / Budget | CT5: Ecart / Actu 3 | CU5: 2024 Réel | CV5: Evol % | CX5: 2025 Budget | CY5: 2024 Actu 1 | CZ5: 2024 Actu 2 | DA5: 2025 Actu 3 | DB5: 2024 Réel | DC5: Bud / 2024 (%) | DD5: Actu 1 / 2023 (%) | DE5: Actu 2 / 2023 (%) | DF5: Actu 3 / 2019 (%)
B7: Parc Total Mobile Actif | D7: 256415.34 | E7: 257215.34 | F7: -800 | G7: 261327.34 | H7: -0.018796349 | J7: 257227.34 | K7: 259498.34 | L7: -2271 | M7: 263850.34 | N7: -0.025101351 | P7: 257252.34 | Q7: 273811.34 | R7: -16559 | S7: 267523.34 | T7: -0.038392912 | V7: 258416.34 | W7: 295411.34 | X7: 260852.34 | Y7: -36995 | Z7: -2436 | AA7: 271367.34 | AB7: -0.047724977 | AD7: 268420.34 | AE7: 320661.34 | AF7: 277602.34 | AG7: -52241 | AH7: -9182 | AI7: 272718.34 | AJ7: -0.01575985 | AL7: 280436.34 | AM7: 347666.34 | AN7: 301107.34 | AO7: -67230 | AP7: -20671 | AQ7: 274567.34 | AR7: 0.021375448 | AT7: 292361.34 | AU7: 372681.34 | AV7: 302440.34 | AW7: -80320 | AX7: -10079 | AY7: 276485.34 | AZ7: 0.057420766 | BB7: 304463.34 | BC7: 388881.34 | BD7: 359445.34 | BE7: -84418 | BF7: -54982 | BG7: 276903.34 | BH7: 0.099529316 | BJ7: 308997.34 | BK7: 404381.34 | BL7: 319963.34 | BM7: -95384 | BN7: -10966 | BO7: 276903.34 | BP7: 0.11590326 | BR7: 312650.34 | BS7: 422881.34 | BT7: 331265.34 | BU7: -110231 | BV7: -18615 | BW7: 274494.34 | BX7: 0.13900469 | BZ7: 312650.34 | CA7: 422881.34 | CB7: 312650.34 | CC7: -110231 | CD7: 0 | CE7: 274494.34 | CF7: 0.13900469 | CH7: 312650.34 | CI7: 422881.34 | CJ7: 312650.34 | CK7: -110231 | CL7: 0 | CM7: 274494.34 | CN7: 0.13900469 | CP7: 312650.34 | CQ7: 422881.34 | CR7: 331265.34 | CS7: -110231 | CT7: -18615 | CU7: 267523.34 | CV7: 0.16868435 | CX7: 460481.34 | CY7: 0 | CZ7: 0 | DA7: 370122 | DB7: 256234.34 | DC7: 0.79711018 | DD7: -1 | DE7: -1 | DF7: 0.44446681
B8: Activations totales | D8: 23283 | E8: 21745 | F8: 1538 | G8: 26228 | H8: -0.11228458 | J8: 22183 | K8: 22915 | L8: -732 | M8: 17015 | N8: 0.303732 | P8: 20785 | Q8: 34405 | R8: -13620 | S8: 19800 | T8: 0.049747475 | V8: 29250 | W8: 42452 | X8: 24452 | Y8: -13202 | Z8: 4798 | AA8: 18148 | AB8: 0.61174785 | AD8: 34803 | AE8: 47713 | AF8: 37713 | AG8: -12910 | AH8: -2910 | AI8: 16425 | AJ8: 1.1189041 | AL8: 31208 | AM8: 47900 | AN8: 42900 | AO8: -16692 | AP8: -11692 | AQ8: 17800 | AR8: 0.75325843 | AT8: 32758 | AU8: 45905 | AV8: 42894 | AW8: -13147 | AX8: -10136 | AY8: 25021 | AZ8: 0.30922025 | BB8: 31311 | BC8: 38237 | BD8: 33309 | BE8: -6926 | BF8: -1998 | BG8: 26384 | BH8: 0.18674196 | BJ8: 28120 | BK8: 38358 | BL8: 36358 | BM8: -10238 | BN8: -8238 | BO8: 26384 | BP8: 0.065797453 | BR8: 28253 | BS8: 40356 | BT8: 30722 | BU8: -12103 | BV8: -2469 | BW8: 16113 | BX8: 0.75342891 | BZ8: 0 | CA8: 0 | CB8: 0 | CC8: 0 | CD8: 0 | CE8: 0 | CH8: 0 | CI8: 0 | CJ8: 0 | CK8: 0 | CL8: 0 | CM8: 0 | CP8: 281954 | CQ8: 380118 | CR8: 305147 | CS8: -98164 | CT8: -23193 | CU8: 209318 | CV8: 0.34701268 | CX8: 462966 | CY8: 0 | CZ8: 0 | DA8: 362587 | DB8: 250537 | DC8: 0.84789472 | DD8: -1 | DE8: -1 | DF8: 0.44723933
B9: Flux d'inactivité | D9: -22571 | E9: -20634 | F9: -1937 | G9: -17576 | H9: 0.28419436 | J9: -21680 | K9: -20500 | L9: -1180 | M9: -14300 | N9: 0.51608392 | P9: -20744 | Q9: -19960 | R9: -784 | S9: -15877 | T9: 0.30654406 | V9: -28074 | W9: -20716 | X9: -20716 | Y9: -7358 | Z9: -7358 | AA9: -14212 | AB9: 0.97537292 | AD9: -24785 | AE9: -22329 | AF9: -20829 | AG9: -2456 | AH9: -3956 | AI9: -14856 | AJ9: 0.66834949 | AL9: -19174 | AM9: -20759 | AN9: -19259 | AO9: 1585 | AP9: 85 | AQ9: -15783 | AR9: 0.21485142 | AT9: -20813 | AU9: -20756 | AV9: -20756 | AW9: -57 | AX9: -57 | AY9: -22929 | AZ9: -0.092284879 | BB9: -19187 | BC9: -22033 | BD9: 20853 | BE9: 2846 | BF9: -40040 | BG9: -25830 | BH9: ns | BJ9: -23566 | BK9: -22720 | BL9: -20720 | BM9: -846 | BN9: -2846 | BO9: -25830 | BP9: -0.087650019 | BR9: -24578 | BS9: -21720 | BT9: -19220 | BU9: -2858 | BV9: -5358 | BW9: -18400 | BX9: 0.33576087 | BZ9: 0 | CA9: 0 | CB9: 0 | CC9: 0 | CD9: 0 | CE9: 0 | CH9: 0 | CI9: 0 | CJ9: 0 | CK9: 0 | CL9: 0 | CM9: 0 | CP9: -225172 | CQ9: -212127 | CR9: -165642 | CS9: -13045 | CT9: -59530 | CU9: -185593 | CV9: 0.21325697 | CX9: -258719 | CY9: 0 | CZ9: 0 | DA9: -247711 | DB9: -247166 | DC9: 0.046741866 | DD9: -1 | DE9: -1 | DF9: 0.0022049958
B10: Acroissement net | D10: 508 | E10: 981 | F10: -473 | G10: 8464 | H10: -0.9399811 | J10: 485 | K10: 2283 | L10: -1798 | M10: 2523 | N10: -0.80776853 | P10: 25 | Q10: 14313 | R10: -14288 | S10: 3673 | T10: -0.99319357 | V10: 1164 | W10: 21600 | X10: 3600 | Y10: -20436 | Z10: -2436 | AA10: 3844 | AB10: -0.69719043 | AD10: 10004 | AE10: 25250 | AF10: 16750 | AG10: -15246 | AH10: -6746 | AI10: 1351 | AJ10: 6.4048853 | AL10: 12016 | AM10: 27005 | AN10: 23505 | AO10: -14989 | AP10: -11489 | AQ10: 1849 | AR10: 5.4986479 | AT10: 11925 | AU10: 25015 | AV10: 22004 | AW10: -13090 | AX10: -10079 | AY10: 1918 | AZ10: 5.217414 | BB10: 12102 | BC10: 16068 | BD10: 54146 | BE10: -3966 | BF10: -42044 | BG10: 418 | BH10: 27.952153 | BJ10: 4534 | BK10: 15500 | BL10: 15500 | BM10: -10966 | BN10: -10966 | BO10: 418 | BP10: 9.84689 | BR10: 3653 | BS10: 18500 | BT10: 11366 | BU10: -14847 | BV10: -7713 | BW10: -2409 | BX10: -2.5163968 | BZ10: 0 | CA10: 0 | CB10: 0 | CC10: 0 | CD10: 0 | CE10: 0 | CH10: 0 | CI10: 0 | CJ10: 0 | CK10: 0 | CL10: 0 | CM10: 0 | CP10: 56416 | CQ10: 166647 | CR10: 138437 | CS10: -110231 | CT10: -82021 | CU10: 22049 | CV10: 1.5586648 | CX10: 204247 | CY10: 0 | CZ10: 0 | DA10: 113888 | DB10: 3371 | DC10: 59.589439 | DD10: -1 | DE10: -1 | DF10: 32.784634
B11: % churn annualisé | D11: -1.0560012 | E11: -0.96448789 | F11: -0.091513327 | G11: -0.068357009 | H11: -98.764421 | J11: -1.0123554 | K11: -0.95217142 | L11: -0.060184014 | M11: -0.65349312 | N11: 0.54914475 | P11: -0.96768836 | Q11: -0.89823984 | R11: -0.069448527 | S11: -0.71709988 | T11: 0.34944712 | V11: -1.3066064 | W11: -0.87344376 | X11: -0.95962075 | Y11: -0.43316264 | Z11: -0.34698566 | AA11: -0.052745392 | AB11: 23.771954 | AD11: -1.1290786 | AE11: -0.78854554 | AF11: -0.93679325 | AG11: -0.34053302 | AH11: -0.19228531 | AI11: -0.65530855 | AJ11: 0.72297241 | AL11: -0.83842653 | AM11: -0.74546665 | AN11: -0.798701 | AO11: -0.092959872 | AP11: -0.039725527 | AQ11: -0.69212847 | AR11: 0.21137414 | AT11: -0.8720566 | AU11: -0.69153273 | AV11: -0.85463018 | AW11: -0.18052387 | AX11: -0.017426428 | AY11: -0.99862685 | AZ11: -0.12674428 | BB11: -0.77156327 | BC11: -0.69447162 | BD11: 0.75287853 | BE11: -0.077091644 | BF11: -1.5244418 | BG11: -1.1202253 | BH11: -0.31124278 | BJ11: -0.9219564 | BK11: -0.68738895 | BL11: -0.79637853 | BM11: -0.23456745 | BN11: -0.12557787 | BO11: -1.1202253 | BP11: -0.1769902 | BR11: -0.94888474 | BS11: -0.63012633 | BT11: -0.70839223 | BU11: -0.31875841 | BV11: -0.24049251 | BW11: -0.80087388 | BX11: 0.1848117 | BZ11: 0 | CA11: 0 | CB11: 0 | CC11: 0 | CD11: 0 | CE11: 0 | CH11: 0 | CI11: 0 | CJ11: 0 | CK11: 0 | CL11: 0 | CM11: 0 | CP11: -8.6932328 | CQ11: -7.4965844 | CR11: -0.63175638 | CS11: -1.1966484 | CT11: -8.0614764 | CU11: -0.69854043 | CV11: -799.46924 | CX11: -0.72195714 | CY11: #DIV/0! | CZ11: #DIV/0! | DA11: -0.79095914 | DB11: -2.8400599 | DC11: 211.81027 | DF11: -0.72149913
B12: Parc Actif Moyen | D12: 256488.34 | E12: 256724.84 | F12: -236.5 | G12: 257120.67 | H12: -0.0024592733 | J12: 256984.84 | K12: 258356.84 | L12: -1372 | M12: 262588.84 | N12: -0.021341349 | P12: 257239.84 | Q12: 266654.84 | R12: -9415 | S12: 265686.84 | T12: -0.031793069 | V12: 257834.34 | W12: 284611.34 | X12: 259052.34 | Y12: -26777 | Z12: -1218 | AA12: 269445.34 | AB12: -0.043092228 | AD12: 263418.34 | AE12: 305498.84 | AF12: 266812.34 | AG12: -42080.5 | AH12: -3394 | AI12: 272042.84 | AJ12: -0.031702727 | AL12: 274428.34 | AM12: 334163.84 | AN12: 289354.84 | AO12: -59735.5 | AP12: -14926.5 | AQ12: 273642.84 | AR12: 0.0028705301 | AT12: 286398.84 | AU12: 360173.84 | AV12: 291438.34 | AW12: -73775 | AX12: -5039.5 | AY12: 275526.34 | AZ12: 0.039460837 | BB12: 298412.34 | BC12: 380715.34 | BD12: 332372.34 | BE12: -82303 | BF12: -33960 | BG12: 276694.34 | BH12: 0.078490944 | BJ12: 306730.34 | BK12: 396631.34 | BL12: 312213.34 | BM12: -89901 | BN12: -5483 | BO12: 276694.34 | BP12: 0.108553 | BR12: 310823.84 | BS12: 413631.34 | BT12: 325582.34 | BU12: -102807.5 | BV12: -14758.5 | BW12: 275698.84 | BX12: 0.12740351 | BZ12: 312650.34 | CA12: 422881.34 | CB12: 312650.34 | CC12: -110231 | CD12: 0 | CE12: 274494.34 | CF12: 0.13900469 | CH12: 312650.34 | CI12: 422881.34 | CJ12: 312650.34 | CK12: -110231 | CL12: 0 | CM12: 274494.34 | CN12: 0.13900469 | CP12: 310823.84 | CQ12: 339557.84 | CR12: 262192.84 | CS12: -28734 | CT12: 48631 | CU12: 265686.84 | CV12: 0.16988798 | CX12: 358357.84 | CY12: 0 | CZ12: 0 | DA12: 313178 | DB12: 261085.34 | DC12: 0.37256975 | DD12: -1 | DE12: -1 | DF12: 0.1995235
B13: Parc actif localisé | D13: 203255.33 | E13: 203200.12 | F13: 55.214733 | G13: 208760 | H13: -0.026368398 | J13: 202795.33 | K13: 205003.69 | L13: -2208.3553 | M13: 216277 | N13: -0.062335184 | P13: 203570 | Q13: 216310.96 | R13: -12740.959 | S13: 212639.67 | T13: -0.042652751 | V13: 206275 | W13: 233374.96 | X13: 206073.35 | Y13: -27099.959 | Z13: 201.6514 | AA13: 207498 | AB13: -0.0058940327 | AD13: #REF! | AE13: 256529.07 | AF13: 222081.87 | AG13: #REF! | AH13: #REF! | AI13: 210486 | AL13: 219174.67 | AM13: 278133.07 | AN13: 240885.87 | AO13: -58958.405 | AP13: -21711.205 | AQ13: 212214.67 | AR13: 0.032796979 | AT13: 226835 | AU13: 298145.07 | AV13: 241952.27 | AW13: -71310.072 | AX13: -15117.272 | AY13: 218811 | AZ13: 0.036670917 | BB13: 237409 | BC13: 311105.07 | BD13: 243863.47 | BE13: -73696.072 | BF13: -6454.472 | BG13: 218442 | BH13: 0.08682854 | BJ13: 182933 | BK13: 323505.07 | BL13: 263970.67 | BM13: -140572.07 | BN13: -81037.672 | BO13: 218442 | BP13: -0.16255574 | BR13: 245567 | BS13: 338305.07 | BT13: 265063.47 | BU13: -92738.072 | BV13: -19496.472 | BW13: 215600.67 | BX13: 0.13898998 | BZ13: 0 | CA13: 0 | CB13: 0 | CC13: 0 | CD13: 0 | CE13: 0 | CH13: 0 | CI13: 0 | CJ13: 0 | CK13: 0 | CL13: 0 | CM13: 0 | CP13: 245567 | CQ13: 203200.12 | CR13: 265063.47 | CS13: 42366.881 | CT13: -19496.472 | CU13: 212639.67 | CV13: 0.15485038 | CX13: 368385.07 | CY13: 0 | CZ13: 0 | DA13: 296097.87 | DB13: 208204.3 | DC13: 0.76934425 | DD13: -1 | DE13: -1 | DF13: 0.42215064
B14: Parc internet | D14: 158249 | E14: 160927.47 | F14: -2678.471 | G14: 164229 | H14: -0.03641257 | J14: 158417 | K14: 163618.89 | L14: -5201.8933 | M14: 163886 | N14: -0.033370758 | P14: 152497 | Q14: 172665.43 | R14: -20168.431 | S14: 167668 | T14: -0.090482382 | V14: 152639 | W14: 186404.56 | X14: 164597.83 | Y14: -33765.556 | Z14: -11958.827 | AA14: 180500 | AB14: -0.15435457 | AD14: 156325 | AE14: 205223.26 | AF14: 177665.5 | AG14: -48898.258 | AH14: -21340.498 | AI14: 181750 | AJ14: -0.13988996 | AL14: 160210 | AM14: 224244.79 | AN14: 194214.23 | AO14: -64034.789 | AP14: -34004.234 | AQ14: 182575 | AR14: -0.1224976 | AT14: 168220.5 | AU14: 242242.87 | AV14: 196586.22 | AW14: -74022.371 | AX14: -28365.721 | AY14: 183318 | AZ14: -0.082356888 | BB14: 171743 | BC14: 254717.28 | BD14: 199663.22 | BE14: -82974.278 | BF14: -27920.218 | BG14: 184218 | BH14: -0.067718681 | BJ14: 172008 | BK14: 264869.78 | BL14: 216125.99 | BM14: -92861.778 | BN14: -44117.988 | BO14: 184218 | BP14: -0.066280168 | BR14: 175621 | BS14: 277410.16 | BT14: 217352.05 | BU14: -101789.16 | BV14: -41731.047 | BW14: 184698 | BX14: -0.049145091 | BZ14: 0 | CA14: 0 | CB14: 0 | CC14: 0 | CD14: 0 | CE14: 0 | CH14: 0 | CI14: 0 | CJ14: 0 | CK14: 0 | CL14: 0 | CM14: 0 | CP14: 175621 | CQ14: 160927.47 | CR14: 217352.05 | CS14: 14693.529 | CT14: -41731.047 | CU14: 163886 | CV14: 0.071604652 | CX14: 307141.05 | CY14: 0 | CZ14: 0 | DA14: 191500 | DB14: 155803 | DC14: 0.97134236 | DD14: -1 | DE14: -1 | DF14: 0.22911626
B15: Parc actif Mobile Money | D15: 0 | E15: 0 | F15: 0 | G15: 0 | J15: 0 | K15: 0 | L15: 0 | M15: 0 | P15: 0 | Q15: 0 | R15: 0 | S15: 0 | V15: 0 | W15: 0 | X15: 0 | Y15: 0 | Z15: 0 | AA15: 0 | AD15: 0 | AE15: 0 | AF15: 0 | AG15: 0 | AH15: 0 | AI15: 0 | AL15: 0 | AM15: 0 | AN15: 0 | AO15: 0 | AP15: 0 | AQ15: 0 | AT15: 0 | AU15: 0 | AV15: 0 | AW15: 0 | AX15: 0 | AY15: 0 | BB15: 0 | BC15: 0 | BE15: 0 | BF15: 0 | BG15: 0 | BJ15: 0 | BK15: 0 | BL15: 0 | BM15: 0 | BN15: 0 | BO15: 0 | BR15: 0 | BS15: 0 | BT15: 0 | BU15: 0 | BV15: 0 | BW15: 0 | BZ15: 0 | CA15: 0 | CB15: 0 | CC15: 0 | CD15: 0 | CE15: 0 | CH15: 0 | CI15: 0 | CJ15: 0 | CK15: 0 | CL15: 0 | CM15: 0 | CP15: 0 | CQ15: 0 | CR15: 0 | CS15: 0 | CT15: 0 | CU15: 0 | CY15: 0 | CZ15: 0 | DA15: 413541.86 | DB15: 0 | DD15: #DIV/0! | DE15: #DIV/0! | DF15: #DIV/0!
B17: Parc Prépayé Actif | Z17: 0 | AH17: 0 | AP17: 0 | AX17: 0 | BF17: 0 | BN17: 0 | BV17: 0 | CD17: 0 | CL17: 0
B18: Parc prépayé actif début Période | D18: 251459.34 | E18: 251459.34 | F18: 0 | G18: 248517 | H18: 0.011839592 | J18: 251962.34 | K18: 252355.34 | L18: -393 | M18: 256879.34 | N18: 0.20064566 | P18: 252451.34 | Q18: 254552.34 | R18: -2101 | S18: 259366.34 | T18: -0.026661131 | V18: 252479.34 | W18: 268793.34 | X18: 252479.34 | Y18: -16314 | Z18: 0 | AA18: 263022.34 | AB18: -0.040084048 | AD18: 253641.34 | AE18: 290336.34 | AF18: 256022.34 | AG18: -36695 | AH18: -2381 | AI18: 266722.34 | AJ18: -0.049043511 | AL18: 263643.34 | AM18: 315516.34 | AN18: 272702.34 | AO18: -51873 | AP18: -9059 | AQ18: 268007.34 | AR18: -0.016283136 | AT18: 275657.34 | AU18: 342471.34 | AV18: 275657.34 | AW18: -66814 | AX18: 0 | AY18: 269842.34 | AZ18: 0.02154962 | BB18: 287579.34 | BC18: 367425.34 | BD18: 300043.34 | BE18: -79846 | BF18: -12464 | BG18: 271744.34 | BH18: 0.058271683 | BJ18: 299678.34 | BK18: 383561.34 | BL18: 299678.34 | BM18: -83883 | BN18: 0 | BO18: 271744.34 | BP18: 0.10279515 | BR18: 304210.34 | BS18: 398995.34 | BT18: 315112.34 | BU18: -94785 | BV18: -10902 | BW18: 272153.34 | BX18: 0.11779021 | BZ18: 307861.34 | CA18: 417424.34 | CB18: 307861.34 | CC18: -109563 | CD18: 0 | CE18: 269737.34 | CF18: 0.1413375 | CH18: 307861.34 | CI18: 417424.34 | CJ18: 307861.34 | CK18: -109563 | CL18: 0 | CM18: 269737.34 | CN18: 0.1413375 | CP18: 304210.34 | CQ18: 251459.34 | CR18: 188335.34 | CS18: 52751 | CT18: 115875 | CU18: 259366.34 | CV18: 0.1728983 | CX18: 251459.34 | DA18: 251514 | DB18: 261173.34 | DC18: -0.037193689 | DD18: -1 | DE18: -1 | DF18: -0.036984403
B19: Activations totales | D19: 23176 | E19: 21595 | F19: 1581 | G19: 26083 | H19: -0.1114519 | J19: 22178 | K19: 22763 | L19: -585 | M19: 16883 | N19: 0.31362909 | P19: 20780 | Q19: 34267 | R19: -13487 | S19: 19658 | T19: 0.057076 | V19: 29242 | W19: 42327 | X19: 24327 | Y19: -13085 | Z19: 4915 | AA19: 17958 | AB19: 0.62835505 | AD19: 34794 | AE19: 47576 | AF19: 37576 | AG19: -12782 | AH19: -2782 | AI19: 16250 | AJ19: 1.1411692 | AL19: 31197 | AM19: 47782 | AN19: 42782 | AO19: -16585 | AP19: -11585 | AQ19: 17702 | AR19: 0.76234324 | AT19: 32745 | AU19: 45777 | AV19: 42766 | AW19: -13032 | AX19: -10021 | AY19: 24918 | AZ19: 0.31411028 | BB19: 31297 | BC19: 38237 | BD19: 33309 | BE19: -6940 | BF19: -2012 | BG19: 26307 | BH19: 0.18968335 | BJ19: 28108 | BK19: 38223 | BL19: 36223 | BM19: -10115 | BN19: -8115 | BO19: 26307 | BP19: 0.068460866 | BR19: 28240 | BS19: 40217 | BT19: 30583 | BU19: -11977 | BV19: -2343 | BW19: 16045 | BX19: 0.76004986 | CC19: 0 | CD19: 0 | CK19: 0 | CL19: 0 | CP19: 281757 | CQ19: 378764 | CR19: 304248 | CS19: -97007 | CT19: -22491 | CU19: 208111 | CV19: 0.35387846 | CX19: 461319 | DA19: 361731 | DB19: 249225 | DC19: 0.85101414 | DD19: -1 | DE19: -1 | DF19: 0.45142341
B20: Flux d'inactivité | D20: -22673 | E20: -20699 | F20: -1974 | G20: -17670 | H20: 0.28313526 | J20: -21689 | K20: -20566 | L20: -1123 | M20: -14396 | N20: 0.50659906 | P20: -20752 | Q20: -20026 | R20: -726 | S20: -16002 | T20: 0.2968379 | V20: -28080 | W20: -20784 | X20: -20784 | Y20: -7296 | Z20: -7296 | AA20: -14258 | AB20: 0.96942068 | AD20: -24792 | AE20: -22396 | AF20: -20896 | AG20: -2396 | AH20: -3896 | AI20: -14965 | AJ20: 0.65666555 | AL20: -19183 | AM20: -20827 | AN20: -19327 | AO20: 1644 | AP20: 144 | AQ20: -15867 | AR20: 0.20898721 | AT20: -20823 | AU20: -20823 | AV20: -20823 | AW20: 0 | AX20: 0 | AY20: -23016 | AZ20: -0.095281543 | BB20: -19198 | BC20: -22101 | BD20: 20845 | BE20: 2903 | BF20: -40043 | BG20: -25898 | BH20: -0.25870724 | BJ20: -23576 | BK20: -22789 | BL20: -20789 | BM20: -787 | BN20: -2787 | BO20: -25898 | BP20: -0.089659433 | BR20: -24589 | BS20: -21788 | BT20: -19288 | BU20: -2801 | BV20: -5301 | BW20: -18461 | BX20: 0.33194302 | CC20: 0 | CD20: 0 | CK20: 0 | CL20: 0 | CP20: -225355 | CQ20: -212799 | CR20: -166176 | CS20: -12556 | CT20: -59179 | CU20: -186431 | CV20: 0.20878502 | CX20: -257914 | DA20: -248205 | DB20: -246232 | DC20: 0.047443062 | DD20: -1 | DE20: -1 | DF20: 0.0080127684
B21: Acroissement net | D21: 503 | E21: 896 | F21: -393 | G21: 8413 | H21: -0.94021158 | J21: 489 | K21: 2197 | L21: -1708 | M21: 2487 | N21: -0.80337756 | P21: 28 | Q21: 14241 | R21: -14213 | S21: 3656 | T21: -0.99234136 | V21: 1162 | W21: 21543 | X21: 3543 | Y21: -20381 | Z21: -2381 | AA21: 3700 | AB21: -0.68594595 | AD21: 10002 | AE21: 25180 | AF21: 16680 | AG21: -15178 | AH21: -6678 | AI21: 1285 | AJ21: 6.7836576 | AL21: 12014 | AM21: 26955 | AN21: 23455 | AO21: -14941 | AP21: -11441 | AQ21: 1835 | AR21: 5.547139 | AT21: 11922 | AU21: 24954 | AV21: 21943 | AW21: -13032 | AX21: -10021 | AY21: 1902 | AZ21: 5.2681388 | BB21: 12099 | BC21: 16136 | BD21: 54154 | BE21: -4037 | BF21: -42055 | BG21: 409 | BH21: 28.581907 | BJ21: 4532 | BK21: 15434 | BL21: 15434 | BM21: -10902 | BN21: -10902 | BO21: 409 | BP21: 10.080685 | BR21: 3651 | BS21: 18429 | BT21: 11295 | BU21: -14778 | BV21: -7644 | BW21: -2416 | BX21: -2.5111755 | BZ21: 0 | CA21: 0 | CB21: 0 | CC21: 0 | CD21: 0 | CE21: 0 | CH21: 0 | CI21: 0 | CJ21: 0 | CK21: 0 | CL21: 0 | CM21: 0 | CP21: 56402 | CQ21: 165965 | CR21: 138072 | CS21: -109563 | CT21: -81670 | CU21: 21680 | CV21: 1.6015683 | CX21: 203405 | CY21: 0 | CZ21: 0 | DA21: 113526 | DB21: 2993 | DC21: 66.960241 | DD21: -1 | DE21: -1 | DF21: 36.930505
B22: % churn annualisé | D22: -1.079828 | E22: -0.98602923 | F22: -0.093798813 | G22: -0.091716212 | H22: -98.811183 | J22: -1.0319625 | K22: -0.97371577 | L22: -0.058246729 | M22: -0.66926274 | N22: 0.54193925 | P22: -0.98636906 | Q22: -0.91836814 | R22: -0.068000917 | S22: -0.73517673 | T22: 0.34167612 | V22: -1.3315401 | W22: -0.89212935 | X22: -0.98095251 | Y22: -0.43941078 | Z22: -0.35058763 | AA22: -0.053829705 | AB22: 17.223256 | AD22: -1.1502525 | AE22: -0.88718597 | AF22: -0.94851634 | AG22: -0.26306653 | AH22: -0.20173616 | AI22: -0.67166648 | AL22: -0.85368333 | AM22: -0.75966164 | AN22: -0.78311076 | AO22: -0.094021689 | AP22: -0.070572568 | AQ22: -0.70801939 | AT22: -0.88728596 | AU22: -0.7039785 | AV22: -0.8717755 | AW22: -0.18330746 | AX22: -0.015510464 | AY22: -1.0199365 | BB22: -0.78458233 | BC22: -0.70630281 | BD22: 0.76467272 | BE22: -0.078279525 | BF22: -1.5492551 | BG22: -1.1427738 | BJ22: -0.93696739 | BK22: -0.69890912 | BL22: -0.81155427 | BM22: -0.23805827 | BN22: -0.12541312 | BO22: -1.1427738 | BR22: -0.96416158 | BS22: -0.64049411 | BT22: -0.72158659 | BU22: -0.32366747 | BV22: -0.24257499 | BW22: -0.81762617 | BZ22: 0 | CA22: 0 | CB22: 0 | CC22: 0 | CD22: 0 | CE22: 0 | CH22: 0 | CI22: 0 | CJ22: 0 | CK22: 0 | CL22: 0 | CM22: 0 | CP22: -8.7840195 | CQ22: -0.67972078 | CR22: -0.6456663 | CS22: -8.1042987 | CT22: -8.1383532 | CU22: -0.94507055 | CV22: -783.89489 | CX22: -0.73029974 | CY22: #DIV/0! | CZ22: #DIV/0! | DA22: -0.80513629 | DB22: -1.305616 | DC22: 57.531624 | DF22: -0.38332841
B23: Parc prépayé actif fin de période | D23: 251962.34 | E23: 252355.34 | F23: -393 | G23: 256879.34 | H23: -0.019141282 | J23: 252451.34 | K23: 254552.34 | L23: -2101 | M23: 259366.34 | N23: -0.026661131 | P23: 252479.34 | Q23: 268793.34 | R23: -16314 | S23: 263022.34 | T23: -0.040084048 | V23: 253641.34 | W23: 290336.34 | X23: 256022.34 | Y23: -36695 | Z23: -2381 | AA23: 266722.34 | AB23: -0.049043511 | AD23: 263643.34 | AE23: 315516.34 | AF23: 272702.34 | AG23: -51873 | AH23: -9059 | AI23: 268007.34 | AJ23: -0.016283136 | AL23: 275657.34 | AM23: 342471.34 | AN23: 296157.34 | AO23: -66814 | AP23: -20500 | AQ23: 269842.34 | AR23: 0.02154962 | AT23: 287579.34 | AU23: 367425.34 | AV23: 297600.34 | AW23: -79846 | AX23: -10021 | AY23: 271744.34 | AZ23: 0.058271683 | BB23: 299678.34 | BC23: 383561.34 | BD23: 354197.34 | BE23: -83883 | BF23: -54519 | BG23: 272153.34 | BH23: 0.10113784 | BJ23: 304210.34 | BK23: 398995.34 | BL23: 315112.34 | BM23: -94785 | BN23: -10902 | BO23: 272153.34 | BP23: 0.11779021 | BR23: 307861.34 | BS23: 417424.34 | BT23: 326407.34 | BU23: -109563 | BV23: -18546 | BW23: 269737.34 | BX23: 0.1413375 | BZ23: 307861.34 | CA23: 417424.34 | CB23: 307861.34 | CC23: -109563 | CD23: 0 | CE23: 269737.34 | CF23: 0.1413375 | CH23: 307861.34 | CI23: 417424.34 | CJ23: 307861.34 | CK23: -109563 | CL23: 0 | CM23: 269737.34 | CN23: 0.1413375 | CP23: 307861.34 | CQ23: 417424.34 | CR23: 326407.34 | CS23: -109563 | CT23: -18546 | CU23: 263022.34 | CV23: 0.17047601 | CX23: 454864.34 | CY23: 0 | CZ23: 0 | DA23: 365040 | DB23: 251459.34 | DC23: 0.80889817 | DD23: -1 | DE23: -1 | DF23: 0.45168599
B24: Parc Actif Moyen | D24: 251710.84 | E24: 251907.34 | F24: -196.5 | G24: 252698.17 | H24: -0.0039071514 | J24: 252206.84 | K24: 253453.84 | L24: -1247 | M24: 258122.84 | N24: -0.02291932 | P24: 252465.34 | Q24: 261672.84 | R24: -9207.5 | S24: 261194.34 | T24: -0.03341956 | V24: 253060.34 | W24: 279564.84 | X24: 254250.84 | Y24: -26504.5 | Z24: -1190.5 | AA24: 264872.34 | AB24: -0.044595068 | AD24: 258642.34 | AE24: 302926.34 | AF24: 264362.34 | AG24: -44284 | AH24: -5720 | AI24: 267364.84 | AJ24: -0.032623961 | AL24: 269650.34 | AM24: 328993.84 | AN24: 284429.84 | AO24: -59343.5 | AP24: -14779.5 | AQ24: 268924.84 | AR24: 0.0026977798 | AT24: 281618.34 | AU24: 354948.34 | AV24: 286628.84 | AW24: -73330 | AX24: -5010.5 | AY24: 270793.34 | AZ24: 0.039975134 | BB24: 293628.84 | BC24: 375493.34 | BD24: 327120.34 | BE24: -81864.5 | BF24: -33491.5 | BG24: 271948.84 | BH24: 0.079720877 | BJ24: 301944.34 | BK24: 391278.34 | BL24: 307395.34 | BM24: -89334 | BN24: -5451 | BO24: 271948.84 | BP24: 0.11029832 | BR24: 306035.84 | BS24: 408209.84 | BT24: 320759.84 | BU24: -102174 | BV24: -14724 | BW24: 270945.34 | BX24: 0.12951136 | BZ24: 307861.34 | CA24: 417424.34 | CB24: 307861.34 | CC24: -109563 | CD24: 0 | CE24: 269737.34 | CF24: 0.1413375 | CH24: 307861.34 | CI24: 417424.34 | CJ24: 307861.34 | CK24: -109563 | CL24: 0 | CM24: 269737.34 | CN24: 0.1413375 | CP24: 306035.84 | CQ24: 334441.84 | CR24: 257371.34 | CS24: -28406 | CT24: 48664.5 | CU24: 261194.34 | CV24: 0.17167868 | CX24: 353161.84 | CY24: 0 | CZ24: 0 | DA24: 308277 | DB24: 256316.34 | DC24: 0.37783584 | DD24: -1 | DE24: -1 | DF24: 0.20272083
B25: Parc actif localisé | D25: 203255.33 | E25: 203200.12 | F25: 55.214733 | G25: 208760 | H25: -0.026368398 | J25: 202795.33 | K25: 205003.69 | L25: -2208.3553 | M25: 216277 | N25: -0.062335184 | P25: 203570 | Q25: 216310.96 | R25: -12740.959 | S25: 212639.67 | T25: -0.042652751 | V25: 206275 | W25: 233374.96 | X25: 206073.35 | Y25: -27099.959 | Z25: 201.6514 | AA25: 207498 | AB25: -0.0058940327 | AD25: #REF! | AE25: 256529.07 | AF25: 222081.87 | AG25: #REF! | AH25: #REF! | AI25: 210486 | AL25: 219174.67 | AM25: 278133.07 | AN25: 240885.87 | AO25: -58958.405 | AP25: -21711.205 | AQ25: 212214.67 | AR25: 0.032796979 | AT25: 226835 | AU25: 298145.07 | AV25: 241952.27 | AW25: -71310.072 | AX25: -15117.272 | AY25: 218811 | AZ25: 0.036670917 | BB25: 237409 | BC25: 311105.07 | BD25: 243863.47 | BE25: -73696.072 | BF25: -6454.472 | BG25: 218442 | BH25: 0.08682854 | BJ25: 182933 | BK25: 323505.07 | BL25: 263970.67 | BM25: -140572.07 | BN25: -81037.672 | BO25: 218442 | BP25: -0.16255574 | BR25: 245567 | BS25: 338305.07 | BT25: 265063.47 | BU25: -92738.072 | BV25: -19496.472 | BW25: 215600.67 | BX25: 0.13898998 | CC25: 0 | CD25: 0 | CK25: 0 | CL25: 0 | CP25: 245567 | CQ25: 203200.12 | CR25: 265063.47 | CS25: 42366.881 | CT25: -19496.472 | CU25: 212639.67 | CV25: 0.15485038 | CX25: 368385.07 | DA25: 296097.87 | DB25: 208204.3 | DC25: 0.76934425 | DD25: -1 | DE25: -1 | DF25: 0.42215064
B26: Parc internet | D26: 158249 | E26: 160927.47 | F26: -2678.471 | G26: 164229 | H26: -0.03641257 | J26: 158417 | K26: 163618.89 | L26: -5201.8933 | M26: 163886 | N26: -0.033370758 | P26: 152497 | Q26: 172665.43 | R26: -20168.431 | S26: 167668 | T26: -0.090482382 | V26: 152639 | W26: 186404.56 | X26: 164597.83 | Y26: -33765.556 | Z26: -11958.827 | AA26: 180500 | AB26: -0.15435457 | AD26: 156325 | AE26: 205223.26 | AF26: 177665.5 | AG26: -48898.258 | AH26: -21340.498 | AI26: 181750 | AJ26: -0.13988996 | AL26: 160210 | AM26: 224244.79 | AN26: 194214.23 | AO26: -64034.789 | AP26: -34004.234 | AQ26: 182575 | AR26: -0.1224976 | AT26: 168220.5 | AU26: 242242.87 | AV26: 196586.22 | AW26: -74022.371 | AX26: -28365.721 | AY26: 183318 | AZ26: -0.082356888 | BB26: 171743 | BC26: 254717.28 | BD26: 199663.22 | BE26: -82974.278 | BF26: -27920.218 | BG26: 184218 | BH26: -0.067718681 | BJ26: 172008 | BK26: 264869.78 | BL26: 216125.99 | BM26: -92861.778 | BN26: -44117.988 | BO26: 184218 | BP26: -0.066280168 | BR26: 175621 | BS26: 277410.16 | BT26: 217352.05 | BU26: -101789.16 | BV26: -41731.047 | BW26: 184698 | BX26: -0.049145091 | CC26: 0 | CD26: 0 | CK26: 0 | CL26: 0 | CP26: 175621 | CQ26: 160927.47 | CR26: 217352.05 | CS26: 14693.529 | CT26: -41731.047 | CU26: 167668 | CV26: 0.047433022 | CX26: 307141.05 | DA26: 191500 | DB26: 155803 | DC26: 0.97134236 | DD26: -1 | DE26: -1 | DF26: 0.22911626
B27: Parc actif Mobile Money | D27: 0 | F27: 0 | G27: 0 | L27: 0 | P27: 0 | R27: 0 | S27: 0 | Y27: 0 | Z27: 0 | AA27: 0 | AE27: 0 | AF27: 0 | AG27: 0 | AH27: 0 | AO27: 0 | AP27: 0 | AW27: 0 | AX27: 0 | BE27: 0 | BF27: 0 | BM27: 0 | BN27: 0 | BU27: 0 | BV27: 0 | CC27: 0 | CD27: 0 | CK27: 0 | CL27: 0 | CP27: 0 | CQ27: 0 | CR27: 0 | CS27: 0 | CT27: 0 | CU27: 0 | DB27: 0 | DD27: #DIV/0! | DE27: #DIV/0! | DF27: #DIV/0!
B29: Parc Postpayé | Z29: 0 | AH29: 0 | AP29: 0 | AX29: 0 | BF29: 0 | BN29: 0 | BV29: 0 | CD29: 0 | CL29: 0
B30: Parc début Période | D30: 4775 | E30: 4775 | F30: 0 | G30: 4397 | H30: 0.085967705 | J30: 4780 | K30: 4860 | L30: -80 | M30: 4448 | N30: 0.074640288 | P30: 4776 | Q30: 4946 | R30: -170 | S30: 4484 | T30: 0.065120428 | V30: 4773 | W30: 5018 | X30: 4773 | Y30: -245 | Z30: 0 | AA30: 4501 | AB30: 0.060431015 | AD30: 4775 | AE30: 5075 | AF30: 4830 | AG30: -300 | AH30: -55 | AI30: 4645 | AJ30: 0.027987083 | AL30: 4777 | AM30: 5145 | AN30: 4900 | AO30: -368 | AP30: -123 | AQ30: 4711 | AR30: 0.014009764 | AT30: 4779 | AU30: 5195 | AV30: 4779 | AW30: -416 | AX30: 0 | AY30: 4725 | AZ30: 0.011428571 | BB30: 4782 | BC30: 5256 | BD30: 5256 | BE30: -474 | BF30: -474 | BG30: 4741 | BH30: 0.0086479646 | BJ30: 4785 | BK30: 5320 | BL30: 4785 | BM30: -535 | BN30: 0 | BO30: 4741 | BP30: 0.0092807425 | BR30: 4787 | BS30: 5386 | BT30: 4787 | BU30: -599 | BV30: 0 | BW30: 4750 | BX30: 0.0077894737 | BZ30: 4789 | CA30: 5457 | CB30: 4789 | CC30: -668 | CD30: 0 | CE30: 4757 | CF30: 0.0067269287 | CH30: 4789 | CI30: 5457 | CJ30: 4789 | CK30: -668 | CL30: 0 | CM30: 4757 | CN30: 0.0067269287 | CP30: 4787 | CQ30: 4775 | CR30: 4785 | CS30: 12 | CT30: 2 | CU30: 4484 | CV30: 0.067573595 | CX30: 4775 | DA30: 4720 | DB30: 4763 | DC30: 0.0025194205 | DD30: -1 | DE30: -1 | DF30: -0.0090279236
B31: Activations totales | D31: 107 | E31: 150 | F31: -43 | G31: 145 | H31: -0.26206897 | J31: 5 | K31: 152 | L31: -147 | M31: 132 | N31: -0.96212121 | P31: 5 | Q31: 138 | R31: -133 | S31: 142 | T31: -0.96478873 | V31: 8 | W31: 125 | X31: 125 | Y31: -117 | Z31: -117 | AA31: 190 | AB31: -0.95789474 | AD31: 9 | AE31: 137 | AF31: 137 | AG31: -128 | AH31: -128 | AI31: 175 | AJ31: -0.94857143 | AL31: 11 | AM31: 118 | AN31: 118 | AO31: -107 | AP31: -107 | AQ31: 98 | AR31: -0.8877551 | AT31: 13 | AU31: 128 | AV31: 128 | AW31: -115 | AX31: -115 | AY31: 103 | AZ31: -0.87378641 | BB31: 14 | BC31: 132 | BE31: -118 | BF31: 14 | BG31: 77 | BH31: -0.81818182 | BJ31: 12 | BK31: 135 | BL31: 135 | BM31: -123 | BN31: -123 | BO31: 77 | BP31: -0.84415584 | BR31: 13 | BS31: 139 | BT31: 139 | BU31: -126 | BV31: -126 | BW31: 68 | BX31: -0.80882353 | CC31: 0 | CD31: 0 | CK31: 0 | CL31: 0 | CP31: 197 | CQ31: 1354 | CR31: 899 | CS31: -1157 | CT31: -702 | CU31: 1207 | CV31: -0.83678542 | CX31: 1647 | DA31: 856 | DB31: 1312 | DC31: 0.25533537 | DD31: -1 | DE31: -1 | DF31: -0.34756098
B32: Résiliations totales | D32: 102 | E32: 65 | F32: 37 | G32: 94 | H32: 0.085106383 | J32: 9 | K32: 66 | L32: -57 | M32: 96 | N32: -0.90625 | P32: 8 | Q32: 66 | R32: -58 | S32: 125 | T32: -0.936 | V32: 6 | W32: 68 | X32: 68 | Y32: -62 | Z32: -62 | AA32: 46 | AB32: -0.86956522 | AD32: 7 | AE32: 67 | AF32: 67 | AG32: -60 | AH32: -60 | AI32: 109 | AJ32: -0.93577982 | AL32: 9 | AM32: 68 | AN32: 68 | AO32: -59 | AP32: -59 | AQ32: 84 | AR32: -0.89285714 | AT32: 10 | AU32: 67 | AV32: 67 | AW32: -57 | AX32: -57 | AY32: 87 | AZ32: -0.88505747 | BB32: 11 | BC32: 68 | BD32: 8 | BE32: -57 | BF32: 3 | BG32: 68 | BH32: -0.83823529 | BJ32: 10 | BK32: 69 | BL32: 69 | BM32: -59 | BN32: -59 | BO32: 68 | BP32: -0.85294118 | BR32: 11 | BS32: 68 | BT32: 68 | BU32: -57 | BV32: -57 | BW32: 61 | BX32: -0.81967213 | CC32: 0 | CD32: 0 | CK32: 0 | CL32: 0 | CP32: 183 | CQ32: 672 | CR32: 534 | CS32: -489 | CT32: -351 | CU32: 838 | CV32: -0.78162291 | CX32: 805 | DA32: 494 | DB32: 934 | DC32: -0.13811563 | DD32: -1 | DE32: -1 | DF32: -0.47109208
B33: % résiliation annualisé | D33: -0.25620094 | E33: -0.1619097 | F33: -0.094291238 | G33: -0.25505936 | H33: 0.0044757674 | J33: -0.0226036 | K33: -0.16153375 | L33: 0.13893016 | M33: -0.25794895 | N33: -0.91237181 | P33: -0.020106817 | Q33: -0.1589723 | R33: 0.13886548 | S33: -0.33388982 | T33: -0.93978008 | V33: -0.015081693 | W33: -0.16169623 | X33: -0.16994689 | Y33: 0.14661453 | Z33: 0.1548652 | AA33: -0.12070851 | AB33: -0.87505692 | AD33: -0.01758794 | AE33: 0 | AF33: -0.16526208 | AG33: -0.01758794 | AH33: 0.14767414 | AI33: -0.27960667 | AJ33: -0.93709757 | AL33: -0.0226036 | AM33: -0.15783366 | AN33: -0.16568528 | AO33: 0.13523006 | AP33: 0.14308168 | AQ33: -0.21364985 | AR33: -0.8942026 | AT33: -0.025101977 | AU33: -0.15386087 | AV33: -0.16716914 | AW33: 0.1287589 | AX33: 0.14206717 | AY33: -0.22057891 | AZ33: -0.88619956 | BB33: -0.027594857 | BC33: -0.15626197 | BD33: -0.018278751 | BE33: 0.12866711 | BF33: -0.0093161064 | BG33: -0.17195238 | BH33: -0.83952035 | BJ33: -0.02507313 | BK33: -0.15467962 | BL33: -0.17185554 | BM33: 0.12960649 | BN33: 0.14678241 | BO33: -0.17195238 | BP33: -0.85418561 | BR33: -0.027568922 | BS33: -0.15051185 | BT33: -0.16920684 | BU33: 0.12294293 | BV33: 0.14163792 | BW33: -0.1539918 | BX33: -0.82097149 | BZ33: 0 | CA33: 0 | CB33: 0 | CC33: 0 | CD33: 0 | CE33: 0 | CH33: 0 | CI33: 0 | CJ33: 0 | CK33: 0 | CL33: 0 | CM33: 0 | CP33: -0.45864662 | CQ33: -0.17513683 | CR33: -0.14767189 | CS33: -0.28350979 | CT33: -0.31097473 | CU33: -0.24871081 | CV33: -20.99358 | CX33: -0.15492687 | CY33: #DIV/0! | CZ33: #DIV/0! | DA33: -0.10079576 | DB33: -0.26113091 | DC33: 10.620405 | DF33: -0.61400298
B34: Ventes nettes | D34: 5 | E34: 85 | F34: -80 | G34: 51 | H34: -0.90196078 | J34: -4 | K34: 86 | L34: -90 | M34: 36 | N34: -1.1111111 | P34: -3 | Q34: 72 | R34: -75 | S34: 17 | T34: -1.1764706 | V34: 2 | W34: 57 | X34: 57 | Y34: -55 | Z34: -55 | AA34: 144 | AB34: -0.98611111 | AD34: 2 | AE34: 70 | AF34: 70 | AG34: -68 | AH34: -68 | AI34: 66 | AJ34: -0.96969697 | AL34: 2 | AM34: 50 | AN34: 50 | AO34: -48 | AP34: -48 | AQ34: 14 | AR34: -0.85714286 | AT34: 3 | AU34: 61 | AV34: 61 | AW34: -58 | AX34: -58 | AY34: 16 | AZ34: -0.8125 | BB34: 3 | BC34: 64 | BD34: -8 | BE34: -61 | BF34: 11 | BG34: 9 | BH34: -0.66666667 | BJ34: 2 | BK34: 66 | BL34: 66 | BM34: -64 | BN34: -64 | BO34: 9 | BP34: -0.77777778 | BR34: 2 | BS34: 71 | BT34: 71 | BU34: -69 | BV34: -69 | BW34: 7 | BX34: -0.71428571 | BZ34: 0 | CA34: 0 | CB34: 0 | CC34: 0 | CD34: 0 | CE34: 0 | CH34: 0 | CI34: 0 | CJ34: 0 | CK34: 0 | CL34: 0 | CM34: 0 | CP34: 14 | CQ34: 682 | CR34: 365 | CS34: -668 | CT34: -351 | CU34: 369 | CV34: -0.96205962 | CX34: 842 | CY34: 0 | CZ34: 0 | DA34: 362 | DB34: 378 | DC34: 1.2275132 | DD34: -1 | DE34: -1 | DF34: -0.042328042
B35: Parc Postpayé | D35: 4780 | E35: 4860 | F35: -80 | G35: 4448 | H35: 0.074640288 | J35: 4776 | K35: 4946 | L35: -170 | M35: 4484 | N35: 0.065120428 | P35: 4773 | Q35: 5018 | R35: -245 | S35: 4501 | T35: 0.060431015 | V35: 4775 | W35: 5075 | X35: 4830 | Y35: -300 | Z35: -55 | AA35: 4645 | AB35: 0.027987083 | AD35: 4777 | AE35: 5145 | AF35: 4900 | AG35: -368 | AH35: -123 | AI35: 4711 | AJ35: 0.014009764 | AL35: 4779 | AM35: 5195 | AN35: 4950 | AO35: -416 | AP35: -171 | AQ35: 4725 | AR35: 0.011428571 | AT35: 4782 | AU35: 5256 | AV35: 4840 | AW35: -474 | AX35: -58 | AY35: 4741 | AZ35: 0.0086479646 | BB35: 4785 | BC35: 5320 | BD35: 5248 | BE35: -535 | BF35: -463 | BG35: 4750 | BH35: 0.0073684211 | BJ35: 4787 | BK35: 5386 | BL35: 4851 | BM35: -599 | BN35: -64 | BO35: 4750 | BP35: 0.0077894737 | BR35: 4789 | BS35: 5457 | BT35: 4858 | BU35: -668 | BV35: -69 | BW35: 4757 | BX35: 0.0067269287 | BZ35: 4789 | CA35: 5457 | CB35: 4789 | CC35: -668 | CD35: 0 | CE35: 4757 | CF35: 0.0067269287 | CH35: 4789 | CI35: 5457 | CJ35: 4789 | CK35: -668 | CL35: 0 | CM35: 4757 | CN35: 0.0067269287 | CP35: 4789 | CQ35: 5457 | CR35: 4858 | CS35: -668 | CT35: -69 | CU35: 4501 | CV35: 0.063985781 | CX35: 5617 | CY35: 0 | CZ35: 0 | DA35: 5082 | DB35: 4775 | DC35: 0.17633508 | DD35: -1 | DE35: -1 | DF35: 0.064293194
B36: Parc Moyen Postpayé | D36: 4777.5 | E36: 4817.5 | F36: -40 | G36: 4422.5 | H36: 0.08027134 | J36: 4778 | K36: 4903 | L36: -125 | M36: 4466 | N36: 0.069861173 | P36: 4774.5 | Q36: 4982 | R36: -207.5 | S36: 4492.5 | T36: 0.062771285 | V36: 4774 | W36: 5046.5 | X36: 4801.5 | Y36: -272.5 | Z36: -27.5 | AA36: 4573 | AB36: 0.043953641 | AD36: 4776 | AE36: 5110 | AF36: 4865 | AG36: -334 | AH36: -89 | AI36: 4678 | AJ36: 0.020949124 | AL36: 4778 | AM36: 5170 | AN36: 4925 | AO36: -392 | AP36: -147 | AQ36: 4718 | AR36: 0.012717253 | AT36: 4780.5 | AU36: 5225.5 | AV36: 4809.5 | AW36: -445 | AX36: -29 | AY36: 4733 | AZ36: 0.010035918 | BB36: 4783.5 | BC36: 5222 | BD36: 5252 | BE36: -438.5 | BF36: -468.5 | BG36: 4745.5 | BH36: 0.0080075861 | BJ36: 4786 | BK36: 5353 | BL36: 4818 | BM36: -567 | BN36: -32 | BO36: 4745.5 | BP36: 0.008534401 | BR36: 4788 | BS36: 5421.5 | BT36: 4822.5 | BU36: -633.5 | BV36: -34.5 | BW36: 4753.5 | BX36: 0.00725781 | BZ36: 4789 | CA36: 5457 | CB36: 4789 | CC36: -668 | CD36: 0 | CE36: 4757 | CF36: 0.0067269287 | CH36: 4789 | CI36: 5457 | CJ36: 4789 | CK36: -668 | CL36: 0 | CM36: 4757 | CN36: 0.0067269287 | CP36: 4788 | CQ36: 5116 | CR36: 4821.5 | CS36: -328 | CT36: -33.5 | CU36: 4492.5 | CV36: 0.065776294 | CX36: 5196 | CY36: 0 | CZ36: 0 | DA36: 4901 | DB36: 4769 | DC36: 0.08953659 | DD36: -1 | DE36: -1 | DF36: 0.027678759
DG38: 2.6724945e+09

Sheet CA
B2: Chiffre d'affaires
D4: JANVIER | J4: FEVRIER | P4: MARS | V4: AVRIL | AD4: MAI | AL4: JUIN | AT4: JUILLET | BB4: AOUT | BJ4: SEPTEMBRE | BR4: OCTOBRE | BZ4: NOVEMBRE | CH4: DECEMBRE | CP4: CUMUL | CX4: ANNUEL
B5: ( Montant MFCFA) | D5: 2025 Réel | E5: 2025 Budget | F5: Ecart / Budget | G5: 2024 Réel | H5: Evol % | J5: 2025 Réel | K5: 2025 Budget | L5: Ecart / Budget | M5: 2024 Réel | N5: Evol % | P5: 2025 Réel | Q5: 2025 Budget | R5: Ecart / Budget | S5: 2024 Réel | T5: Evol % | V5: 2025 Réel | W5: 2025 Budget | X5: 2025 Actu 1 | Y5: Ecart / Budget | Z5: Ecart / Actu 1 | AA5: 2024 Réel | AB5: Evol % | AD5: 2025 Réel | AE5: 2025 Budget | AF5: 2025 Actu 1 | AG5: Ecart / Budget | AH5: Ecart / Actu 1 | AI5: 2024 Réel | AJ5: Evol % | AL5: 2025 Réel | AM5: 2025 Budget | AN5: 2025 Actu 1 | AO5: Ecart / Budget | AP5: Ecart / Actu 1 | AQ5: 2024 Réel | AR5: Evol % | AT5: 2025 Réel | AU5: 2025 Budget | AV5: 2025 Actu 2 | AW5: Ecart / Budget | AX5: Ecart / Actu 2 | AY5: 2024 Réel | AZ5: Evol % | BB5: 2025 Réel | BC5: 2025 Budget | BD5: 2025 Actu3 | BE5: Ecart / Budget | BF5: Ecart / Actu 3 | BG5: 2024 Réel | BH5: Evol % | BJ5: 2025 Réel | BK5: 2025 Budget | BL5: 2025 Actu3 | BM5: Ecart / Budget | BN5: Ecart / Actu 3 | BO5: 2024 Réel | BP5: Evol % | BR5: 2025 Réel | BS5: 2025 Budget | BT5: 2025 Actu 3 | BU5: Ecart / Budget | BV5: Ecart / Actu 3 | BW5: 2024 Réel | BX5: Evol % | BZ5: 2025 Réel | CA5: 2025 Budget | CB5: 2025 Actu 3 | CC5: Ecart / Budget | CD5: Ecart / Actu 3 | CE5: 2024 Réel | CF5: Evol % | CH5: 2025 Réel | CI5: 2025 Budget | CJ5: 2025 Actu 3 | CK5: Ecart / Budget | CL5: Ecart / Actu 3 | CM5: 2024 Réel | CN5: Evol % | CP5: 2025 Réel | CQ5: 2025 Budget | CR5: 2025 Actu 3 | CS5: Ecart / Budget | CT5: Ecart / Actu 3 | CU5: 2024 Réel | CV5: Evol % | CX5: 2025 Budget | CY5: 2024 Actu 1 | CZ5: 2024 Actu 2 | DA5: 2025 Actu 3 | DB5: 2024 Réel | DC5: Bud / 2024 (%) | DD5: Actu 1 / 2023 (%) | DE5: Actu 2 / 2023 (%) | DF5: Actu 3 / 2019 (%)
B7: CA Global | D7: 3.6285608e+08 | E7: 3.5669185e+08 | F7: 6164234.3 | G7: 4.029166e+08 | H7: -0.099426324 | J7: 3.1716648e+08 | K7: 3.2553763e+08 | L7: -8371149.5 | M7: 3.2662376e+08 | N7: -0.028954673 | P7: 3.4779065e+08 | Q7: 4.0733975e+08 | R7: -59549100 | S7: 3.7071492e+08 | T7: -0.061837992 | V7: 3.886432e+08 | W7: 4.7545806e+08 | X7: 3.9549e+08 | Y7: -86814858 | Z7: -6846804.5 | AA7: 3.9318629e+08 | AB7: -0.011554549 | AD7: 3.7969038e+08 | AE7: 5.1915384e+08 | AF7: 4.6467864e+08 | AG7: -1.3946345e+08 | AH7: -84988254 | AI7: 3.786904e+08 | AJ7: 0.0026406309 | AL7: 3.5631472e+08 | AM7: 5.6135971e+08 | AN7: 5.7117526e+08 | AO7: -2.0504499e+08 | AP7: -2.1486054e+08 | AQ7: 3.6322803e+08 | AR7: -0.019032983 | AT7: 3.9726618e+08 | AU7: 5.985446e+08 | AV7: 4.2375612e+08 | AW7: -2.0127842e+08 | AX7: -26489944 | AY7: 3.8931613e+08 | AZ7: 0.02042054 | BB7: 3.9608218e+08 | BC7: 6.2103624e+08 | BD7: 3.9999793e+08 | BE7: -2.2495406e+08 | BF7: -3915749 | BG7: 3.7892957e+08 | BH7: 0.045265947 | BJ7: 3.8907851e+08 | BK7: 6.3756647e+08 | BL7: 3.9831703e+08 | BM7: -2.4848796e+08 | BN7: -9238517.4 | BO7: 3.6587225e+08 | BP7: 0.063427215 | BR7: 4.3433758e+08 | BS7: 6.7285925e+08 | BT7: 4.0363699e+08 | BU7: -2.3852166e+08 | BV7: 30700598 | BW7: 3.6389707e+08 | BX7: 0.19357264 | BZ7: 0 | CA7: 0 | CB7: 0 | CC7: 0 | CD7: 0 | CE7: 0 | CH7: 0 | CI7: 0 | CJ7: 0 | CK7: 0 | CL7: 0 | CM7: 0 | CP7: 3.769226e+09 | CQ7: 5.1755474e+09 | CR7: 3.7385254e+09 | CS7: -1.4063214e+09 | CT7: 30700598 | CU7: 3.733375e+09 | CV7: 0.0096028226 | CX7: 6.6367354e+09 | CY7: 0 | CZ7: 0 | DA7: 4.557486e+09 | DB7: 4.4447559e+09 | DC7: 0.49316083 | DD7: -1 | DE7: -1 | DF7: 0.025362485
BL8: 0 | BO8: 0
B9: CA services Mobile | D9: 3.5515608e+08 | E9: 3.4381935e+08 | F9: 11336734 | G9: 3.975065e+08 | H9: -0.10654019 | J9: 3.1166648e+08 | K9: 3.1208013e+08 | L9: -413649.47 | M9: 3.2253376e+08 | N9: -0.033693478 | P9: 3.4346228e+08 | Q9: 3.8613725e+08 | R9: -42674975 | S9: 3.6621492e+08 | T9: -0.062129204 | V9: 3.829932e+08 | W9: 4.1998686e+08 | X9: 3.873188e+08 | Y9: -36993658 | Z9: -4325604.5 | AA9: 3.8868629e+08 | AB9: -0.014647006 | AD9: 3.7639038e+08 | AE9: 4.6052604e+08 | AF9: 4.5105084e+08 | AG9: -84135654 | AH9: -74660454 | AI9: 3.742365e+08 | AJ9: 0.0057554021 | AL9: 3.4953472e+08 | AM9: 5.0261971e+08 | AN9: 5.2943526e+08 | AO9: -1.5308499e+08 | AP9: -1.7990054e+08 | AQ9: 3.573815e+08 | AR9: -0.021956307 | AT9: 3.8976618e+08 | AU9: 5.610016e+08 | AV9: 4.0930362e+08 | AW9: -1.7123542e+08 | AX9: -19537444 | AY9: 3.8311613e+08 | AZ9: 0.017357781 | BB9: 3.8588218e+08 | BC9: 5.8919131e+08 | BD9: 3.9261115e+08 | BE9: -2.0330913e+08 | BF9: -6728969 | BG9: 3.7464957e+08 | BH9: 0.029981633 | BJ9: 3.8157851e+08 | BK9: 6.0855167e+08 | BL9: 3.8811703e+08 | BM9: -2.2697316e+08 | BN9: -6538517.4 | BO9: 3.5967225e+08 | BP9: 0.060906166 | BR9: 4.2703758e+08 | BS9: 6.4264565e+08 | BT9: 3.9343699e+08 | BU9: -2.1560806e+08 | BV9: 33600598 | BW9: 3.5906707e+08 | BX9: 0.18929755 | BZ9: 0 | CA9: 0 | CB9: 0 | CC9: 0 | CD9: 0 | CE9: 0 | CH9: 0 | CI9: 0 | CJ9: 0 | CK9: 0 | CL9: 0 | CM9: 0 | CP9: 3.7034676e+09 | CQ9: 4.8265596e+09 | CR9: 3.669867e+09 | CS9: -1.123092e+09 | CT9: 33600598 | CU9: 3.6830645e+09 | CV9: 0.005539707 | CX9: 6.2200388e+09 | CY9: 0 | CZ9: 0 | DA9: 4.4649276e+09 | DB9: 4.3792454e+09 | DC9: 0.42034489 | DD9: -1 | DE9: -1 | DF9: 0.01956552
BL10: 0 | BO10: 0
B11: CA récurrent | D11: 3.5415608e+08 | E11: 3.4181935e+08 | F11: 12336734 | G11: 3.9643693e+08 | H11: -0.10665215 | J11: 3.1086929e+08 | K11: 3.1008013e+08 | L11: 789161.53 | M11: 3.2168205e+08 | N11: -0.033613189 | P11: 3.4286102e+08 | Q11: 3.8413725e+08 | R11: -41276237 | S11: 3.6538763e+08 | T11: -0.061651285 | V11: 3.819932e+08 | W11: 4.1798686e+08 | X11: 3.863188e+08 | Y11: -35993658 | Z11: -4325604.5 | AA11: 3.8768629e+08 | AB11: -0.014684786 | AD11: 3.757148e+08 | AE11: 4.5852604e+08 | AF11: 4.4905084e+08 | AG11: -82811242 | AH11: -73336041 | AI11: 3.732365e+08 | AJ11: 0.0066400104 | AL11: 3.4884988e+08 | AM11: 5.0061971e+08 | AN11: 5.2743526e+08 | AO11: -1.5176983e+08 | AP11: -1.7858537e+08 | AQ11: 3.5593534e+08 | AR11: -0.019906579 | AT11: 3.8896618e+08 | AU11: 5.590016e+08 | AV11: 4.0730362e+08 | AW11: -1.7003542e+08 | AX11: -18337444 | AY11: 3.821592e+08 | AZ11: 0.017811878 | BB11: 3.8511415e+08 | BC11: 5.8719131e+08 | BD11: 3.9161115e+08 | BE11: -2.0207715e+08 | BF11: -6496994 | BG11: 3.7369264e+08 | BH11: 0.03056391 | BJ11: 3.80813e+08 | BK11: 6.0655167e+08 | BL11: 3.7336051e+08 | BM11: -2.2573867e+08 | BN11: 7452493.4 | BO11: 3.5873044e+08 | BP11: 0.061557536 | BR11: 4.2627208e+08 | BS11: 6.4064565e+08 | BT11: 3.9143699e+08 | BU11: -2.1437357e+08 | BV11: 34835092 | BW11: 3.5815629e+08 | BX11: 0.19018453 | BZ11: 0 | CA11: 0 | CB11: 0 | CC11: 0 | CD11: 0 | CE11: 0 | CH11: 0 | CI11: 0 | CJ11: 0 | CK11: 0 | CL11: 0 | CM11: 0 | CP11: 3.6956097e+09 | CQ11: 4.8065596e+09 | CR11: 3.6607746e+09 | CS11: -1.1109499e+09 | CT11: 34835092 | CU11: 3.6731033e+09 | CV11: 0.0061273397 | CX11: 6.1960388e+09 | CY11: 0 | CZ11: 0 | DA11: 4.4506007e+09 | DB11: 4.3678001e+09 | DC11: 0.41857196 | DD11: -1 | DE11: -1 | DF11: 0.01895704
BL12: 3.5146655e+08 | BO12: 0
B13: CA sortant | D13: 3.4271401e+08 | E13: 3.29278e+08 | F13: 13436005 | G13: 3.8275475e+08 | H13: -0.104612 | J13: 2.9995503e+08 | K13: 2.971768e+08 | L13: 2778225.2 | M13: 3.0980918e+08 | N13: -0.031807153 | P13: 3.3111528e+08 | Q13: 368068600 | R13: -36953317 | S13: 3.5326447e+08 | T13: -0.062698606 | V13: 3.7131454e+08 | W13: 401411752 | X13: 373926952 | Y13: -30097212 | Z13: -2612411.8 | AA13: 3.7583969e+08 | AB13: -0.01204011 | AD13: 3.6329857e+08 | AE13: 4.4138928e+08 | AF13: 4.3538609e+08 | AG13: -78090708 | AH13: -72087516 | AI13: 3.6132845e+08 | AJ13: 0.0054524616 | AL13: 3.3689792e+08 | AM13: 4.8289302e+08 | AN13: 5.1307895e+08 | AO13: -1.459951e+08 | AP13: -1.7618103e+08 | AQ13: 3.4321321e+08 | AR13: -0.018400466 | AT13: 3.7698958e+08 | AU13: 5.4065501e+08 | AV13: 3.9357848e+08 | AW13: -1.6366542e+08 | AX13: -16588891 | AY13: 3.7009559e+08 | AZ13: 0.018627614 | BB13: 3.7190975e+08 | BC13: 5.6655155e+08 | BD13: 378603400 | BE13: -1.9464181e+08 | BF13: -6693652.9 | BG13: 3.6188731e+08 | BH13: 0.027694918 | BJ13: 3.6826125e+08 | BK13: 5.8521914e+08 | BL13: 3.7336051e+08 | BM13: -2.1695789e+08 | BN13: -5099256.1 | BO13: 3.4695553e+08 | BP13: 0.061407639 | BR13: 4.1297286e+08 | BS13: 6.1858413e+08 | BT13: 3.7814164e+08 | BU13: -2.0561126e+08 | BV13: 34831221 | BW13: 3.4674022e+08 | BX13: 0.19101517 | BZ13: 0 | CA13: 0 | CB13: 0 | CC13: 0 | CD13: 0 | CE13: 0 | CH13: 0 | CI13: 0 | CJ13: 0 | CK13: 0 | CL13: 0 | CM13: 0 | CP13: 3.5754288e+09 | CQ13: 4.6312273e+09 | CR13: 3.5405976e+09 | CS13: -1.0557985e+09 | CT13: 34831221 | CU13: 3.5518884e+09 | CV13: 0.0066275785 | CX13: 5.9737202e+09 | CY13: 0 | CZ13: 0 | DA13: 4.3019026e+09 | DB13: 4.2240867e+09 | DC13: 0.41420396 | DD13: -1 | DE13: -1 | DF13: 0.01842195
B14: Prépayé (yc commissions) | D14: 3.2212346e+08 | E14: 3.05878e+08 | F14: 16245460 | G14: 3.6985475e+08 | H14: -0.12905413 | J14: 2.7933738e+08 | K14: 2.737768e+08 | L14: 5560580.1 | M14: 2.9752918e+08 | N14: -0.061142888 | P14: 3.1011528e+08 | Q14: 344656600 | R14: -34541317 | S14: 3.4088447e+08 | T14: -0.090262809 | V14: 3.5031454e+08 | W14: 377011752 | X14: 352926952 | Y14: -26697212 | Z14: -2612411.8 | AA14: 3.6404451e+08 | AB14: -0.037715093 | AD14: 3.4299857e+08 | AE14: 4.1381228e+08 | AF14: 4.0851609e+08 | AG14: -70813708 | AH14: -65517516 | AI14: 3.4992845e+08 | AJ14: -0.019803679 | AL14: 3.1659792e+08 | AM14: 4.5513725e+08 | AN14: 4.8603725e+08 | AO14: -1.3853933e+08 | AP14: -1.6943933e+08 | AQ14: 3.3371321e+08 | AR14: -0.051287401 | AT14: 3.5668958e+08 | AU14: 5.1223368e+08 | AV14: 3.7327848e+08 | AW14: -1.5554409e+08 | AX14: -16588891 | AY14: 3.6009559e+08 | AZ14: -0.0094586057 | BB14: 3.5040975e+08 | BC14: 5.3743861e+08 | BD14: 358603400 | BE14: -1.8702886e+08 | BF14: -8193652.9 | BG14: 3.3997497e+08 | BH14: 0.030692785 | BJ14: 3.4726125e+08 | BK14: 5.553873e+08 | BL14: 3.5146655e+08 | BM14: -2.0812605e+08 | BN14: -4205293.6 | BO14: 3.2375553e+08 | BP14: 0.072603301 | BR14: 3.9287286e+08 | BS14: 5.8800481e+08 | BT14: 3.5608103e+08 | BU14: -1.9513195e+08 | BV14: 36791833 | BW14: 3.2464022e+08 | BX14: 0.21017927 | BZ14: 0 | CA14: 0 | CB14: 0 | CC14: 0 | CD14: 0 | CE14: 0 | CH14: 0 | CI14: 0 | CJ14: 0 | CK14: 0 | CL14: 0 | CM14: 0 | CP14: 3.3687206e+09 | CQ14: 4.3633371e+09 | CR14: 3.3319288e+09 | CS14: -9.9461648e+08 | CT14: 36791833 | CU14: 3.4044209e+09 | CV14: -0.010486439 | CX14: 5.6423078e+09 | CY14: 0 | CZ14: 0 | DA14: 4.047712e+09 | DB14: 4.0046177e+09 | DC14: 0.4089504 | DD14: -1 | DE14: -1 | DF14: 0.010761146
B15: dont voix | D15: 82222561 | E15: 77450375 | F15: 4772185.8 | G15: 1.0971993e+08 | H15: -0.25061419 | J15: 76128865 | K15: 66000000 | L15: 10128865 | M15: 1.0772944e+08 | N15: -0.29333275 | P15: 85856478 | Q15: 81029000 | R15: 4827477.7 | S15: 1.0226094e+08 | T15: -0.1604177 | V15: 88000000 | W15: 89000000 | X15: 91000000 | Y15: -1000000 | Z15: -3000000 | AA15: 1.0455777e+08 | AB15: -0.15835999 | AD15: 87700000 | AE15: 96000000 | AF15: 98000000 | AG15: -8300000 | AH15: -10300000 | AI15: 1.0222376e+08 | AJ15: -0.14207816 | AL15: 83747338 | AM15: 101000000 | AN15: 103000000 | AO15: -17252662 | AP15: -19252662 | AQ15: 93455764 | AR15: -0.10388258 | AT15: 94678201 | AU15: 106000000 | AV15: 91992915 | AW15: -11321799 | AX15: 2685286.5 | AY15: 1.0044708e+08 | AZ15: -0.057432017 | BB15: 95767645 | BC15: 113000000 | BD15: 95700000 | BE15: -17232355 | BF15: 67644.538 | BG15: 86177399 | BH15: 0.11128493 | BJ15: 88303361 | BK15: 119000000 | BL15: 97682997 | BM15: -30696639 | BN15: -9379636.1 | BO15: 79334418 | BP15: 0.11305237 | BR15: 96076457 | BS15: 124000000 | BT15: 99636657 | BU15: -27923543 | BV15: -3560200.2 | BW15: 77835997 | BX15: 0.23434478 | CC15: 0 | CD15: 0 | CK15: 0 | CL15: 0 | CP15: 8.7848091e+08 | CQ15: 972479375 | CR15: 8.8204111e+08 | CS15: -93998469 | CT15: -3560200.2 | CU15: 9.637425e+08 | CV15: -0.088469271 | CX15: 1249479375 | DA15: 1.0970365e+09 | DB15: 1.1157659e+09 | DC15: 0.11984004 | DD15: -1 | DE15: -1 | DF15: -0.016786149
B16: CA Internet 2G/3G/4G | D16: 2.0599548e+08 | E16: 1.9642763e+08 | F16: 9567850.7 | G16: 2.3494905e+08 | H16: -0.12323338 | J16: 1.7203059e+08 | K16: 1.753968e+08 | L16: -3366211 | M16: 1.704311e+08 | N16: 0.0093849997 | P16: 2.1038982e+08 | Q16: 230160000 | R16: -19770184 | S16: 2.2140139e+08 | T16: -0.04973578 | V16: 234000000 | W16: 252670000 | X16: 234870000 | Y16: -18670000 | Z16: -870000 | AA16: 2.3754931e+08 | AB16: -0.014941365 | AD16: 230000000 | AE16: 280658000 | AF16: 280658000 | AG16: -50658000 | AH16: -50658000 | AI16: 2.2261312e+08 | AJ16: 0.033182582 | AL16: 2.0735058e+08 | AM16: 307866000 | AN16: 346766000 | AO16: -1.0051542e+08 | AP16: -1.3941542e+08 | AQ16: 2.0891092e+08 | AR16: -0.0074689145 | AT16: 2.3628268e+08 | AU16: 356337000 | AV16: 252747000 | AW16: -1.2005432e+08 | AX16: -16464323 | AY16: 2.3161649e+08 | AZ16: 0.020146191 | BB16: 2.2873477e+08 | BC16: 372580000 | BD16: 238000000 | BE16: -1.4384523e+08 | BF16: -9265231.1 | BG16: 2.2272204e+08 | BH16: 0.02699657 | BJ16: 2.3246327e+08 | BK16: 384212000 | BL16: 2.2660825e+08 | BM16: -1.5174873e+08 | BN16: 5855020.3 | BO16: 2.1026474e+08 | BP16: 0.1055742 | BR16: 2.7217593e+08 | BS16: 409687000 | BT16: 2.2926907e+08 | BU16: -1.3751107e+08 | BV16: 42906858 | BW16: 2.1312868e+08 | BX16: 0.27704975 | CC16: 0 | CD16: 0 | CK16: 0 | CL16: 0 | CP16: 2.2294231e+09 | CQ16: 2.9659944e+09 | CR16: 2.1865163e+09 | CS16: -7.3657132e+08 | CT16: 42906858 | CU16: 2.1735868e+09 | CV16: 0.025688548 | CX16: 3.8537854e+09 | DA16: 2.6322728e+09 | DB16: 2.5649384e+09 | DC16: 0.50248653 | DD16: -1 | DE16: -1
B17: dont BLR | D17: 30090726 | E17: 28000000 | F17: 2090726.4 | G17: 20206769 | H17: 0.48914091 | J17: 28000000 | K17: 28000000 | L17: 0.36134454 | M17: 15326153 | N17: 0.82694256 | P17: 10627069 | Q17: 29000000 | R17: -18372931 | S17: 13816661 | T17: -0.23085115 | V17: 24580000 | W17: 30284800 | X17: 22000000 | Y17: -5704800 | Z17: 2580000 | AA17: 18457932 | AB17: 0.3316768 | AD17: 22000000 | AE17: 31496192 | AF17: 24200000 | AG17: -9496192 | AH17: -2200000 | AI17: 21197838 | AJ17: 0.037841695 | AL17: 21500000 | AM17: 40000000 | AN17: 30000000 | AO17: -18500000 | AP17: -8500000 | AQ17: 27380617 | AR17: -0.21477299 | AT17: 22000000 | AU17: 43000000 | AV17: 24500000 | AW17: -21000000 | AX17: -2500000 | AY17: 23967595 | AZ17: -0.082093984 | BB17: 22000000 | BC17: 44824000 | BD17: 21500000 | BE17: -22824000 | BF17: 500000 | BG17: 27019869 | BH17: -0.18578435 | BJ17: 22000000 | BK17: 45000000 | BL17: 22000000 | BM17: -23000000 | BN17: 0 | BO17: 30365281 | BP17: -0.27548834 | BR17: 20000000 | BS17: 46999000 | BT17: 22000000 | BU17: -26999000 | BV17: -2000000 | BW17: 30365281 | BX17: -0.34135304 | CC17: 0 | CD17: 0 | CK17: 0 | CL17: 0 | CP17: 2.227978e+08 | CQ17: 366603992 | CR17: 2.247978e+08 | CS17: -1.438062e+08 | CT17: -2000000 | CU17: 2.28104e+08 | CV17: -0.023262196 | CX17: 465103992 | DA17: 2.687978e+08 | DB17: 2.7732939e+08 | DC17: 0.67708151 | DD17: -1 | DE17: -1
B18: dont MIHD | F18: 0 | G18: 1311839 | H18: -1 | L18: 0 | M18: 898110 | N18: -1 | R18: 0 | S18: 0 | Y18: 0 | Z18: 0 | AG18: 0 | AH18: 0 | AI18: 0 | AO18: 0 | AP18: 0 | AQ18: 0 | AW18: 0 | AX18: 0 | AY18: 0 | BE18: 0 | BF18: 0 | BG18: 0 | BL18: 0 | BM18: 0 | BN18: 0 | BO18: 0 | BU18: 0 | BV18: 0 | CC18: 0 | CD18: 0 | CK18: 0 | CL18: 0 | CP18: 0 | CQ18: 0 | CR18: 0 | CS18: 0 | CT18: 0 | CU18: 2209949 | CV18: -1 | DB18: 2209949 | DC18: -1 | DD18: -1 | DE18: -1
B19: dont sms | D19: 3814697.5 | E19: 4000000 | F19: -185302.52 | G19: 3667161.3 | H19: 0.0402317 | J19: 3177926.1 | K19: 4380000 | L19: -1202073.9 | M19: 3144380.7 | N19: 0.010668358 | P19: 3241920.5 | Q19: 4467600 | R19: -1225679.5 | S19: 3405482.4 | T19: -0.048028997 | V19: 3734540.2 | W19: 5056952 | X19: 5056952 | Y19: -1322411.8 | Z19: -1322411.8 | AA19: 3479502.5 | AB19: 0.073297172 | AD19: 3298574.9 | AE19: 5658091 | AF19: 5658091 | AG19: -2359516.1 | AH19: -2359516.1 | AI19: 3893721 | AJ19: -0.15284765 | AL19: 4000000 | AM19: 6271252.9 | AN19: 6271252.9 | AO19: -2271252.9 | AP19: -2271252.9 | AQ19: 3965902.8 | AR19: 0.0085975983 | AT19: 3728705.9 | AU19: 6896677.9 | AV19: 4038560.7 | AW19: -3167972 | AX19: -309854.78 | AY19: 4064424.4 | AZ19: -0.08259927 | BB19: 3907333.6 | BC19: 7034611.5 | BD19: 3403400 | BE19: -3127277.9 | BF19: 503933.61 | BG19: 4055663 | BH19: -0.036573406 | BJ19: 4494625.9 | BK19: 7175303.7 | BL19: 5175303.7 | BM19: -2680677.8 | BN19: -680677.84 | BO19: 3791099.2 | BP19: 0.18557328 | BR19: 4620479 | BS19: 7318809.8 | BT19: 5175303.7 | BU19: -2698330.8 | BV19: -554824.71 | BW19: 3310262.2 | BX19: 0.39580454 | CC19: 0 | CD19: 0 | CK19: 0 | CL19: 0 | CP19: 38018804 | CQ19: 58259299 | CR19: 38573628 | CS19: -20240495 | CT19: -554824.71 | CU19: 36777599 | CV19: 0.033748914 | CX19: 73938974 | DA19: 49604913 | DB19: 44374040 | DC19: 0.66626647 | DD19: -1 | DE19: -1
B20: CA Mobile money | F20: 0 | G20: 0 | L20: 0 | R20: 0 | Y20: 0 | Z20: 0 | AG20: 0 | AH20: 0 | AI20: 0 | AO20: 0 | AP20: 0 | AW20: 0 | AX20: 0 | AY20: 0 | BE20: 0 | BF20: 0 | BL20: 16665000 | BM20: 0 | BN20: -16665000 | BO20: 0 | BU20: 0 | BV20: 0 | CC20: 0 | CD20: 0 | CK20: 0 | CL20: 0 | CP20: 0 | CQ20: 0 | CS20: 0 | CT20: 0 | CU20: 0 | DB20: 0
B21: Postpayé | D21: 20590545 | E21: 23400000 | F21: -2809455.3 | G21: 12900000 | H21: 0.59616626 | J21: 20617645 | K21: 23400000 | L21: -2782354.9 | M21: 12280000 | N21: 0.67896133 | P21: 21000000 | Q21: 23412000 | R21: -2412000 | S21: 12380000 | T21: 0.69628433 | V21: 21000000 | W21: 24400000 | X21: 21000000 | Y21: -3400000 | Z21: 0 | AA21: 11795179 | AB21: 0.78038847 | AD21: 20300000 | AE21: 27577000 | AF21: 26870000 | AG21: -7277000 | AH21: -6570000 | AI21: 11400000 | AJ21: 0.78070175 | AL21: 20300000 | AM21: 27755770 | AN21: 27041700 | AO21: -7455770 | AP21: -6741700 | AQ21: 9500000 | AR21: 1.1368421 | AT21: 20300000 | AU21: 28421328 | AV21: 20300000 | AW21: -8121327.7 | AX21: 0 | AY21: 10000000 | AZ21: 1.03 | BB21: 21500000 | BC21: 29112941 | BD21: 20000000 | BE21: -7612941 | BF21: 1500000 | BG21: 21912339 | BH21: -0.018817669 | BJ21: 21000000 | BK21: 29831840 | BL21: 21893962 | BM21: -8831840.4 | BN21: -893962.5 | BO21: 23200000 | BP21: -0.094827586 | BR21: 20100000 | BS21: 30579317 | BT21: 22060612 | BU21: -10479317 | BV21: -1960612.5 | BW21: 22100000 | BX21: -0.090497738 | BZ21: 0 | CA21: 0 | CB21: 0 | CC21: 0 | CD21: 0 | CE21: 0 | CH21: 0 | CI21: 0 | CJ21: 0 | CK21: 0 | CL21: 0 | CM21: 0 | CP21: 2.0670819e+08 | CQ21: 2.678902e+08 | CR21: 2.086688e+08 | CS21: -61182007 | CT21: -1960612.5 | CU21: 1.4746752e+08 | CV21: 0.40172014 | CX21: 3.3141241e+08 | CY21: 0 | CZ21: 0 | DA21: 2.5419062e+08 | DB21: 2.1946898e+08 | DC21: 0.51006492 | DD21: -1 | DE21: -1 | DF21: 0.15820749
